Workbook

Sheet start

Sheet ご留意事項
B2: ＜重要なご留意事項＞
B3: ・当該参考資料（以下、「本資料」といいます）は、株式会社M&A承継機構（以下「弊社」といいます）が、対象会社の発行済株式の取得もしくは事業その他資産の譲受（以下「本取引」といいます）に関する仲介者として、対象会社から提供された情報に基づき、対象会社に関する情報を貴社に提供するために作成したものです。
B5: ・本資料の存在及び記載されている情報並びに本資料に関する全ての連絡・協議は貴社と弊社間で締結している秘密保持契約書（以下「秘密保持契約書」といいます）に定めのある秘密情報に該当致します。
B7: ・本資料は、本資料の受領者（以下「受領者」といいます）が、意向表明書提出の為に行う検討のご参考情報を提供することのみを目的に作成されています。従って、本資料は完全性を期すことを目的としておらず、受領者が必要と考える全ての情報を網羅しているとは限りません。また、弊社は、本資料に記載されている各々の情報について独自の精査を行う責任を負っておりません。対象会社及び弊社並びにそれらの役員及び従業員（以下総称して「情報提供者等」といいます）は、本資料に記載されているいかなる情報に関しても、その正確性及び完全性について表明または保証（明示か黙示かを問いません）するものではありません。また、情報提供者等は、本資料記載の情報に基づいてなされた受領者または第三者の意思決定により生じたいかなる責任からも免除されることといたします。
B9: ・いかなる場合でも、本取引に関して、対象会社の役職員（元役職員を含む）及び取引先に対して、貴社及び貴社のアドバイザー等本取引に関与する者が直接、間接を問わずコンタクトをとることを禁止させていただくと共に、全てのご連絡は必ず弊社を介していただきますようお願い申し上げます。

Sheet 202408-202507
A1: 対象時期：202408~202507 | L1: =B4+E4+K4 -> 154685143 | M1: =B4+E4+H4+K4 -> 289565955
A2: 2025年7月期 | B2: 企画制作部門 | E2: デジタル制作部門 | H2: ソリューション開発部門 | K2: データベースマーケティング部門 | N2: 共通部門 | Q2: 譲渡対象事業PL （広告制作） | T2: 譲渡対象事業PL （Data＆DigitalGrowth） | W2: 譲渡対象事業PL （広告制作＋Data＆DigitalGrowth）
B3: 実績 | C3: 修正額 | D3: 修正後 | E3: 実績 | F3: 修正額 | G3: 修正後 | H3: 実績 | I3: 修正額 | J3: 修正後 | K3: 実績 | L3: 修正額 | M3: 修正後 | N3: 実績 | O3: 修正額 | P3: 修正後 | Q3: 実績 | R3: 修正額 | S3: 修正後 | T3: 実績 | U3: 修正額 | V3: 修正後 | W3: 実績 | X3: 修正額 | Y3: 修正後
A4: 売上高 | B4: =SUM(B5:B6) -> 97380463 | C4: 0 | D4: =B4+C4 -> 97380463 | E4: =SUM(E5:E6) -> 25572530 | F4: 0 | G4: =E4+F4 -> 25572530 | H4: =SUM(H5:H6) -> 134880812 | I4: 0 | J4: =H4+I4 -> 134880812 | K4: =SUM(K5:K6) -> 31732150 | L4: 0 | M4: =K4+L4 -> 31732150 | N4: =SUM(N5:N6) -> 12491900 | O4: 0 | P4: =N4+O4 -> 12491900 | Q4: =SUM(B4+E4) -> 122952993 | R4: =SUM(C4+F4) -> 0 | S4: =SUM(D4+G4) -> 122952993 | T4: =H4+K4 -> 166612962 | U4: =I4+L4 -> 0 | V4: =J4+M4 -> 166612962 | W4: =SUM(B4,E4,H4,K4) -> 289565955 | X4: =SUM(C4,F4,I4,L4) -> 0 | Y4: =SUM(D4,G4,J4,M4) -> 289565955
A5: 売上高 | B5: 97380463 | C5: 0 | D5: =B5+C5 -> 97380463 | E5: 25572530 | F5: 0 | G5: =E5+F5 -> 25572530 | H5: 134880812 | I5: 0 | J5: =H5+I5 -> 134880812 | K5: 31732150 | L5: 0 | M5: =K5+L5 -> 31732150 | N5: -708100 | O5: 0 | P5: =N5+O5 -> -708100 | Q5: =SUM(B5+E5) -> 122952993 | R5: =SUM(C5+F5) -> 0 | S5: =SUM(D5+G5) -> 122952993 | T5: =H5+K5 -> 166612962 | U5: =I5+L5 -> 0 | V5: =J5+M5 -> 166612962 | W5: =SUM(B5,E5,H5,K5) -> 289565955 | X5: =SUM(C5,F5,I5,L5) -> 0 | Y5: =SUM(D5,G5,J5,M5) -> 289565955 | AA5: ※実績値は加藤様ご提供Excel「55期部門別・営業利益」の再集計値に更新。同Excelは「広告制作」「DDG」の2区分のみで部門内訳がないため、差異額は当該区分内の各部門の既存残高比で按分している（区分合計は完全一致）。 当行の差異＋6,875円は企画制作＋5,445円／デジタル制作＋1,430円として按分。
A6: 賃料収入 | B6: 0 | C6: 0 | D6: =B6+C6 -> 0 | E6: 0 | F6: 0 | G6: =E6+F6 -> 0 | H6: 0 | I6: 0 | J6: =H6+I6 -> 0 | K6: 0 | L6: 0 | M6: =K6+L6 -> 0 | N6: 13200000 | O6: 0 | P6: =N6+O6 -> 13200000 | Q6: =SUM(B6+E6) -> 0 | R6: =SUM(C6+F6) -> 0 | S6: =SUM(D6+G6) -> 0 | T6: =H6+K6 -> 0 | U6: =I6+L6 -> 0 | V6: =J6+M6 -> 0 | W6: =SUM(B6,E6,H6,K6) -> 0 | X6: =SUM(C6,F6,I6,L6) -> 0 | Y6: =SUM(D6,G6,J6,M6) -> 0
A7: 売上原価 | B7: 0 | C7: 0 | D7: =B7+C7 -> 0 | E7: 0 | F7: 0 | G7: =E7+F7 -> 0 | H7: 0 | I7: 0 | J7: =H7+I7 -> 0 | K7: 0 | L7: 0 | M7: =K7+L7 -> 0 | N7: 0 | O7: 0 | P7: =N7+O7 -> 0 | Q7: =SUM(B7+E7) -> 0 | R7: =SUM(C7+F7) -> 0 | S7: =SUM(D7+G7) -> 0 | T7: =H7+K7 -> 0 | U7: =I7+L7 -> 0 | V7: =J7+M7 -> 0 | W7: =SUM(B7,E7,H7,K7) -> 0 | X7: =SUM(C7,F7,I7,L7) -> 0 | Y7: =SUM(D7,G7,J7,M7) -> 0
A8: 売上総利益 | B8: =B4-B7 -> 97380463 | C8: 0 | D8: =B8+C8 -> 97380463 | E8: =E4-E7 -> 25572530 | F8: 0 | G8: =E8+F8 -> 25572530 | H8: =H4-H7 -> 134880812 | I8: 0 | J8: =H8+I8 -> 134880812 | K8: =K4-K7 -> 31732150 | L8: 0 | M8: =K8+L8 -> 31732150 | N8: =N4-N7 -> 12491900 | O8: 0 | P8: =N8+O8 -> 12491900 | Q8: =SUM(B8+E8) -> 122952993 | R8: =SUM(C8+F8) -> 0 | S8: =SUM(D8+G8) -> 122952993 | T8: =H8+K8 -> 166612962 | U8: =I8+L8 -> 0 | V8: =J8+M8 -> 166612962 | W8: =SUM(B8,E8,H8,K8) -> 289565955 | X8: =SUM(C8,F8,I8,L8) -> 0 | Y8: =SUM(D8,G8,J8,M8) -> 289565955
A9: 販売費及び一般管理費 | B9: =B10+SUM(B16:B43) -> 84749341 | C9: =C10+SUM(C16:C43) -> -6553888.5 | D9: =D10+SUM(D16:D43) -> 78195452 | E9: =E10+SUM(E16:E43) -> 21351823 | F9: =F10+SUM(F16:F43) -> -2622262.2 | G9: =E9+F9 -> 18729561 | H9: =H10+SUM(H16:H43) -> 119830678 | I9: =I10+SUM(I16:I43) -> 21801067 | J9: =H9+I9 -> 1.4163174e+08 | K9: =K10+SUM(K16:K43) -> 21681104 | L9: =L10+SUM(L16:L43) -> -4194610.8 | M9: =K9+L9 -> 17486493 | N9: =N10+SUM(N16:N43) -> 94572730 | O9: =O10+SUM(O16:O43) -> -47260868 | P9: =N9+O9 -> 47311862 | Q9: =SUM(B9+E9) -> 106101164 | R9: =SUM(C9+F9) -> -9176150.8 | S9: =SUM(D9+G9) -> 96925013 | T9: =H9+K9 -> 141511782 | U9: =I9+L9 -> 17606456 | V9: =J9+M9 -> 1.5911824e+08 | W9: =SUM(B9,E9,H9,K9) -> 247612946 | X9: =SUM(C9,F9,I9,L9) -> 8430305 | Y9: =SUM(D9,G9,J9,M9) -> 256043251
A10: 人件費 | B10: =SUM(B11:B15) -> 42303396 | C10: =SUM(C11:C15) -> 0 | D10: =B10+C10 -> 42303396 | E10: =SUM(E11:E15) -> 6509683 | F10: =SUM(F11:F15) -> 0 | G10: =E10+F10 -> 6509683 | H10: =SUM(H11:H15) -> 32642425 | I10: =SUM(I11:I15) -> 31849878 | J10: =H10+I10 -> 64492303 | K10: =SUM(K11:K15) -> 12035302 | L10: =SUM(L11:L15) -> 0 | M10: =K10+L10 -> 12035302 | N10: =SUM(N11:N15) -> 45092289 | O10: =SUM(O11:O15) -> -31849878 | P10: =N10+O10 -> 13242411 | Q10: =SUM(B10+E10) -> 48813079 | R10: =SUM(C10+F10) -> 0 | S10: =SUM(D10+G10) -> 48813079 | T10: =H10+K10 -> 44677727 | U10: =I10+L10 -> 31849878 | V10: =J10+M10 -> 76527605 | W10: =SUM(B10,E10,H10,K10) -> 93490806 | X10: =SUM(C10,F10,I10,L10) -> 31849878 | Y10: =SUM(D10,G10,J10,M10) -> 125340684
A11: ー役員報酬 | B11: 0 | C11: 0 | D11: =B11+C11 -> 0 | E11: 0 | F11: 0 | G11: =E11+F11 -> 0 | H11: 0 | I11: =-O11 -> 12000000 | J11: =H11+I11 -> 12000000 | K11: 0 | L11: 0 | M11: =K11+L11 -> 0 | N11: 12000000 | O11: =-N11 -> -12000000 | P11: =N11+O11 -> 0 | Q11: =SUM(B11+E11) -> 0 | R11: =SUM(C11+F11) -> 0 | S11: =SUM(D11+G11) -> 0 | T11: =H11+K11 -> 0 | U11: =I11+L11 -> 12000000 | V11: =J11+M11 -> 12000000 | W11: =SUM(B11,E11,H11,K11) -> 0 | X11: =SUM(C11,F11,I11,L11) -> 12000000 | Y11: =SUM(D11,G11,J11,M11) -> 12000000 | AA11: 加藤様分の役員報酬を共通部門からソリューション部門へ振り分け
A12: ー給料手当 | B12: 35873203 | C12: 0 | D12: =B12+C12 -> 35873203 | E12: 5460000 | F12: 0 | G12: =E12+F12 -> 5460000 | H12: 28184333 | I12: =SUM(内訳_共通部門!O6:O7) -> 16920000 | J12: =H12+I12 -> 45104333 | K12: 10470000 | L12: 0 | M12: =K12+L12 -> 10470000 | N12: 27553741 | O12: =-SUM(内訳_共通部門!O6:O7) -> -16920000 | P12: =N12+O12 -> 10633741 | Q12: =SUM(B12+E12) -> 41333203 | R12: =SUM(C12+F12) -> 0 | S12: =SUM(D12+G12) -> 41333203 | T12: =H12+K12 -> 38654333 | U12: =I12+L12 -> 16920000 | V12: =J12+M12 -> 55574333 | W12: =SUM(B12,E12,H12,K12) -> 79987536 | X12: =SUM(C12,F12,I12,L12) -> 16920000 | Y12: =SUM(D12,G12,J12,M12) -> 96907536 | AA12: 共通部門に譲渡対象者2名（水元・小濱）が存在する為、該当金額を調整。【内訳_共通部門タブを参照】
A13: ー賞与 | B13: 0 | C13: 0 | D13: =B13+C13 -> 0 | E13: 0 | F13: 0 | G13: =E13+F13 -> 0 | H13: 0 | I13: 0 | J13: =H13+I13 -> 0 | K13: 0 | L13: 0 | M13: =K13+L13 -> 0 | N13: 0 | O13: 0 | P13: =N13+O13 -> 0 | Q13: =SUM(B13+E13) -> 0 | R13: =SUM(C13+F13) -> 0 | S13: =SUM(D13+G13) -> 0 | T13: =H13+K13 -> 0 | U13: =I13+L13 -> 0 | V13: =J13+M13 -> 0 | W13: =SUM(B13,E13,H13,K13) -> 0 | X13: =SUM(C13,F13,I13,L13) -> 0 | Y13: =SUM(D13,G13,J13,M13) -> 0
A14: ー法定福利費 | B14: 5806193 | C14: 0 | D14: =B14+C14 -> 5806193 | E14: 941683 | F14: 0 | G14: =E14+F14 -> 941683 | H14: 4273092 | I14: =SUM(内訳_共通部門!O10:O11) -> 2785878 | J14: =H14+I14 -> 7058970 | K14: 1481302 | L14: 0 | M14: =K14+L14 -> 1481302 | N14: 5310548 | O14: =-SUM(内訳_共通部門!O10:O11) -> -2785878 | P14: =N14+O14 -> 2524670 | Q14: =SUM(B14+E14) -> 6747876 | R14: =SUM(C14+F14) -> 0 | S14: =SUM(D14+G14) -> 6747876 | T14: =H14+K14 -> 5754394 | U14: =I14+L14 -> 2785878 | V14: =J14+M14 -> 8540272 | W14: =SUM(B14,E14,H14,K14) -> 12502270 | X14: =SUM(C14,F14,I14,L14) -> 2785878 | Y14: =SUM(D14,G14,J14,M14) -> 15288148 | AA14: 共通部門に計上されている譲渡対象者2名（水元・小濱）分の法定福利費をソリューション部門へ調整。
A15: ー退職共済金 | B15: 624000 | C15: 0 | D15: =B15+C15 -> 624000 | E15: 108000 | F15: 0 | G15: =E15+F15 -> 108000 | H15: 185000 | I15: =SUM(内訳_共通部門!O17:O18) -> 144000 | J15: =H15+I15 -> 329000 | K15: 84000 | L15: 0 | M15: =K15+L15 -> 84000 | N15: 228000 | O15: =-SUM(内訳_共通部門!O17:O18) -> -144000 | P15: =N15+O15 -> 84000 | Q15: =SUM(B15+E15) -> 732000 | R15: =SUM(C15+F15) -> 0 | S15: =SUM(D15+G15) -> 732000 | T15: =H15+K15 -> 269000 | U15: =I15+L15 -> 144000 | V15: =J15+M15 -> 413000 | W15: =SUM(B15,E15,H15,K15) -> 1001000 | X15: =SUM(C15,F15,I15,L15) -> 144000 | Y15: =SUM(D15,G15,J15,M15) -> 1145000
A16: 福利厚生費 | B16: 119890 | C16: 0 | D16: =B16+C16 -> 119890 | E16: 8091 | F16: 0 | G16: =E16+F16 -> 8091 | H16: 39402 | I16: =SUM(内訳_共通部門!O14:O16) -> 59178 | J16: =H16+I16 -> 98580 | K16: 4802 | L16: 0 | M16: =K16+L16 -> 4802 | N16: 716977 | O16: =-SUM(内訳_共通部門!O14:O15) -> -59178 | P16: =N16+O16 -> 657799 | Q16: =SUM(B16+E16) -> 127981 | R16: =SUM(C16+F16) -> 0 | S16: =SUM(D16+G16) -> 127981 | T16: =H16+K16 -> 44204 | U16: =I16+L16 -> 59178 | V16: =J16+M16 -> 103382 | W16: =SUM(B16,E16,H16,K16) -> 172185 | X16: =SUM(C16,F16,I16,L16) -> 59178 | Y16: =SUM(D16,G16,J16,M16) -> 231363 | AA16: 共通部門に計上されている譲渡対象者2名（水元・小濱）分の福利厚生費をソリューション部門へ調整。
A17: 通勤費 | B17: 789274 | C17: 0 | D17: =B17+C17 -> 789274 | E17: 301928 | F17: 0 | G17: =E17+F17 -> 301928 | H17: 623630 | I17: =SUM(内訳_共通部門!O2:O3) -> 137405 | J17: =H17+I17 -> 761035 | K17: 177220 | L17: 0 | M17: =K17+L17 -> 177220 | N17: 137405 | O17: =-SUM(内訳_共通部門!O2:O3) -> -137405 | P17: =N17+O17 -> 0 | Q17: =SUM(B17+E17) -> 1091202 | R17: =SUM(C17+F17) -> 0 | S17: =SUM(D17+G17) -> 1091202 | T17: =H17+K17 -> 800850 | U17: =I17+L17 -> 137405 | V17: =J17+M17 -> 938255 | W17: =SUM(B17,E17,H17,K17) -> 1892052 | X17: =SUM(C17,F17,I17,L17) -> 137405 | Y17: =SUM(D17,G17,J17,M17) -> 2029457 | AA17: 共通部門に計上されている譲渡対象者2名（水元・小濱）分の交通費をソリューション部門へ調整。
A18: 採用教育費 | B18: 0 | C18: 0 | D18: =B18+C18 -> 0 | E18: 0 | F18: 0 | G18: =E18+F18 -> 0 | H18: 5277000 | I18: 0 | J18: =H18+I18 -> 5277000 | K18: 0 | L18: 0 | M18: =K18+L18 -> 0 | N18: 0 | O18: 0 | P18: =N18+O18 -> 0 | Q18: =SUM(B18+E18) -> 0 | R18: =SUM(C18+F18) -> 0 | S18: =SUM(D18+G18) -> 0 | T18: =H18+K18 -> 5277000 | U18: =I18+L18 -> 0 | V18: =J18+M18 -> 5277000 | W18: =SUM(B18,E18,H18,K18) -> 5277000 | X18: =SUM(C18,F18,I18,L18) -> 0 | Y18: =SUM(D18,G18,J18,M18) -> 5277000
A19: 外注費 | B19: 16735149 | C19: 0 | D19: =B19+C19 -> 16735149 | E19: 10261791 | F19: 0 | G19: =E19+F19 -> 10261791 | H19: 51276325 | I19: 0 | J19: =H19+I19 -> 51276325 | K19: 3007160 | L19: 0 | M19: =K19+L19 -> 3007160 | N19: 74032 | O19: 0 | P19: =N19+O19 -> 74032 | Q19: =SUM(B19+E19) -> 26996940 | R19: =SUM(C19+F19) -> 0 | S19: =SUM(D19+G19) -> 26996940 | T19: =H19+K19 -> 54283485 | U19: =I19+L19 -> 0 | V19: =J19+M19 -> 54283485 | W19: =SUM(B19,E19,H19,K19) -> 81280425 | X19: =SUM(C19,F19,I19,L19) -> 0 | Y19: =SUM(D19,G19,J19,M19) -> 81280425 | AA19: ※差異：広告制作＋168,945円（企画制作＋104,727円／デジタル制作＋64,218円）、DDG＋49,823円（ソリューション開発＋47,063円／データベースマーケティング＋2,760円）。既存残高比で按分。
A20: 朝日請求 | B20: 265610 | C20: 0 | D20: =B20+C20 -> 265610 | E20: 0 | F20: 0 | G20: =E20+F20 -> 0 | H20: 0 | I20: 0 | J20: =H20+I20 -> 0 | K20: 0 | L20: 0 | M20: =K20+L20 -> 0 | N20: 0 | O20: 0 | P20: =N20+O20 -> 0 | Q20: =SUM(B20+E20) -> 265610 | R20: =SUM(C20+F20) -> 0 | S20: =SUM(D20+G20) -> 265610 | T20: =H20+K20 -> 0 | U20: =I20+L20 -> 0 | V20: =J20+M20 -> 0 | W20: =SUM(B20,E20,H20,K20) -> 265610 | X20: =SUM(C20,F20,I20,L20) -> 0 | Y20: =SUM(D20,G20,J20,M20) -> 265610
A21: 広告宣伝費 | B21: 0 | C21: 0 | D21: =B21+C21 -> 0 | E21: 0 | F21: 0 | G21: =E21+F21 -> 0 | H21: 0 | I21: 0 | J21: =H21+I21 -> 0 | K21: 0 | L21: 0 | M21: =K21+L21 -> 0 | N21: 0 | O21: 0 | P21: =N21+O21 -> 0 | Q21: =SUM(B21+E21) -> 0 | R21: =SUM(C21+F21) -> 0 | S21: =SUM(D21+G21) -> 0 | T21: =H21+K21 -> 0 | U21: =I21+L21 -> 0 | V21: =J21+M21 -> 0 | W21: =SUM(B21,E21,H21,K21) -> 0 | X21: =SUM(C21,F21,I21,L21) -> 0 | Y21: =SUM(D21,G21,J21,M21) -> 0 | AA21: (株)Kuberu社【原田様の代表法人】への業務委託料分を控除。なお、同社への業務委託料は通期で26,945,460円。
A22: 業務委託費 | B22: 22753440 | C22: =-B22+8400000 -> -14353440 | D22: =B22+C22 -> 8400000 | E22: 3997632 | F22: =-E22 -> -3997632 | G22: =E22+F22 -> 0 | H22: 22587303 | I22: -11460027 | J22: =H22+I22 -> 11127276 | K22: 5901264 | L22: =-K22 -> -5901264 | M22: =K22+L22 -> 0 | N22: 0 | O22: 0 | P22: =N22+O22 -> 0 | Q22: =SUM(B22+E22) -> 26751072 | R22: =SUM(C22+F22) -> -18351072 | S22: =SUM(D22+G22) -> 8400000 | T22: =H22+K22 -> 28488567 | U22: =I22+L22 -> -17361291 | V22: =J22+M22 -> 11127276 | W22: =SUM(B22,E22,H22,K22) -> 55239639 | X22: =SUM(C22,F22,I22,L22) -> -35712363 | Y22: =SUM(D22,G22,J22,M22) -> 19527276 | AA22: (株)Rimito社【加藤様の代表法人】への業務委託料分のみ計上を残す修正を行う。Rimito社への業務委託料は、11,127,276円。
A23: 交際費 | B23: 44610 | C23: 0 | D23: =B23+C23 -> 44610 | E23: 0 | F23: 0 | G23: =E23+F23 -> 0 | H23: 47023 | I23: 0 | J23: =H23+I23 -> 47023 | K23: 0 | L23: 0 | M23: =K23+L23 -> 0 | N23: 6777295 | O23: 0 | P23: =N23+O23 -> 6777295 | Q23: =SUM(B23+E23) -> 44610 | R23: =SUM(C23+F23) -> 0 | S23: =SUM(D23+G23) -> 44610 | T23: =H23+K23 -> 47023 | U23: =I23+L23 -> 0 | V23: =J23+M23 -> 47023 | W23: =SUM(B23,E23,H23,K23) -> 91633 | X23: =SUM(C23,F23,I23,L23) -> 0 | Y23: =SUM(D23,G23,J23,M23) -> 91633 | AA23: ※その他の業務委託費は、退職者への業務継続費用と(株)Kuberu社【原田様の代表法人】であり、今後の計上予定はない。純粋な外部への委託は外注費で計上されている。
A24: 会議費 | B24: 0 | C24: 0 | D24: =B24+C24 -> 0 | E24: 0 | F24: 0 | G24: =E24+F24 -> 0 | H24: 0 | I24: 0 | J24: =H24+I24 -> 0 | K24: 0 | L24: 0 | M24: =K24+L24 -> 0 | N24: 151000 | O24: 0 | P24: =N24+O24 -> 151000 | Q24: =SUM(B24+E24) -> 0 | R24: =SUM(C24+F24) -> 0 | S24: =SUM(D24+G24) -> 0 | T24: =H24+K24 -> 0 | U24: =I24+L24 -> 0 | V24: =J24+M24 -> 0 | W24: =SUM(B24,E24,H24,K24) -> 0 | X24: =SUM(C24,F24,I24,L24) -> 0 | Y24: =SUM(D24,G24,J24,M24) -> 0
A25: 旅費交通費 | B25: 485067 | C25: 0 | D25: =B25+C25 -> 485067 | E25: 0 | F25: 0 | G25: =E25+F25 -> 0 | H25: 686052 | I25: 0 | J25: =H25+I25 -> 686052 | K25: 144356 | L25: 0 | M25: =K25+L25 -> 144356 | N25: 5409362 | O25: 0 | P25: =N25+O25 -> 5409362 | Q25: =SUM(B25+E25) -> 485067 | R25: =SUM(C25+F25) -> 0 | S25: =SUM(D25+G25) -> 485067 | T25: =H25+K25 -> 830408 | U25: =I25+L25 -> 0 | V25: =J25+M25 -> 830408 | W25: =SUM(B25,E25,H25,K25) -> 1315475 | X25: =SUM(C25,F25,I25,L25) -> 0 | Y25: =SUM(D25,G25,J25,M25) -> 1315475 | AA25: ※差異：広告制作＋4,078円（全額企画制作）、DDG＋256,102円（ソリューション開発＋211,582円／データベースマーケティング＋44,520円）。既存残高比で按分。
A26: 通信費 | B26: 5474 | C26: 0 | D26: =B26+C26 -> 5474 | E26: 637 | F26: 0 | G26: =E26+F26 -> 637 | H26: 0 | I26: 0 | J26: =H26+I26 -> 0 | K26: 0 | L26: 0 | M26: =K26+L26 -> 0 | N26: 1417106 | O26: 0 | P26: =N26+O26 -> 1417106 | Q26: =SUM(B26+E26) -> 6111 | R26: =SUM(C26+F26) -> 0 | S26: =SUM(D26+G26) -> 6111 | T26: =H26+K26 -> 0 | U26: =I26+L26 -> 0 | V26: =J26+M26 -> 0 | W26: =SUM(B26,E26,H26,K26) -> 6111 | X26: =SUM(C26,F26,I26,L26) -> 0 | Y26: =SUM(D26,G26,J26,M26) -> 6111
A27: 水道光熱費 | B27: 0 | C27: 0 | D27: =B27+C27 -> 0 | E27: 0 | F27: 0 | G27: =E27+F27 -> 0 | H27: 0 | I27: 0 | J27: =H27+I27 -> 0 | K27: 0 | L27: 0 | M27: =K27+L27 -> 0 | N27: 464150 | O27: 0 | P27: =N27+O27 -> 464150 | Q27: =SUM(B27+E27) -> 0 | R27: =SUM(C27+F27) -> 0 | S27: =SUM(D27+G27) -> 0 | T27: =H27+K27 -> 0 | U27: =I27+L27 -> 0 | V27: =J27+M27 -> 0 | W27: =SUM(B27,E27,H27,K27) -> 0 | X27: =SUM(C27,F27,I27,L27) -> 0 | Y27: =SUM(D27,G27,J27,M27) -> 0
A28: 荷造運賃 | B28: 0 | C28: 0 | D28: =B28+C28 -> 0 | E28: 0 | F28: 0 | G28: =E28+F28 -> 0 | H28: 0 | I28: 0 | J28: =H28+I28 -> 0 | K28: 0 | L28: 0 | M28: =K28+L28 -> 0 | N28: 0 | O28: 0 | P28: =N28+O28 -> 0 | Q28: =SUM(B28+E28) -> 0 | R28: =SUM(C28+F28) -> 0 | S28: =SUM(D28+G28) -> 0 | T28: =H28+K28 -> 0 | U28: =I28+L28 -> 0 | V28: =J28+M28 -> 0 | W28: =SUM(B28,E28,H28,K28) -> 0 | X28: =SUM(C28,F28,I28,L28) -> 0 | Y28: =SUM(D28,G28,J28,M28) -> 0
A29: 修繕費 | B29: 0 | C29: 0 | D29: =B29+C29 -> 0 | E29: 0 | F29: 0 | G29: =E29+F29 -> 0 | H29: 0 | I29: 0 | J29: =H29+I29 -> 0 | K29: 0 | L29: 0 | M29: =K29+L29 -> 0 | N29: 442500 | O29: 0 | P29: =N29+O29 -> 442500 | Q29: =SUM(B29+E29) -> 0 | R29: =SUM(C29+F29) -> 0 | S29: =SUM(D29+G29) -> 0 | T29: =H29+K29 -> 0 | U29: =I29+L29 -> 0 | V29: =J29+M29 -> 0 | W29: =SUM(B29,E29,H29,K29) -> 0 | X29: =SUM(C29,F29,I29,L29) -> 0 | Y29: =SUM(D29,G29,J29,M29) -> 0
A30: 新聞図書費 | B30: 3084 | C30: 0 | D30: =B30+C30 -> 3084 | E30: 0 | F30: 0 | G30: =E30+F30 -> 0 | H30: 0 | I30: 0 | J30: =H30+I30 -> 0 | K30: 0 | L30: 0 | M30: =K30+L30 -> 0 | N30: 192496 | O30: 0 | P30: =N30+O30 -> 192496 | Q30: =SUM(B30+E30) -> 3084 | R30: =SUM(C30+F30) -> 0 | S30: =SUM(D30+G30) -> 3084 | T30: =H30+K30 -> 0 | U30: =I30+L30 -> 0 | V30: =J30+M30 -> 0 | W30: =SUM(B30,E30,H30,K30) -> 3084 | X30: =SUM(C30,F30,I30,L30) -> 0 | Y30: =SUM(D30,G30,J30,M30) -> 3084
A31: 諸会費 | B31: 0 | C31: 0 | D31: =B31+C31 -> 0 | E31: 0 | F31: 0 | G31: =E31+F31 -> 0 | H31: 0 | I31: 0 | J31: =H31+I31 -> 0 | K31: 0 | L31: 0 | M31: =K31+L31 -> 0 | N31: 37500 | O31: 0 | P31: =N31+O31 -> 37500 | Q31: =SUM(B31+E31) -> 0 | R31: =SUM(C31+F31) -> 0 | S31: =SUM(D31+G31) -> 0 | T31: =H31+K31 -> 0 | U31: =I31+L31 -> 0 | V31: =J31+M31 -> 0 | W31: =SUM(B31,E31,H31,K31) -> 0 | X31: =SUM(C31,F31,I31,L31) -> 0 | Y31: =SUM(D31,G31,J31,M31) -> 0
A32: 支払手数料/システム利用料 | B32: 1138519 | C32: =$N$32*B4/$L$1 -> 2109229.2 | D32: =B32+C32 -> 3247748.2 | E32: 272061 | F32: =$N$32*E4/$L$1 -> 553892.7 | G32: =E32+F32 -> 825953.7 | H32: 6538700 | I32: =-3118200 -> -3118200 | J32: =H32+I32 -> 3420500 | K32: 0 | L32: =$N$32*K4/$L$1 -> 687308.07 | M32: =K32+L32 -> 687308.07 | N32: 3350430 | O32: =-SUM(C32,F32,L32) -> -3350430 | P32: =N32+O32 -> 0 | Q32: =SUM(B32+E32) -> 1410580 | R32: =SUM(C32+F32) -> 2663121.9 | S32: =SUM(D32+G32) -> 4073701.9 | T32: =H32+K32 -> 6538700 | U32: =I32+L32 -> -2430891.9 | V32: =J32+M32 -> 4107808.1 | W32: =SUM(B32,E32,H32,K32) -> 7949280 | X32: =SUM(C32,F32,I32,L32) -> 232230 | Y32: =SUM(D32,G32,J32,M32) -> 8181510 | AA32: 共通部門経費を、売上割合に応じて、各部門へ振り分け。25年7月期はSalesforceライセンスの購入費用が嵩まったが、￥3,420,500の金額に調整可能な為、差額分を修正。 ※実績の差異＋12,834円は企画制作＋10,359円／デジタル制作＋2,475円として按分。
A33: 地代家賃 | B33: 0 | C33: =$N33*B$4/$M$1 -> 2697984.7 | D33: =B33+C33 -> 2697984.7 | E33: 0 | F33: =$N33*E$4/$M$1 -> 708502.42 | G33: =E33+F33 -> 708502.42 | H33: 0 | I33: =$N33*H$4/$M$1 -> 3736954.5 | J33: =H33+I33 -> 3736954.5 | K33: 0 | L33: =$N33*K$4/$M$1 -> 879158.42 | M33: =K33+L33 -> 879158.42 | N33: 8022600 | O33: =-SUM(C33,F33,I33,L33) -> -8022600 | P33: =N33+O33 -> 0 | Q33: =SUM(B33+E33) -> 0 | R33: =SUM(C33+F33) -> 3406487.1 | S33: =SUM(D33+G33) -> 3406487.1 | T33: =H33+K33 -> 0 | U33: =I33+L33 -> 4616112.9 | V33: =J33+M33 -> 4616112.9 | W33: =SUM(B33,E33,H33,K33) -> 0 | X33: =SUM(C33,F33,I33,L33) -> 8022600 | Y33: =SUM(D33,G33,J33,M33) -> 8022600 | AA33: 共通部門経費を、売上割合に応じて、各部門へ振り分け
A34: 共益費 | B34: 0 | C34: =$N34*B$4/$M$1 -> 430208.59 | D34: =B34+C34 -> 430208.59 | E34: 0 | F34: =$N34*E$4/$M$1 -> 112974.63 | G34: =E34+F34 -> 112974.63 | H34: 0 | I34: =$N34*H$4/$M$1 -> 595878.09 | J34: =H34+I34 -> 595878.09 | K34: 0 | L34: =$N34*K$4/$M$1 -> 140186.68 | M34: =K34+L34 -> 140186.68 | N34: 1279248 | O34: =-SUM(C34,F34,I34,L34) -> -1279248 | P34: =N34+O34 -> 0 | Q34: =SUM(B34+E34) -> 0 | R34: =SUM(C34+F34) -> 543183.23 | S34: =SUM(D34+G34) -> 543183.23 | T34: =H34+K34 -> 0 | U34: =I34+L34 -> 736064.77 | V34: =J34+M34 -> 736064.77 | W34: =SUM(B34,E34,H34,K34) -> 0 | X34: =SUM(C34,F34,I34,L34) -> 1279248 | Y34: =SUM(D34,G34,J34,M34) -> 1279248 | AA34: 共通部門経費を、売上割合に応じて、各部門へ振り分け
A35: 賃借料 | B35: 105400 | C35: 0 | D35: =B35+C35 -> 105400 | E35: 0 | F35: 0 | G35: =E35+F35 -> 0 | H35: 0 | I35: 0 | J35: =H35+I35 -> 0 | K35: 0 | L35: 0 | M35: =K35+L35 -> 0 | N35: 725952 | O35: 0 | P35: =N35+O35 -> 725952 | Q35: =SUM(B35+E35) -> 105400 | R35: =SUM(C35+F35) -> 0 | S35: =SUM(D35+G35) -> 105400 | T35: =H35+K35 -> 0 | U35: =I35+L35 -> 0 | V35: =J35+M35 -> 0 | W35: =SUM(B35,E35,H35,K35) -> 105400 | X35: =SUM(C35,F35,I35,L35) -> 0 | Y35: =SUM(D35,G35,J35,M35) -> 105400
A36: 保険料 | B36: 0 | C36: 0 | D36: =B36+C36 -> 0 | E36: 0 | F36: 0 | G36: =E36+F36 -> 0 | H36: 0 | I36: 0 | J36: =H36+I36 -> 0 | K36: 0 | L36: 0 | M36: =K36+L36 -> 0 | N36: 442756 | O36: 0 | P36: =N36+O36 -> 442756 | Q36: =SUM(B36+E36) -> 0 | R36: =SUM(C36+F36) -> 0 | S36: =SUM(D36+G36) -> 0 | T36: =H36+K36 -> 0 | U36: =I36+L36 -> 0 | V36: =J36+M36 -> 0 | W36: =SUM(B36,E36,H36,K36) -> 0 | X36: =SUM(C36,F36,I36,L36) -> 0 | Y36: =SUM(D36,G36,J36,M36) -> 0
A37: 租税公課 | B37: 0 | C37: 0 | D37: =B37+C37 -> 0 | E37: 0 | F37: 0 | G37: =E37+F37 -> 0 | H37: 0 | I37: 0 | J37: =H37+I37 -> 0 | K37: 0 | L37: 0 | M37: =K37+L37 -> 0 | N37: 1058500 | O37: 0 | P37: =N37+O37 -> 1058500 | Q37: =SUM(B37+E37) -> 0 | R37: =SUM(C37+F37) -> 0 | S37: =SUM(D37+G37) -> 0 | T37: =H37+K37 -> 0 | U37: =I37+L37 -> 0 | V37: =J37+M37 -> 0 | W37: =SUM(B37,E37,H37,K37) -> 0 | X37: =SUM(C37,F37,I37,L37) -> 0 | Y37: =SUM(D37,G37,J37,M37) -> 0
A38: 支払報酬料 | B38: 0 | C38: 0 | D38: =B38+C38 -> 0 | E38: 0 | F38: 0 | G38: =E38+F38 -> 0 | H38: 0 | I38: 0 | J38: =H38+I38 -> 0 | K38: 0 | L38: 0 | M38: =K38+L38 -> 0 | N38: 6647672 | O38: 0 | P38: =N38+O38 -> 6647672 | Q38: =SUM(B38+E38) -> 0 | R38: =SUM(C38+F38) -> 0 | S38: =SUM(D38+G38) -> 0 | T38: =H38+K38 -> 0 | U38: =I38+L38 -> 0 | V38: =J38+M38 -> 0 | W38: =SUM(B38,E38,H38,K38) -> 0 | X38: =SUM(C38,F38,I38,L38) -> 0 | Y38: =SUM(D38,G38,J38,M38) -> 0
A39: 減価償却費 | B39: 0 | C39: 0 | D39: =B39+C39 -> 0 | E39: 0 | F39: 0 | G39: =E39+F39 -> 0 | H39: 0 | I39: 0 | J39: =H39+I39 -> 0 | K39: 410000 | L39: 0 | M39: =K39+L39 -> 410000 | N39: 5736372 | O39: 0 | P39: =N39+O39 -> 5736372 | Q39: =SUM(B39+E39) -> 0 | R39: =SUM(C39+F39) -> 0 | S39: =SUM(D39+G39) -> 0 | T39: =H39+K39 -> 410000 | U39: =I39+L39 -> 0 | V39: =J39+M39 -> 410000 | W39: =SUM(B39,E39,H39,K39) -> 410000 | X39: =SUM(C39,F39,I39,L39) -> 0 | Y39: =SUM(D39,G39,J39,M39) -> 410000
A40: 研修費 | B40: 0 | C40: 0 | D40: =B40-C40 -> 0 | E40: 0 | F40: 0 | G40: =E40-F40 -> 0 | H40: 90674 | I40: 0 | J40: =H40-I40 -> 90674 | K40: 0 | L40: 0 | M40: =K40-L40 -> 0 | N40: 85417 | O40: 0 | P40: =N40+O40 -> 85417 | Q40: =SUM(B40+E40) -> 0 | R40: =SUM(C40+F40) -> 0 | S40: =SUM(D40+G40) -> 0 | T40: =H40+K40 -> 90674 | U40: =I40+L40 -> 0 | V40: =J40+M40 -> 90674 | W40: =SUM(B40,E40,H40,K40) -> 90674 | X40: =SUM(C40,F40,I40,L40) -> 0 | Y40: =SUM(D40,G40,J40,M40) -> 90674
...

Sheet 内訳_共通部門
C1: 45505 | D1: 45536 | E1: 45566 | F1: 45597 | G1: 45627 | H1: 45658 | I1: 45689 | J1: 45717 | K1: 45748 | L1: 45778 | M1: 45809 | N1: 45839 | O1: 総計
A2: 通勤費 | B2: 水元豪 | C2: 0 | D2: 0 | E2: 40110 | F2: 0 | G2: 0 | H2: 0 | I2: 0 | J2: 0 | K2: 40110 | L2: 0 | M2: 0 | N2: 0 | O2: =SUM(C2:N2) -> 80220 | R2: 経営企画
B3: 小濱 郁哉 | C3: 0 | D3: 0 | E3: 6055 | F3: 8746 | G3: 8073 | H3: 0 | I3: 6728 | J3: 6055 | K3: 5382 | L3: 7400 | M3: 8746 | N3: 0 | O3: =SUM(C3:N3) -> 57185 | R3: DDG
B4: 髙橋 由美子 | C4: 0 | D4: 0 | E4: 0 | F4: 0 | G4: 0 | H4: 40618 | I4: 0 | J4: 0 | K4: 0 | L4: 0 | M4: 0 | N4: 40618 | O4: =SUM(C4:N4) -> 81236 | R4: DDG
B5: 中村 慎太郎 | C5: 0 | D5: 0 | E5: 0 | F5: 0 | G5: 0 | H5: 0 | I5: 0 | J5: 0 | K5: 0 | L5: 0 | M5: 0 | N5: 0 | O5: =SUM(C5:N5) -> 0 | R5: DDG
A6: 給料手当 | B6: 水元豪 | C6: 570000 | D6: 570000 | E6: 570000 | F6: 570000 | G6: 570000 | H6: 570000 | I6: 570000 | J6: 570000 | K6: 570000 | L6: 570000 | M6: 570000 | N6: 570000 | O6: =SUM(C6:N6) -> 6840000 | R6: 経営企画
B7: 小濱 郁哉 | C7: 840000 | D7: 840000 | E7: 840000 | F7: 840000 | G7: 840000 | H7: 840000 | I7: 840000 | J7: 840000 | K7: 840000 | L7: 840000 | M7: 840000 | N7: 840000 | O7: =SUM(C7:N7) -> 10080000 | R7: DDG
B8: 髙橋 由美子 | C8: 0 | D8: 0 | E8: 0 | F8: 0 | G8: 0 | H8: 685000 | I8: 685000 | J8: 685000 | K8: 685000 | L8: 685000 | M8: 685000 | N8: 685000 | O8: =SUM(C8:N8) -> 4795000 | R8: DDG
B9: 中村 慎太郎 | C9: 0 | D9: 0 | E9: 0 | F9: 0 | G9: 0 | H9: 0 | I9: 0 | J9: 0 | K9: 0 | L9: 415000 | M9: 415000 | N9: 415000 | O9: =SUM(C9:N9) -> 1245000 | R9: DDG
A10: 法定福利費 | B10: 水元豪 | C10: =C6*$Q$27 -> 93850.5 | D10: =D6*$Q$27 -> 93850.5 | E10: =E6*$Q$27 -> 93850.5 | F10: =F6*$Q$27 -> 93850.5 | G10: =G6*$Q$27 -> 93850.5 | H10: =H6*$Q$27 -> 93850.5 | I10: =I6*$Q$27 -> 93850.5 | J10: =J6*$Q$27 -> 93850.5 | ... N10: =N6*$Q$27 -> 93850.5 | O10: =SUM(C10:N10) -> 1126206
B11: 小濱 郁哉 | C11: =C7*$Q$27 -> 138306 | D11: =D7*$Q$27 -> 138306 | E11: =E7*$Q$27 -> 138306 | F11: =F7*$Q$27 -> 138306 | G11: =G7*$Q$27 -> 138306 | H11: =H7*$Q$27 -> 138306 | I11: =I7*$Q$27 -> 138306 | J11: =J7*$Q$27 -> 138306 | ... N11: =N7*$Q$27 -> 138306 | O11: =SUM(C11:N11) -> 1659672
B12: 髙橋 由美子 | C12: 0 | D12: 0 | E12: 0 | F12: 0 | G12: 0 | H12: =H8*$Q$27 -> 112785.25 | I12: =I8*$Q$27 -> 112785.25 | J12: =J8*$Q$27 -> 112785.25 | K12: =K8*$Q$27 -> 112785.25 | L12: =L8*$Q$27 -> 112785.25 | M12: =M8*$Q$27 -> 112785.25 | N12: =N8*$Q$27 -> 112785.25 | O12: =SUM(C12:N12) -> 789496.75
B13: 中村 慎太郎 | C13: 0 | D13: 0 | E13: 0 | F13: 0 | G13: 0 | H13: =H9*$Q$27 -> 0 | I13: =I9*$Q$27 -> 0 | J13: =J9*$Q$27 -> 0 | K13: =K9*$Q$27 -> 0 | L13: =L9*$Q$27 -> 68329.75 | M13: =M9*$Q$27 -> 68329.75 | N13: =N9*$Q$27 -> 68329.75 | O13: =SUM(C13:N13) -> 204989.25
A14: 福利厚生費 | B14: 水元豪 | C14: 0 | D14: 0 | E14: 31331 | F14: 0 | G14: 0 | H14: 0 | I14: 0 | J14: 0 | K14: 0 | L14: 0 | M14: 0 | N14: 0 | O14: =SUM(C14:N14) -> 31331
B15: 小濱 郁哉 | C15: 0 | D15: 0 | E15: 0 | F15: 27847 | G15: 0 | H15: 0 | I15: 0 | J15: 0 | K15: 0 | L15: 0 | M15: 0 | N15: 0 | O15: =SUM(C15:N15) -> 27847
B16: 中村 慎太郎 | C16: 0 | D16: 0 | E16: 0 | F16: 0 | G16: 0 | H16: 0 | I16: 0 | J16: 0 | K16: 0 | L16: 0 | M16: 0 | N16: 0 | O16: =SUM(C16:N16) -> 0
A17: 退職共済金 | B17: 水元豪 | C17: 6000 | D17: 6000 | E17: 6000 | F17: 6000 | G17: 6000 | H17: 6000 | I17: 6000 | J17: 6000 | K17: 6000 | L17: 6000 | M17: 6000 | N17: 6000 | O17: =SUM(C17:N17) -> 72000
B18: 小濱 郁哉 | C18: 6000 | D18: 6000 | E18: 6000 | F18: 6000 | G18: 6000 | H18: 6000 | I18: 6000 | J18: 6000 | K18: 6000 | L18: 6000 | M18: 6000 | N18: 6000 | O18: =SUM(C18:N18) -> 72000
B19: 髙橋 由美子 | C19: 0 | D19: 0 | E19: 0 | F19: 0 | G19: 0 | H19: 0 | I19: 0 | J19: 0 | K19: 0 | L19: 0 | M19: 0 | N19: 4000 | O19: =SUM(C19:N19) -> 4000
B20: 中村 慎太郎 | C20: 0 | D20: 0 | E20: 0 | F20: 0 | G20: 0 | H20: 0 | I20: 0 | J20: 0 | K20: 0 | L20: 0 | M20: 0 | N20: 0 | O20: =SUM(C20:N20) -> 0 | Q20: 法定福利
Q21: 0.05
Q22: 0.00805
Q23: 0.0915
Q24: 0.0036
Q25: 0.0085
Q26: 0.003
Q27: =SUM(Q21:Q26) -> 0.16465

Sheet end

Sheet 202208-12分_検証用1_関数積算
B2: 企画制作部門 | F2: デジタル制作部門 | J2: ソリューション開発部門 | N2: 共通部門 | R2: 合計
B3: 部門別予算 | C3: 実績 | D3: 差額 | E3: 差額(率) | F3: 部門別予算 | G3: 実績 | H3: 差額 | I3: 差額(率) | J3: 部門別予算 | K3: 実績 | L3: 差額 | M3: 差額(率) | N3: 部門別予算 | O3: 実績 | P3: 差額 | Q3: 差額(率) | R3: 部門別予算 | S3: 実績 | T3: 差額 | U3: 差額(率)
A4: 売上高 | B4: =SUM(start:end!B4:B4) -> 97380463 | C4: =SUM(start:end!C4:C4) -> 0 | D4: =SUM(start:end!D4:D4) -> 97380463 | E4: =IFERROR(C4/B4,"-") -> 0 | F4: =SUM(start:end!F4:F4) -> 0 | G4: =SUM(start:end!G4:G4) -> 25572530 | H4: =SUM(start:end!H4:H4) -> 134921430 | I4: =IFERROR(G4/F4,"-") -> - | J4: =SUM(start:end!J4:J4) -> 134880812 | K4: =SUM(start:end!K4:K4) -> 31732150 | L4: =SUM(start:end!L4:L4) -> 0 | M4: =IFERROR(K4/J4,"-") -> 0.23526067 | N4: =SUM(start:end!N4:N4) -> 12532518 | O4: =SUM(start:end!O4:O4) -> 81236 | P4: =SUM(start:end!P4:P4) -> 12491900 | Q4: =IFERROR(O4/N4,"-") -> 0.0064820174 | R4: =SUM(start:end!R4:R4) -> 0 | S4: =SUM(start:end!S4:S4) -> 122952993 | T4: =SUM(start:end!T4:T4) -> 166612962 | U4: =IFERROR(S4/R4,"-") -> -
A5: 売上高 | B5: =SUM(start:end!B5:B5) -> 97380463 | C5: =SUM(start:end!C5:C5) -> 0 | D5: =SUM(start:end!D5:D5) -> 97380463 | E5: =IFERROR(C5/B5,"-") -> 0 | F5: =SUM(start:end!F5:F5) -> 0 | G5: =SUM(start:end!G5:G5) -> 25572530 | H5: =SUM(start:end!H5:H5) -> 134880812 | I5: =IFERROR(G5/F5,"-") -> - | J5: =SUM(start:end!J5:J5) -> 134880812 | K5: =SUM(start:end!K5:K5) -> 31732150 | L5: =SUM(start:end!L5:L5) -> 0 | M5: =IFERROR(K5/J5,"-") -> 0.23526067 | N5: =SUM(start:end!N5:N5) -> -708100 | O5: =SUM(start:end!O5:O5) -> 0 | P5: =SUM(start:end!P5:P5) -> -708100 | Q5: =IFERROR(O5/N5,"-") -> 0 | R5: =SUM(start:end!R5:R5) -> 0 | S5: =SUM(start:end!S5:S5) -> 122952993 | T5: =SUM(start:end!T5:T5) -> 166612962 | U5: =IFERROR(S5/R5,"-") -> -
A6: 賃料収入 | B6: =SUM(start:end!B6:B6) -> 0 | C6: =SUM(start:end!C6:C6) -> 570000 | D6: =SUM(start:end!D6:D6) -> 570000 | E6: =IFERROR(C6/B6,"-") -> - | F6: =SUM(start:end!F6:F6) -> 570000 | G6: =SUM(start:end!G6:G6) -> 570000 | H6: =SUM(start:end!H6:H6) -> 570000 | I6: =IFERROR(G6/F6,"-") -> 1 | J6: =SUM(start:end!J6:J6) -> 570000 | K6: =SUM(start:end!K6:K6) -> 570000 | L6: =SUM(start:end!L6:L6) -> 570000 | M6: =IFERROR(K6/J6,"-") -> 1 | N6: =SUM(start:end!N6:N6) -> 13770000 | O6: =SUM(start:end!O6:O6) -> 6840000 | P6: =SUM(start:end!P6:P6) -> 13200000 | Q6: =IFERROR(O6/N6,"-") -> 0.49673203 | R6: =SUM(start:end!R6:R6) -> 0 | S6: =SUM(start:end!S6:S6) -> 0 | T6: =SUM(start:end!T6:T6) -> 0 | U6: =IFERROR(S6/R6,"-") -> -
A7: 売上原価 | B7: =SUM(start:end!B7:B7) -> 0 | C7: =SUM(start:end!C7:C7) -> 840000 | D7: =SUM(start:end!D7:D7) -> 840000 | E7: =IFERROR(C7/B7,"-") -> - | F7: =SUM(start:end!F7:F7) -> 840000 | G7: =SUM(start:end!G7:G7) -> 840000 | H7: =SUM(start:end!H7:H7) -> 840000 | I7: =IFERROR(G7/F7,"-") -> 1 | J7: =SUM(start:end!J7:J7) -> 840000 | K7: =SUM(start:end!K7:K7) -> 840000 | L7: =SUM(start:end!L7:L7) -> 840000 | M7: =IFERROR(K7/J7,"-") -> 1 | N7: =SUM(start:end!N7:N7) -> 840000 | O7: =SUM(start:end!O7:O7) -> 10080000 | P7: =SUM(start:end!P7:P7) -> 0 | Q7: =IFERROR(O7/N7,"-") -> 12 | R7: =SUM(start:end!R7:R7) -> 0 | S7: =SUM(start:end!S7:S7) -> 0 | T7: =SUM(start:end!T7:T7) -> 0 | U7: =IFERROR(S7/R7,"-") -> -
A8: 売上総利益 | B8: =SUM(start:end!B8:B8) -> 97380463 | C8: =SUM(start:end!C8:C8) -> 0 | D8: =SUM(start:end!D8:D8) -> 97380463 | E8: =IFERROR(C8/B8,"-") -> 0 | F8: =SUM(start:end!F8:F8) -> 0 | G8: =SUM(start:end!G8:G8) -> 25572530 | H8: =SUM(start:end!H8:H8) -> 135565812 | I8: =IFERROR(G8/F8,"-") -> - | J8: =SUM(start:end!J8:J8) -> 135565812 | K8: =SUM(start:end!K8:K8) -> 32417150 | L8: =SUM(start:end!L8:L8) -> 685000 | M8: =IFERROR(K8/J8,"-") -> 0.23912482 | N8: =SUM(start:end!N8:N8) -> 13176900 | O8: =SUM(start:end!O8:O8) -> 4795000 | P8: =SUM(start:end!P8:P8) -> 12491900 | Q8: =IFERROR(O8/N8,"-") -> 0.36389439 | R8: =SUM(start:end!R8:R8) -> 0 | S8: =SUM(start:end!S8:S8) -> 122952993 | T8: =SUM(start:end!T8:T8) -> 166612962 | U8: =IFERROR(S8/R8,"-") -> -
A9: 販売費及び一般管理費 | B9: =SUM(start:end!B9:B9) -> 84749341 | C9: =SUM(start:end!C9:C9) -> -6553888.5 | D9: =SUM(start:end!D9:D9) -> 78195452 | E9: =IFERROR(C9/B9,"-") -> -0.077332619 | F9: =SUM(start:end!F9:F9) -> -2622262.2 | G9: =SUM(start:end!G9:G9) -> 18729561 | H9: =SUM(start:end!H9:H9) -> 119830678 | I9: =IFERROR(G9/F9,"-") -> -7.1425201 | J9: =SUM(start:end!J9:J9) -> 1.4163174e+08 | K9: =SUM(start:end!K9:K9) -> 21681104 | L9: =SUM(start:end!L9:L9) -> -3779610.8 | M9: =IFERROR(K9/J9,"-") -> 0.15308082 | N9: =SUM(start:end!N9:N9) -> 94987730 | O9: =SUM(start:end!O9:O9) -> -46015868 | P9: =SUM(start:end!P9:P9) -> 47311862 | Q9: =IFERROR(O9/N9,"-") -> -0.48444013 | R9: =SUM(start:end!R9:R9) -> -9176150.8 | S9: =SUM(start:end!S9:S9) -> 96925013 | T9: =SUM(start:end!T9:T9) -> 141511782 | U9: =IFERROR(S9/R9,"-") -> -10.562709
A10: 人件費 | B10: =SUM(start:end!B10:B10) -> 42303396 | C10: =SUM(start:end!C10:C10) -> 93850.5 | D10: =SUM(start:end!D10:D10) -> 42397246 | E10: =IFERROR(C10/B10,"-") -> 0.0022185098 | F10: =SUM(start:end!F10:F10) -> 93850.5 | G10: =SUM(start:end!G10:G10) -> 6603533.5 | H10: =SUM(start:end!H10:H10) -> 32736276 | I10: =IFERROR(G10/F10,"-") -> 70.362262 | J10: =SUM(start:end!J10:J10) -> 64586154 | K10: =SUM(start:end!K10:K10) -> 12129152 | L10: =SUM(start:end!L10:L10) -> 93850.5 | M10: =IFERROR(K10/J10,"-") -> 0.18779803 | N10: =SUM(start:end!N10:N10) -> 45186140 | O10: =SUM(start:end!O10:O10) -> -30723672 | P10: =SUM(start:end!P10:P10) -> 13242411 | Q10: =IFERROR(O10/N10,"-") -> -0.67993576 | R10: =SUM(start:end!R10:R10) -> 0 | S10: =SUM(start:end!S10:S10) -> 48813079 | T10: =SUM(start:end!T10:T10) -> 44677727 | U10: =IFERROR(S10/R10,"-") -> -
A11: 役員報酬 | B11: =SUM(start:end!B11:B11) -> 0 | C11: =SUM(start:end!C11:C11) -> 138306 | D11: =SUM(start:end!D11:D11) -> 138306 | E11: =IFERROR(C11/B11,"-") -> - | F11: =SUM(start:end!F11:F11) -> 138306 | G11: =SUM(start:end!G11:G11) -> 138306 | H11: =SUM(start:end!H11:H11) -> 138306 | I11: =IFERROR(G11/F11,"-") -> 1 | J11: =SUM(start:end!J11:J11) -> 12138306 | K11: =SUM(start:end!K11:K11) -> 138306 | L11: =SUM(start:end!L11:L11) -> 138306 | M11: =IFERROR(K11/J11,"-") -> 0.011394176 | N11: =SUM(start:end!N11:N11) -> 12138306 | O11: =SUM(start:end!O11:O11) -> -10340328 | P11: =SUM(start:end!P11:P11) -> 0 | Q11: =IFERROR(O11/N11,"-") -> -0.85187571 | R11: =SUM(start:end!R11:R11) -> 0 | S11: =SUM(start:end!S11:S11) -> 0 | T11: =SUM(start:end!T11:T11) -> 0 | U11: =IFERROR(S11/R11,"-") -> -
A12: 給料手当 | B12: =SUM(start:end!B12:B12) -> 35873203 | C12: =SUM(start:end!C12:C12) -> 0 | D12: =SUM(start:end!D12:D12) -> 35873203 | E12: =IFERROR(C12/B12,"-") -> 0 | F12: =SUM(start:end!F12:F12) -> 0 | G12: =SUM(start:end!G12:G12) -> 5460000 | H12: =SUM(start:end!H12:H12) -> 28297118 | I12: =IFERROR(G12/F12,"-") -> - | J12: =SUM(start:end!J12:J12) -> 45217118 | K12: =SUM(start:end!K12:K12) -> 10582785 | L12: =SUM(start:end!L12:L12) -> 112785.25 | M12: =IFERROR(K12/J12,"-") -> 0.23404378 | N12: =SUM(start:end!N12:N12) -> 27666526 | O12: =SUM(start:end!O12:O12) -> -16130503 | P12: =SUM(start:end!P12:P12) -> 10633741 | Q12: =IFERROR(O12/N12,"-") -> -0.5830332 | R12: =SUM(start:end!R12:R12) -> 0 | S12: =SUM(start:end!S12:S12) -> 41333203 | T12: =SUM(start:end!T12:T12) -> 38654333 | U12: =IFERROR(S12/R12,"-") -> -
A13: 法定福利費 | B13: =SUM(start:end!B13:B13) -> 0 | C13: =SUM(start:end!C13:C13) -> 0 | D13: =SUM(start:end!D13:D13) -> 0 | E13: =IFERROR(C13/B13,"-") -> - | F13: =SUM(start:end!F13:F13) -> 0 | G13: =SUM(start:end!G13:G13) -> 0 | H13: =SUM(start:end!H13:H13) -> 0 | I13: =IFERROR(G13/F13,"-") -> - | J13: =SUM(start:end!J13:J13) -> 0 | K13: =SUM(start:end!K13:K13) -> 0 | L13: =SUM(start:end!L13:L13) -> 68329.75 | M13: =IFERROR(K13/J13,"-") -> - | N13: =SUM(start:end!N13:N13) -> 68329.75 | O13: =SUM(start:end!O13:O13) -> 204989.25 | P13: =SUM(start:end!P13:P13) -> 0 | Q13: =IFERROR(O13/N13,"-") -> 3 | R13: =SUM(start:end!R13:R13) -> 0 | S13: =SUM(start:end!S13:S13) -> 0 | T13: =SUM(start:end!T13:T13) -> 0 | U13: =IFERROR(S13/R13,"-") -> -
A14: 退職共済金 | B14: =SUM(start:end!B14:B14) -> 5806193 | C14: =SUM(start:end!C14:C14) -> 0 | D14: =SUM(start:end!D14:D14) -> 5806193 | E14: =IFERROR(C14/B14,"-") -> 0 | F14: =SUM(start:end!F14:F14) -> 0 | G14: =SUM(start:end!G14:G14) -> 941683 | H14: =SUM(start:end!H14:H14) -> 4273092 | I14: =IFERROR(G14/F14,"-") -> - | J14: =SUM(start:end!J14:J14) -> 7058970 | K14: =SUM(start:end!K14:K14) -> 1481302 | L14: =SUM(start:end!L14:L14) -> 0 | M14: =IFERROR(K14/J14,"-") -> 0.20984676 | N14: =SUM(start:end!N14:N14) -> 5310548 | O14: =SUM(start:end!O14:O14) -> -2754547 | P14: =SUM(start:end!P14:P14) -> 2524670 | Q14: =IFERROR(O14/N14,"-") -> -0.51869355 | R14: =SUM(start:end!R14:R14) -> 0 | S14: =SUM(start:end!S14:S14) -> 6747876 | T14: =SUM(start:end!T14:T14) -> 5754394 | U14: =IFERROR(S14/R14,"-") -> -
A15: 福利厚生費 | B15: =SUM(start:end!B15:B15) -> 624000 | C15: =SUM(start:end!C15:C15) -> 0 | D15: =SUM(start:end!D15:D15) -> 624000 | E15: =IFERROR(C15/B15,"-") -> 0 | F15: =SUM(start:end!F15:F15) -> 27847 | G15: =SUM(start:end!G15:G15) -> 108000 | H15: =SUM(start:end!H15:H15) -> 185000 | I15: =IFERROR(G15/F15,"-") -> 3.8783352 | J15: =SUM(start:end!J15:J15) -> 329000 | K15: =SUM(start:end!K15:K15) -> 84000 | L15: =SUM(start:end!L15:L15) -> 0 | M15: =IFERROR(K15/J15,"-") -> 0.25531915 | N15: =SUM(start:end!N15:N15) -> 228000 | O15: =SUM(start:end!O15:O15) -> -116153 | P15: =SUM(start:end!P15:P15) -> 84000 | Q15: =IFERROR(O15/N15,"-") -> -0.50944298 | R15: =SUM(start:end!R15:R15) -> 0 | S15: =SUM(start:end!S15:S15) -> 732000 | T15: =SUM(start:end!T15:T15) -> 269000 | U15: =IFERROR(S15/R15,"-") -> -
... A52: 当期純利益 | B52: =SUM(start:end!B52:B52) -> 0 | C52: =SUM(start:end!C52:C52) -> 0 | D52: =SUM(start:end!D52:D52) -> 0 | E52: =IFERROR(C52/B52,"-") -> - | F52: =SUM(start:end!F52:F52) -> 0 | G52: =SUM(start:end!G52:G52) -> 0 | H52: =SUM(start:end!H52:H52) -> 0 | I52: =IFERROR(G52/F52,"-") -> - | J52: =SUM(start:end!J52:J52) -> 0 | K52: =SUM(start:end!K52:K52) -> 0 | L52: =SUM(start:end!L52:L52) -> 0 | M52: =IFERROR(K52/J52,"-") -> - | N52: =SUM(start:end!N52:N52) -> 0 | O52: =SUM(start:end!O52:O52) -> 0 | P52: =SUM(start:end!P52:P52) -> 0 | Q52: =IFERROR(O52/N52,"-") -> - | R52: =SUM(start:end!R52:R52) -> 0 | S52: =SUM(start:end!S52:S52) -> 0 | T52: =SUM(start:end!T52:T52) -> 0 | U52: =IFERROR(S52/R52,"-") -> -

Sheet 202208-12分_検証用2_diff
B2: 企画制作部門 | F2: デジタル制作部門 | J2: ソリューション開発部門 | N2: 共通部門 | R2: 合計
B3: 部門別予算 | C3: 実績 | D3: 差額 | E3: 差額(率) | F3: 部門別予算 | G3: 実績 | H3: 差額 | I3: 差額(率) | J3: 部門別予算 | K3: 実績 | L3: 差額 | M3: 差額(率) | N3: 部門別予算 | O3: 実績 | P3: 差額 | Q3: 差額(率) | R3: 部門別予算 | S3: 実績 | T3: 差額 | U3: 差額(率)
A4: 売上高 | B4: =#REF!-'202208-12分_検証用1_関数積算'!B4 -> #REF! | C4: =#REF!-'202208-12分_検証用1_関数積算'!C4 -> #REF! | D4: =#REF!-'202208-12分_検証用1_関数積算'!D4 -> #REF! | E4: =#REF!-'202208-12分_検証用1_関数積算'!E4 -> #REF! | F4: =#REF!-'202208-12分_検証用1_関数積算'!F4 -> #REF! | G4: =#REF!-'202208-12分_検証用1_関数積算'!G4 -> #REF! | H4: =#REF!-'202208-12分_検証用1_関数積算'!H4 -> #REF! | I4: =#REF!-'202208-12分_検証用1_関数積算'!I4 -> #REF! | ... U4: =#REF!-'202208-12分_検証用1_関数積算'!U4 -> #REF!
A5: 売上高 | B5: =#REF!-'202208-12分_検証用1_関数積算'!B5 -> #REF! | C5: =#REF!-'202208-12分_検証用1_関数積算'!C5 -> #REF! | D5: =#REF!-'202208-12分_検証用1_関数積算'!D5 -> #REF! | E5: =#REF!-'202208-12分_検証用1_関数積算'!E5 -> #REF! | F5: =#REF!-'202208-12分_検証用1_関数積算'!F5 -> #REF! | G5: =#REF!-'202208-12分_検証用1_関数積算'!G5 -> #REF! | H5: =#REF!-'202208-12分_検証用1_関数積算'!H5 -> #REF! | I5: =#REF!-'202208-12分_検証用1_関数積算'!I5 -> #REF! | ... U5: =#REF!-'202208-12分_検証用1_関数積算'!U5 -> #REF!
A6: 賃料収入 | B6: =#REF!-'202208-12分_検証用1_関数積算'!B6 -> #REF! | C6: =#REF!-'202208-12分_検証用1_関数積算'!C6 -> #REF! | D6: =#REF!-'202208-12分_検証用1_関数積算'!D6 -> #REF! | E6: =#REF!-'202208-12分_検証用1_関数積算'!E6 -> #REF! | F6: =#REF!-'202208-12分_検証用1_関数積算'!F6 -> #REF! | G6: =#REF!-'202208-12分_検証用1_関数積算'!G6 -> #REF! | H6: =#REF!-'202208-12分_検証用1_関数積算'!H6 -> #REF! | I6: =#REF!-'202208-12分_検証用1_関数積算'!I6 -> #REF! | ... U6: =#REF!-'202208-12分_検証用1_関数積算'!U6 -> #REF!
A7: 売上原価 | B7: =#REF!-'202208-12分_検証用1_関数積算'!B7 -> #REF! | C7: =#REF!-'202208-12分_検証用1_関数積算'!C7 -> #REF! | D7: =#REF!-'202208-12分_検証用1_関数積算'!D7 -> #REF! | E7: =#REF!-'202208-12分_検証用1_関数積算'!E7 -> #REF! | F7: =#REF!-'202208-12分_検証用1_関数積算'!F7 -> #REF! | G7: =#REF!-'202208-12分_検証用1_関数積算'!G7 -> #REF! | H7: =#REF!-'202208-12分_検証用1_関数積算'!H7 -> #REF! | I7: =#REF!-'202208-12分_検証用1_関数積算'!I7 -> #REF! | ... U7: =#REF!-'202208-12分_検証用1_関数積算'!U7 -> #REF!
A8: 売上総利益 | B8: =#REF!-'202208-12分_検証用1_関数積算'!B8 -> #REF! | C8: =#REF!-'202208-12分_検証用1_関数積算'!C8 -> #REF! | D8: =#REF!-'202208-12分_検証用1_関数積算'!D8 -> #REF! | E8: =#REF!-'202208-12分_検証用1_関数積算'!E8 -> #REF! | F8: =#REF!-'202208-12分_検証用1_関数積算'!F8 -> #REF! | G8: =#REF!-'202208-12分_検証用1_関数積算'!G8 -> #REF! | H8: =#REF!-'202208-12分_検証用1_関数積算'!H8 -> #REF! | I8: =#REF!-'202208-12分_検証用1_関数積算'!I8 -> #REF! | ... U8: =#REF!-'202208-12分_検証用1_関数積算'!U8 -> #REF!
A9: 販売費及び一般管理費 | B9: =#REF!-'202208-12分_検証用1_関数積算'!B9 -> #REF! | C9: =#REF!-'202208-12分_検証用1_関数積算'!C9 -> #REF! | D9: =#REF!-'202208-12分_検証用1_関数積算'!D9 -> #REF! | E9: =#REF!-'202208-12分_検証用1_関数積算'!E9 -> #REF! | F9: =#REF!-'202208-12分_検証用1_関数積算'!F9 -> #REF! | G9: =#REF!-'202208-12分_検証用1_関数積算'!G9 -> #REF! | H9: =#REF!-'202208-12分_検証用1_関数積算'!H9 -> #REF! | I9: =#REF!-'202208-12分_検証用1_関数積算'!I9 -> #REF! | ... U9: =#REF!-'202208-12分_検証用1_関数積算'!U9 -> #REF!
A10: 人件費 | B10: =#REF!-'202208-12分_検証用1_関数積算'!B10 -> #REF! | C10: =#REF!-'202208-12分_検証用1_関数積算'!C10 -> #REF! | D10: =#REF!-'202208-12分_検証用1_関数積算'!D10 -> #REF! | E10: =#REF!-'202208-12分_検証用1_関数積算'!E10 -> #REF! | F10: =#REF!-'202208-12分_検証用1_関数積算'!F10 -> #REF! | G10: =#REF!-'202208-12分_検証用1_関数積算'!G10 -> #REF! | H10: =#REF!-'202208-12分_検証用1_関数積算'!H10 -> #REF! | I10: =#REF!-'202208-12分_検証用1_関数積算'!I10 -> #REF! | ... U10: =#REF!-'202208-12分_検証用1_関数積算'!U10 -> #REF!
A11: 役員報酬 | B11: =#REF!-'202208-12分_検証用1_関数積算'!B11 -> #REF! | C11: =#REF!-'202208-12分_検証用1_関数積算'!C11 -> #REF! | D11: =#REF!-'202208-12分_検証用1_関数積算'!D11 -> #REF! | E11: =#REF!-'202208-12分_検証用1_関数積算'!E11 -> #REF! | F11: =#REF!-'202208-12分_検証用1_関数積算'!F11 -> #REF! | G11: =#REF!-'202208-12分_検証用1_関数積算'!G11 -> #REF! | H11: =#REF!-'202208-12分_検証用1_関数積算'!H11 -> #REF! | I11: =#REF!-'202208-12分_検証用1_関数積算'!I11 -> #REF! | ... U11: =#REF!-'202208-12分_検証用1_関数積算'!U11 -> #REF!
A12: 給料手当 | B12: =#REF!-'202208-12分_検証用1_関数積算'!B12 -> #REF! | C12: =#REF!-'202208-12分_検証用1_関数積算'!C12 -> #REF! | D12: =#REF!-'202208-12分_検証用1_関数積算'!D12 -> #REF! | E12: =#REF!-'202208-12分_検証用1_関数積算'!E12 -> #REF! | F12: =#REF!-'202208-12分_検証用1_関数積算'!F12 -> #REF! | G12: =#REF!-'202208-12分_検証用1_関数積算'!G12 -> #REF! | H12: =#REF!-'202208-12分_検証用1_関数積算'!H12 -> #REF! | I12: =#REF!-'202208-12分_検証用1_関数積算'!I12 -> #REF! | ... U12: =#REF!-'202208-12分_検証用1_関数積算'!U12 -> #REF!
A13: 法定福利費 | B13: =#REF!-'202208-12分_検証用1_関数積算'!B13 -> #REF! | C13: =#REF!-'202208-12分_検証用1_関数積算'!C13 -> #REF! | D13: =#REF!-'202208-12分_検証用1_関数積算'!D13 -> #REF! | E13: =#REF!-'202208-12分_検証用1_関数積算'!E13 -> #REF! | F13: =#REF!-'202208-12分_検証用1_関数積算'!F13 -> #REF! | G13: =#REF!-'202208-12分_検証用1_関数積算'!G13 -> #REF! | H13: =#REF!-'202208-12分_検証用1_関数積算'!H13 -> #REF! | I13: =#REF!-'202208-12分_検証用1_関数積算'!I13 -> #REF! | ... U13: =#REF!-'202208-12分_検証用1_関数積算'!U13 -> #REF!
A14: 退職共済金 | B14: =#REF!-'202208-12分_検証用1_関数積算'!B14 -> #REF! | C14: =#REF!-'202208-12分_検証用1_関数積算'!C14 -> #REF! | D14: =#REF!-'202208-12分_検証用1_関数積算'!D14 -> #REF! | E14: =#REF!-'202208-12分_検証用1_関数積算'!E14 -> #REF! | F14: =#REF!-'202208-12分_検証用1_関数積算'!F14 -> #REF! | G14: =#REF!-'202208-12分_検証用1_関数積算'!G14 -> #REF! | H14: =#REF!-'202208-12分_検証用1_関数積算'!H14 -> #REF! | I14: =#REF!-'202208-12分_検証用1_関数積算'!I14 -> #REF! | ... U14: =#REF!-'202208-12分_検証用1_関数積算'!U14 -> #REF!
A15: 福利厚生費 | B15: =#REF!-'202208-12分_検証用1_関数積算'!B15 -> #REF! | C15: =#REF!-'202208-12分_検証用1_関数積算'!C15 -> #REF! | D15: =#REF!-'202208-12分_検証用1_関数積算'!D15 -> #REF! | E15: =#REF!-'202208-12分_検証用1_関数積算'!E15 -> #REF! | F15: =#REF!-'202208-12分_検証用1_関数積算'!F15 -> #REF! | G15: =#REF!-'202208-12分_検証用1_関数積算'!G15 -> #REF! | H15: =#REF!-'202208-12分_検証用1_関数積算'!H15 -> #REF! | I15: =#REF!-'202208-12分_検証用1_関数積算'!I15 -> #REF! | ... U15: =#REF!-'202208-12分_検証用1_関数積算'!U15 -> #REF!
... A52: 当期純利益 | B52: =#REF!-'202208-12分_検証用1_関数積算'!B52 -> #REF! | C52: =#REF!-'202208-12分_検証用1_関数積算'!C52 -> #REF! | D52: =#REF!-'202208-12分_検証用1_関数積算'!D52 -> #REF! | E52: =#REF!-'202208-12分_検証用1_関数積算'!E52 -> #REF! | F52: =#REF!-'202208-12分_検証用1_関数積算'!F52 -> #REF! | G52: =#REF!-'202208-12分_検証用1_関数積算'!G52 -> #REF! | H52: =#REF!-'202208-12分_検証用1_関数積算'!H52 -> #REF! | I52: =#REF!-'202208-12分_検証用1_関数積算'!I52 -> #REF! | ... U52: =#REF!-'202208-12分_検証用1_関数積算'!U52 -> #REF!
