Workbook

Sheet ルール
A1: 案件マスター 運用ルール（株式会社鶴岡中央青果）
B3: 1. 本ファイルが唯一の数値ソース。企業概要書・評価書の数字は必ず本ファイルから転記する（パワポに直接打たない）。
B4: 2. 文字は「游ゴシック」、数字は「Arial」、備考等の細かい文章は「游ゴシック Medium」。タイトル・合計欄は太字。
B5: 3. 数字は円単位で入力する。表示は千円単位に設定済み（千円で入力すると1000倍ずれる）。
B6: 4. 未確認事項は推測で埋めず「要確認」と記載し、「その他」シートに集約する。推測を書く場合は「推察」「想定」「（仮説）」と明記。
B7: 5. 転記元：第51〜53期決算報告書（勘定科目内訳明細書・法人税申告書・法人事業概況説明書を含む）、2026年7月試算表、
B8: 職員名簿（2026/9/1現在）、履歴事項全部証明書（2026/9/10取得）、R8年度固定資産税課税明細書。
B9: 6. 進行期（G列）は2026年4月〜7月の4か月累計。7〜8月が繁忙期（だだちゃ豆・メロン等）のため単純年換算しない。
B10: 7. 作成日：2026年9月23日 初版

Sheet 財務入力→

Sheet BS(借方)
A1: 貸借対照表（資産の部）
A2: 単位：千円（入力は円）
B4: 勘定科目 | C4: 2024年3月期 (第51期) | D4: 2025年3月期 (第52期) | E4: 2026年3月期 (第53期) | F4: （4期目） | G4: 2026年7月 (試算表)
B5: 【流動資産】
B6: 現金及び預金 | C6: 339552632 | D6: 259719301 | E6: 210887077 | G6: 162087296
B7: 売掛金 | C7: 21171056 | D7: 21896538 | E7: 19608899 | G7: 40586984
B8: 資材肥料売掛金 | C8: 1352474 | D8: 1269087 | E8: 1227419 | G8: 2365307
B9: 棚卸資産 | C9: 9859795 | D9: 15443609 | E9: 14596695 | G9: 36647736
B10: 立替金 | C10: 96860 | D10: 6400 | E10: 0 | G10: 0
B11: 未収入金 | C11: 3684415 | D11: 3905410 | E11: 3011112 | G11: 2664958
B12: 前払費用 | C12: 108779 | D12: 96162 | E12: 83575 | G12: 101324
B13: 仮払金 | C13: 0 | D13: 0 | E13: 493135 | G13: 0
B14: 仮払税金等 | C14: 0 | D14: 998300 | E14: 0 | G14: 0
B15: 貸倒引当金 | C15: -237000 | D15: -234000 | E15: -203000 | G15: -203000
B16: 流動資産計 | C16: =SUM(C6:C15) -> 375589011 | D16: =SUM(D6:D15) -> 303100807 | E16: =SUM(E6:E15) -> 249704912 | F16: =SUM(F6:F15) -> 0 | G16: =SUM(G6:G15) -> 244250605
B17: 【有形固定資産】
B18: 建物 | C18: 101161720 | D18: 95851274 | E18: 92065694 | G18: 92065694
B19: 建物付属設備 | C19: 15416918 | D19: 13503020 | E19: 11399836 | G19: 11399836
B20: 構築物 | C20: 382601 | D20: 333498 | E20: 284395 | G20: 284395
B21: 機械装置 | C21: 133566 | D21: 2 | E21: 2 | G21: 2
B22: 車両運搬具 | C22: 5837529 | D22: 1281878 | E22: 15 | G22: 15
B23: 工具器具備品 | C23: 287873 | D23: 153209 | E23: 18546 | G23: 18546
B24: 土地 | C24: 93137240 | D24: 93137240 | E24: 93137240 | G24: 93137240
B25: 減価償却累計額（期中計上分） | C25: 0 | D25: 0 | E25: 0 | G25: -2436000
B26: 有形固定資産計 | C26: =SUM(C18:C25) -> 216357447 | D26: =SUM(D18:D25) -> 204260121 | E26: =SUM(E18:E25) -> 196905728 | F26: =SUM(F18:F25) -> 0 | G26: =SUM(G18:G25) -> 194469728
B27: 【無形固定資産】
B28: 電話加入権 | C28: 2155595 | D28: 2155595 | E28: 2155595 | G28: 2155595
B29: ソフトウェア | C29: 715000 | D29: 543400 | E29: 371800 | G29: 371800
B30: 無形固定資産計 | C30: =SUM(C28:C29) -> 2870595 | D30: =SUM(D28:D29) -> 2698995 | E30: =SUM(E28:E29) -> 2527395 | F30: =SUM(F28:F29) -> 0 | G30: =SUM(G28:G29) -> 2527395
B31: 【投資その他の資産】
B32: 投資有価証券 | C32: 3250000 | D32: 3250000 | E32: 2600000 | G32: 1600000
B33: 出資金 | C33: 75000 | D33: 75000 | E33: 75000 | G33: 75000
B34: 長期前払費用 | C34: 397411 | D34: 74500 | E34: 74500 | G34: 74500
B35: 保証金 | C35: 32002569 | D35: 33002569 | E35: 33302569 | G35: 33302569
B36: 事業保険積立金 | C36: 21161692 | D36: 20900138 | E36: 0 | G36: 0
B37: 投資その他の資産計 | C37: =SUM(C32:C36) -> 56886672 | D37: =SUM(D32:D36) -> 57302207 | E37: =SUM(E32:E36) -> 36052069 | F37: =SUM(F32:F36) -> 0 | G37: =SUM(G32:G36) -> 35052069
B38: 固定資産計 | C38: =C26+C30+C37 -> 276114714 | D38: =D26+D30+D37 -> 264261323 | E38: =E26+E30+E37 -> 235485192 | F38: =F26+F30+F37 -> 0 | G38: =G26+G30+G37 -> 232049192
B39: 繰延資産 | C39: 243834 | D39: 166834 | E39: 0 | G39: 0
B40: 資産の部合計 | C40: =C16+C38+C39 -> 651947559 | D40: =D16+D38+D39 -> 567528964 | E40: =E16+E38+E39 -> 485190104 | F40: =F16+F38+F39 -> 0 | G40: =G16+G38+G39 -> 476299797
B42: 決算書記載の資産合計 | C42: 651947559 | D42: 567528964 | E42: 485190104 | G42: 476299797
...

Sheet BS (貸方)
A1: 貸借対照表（負債・純資産の部）
A2: 単位：千円（入力は円）
B4: 勘定科目 | C4: 2024年3月期 (第51期) | D4: 2025年3月期 (第52期) | E4: 2026年3月期 (第53期) | F4: （4期目） | G4: 2026年7月 (試算表)
B5: 【流動負債】
B6: 買掛金 | C6: 18127739 | D6: 19954920 | E6: 26349122 | G6: 32102162
B7: 未払金 | C7: 10198849 | D7: 7302614 | E7: 6630301 | G7: 3999712
B8: 仮受金 | C8: 0 | D8: 0 | E8: 0 | G8: 5641499
B9: 預り金 | C9: 504234 | D9: 557594 | E9: 281300 | G9: 196956
B10: 未払法人税等 | C10: 2308000 | D10: 33900 | E10: 1851300 | G10: 0
B11: 未払消費税 | C11: 2970400 | D11: 1606700 | E11: 2167500 | G11: 3760000
B12: 流動負債計 | C12: =SUM(C6:C11) -> 34109222 | D12: =SUM(D6:D11) -> 29455728 | E12: =SUM(E6:E11) -> 37279523 | F12: =SUM(F6:F11) -> 0 | G12: =SUM(G6:G11) -> 45700329
B13: 【固定負債】
B14: 長期借入金 | C14: 514690000 | D14: 434046000 | E14: 361058000 | G14: 337862000
B15: 預り保証金 | C15: 10320000 | D15: 10270000 | E15: 8980000 | G15: 8980000
B16: 固定負債計 | C16: =SUM(C14:C15) -> 525010000 | D16: =SUM(D14:D15) -> 444316000 | E16: =SUM(E14:E15) -> 370038000 | F16: =SUM(F14:F15) -> 0 | G16: =SUM(G14:G15) -> 346842000
B17: 負債の部合計 | C17: =C12+C16 -> 559119222 | D17: =D12+D16 -> 473771728 | E17: =E12+E16 -> 407317523 | F17: =F12+F16 -> 0 | G17: =G12+G16 -> 392542329
B18: 【純資産】
B19: 資本金 | C19: 40000000 | D19: 40000000 | E19: 40000000 | G19: 40000000
B20: 利益準備金 | C20: 1800000 | D20: 2000000 | E20: 2080000 | G20: 2080000
B21: 繰越利益剰余金 | C21: 51028337 | D21: 51757236 | E21: 35792581 | G21: 41677468
B22: 純資産の部合計 | C22: =SUM(C19:C21) -> 92828337 | D22: =SUM(D19:D21) -> 93757236 | E22: =SUM(E19:E21) -> 77872581 | F22: =SUM(F19:F21) -> 0 | G22: =SUM(G19:G21) -> 83757468
B23: 負債・純資産の部合計 | C23: =C17+C22 -> 651947559 | D23: =D17+D22 -> 567528964 | E23: =E17+E22 -> 485190104 | F23: =F17+F22 -> 0 | G23: =G17+G22 -> 476299797
B25: ※2026年7月の買掛金は委託分6,457千円・仕入分25,126千円・資材分519千円の合計。長期借入金は1年内返済予定額を区分していない（要確認）。

Sheet SGA
A1: 販売費及び一般管理費
A2: 単位：千円（入力は円）／売上高比
B4: 勘定科目 | C4: 2024年3月期 (第51期) | D4: 売上比 | E4: 2025年3月期 (第52期) | F4: 売上比 | G4: 2026年3月期 (第53期) | H4: 売上比 | I4: 2026年7月 (試算表) | J4: 売上比
B5: 役員報酬 | C5: 22200000 | D5: =IFERROR(C5/PL!C$10,"") -> 0.01883768 | E5: 22200000 | F5: =IFERROR(E5/PL!E$10,"") -> 0.018782563 | G5: 15360000 | H5: =IFERROR(G5/PL!G$10,"") -> 0.012843956 | I5: 4730000 | J5: =IFERROR(I5/PL!I$10,"") -> 0.011504179
B6: 給料手当 | C6: 73148460 | D6: =IFERROR(C6/PL!C$10,"") -> 0.062069696 | E6: 74179162 | F6: =IFERROR(E6/PL!E$10,"") -> 0.062760124 | G6: 71673365 | H6: =IFERROR(G6/PL!G$10,"") -> 0.059932911 | I6: 19328747 | J6: =IFERROR(I6/PL!I$10,"") -> 0.047010858
B7: 賞与 | C7: 6002150 | D7: =IFERROR(C7/PL!C$10,"") -> 0.0050930891 | E7: 5692500 | F7: =IFERROR(E7/PL!E$10,"") -> 0.0048162044 | G7: 0 | H7: =IFERROR(G7/PL!G$10,"") -> 0 | I7: 0 | J7: =IFERROR(I7/PL!I$10,"") -> 0
B8: 退職金共済掛金 | C8: 3175000 | D8: =IFERROR(C8/PL!C$10,"") -> 0.0026941276 | E8: 3166000 | F8: =IFERROR(E8/PL!E$10,"") -> 0.0026786303 | G8: 3026000 | H8: =IFERROR(G8/PL!G$10,"") -> 0.0025303261 | I8: 769000 | J8: =IFERROR(I8/PL!I$10,"") -> 0.0018703411
B9: 退職金 | C9: 0 | D9: =IFERROR(C9/PL!C$10,"") -> 0 | E9: 356400 | F9: =IFERROR(E9/PL!E$10,"") -> 0.00030153628 | G9: 746960 | H9: =IFERROR(G9/PL!G$10,"") -> 0.00062460423 | I9: 0 | J9: =IFERROR(I9/PL!I$10,"") -> 0
B10: 法定福利費 | C10: 15154087 | D10: =IFERROR(C10/PL!C$10,"") -> 0.012858911 | E10: 14913183 | F10: =IFERROR(E10/PL!E$10,"") -> 0.012617468 | G10: 13295870 | H10: =IFERROR(G10/PL!G$10,"") -> 0.01111794 | I10: 3603031 | J10: =IFERROR(I10/PL!I$10,"") -> 0.0087631951
B11: 福利厚生費 | C11: 594849 | D11: =IFERROR(C11/PL!C$10,"") -> 0.00050475562 | E11: 899852 | F11: =IFERROR(E11/PL!E$10,"") -> 0.00076133003 | G11: 460243 | H11: =IFERROR(G11/PL!G$10,"") -> 0.00038485291 | I11: 95149 | J11: =IFERROR(I11/PL!I$10,"") -> 0.00023141884
B12: 広告宣伝費 | C12: 203020 | D12: =IFERROR(C12/PL!C$10,"") -> 0.00017227143 | E12: 114444 | F12: =IFERROR(E12/PL!E$10,"") -> 9.6826649e-05 | G12: 89300 | H12: =IFERROR(G12/PL!G$10,"") -> 7.4672216e-05 | I12: 10000 | J12: =IFERROR(I12/PL!I$10,"") -> 2.4321731e-05
B13: 旅費交通費 | C13: 44957 | D13: =IFERROR(C13/PL!C$10,"") -> 3.8147998e-05 | E13: 212048 | F13: =IFERROR(E13/PL!E$10,"") -> 0.00017940562 | G13: 78650 | H13: =IFERROR(G13/PL!G$10,"") -> 6.5766739e-05 | I13: 9490 | J13: =IFERROR(I13/PL!I$10,"") -> 2.3081323e-05
B14: 通信費 | C14: 1434812 | D14: =IFERROR(C14/PL!C$10,"") -> 0.0012175013 | E14: 1143086 | F14: =IFERROR(E14/PL!E$10,"") -> 0.00096712092 | G14: 1191701 | H14: =IFERROR(G14/PL!G$10,"") -> 0.00099649445 | I14: 296684 | J14: =IFERROR(I14/PL!I$10,"") -> 0.00072158684
B15: 車両関連費 | C15: 8475295 | D15: =IFERROR(C15/PL!C$10,"") -> 0.0071916618 | E15: 10126052 | F15: =IFERROR(E15/PL!E$10,"") -> 0.0085672615 | G15: 9861597 | H15: =IFERROR(G15/PL!G$10,"") -> 0.0082462183 | I15: 2954932 | J15: =IFERROR(I15/PL!I$10,"") -> 0.0071869061
B16: 運賃 | C16: 27546757 | D16: =IFERROR(C16/PL!C$10,"") -> 0.023374639 | E16: 29493733 | F16: =IFERROR(E16/PL!E$10,"") -> 0.024953509 | G16: 28996599 | H16: =IFERROR(G16/PL!G$10,"") -> 0.024246812 | I16: 8099852 | J16: =IFERROR(I16/PL!I$10,"") -> 0.019700242
... B32: 雑費 | C32: 4521805 | D32: =IFERROR(C32/PL!C$10,"") -> 0.0038369511 | E32: 4393320 | F32: =IFERROR(E32/PL!E$10,"") -> 0.0037170184 | G32: 4689970 | H32: =IFERROR(G32/PL!G$10,"") -> 0.0039217296 | I32: 1266623 | J32: =IFERROR(I32/PL!I$10,"") -> 0.0030806464
B33: 販売費及び一般管理費 計 | C33: =SUM(C5:C32) -> 214823441 | D33: =IFERROR(C33/PL!C$10,"") -> 0.18228717 | E33: =SUM(E5:E32) -> 215718454 | F33: =IFERROR(E33/PL!E$10,"") -> 0.18251105 | G33: =SUM(G5:G32) -> 193151054 | H33: =IFERROR(G33/PL!G$10,"") -> 0.16151195 | I33: =SUM(I5:I32) -> 55896593 | J33: =IFERROR(I33/PL!I$10,"") -> 0.13595019
B34: 決算書記載の販管費計 | C34: 214823441 | E34: 215718454 | G34: 193151054 | I34: 55896593
B35: チェック | C35: =EXACT(C33,C34) -> TRUE | E35: =EXACT(E33,E34) -> TRUE | G35: =EXACT(G33,G34) -> TRUE | I35: =EXACT(I33,I34) -> TRUE
B37: ※消費税等は税込方式のため、納付消費税相当は租税公課（決算）／消費税引当金（試算表）に計上されている。2026/3期は賞与の計上なし（要確認）。

Sheet PL
A1: 損益計算書
A2: 単位：千円（入力は円）／売上高比
B4: 勘定科目 | C4: 2024年3月期 (第51期) | D4: 売上比 | E4: 2025年3月期 (第52期) | F4: 売上比 | G4: 2026年3月期 (第53期) | H4: 売上比 | I4: 2026年7月 (試算表) | J4: 売上比
B5: 商品売上高 | C5: 1179974308 | D5: =IFERROR(C5/C$10,"") -> 1.0012603 | E5: 1183308630 | F5: =IFERROR(E5/E$10,"") -> 1.0011517 | G5: 1197530299 | H5: =IFERROR(G5/G$10,"") -> 1.0013689 | I5: 375960544 | J5: =IFERROR(I5/I$10,"") -> 0.91440112
B6: 資材売上高 | C6: 0 | D6: =IFERROR(C6/C$10,"") -> 0 | E6: 0 | F6: =IFERROR(E6/E$10,"") -> 0 | G6: 0 | H6: =IFERROR(G6/G$10,"") -> 0 | I6: 10820414 | J6: =IFERROR(I6/I$10,"") -> 0.02631712
B7: センター費収入 | C7: 0 | D7: =IFERROR(C7/C$10,"") -> 0 | E7: 0 | F7: =IFERROR(E7/E$10,"") -> 0 | G7: 0 | H7: =IFERROR(G7/G$10,"") -> 0 | I7: 12272629 | J7: =IFERROR(I7/I$10,"") -> 0.029849158
B8: 委託手数料収入 | C8: 0 | D8: =IFERROR(C8/C$10,"") -> 0 | E8: 0 | F8: =IFERROR(E8/E$10,"") -> 0 | G8: 0 | H8: =IFERROR(G8/G$10,"") -> 0 | I8: 12563500 | J8: =IFERROR(I8/I$10,"") -> 0.030556607
B9: 売上割戻 | C9: -1485210 | D9: =IFERROR(C9/C$10,"") -> -0.0012602662 | E9: -1361290 | F9: =IFERROR(E9/E$10,"") -> -0.0011517349 | G9: -1637030 | H9: =IFERROR(G9/G$10,"") -> -0.0013688763 | I9: -462140 | J9: =IFERROR(I9/I$10,"") -> -0.0011240045
B10: 売上高 | C10: =SUM(C5:C9) -> 1178489098 | D10: =IFERROR(C10/C$10,"") -> 1 | E10: =SUM(E5:E9) -> 1181947340 | F10: =IFERROR(E10/E$10,"") -> 1 | G10: =SUM(G5:G9) -> 1195893269 | H10: =IFERROR(G10/G$10,"") -> 1 | I10: =SUM(I5:I9) -> 411154947 | J10: =IFERROR(I10/I$10,"") -> 1
B11: 期首棚卸高 | C11: 15470384 | D11: =IFERROR(C11/C$10,"") -> 0.013127303 | E11: 9859795 | F11: =IFERROR(E11/E$10,"") -> 0.0083419918 | G11: 15443609 | H11: =IFERROR(G11/G$10,"") -> 0.012913869 | I11: 14596695 | J11: =IFERROR(I11/I$10,"") -> 0.035501689
B12: 当期仕入高 | C12: 953298320 | D12: =IFERROR(C12/C$10,"") -> 0.80891569 | E12: 976235640 | F12: =IFERROR(E12/E$10,"") -> 0.82595527 | G12: 996035389 | H12: =IFERROR(G12/G$10,"") -> 0.83287984 | I12: 371992415 | J12: =IFERROR(I12/I$10,"") -> 0.90474994
B13: 期末棚卸高 | C13: -9859795 | D13: =IFERROR(C13/C$10,"") -> -0.0083664711 | E13: -15443609 | F13: =IFERROR(E13/E$10,"") -> -0.013066241 | G13: -14596695 | H13: =IFERROR(G13/G$10,"") -> -0.012205684 | I13: -36647736 | J13: =IFERROR(I13/I$10,"") -> -0.089133637
B14: 売上原価 | C14: =SUM(C11:C13) -> 958908909 | D14: =IFERROR(C14/C$10,"") -> 0.81367652 | E14: =SUM(E11:E13) -> 970651826 | F14: =IFERROR(E14/E$10,"") -> 0.82123103 | G14: =SUM(G11:G13) -> 996882303 | H14: =IFERROR(G14/G$10,"") -> 0.83358802 | I14: =SUM(I11:I13) -> 349941374 | J14: =IFERROR(I14/I$10,"") -> 0.85111799
B15: 売上総利益 | C15: =C10-C14 -> 219580189 | D15: =IFERROR(C15/C$10,"") -> 0.18632348 | E15: =E10-E14 -> 211295514 | F15: =IFERROR(E15/E$10,"") -> 0.17876897 | G15: =G10-G14 -> 199010966 | H15: =IFERROR(G15/G$10,"") -> 0.16641198 | I15: =I10-I14 -> 61213573 | J15: =IFERROR(I15/I$10,"") -> 0.14888201
B16: 販売費及び一般管理費 | C16: =SGA!C33 -> 214823441 | D16: =IFERROR(C16/C$10,"") -> 0.18228717 | E16: =SGA!E33 -> 215718454 | F16: =IFERROR(E16/E$10,"") -> 0.18251105 | G16: =SGA!G33 -> 193151054 | H16: =IFERROR(G16/G$10,"") -> 0.16151195 | I16: =SGA!I33 -> 55896593 | J16: =IFERROR(I16/I$10,"") -> 0.13595019
B17: 営業利益 | C17: =C15-C16 -> 4756748 | D17: =IFERROR(C17/C$10,"") -> 0.0040363106 | E17: =E15-E16 -> -4422940 | F17: =IFERROR(E17/E$10,"") -> -0.0037420787 | G17: =G15-G16 -> 5859912 | H17: =IFERROR(G17/G$10,"") -> 0.0049000293 | I17: =I15-I16 -> 5316980 | J17: =IFERROR(I17/I$10,"") -> 0.012931816
B18: 受取利息 | C18: 1252 | D18: =IFERROR(C18/C$10,"") -> 1.0623772e-06 | E18: 84858 | F18: =IFERROR(E18/E$10,"") -> 7.1795077e-05 | G18: 267463 | H18: =IFERROR(G18/G$10,"") -> 0.00022365123 | I18: 0 | J18: =IFERROR(I18/I$10,"") -> 0
B19: 受取配当金 | C19: 30500 | D19: =IFERROR(C19/C$10,"") -> 2.5880596e-05 | E19: 30500 | F19: =IFERROR(E19/E$10,"") -> 2.5804872e-05 | G19: 30500 | H19: =IFERROR(G19/G$10,"") -> 2.5503948e-05 | I19: 30950 | J19: =IFERROR(I19/I$10,"") -> 7.5275757e-05
B20: 受取奨励金 | C20: 2284370 | D20: =IFERROR(C20/C$10,"") -> 0.0019383887 | E20: 2406729 | F20: =IFERROR(E20/E$10,"") -> 0.0020362405 | G20: 2513377 | H20: =IFERROR(G20/G$10,"") -> 0.0021016733 | I20: 652788 | J20: =IFERROR(I20/I$10,"") -> 0.0015876934
B21: 受取延滞料 | C21: 170242 | D21: =IFERROR(C21/C$10,"") -> 0.00014445785 | E21: 147416 | F21: =IFERROR(E21/E$10,"") -> 0.00012472298 | G21: 96879 | H21: =IFERROR(G21/G$10,"") -> 8.1009738e-05 | I21: 51327 | J21: =IFERROR(I21/I$10,"") -> 0.00012483615
B22: 受取運賃・配達収入 | C22: 0 | D22: =IFERROR(C22/C$10,"") -> 0 | E22: 0 | F22: =IFERROR(E22/E$10,"") -> 0 | G22: 0 | H22: =IFERROR(G22/G$10,"") -> 0 | I22: 49500 | J22: =IFERROR(I22/I$10,"") -> 0.00012039257
B23: 雑収入 | C23: 8141731 | D23: =IFERROR(C23/C$10,"") -> 0.006908618 | E23: 8067387 | F23: =IFERROR(E23/E$10,"") -> 0.0068255046 | G23: 3669539 | H23: =IFERROR(G23/G$10,"") -> 0.0030684502 | I23: 976086 | J23: =IFERROR(I23/I$10,"") -> 0.0023740101
B24: 営業外収益計 | C24: =SUM(C18:C23) -> 10628095 | D24: =IFERROR(C24/C$10,"") -> 0.0090184076 | E24: =SUM(E18:E23) -> 10736890 | F24: =IFERROR(E24/E$10,"") -> 0.009084068 | G24: =SUM(G18:G23) -> 6577758 | H24: =IFERROR(G24/G$10,"") -> 0.0055002885 | I24: =SUM(I18:I23) -> 1760651 | J24: =IFERROR(I24/I$10,"") -> 0.004282208
B25: 支払利息 | C25: 3962441 | D25: =IFERROR(C25/C$10,"") -> 0.003362306 | E25: 4040547 | F25: =IFERROR(E25/E$10,"") -> 0.0034185508 | G25: 3895556 | H25: =IFERROR(G25/G$10,"") -> 0.0032574445 | I25: 1192744 | J25: =IFERROR(I25/I$10,"") -> 0.0029009599
B26: 出荷奨励金 | C26: 105862 | D26: =IFERROR(C26/C$10,"") -> 8.9828578e-05 | E26: 92022 | F26: =IFERROR(E26/E$10,"") -> 7.785626e-05 | G26: 94929 | H26: =IFERROR(G26/G$10,"") -> 7.9379157e-05 | I26: 0 | J26: =IFERROR(I26/I$10,"") -> 0
B27: 雑損失 | C27: 0 | D27: =IFERROR(C27/C$10,"") -> 0 | E27: 0 | F27: =IFERROR(E27/E$10,"") -> 0 | G27: 379401 | H27: =IFERROR(G27/G$10,"") -> 0.00031725323 | I27: 0 | J27: =IFERROR(I27/I$10,"") -> 0
B28: 営業外費用計 | C28: =SUM(C25:C27) -> 4068303 | D28: =IFERROR(C28/C$10,"") -> 0.0034521346 | E28: =SUM(E25:E27) -> 4132569 | F28: =IFERROR(E28/E$10,"") -> 0.003496407 | G28: =SUM(G25:G27) -> 4369886 | H28: =IFERROR(G28/G$10,"") -> 0.0036540769 | I28: =SUM(I25:I27) -> 1192744 | J28: =IFERROR(I28/I$10,"") -> 0.0029009599
B29: 経常利益 | C29: =C17+C24-C28 -> 11316540 | D29: =IFERROR(C29/C$10,"") -> 0.0096025835 | E29: =E17+E24-E28 -> 2181381 | F29: =IFERROR(E29/E$10,"") -> 0.0018455822 | G29: =G17+G24-G28 -> 8067784 | H29: =IFERROR(G29/G$10,"") -> 0.0067462408 | I29: =I17+I24-I28 -> 5884887 | J29: =IFERROR(I29/I$10,"") -> 0.014313064
B30: 固定資産売却益 | C30: 1711177 | D30: =IFERROR(C30/C$10,"") -> 0.0014520092 | E30: 1608918 | F30: =IFERROR(E30/E$10,"") -> 0.0013612434 | G30: 0 | H30: =IFERROR(G30/G$10,"") -> 0 | I30: 0 | J30: =IFERROR(I30/I$10,"") -> 0
B31: 貸倒引当金戻入 | C31: 176000 | D31: =IFERROR(C31/C$10,"") -> 0.00014934377 | E31: 237000 | F31: =IFERROR(E31/E$10,"") -> 0.00020051655 | G31: 234000 | H31: =IFERROR(G31/G$10,"") -> 0.00019566964 | I31: 0 | J31: =IFERROR(I31/I$10,"") -> 0
B32: 特別利益計 | C32: =SUM(C30:C31) -> 1887177 | D32: =IFERROR(C32/C$10,"") -> 0.001601353 | E32: =SUM(E30:E31) -> 1845918 | F32: =IFERROR(E32/E$10,"") -> 0.0015617599 | G32: =SUM(G30:G31) -> 234000 | H32: =IFERROR(G32/G$10,"") -> 0.00019566964 | I32: =SUM(I30:I31) -> 0 | J32: =IFERROR(I32/I$10,"") -> 0
B33: 固定資産売却除却損 | C33: 201719 | D33: =IFERROR(C33/C$10,"") -> 0.00017116747 | E33: 0 | F33: =IFERROR(E33/E$10,"") -> 0 | G33: 1 | H33: =IFERROR(G33/G$10,"") -> 8.3619502e-10 | I33: 0 | J33: =IFERROR(I33/I$10,"") -> 0
B34: 貸倒引当金繰入 | C34: 237000 | D34: =IFERROR(C34/C$10,"") -> 0.00020110496 | E34: 234000 | F34: =IFERROR(E34/E$10,"") -> 0.00019797836 | G34: 203000 | H34: =IFERROR(G34/G$10,"") -> 0.00016974759 | I34: 0 | J34: =IFERROR(I34/I$10,"") -> 0
B35: 前期損益修正損 | C35: 0 | D35: =IFERROR(C35/C$10,"") -> 0 | E35: 0 | F35: =IFERROR(E35/E$10,"") -> 0 | G35: 20900138 | H35: =IFERROR(G35/G$10,"") -> 0.017476591 | I35: 0 | J35: =IFERROR(I35/I$10,"") -> 0
B36: 特別損失計 | C36: =SUM(C33:C35) -> 438719 | D36: =IFERROR(C36/C$10,"") -> 0.00037227243 | E36: =SUM(E33:E35) -> 234000 | F36: =IFERROR(E36/E$10,"") -> 0.00019797836 | G36: =SUM(G33:G35) -> 21103139 | H36: =IFERROR(G36/G$10,"") -> 0.01764634 | I36: =SUM(I33:I35) -> 0 | J36: =IFERROR(I36/I$10,"") -> 0
B37: 税引前当期純利益 | C37: =C29+C32-C36 -> 12764998 | D37: =IFERROR(C37/C$10,"") -> 0.010831664 | E37: =E29+E32-E36 -> 3793299 | F37: =IFERROR(E37/E$10,"") -> 0.0032093638 | G37: =G29+G32-G36 -> -12801355 | H37: =IFERROR(G37/G$10,"") -> -0.010704429 | I37: =I29+I32-I36 -> 5884887 | J37: =IFERROR(I37/I$10,"") -> 0.014313064
B38: 法人税等 | C38: 3658100 | D38: =IFERROR(C38/C$10,"") -> 0.0031040593 | E38: 864400 | F38: =IFERROR(E38/E$10,"") -> 0.00073133546 | G38: 2283300 | H38: =IFERROR(G38/G$10,"") -> 0.0019092841 | I38: 0 | J38: =IFERROR(I38/I$10,"") -> 0
B39: 当期純利益 | C39: =C37-C38 -> 9106898 | D39: =IFERROR(C39/C$10,"") -> 0.0077276048 | E39: =E37-E38 -> 2928899 | F39: =IFERROR(E39/E$10,"") -> 0.0024780283 | G39: =G37-G38 -> -15084655 | H39: =IFERROR(G39/G$10,"") -> -0.012613713 | I39: =I37-I38 -> 5884887 | J39: =IFERROR(I39/I$10,"") -> 0.014313064
B41: チェック：営業利益 | C41: =EXACT(C17,4756748) -> TRUE | E41: =EXACT(E17,-4422940) -> TRUE | G41: =EXACT(G17,5859912) -> TRUE | I41: =EXACT(I17,5316980) -> TRUE
B42: チェック：当期純利益 | C42: =EXACT(C39,9106898) -> TRUE | E42: =EXACT(E39,2928899) -> TRUE | G42: =EXACT(G39,-15084655) -> TRUE | I42: =EXACT(I39,5884887) -> TRUE
...

Sheet IM→

Sheet 会社概要
A1: 会社概要（基本情報ページの原本）
B3: 項目 | C3: 内容
B4: 商号 | C4: 株式会社鶴岡中央青果
B5: 本店所在地 | C5: 山形県鶴岡市宝田一丁目4番20号
B6: 設立 | C6: 1973年（昭和48年）11月22日
B7: 代表者 | C7: 代表取締役 岡部 寛
B8: 資本金 | C8: 40,000千円
B9: 発行済株式総数 | C9: 4,000株（発行可能株式総数5,000株、譲渡制限あり：取締役会の承認）
B10: 事業内容 | C10: 青果物（野菜・果実）の卸売（鶴岡市宝田における地方卸売市場の開設・運営および卸売業）、包装資材・肥料等の販売、パッケージ（小分け・包装）業務、倉庫業
B11: 登記上の目的 | C11: 1 青果物の販売及び卸売の業務 2 倉庫業 3 前号に附帯する一切の業務
B12: 機関設計 | C12: 取締役会設置会社／監査役設置会社（監査の範囲を会計に限定）
B13: 従業員数 | C13: 職員名簿24名（うち正社員等17名・嘱託/再雇用/試用3名・パート3名・アルバイト1名）＋常勤役員2名（2026年9月1日現在）
B14: 決算期 | C14: 3月
... B19: 直近業績(2026/3期) | C19: 売上高 1,195,893千円／営業利益 5,859千円／経常利益 8,067千円

Sheet PLハイライト
A1: 財務ハイライト（P/L）・調整後EBITDA
A2: 単位：千円（入力は円）
B4: 項目 | C4: 2024年3月期 (第51期) | D4: 2025年3月期 (第52期) | E4: 2026年3月期 (第53期) | F4: 3期平均 | G4: 直近2期平均 | H4: 備考
B5: 売上高 | C5: =PL!C10 -> 1178489098 | D5: =PL!E10 -> 1181947340 | E5: =PL!G10 -> 1195893269 | F5: =AVERAGE(C5:E5) -> 1.1854432e+09 | G5: =AVERAGE(D5:E5) -> 1.1889203e+09
B6: 売上総利益 | C6: =PL!C15 -> 219580189 | D6: =PL!E15 -> 211295514 | E6: =PL!G15 -> 199010966 | F6: =AVERAGE(C6:E6) -> 209962223 | G6: =AVERAGE(D6:E6) -> 205153240
B7: 売上総利益率 | C7: =IFERROR(C6/C5,"") -> 0.18632348 | D7: =IFERROR(D6/D5,"") -> 0.17876897 | E7: =IFERROR(E6/E5,"") -> 0.16641198
B8: 販売費及び一般管理費 | C8: =PL!C16 -> 214823441 | D8: =PL!E16 -> 215718454 | E8: =PL!G16 -> 193151054 | F8: =AVERAGE(C8:E8) -> 2.0789765e+08 | G8: =AVERAGE(D8:E8) -> 204434754
B9: 営業利益 | C9: =PL!C17 -> 4756748 | D9: =PL!E17 -> -4422940 | E9: =PL!G17 -> 5859912 | F9: =AVERAGE(C9:E9) -> 2064573.3 | G9: =AVERAGE(D9:E9) -> 718486
B10: 減価償却費 | C10: =SGA!C31 -> 13663684 | D10: =SGA!E31 -> 12557564 | E10: =SGA!G31 -> 8878970 | F10: =AVERAGE(C10:E10) -> 11700073 | G10: =AVERAGE(D10:E10) -> 10718267
B11: EBITDA（営業利益＋減価償却費） | C11: =C9+C10 -> 18420432 | D11: =D9+D10 -> 8134624 | E11: =E9+E10 -> 14738882 | F11: =AVERAGE(C11:E11) -> 13764646 | G11: =AVERAGE(D11:E11) -> 11436753
B12: 【調整項目】
B13: 代表者及びその家族分の役員報酬（実績） | C13: 10680000 | D13: 10680000 | E13: 4440000 | H13: 勘定科目内訳書「人件費の内訳」
B14: 後任経営者の想定報酬（仮定） | C14: 8000000 | D14: 8000000 | E14: 8000000 | H14: （仮定）年8,000千円。譲渡後の経営体制により見直す
B15: ①役員報酬の正常化 | C15: =C13-C14 -> 2680000 | D15: =D13-D14 -> 2680000 | E15: =E13-E14 -> -3560000 | F15: =AVERAGE(C15:E15) -> 600000 | G15: =AVERAGE(D15:E15) -> -440000 | H15: 代表者・配偶者報酬を後任経営者想定報酬に置換（仮定）。常務取締役（2026/5退任、年6,600千円）の後任要否は要確認のため調整対象外
B16: ②賞与の正常化 | C16: =0 -> 0 | D16: =0 -> 0 | E16: =-AVERAGE(SGA!C7,SGA!E7) -> -5847325 | F16: =AVERAGE(C16:E16) -> -1949108.3 | G16: =AVERAGE(D16:E16) -> -2923662.5 | H16: 2026/3期は賞与計上なし。前2期平均相当を費用として控除（仮説：今後支給が再開される前提）。不支給の経緯は要確認
B17: ③受取奨励金（純額）の加算 | C17: =PL!C20-PL!C26 -> 2178508 | D17: =PL!E20-PL!E26 -> 2314707 | E17: =PL!G20-PL!G26 -> 2418448 | F17: =AVERAGE(C17:E17) -> 2303887.7 | G17: =AVERAGE(D17:E17) -> 2366577.5 | H17: 仕入完納等に伴い毎期経常的に発生する事業関連収益（受取奨励金−出荷奨励金）。発生根拠は要確認
B18: 調整額 計 | C18: =C15+C16+C17 -> 4858508 | D18: =D15+D16+D17 -> 4994707 | E18: =E15+E16+E17 -> -6988877 | F18: =AVERAGE(C18:E18) -> 954779.33 | G18: =AVERAGE(D18:E18) -> -997085
B19: 調整後EBITDA | C19: =C11+C18 -> 23278940 | D19: =D11+D18 -> 13129331 | E19: =E11+E18 -> 7750005 | F19: =AVERAGE(C19:E19) -> 14719425 | G19: =AVERAGE(D19:E19) -> 10439668
B21: 経常利益 | C21: =PL!C29 -> 11316540 | D21: =PL!E29 -> 2181381 | E21: =PL!G29 -> 8067784 | F21: =AVERAGE(C21:E21) -> 7188568.3 | G21: =AVERAGE(D21:E21) -> 5124582.5
B22: 当期純利益 | C22: =PL!C39 -> 9106898 | D22: =PL!E39 -> 2928899 | E22: =PL!G39 -> -15084655 | F22: =AVERAGE(C22:E22) -> -1016286 | G22: =AVERAGE(D22:E22) -> -6077878
B23: 支払利息 | C23: =PL!C25 -> 3962441 | D23: =PL!E25 -> 4040547 | E23: =PL!G25 -> 3895556 | F23: =AVERAGE(C23:E23) -> 3966181.3 | G23: =AVERAGE(D23:E23) -> 3968051.5
B24: 人件費（役員報酬・給与・賞与・法定福利等） | C24: =SGA!C5+SGA!C6+SGA!C7+SGA!C8+SGA!C9+SGA!C10+SGA!C11 -> 120274546 | D24: =SGA!E5+SGA!E6+SGA!E7+SGA!E8+SGA!E9+SGA!E10+SGA!E11 -> 121407097 | E24: =SGA!G5+SGA!G6+SGA!G7+SGA!G8+SGA!G9+SGA!G10+SGA!G11 -> 104562438 | F24: =AVERAGE(C24:E24) -> 1.1541469e+08 | G24: =AVERAGE(D24:E24) -> 1.1298477e+08
B25: 運賃＋車両関連費 | C25: =SGA!C16+SGA!C15 -> 36022052 | D25: =SGA!E16+SGA!E15 -> 39619785 | E25: =SGA!G16+SGA!G15 -> 38858196 | F25: =AVERAGE(C25:E25) -> 38166678 | G25: =AVERAGE(D25:E25) -> 39238990
B27: 【進行期：2026年4〜7月（4か月累計）】
B28: 売上高 | C28: =PL!I10 -> 411154947
B29: 売上総利益 | C29: =PL!I15 -> 61213573
B30: 営業利益 | C30: =PL!I17 -> 5316980
B31: 減価償却費 | C31: =SGA!I31 -> 2436000
B32: 経常利益 | C32: =PL!I29 -> 5884887
B33: 売上総利益率 | C33: =IFERROR(C29/C28,"") -> 0.14888201
B34: 前期同期間（4〜7月）売上高：概況説明書月別 | C34: 419288000 | H34: 2025年4〜7月の月別売上合計（千円単位の記載を円換算）

Sheet BSハイライト
A1: 財務ハイライト（B/S）
A2: 単位：千円（入力は円）
B4: 項目 | C4: 2024年3月期 (第51期) | D4: 2025年3月期 (第52期) | E4: 2026年3月期 (第53期) | F4: 2026年7月 (試算表) | G4: 備考
B5: 現金及び預金 | C5: ='BS(借方)'!C6 -> 339552632 | D5: ='BS(借方)'!D6 -> 259719301 | E5: ='BS(借方)'!E6 -> 210887077 | F5: ='BS(借方)'!G6 -> 162087296
B6: 売上債権（売掛金・資材肥料売掛金） | C6: ='BS(借方)'!C7+'BS(借方)'!C8 -> 22523530 | D6: ='BS(借方)'!D7+'BS(借方)'!D8 -> 23165625 | E6: ='BS(借方)'!E7+'BS(借方)'!E8 -> 20836318 | F6: ='BS(借方)'!G7+'BS(借方)'!G8 -> 42952291
B7: 棚卸資産 | C7: ='BS(借方)'!C9 -> 9859795 | D7: ='BS(借方)'!D9 -> 15443609 | E7: ='BS(借方)'!E9 -> 14596695 | F7: ='BS(借方)'!G9 -> 36647736
B8: 流動資産計 | C8: ='BS(借方)'!C16 -> 375589011 | D8: ='BS(借方)'!D16 -> 303100807 | E8: ='BS(借方)'!E16 -> 249704912 | F8: ='BS(借方)'!G16 -> 244250605
B9: 建物・附属設備・構築物 | C9: ='BS(借方)'!C18+'BS(借方)'!C19+'BS(借方)'!C20 -> 116961239 | D9: ='BS(借方)'!D18+'BS(借方)'!D19+'BS(借方)'!D20 -> 109687792 | E9: ='BS(借方)'!E18+'BS(借方)'!E19+'BS(借方)'!E20 -> 103749925 | F9: ='BS(借方)'!G18+'BS(借方)'!G19+'BS(借方)'!G20 -> 103749925
B10: 土地 | C10: ='BS(借方)'!C24 -> 93137240 | D10: ='BS(借方)'!D24 -> 93137240 | E10: ='BS(借方)'!E24 -> 93137240 | F10: ='BS(借方)'!G24 -> 93137240 | G10: 固定資産税評価額合計47,478千円（R8年度）。簿価との差は時価評価で要確認
B11: 保証金 | C11: ='BS(借方)'!C35 -> 32002569 | D11: ='BS(借方)'!D35 -> 33002569 | E11: ='BS(借方)'!E35 -> 33302569 | F11: ='BS(借方)'!G35 -> 33302569 | G11: うち庄内青果物卸売精算(有)31,993千円（FY53）
B12: 事業保険積立金 | C12: ='BS(借方)'!C36 -> 21161692 | D12: ='BS(借方)'!D36 -> 20900138 | E12: ='BS(借方)'!E36 -> 0 | F12: ='BS(借方)'!G36 -> 0 | G12: 2026/3期に前期損益修正損として全額取崩し
B13: 資産合計 | C13: ='BS(借方)'!C40 -> 651947559 | D13: ='BS(借方)'!D40 -> 567528964 | E13: ='BS(借方)'!E40 -> 485190104 | F13: ='BS(借方)'!G40 -> 476299797
B14: 仕入債務（買掛金） | C14: ='BS (貸方)'!C6 -> 18127739 | D14: ='BS (貸方)'!D6 -> 19954920 | E14: ='BS (貸方)'!E6 -> 26349122 | F14: ='BS (貸方)'!G6 -> 32102162
B15: 有利子負債（長期借入金） | C15: ='BS (貸方)'!C14 -> 514690000 | D15: ='BS (貸方)'!D14 -> 434046000 | E15: ='BS (貸方)'!E14 -> 361058000 | F15: ='BS (貸方)'!G14 -> 337862000
B16: 預り保証金 | C16: ='BS (貸方)'!C15 -> 10320000 | D16: ='BS (貸方)'!D15 -> 10270000 | E16: ='BS (貸方)'!E15 -> 8980000 | F16: ='BS (貸方)'!G15 -> 8980000 | G16: 取引先（仲卸・買参人等と推察）からの預り。債務類似項目
B17: 負債合計 | C17: ='BS (貸方)'!C17 -> 559119222 | D17: ='BS (貸方)'!D17 -> 473771728 | E17: ='BS (貸方)'!E17 -> 407317523 | F17: ='BS (貸方)'!G17 -> 392542329
B18: 純資産 | C18: ='BS (貸方)'!C22 -> 92828337 | D18: ='BS (貸方)'!D22 -> 93757236 | E18: ='BS (貸方)'!E22 -> 77872581 | F18: ='BS (貸方)'!G22 -> 83757468
B19: 自己資本比率 | C19: =IFERROR(C18/C13,"") -> 0.1423862 | D19: =IFERROR(D18/D13,"") -> 0.16520256 | E19: =IFERROR(E18/E13,"") -> 0.16049911 | F19: =IFERROR(F18/F13,"") -> 0.17585031
B20: ネットデット（有利子負債−現預金） | C20: =C15-C5 -> 175137368 | D20: =D15-D5 -> 174326699 | E20: =E15-E5 -> 150170923 | F20: =F15-F5 -> 175774704 | G20: 預り保証金は含めず
B22: 借入先別残高（2026/3期末）
B23: 鶴岡信用金庫 本店営業部 | E23: 182840000
B24: 山形銀行 鶴岡支店 | E24: 70250000
B25: 日本政策金融公庫 山形支店（1） | E25: 60730000
B26: 日本政策金融公庫 山形支店（2） | E26: 39380000
B27: 日本政策金融公庫 山形支店（3） | E27: 7858000
B28: 合計 | E28: =SUM(E23:E27) -> 361058000
B29: ※金利・返済条件・担保・保証（代表者の連帯保証含む）は内訳書に記載がなく要確認。

Sheet 取引先
A1: 主要販売先（期末売掛金残高ベース）
A2: 単位：千円（入力は円）／年間取引高は資料未受領のため期末残高で代替（要確認）
B4: 相手先 | C4: 2024/3末 | D4: 2025/3末 | E4: 2026/3末 | F4: 所在地 | G4: 業態・備考
B5: (株)主婦の店 | C5: 7624554 | D5: 7465020 | E5: 7194026 | F5: 鶴岡市 | G5: 食品スーパー（推察）
B6: 小島商店 | C6: 3566319 | D6: 1609526 | E6: 2482212 | F6: 鶴岡市 | G6: 青果小売（推察）
B7: 長井中央青果(株) | C7: 3038668 | D7: 4185185 | E7: 1785378 | F7: 長井市 | G7: 青果卸（長井中央青果地方卸売市場）
B8: 生活協同組合共立社 | C8: 1109653 | D8: 2034205 | E8: 1931830 | F8: 鶴岡市 | G8: 生協
B9: 給食センター | C9: 793291 | D9: 1307264 | E9: 1121037 | F9: 鶴岡市 | G9: 学校給食（推察）
B10: 元青果 | C10: 1050840 | D10: 1018741 | E10: 745635 | F10: 三川町 | G10: 公設庄内青果物地方卸売市場内事業者（推察）
B11: 生活協同組合連合会アイチョイス | C11: 751258 | D11: 1032520 | E11: 617729 | F11: 名古屋市 | G11: 生協連合会
B12: (株)みどりの里 | C12: 502958 | D12: 886182 | F12: 愛知県豊田市
B13: (有)新庄丸果青果 | C13: 825334 | D13: 705974 | F13: 新庄市 | G13: 青果卸（推察）
B14: (株)やま高商店 | C14: 862435 | F14: 仙台市
B15: みどり水産 | D15: 630388
B16: その他 | C16: 2398220 | D16: 2290620 | E16: 4958471
B17: 合計 | C17: 22523530 | D17: 23165625 | E17: 20836318
B18: チェック（明細合計＝合計） | C18: =EXACT(SUM(C5:C16),C17) -> TRUE | D18: =EXACT(SUM(D5:D16),D17) -> TRUE | E18: =EXACT(SUM(E5:E16),E17) -> TRUE
B20: ※内訳書は残高50万円以上の相手先のみ個別記載。空欄は「その他」に含まれる。業態は公開情報からの推察を含む。

Sheet 仕入先
A1: 主要仕入先（期末買掛金残高ベース）
A2: 単位：千円（入力は円）／年間取引高は資料未受領のため期末残高で代替（要確認）
B4: 相手先 | C4: 2024/3末 | D4: 2025/3末 | E4: 2026/3末 | F4: 所在地 | G4: 業態・備考
B5: 丸果庄内青果(株) | C5: 6568837 | D5: 5733427 | E5: 12426183 | F5: 三川町 | G5: 青果卸（公設庄内青果物地方卸売市場）
B6: 長井中央青果(株) | C6: 1308421 | D6: 2086538 | E6: 7397876 | F6: 長井市 | G6: 青果卸
B7: (株)庄果 | C7: 3610982 | D7: 4495652 | F7: 三川町 | G7: 青果卸（公設庄内青果物地方卸売市場）
B8: (株)マルト直治郎商店 | C8: 1228678 | D8: 1954193 | E8: 676643 | F8: 三川町
B9: 成田食品(株) | C9: 540882 | D9: 698863 | E9: 615054 | F9: 福島県相馬市
B10: (株)ファーマインド | E10: 707255 | F10: 東京都千代田区 | G10: 青果流通（バナナ等・推察）
B11: (株)東根農産センター | E11: 547560 | F11: 東根市
B12: その他 | C12: 4869939 | D12: 4986247 | E12: 3978551
B13: 合計 | C13: 18127739 | D13: 19954920 | E13: 26349122
B14: チェック（明細合計＝合計） | C14: =EXACT(SUM(C5:C12),C13) -> TRUE | D14: =EXACT(SUM(D5:D12),D13) -> TRUE | E14: =EXACT(SUM(E5:E12),E13) -> TRUE
B16: ※内訳書は残高50万円以上の相手先のみ個別記載。空欄は「その他」に含まれる。業態は公開情報からの推察を含む。

Sheet 株主
A1: 株主構成
A2: 出所：法人税申告書 別表二（2026/3期）
B4: 株主名 | C4: 続柄・役職 | D4: 株式数 | E4: 持株比率
B5: 岡部 寛 | C5: 代表取締役（本人） | D5: 1510 | E5: =D5/D$13 -> 0.3775
B6: 岡部 一 | C6: 取締役・代表者の兄弟 | D6: 720 | E6: =D6/D$13 -> 0.18
B7: 岡部 和子 | C7: 代表者の兄弟 | D7: 500 | E7: =D7/D$13 -> 0.125
B8: 梅津 恵一 | C8: — | D8: 360 | E8: =D8/D$13 -> 0.09
B9: 小野寺 則和 | C9: 監査役 | D9: 350 | E9: =D9/D$13 -> 0.0875
B10: 岡部 竹古 | C10: 取締役・代表者の配偶者 | D10: 300 | E10: =D10/D$13 -> 0.075
B11: 佐藤 令子 | C11: — | D11: 200 | E11: =D11/D$13 -> 0.05
B12: 菅原 圭吾 | C12: 元常務取締役（2026年5月退任） | D12: 60 | E12: =D12/D$13 -> 0.015
B13: 合計 | D13: =SUM(D5:D12) -> 4000 | E13: =D13/D13 -> 1
B14: うち岡部家（4名） | D14: =D5+D6+D7+D10 -> 3030 | E14: =D14/D13 -> 0.7575
B16: ※株主名簿・名義株の有無・親族外株主（4名・合計970株）の取得経緯は要確認。発行済株式総数4,000株と一致。

Sheet 取締役
A1: 役員構成・役員報酬
A2: 出所：履歴事項全部証明書（2026/9/10）、勘定科目内訳書（役員給与等）
B4: 役職 | C4: 氏名 | D4: 常勤/非常勤 | E4: 備考 | F4: 2024/3期 | G4: 2025/3期 | H4: 2026/3期
B5: 代表取締役 | C5: 岡部 寛 | D5: 常勤 | E5: 社長 | F5: 10560000 | G5: 10560000 | H5: 4320000
B6: 取締役 | C6: 岡部 一 | D6: 常勤 | E6: 部長（代表者の兄弟） | F6: 4800000 | G6: 4800000 | H6: 4200000
B7: 取締役 | C7: 岡部 竹古 | D7: 非常勤 | E7: 代表者の配偶者 | F7: 120000 | G7: 120000 | H7: 120000
B8: 監査役 | C8: 小野寺 則和 | D8: 非常勤 | E8: 会計監査限定 | F8: 120000 | G8: 120000 | H8: 120000
B9: （退任）常務取締役 | C9: 菅原 圭吾 | D9: 常勤 | E9: 2026年5月29日退任 | F9: 6600000 | G9: 6600000 | H9: 6600000
B10: 役員報酬 計 | F10: =SUM(F5:F9) -> 22200000 | G10: =SUM(G5:G9) -> 22200000 | H10: =SUM(H5:H9) -> 15360000
B12: ※任期：取締役は2年（直近重任2026/5/29）、監査役は2024/5/18重任。代表者の連帯保証・退職慰労金規程の有無は要確認。

Sheet 従業員
A1: 従業員一覧（2026年9月1日現在）
A2: 出所：職員名簿。氏名・住所・電話番号は概要書に記載しない
B4: No. | C4: 部署 | D4: 役職 | E4: 雇用形態 | F4: 性別 | G4: 年齢 | H4: 入社年 | I4: 勤続年数 | J4: 所定労働 | K4: セリ人資格 | L4: フォークリフト | M4: 備考
B5: 1 | C5: 野菜営業部 | D5: 副部長 | E5: 正社員 | F5: 男 | G5: 63 | H5: 2025 | I5: 1 | J5: 8h
B6: 2 | C6: 野菜営業部 | D6: 副部長 | E6: 正社員 | F6: 男 | G6: 47 | H6: 2002 | I6: 24 | J6: 8h | K6: ○ | L6: ○
B7: 3 | C7: 近郷部 | D7: 課長 | E7: 正社員 | F7: 男 | G7: 31 | H7: 2014 | I7: 12 | J7: 8h | K7: ○ | L7: ○
B8: 4 | C8: 近郷部 | E8: 正社員 | F8: 男 | G8: 42 | H8: 2019 | I8: 7 | J8: 8h | L8: ○
B9: 5 | C9: 近郷部 | E9: 正社員 | F9: 男 | G9: 45 | H9: 2019 | I9: 7 | J9: 8h | L9: ○
B10: 6 | C10: 集配部 | E10: 正社員 | F10: 男 | G10: 63 | H10: 2020 | I10: 6 | J10: 8h | L10: ○
B11: 7 | C11: 野菜営業部 | E11: 正社員 | F11: 男 | G11: 32 | H11: 2020 | I11: 6 | J11: 8h | L11: ○
B12: 8 | C12: 果実営業部 | E12: 正社員 | F12: 男 | G12: 36 | H12: 2021 | I12: 4 | J12: 8h | L12: ○
B13: 9 | C13: 集配部 | E13: 正社員 | F13: 男 | G13: 42 | H13: 2012 | I13: 14 | J13: 8h | L13: ○ | M13: 2022年4月よりフルタイム
B14: 10 | C14: 生花部 | E14: 嘱託社員 | F14: 男 | G14: 69 | H14: 2006 | I14: 20 | J14: 8h | L14: ○
B15: 11 | C15: 集配部 | E15: 再雇用正社員 | F15: 男 | G15: 40 | H15: 2023 | I15: 3 | J15: 8h
B16: 12 | C16: 近郷部 | E16: 試用期間 | F16: 男 | G16: 66 | H16: 2024 | I16: 2 | J16: 8h | K16: ○
B17: 13 | C17: 集配部 | E17: アルバイト | F17: 男 | G17: 55 | H17: 2026 | I17: 0 | J17: 休日のみ配送
B18: 14 | C18: 総務部 | D18: 部長 | E18: 正社員 | F18: 女 | G18: 56 | H18: 1988 | I18: 38 | J18: 8h
B19: 15 | C19: 資材部 | D19: 課長 | E19: 正社員 | F19: 女 | G19: 65 | H19: 1979 | I19: 47 | J19: 8h | M19: 定年後再雇用
B20: 16 | C20: 果実営業部 | D20: 課長 | E20: 正社員 | F20: 女 | G20: 49 | H20: 2007 | I20: 19 | J20: 8h
B21: 17 | C21: 事務 | E21: 正社員 | F21: 女 | G21: 28 | H21: 2019 | I21: 7 | J21: 8h
B22: 18 | C22: パッケージ部 | D22: 係長 | E22: 正社員 | F22: 女 | G22: 52 | H22: 2006 | I22: 20 | J22: 8h | M22: 2012年4月よりフルタイム
B23: 19 | C23: パッケージ部 | E23: 正社員 | F23: 女 | G23: 65 | H23: 2006 | I23: 20 | J23: 8h | M23: 2012年4月よりフルタイム／定年後再雇用
B24: 20 | C24: パッケージ部 | E24: 正社員 | F24: 女 | G24: 55 | H24: 2021 | I24: 5 | J24: 8h
B25: 21 | C25: パッケージ部 | E25: 正社員 | F25: 女 | G25: 65 | H25: 2009 | I25: 17 | J25: 8h | M25: 2012年4月よりフルタイム
B26: 22 | C26: パッケージ部 | E26: パート | F26: 女 | G26: 67 | H26: 2012 | I26: 14 | J26: 4h
B27: 23 | C27: パッケージ部 | E27: パート | F27: 男 | G27: 29 | H27: 2018 | I27: 8 | J27: 4h
B28: 24 | C28: パッケージ部 | E28: パート | F28: 女 | G28: 59 | H28: 2023 | I28: 3 | J28: 4h
B30: ※セリ人資格保有3名（No.2・3・12）。定年は60歳（名簿注記「当時60歳定年退職後、再雇用契約更新」）と65歳の両記載あり、就業規則で要確認。
B31: ※法人事業概況説明書（2026/3期末）では常勤役員3名＋その他27名＝30名、山形県資料では40名と記載。人数定義の差は要確認。

Sheet 拠点(本社等)
A1: 拠点概要
B3: 項目 | C3: 内容
B4: 本社・市場 | C4: 山形県鶴岡市宝田一丁目4番20号（宝田一丁目4-2：宅地3,100.22㎡。事務所・市場・倉庫・貯蔵庫。自社所有）
B5: パッケージ場・倉庫 | C5: 鶴岡市宝田一丁目5-1（宅地900.50㎡。事務所兼倉庫〔パッケージ場〕629.34㎡・倉庫139.08㎡。自社所有）
B6: 倉庫敷地 | C6: 東田川郡庄内町長沼字宮前304-7（宅地261.81㎡。自社所有。建物の課税明細なし＝建物の有無は要確認）
B7: 賃借物件 | C7: なし（地代家賃の計上なし）。ただしリース料年6,227千円（車両・冷蔵設備等と推察、要確認）

Sheet 不動産(所有)
A1: 所有不動産
A2: 出所：R8年度固定資産税課税明細書、固定資産（土地・建物）内訳書
B4: 所在 | C4: 地目 | D4: 用途 | E4: 地積(㎡) | F4: 固定資産税評価額 | H4: 簿価(2026/3末)
B5: 鶴岡市宝田一丁目4-2 | C5: 宅地 | D5: 市場・事務所・倉庫 | E5: 3100.22 | F5: 35861205 | H5: 70757240
B6: 鶴岡市宝田一丁目5-1 | C6: 宅地 | D6: パッケージ場・倉庫 | E6: 900.5 | F6: 10560298 | H6: 21380000
B7: 東田川郡庄内町長沼字宮前304-7 | C7: 宅地 | D7: 倉庫敷地 | E7: 261.81 | F7: 1056005 | H7: 1000000
B8: 土地 計 | E8: =SUM(E5:E7) -> 4262.53 | F8: =SUM(F5:F7) -> 47477508 | H8: =SUM(H5:H7) -> 93137240
B10: 所在 | C10: 種類 | D10: 構造 | E10: 階数 | F10: 床面積(㎡) | G10: 建築年 | H10: 固定資産税評価額
B11: 宝田一丁目4-2 | C11: 事務所 | D11: 鉄骨造 亜鉛メッキ鋼板葺 | E11: 2階 | F11: 365.63 | G11: 1981年（昭和56年） | H11: 11218061
B12: 宝田一丁目4-2 | C12: 市場 | D12: 鉄骨造 亜鉛メッキ鋼板葺 | E12: 1階 | F12: 320.22 | G12: 1981年（昭和56年） | H12: 4712536
B13: 宝田一丁目4-2 | C13: 倉庫 | D13: 鉄骨造 亜鉛メッキ鋼板葺 | E13: 1階 | F13: 327.13 | G13: 1981年（昭和56年） | H13: 4560792
B14: 宝田一丁目4-2 | C14: 倉庫 | D14: 軽量鉄骨造 | E14: 2階 | F14: 198.74 | G14: 1981年（昭和56年） | H14: 1237049
B15: 宝田一丁目4-2 | C15: 貯蔵庫 | D15: 軽量鉄骨造 | E15: 1階 | F15: 34.48 | G15: 1981年（昭和56年） | H15: 566907
B16: 宝田一丁目5-1 | C16: 事務所兼倉庫 | D16: 鉄骨造 亜鉛メッキ鋼板葺 | E16: 2階 | F16: 627.4 | G16: 1982年（昭和57年） | H16: 13110977
B17: 宝田一丁目5-1 | C17: 倉庫 | D17: 鉄骨造 亜鉛メッキ鋼板葺 | E17: 1階 | F17: 139.08 | G17: 2012年（平成24年） | H17: 11655678
B18: 建物 計 | F18: =SUM(F11:F17) -> 2012.68 | H18: =SUM(H11:H17) -> 47062000
B20: ※建物簿価（2026/3末）92,066千円・建物付属設備11,400千円。主要棟は1981〜82年築であり、新耐震基準への適合（確認済証の日付）・アスベスト・修繕履歴は要確認。
B21: ※土地の簿価93,137千円に対し、固定資産税評価額は47,478千円。評価額÷0.7で推計した時価は約67,800千円（推察）であり、含み損の可能性あり。鑑定・路線価で要確認。
B22: ※償却資産の課税標準額9,779千円。R8年度固定資産税・都市計画税の年税額1,488千円。

Sheet 設備
A1: 保有設備
A2: 固定資産台帳は未受領（要確認）。BS科目別簿価で代替
B4: 区分 | C4: 簿価(2026/3末) | D4: 備考
B5: 建物付属設備 | C5: ='BS(借方)'!E19 -> 11399836 | D5: 冷蔵庫ユニット交換・シャッター更新等（内訳書記載の改修工事）
B6: 構築物 | C6: ='BS(借方)'!E20 -> 284395
B7: 機械装置 | C7: ='BS(借方)'!E21 -> 2 | D7: 備忘価額のみ（償却済）
B8: 車両運搬具 | C8: ='BS(借方)'!E22 -> 15 | D8: 備忘価額のみ。集配車両はリースと推察（要確認）
B9: 工具器具備品 | C9: ='BS(借方)'!E23 -> 18546
B10: ソフトウェア | C10: ='BS(借方)'!E29 -> 371800 | D10: 販売管理システム等と推察（要確認）

Sheet 月別売上
A1: 月別売上高・仕入高（2026/3期）
A2: 出所：法人事業概況説明書。単位：千円（概況説明書記載値をそのまま転記）
B4: 項目 | C4: 4月 | D4: 5月 | E4: 6月 | F4: 7月 | G4: 8月 | H4: 9月 | I4: 10月 | J4: 11月 | K4: 12月 | L4: 1月 | M4: 2月 | N4: 3月 | O4: 合計
B5: 売上高 | C5: 87736 | D5: 101698 | E5: 83794 | F5: 146060 | G5: 138177 | H5: 110175 | I5: 106499 | J5: 100617 | K5: 98058 | L5: 69520 | M5: 69339 | N5: 84221 | O5: =SUM(C5:N5) -> 1195894
B6: 仕入高 | C6: 76904 | D6: 86235 | E6: 74095 | F6: 139243 | G6: 96826 | H6: 85074 | I6: 84386 | J6: 85425 | K6: 82345 | L6: 56698 | M6: 58088 | N6: 70716 | O6: =SUM(C6:N6) -> 996035
B7: 人件費 | C7: 4204 | D7: 7349 | E7: 7586 | F7: 7363 | G7: 7717 | H7: 7474 | I7: 7291 | J7: 7298 | K7: 7200 | L7: 6903 | M7: 6884 | N7: 9764 | O7: =SUM(C7:N7) -> 87033

Sheet その他
A1: 要確認事項・Web調査メモ（ヒアリング項目／資料依頼の原本）
B3: No. | C3: 区分 | D3: 内容 | E3: 優先度
B4: 1 | C4: 事業 | D4: 売上高の構成（買付販売／受託販売手数料／センター費／資材・肥料売上）の年度別内訳。決算書では「商品売上高」1本表示 | E4: 高
B5: 2 | C5: 事業 | D5: 市場の法的位置づけ（卸売市場法上の地方卸売市場の認定／開設者兼卸売業者）、認定日・条件、仲卸業者数・売買参加者数 | E5: 高
B6: 3 | C6: 事業 | D6: 主要販売先別・仕入先（出荷者）別の年間取引高（内訳書は期末残高のみ）。(株)主婦の店への依存度 | E6: 高
B7: 4 | C7: 事業 | D7: 「主婦センター費」「センター費」の内容（主婦の店の物流センター業務の受託と推察）、契約条件 | E7: 高
B8: 5 | C8: 財務 | D8: 2025/3期の営業赤字（△4,423千円）の要因。売上総利益率は18.6%→17.9%→16.6%と低下 | E8: 高
B9: 6 | C9: 財務 | D9: 2026/3期に賞与計上がない理由。今後の支給方針 | E9: 高
B10: 7 | C10: 財務 | D10: 前期損益修正損20,900千円（過年度保険解約訂正額）の経緯。解約返戻金の受領有無 | E10: 高
B11: 8 | C11: 財務 | D11: 役員報酬の減額（代表者10,560千円→4,320千円）の理由、常務取締役退任（2026/5）後の体制 | E11: 高
B12: 9 | C12: 財務 | D12: 借入金の金利・返済予定・担保・代表者保証。有利子負債361,058千円（2026/3末） | E12: 高
B13: 10 | C13: 財務 | D13: 保証金31,993千円（庄内青果物卸売精算(有)）の性質・返還条件、預り保証金8,980千円の相手先 | E13: 中
B14: 11 | C14: 財務 | D14: 投資有価証券の減少（2026/3末2,600千円→2026/7末1,600千円）。(株)庄果株式の処分有無 | E14: 中
B15: 12 | C15: 財務 | D15: 租税公課12,177千円の内訳（税込経理による消費税納付額と推察） | E15: 中
... B23: 20 | C23: 譲渡条件 | D23: スキーム（株式譲渡100%を想定）、希望価格、役員の継続関与、従業員の雇用維持、譲渡理由 | E23: 高
C25: Web出所：https://www.turu-chu.co.jp/ ／ https://www.pref.yamagata.jp/140031/sangyo/nourinsuisangyou/nogyo/business/oroshiurisijyou.html ／
C26: https://www.pref.yamagata.jp/documents/26382/r7shijo_gaiyou.pdf ／ https://www.inetshonai.or.jp/~seika/main.html
