Workbook

Sheet ルール
A1: 案件マスター 運用ルール（株式会社鶴岡中央青果）
B3: 1. 本ファイルが唯一の数値ソース。企業概要書・評価書の数字は必ず本ファイルから転記する（パワポに直接打たない）。
B4: 2. 文字は「游ゴシック」、数字は「Arial」、備考等の細かい文章は「游ゴシック Medium」。タイトル・合計欄は太字。
B5: 3. 数字は円単位で入力する。表示は千円単位に設定済み（千円で入力すると1000倍ずれる）。
B6: 4. 未確認事項は推測で埋めず「要確認」と記載し、「その他」シートに集約する。推測を書く場合は「推察」「想定」「（仮説）」と明記。
B7: 5. 転記元：第51〜53期決算報告書（勘定科目内訳明細書・法人税申告書・法人事業概況説明書を含む）、2026年7月試算表、
B8: 職員名簿（2026/9/1現在）、履歴事項全部証明書（2026/9/10取得）、R8年度固定資産税課税明細書。
B9: 6. 進行期（G列）は2026年4月〜7月の4か月累計。7〜8月が繁忙期（だだちゃ豆・メロン等）のため単純年換算しない。
B10: 7. 作成日：2026年9月23日 初版
B11: 8. 更新：2026年10月19日 第2回面談（2026/10/16往訪・岡部社長）のメモ・文字起こしを反映。回答状況・社内限のプロセス事項は「その他」シートに集約。
B13: ■ 企業概要書への貼付範囲一覧（IM→セクション）
B14: 作り方：①転記→②IMシートの貼付範囲を確認→③範囲をコピー→④概要書の該当ページへ貼り付け→⑤リード文・Commentを記入。業種により不要なページは削除、必要なページ（商流・生産サイクル等）は追加する。
B15: PLハイライト!B4:F25 → 財務ハイライト（P/L）
... B36: 会社概要!B4:C17 → 基本情報

Sheet 財務入力→

Sheet BS(借方)
A1: 貸借対照表（資産の部）
A2: 単位：千円（入力は円）
B4: 勘定科目 | C4: 2024年3月期 (第51期) | D4: 2025年3月期 (第52期) | E4: 2026年3月期 (第53期) | F4: （4期目） | G4: 2026年7月 (試算表)
B5: 【流動資産】
B6: 現金及び預金 | C6: 339552632 | D6: 259719301 | E6: 210887077 | G6: 162087296
B7: 売掛金 | C7: 21171056 | D7: 21896538 | E7: 19608899 | G7: 40586984
B8: 資材肥料売掛金 | C8: 1352474 | D8: 1269087 | E8: 1227419 | G8: 2365307
B9: 棚卸資産 | C9: 9859795 | D9: 15443609 | E9: 14596695 | G9: 36647736
B10: 立替金 | C10: 96860 | D10: 6400 | E10: 0 | G10: 0
B11: 未収入金 | C11: 3684415 | D11: 3905410 | E11: 3011112 | G11: 2664958
B12: 前払費用 | C12: 108779 | D12: 96162 | E12: 83575 | G12: 101324
B13: 仮払金 | C13: 0 | D13: 0 | E13: 493135 | G13: 0
B14: 仮払税金等 | C14: 0 | D14: 998300 | E14: 0 | G14: 0
B15: 貸倒引当金 | C15: -237000 | D15: -234000 | E15: -203000 | G15: -203000
B16: 流動資産計 | C16: =SUM(C6:C15) -> 375589011 | D16: =SUM(D6:D15) -> 303100807 | E16: =SUM(E6:E15) -> 249704912 | F16: =SUM(F6:F15) -> 0 | G16: =SUM(G6:G15) -> 244250605
B17: 【有形固定資産】
B18: 建物 | C18: 101161720 | D18: 95851274 | E18: 92065694 | G18: 92065694
B19: 建物付属設備 | C19: 15416918 | D19: 13503020 | E19: 11399836 | G19: 11399836
B20: 構築物 | C20: 382601 | D20: 333498 | E20: 284395 | G20: 284395
B21: 機械装置 | C21: 133566 | D21: 2 | E21: 2 | G21: 2
B22: 車両運搬具 | C22: 5837529 | D22: 1281878 | E22: 15 | G22: 15
B23: 工具器具備品 | C23: 287873 | D23: 153209 | E23: 18546 | G23: 18546
B24: 土地 | C24: 93137240 | D24: 93137240 | E24: 93137240 | G24: 93137240
B25: 減価償却累計額（期中計上分） | C25: 0 | D25: 0 | E25: 0 | G25: -2436000
B26: 有形固定資産計 | C26: =SUM(C18:C25) -> 216357447 | D26: =SUM(D18:D25) -> 204260121 | E26: =SUM(E18:E25) -> 196905728 | F26: =SUM(F18:F25) -> 0 | G26: =SUM(G18:G25) -> 194469728
B27: 【無形固定資産】
B28: 電話加入権 | C28: 2155595 | D28: 2155595 | E28: 2155595 | G28: 2155595
B29: ソフトウェア | C29: 715000 | D29: 543400 | E29: 371800 | G29: 371800
B30: 無形固定資産計 | C30: =SUM(C28:C29) -> 2870595 | D30: =SUM(D28:D29) -> 2698995 | E30: =SUM(E28:E29) -> 2527395 | F30: =SUM(F28:F29) -> 0 | G30: =SUM(G28:G29) -> 2527395
B31: 【投資その他の資産】
B32: 投資有価証券 | C32: 3250000 | D32: 3250000 | E32: 2600000 | G32: 1600000
B33: 出資金 | C33: 75000 | D33: 75000 | E33: 75000 | G33: 75000
B34: 長期前払費用 | C34: 397411 | D34: 74500 | E34: 74500 | G34: 74500
B35: 保証金 | C35: 32002569 | D35: 33002569 | E35: 33302569 | G35: 33302569
B36: 事業保険積立金 | C36: 21161692 | D36: 20900138 | E36: 0 | G36: 0
B37: 投資その他の資産計 | C37: =SUM(C32:C36) -> 56886672 | D37: =SUM(D32:D36) -> 57302207 | E37: =SUM(E32:E36) -> 36052069 | F37: =SUM(F32:F36) -> 0 | G37: =SUM(G32:G36) -> 35052069
B38: 固定資産計 | C38: =C26+C30+C37 -> 276114714 | D38: =D26+D30+D37 -> 264261323 | E38: =E26+E30+E37 -> 235485192 | F38: =F26+F30+F37 -> 0 | G38: =G26+G30+G37 -> 232049192
B39: 繰延資産 | C39: 243834 | D39: 166834 | E39: 0 | G39: 0
B40: 資産の部合計 | C40: =C16+C38+C39 -> 651947559 | D40: =D16+D38+D39 -> 567528964 | E40: =E16+E38+E39 -> 485190104 | F40: =F16+F38+F39 -> 0 | G40: =G16+G38+G39 -> 476299797
B42: 決算書記載の資産合計 | C42: 651947559 | D42: 567528964 | E42: 485190104 | G42: 476299797
...

Sheet BS (貸方)
A1: 貸借対照表（負債・純資産の部）
A2: 単位：千円（入力は円）
B4: 勘定科目 | C4: 2024年3月期 (第51期) | D4: 2025年3月期 (第52期) | E4: 2026年3月期 (第53期) | F4: （4期目） | G4: 2026年7月 (試算表)
B5: 【流動負債】
B6: 買掛金 | C6: 18127739 | D6: 19954920 | E6: 26349122 | G6: 32102162
B7: 未払金 | C7: 10198849 | D7: 7302614 | E7: 6630301 | G7: 3999712
B8: 仮受金 | C8: 0 | D8: 0 | E8: 0 | G8: 5641499
B9: 預り金 | C9: 504234 | D9: 557594 | E9: 281300 | G9: 196956
B10: 未払法人税等 | C10: 2308000 | D10: 33900 | E10: 1851300 | G10: 0
B11: 未払消費税 | C11: 2970400 | D11: 1606700 | E11: 2167500 | G11: 3760000
B12: 流動負債計 | C12: =SUM(C6:C11) -> 34109222 | D12: =SUM(D6:D11) -> 29455728 | E12: =SUM(E6:E11) -> 37279523 | F12: =SUM(F6:F11) -> 0 | G12: =SUM(G6:G11) -> 45700329
B13: 【固定負債】
B14: 長期借入金 | C14: 514690000 | D14: 434046000 | E14: 361058000 | G14: 337862000
B15: 預り保証金 | C15: 10320000 | D15: 10270000 | E15: 8980000 | G15: 8980000
B16: 固定負債計 | C16: =SUM(C14:C15) -> 525010000 | D16: =SUM(D14:D15) -> 444316000 | E16: =SUM(E14:E15) -> 370038000 | F16: =SUM(F14:F15) -> 0 | G16: =SUM(G14:G15) -> 346842000
B17: 負債の部合計 | C17: =C12+C16 -> 559119222 | D17: =D12+D16 -> 473771728 | E17: =E12+E16 -> 407317523 | F17: =F12+F16 -> 0 | G17: =G12+G16 -> 392542329
B18: 【純資産】
B19: 資本金 | C19: 40000000 | D19: 40000000 | E19: 40000000 | G19: 40000000
B20: 利益準備金 | C20: 1800000 | D20: 2000000 | E20: 2080000 | G20: 2080000
B21: 繰越利益剰余金 | C21: 51028337 | D21: 51757236 | E21: 35792581 | G21: 41677468
B22: 純資産の部合計 | C22: =SUM(C19:C21) -> 92828337 | D22: =SUM(D19:D21) -> 93757236 | E22: =SUM(E19:E21) -> 77872581 | F22: =SUM(F19:F21) -> 0 | G22: =SUM(G19:G21) -> 83757468
B23: 負債・純資産の部合計 | C23: =C17+C22 -> 651947559 | D23: =D17+D22 -> 567528964 | E23: =E17+E22 -> 485190104 | F23: =F17+F22 -> 0 | G23: =G17+G22 -> 476299797
B25: ※2026年7月の買掛金は委託分6,457千円・仕入分25,126千円・資材分519千円の合計。長期借入金は1年内返済予定額を区分していない（要確認）。

Sheet SGA
A1: 販売費及び一般管理費
A2: 単位：千円（入力は円）／売上高比
B4: 勘定科目 | C4: 2024年3月期 (第51期) | D4: 売上比 | E4: 2025年3月期 (第52期) | F4: 売上比 | G4: 2026年3月期 (第53期) | H4: 売上比 | I4: 2026年7月 (試算表) | J4: 売上比
B5: 役員報酬 | C5: 22200000 | D5: =IFERROR(C5/PL!C$10,"") -> 0.01883768 | E5: 22200000 | F5: =IFERROR(E5/PL!E$10,"") -> 0.018782563 | G5: 15360000 | H5: =IFERROR(G5/PL!G$10,"") -> 0.012843956 | I5: 4730000 | J5: =IFERROR(I5/PL!I$10,"") -> 0.011504179
B6: 給料手当 | C6: 73148460 | D6: =IFERROR(C6/PL!C$10,"") -> 0.062069696 | E6: 74179162 | F6: =IFERROR(E6/PL!E$10,"") -> 0.062760124 | G6: 71673365 | H6: =IFERROR(G6/PL!G$10,"") -> 0.059932911 | I6: 19328747 | J6: =IFERROR(I6/PL!I$10,"") -> 0.047010858
B7: 賞与 | C7: 6002150 | D7: =IFERROR(C7/PL!C$10,"") -> 0.0050930891 | E7: 5692500 | F7: =IFERROR(E7/PL!E$10,"") -> 0.0048162044 | G7: 0 | H7: =IFERROR(G7/PL!G$10,"") -> 0 | I7: 0 | J7: =IFERROR(I7/PL!I$10,"") -> 0
B8: 退職金共済掛金 | C8: 3175000 | D8: =IFERROR(C8/PL!C$10,"") -> 0.0026941276 | E8: 3166000 | F8: =IFERROR(E8/PL!E$10,"") -> 0.0026786303 | G8: 3026000 | H8: =IFERROR(G8/PL!G$10,"") -> 0.0025303261 | I8: 769000 | J8: =IFERROR(I8/PL!I$10,"") -> 0.0018703411
B9: 退職金 | C9: 0 | D9: =IFERROR(C9/PL!C$10,"") -> 0 | E9: 356400 | F9: =IFERROR(E9/PL!E$10,"") -> 0.00030153628 | G9: 746960 | H9: =IFERROR(G9/PL!G$10,"") -> 0.00062460423 | I9: 0 | J9: =IFERROR(I9/PL!I$10,"") -> 0
B10: 法定福利費 | C10: 15154087 | D10: =IFERROR(C10/PL!C$10,"") -> 0.012858911 | E10: 14913183 | F10: =IFERROR(E10/PL!E$10,"") -> 0.012617468 | G10: 13295870 | H10: =IFERROR(G10/PL!G$10,"") -> 0.01111794 | I10: 3603031 | J10: =IFERROR(I10/PL!I$10,"") -> 0.0087631951
B11: 福利厚生費 | C11: 594849 | D11: =IFERROR(C11/PL!C$10,"") -> 0.00050475562 | E11: 899852 | F11: =IFERROR(E11/PL!E$10,"") -> 0.00076133003 | G11: 460243 | H11: =IFERROR(G11/PL!G$10,"") -> 0.00038485291 | I11: 95149 | J11: =IFERROR(I11/PL!I$10,"") -> 0.00023141884
B12: 広告宣伝費 | C12: 203020 | D12: =IFERROR(C12/PL!C$10,"") -> 0.00017227143 | E12: 114444 | F12: =IFERROR(E12/PL!E$10,"") -> 9.6826649e-05 | G12: 89300 | H12: =IFERROR(G12/PL!G$10,"") -> 7.4672216e-05 | I12: 10000 | J12: =IFERROR(I12/PL!I$10,"") -> 2.4321731e-05
B13: 旅費交通費 | C13: 44957 | D13: =IFERROR(C13/PL!C$10,"") -> 3.8147998e-05 | E13: 212048 | F13: =IFERROR(E13/PL!E$10,"") -> 0.00017940562 | G13: 78650 | H13: =IFERROR(G13/PL!G$10,"") -> 6.5766739e-05 | I13: 9490 | J13: =IFERROR(I13/PL!I$10,"") -> 2.3081323e-05
B14: 通信費 | C14: 1434812 | D14: =IFERROR(C14/PL!C$10,"") -> 0.0012175013 | E14: 1143086 | F14: =IFERROR(E14/PL!E$10,"") -> 0.00096712092 | G14: 1191701 | H14: =IFERROR(G14/PL!G$10,"") -> 0.00099649445 | I14: 296684 | J14: =IFERROR(I14/PL!I$10,"") -> 0.00072158684
B15: 車両関連費 | C15: 8475295 | D15: =IFERROR(C15/PL!C$10,"") -> 0.0071916618 | E15: 10126052 | F15: =IFERROR(E15/PL!E$10,"") -> 0.0085672615 | G15: 9861597 | H15: =IFERROR(G15/PL!G$10,"") -> 0.0082462183 | I15: 2954932 | J15: =IFERROR(I15/PL!I$10,"") -> 0.0071869061
B16: 運賃 | C16: 27546757 | D16: =IFERROR(C16/PL!C$10,"") -> 0.023374639 | E16: 29493733 | F16: =IFERROR(E16/PL!E$10,"") -> 0.024953509 | G16: 28996599 | H16: =IFERROR(G16/PL!G$10,"") -> 0.024246812 | I16: 8099852 | J16: =IFERROR(I16/PL!I$10,"") -> 0.019700242
... B32: 雑費 | C32: 4521805 | D32: =IFERROR(C32/PL!C$10,"") -> 0.0038369511 | E32: 4393320 | F32: =IFERROR(E32/PL!E$10,"") -> 0.0037170184 | G32: 4689970 | H32: =IFERROR(G32/PL!G$10,"") -> 0.0039217296 | I32: 1266623 | J32: =IFERROR(I32/PL!I$10,"") -> 0.0030806464
B33: 販売費及び一般管理費 計 | C33: =SUM(C5:C32) -> 214823441 | D33: =IFERROR(C33/PL!C$10,"") -> 0.18228717 | E33: =SUM(E5:E32) -> 215718454 | F33: =IFERROR(E33/PL!E$10,"") -> 0.18251105 | G33: =SUM(G5:G32) -> 193151054 | H33: =IFERROR(G33/PL!G$10,"") -> 0.16151195 | I33: =SUM(I5:I32) -> 55896593 | J33: =IFERROR(I33/PL!I$10,"") -> 0.13595019
B34: 決算書記載の販管費計 | C34: 214823441 | E34: 215718454 | G34: 193151054 | I34: 55896593
B35: チェック | C35: =EXACT(C33,C34) -> TRUE | E35: =EXACT(E33,E34) -> TRUE | G35: =EXACT(G33,G34) -> TRUE | I35: =EXACT(I33,I34) -> TRUE
B37: ※消費税等は税込方式のため、納付消費税相当は租税公課（決算）／消費税引当金（試算表）に計上されている。2026/3期は賞与の計上なし（要確認）。

Sheet PL
A1: 損益計算書
A2: 単位：千円（入力は円）／売上高比
B4: 勘定科目 | C4: 2024年3月期 (第51期) | D4: 売上比 | E4: 2025年3月期 (第52期) | F4: 売上比 | G4: 2026年3月期 (第53期) | H4: 売上比 | I4: 2026年7月 (試算表) | J4: 売上比
B5: 商品売上高 | C5: 1179974308 | D5: =IFERROR(C5/C$10,"") -> 1.0012603 | E5: 1183308630 | F5: =IFERROR(E5/E$10,"") -> 1.0011517 | G5: 1197530299 | H5: =IFERROR(G5/G$10,"") -> 1.0013689 | I5: 375960544 | J5: =IFERROR(I5/I$10,"") -> 0.91440112
B6: 資材売上高 | C6: 0 | D6: =IFERROR(C6/C$10,"") -> 0 | E6: 0 | F6: =IFERROR(E6/E$10,"") -> 0 | G6: 0 | H6: =IFERROR(G6/G$10,"") -> 0 | I6: 10820414 | J6: =IFERROR(I6/I$10,"") -> 0.02631712
B7: センター費収入 | C7: 0 | D7: =IFERROR(C7/C$10,"") -> 0 | E7: 0 | F7: =IFERROR(E7/E$10,"") -> 0 | G7: 0 | H7: =IFERROR(G7/G$10,"") -> 0 | I7: 12272629 | J7: =IFERROR(I7/I$10,"") -> 0.029849158
B8: 委託手数料収入 | C8: 0 | D8: =IFERROR(C8/C$10,"") -> 0 | E8: 0 | F8: =IFERROR(E8/E$10,"") -> 0 | G8: 0 | H8: =IFERROR(G8/G$10,"") -> 0 | I8: 12563500 | J8: =IFERROR(I8/I$10,"") -> 0.030556607
B9: 売上割戻 | C9: -1485210 | D9: =IFERROR(C9/C$10,"") -> -0.0012602662 | E9: -1361290 | F9: =IFERROR(E9/E$10,"") -> -0.0011517349 | G9: -1637030 | H9: =IFERROR(G9/G$10,"") -> -0.0013688763 | I9: -462140 | J9: =IFERROR(I9/I$10,"") -> -0.0011240045
B10: 売上高 | C10: =SUM(C5:C9) -> 1178489098 | D10: =IFERROR(C10/C$10,"") -> 1 | E10: =SUM(E5:E9) -> 1181947340 | F10: =IFERROR(E10/E$10,"") -> 1 | G10: =SUM(G5:G9) -> 1195893269 | H10: =IFERROR(G10/G$10,"") -> 1 | I10: =SUM(I5:I9) -> 411154947 | J10: =IFERROR(I10/I$10,"") -> 1
B11: 期首棚卸高 | C11: 15470384 | D11: =IFERROR(C11/C$10,"") -> 0.013127303 | E11: 9859795 | F11: =IFERROR(E11/E$10,"") -> 0.0083419918 | G11: 15443609 | H11: =IFERROR(G11/G$10,"") -> 0.012913869 | I11: 14596695 | J11: =IFERROR(I11/I$10,"") -> 0.035501689
B12: 当期仕入高 | C12: 953298320 | D12: =IFERROR(C12/C$10,"") -> 0.80891569 | E12: 976235640 | F12: =IFERROR(E12/E$10,"") -> 0.82595527 | G12: 996035389 | H12: =IFERROR(G12/G$10,"") -> 0.83287984 | I12: 371992415 | J12: =IFERROR(I12/I$10,"") -> 0.90474994
B13: 期末棚卸高 | C13: -9859795 | D13: =IFERROR(C13/C$10,"") -> -0.0083664711 | E13: -15443609 | F13: =IFERROR(E13/E$10,"") -> -0.013066241 | G13: -14596695 | H13: =IFERROR(G13/G$10,"") -> -0.012205684 | I13: -36647736 | J13: =IFERROR(I13/I$10,"") -> -0.089133637
B14: 売上原価 | C14: =SUM(C11:C13) -> 958908909 | D14: =IFERROR(C14/C$10,"") -> 0.81367652 | E14: =SUM(E11:E13) -> 970651826 | F14: =IFERROR(E14/E$10,"") -> 0.82123103 | G14: =SUM(G11:G13) -> 996882303 | H14: =IFERROR(G14/G$10,"") -> 0.83358802 | I14: =SUM(I11:I13) -> 349941374 | J14: =IFERROR(I14/I$10,"") -> 0.85111799
B15: 売上総利益 | C15: =C10-C14 -> 219580189 | D15: =IFERROR(C15/C$10,"") -> 0.18632348 | E15: =E10-E14 -> 211295514 | F15: =IFERROR(E15/E$10,"") -> 0.17876897 | G15: =G10-G14 -> 199010966 | H15: =IFERROR(G15/G$10,"") -> 0.16641198 | I15: =I10-I14 -> 61213573 | J15: =IFERROR(I15/I$10,"") -> 0.14888201
B16: 販売費及び一般管理費 | C16: =SGA!C33 -> 214823441 | D16: =IFERROR(C16/C$10,"") -> 0.18228717 | E16: =SGA!E33 -> 215718454 | F16: =IFERROR(E16/E$10,"") -> 0.18251105 | G16: =SGA!G33 -> 193151054 | H16: =IFERROR(G16/G$10,"") -> 0.16151195 | I16: =SGA!I33 -> 55896593 | J16: =IFERROR(I16/I$10,"") -> 0.13595019
B17: 営業利益 | C17: =C15-C16 -> 4756748 | D17: =IFERROR(C17/C$10,"") -> 0.0040363106 | E17: =E15-E16 -> -4422940 | F17: =IFERROR(E17/E$10,"") -> -0.0037420787 | G17: =G15-G16 -> 5859912 | H17: =IFERROR(G17/G$10,"") -> 0.0049000293 | I17: =I15-I16 -> 5316980 | J17: =IFERROR(I17/I$10,"") -> 0.012931816
B18: 受取利息 | C18: 1252 | D18: =IFERROR(C18/C$10,"") -> 1.0623772e-06 | E18: 84858 | F18: =IFERROR(E18/E$10,"") -> 7.1795077e-05 | G18: 267463 | H18: =IFERROR(G18/G$10,"") -> 0.00022365123 | I18: 0 | J18: =IFERROR(I18/I$10,"") -> 0
B19: 受取配当金 | C19: 30500 | D19: =IFERROR(C19/C$10,"") -> 2.5880596e-05 | E19: 30500 | F19: =IFERROR(E19/E$10,"") -> 2.5804872e-05 | G19: 30500 | H19: =IFERROR(G19/G$10,"") -> 2.5503948e-05 | I19: 30950 | J19: =IFERROR(I19/I$10,"") -> 7.5275757e-05
B20: 受取奨励金 | C20: 2284370 | D20: =IFERROR(C20/C$10,"") -> 0.0019383887 | E20: 2406729 | F20: =IFERROR(E20/E$10,"") -> 0.0020362405 | G20: 2513377 | H20: =IFERROR(G20/G$10,"") -> 0.0021016733 | I20: 652788 | J20: =IFERROR(I20/I$10,"") -> 0.0015876934
B21: 受取延滞料 | C21: 170242 | D21: =IFERROR(C21/C$10,"") -> 0.00014445785 | E21: 147416 | F21: =IFERROR(E21/E$10,"") -> 0.00012472298 | G21: 96879 | H21: =IFERROR(G21/G$10,"") -> 8.1009738e-05 | I21: 51327 | J21: =IFERROR(I21/I$10,"") -> 0.00012483615
B22: 受取運賃・配達収入 | C22: 0 | D22: =IFERROR(C22/C$10,"") -> 0 | E22: 0 | F22: =IFERROR(E22/E$10,"") -> 0 | G22: 0 | H22: =IFERROR(G22/G$10,"") -> 0 | I22: 49500 | J22: =IFERROR(I22/I$10,"") -> 0.00012039257
B23: 雑収入 | C23: 8141731 | D23: =IFERROR(C23/C$10,"") -> 0.006908618 | E23: 8067387 | F23: =IFERROR(E23/E$10,"") -> 0.0068255046 | G23: 3669539 | H23: =IFERROR(G23/G$10,"") -> 0.0030684502 | I23: 976086 | J23: =IFERROR(I23/I$10,"") -> 0.0023740101
B24: 営業外収益計 | C24: =SUM(C18:C23) -> 10628095 | D24: =IFERROR(C24/C$10,"") -> 0.0090184076 | E24: =SUM(E18:E23) -> 10736890 | F24: =IFERROR(E24/E$10,"") -> 0.009084068 | G24: =SUM(G18:G23) -> 6577758 | H24: =IFERROR(G24/G$10,"") -> 0.0055002885 | I24: =SUM(I18:I23) -> 1760651 | J24: =IFERROR(I24/I$10,"") -> 0.004282208
B25: 支払利息 | C25: 3962441 | D25: =IFERROR(C25/C$10,"") -> 0.003362306 | E25: 4040547 | F25: =IFERROR(E25/E$10,"") -> 0.0034185508 | G25: 3895556 | H25: =IFERROR(G25/G$10,"") -> 0.0032574445 | I25: 1192744 | J25: =IFERROR(I25/I$10,"") -> 0.0029009599
B26: 出荷奨励金 | C26: 105862 | D26: =IFERROR(C26/C$10,"") -> 8.9828578e-05 | E26: 92022 | F26: =IFERROR(E26/E$10,"") -> 7.785626e-05 | G26: 94929 | H26: =IFERROR(G26/G$10,"") -> 7.9379157e-05 | I26: 0 | J26: =IFERROR(I26/I$10,"") -> 0
B27: 雑損失 | C27: 0 | D27: =IFERROR(C27/C$10,"") -> 0 | E27: 0 | F27: =IFERROR(E27/E$10,"") -> 0 | G27: 379401 | H27: =IFERROR(G27/G$10,"") -> 0.00031725323 | I27: 0 | J27: =IFERROR(I27/I$10,"") -> 0
B28: 営業外費用計 | C28: =SUM(C25:C27) -> 4068303 | D28: =IFERROR(C28/C$10,"") -> 0.0034521346 | E28: =SUM(E25:E27) -> 4132569 | F28: =IFERROR(E28/E$10,"") -> 0.003496407 | G28: =SUM(G25:G27) -> 4369886 | H28: =IFERROR(G28/G$10,"") -> 0.0036540769 | I28: =SUM(I25:I27) -> 1192744 | J28: =IFERROR(I28/I$10,"") -> 0.0029009599
B29: 経常利益 | C29: =C17+C24-C28 -> 11316540 | D29: =IFERROR(C29/C$10,"") -> 0.0096025835 | E29: =E17+E24-E28 -> 2181381 | F29: =IFERROR(E29/E$10,"") -> 0.0018455822 | G29: =G17+G24-G28 -> 8067784 | H29: =IFERROR(G29/G$10,"") -> 0.0067462408 | I29: =I17+I24-I28 -> 5884887 | J29: =IFERROR(I29/I$10,"") -> 0.014313064
B30: 固定資産売却益 | C30: 1711177 | D30: =IFERROR(C30/C$10,"") -> 0.0014520092 | E30: 1608918 | F30: =IFERROR(E30/E$10,"") -> 0.0013612434 | G30: 0 | H30: =IFERROR(G30/G$10,"") -> 0 | I30: 0 | J30: =IFERROR(I30/I$10,"") -> 0
B31: 貸倒引当金戻入 | C31: 176000 | D31: =IFERROR(C31/C$10,"") -> 0.00014934377 | E31: 237000 | F31: =IFERROR(E31/E$10,"") -> 0.00020051655 | G31: 234000 | H31: =IFERROR(G31/G$10,"") -> 0.00019566964 | I31: 0 | J31: =IFERROR(I31/I$10,"") -> 0
B32: 特別利益計 | C32: =SUM(C30:C31) -> 1887177 | D32: =IFERROR(C32/C$10,"") -> 0.001601353 | E32: =SUM(E30:E31) -> 1845918 | F32: =IFERROR(E32/E$10,"") -> 0.0015617599 | G32: =SUM(G30:G31) -> 234000 | H32: =IFERROR(G32/G$10,"") -> 0.00019566964 | I32: =SUM(I30:I31) -> 0 | J32: =IFERROR(I32/I$10,"") -> 0
B33: 固定資産売却除却損 | C33: 201719 | D33: =IFERROR(C33/C$10,"") -> 0.00017116747 | E33: 0 | F33: =IFERROR(E33/E$10,"") -> 0 | G33: 1 | H33: =IFERROR(G33/G$10,"") -> 8.3619502e-10 | I33: 0 | J33: =IFERROR(I33/I$10,"") -> 0
B34: 貸倒引当金繰入 | C34: 237000 | D34: =IFERROR(C34/C$10,"") -> 0.00020110496 | E34: 234000 | F34: =IFERROR(E34/E$10,"") -> 0.00019797836 | G34: 203000 | H34: =IFERROR(G34/G$10,"") -> 0.00016974759 | I34: 0 | J34: =IFERROR(I34/I$10,"") -> 0
B35: 前期損益修正損 | C35: 0 | D35: =IFERROR(C35/C$10,"") -> 0 | E35: 0 | F35: =IFERROR(E35/E$10,"") -> 0 | G35: 20900138 | H35: =IFERROR(G35/G$10,"") -> 0.017476591 | I35: 0 | J35: =IFERROR(I35/I$10,"") -> 0
B36: 特別損失計 | C36: =SUM(C33:C35) -> 438719 | D36: =IFERROR(C36/C$10,"") -> 0.00037227243 | E36: =SUM(E33:E35) -> 234000 | F36: =IFERROR(E36/E$10,"") -> 0.00019797836 | G36: =SUM(G33:G35) -> 21103139 | H36: =IFERROR(G36/G$10,"") -> 0.01764634 | I36: =SUM(I33:I35) -> 0 | J36: =IFERROR(I36/I$10,"") -> 0
B37: 税引前当期純利益 | C37: =C29+C32-C36 -> 12764998 | D37: =IFERROR(C37/C$10,"") -> 0.010831664 | E37: =E29+E32-E36 -> 3793299 | F37: =IFERROR(E37/E$10,"") -> 0.0032093638 | G37: =G29+G32-G36 -> -12801355 | H37: =IFERROR(G37/G$10,"") -> -0.010704429 | I37: =I29+I32-I36 -> 5884887 | J37: =IFERROR(I37/I$10,"") -> 0.014313064
B38: 法人税等 | C38: 3658100 | D38: =IFERROR(C38/C$10,"") -> 0.0031040593 | E38: 864400 | F38: =IFERROR(E38/E$10,"") -> 0.00073133546 | G38: 2283300 | H38: =IFERROR(G38/G$10,"") -> 0.0019092841 | I38: 0 | J38: =IFERROR(I38/I$10,"") -> 0
B39: 当期純利益 | C39: =C37-C38 -> 9106898 | D39: =IFERROR(C39/C$10,"") -> 0.0077276048 | E39: =E37-E38 -> 2928899 | F39: =IFERROR(E39/E$10,"") -> 0.0024780283 | G39: =G37-G38 -> -15084655 | H39: =IFERROR(G39/G$10,"") -> -0.012613713 | I39: =I37-I38 -> 5884887 | J39: =IFERROR(I39/I$10,"") -> 0.014313064
B41: チェック：営業利益 | C41: =EXACT(C17,4756748) -> TRUE | E41: =EXACT(E17,-4422940) -> TRUE | G41: =EXACT(G17,5859912) -> TRUE | I41: =EXACT(I17,5316980) -> TRUE
B42: チェック：当期純利益 | C42: =EXACT(C39,9106898) -> TRUE | E42: =EXACT(E39,2928899) -> TRUE | G42: =EXACT(G39,-15084655) -> TRUE | I42: =EXACT(I39,5884887) -> TRUE
...

Sheet VR→

Sheet 修正PL
A1: 修正PL（正常収益力の算定）
A2: 単位：千円（入力は円）。営業利益ベースで調整。概要書の調整後EBITDAも本シートを参照する
B4: 項目 | C4: 2024年3月期 (第51期) | D4: 2025年3月期 (第52期) | E4: 2026年3月期 (第53期) | F4: 調整事由
B5: 営業利益（帳簿） | C5: =PL!C17 -> 4756748 | D5: =PL!E17 -> -4422940 | E5: =PL!G17 -> 5859912
B6: （前提）社会保険料率 | C6: 0.15
B7: （前提）代表者及びその家族分の役員報酬（実績） | C7: 10680000 | D7: 10680000 | E7: 4440000 | F7: 勘定科目内訳書「人件費の内訳」（代表取締役・取締役〔配偶者〕）
B8: （前提）新体制の役員報酬（仮定） | C8: 8000000 | D8: 8000000 | E8: 8000000 | F8: （仮定）買手からの派遣役員等を年8,000千円と想定
B9: ①役員報酬の正常化（社保込） | C9: =(C7-C8)*(1+$C$6) -> 3082000 | D9: =(D7-D8)*(1+$C$6) -> 3082000 | E9: =(E7-E8)*(1+$C$6) -> -4094000 | F9: 退任予定と想定する代表者・配偶者の報酬を控除し、新体制の報酬に置換。社会保険料も概算15%で連動。常務取締役（2026/5退任）の後任要否は要確認のため対象外
B10: ②賞与の正常化（社保込） | C10: =0 -> 0 | D10: =0 -> 0 | E10: =-AVERAGE(SGA!C7,SGA!E7)*(1+$C$6) -> -6724423.8 | F10: 2026/3期は賞与計上なし。前2期平均相当を費用計上（仮説：支給再開を前提。不支給の経緯は要確認）
B11: ③寄付金の加算 | C11: =SGA!C26 -> 13000 | D11: =SGA!E26 -> 71000 | E11: =SGA!G26 -> 11000 | F11: 譲渡後に発生しない費用として加算
B12: ④受取奨励金（純額）の加算 | C12: =PL!C20-PL!C26 -> 2178508 | D12: =PL!E20-PL!E26 -> 2314707 | E12: =PL!G20-PL!G26 -> 2418448 | F12: 営業外に計上されているが、仕入完納等に伴い毎期経常的に発生する事業関連収益（受取奨励金−出荷奨励金）
B13: 修正額 計 | C13: =SUM(C9:C12) -> 5273508 | D13: =SUM(D9:D12) -> 5467707 | E13: =SUM(E9:E12) -> -8388975.8
B14: 修正後営業利益 | C14: =C5+C13 -> 10030256 | D14: =D5+D13 -> 1044767 | E14: =E5+E13 -> -2529063.8
B15: （前提）実効税率 | C15: 0.34
B16: 税考慮額 | C16: =-C14*$C$15 -> -3410287 | D16: =-D14*$C$15 -> -355220.78 | E16: =-E14*$C$15 -> 859881.68
B17: 修正後税考慮後営業利益 | C17: =C14+C16 -> 6619969 | D17: =D14+D16 -> 689546.22 | E17: =E14+E16 -> -1669182.1
B18: 減価償却費 | C18: =SGA!C31 -> 13663684 | D18: =SGA!E31 -> 12557564 | E18: =SGA!G31 -> 8878970
B19: 修正後EBITDA | C19: =C14+C18 -> 23693940 | D19: =D14+D18 -> 13602331 | E19: =E14+E18 -> 6349906.2
B20: 加重（前々期：前期：直近期） | C20: 0.2 | D20: 0.3 | E20: 0.5
B21: 基準営業利益（税考慮後・加重平均） | E21: =SUMPRODUCT(C17:E17,C20:E20) -> 696266.62
B22: 基準EBITDA（加重平均） | E22: =SUMPRODUCT(C19:E19,C20:E20) -> 11994440
B24: ※支払利息は営業外費用のため営業利益ベースの正常収益力には含まれない（債権者への分配前の収益として算定）。
B25: ※前期損益修正損（保険解約訂正）・固定資産売却損益・貸倒引当金繰入/戻入は特別損益のため対象外（非経常）。
B26: ※雑収入（ゴミ処理料・冷蔵庫保管料等の経常部分を含む）は内容の区分資料がないため加算していない（要確認。加算余地あり）。
B27: ※支払保険料・接待交際費にオーナー個人に帰属する費用が含まれるかは未確認（要確認）。

Sheet 修正BS
A1: 修正BS（時価純資産の算定）
A2: 評価基準日：2026年3月31日（2026/3期末貸借対照表）。単位：千円（入力は円）
B4: 科目 | C4: 帳簿価額 | D4: 修正額 | E4: 修正後 | F4: 修正事由／評価方法
B5: 現金及び預金 | C5: ='BS(借方)'!E6 -> 210887077 | D5: 0 | E5: =C5+D5 -> 210887077 | F5: 残高証明書との照合は未了（簿価評価）
B6: 売掛金 | C6: ='BS(借方)'!E7 -> 19608899 | D6: 0 | E6: =C6+D6 -> 19608899 | F6: 年齢表未受領のため簿価評価（長期滞留の有無は要確認）
B7: 資材肥料売掛金 | C7: ='BS(借方)'!E8 -> 1227419 | D7: 0 | E7: =C7+D7 -> 1227419 | F7: 同上
B8: 棚卸資産 | C8: ='BS(借方)'!E9 -> 14596695 | D8: 0 | E8: =C8+D8 -> 14596695 | F8: 青果物は短期回転。資材（パック・容器）の滞留有無は要確認（簿価評価）
B9: 立替金 | C9: ='BS(借方)'!E10 -> 0 | D9: 0 | E9: =C9+D9 -> 0 | F9: 簿価評価
B10: 未収入金 | C10: ='BS(借方)'!E11 -> 3011112 | D10: 0 | E10: =C10+D10 -> 3011112 | F10: センター費・完納奨励金等。簿価評価
B11: 前払費用 | C11: ='BS(借方)'!E12 -> 83575 | D11: 0 | E11: =C11+D11 -> 83575 | F11: 簿価評価
B12: 仮払金 | C12: ='BS(借方)'!E13 -> 493135 | D12: 0 | E12: =C12+D12 -> 493135 | F12: 簿価評価
B13: 仮払税金等 | C13: ='BS(借方)'!E14 -> 0 | D13: 0 | E13: =C13+D13 -> 0 | F13: 簿価評価
B14: 貸倒引当金 | C14: ='BS(借方)'!E15 -> -203000 | D14: =-C14 -> 203000 | E14: =C14+D14 -> 0 | F14: 個別に回収可能性を判断するため全額戻入（貸倒実績は要確認）
B15: 建物 | C15: ='BS(借方)'!E18 -> 92065694 | D15: 0 | E15: =C15+D15 -> 92065694 | F15: 固定資産台帳未受領のため簿価評価（定額法で償却不足なし：別表十六）。固定資産税評価額は47,062千円
B16: 建物付属設備 | C16: ='BS(借方)'!E19 -> 11399836 | D16: 0 | E16: =C16+D16 -> 11399836 | F16: 簿価評価
B17: 構築物 | C17: ='BS(借方)'!E20 -> 284395 | D17: 0 | E17: =C17+D17 -> 284395 | F17: 簿価評価
B18: 機械装置 | C18: ='BS(借方)'!E21 -> 2 | D18: 0 | E18: =C18+D18 -> 2 | F18: 簿価評価
B19: 車両運搬具 | C19: ='BS(借方)'!E22 -> 15 | D19: 0 | E19: =C19+D19 -> 15 | F19: 簿価評価
B20: 工具器具備品 | C20: ='BS(借方)'!E23 -> 18546 | D20: 0 | E20: =C20+D20 -> 18546 | F20: 簿価評価
B21: 土地 | C21: ='BS(借方)'!E24 -> 93137240 | D21: =47477508/0.7-C21 -> -25312229 | E21: =C21+D21 -> 67825011 | F21: 固定資産税評価額（R8年度）47,478千円÷0.7で時価を推計（鑑定・路線価で要確認）
B22: 電話加入権 | C22: ='BS(借方)'!E28 -> 2155595 | D22: =-C22 -> -2155595 | E22: =C22+D22 -> 0 | F22: 換金価値なしとしてゼロ評価
B23: ソフトウェア | C23: ='BS(借方)'!E29 -> 371800 | D23: 0 | E23: =C23+D23 -> 371800 | F23: 簿価評価
B24: 投資有価証券 | C24: ='BS(借方)'!E32 -> 2600000 | D24: 7242000 | E24: =C24+D24 -> 9842000 | F24: フィデアHD株式3,000株を2026/9/18終値2,814円で時価評価（算定日終値で要更新）。(株)庄果株式・鶴岡信金出資は簿価
B25: 出資金 | C25: ='BS(借方)'!E33 -> 75000 | D25: 0 | E25: =C25+D25 -> 75000 | F25: 簿価評価
B26: 長期前払費用 | C26: ='BS(借方)'!E34 -> 74500 | D26: 0 | E26: =C26+D26 -> 74500 | F26: 簿価評価（僅少）
B27: 保証金 | C27: ='BS(借方)'!E35 -> 33302569 | D27: 0 | E27: =C27+D27 -> 33302569 | F27: 庄内青果物卸売精算(有)31,993千円ほか。返還条件未確認のため簿価評価（要確認）
B28: 事業保険積立金 | C28: ='BS(借方)'!E36 -> 0 | D28: 0 | E28: =C28+D28 -> 0 | F28: 2026/3期に全額取崩し済
B29: 繰延資産 | C29: ='BS(借方)'!E39 -> 0 | D29: 0 | E29: =C29+D29 -> 0
B30: 資産合計 | C30: =SUM(C5:C29) -> 485190104 | D30: =SUM(D5:D29) -> -20022824 | E30: =SUM(E5:E29) -> 4.6516728e+08
B31: 買掛金 | C31: ='BS (貸方)'!E6 -> 26349122 | D31: 0 | E31: =C31+D31 -> 26349122 | F31: 簿価評価
B32: 未払金 | C32: ='BS (貸方)'!E7 -> 6630301 | D32: 0 | E32: =C32+D32 -> 6630301 | F32: 3/16〜3/31の未払給与2,837千円は計上済のため追加計上なし
B33: 仮受金 | C33: ='BS (貸方)'!E8 -> 0 | D33: 0 | E33: =C33+D33 -> 0 | F33: 簿価評価
B34: 預り金 | C34: ='BS (貸方)'!E9 -> 281300 | D34: 0 | E34: =C34+D34 -> 281300 | F34: 簿価評価
B35: 未払法人税等 | C35: ='BS (貸方)'!E10 -> 1851300 | D35: 0 | E35: =C35+D35 -> 1851300 | F35: 簿価評価
B36: 未払消費税 | C36: ='BS (貸方)'!E11 -> 2167500 | D36: 0 | E36: =C36+D36 -> 2167500 | F36: 簿価評価
B37: 長期借入金 | C37: ='BS (貸方)'!E14 -> 361058000 | D37: 0 | E37: =C37+D37 -> 361058000 | F37: 1年内返済額の区分なし。額面で評価
B38: 預り保証金 | C38: ='BS (貸方)'!E15 -> 8980000 | D38: 0 | E38: =C38+D38 -> 8980000 | F38: 仲卸業者・買参人等からの預りと推察。返還義務ありとして額面評価
B39: 賞与引当金 | C39: 0 | D39: 0 | E39: =C39+D39 -> 0 | F39: 2026/3期は賞与支給なし・規程未受領のため計上せず（要確認）
B40: 退職給付引当金 | C40: 0 | D40: 0 | E40: =C40+D40 -> 0 | F40: 中小企業退職金共済に加入（掛金3,026千円/年）。外部積立で充足と推定し計上せず（退職金規程で要確認）
B41: 繰延税金負債（税効果） | C41: 0 | D41: =(D14+D24)*0.34 -> 2531300 | E41: =C41+D41 -> 2531300 | F41: 貸倒引当金戻入・有価証券評価益に実効税率34%で税効果を認識。土地評価損・電話加入権は売却予定がなく実現可能性が低いため認識しない
...

Sheet ネットキャッシュ
A1: ネットキャッシュ
A2: 評価基準日：2026年3月31日（修正後BS）。単位：千円（入力は円）
B4: 項目 | C4: 金額 | D4: 判断根拠
B5: 現金及び預金 | C5: =修正BS!E5 -> 210887077 | D5: 全額をキャッシュライクとする（運転資金は考慮しない）
B6: 投資有価証券（フィデアHD株式・時価） | C6: 8442000 | D6: 事業運営に供されていない上場株式。(株)庄果株式・信金出資は取引関係上の保有のため除外
B7: キャッシュライク 計 | C7: =C5+C6 -> 219329077
B8: 長期借入金 | C8: =修正BS!E37 -> 361058000 | D8: 有利子負債
B9: 未払法人税等 | C9: =修正BS!E35 -> 1851300
B10: デットライク 計 | C10: =C8+C9 -> 362909300
B11: ネットキャッシュ | C11: =C7-C10 -> -143580223
B13: ※預り保証金8,980千円・保証金33,303千円は事業上の預託・預り金としてネットキャッシュに含めていない（取扱いは要確認）。

Sheet 年買法
A1: 年買法（コストアプローチ）
A2: 想定株式価値＝時価純資産＋営業権（基準営業利益×倍率）。単位：千円（入力は円）
B4: 時価純資産 | C4: =修正BS!E43 -> 55318457
B5: 基準営業利益（税考慮後・加重平均） | C5: =修正PL!E21 -> 696266.62
B7: 営業権倍率 | C7: 1倍 | D7: 2倍 | E7: 3倍
B8: 倍率 | C8: 1 | D8: 2 | E8: 3
B9: 時価純資産 | C9: =$C$4 -> 55318457 | D9: =$C$4 -> 55318457 | E9: =$C$4 -> 55318457
B10: 営業権 | C10: =MAX($C$5,0)*C8 -> 696266.62 | D10: =MAX($C$5,0)*D8 -> 1392533.2 | E10: =MAX($C$5,0)*E8 -> 2088799.9
B11: 想定株式価値 | C11: =C9+C10 -> 56014724 | D11: =D9+D10 -> 56710991 | E11: =E9+E10 -> 57407257
B13: ※営業権倍率1〜3倍は国内中小企業M&Aのボリュームゾーン。基準営業利益がマイナスの場合は営業権ゼロ。
B15: （参考）賞与正常化を行わない場合の基準営業利益 | C15: =C5-修正PL!E10*(1-0.34)*0.5 -> 2915326.5
B16: （参考）想定株式価値 | C16: =$C$4+MAX($C$15,0)*C8 -> 58233784 | D16: =$C$4+MAX($C$15,0)*D8 -> 61149110 | E16: =$C$4+MAX($C$15,0)*E8 -> 64064437

Sheet EV EBITDAマルチプル
A1: EV/EBITDAマルチプル法（マーケットアプローチ）
A2: 想定株式価値＝基準EBITDA×倍率×(1−非流動性ディスカウント)＋ネットキャッシュ。単位：千円（入力は円）
B4: 基準EBITDA（加重平均） | C4: =修正PL!E22 -> 11994440
B5: ネットキャッシュ | C5: =ネットキャッシュ!C11 -> -143580223
B6: 非流動性ディスカウント | C6: 0.3
B8: マルチプル倍率 | C8: 3倍 | D8: 4倍 | E8: 5倍
B9: 倍率 | C9: 3 | D9: 4 | E9: 5
B10: EV（EBITDA×倍率） | C10: =$C$4*C9 -> 35983321 | D10: =$C$4*D9 -> 47977762 | E10: =$C$4*E9 -> 59972202
B11: 非流動性ディスカウント | C11: =-C10*$C$6 -> -10794996 | D11: =-D10*$C$6 -> -14393329 | E11: =-E10*$C$6 -> -17991661
B12: ネットキャッシュ | C12: =$C$5 -> -143580223 | D12: =$C$5 -> -143580223 | E12: =$C$5 -> -143580223
B13: 想定株式価値（算定値） | C13: =SUM(C10:C12) -> -1.183919e+08 | D13: =SUM(D10:D12) -> -1.0999579e+08 | E13: =SUM(E10:E12) -> -1.0159968e+08
B15: ※倍率3〜5倍は国内中小企業M&Aの実務水準。卸売市場関連の上場会社の倍率は算定日時点の株価で更新が必要（要確認）。
B16: ※算定値がマイナスの場合、ネットデット（有利子負債−現預金等）が事業価値を上回ることを示す。

Sheet 株式価値
A1: 株式価値の試算結果（集計）
A2: 単位：千円（入力は円）
B4: アプローチ | C4: 下限 | D4: 上限 | E4: 備考
B5: コストアプローチ（年買法） | C5: =年買法!C11 -> 56014724 | D5: =年買法!E11 -> 57407257 | E5: 営業権倍率1〜3倍
B6: マーケットアプローチ（EV/EBITDAマルチプル法） | C6: ='EV EBITDAマルチプル'!C13 -> -1.183919e+08 | D6: ='EV EBITDAマルチプル'!E13 -> -1.0159968e+08 | E6: EV/EBITDA3〜5倍、非流動性ディスカウント30%
B7: インカムアプローチ（DCF法） | E7: 不採用（詳細な事業計画が存在せず算定困難）

Sheet IM→

Sheet 会社概要
A1: 会社概要（基本情報）
A2: ■ 貼付範囲 B4:C17 → 企業概要書「基本情報」（範囲をコピーしてパワポに貼り付け。数字はここを直す）
B4: 項目 | C4: 内容
B5: 会社名 | C5: 株式会社鶴岡中央青果（http://www.turu-chu.co.jp/）
B6: 本社所在地 | C6: 山形県鶴岡市宝田一丁目4番20号
B7: 拠点 | C7: ① 本社・市場：山形県鶴岡市宝田一丁目4番20号 ② パッケージ場：山形県鶴岡市宝田一丁目5-1 ③ 旧倉庫敷地（駐車場）：山形県東田川郡庄内町長沼字宮前304-7
B8: 設立 | C8: 1973年（昭和48年）11月22日
B9: 資本金 | C9: =TEXT('BS (貸方)'!E19/1000,"#,##0")&"千円" -> 40,000千円
B10: 代表者 | C10: 岡部 寛
B11: 株主 | C11: ="岡部 寛（"&TEXT(株主!F6,"#,##0")&"株／"&TEXT(株主!G6,"0.0%")&"）ほか7名"&CHAR(10)&"代表者一族4名で"&TEXT(株主!G16,"0.0%")&"を保有" -> 岡部 寛（1,510株／37.8%）ほか7名 代表者一族4名で75.8%を保有
B12: 事業内容 | C12: ・青果物（野菜・果実）の卸売（地方卸売市場の開設・運営、買付販売・受託販売） ・パッケージ（小分け・包装）、配送（量販店の配送受託を含む） ・包装資材の販売
B13: 従業員数 | C13: =従業員!D32&"名（正社員"&従業員!D37&"名、嘱託・再雇用・試用3名、パート・アルバイト4名）"&CHAR(10)&"※2026年9月1日時点。別途、常勤役員2名" -> 24名（正社員17名、嘱託・再雇用・試用3名、パート・アルバイト4名） ※2026年9月1日時点。別途、常勤役員2名
B14: 許認可等 | C14: 地方卸売市場（卸売市場法）※認定の時期・条件は要確認
B15: 売上高 | C15: =TEXT(PL!G10/1000,"#,##0")&"千円（2026年3月期）" -> 1,195,893千円（2026年3月期）
B16: 調整後EBITDA | C16: =TEXT(PLハイライト!C43/1000,"#,##0")&"千円（過去3期平均）" -> 14,549千円（過去3期平均）
B17: 譲渡理由 | C17: 後継者不在およびさらなる企業の発展
B19: 参考（概要書非掲載の登記・基本事項）
B20: 発行済株式総数 | C20: 4,000株（発行可能株式総数5,000株、譲渡制限あり：取締役会の承認）
B21: 登記上の目的 | C21: 1 青果物の販売及び卸売の業務 2 倉庫業 3 前号に附帯する一切の業務
B22: 機関設計 | C22: 取締役会設置会社／監査役設置会社（監査の範囲を会計に限定）
B23: 決算期 | C23: 3月
B24: 営業時間／定休日 | C24: 5時〜（終業時刻は要確認）／水・日・祝日
B25: 主要取引金融機関 | C25: 鶴岡信用金庫、山形銀行、荘内銀行、日本政策金融公庫
B26: 顧問税理士 | C26: 池田昭一税理士事務所（山形県酒田市）
B27: Webサイト | C27: https://www.turu-chu.co.jp/（検索結果により存在を確認。法人事業概況説明書では「HPなし」と記載：要確認）

Sheet PLハイライト
A1: 財務ハイライト（P/L）・調整後EBITDA
A2: ■ 貼付範囲 B4:F25 → 企業概要書「財務ハイライト（P/L）」（範囲をコピーしてパワポに貼り付け。数字はここを直す）
F4: (単位：千円)
C5: 2024年3月期 | D5: 2025年3月期 | E5: 2026年3月期 | F5: 2026年4〜7月 | G5: 調整理由（概要書【調整項目】の原本）
B6: 売上高 | C6: =PL!C10 -> 1178489098 | D6: =PL!E10 -> 1181947340 | E6: =PL!G10 -> 1195893269 | F6: =PL!I10 -> 411154947
B7: 前期比 | C7: - | D7: =IFERROR(D6/C6,"") -> 1.0029345 | E7: =IFERROR(E6/D6,"") -> 1.0117991 | F7: =IFERROR(F6/C34,"") -> 0.98060271
B8: 売上総利益 | C8: =PL!C15 -> 219580189 | D8: =PL!E15 -> 211295514 | E8: =PL!G15 -> 199010966 | F8: =PL!I15 -> 61213573
B9: 利益率 | C9: =IFERROR(C8/C$6,"") -> 0.18632348 | D9: =IFERROR(D8/D$6,"") -> 0.17876897 | E9: =IFERROR(E8/E$6,"") -> 0.16641198 | F9: =IFERROR(F8/F$6,"") -> 0.14888201
B10: 営業利益 | C10: =PL!C17 -> 4756748 | D10: =PL!E17 -> -4422940 | E10: =PL!G17 -> 5859912 | F10: =PL!I17 -> 5316980
B11: 利益率 | C11: =IFERROR(C10/C$6,"") -> 0.0040363106 | D11: =IFERROR(D10/D$6,"") -> -0.0037420787 | E11: =IFERROR(E10/E$6,"") -> 0.0049000293 | F11: =IFERROR(F10/F$6,"") -> 0.012931816
B12: 経常利益 | C12: =PL!C29 -> 11316540 | D12: =PL!E29 -> 2181381 | E12: =PL!G29 -> 8067784 | F12: =PL!I29 -> 5884887
B13: 利益率 | C13: =IFERROR(C12/C$6,"") -> 0.0096025835 | D13: =IFERROR(D12/D$6,"") -> 0.0018455822 | E13: =IFERROR(E12/E$6,"") -> 0.0067462408 | F13: =IFERROR(F12/F$6,"") -> 0.014313064
B14: 税引後当期純利益 | C14: =PL!C39 -> 9106898 | D14: =PL!E39 -> 2928899 | E14: =PL!G39 -> -15084655 | F14: =PL!I39 -> 5884887
B15: 利益率 | C15: =IFERROR(C14/C$6,"") -> 0.0077276048 | D15: =IFERROR(D14/D$6,"") -> 0.0024780283 | E15: =IFERROR(E14/E$6,"") -> -0.012613713 | F15: =IFERROR(F14/F$6,"") -> 0.014313064
B17: 減価償却費 | C17: =SGA!C31 -> 13663684 | D17: =SGA!E31 -> 12557564 | E17: =SGA!G31 -> 8878970 | F17: =SGA!I31 -> 2436000
B19: 調整項目 合計 | C19: =SUM(C20:C23) -> 5273508 | D19: =SUM(D20:D23) -> 5467707 | E19: =SUM(E20:E23) -> -8388975.8 | F19: －
B20: ①役員報酬の正常化 | C20: =修正PL!C9 -> 3082000 | D20: =修正PL!D9 -> 3082000 | E20: =修正PL!E9 -> -4094000 | F20: － | G20: 代表者・配偶者の報酬を新体制の役員報酬（仮定8,000千円）に置換。社会保険料15%を連動
B21: ②賞与の正常化 | C21: =修正PL!C10 -> 0 | D21: =修正PL!D10 -> 0 | E21: =修正PL!E10 -> -6724423.8 | F21: － | G21: 賞与規定はなく業績に応じて支給（第2回面談）。2026/3期は支給なし。継続支給を前提に前2期平均（社保込）を控除（保守的に想定）
B22: ③受取奨励金（純額） | C22: =修正PL!C12 -> 2178508 | D22: =修正PL!D12 -> 2314707 | E22: =修正PL!E12 -> 2418448 | F22: － | G22: 仕入先市場から受け取る完納奨励金（期限内の代金支払に対する奨励金。保証金として積立：代表者談）。毎期経常的に発生するため加算
B23: ④寄付金 | C23: =修正PL!C11 -> 13000 | D23: =修正PL!D11 -> 71000 | E23: =修正PL!E11 -> 11000 | F23: － | G23: 譲渡後に発生しない費用として加算
B25: 調整後EBITDA | C25: =C10+C17+C19 -> 23693940 | D25: =D10+D17+D19 -> 13602331 | E25: =E10+E17+E19 -> 6349906.2 | F25: －
B33: 参考（リード文・コメント用の集計。貼付範囲外）
B34: 前年同期（2025年4〜7月）売上高 | C34: 419288000
B35: 売上総利益率 | C35: =IFERROR(C8/C6,"") -> 0.18632348 | D35: =IFERROR(D8/D6,"") -> 0.17876897 | E35: =IFERROR(E8/E6,"") -> 0.16641198 | F35: =IFERROR(F8/F6,"") -> 0.14888201
B36: 販売費及び一般管理費 | C36: =PL!C16 -> 214823441 | D36: =PL!E16 -> 215718454 | E36: =PL!G16 -> 193151054 | F36: =PL!I16 -> 55896593
B37: EBITDA（営業利益＋減価償却費） | C37: =C10+C17 -> 18420432 | D37: =D10+D17 -> 8134624 | E37: =E10+E17 -> 14738882 | F37: =F10+F17 -> 7752980
B38: 当期純利益 | C38: =C14 -> 9106898 | D38: =D14 -> 2928899 | E38: =E14 -> -15084655 | F38: =F14 -> 5884887
B39: 当期仕入高 | C39: =PL!C12 -> 953298320 | D39: =PL!E12 -> 976235640 | E39: =PL!G12 -> 996035389 | F39: =PL!I12 -> 371992415
B40: 支払利息 | C40: =PL!C25 -> 3962441 | D40: =PL!E25 -> 4040547 | E40: =PL!G25 -> 3895556 | F40: =PL!I25 -> 1192744
B41: 人件費（役員報酬・給与・賞与・法定福利等） | C41: =SGA!C5+SGA!C6+SGA!C7+SGA!C8+SGA!C9+SGA!C10+SGA!C11 -> 120274546 | D41: =SGA!E5+SGA!E6+SGA!E7+SGA!E8+SGA!E9+SGA!E10+SGA!E11 -> 121407097 | E41: =SGA!G5+SGA!G6+SGA!G7+SGA!G8+SGA!G9+SGA!G10+SGA!G11 -> 104562438 | F41: =SGA!I5+SGA!I6+SGA!I7+SGA!I8+SGA!I9+SGA!I10+SGA!I11 -> 28525927
B42: 運賃＋車両関連費 | C42: =SGA!C16+SGA!C15 -> 36022052 | D42: =SGA!E16+SGA!E15 -> 39619785 | E42: =SGA!G16+SGA!G15 -> 38858196 | F42: =SGA!I16+SGA!I15 -> 11054784
B43: 調整後EBITDA 3期平均 | C43: =AVERAGE(C25:E25) -> 14548726
B44: 調整後EBITDA 直近2期平均 | C44: =AVERAGE(D25:E25) -> 9976118.6
B46: ※進行期（2026年4〜7月）は試算表の4か月累計。前期比は前年同期（法人事業概況説明書の月別売上の4〜7月合計）との比較。調整項目は年度決算のみ算定。

Sheet BSハイライト
A1: 財務ハイライト（B/S）
A2: ■ 貼付範囲 B4:F19 → 企業概要書「財務ハイライト（B/S）」（範囲をコピーしてパワポに貼り付け。数字はここを直す）
F4: (単位：千円)
B5: 2026年3月期末
B6: 流動資産 | C6: ='BS(借方)'!E16 -> 249704912 | E6: 流動負債 | F6: ='BS (貸方)'!E12 -> 37279523
B7: 現金及び預金 | C7: ='BS(借方)'!E6 -> 210887077 | E7: 買掛金 | F7: ='BS (貸方)'!E6 -> 26349122
B8: 売上債権 | C8: ='BS(借方)'!E7+'BS(借方)'!E8 -> 20836318 | E8: 未払金 | F8: ='BS (貸方)'!E7 -> 6630301
B9: 棚卸資産 | C9: ='BS(借方)'!E9 -> 14596695 | E9: 未払法人税等 | F9: ='BS (貸方)'!E10 -> 1851300
B10: その他 | C10: ='BS(借方)'!E16-'BS(借方)'!E6-'BS(借方)'!E7-'BS(借方)'!E8-'BS(借方)'!E9 -> 3384822 | E10: その他 | F10: ='BS (貸方)'!E12-'BS (貸方)'!E6-'BS (貸方)'!E7-'BS (貸方)'!E10 -> 2448800
B11: 固定資産 | C11: ='BS(借方)'!E38 -> 235485192 | E11: 固定負債 | F11: ='BS (貸方)'!E16 -> 370038000
B12: 建物等 | C12: ='BS(借方)'!E18+'BS(借方)'!E19+'BS(借方)'!E20 -> 103749925 | E12: 長期借入金 | F12: ='BS (貸方)'!E14 -> 361058000
B13: 土地 | C13: ='BS(借方)'!E24 -> 93137240 | E13: 預り保証金 | F13: ='BS (貸方)'!E15 -> 8980000
B14: 電話加入権等（無形） | C14: ='BS(借方)'!E30 -> 2527395
B15: 投資有価証券 | C15: ='BS(借方)'!E32 -> 2600000 | E15: 負債合計 | F15: ='BS (貸方)'!E17 -> 407317523
B16: 保証金 | C16: ='BS(借方)'!E35 -> 33302569 | E16: 資本金 | F16: ='BS (貸方)'!E19 -> 40000000
B17: その他 | C17: ='BS(借方)'!E38-('BS(借方)'!E18+'BS(借方)'!E19+'BS(借方)'!E20)-'BS(借方)'!E24-'BS(借方)'!E30-'BS(借方)'!E32-'BS(借方)'!E35 -> 168063 | E17: 利益剰余金 | F17: ='BS (貸方)'!E20+'BS (貸方)'!E21 -> 37872581
E18: 純資産合計 | F18: ='BS (貸方)'!E22 -> 77872581
B19: 資産合計 | C19: ='BS(借方)'!E40 -> 485190104 | E19: 負債・純資産合計 | F19: ='BS (貸方)'!E23 -> 485190104
B22: 参考：B/S推移（コメント・リード文用。貼付範囲外）
B23: 項目 | C23: 2024/3末 | D23: 2025/3末 | E23: 2026/3末 | F23: 2026/7末
B24: 現金及び預金 | C24: ='BS(借方)'!C6 -> 339552632 | D24: ='BS(借方)'!D6 -> 259719301 | E24: ='BS(借方)'!E6 -> 210887077 | F24: ='BS(借方)'!G6 -> 162087296
B25: 売上債権（売掛金・資材肥料売掛金） | C25: ='BS(借方)'!C7+'BS(借方)'!C8 -> 22523530 | D25: ='BS(借方)'!D7+'BS(借方)'!D8 -> 23165625 | E25: ='BS(借方)'!E7+'BS(借方)'!E8 -> 20836318 | F25: ='BS(借方)'!G7+'BS(借方)'!G8 -> 42952291
B26: 棚卸資産 | C26: ='BS(借方)'!C9 -> 9859795 | D26: ='BS(借方)'!D9 -> 15443609 | E26: ='BS(借方)'!E9 -> 14596695 | F26: ='BS(借方)'!G9 -> 36647736
B27: 資産合計 | C27: ='BS(借方)'!C40 -> 651947559 | D27: ='BS(借方)'!D40 -> 567528964 | E27: ='BS(借方)'!E40 -> 485190104 | F27: ='BS(借方)'!G40 -> 476299797
B28: 有利子負債（長期借入金） | C28: ='BS (貸方)'!C14 -> 514690000 | D28: ='BS (貸方)'!D14 -> 434046000 | E28: ='BS (貸方)'!E14 -> 361058000 | F28: ='BS (貸方)'!G14 -> 337862000
B29: 純資産 | C29: ='BS (貸方)'!C22 -> 92828337 | D29: ='BS (貸方)'!D22 -> 93757236 | E29: ='BS (貸方)'!E22 -> 77872581 | F29: ='BS (貸方)'!G22 -> 83757468
B30: 自己資本比率 | C30: =IFERROR(C29/C27,"") -> 0.1423862 | D30: =IFERROR(D29/D27,"") -> 0.16520256 | E30: =IFERROR(E29/E27,"") -> 0.16049911 | F30: =IFERROR(F29/F27,"") -> 0.17585031
B31: ネットデット（有利子負債−現預金） | C31: =C28-C24 -> 175137368 | D31: =D28-D24 -> 174326699 | E31: =E28-E24 -> 150170923 | F31: =F28-F24 -> 175774704
B33: 借入先別残高（2026/3期末） | C33: 残高
B34: 鶴岡信用金庫 本店営業部 | C34: 182840000
B35: 山形銀行 鶴岡支店 | C35: 70250000
B36: 日本政策金融公庫 山形支店（1） | C36: 60730000
B37: 日本政策金融公庫 山形支店（2） | C37: 39380000
B38: 日本政策金融公庫 山形支店（3） | C38: 7858000
B39: 合計 | C39: =SUM(C34:C38) -> 361058000
B40: チェック：BS長期借入金と一致 | C40: =EXACT(C39,'BS (貸方)'!E14) -> TRUE
B42: ※金利・返済条件・担保・保証（代表者の連帯保証含む）は内訳書に記載がなく要確認。

Sheet 売上構成
A1: 収益源別売上高（進行期試算表）
A2: ■ 貼付範囲 B4:E11 → 企業概要書「事業の仕組みと収益源」（範囲をコピーしてパワポに貼り付け。数字はここを直す）
C4: (単位：千円)
B5: 収益区分 （2026年4〜7月） | C5: 金額 | D5: 構成比 | E5: 内容
B6: 商品売上高 | C6: =PL!I5 -> 375960544 | D6: =IFERROR(C6/C$11,"") -> 0.91440112 | E6: 青果物の販売（買付販売は総額、受託販売は2019年10月以降手数料のみの純額で計上）
B7: 委託手数料収入 | C7: =PL!I8 -> 12563500 | D7: =IFERROR(C7/C$11,"") -> 0.030556607 | E7: 受託販売の手数料。生産者の商品を預かり、販売後に販売額の8.5%を収受
B8: センター費収入 | C8: =PL!I7 -> 12272629 | D8: =IFERROR(C8/C$11,"") -> 0.029849158 | E8: (株)主婦の店の仕入商品の配送受託。配送額の約10%（1日約10万円）を収受
B9: 資材売上高 | C9: =PL!I6 -> 10820414 | D9: =IFERROR(C9/C$11,"") -> 0.02631712 | E9: 包装資材の販売（仕入資材の約8割は自社利用。肥料はほぼ取扱いなし）
B10: 売上割戻 | C10: =PL!I9 -> -462140 | D10: =IFERROR(C10/C$11,"") -> -0.0011240045 | E10: 完納奨励金：期限内に代金を支払った八百屋等へ対象売上の約3%を還元（市場の商慣習）
B11: 売上高 計 | C11: =SUM(C6:C10) -> 411154947 | D11: =IFERROR(C11/C11,"") -> 1
B12: チェック：PL売上高と一致 | C12: =EXACT(C11,PL!I10) -> TRUE
B14: 参考（貼付範囲外）
B15: 受託手数料率（第2回面談） | C15: 0.085
B16: 受託販売の取扱高（推計） | C16: =IFERROR(C7/C15,"") -> 1.4780588e+08 | D16: 委託手数料収入÷手数料率（4か月）
B17: センター費の月平均（試算表） | C17: =C8/4 -> 3068157.2 | D17: 代表者談「1日約10万円」と照合用
B18: 取扱構成（代表者の感覚値） | C18: 買付販売 約7割／受託販売 約2割／関連サービス等 約1割／資材 ほぼ0
B20: ※決算書では売上高を「商品売上高」1本で表示しているため、収益源別の内訳は試算表（2026年4〜7月）で代替。年度別内訳は要確認。

Sheet 取引先
A1: 主要得意先の3期推移（期末売掛金残高）
A2: ■ 貼付範囲 B4:L19 → 企業概要書「主要得意先の3期推移」（範囲をコピーしてパワポに貼り付け。数字はここを直す）
L4: (単位：千円)
B5: № | C5: 得意先 | D5: 本社所在地 | E5: 業種等 | F5: 2024年3月期末 | H5: 2025年3月期末 | J5: 2026年3月期末 | L5: 備考
F6: 残高 | G6: 構成比 | H6: 残高 | I6: 構成比 | J6: 残高 | K6: 構成比
B7: 1 | C7: (株)主婦の店 | D7: 鶴岡市 | E7: 食品スーパー（推察） | F7: 7624554 | G7: =IFERROR(F7/F$19,"") -> 0.33851506 | H7: 7465020 | I7: =IFERROR(H7/H$19,"") -> 0.32224557 | J7: 7194026 | K7: =IFERROR(J7/J$19,"") -> 0.34526378
B8: 2 | C8: 小島商店 | D8: 鶴岡市 | E8: 青果小売（推察） | F8: 3566319 | G8: =IFERROR(F8/F$19,"") -> 0.15833748 | H8: 1609526 | I8: =IFERROR(H8/H$19,"") -> 0.069479067 | J8: 2482212 | K8: =IFERROR(J8/J$19,"") -> 0.11912911
B9: 3 | C9: 長井中央青果(株) | D9: 長井市 | E9: 青果卸（長井中央青果地方卸売市場） | F9: 3038668 | G9: =IFERROR(F9/F$19,"") -> 0.13491082 | H9: 4185185 | I9: =IFERROR(H9/H$19,"") -> 0.18066359 | J9: 1785378 | K9: =IFERROR(J9/J$19,"") -> 0.085685868
B10: 4 | C10: 生活協同組合共立社 | D10: 鶴岡市 | E10: 生協 | F10: 1109653 | G10: =IFERROR(F10/F$19,"") -> 0.049266389 | H10: 2034205 | I10: =IFERROR(H10/H$19,"") -> 0.087811358 | J10: 1931830 | K10: =IFERROR(J10/J$19,"") -> 0.092714557
B11: 5 | C11: 給食センター | D11: 鶴岡市 | E11: 学校給食（推察） | F11: 793291 | G11: =IFERROR(F11/F$19,"") -> 0.035220545 | H11: 1307264 | I11: =IFERROR(H11/H$19,"") -> 0.056431199 | J11: 1121037 | K11: =IFERROR(J11/J$19,"") -> 0.053802068
B12: 6 | C12: 元青果 | D12: 三川町 | E12: 公設庄内青果物地方卸売市場内事業者（推察） | F12: 1050840 | G12: =IFERROR(F12/F$19,"") -> 0.046655209 | H12: 1018741 | I12: =IFERROR(H12/H$19,"") -> 0.043976409 | J12: 745635 | K12: =IFERROR(J12/J$19,"") -> 0.035785353
B13: 7 | C13: 生活協同組合連合会アイチョイス | D13: 名古屋市 | E13: 生協連合会 | F13: 751258 | G13: =IFERROR(F13/F$19,"") -> 0.033354363 | H13: 1032520 | I13: =IFERROR(H13/H$19,"") -> 0.044571213 | J13: 617729 | K13: =IFERROR(J13/J$19,"") -> 0.029646745
B14: 8 | C14: (株)みどりの里 | D14: 愛知県豊田市 | F14: 502958 | G14: =IFERROR(F14/F$19,"") -> 0.022330336 | H14: 886182 | I14: =IFERROR(H14/H$19,"") -> 0.03825418 | K14: =IFERROR(J14/J$19,"") -> 0
B15: 9 | C15: (有)新庄丸果青果 | D15: 新庄市 | E15: 青果卸（推察） | F15: 825334 | G15: =IFERROR(F15/F$19,"") -> 0.03664319 | H15: 705974 | I15: =IFERROR(H15/H$19,"") -> 0.030475068 | K15: =IFERROR(J15/J$19,"") -> 0
B16: 10 | C16: (株)やま高商店 | D16: 仙台市 | F16: 862435 | G16: =IFERROR(F16/F$19,"") -> 0.038290401 | I16: =IFERROR(H16/H$19,"") -> 0 | K16: =IFERROR(J16/J$19,"") -> 0
B17: 11 | C17: みどり水産 | G17: =IFERROR(F17/F$19,"") -> 0 | H17: 630388 | I17: =IFERROR(H17/H$19,"") -> 0.027212216 | K17: =IFERROR(J17/J$19,"") -> 0
C18: その他 | F18: 2398220 | G18: =IFERROR(F18/F$19,"") -> 0.10647621 | H18: 2290620 | I18: =IFERROR(H18/H$19,"") -> 0.09888013 | J18: 4958471 | K18: =IFERROR(J18/J$19,"") -> 0.23797252
C19: 合計 | F19: 22523530 | G19: =IFERROR(F19/F19,"") -> 1 | H19: 23165625 | I19: =IFERROR(H19/H19,"") -> 1 | J19: 20836318 | K19: =IFERROR(J19/J19,"") -> 1
C20: チェック（明細合計＝合計） | F20: =EXACT(SUM(F7:F18),F19) -> TRUE | H20: =EXACT(SUM(H7:H18),H19) -> TRUE | J20: =EXACT(SUM(J7:J18),J19) -> TRUE
B22: ※勘定科目内訳明細書の期末残高（50万円以上の相手先を個別記載）。年間取引高ではないため取引規模の順位とは異なる可能性がある（年間取引高は資料依頼中）。業種は公開情報等からの推察を含む。

Sheet 仕入先
A1: 主要仕入先の3期推移（期末買掛金残高）
A2: ■ 貼付範囲 B4:L15 → 企業概要書「主要仕入先の3期推移」（範囲をコピーしてパワポに貼り付け。数字はここを直す）
L4: (単位：千円)
B5: № | C5: 仕入先 | D5: 本社所在地 | E5: 業種等 | F5: 2024年3月期末 | H5: 2025年3月期末 | J5: 2026年3月期末 | L5: 備考
F6: 残高 | G6: 構成比 | H6: 残高 | I6: 構成比 | J6: 残高 | K6: 構成比
B7: 1 | C7: 丸果庄内青果(株) | D7: 三川町 | E7: 青果卸（公設庄内青果物地方卸売市場） | F7: 6568837 | G7: =IFERROR(F7/F$15,"") -> 0.36236383 | H7: 5733427 | I7: =IFERROR(H7/H$15,"") -> 0.28731897 | J7: 12426183 | K7: =IFERROR(J7/J$15,"") -> 0.47159761
B8: 2 | C8: 長井中央青果(株) | D8: 長井市 | E8: 青果卸 | F8: 1308421 | G8: =IFERROR(F8/F$15,"") -> 0.072177838 | H8: 2086538 | I8: =IFERROR(H8/H$15,"") -> 0.10456258 | J8: 7397876 | K8: =IFERROR(J8/J$15,"") -> 0.28076366
B9: 3 | C9: (株)庄果 | D9: 三川町 | E9: 青果卸（公設庄内青果物地方卸売市場） | F9: 3610982 | G9: =IFERROR(F9/F$15,"") -> 0.19919649 | H9: 4495652 | I9: =IFERROR(H9/H$15,"") -> 0.2252904 | K9: =IFERROR(J9/J$15,"") -> 0
B10: 4 | C10: (株)マルト直治郎商店 | D10: 三川町 | F10: 1228678 | G10: =IFERROR(F10/F$15,"") -> 0.067778888 | H10: 1954193 | I10: =IFERROR(H10/H$15,"") -> 0.097930385 | J10: 676643 | K10: =IFERROR(J10/J$15,"") -> 0.025679907
B11: 5 | C11: 成田食品(株) | D11: 福島県相馬市 | F11: 540882 | G11: =IFERROR(F11/F$15,"") -> 0.029837257 | H11: 698863 | I11: =IFERROR(H11/H$15,"") -> 0.03502209 | J11: 615054 | K11: =IFERROR(J11/J$15,"") -> 0.023342486
B12: 6 | C12: (株)ファーマインド | D12: 東京都千代田区 | E12: 青果流通（バナナ等・推察） | G12: =IFERROR(F12/F$15,"") -> 0 | I12: =IFERROR(H12/H$15,"") -> 0 | J12: 707255 | K12: =IFERROR(J12/J$15,"") -> 0.026841691
B13: 7 | C13: (株)東根農産センター | D13: 東根市 | G13: =IFERROR(F13/F$15,"") -> 0 | I13: =IFERROR(H13/H$15,"") -> 0 | J13: 547560 | K13: =IFERROR(J13/J$15,"") -> 0.020780958
C14: その他 | F14: 4869939 | G14: =IFERROR(F14/F$15,"") -> 0.26864569 | H14: 4986247 | I14: =IFERROR(H14/H$15,"") -> 0.24987557 | J14: 3978551 | K14: =IFERROR(J14/J$15,"") -> 0.15099368
C15: 合計 | F15: 18127739 | G15: =IFERROR(F15/F15,"") -> 1 | H15: 19954920 | I15: =IFERROR(H15/H15,"") -> 1 | J15: 26349122 | K15: =IFERROR(J15/J15,"") -> 1
C16: チェック（明細合計＝合計） | F16: =EXACT(SUM(F7:F14),F15) -> TRUE | H16: =EXACT(SUM(H7:H14),H15) -> TRUE | J16: =EXACT(SUM(J7:J14),J15) -> TRUE
B18: ※勘定科目内訳明細書の期末残高（50万円以上の相手先を個別記載）。年間取引高ではないため取引規模の順位とは異なる可能性がある（年間取引高は資料依頼中）。業種は公開情報等からの推察を含む。

Sheet 株主
A1: 株主
A2: ■ 貼付範囲 B4:H14 → 企業概要書「株主及び役員（株主）」（範囲をコピーしてパワポに貼り付け。数字はここを直す）
E4: (単位：千円)
B5: № | C5: 氏名 | D5: 役職・続柄 | E5: 役員報酬 (2026年3月期) | F5: 保有株式数 | G5: 保有割合 | H5: 備考
B6: 1 | C6: 岡部 寛 | D6: 代表取締役（本人） | E6: 4320000 | F6: 1510 | G6: =IFERROR(F6/F$14,"") -> 0.3775
B7: 2 | C7: 岡部 一 | D7: 取締役・代表者の兄弟 | E7: 4200000 | F7: 720 | G7: =IFERROR(F7/F$14,"") -> 0.18
B8: 3 | C8: 岡部 和子 | D8: 代表者の兄弟 | E8: 0 | F8: 500 | G8: =IFERROR(F8/F$14,"") -> 0.125
B9: 4 | C9: 梅津 恵一 | D9: － | E9: 0 | F9: 360 | G9: =IFERROR(F9/F$14,"") -> 0.09
B10: 5 | C10: 小野寺 則和 | D10: 監査役 | E10: 120000 | F10: 350 | G10: =IFERROR(F10/F$14,"") -> 0.0875
B11: 6 | C11: 岡部 竹古 | D11: 取締役・代表者の配偶者 | E11: 120000 | F11: 300 | G11: =IFERROR(F11/F$14,"") -> 0.075
B12: 7 | C12: 佐藤 令子 | D12: － | E12: 0 | F12: 200 | G12: =IFERROR(F12/F$14,"") -> 0.05
B13: 8 | C13: 菅原 圭吾 | D13: 元常務取締役 | E13: 6600000 | F13: 60 | G13: =IFERROR(F13/F$14,"") -> 0.015 | H13: 2026年5月29日退任
C14: 合計 | E14: =SUM(E6:E13) -> 15360000 | F14: =SUM(F6:F13) -> 4000 | G14: =IFERROR(F14/F14,"") -> 1
B16: うち代表者一族（岡部家4名） | F16: =F6+F7+F8+F11 -> 3030 | G16: =F16/F14 -> 0.7575
B17: チェック：発行済株式総数4,000株と一致 | F17: =EXACT(F14,4000) -> TRUE
B19: ※出所：法人税申告書別表二（2026/3期）。株主名簿・名義株の有無・親族外株主の取得経緯は要確認。

Sheet 取締役
A1: 役員
A2: ■ 貼付範囲 B4:I11 → 企業概要書「株主及び役員（役員）」（範囲をコピーしてパワポに貼り付け。数字はここを直す）
G4: (単位：千円)
B5: № | C5: 氏名 | D5: 役職 | E5: 代表者 との関係 | F5: 常勤／ 非常勤 | G5: 役員報酬 (2026年3月期) | H5: 業務範囲 | I5: 備考
B6: 1 | C6: 岡部 寛 | D6: 代表取締役 | E6: 本人 | F6: 常勤 | G6: 4320000 | H6: 経営全般・販売 | I6: 譲渡後は顧問就任可
B7: 2 | C7: 岡部 一 | D7: 取締役 | E7: 兄弟 | F7: 常勤 | G7: 4200000 | H7: 買付・販売 | I7: 譲渡後も残留予定
B8: 3 | C8: 岡部 竹古 | D8: 取締役 | E8: 配偶者 | F8: 非常勤 | G8: 120000 | H8: 業務への関与なし | I8: 譲渡時に退任予定
B9: 4 | C9: 小野寺 則和 | D9: 監査役 | E9: － | F9: 非常勤 | G9: 120000 | H9: 会計監査 | I9: 譲渡時に退任予定
B10: 5 | C10: 菅原 圭吾 | D10: 常務取締役 | E10: － | F10: 常勤 | G10: 6600000 | H10: － | I10: 2026年5月29日退任
C11: 合計 | G11: =SUM(G6:G10) -> 15360000
B14: 参考：役員報酬推移（評価書用。貼付範囲外）
B15: 役職 | C15: 氏名 | D15: 常勤/非常勤 | E15: 備考 | F15: 2024/3期 | G15: 2025/3期 | H15: 2026/3期
B16: 代表取締役 | C16: 岡部 寛 | D16: 常勤 | E16: 社長 | F16: 10560000 | G16: 10560000 | H16: 4320000
B17: 取締役 | C17: 岡部 一 | D17: 常勤 | E17: 部長（代表者の兄弟） | F17: 4800000 | G17: 4800000 | H17: 4200000
B18: 取締役 | C18: 岡部 竹古 | D18: 非常勤 | E18: 代表者の配偶者 | F18: 120000 | G18: 120000 | H18: 120000
B19: 監査役 | C19: 小野寺 則和 | D19: 非常勤 | E19: 会計監査限定 | F19: 120000 | G19: 120000 | H19: 120000
B20: （退任）常務取締役 | C20: 菅原 圭吾 | D20: 常勤 | E20: 2026年5月29日退任 | F20: 6600000 | G20: 6600000 | H20: 6600000
B21: 役員報酬 計 | F21: =SUM(F16:F20) -> 22200000 | G21: =SUM(G16:G20) -> 22200000 | H21: =SUM(H16:H20) -> 15360000
B22: チェック：SGA役員報酬と一致 | F22: =EXACT(F21,SGA!C5) -> TRUE | G22: =EXACT(G21,SGA!E5) -> TRUE | H22: =EXACT(H21,SGA!G5) -> TRUE
B24: ※任期：取締役は2年（直近重任2026/5/29）、監査役は2024/5/18重任。代表者の連帯保証・退職慰労金規程の有無、各取締役の担当業務は要確認。

Sheet 従業員
A1: 従業員一覧（2026年9月1日現在）
A2: ■ 貼付範囲 B4:J29 → 企業概要書「従業員一覧」（範囲をコピーしてパワポに貼り付け。数字はここを直す）
J4: 2026年9月1日現在
B5: № | C5: 雇用形態 | D5: 性別 | E5: 年齢 （歳） | F5: 勤続年数 （年） | G5: 部署 | H5: 役職 | I5: 取得資格 | J5: 備考
B6: 2 | C6: 正社員 | D6: 男 | E6: 47 | F6: 24 | G6: 野菜営業部 | H6: 副部長 | I6: セリ人・フォークリフト
B7: 1 | C7: 正社員 | D7: 男 | E7: 63 | F7: 1 | G7: 野菜営業部 | H7: 副部長
B8: 7 | C8: 正社員 | D8: 男 | E8: 32 | F8: 6 | G8: 野菜営業部 | I8: フォークリフト
B9: 16 | C9: 正社員 | D9: 女 | E9: 49 | F9: 19 | G9: 果実営業部 | H9: 課長
B10: 8 | C10: 正社員 | D10: 男 | E10: 36 | F10: 4 | G10: 果実営業部 | I10: フォークリフト
B11: 3 | C11: 正社員 | D11: 男 | E11: 31 | F11: 12 | G11: 近郷部 | H11: 課長 | I11: セリ人・フォークリフト
B12: 4 | C12: 正社員 | D12: 男 | E12: 42 | F12: 7 | G12: 近郷部 | I12: フォークリフト
B13: 5 | C13: 正社員 | D13: 男 | E13: 45 | F13: 7 | G13: 近郷部 | I13: フォークリフト
B14: 12 | C14: 試用期間 | D14: 男 | E14: 66 | F14: 2 | G14: 近郷部 | I14: セリ人
B15: 9 | C15: 正社員 | D15: 男 | E15: 42 | F15: 14 | G15: 集配部 | I15: フォークリフト | J15: 2022年4月よりフルタイム
B16: 6 | C16: 正社員 | D16: 男 | E16: 63 | F16: 6 | G16: 集配部 | I16: フォークリフト
B17: 11 | C17: 再雇用正社員 | D17: 男 | E17: 40 | F17: 3 | G17: 集配部
B18: 13 | C18: アルバイト | D18: 男 | E18: 55 | F18: 0 | G18: 集配部 | J18: 休日のみ配送
B19: 10 | C19: 嘱託社員 | D19: 男 | E19: 69 | F19: 20 | G19: 生花部 | I19: フォークリフト
B20: 18 | C20: 正社員 | D20: 女 | E20: 52 | F20: 20 | G20: パッケージ部 | H20: 係長 | J20: 2012年4月よりフルタイム
B21: 19 | C21: 正社員 | D21: 女 | E21: 65 | F21: 20 | G21: パッケージ部 | J21: 2012年4月よりフルタイム／定年後再雇用
B22: 21 | C22: 正社員 | D22: 女 | E22: 65 | F22: 17 | G22: パッケージ部 | J22: 2012年4月よりフルタイム
B23: 22 | C23: パート | D23: 女 | E23: 67 | F23: 14 | G23: パッケージ部 | J23: 4h
B24: 23 | C24: パート | D24: 男 | E24: 29 | F24: 8 | G24: パッケージ部 | J24: 4h
B25: 20 | C25: 正社員 | D25: 女 | E25: 55 | F25: 5 | G25: パッケージ部
B26: 24 | C26: パート | D26: 女 | E26: 59 | F26: 3 | G26: パッケージ部 | J26: 4h
B27: 15 | C27: 正社員 | D27: 女 | E27: 65 | F27: 47 | G27: 資材部 | H27: 課長 | J27: 定年後再雇用
B28: 14 | C28: 正社員 | D28: 女 | E28: 56 | F28: 38 | G28: 総務部 | H28: 部長
B29: 17 | C29: 正社員 | D29: 女 | E29: 28 | F29: 7 | G29: 事務
B31: 参考（リード文用の集計。貼付範囲外）
B32: 人数 | D32: =COUNT(B6:B29) -> 24
B33: 平均年齢 | D33: =AVERAGE(E6:E29) -> 50.875
B34: 平均勤続年数 | D34: =AVERAGE(F6:F29) -> 12.666667
B35: 60歳以上 | D35: =COUNTIF(E6:E29,">=60") -> 8
B36: セリ人資格者 | D36: =SUMPRODUCT(ISNUMBER(FIND("セリ人",I6:I29))*1) -> 3
B37: 正社員 | D37: =COUNTIF(C6:C29,"正社員") -> 17
B39: ※出所：職員名簿（2026年9月1日現在）。氏名・住所・電話番号は概要書に記載しない。№は名簿の番号（組織図と対応）。部署→役職→勤続年数の順に並べ替え。
B40: ※定年は60歳（名簿注記）と65歳の両記載あり、就業規則で要確認。法人事業概況説明書（2026/3期末）では従業員30名（常勤役員3名含む）と記載があり、人数定義の差は要確認。

Sheet 拠点(本社等)
A1: 拠点概要
A2: ■ 貼付範囲 B5:G9 → 企業概要書「拠点概要（本社・市場）」（範囲をコピーしてパワポに貼り付け。数字はここを直す）
B5: 拠点 | C5: 所在地 | D5: 所有区分 | E5: 土地面積 (㎡) | F5: 主な建物 | G5: 用途
B6: 本社・市場 | C6: 山形県鶴岡市宝田一丁目4番20号 （地番：宝田一丁目4-2） | D6: 法人 | E6: ='不動産(所有)'!E5 -> 3100.22 | F6: 事務所（管理棟）・市場・倉庫・容器庫・貯蔵庫 | G6: 事務、セリ・相対取引、保管
B7: パッケージ場 | C7: 山形県鶴岡市宝田一丁目5-1 | D7: 法人 | E7: ='不動産(所有)'!E6 -> 900.5 | F7: 事務所兼倉庫（パッケージ場）・倉庫 | G7: 小分け・包装、保管
B8: 旧倉庫敷地 | C8: 山形県東田川郡庄内町長沼字宮前304-7 | D8: 法人 | E8: ='不動産(所有)'!E7 -> 261.81 | F8: なし（倉庫は老朽化により解体済み） | G8: 月極駐車場として近隣へ賃貸
B9: 賃借物件 | C9: なし（地代家賃の計上なし） | D9: － | F9: － | G9: －
B11: ※営業時間は早朝5時から（終業時刻は要確認）、定休日は水・日・祝日。リース料年6,227千円を計上（対象資産・車両の保有形態は要確認）。

Sheet 不動産概況
A1: 不動産概況
A2: ■ 貼付範囲 B4:J9 → 企業概要書「不動産概況」（範囲をコピーしてパワポに貼り付け。数字はここを直す）
J4: (単位：千円)
B5: 拠点 | C5: 所在地 | D5: 土地面積 (㎡) | E5: 土地の 所有区分 | F5: 建物の所有区分 | G5: 土地簿価 (千円) | H5: 土地時価 (千円) | I5: 建物固定資産税 評価額(千円) | J5: 担保
B6: 本社・市場 | C6: ='不動産(所有)'!B5 -> 鶴岡市宝田一丁目4-2 | D6: ='不動産(所有)'!E5 -> 3100.22 | E6: 法人 | F6: 法人（5棟／延床1,246.20㎡） | G6: ='不動産(所有)'!H5 -> 70757240 | H6: ='不動産(所有)'!F5/0.7 -> 51230293 | I6: ='不動産(所有)'!H12+'不動産(所有)'!H13+'不動産(所有)'!H14+'不動産(所有)'!H15+'不動産(所有)'!H16 -> 22295345 | J6: 要確認
B7: パッケージ場 | C7: ='不動産(所有)'!B6 -> 鶴岡市宝田一丁目5-1 | D7: ='不動産(所有)'!E6 -> 900.5 | E7: 法人 | F7: 法人（2棟／延床766.48㎡） | G7: ='不動産(所有)'!H6 -> 21380000 | H7: ='不動産(所有)'!F6/0.7 -> 15086140 | I7: ='不動産(所有)'!H17+'不動産(所有)'!H18 -> 24766655 | J7: 要確認
B8: 旧倉庫敷地 | C8: ='不動産(所有)'!B7 -> 東田川郡庄内町長沼字宮前304-7 | D8: ='不動産(所有)'!E7 -> 261.81 | E8: 法人 | F8: 建物なし（老朽化により解体済み） | G8: ='不動産(所有)'!H7 -> 1000000 | H8: ='不動産(所有)'!F7/0.7 -> 1508578.6 | J8: 要確認
B9: 合計 | D9: =SUM(D6:D8) -> 4262.53 | F9: 法人 7棟 | G9: =SUM(G6:G8) -> 93137240 | H9: =SUM(H6:H8) -> 67825011 | I9: =SUM(I6:I8) -> 47062000
B10: チェック | G10: =EXACT(G9,'不動産(所有)'!H8) -> TRUE | I10: =EXACT(I9,'不動産(所有)'!H19) -> TRUE
B12: ※面積は登記地積（固定資産税課税明細書）。土地時価＝固定資産税評価額÷0.7（公示価格水準への割戻し。推計）。建物評価額は令和8年度固定資産税評価額。
B13: ※担保設定の状況は不動産登記簿謄本（未受領）により確認予定。

Sheet 不動産(所有)
A1: 所有不動産（転記元データ）
A2: 出所：R8年度固定資産税課税明細書、固定資産（土地・建物）内訳書。概要書へは「不動産概況」「不動産詳細」シート経由で貼り付ける
B4: 所在 | C4: 地目 | D4: 用途 | E4: 地積(㎡) | F4: 固定資産税評価額 | H4: 簿価(2026/3末)
B5: 鶴岡市宝田一丁目4-2 | C5: 宅地 | D5: 市場・事務所・倉庫 | E5: 3100.22 | F5: 35861205 | H5: 70757240
B6: 鶴岡市宝田一丁目5-1 | C6: 宅地 | D6: パッケージ場・倉庫 | E6: 900.5 | F6: 10560298 | H6: 21380000
B7: 東田川郡庄内町長沼字宮前304-7 | C7: 宅地 | D7: 駐車場・旧倉庫敷地 | E7: 261.81 | F7: 1056005 | H7: 1000000
B8: 土地 計 | E8: =SUM(E5:E7) -> 4262.53 | F8: =SUM(F5:F7) -> 47477508 | H8: =SUM(H5:H7) -> 93137240
B9: チェック：BS土地と一致 | H9: =EXACT(H8,'BS(借方)'!E24) -> TRUE
B11: 所在 | C11: 種類 | D11: 構造 | E11: 階数 | F11: 床面積(㎡) | G11: 建築年 | H11: 固定資産税評価額
B12: 宝田一丁目4-2 | C12: 事務所 | D12: 鉄骨造 亜鉛メッキ鋼板葺 | E12: 2階 | F12: 365.63 | G12: 1981年（昭和56年） | H12: 11218061
B13: 宝田一丁目4-2 | C13: 市場 | D13: 鉄骨造 亜鉛メッキ鋼板葺 | E13: 1階 | F13: 320.22 | G13: 1981年（昭和56年） | H13: 4712536
B14: 宝田一丁目4-2 | C14: 倉庫 | D14: 鉄骨造 亜鉛メッキ鋼板葺 | E14: 1階 | F14: 327.13 | G14: 1981年（昭和56年） | H14: 4560792
B15: 宝田一丁目4-2 | C15: 倉庫 | D15: 軽量鉄骨造 | E15: 2階 | F15: 198.74 | G15: 1981年（昭和56年） | H15: 1237049
B16: 宝田一丁目4-2 | C16: 貯蔵庫 | D16: 軽量鉄骨造 | E16: 1階 | F16: 34.48 | G16: 1981年（昭和56年） | H16: 566907
B17: 宝田一丁目5-1 | C17: 事務所兼倉庫 | D17: 鉄骨造 亜鉛メッキ鋼板葺 | E17: 2階 | F17: 627.4 | G17: 1982年（昭和57年） | H17: 13110977
B18: 宝田一丁目5-1 | C18: 倉庫 | D18: 鉄骨造 亜鉛メッキ鋼板葺 | E18: 1階 | F18: 139.08 | G18: 2012年（平成24年） | H18: 11655678
B19: 建物 計 | F19: =SUM(F12:F18) -> 2012.68 | H19: =SUM(H12:H18) -> 47062000
B21: ※建物簿価（2026/3末）92,066千円・建物付属設備11,400千円。主要棟は1981〜82年築であり、新耐震基準への適合（確認済証の日付）・アスベスト・修繕履歴は要確認。
B22: ※土地の簿価93,137千円に対し、固定資産税評価額は47,478千円。評価額÷0.7で推計した時価は約67,800千円（推察）であり、含み損の可能性あり。鑑定・路線価で要確認。
B23: ※償却資産の課税標準額9,779千円。R8年度固定資産税・都市計画税の年税額1,488千円。

Sheet 不動産詳細
A1: 不動産詳細
A2: ■ 貼付範囲 B4:I17 → 企業概要書「不動産詳細」（範囲をコピーしてパワポに貼り付け。数字はここを直す）
I4: (単位：千円)
B5: 区分 | C5: 所在地 | D5: 面積 (㎡) | E5: 地目・構造 | F5: 建築年 | G5: 期末簿価 (千円) | H5: 固定資産税 評価額(千円) | I5: 時価 (千円)
B6: 土地 | C6: ='不動産(所有)'!B5 -> 鶴岡市宝田一丁目4-2 | D6: ='不動産(所有)'!E5 -> 3100.22 | E6: ='不動産(所有)'!C5&"（"&'不動産(所有)'!D5&"）" -> 宅地（市場・事務所・倉庫） | F6: － | G6: ='不動産(所有)'!H5 -> 70757240 | H6: ='不動産(所有)'!F5 -> 35861205 | I6: ='不動産(所有)'!F5/0.7 -> 51230293
B7: 土地 | C7: ='不動産(所有)'!B6 -> 鶴岡市宝田一丁目5-1 | D7: ='不動産(所有)'!E6 -> 900.5 | E7: ='不動産(所有)'!C6&"（"&'不動産(所有)'!D6&"）" -> 宅地（パッケージ場・倉庫） | F7: － | G7: ='不動産(所有)'!H6 -> 21380000 | H7: ='不動産(所有)'!F6 -> 10560298 | I7: ='不動産(所有)'!F6/0.7 -> 15086140
B8: 土地 | C8: ='不動産(所有)'!B7 -> 東田川郡庄内町長沼字宮前304-7 | D8: ='不動産(所有)'!E7 -> 261.81 | E8: ='不動産(所有)'!C7&"（"&'不動産(所有)'!D7&"）" -> 宅地（駐車場・旧倉庫敷地） | F8: － | G8: ='不動産(所有)'!H7 -> 1000000 | H8: ='不動産(所有)'!F7 -> 1056005 | I8: ='不動産(所有)'!F7/0.7 -> 1508578.6
B9: 土地 計 | D9: =SUM(D6:D8) -> 4262.53 | G9: =SUM(G6:G8) -> 93137240 | H9: =SUM(H6:H8) -> 47477508 | I9: =SUM(I6:I8) -> 67825011
B10: ='不動産(所有)'!C12 -> 事務所 | C10: ="鶴岡市"&'不動産(所有)'!B12 -> 鶴岡市宝田一丁目4-2 | D10: ='不動産(所有)'!F12 -> 365.63 | E10: ='不動産(所有)'!D12&" "&'不動産(所有)'!E12 -> 鉄骨造 亜鉛メッキ鋼板葺 2階 | F10: =LEFT('不動産(所有)'!G12,5) -> 1981年 | G10: － | H10: ='不動産(所有)'!H12 -> 11218061 | I10: －
B11: ='不動産(所有)'!C13 -> 市場 | C11: ="鶴岡市"&'不動産(所有)'!B13 -> 鶴岡市宝田一丁目4-2 | D11: ='不動産(所有)'!F13 -> 320.22 | E11: ='不動産(所有)'!D13&" "&'不動産(所有)'!E13 -> 鉄骨造 亜鉛メッキ鋼板葺 1階 | F11: =LEFT('不動産(所有)'!G13,5) -> 1981年 | G11: － | H11: ='不動産(所有)'!H13 -> 4712536 | I11: －
B12: ='不動産(所有)'!C14 -> 倉庫 | C12: ="鶴岡市"&'不動産(所有)'!B14 -> 鶴岡市宝田一丁目4-2 | D12: ='不動産(所有)'!F14 -> 327.13 | E12: ='不動産(所有)'!D14&" "&'不動産(所有)'!E14 -> 鉄骨造 亜鉛メッキ鋼板葺 1階 | F12: =LEFT('不動産(所有)'!G14,5) -> 1981年 | G12: － | H12: ='不動産(所有)'!H14 -> 4560792 | I12: －
B13: ='不動産(所有)'!C15 -> 倉庫 | C13: ="鶴岡市"&'不動産(所有)'!B15 -> 鶴岡市宝田一丁目4-2 | D13: ='不動産(所有)'!F15 -> 198.74 | E13: ='不動産(所有)'!D15&" "&'不動産(所有)'!E15 -> 軽量鉄骨造 2階 | F13: =LEFT('不動産(所有)'!G15,5) -> 1981年 | G13: － | H13: ='不動産(所有)'!H15 -> 1237049 | I13: －
B14: ='不動産(所有)'!C16 -> 貯蔵庫 | C14: ="鶴岡市"&'不動産(所有)'!B16 -> 鶴岡市宝田一丁目4-2 | D14: ='不動産(所有)'!F16 -> 34.48 | E14: ='不動産(所有)'!D16&" "&'不動産(所有)'!E16 -> 軽量鉄骨造 1階 | F14: =LEFT('不動産(所有)'!G16,5) -> 1981年 | G14: － | H14: ='不動産(所有)'!H16 -> 566907 | I14: －
B15: ='不動産(所有)'!C17 -> 事務所兼倉庫 | C15: ="鶴岡市"&'不動産(所有)'!B17 -> 鶴岡市宝田一丁目5-1 | D15: ='不動産(所有)'!F17 -> 627.4 | E15: ='不動産(所有)'!D17&" "&'不動産(所有)'!E17 -> 鉄骨造 亜鉛メッキ鋼板葺 2階 | F15: =LEFT('不動産(所有)'!G17,5) -> 1982年 | G15: － | H15: ='不動産(所有)'!H17 -> 13110977 | I15: －
B16: ='不動産(所有)'!C18 -> 倉庫 | C16: ="鶴岡市"&'不動産(所有)'!B18 -> 鶴岡市宝田一丁目5-1 | D16: ='不動産(所有)'!F18 -> 139.08 | E16: ='不動産(所有)'!D18&" "&'不動産(所有)'!E18 -> 鉄骨造 亜鉛メッキ鋼板葺 1階 | F16: =LEFT('不動産(所有)'!G18,5) -> 2012年 | G16: － | H16: ='不動産(所有)'!H18 -> 11655678 | I16: －
B17: 建物 計 | D17: =SUM(D10:D16) -> 2012.68 | G17: ='BS(借方)'!E18 -> 92065694 | H17: =SUM(H10:H16) -> 47062000 | I17: －
B19: ※建物の簿価は棟別ではなく改修工事を含めた合計（BS建物）で記載。棟別の内訳は「設備」シート参照。土地時価＝固定資産税評価額÷0.7（推計）。
B20: ※1981年築の建物は新耐震基準（1981年6月施行）の適用有無を建築確認日で要確認。土地の時価は鑑定・路線価で要確認。賃借物件なし。

Sheet 設備
A1: 保有設備一覧
A2: ■ 貼付範囲 B4:E32（建物内訳）／G36:I45（科目別）→ 企業概要書「保有設備一覧」
E4: (単位：千円)
B5: 建物内訳（用途） | C5: 所在 | D5: 面積(㎡) | E5: 簿価
B6: 管理棟 | C6: 宝田一丁目4-20 | D6: 365 | E6: 20192827
B7: 荷捌市場 | C7: 宝田一丁目4-20 | D7: 330.7 | E7: 5899377
B8: 倉庫 | C8: 宝田一丁目4-20 | D8: 320.2 | E8: 1165921
B9: 容器庫 | C9: 宝田一丁目4-20 | D9: 198.7 | E9: 500001
B10: 物置 | C10: 宝田一丁目4-20 | D10: 34.4 | E10: 1
B11: 容器倉庫 | C11: 宝田一丁目4-20 | E11: 249260
B12: シャッター | C12: 宝田一丁目4-20 | E12: 1
B13: シャッター取替 | C13: 宝田一丁目4-20 | E13: 1739340
B14: 改修工事 | C14: 宝田一丁目4-20 | E14: 2695280
B15: 改修工事 | C15: 宝田一丁目4-20 | E15: 6000156
B16: パッケージ場 | C16: 宝田一丁目5-20 | D16: 629.34 | E16: 11751239
B17: シャッター更新 | C17: 宝田一丁目4-20 | E17: 1077501
B18: プレハブ修繕 | C18: 宝田一丁目4-20 | E18: 1377441
B19: 不用材置場 | C19: 宝田一丁目4-20 | E19: 1
B20: 倉庫 | C20: 宝田一丁目5-1 | E20: 8917430
B21: 2階改修 | C21: 宝田一丁目4-20 | E21: 6403541
B22: 1階トイレ改修 | C22: 宝田一丁目4-20 | E22: 1169632
B23: 屋根改修 | C23: 宝田一丁目4-20 | E23: 3391200
B24: 屋根改修 | C24: 宝田一丁目4-20 | E24: 3120320
B25: 屋根改修 | C25: 宝田一丁目4-20 | E25: 3736745
B26: 下屋修理・塗装 | C26: 宝田一丁目4-20 | E26: 971487
B27: パッケージ場外壁 | C27: 宝田一丁目5-20 | E27: 6815160
B28: 冷蔵庫ユニット交換工事 | C28: 宝田一丁目4-20 | E28: 1001990
... B31: 資材倉庫シャッター（2025年5月） | C31: 宝田一丁目4-20 | E31: 401759
B32: 建物 計 | E32: =SUM(E6:E31) -> 92065694
B33: チェック：BS建物と一致 | E33: =EXACT(E32,'BS(借方)'!E18) -> TRUE
I36: (単位：千円)
G37: 区分 | H37: 簿価(2026/3末) | I37: 備考
G38: 建物 | H38: ='BS(借方)'!E18 -> 92065694 | I38: 左表の内訳のとおり。改修工事を資産計上
G39: 建物付属設備 | H39: ='BS(借方)'!E19 -> 11399836 | I39: 冷蔵庫ユニット・シャッター等（内訳は台帳で要確認）
G40: 構築物 | H40: ='BS(借方)'!E20 -> 284395
G41: 機械装置 | H41: ='BS(借方)'!E21 -> 2 | I41: 備忘価額のみ（償却済）
G42: 車両運搬具 | H42: ='BS(借方)'!E22 -> 15 | I42: 備忘価額のみ。集配車両はリースと推察（要確認）
G43: 工具器具備品 | H43: ='BS(借方)'!E23 -> 18546
G44: ソフトウェア | H44: ='BS(借方)'!E29 -> 371800 | I44: 販売管理システム等と推察（要確認）
G45: 合計 | H45: =SUM(H38:H44) -> 104140288
...

Sheet 月別売上
A1: 月別売上高・仕入高（2026/3期）
A2: ■ 貼付範囲 B4:O8 → 企業概要書「月別売上高」（範囲をコピーしてパワポに貼り付け。数字はここを直す）
O4: (単位：千円)
C5: 4月 | D5: 5月 | E5: 6月 | F5: 7月 | G5: 8月 | H5: 9月 | I5: 10月 | J5: 11月 | K5: 12月 | L5: 1月 | M5: 2月 | N5: 3月 | O5: 合計
B6: 売上高 | C6: 87736 | D6: 101698 | E6: 83794 | F6: 146060 | G6: 138177 | H6: 110175 | I6: 106499 | J6: 100617 | K6: 98058 | L6: 69520 | M6: 69339 | N6: 84221 | O6: =SUM(C6:N6) -> 1195894
B7: 仕入高 | C7: 76904 | D7: 86235 | E7: 74095 | F7: 139243 | G7: 96826 | H7: 85074 | I7: 84386 | J7: 85425 | K7: 82345 | L7: 56698 | M7: 58088 | N7: 70716 | O7: =SUM(C7:N7) -> 996035
B8: 月平均比 | C8: =IFERROR(C6/($O$6/12),"") -> 0.88037234 | D8: =IFERROR(D6/($O$6/12),"") -> 1.0204717 | E8: =IFERROR(E6/($O$6/12),"") -> 0.840817 | F8: =IFERROR(F6/($O$6/12),"") -> 1.4656148 | G8: =IFERROR(G6/($O$6/12),"") -> 1.3865142 | H8: =IFERROR(H6/($O$6/12),"") -> 1.1055328 | I8: =IFERROR(I6/($O$6/12),"") -> 1.0686466 | J8: =IFERROR(J6/($O$6/12),"") -> 1.0096246 | ... N8: =IFERROR(N6/($O$6/12),"") -> 0.84510166
B10: 人件費 | C10: 4204 | D10: 7349 | E10: 7586 | F10: 7363 | G10: 7717 | H10: 7474 | I10: 7291 | J10: 7298 | K10: 7200 | L10: 6903 | M10: 6884 | N10: 9764
B12: ※出所：法人事業概況説明書（2026/3期）。千円単位の記載値をそのまま転記（円単位入力の例外）。合計はPLの売上高と端数・集計範囲の差がある。

Sheet 貸借対照表
A1: 貸借対照表（財務情報詳細）
A2: ■ 貼付範囲 B4:E37（資産）／G5:J16（負債）／G31:J37（純資産）→ 企業概要書「貸借対照表」
J4: (単位：千円)
B5: 資産の部 | G5: 負債の部
B6: 科目 | C6: 2024年3月期 | D6: 2025年3月期 | E6: 2026年3月期 | G6: 科目 | H6: 2024年3月期 | I6: 2025年3月期 | J6: 2026年3月期
B7: 【流動資産】 | C7: ='BS(借方)'!C16 -> 375589011 | D7: ='BS(借方)'!D16 -> 303100807 | E7: ='BS(借方)'!E16 -> 249704912 | G7: 【流動負債】 | H7: ='BS (貸方)'!C12 -> 34109222 | I7: ='BS (貸方)'!D12 -> 29455728 | J7: ='BS (貸方)'!E12 -> 37279523
B8: 現金及び預金 | C8: ='BS(借方)'!C6 -> 339552632 | D8: ='BS(借方)'!D6 -> 259719301 | E8: ='BS(借方)'!E6 -> 210887077 | G8: 買掛金 | H8: ='BS (貸方)'!C6 -> 18127739 | I8: ='BS (貸方)'!D6 -> 19954920 | J8: ='BS (貸方)'!E6 -> 26349122
B9: 売掛金 | C9: ='BS(借方)'!C7 -> 21171056 | D9: ='BS(借方)'!D7 -> 21896538 | E9: ='BS(借方)'!E7 -> 19608899 | G9: 未払金 | H9: ='BS (貸方)'!C7 -> 10198849 | I9: ='BS (貸方)'!D7 -> 7302614 | J9: ='BS (貸方)'!E7 -> 6630301
B10: 資材肥料売掛金 | C10: ='BS(借方)'!C8 -> 1352474 | D10: ='BS(借方)'!D8 -> 1269087 | E10: ='BS(借方)'!E8 -> 1227419 | G10: 預り金 | H10: ='BS (貸方)'!C9 -> 504234 | I10: ='BS (貸方)'!D9 -> 557594 | J10: ='BS (貸方)'!E9 -> 281300
B11: 棚卸資産 | C11: ='BS(借方)'!C9 -> 9859795 | D11: ='BS(借方)'!D9 -> 15443609 | E11: ='BS(借方)'!E9 -> 14596695 | G11: 未払法人税等 | H11: ='BS (貸方)'!C10 -> 2308000 | I11: ='BS (貸方)'!D10 -> 33900 | J11: ='BS (貸方)'!E10 -> 1851300
B12: 立替金 | C12: ='BS(借方)'!C10 -> 96860 | D12: ='BS(借方)'!D10 -> 6400 | E12: ='BS(借方)'!E10 -> 0 | G12: 未払消費税 | H12: ='BS (貸方)'!C11 -> 2970400 | I12: ='BS (貸方)'!D11 -> 1606700 | J12: ='BS (貸方)'!E11 -> 2167500
B13: 未収入金 | C13: ='BS(借方)'!C11 -> 3684415 | D13: ='BS(借方)'!D11 -> 3905410 | E13: ='BS(借方)'!E11 -> 3011112 | G13: 【固定負債】 | H13: ='BS (貸方)'!C16 -> 525010000 | I13: ='BS (貸方)'!D16 -> 444316000 | J13: ='BS (貸方)'!E16 -> 370038000
