Workbook

Sheet ルール
B3: 1 | C3: 文字は「游ゴシック」、数字は「Arial」を基本。備考欄などの細かい文章は「游ゴシック Medium」。
B4: 2 | C4: タイトル、合計欄は太字
B5: 3 | C5: 数字は円単位で入力、表示は千円単位に設定済み
B6: 4 | C6: 基本の背景は以下の通り。紺、水色、グレー、白、青。パレットの上部の色。
C8: 線は紺か白か青。
C10: 資産の部
C11: 科目 | D11: ='BS(借方)'!F10 -> 0 | E11: 調整額 | F11: 調整後
C12: 【流動資産】 | D12: =SUM(D13:D26) -> 5000000 | E12: =SUM(E13:E26) -> -500000 | F12: =SUM(F13:F26) -> 4500000
C13: 現金及び預金 | D13: 5000000 | E13: -500000 | F13: =D13+E13 -> 4500000
F14: =D14+E14 -> 0
B16: ■ 本案件の運用（株式会社鶴岡中央青果）
B17: 1. 本ファイルが唯一の数値ソース。企業概要書・評価書の数字は必ず本ファイルから貼る（パワポに直接打たない）。
B18: 2. 財務入力：D列=24年3月期（第51期）、E列=25年3月期、F列=26年3月期（直近期・評価基準日）、G列=進行期（2026年4〜9月の試算表、6か月累計）。1期目（C列）は未使用のため非表示。
B19: 3. 非表示の行・列は概要書に貼らない（空行・1期目・売上行・氏名等）。貼付スクリプト（im_paste.paste_range）も非表示を自動で除く。
B20: 4. 未確認事項は推測で埋めず「要確認」。推測は「推察」「想定」「（仮説）」と明記し、「その他」シートに集約。社内限の情報は「その他」の「プロセス関連（社内確認事項）」のみに記載。
B21: 5. 更新：2026/10/27 公式フォーマットへ移行（旧マスター261019の内容を転記）。9月試算表・順位表・分類別売上・認定証を反映。SGA 26/3期の行ずれ、テンプレートの数式不具合（年買法G8/H8、ネットキャッシュF15、修正BS(貸方)D50）を修正。
B23: ■ 企業概要書への貼付範囲一覧（各IMシートのA1/A2にも表記）
B24: 会社概要!B2:C15 → 基本情報
B25: PLハイライト!B2:G25 → 財務ハイライト（P/L）
B26: BSハイライト!B2:F21 → 財務ハイライト（B/S）
B27: 取引先!B2:M17 → 主要得意先の3期推移
B28: 仕入先!B2:L17 → 主要仕入先の3期推移
... B47: SGA!B2:L40 → 販売費及び一般管理費

Sheet 財務入力→

Sheet BS(借方)
A1: ■ 貼付範囲 B3:G61 → 企業概要書「貸借対照表（資産の部）」（C列・空行は非表示） | C1: ←基本的にはここをつかう→
C2: 1期目 | D2: 2期目 | E2: 3期目 | F2: （4期目） | G2: 進行期
B3: 資産の部
B4: 科目 | C4: ●●年●月期 | D4: 24年3月期 | E4: 25年3月期 | F4: 26年3月期 | G4: 27年3月期 4〜9月TB
B5: 【流動資産】 | C5: =SUM(C6:C19) -> 0 | D5: =SUM(D6:D19) -> 375589011 | E5: =SUM(E6:E19) -> 303100807 | F5: =SUM(F6:F19) -> 249704912 | G5: =SUM(G6:G19) -> 434733191
B6: 現金及び預金 | D6: 339552632 | E6: 259719301 | F6: 210887077 | G6: 393410846
B7: 売掛金 | D7: 21171056 | E7: 21896538 | F7: 19608899 | G7: 22835432
B8: 資材肥料売掛金 | D8: 1352474 | E8: 1269087 | F8: 1227419 | G8: 1137638
B9: 棚卸資産 | D9: 9859795 | E9: 15443609 | F9: 14596695 | G9: 14405198
B10: 立替金 | D10: 96860 | E10: 6400
B11: 未収入金 | D11: 3684415 | E11: 3905410 | F11: 3011112 | G11: 3045753
B12: 仮払金 | F12: 493135
B13: 前払費用 | D13: 108779 | E13: 96162 | F13: 83575 | G13: 101324
B14: 仮払税金等 | E14: 998300
B15: 貸倒引当金 | D15: -237000 | E15: -234000 | F15: -203000 | G15: -203000
B20: 【固定資産】 | C20: =C21+C35+C46 -> 0 | D20: =D21+D35+D46 -> 276114714 | E20: =E21+E35+E46 -> 264261323 | F20: =F21+F35+F46 -> 235485192 | G20: =G21+G35+G46 -> 230831192
B21: ［有形固定資産］ | C21: =SUM(C22:C34) -> 0 | D21: =SUM(D22:D34) -> 216357447 | E21: =SUM(E22:E34) -> 204260121 | F21: =SUM(F22:F34) -> 196905728 | G21: =SUM(G22:G34) -> 193251728
B22: 建物 | D22: 101161720 | E22: 95851274 | F22: 92065694 | G22: 92065694
B23: 建物付属設備 | D23: 15416918 | E23: 13503020 | F23: 11399836 | G23: 11399836
B24: 構築物 | D24: 382601 | E24: 333498 | F24: 284395 | G24: 284395
B25: 機械装置 | D25: 133566 | E25: 2 | F25: 2 | G25: 2
B26: 車両運搬具 | D26: 5837529 | E26: 1281878 | F26: 15 | G26: 15
B27: 工具器具備品 | D27: 287873 | E27: 153209 | F27: 18546 | G27: 18546
B28: 土地 | D28: 93137240 | E28: 93137240 | F28: 93137240 | G28: 93137240
B29: 減価償却累計額 | G29: -3654000
B35: ［無形固定資産］ | C35: =SUM(C36:C45) -> 0 | D35: =SUM(D36:D45) -> 2870595 | E35: =SUM(E36:E45) -> 2698995 | F35: =SUM(F36:F45) -> 2527395 | G35: =SUM(G36:G45) -> 2527395
B36: 電話加入権 | D36: 2155595 | E36: 2155595 | F36: 2155595 | G36: 2155595
B37: ソフトウェア | D37: 715000 | E37: 543400 | F37: 371800 | G37: 371800
B46: ［投資その他資産］ | C46: =SUM(C47:C55) -> 0 | D46: =SUM(D47:D55) -> 56886672 | E46: =SUM(E47:E55) -> 57302207 | F46: =SUM(F47:F55) -> 36052069 | G46: =SUM(G47:G55) -> 35052069
B47: 投資有価証券 | D47: 3250000 | E47: 3250000 | F47: 2600000 | G47: 1600000
B48: 出資金 | D48: 75000 | E48: 75000 | F48: 75000 | G48: 75000
B49: 長期前払費用 | D49: 397411 | E49: 74500 | F49: 74500 | G49: 74500
B50: 保証金 | D50: 32002569 | E50: 33002569 | F50: 33302569 | G50: 33302569
B51: 事業保険積立金 | D51: 21161692 | E51: 20900138
B56: 【繰延資産】 | C56: =SUM(C57:C60) -> 0 | D56: =SUM(D57:D60) -> 243834 | E56: =SUM(E57:E60) -> 166834 | F56: =SUM(F57:F60) -> 0 | G56: =SUM(G57:G60) -> 0
B57: 繰延資産 | D57: 243834 | E57: 166834
B61: 資産合計 | C61: =C5+C20+C56 -> 0 | D61: =D5+D20+D56 -> 651947559 | E61: =E5+E20+E56 -> 567528964 | F61: =F5+F20+F56 -> 485190104 | G61: =G5+G20+G56 -> 665564383
B63: バランスチェック | C63: =EXACT(C61,'BS (貸方)'!C51) -> 1 | D63: =EXACT(D61,'BS (貸方)'!D51) -> 1 | E63: =EXACT(E61,'BS (貸方)'!E51) -> 1 | F63: =EXACT(F61,'BS (貸方)'!F51) -> 1 | G63: =EXACT(G61,'BS (貸方)'!G51) -> 1
B65: 決算書・試算表の資産合計 | D65: 651947559 | E65: 567528964 | F65: 485190104 | G65: 665564383
B66: チェック | D66: =EXACT(D61,D65) -> 1 | E66: =EXACT(E61,E65) -> 1 | F66: =EXACT(F61,F65) -> 1 | G66: =EXACT(G61,G65) -> 1
...

Sheet BS (貸方)
A1: ■ 貼付範囲 B3:G25（負債）／B34:G51（純資産）→ 企業概要書「貸借対照表」
E2: (単位：千円)
B3: 負債の部
B4: 科目 | C4: ='BS(借方)'!C4 -> ●●年●月期 | D4: ='BS(借方)'!D4 -> 24年3月期 | E4: ='BS(借方)'!E4 -> 25年3月期 | F4: ='BS(借方)'!F4 -> 26年3月期 | G4: ='BS(借方)'!G4 -> 27年3月期 4〜9月TB
B5: 【流動負債】 | C5: =SUM(C6:C17) -> 0 | D5: =SUM(D6:D17) -> 34109222 | E5: =SUM(E6:E17) -> 29455728 | F5: =SUM(F6:F17) -> 37279523 | G5: =SUM(G6:G17) -> 31281895
B6: 買掛金 | D6: 18127739 | E6: 19954920 | F6: 26349122 | G6: 18258090
B7: 未払金 | D7: 10198849 | E7: 7302614 | F7: 6630301 | G7: 3564068
B8: 仮受金 | G8: 6109017
B9: 預り金 | D9: 504234 | E9: 557594 | F9: 281300 | G9: 327720
B10: 未払法人税等 | D10: 2308000 | E10: 33900 | F10: 1851300
B11: 未払消費税 | D11: 2970400 | E11: 1606700 | F11: 2167500 | G11: 3023000
B18: 【固定負債】 | C18: =SUM(C19:C24) -> 0 | D18: =SUM(D19:D24) -> 525010000 | E18: =SUM(E19:E24) -> 444316000 | F18: =SUM(F19:F24) -> 370038000 | G18: =SUM(G19:G24) -> 535244000
B19: 長期借入金 | D19: 514690000 | E19: 434046000 | F19: 361058000 | G19: 526264000
B20: 預り保証金 | D20: 10320000 | E20: 10270000 | F20: 8980000 | G20: 8980000
B25: 負債合計 | C25: =C5+C18 -> 0 | D25: =D5+D18 -> 559119222 | E25: =E5+E18 -> 473771728 | F25: =F5+F18 -> 407317523 | G25: =G5+G18 -> 566525895
B34: 純資産の部
B35: 【資本金】 | C35: =SUM(C36:C38) -> 0 | D35: =SUM(D36:D38) -> 40000000 | E35: =SUM(E36:E38) -> 40000000 | F35: =SUM(F36:F38) -> 40000000 | G35: =SUM(G36:G38) -> 40000000
B36: 資本金 | D36: 40000000 | E36: 40000000 | F36: 40000000 | G36: 40000000
B39: 【資本剰余金】 | C39: =SUM(C40:C42) -> 0 | D39: =SUM(D40:D42) -> 0 | E39: =SUM(E40:E42) -> 0 | F39: =SUM(F40:F42) -> 0 | G39: =SUM(G40:G42) -> 0
B43: 【利益剰余金】 | C43: =SUM(C44:C48) -> 0 | D43: =SUM(D44:D48) -> 52828337 | E43: =SUM(E44:E48) -> 53757236 | F43: =SUM(F44:F48) -> 37872581 | G43: =SUM(G44:G48) -> 59038488
B44: 利益準備金 | D44: 1800000 | E44: 2000000 | F44: 2080000 | G44: 2080000
B45: 繰越利益剰余金 | D45: 51028337 | E45: 51757236 | F45: 35792581 | G45: 56958488
B49: 【自己株式】 | C49: 0 | D49: 0 | E49: 0 | F49: 0 | G49: 0
B50: 純資産合計 | C50: =C35+C39+C43+C49 -> 0 | D50: =D35+D39+D43+D49 -> 92828337 | E50: =E35+E39+E43+E49 -> 93757236 | F50: =F35+F39+F43+F49 -> 77872581 | G50: =G35+G39+G43+G49 -> 99038488
B51: 負債・純資産合計 | C51: =C25+C50 -> 0 | D51: =D25+D50 -> 651947559 | E51: =E25+E50 -> 567528964 | F51: =F25+F50 -> 485190104 | G51: =G25+G50 -> 665564383
B53: バランスチェック | C53: =EXACT(C51,'BS(借方)'!C61) -> 1 | D53: =EXACT(D51,'BS(借方)'!D61) -> 1 | E53: =EXACT(E51,'BS(借方)'!E61) -> 1 | F53: =EXACT(F51,'BS(借方)'!F61) -> 1 | G53: =EXACT(G51,'BS(借方)'!G61) -> 1

Sheet PL
A1: ■ 貼付範囲 B2:L56 → 企業概要書「損益計算書」（C:D列・空行は非表示）
L2: (単位：千円)
B3: 科目 | C3: ='BS(借方)'!C4 -> ●●年●月期 | E3: ='BS(借方)'!D4 -> 24年3月期 | G3: ='BS(借方)'!E4 -> 25年3月期 | I3: ='BS(借方)'!F4 -> 26年3月期 | K3: ='BS(借方)'!G4 -> 27年3月期 4〜9月TB
C4: 帳簿価額 | D4: 売上高比 | E4: 帳簿価額 | F4: 売上高比 | G4: 帳簿価額 | H4: 売上高比 | I4: 帳簿価額 | J4: 売上高比 | K4: 帳簿価額 | L4: 売上高比
B5: 商品売上高 | D5: =IF(C5=0,"",C5/C$11) | E5: 1179974308 | F5: =IF(E5=0,"",E5/E$11) -> 1.0012603 | G5: 1183308630 | H5: =IF(G5=0,"",G5/G$11) -> 1.0011517 | I5: 1197530299 | J5: =IF(I5=0,"",I5/I$11) -> 1.0013689 | K5: 568871022 | L5: =IF(K5=0,"",K5/K$11) -> 0.91556776
B6: 資材売上高 | D6: =IF(C6=0,"",C6/C$11) | F6: =IF(E6=0,"",E6/E$11) | H6: =IF(G6=0,"",G6/G$11) | J6: =IF(I6=0,"",I6/I$11) | K6: 5369372 | L6: =IF(K6=0,"",K6/K$11) -> 0.0086417196
B7: 資材売上（自社） | D7: =IF(C7=0,"",C7/C$11) | F7: =IF(E7=0,"",E7/E$11) | H7: =IF(G7=0,"",G7/G$11) | J7: =IF(I7=0,"",I7/I$11) | K7: 9473775 | L7: =IF(K7=0,"",K7/K$11) -> 0.015247539
B8: 主婦センター費 | D8: =IF(C8=0,"",C8/C$11) | F8: =IF(E8=0,"",E8/E$11) | H8: =IF(G8=0,"",G8/G$11) | J8: =IF(I8=0,"",I8/I$11) | K8: 18416492 | L8: =IF(K8=0,"",K8/K$11) -> 0.029640368
B9: 委託手数料収入 | D9: =IF(C9=0,"",C9/C$11) | F9: =IF(E9=0,"",E9/E$11) | H9: =IF(G9=0,"",G9/G$11) | J9: =IF(I9=0,"",I9/I$11) | K9: 19958506 | L9: =IF(K9=0,"",K9/K$11) -> 0.032122158
B10: 売上割戻金 | D10: =IF(C10=0,"",C10/C$11) | E10: -1485210 | F10: =IF(E10=0,"",E10/E$11) -> -0.0012602662 | G10: -1361290 | H10: =IF(G10=0,"",G10/G$11) -> -0.0011517349 | I10: -1637030 | J10: =IF(I10=0,"",I10/I$11) -> -0.0013688763 | K10: -757740 | L10: =IF(K10=0,"",K10/K$11) -> -0.0012195424
B11: 売上高 | C11: =SUM(C5:C10) -> 0 | D11: =IF(C11=0,"",C11/C$11) | E11: =SUM(E5:E10) -> 1178489098 | F11: =IF(E11=0,"",E11/E$11) -> 1 | G11: =SUM(G5:G10) -> 1181947340 | H11: =IF(G11=0,"",G11/G$11) -> 1 | I11: =SUM(I5:I10) -> 1195893269 | J11: =IF(I11=0,"",I11/I$11) -> 1 | K11: =SUM(K5:K10) -> 621331427 | L11: =IF(K11=0,"",K11/K$11) -> 1
B12: 期首棚卸高 | D12: =IF(C12=0,"",C12/C$11) | E12: 15470384 | F12: =IF(E12=0,"",E12/E$11) -> 0.013127303 | G12: 9859795 | H12: =IF(G12=0,"",G12/G$11) -> 0.0083419918 | I12: 15443609 | J12: =IF(I12=0,"",I12/I$11) -> 0.012913869 | K12: 14596695 | L12: =IF(K12=0,"",K12/K$11) -> 0.023492607
B13: 仕入高 | D13: =IF(C13=0,"",C13/C$11) | E13: 953298320 | F13: =IF(E13=0,"",E13/E$11) -> 0.80891569 | G13: 976235640 | H13: =IF(G13=0,"",G13/G$11) -> 0.82595527 | I13: 996035389 | J13: =IF(I13=0,"",I13/I$11) -> 0.83287984 | K13: 514967990 | L13: =IF(K13=0,"",K13/K$11) -> 0.82881369
B14: 期末棚卸高 | D14: =IF(C14=0,"",C14/C$11) | E14: -9859795 | F14: =IF(E14=0,"",E14/E$11) -> -0.0083664711 | G14: -15443609 | H14: =IF(G14=0,"",G14/G$11) -> -0.013066241 | I14: -14596695 | J14: =IF(I14=0,"",I14/I$11) -> -0.012205684 | K14: -14405198 | L14: =IF(K14=0,"",K14/K$11) -> -0.023184403
D15: =IF(C15=0,"",C15/C$11) | F15: =IF(E15=0,"",E15/E$11) | H15: =IF(G15=0,"",G15/G$11) | J15: =IF(I15=0,"",I15/I$11) | L15: =IF(K15=0,"",K15/K$11)
B16: 売上原価 | C16: =SUM(C12:C15) -> 0 | D16: =IF(C16=0,"",C16/C$11) | E16: =SUM(E12:E15) -> 958908909 | F16: =IF(E16=0,"",E16/E$11) -> 0.81367652 | G16: =SUM(G12:G15) -> 970651826 | H16: =IF(G16=0,"",G16/G$11) -> 0.82123103 | I16: =SUM(I12:I15) -> 996882303 | J16: =IF(I16=0,"",I16/I$11) -> 0.83358802 | K16: =SUM(K12:K15) -> 515159487 | L16: =IF(K16=0,"",K16/K$11) -> 0.82912189
B17: 売上総利益 | C17: =C11-C16 -> 0 | D17: =IF(C17=0,"",C17/C$11) | E17: =E11-E16 -> 219580189 | F17: =IF(E17=0,"",E17/E$11) -> 0.18632348 | G17: =G11-G16 -> 211295514 | H17: =IF(G17=0,"",G17/G$11) -> 0.17876897 | I17: =I11-I16 -> 199010966 | J17: =IF(I17=0,"",I17/I$11) -> 0.16641198 | K17: =K11-K16 -> 106171940 | L17: =IF(K17=0,"",K17/K$11) -> 0.17087811
B18: 販売費及び一般管理費 | C18: =SGA!C40 -> 0 | D18: =IF(C18=0,"",C18/C$11) | E18: =SGA!E40 -> 214823441 | F18: =IF(E18=0,"",E18/E$11) -> 0.18228717 | G18: =SGA!G40 -> 215718454 | H18: =IF(G18=0,"",G18/G$11) -> 0.18251105 | I18: =SGA!I40 -> 193151054 | J18: =IF(I18=0,"",I18/I$11) -> 0.16151195 | K18: =SGA!K40 -> 85746239 | L18: =IF(K18=0,"",K18/K$11) -> 0.13800403
B19: 営業利益 | C19: =C17- C18 -> 0 | D19: =IF(C19=0,"",C19/C$11) | E19: =E17- E18 -> 4756748 | F19: =IF(E19=0,"",E19/E$11) -> 0.0040363106 | G19: =G17- G18 -> -4422940 | H19: =IF(G19=0,"",G19/G$11) -> -0.0037420787 | I19: =I17- I18 -> 5859912 | J19: =IF(I19=0,"",I19/I$11) -> 0.0049000293 | K19: =K17- K18 -> 20425701 | L19: =IF(K19=0,"",K19/K$11) -> 0.032874083
B20: 営業外収益 | C20: =SUM(C21:C27) -> 0 | D20: =IF(C20=0,"",C20/C$11) | E20: =SUM(E21:E27) -> 10628095 | F20: =IF(E20=0,"",E20/E$11) -> 0.0090184076 | G20: =SUM(G21:G27) -> 10736890 | H20: =IF(G20=0,"",G20/G$11) -> 0.009084068 | I20: =SUM(I21:I27) -> 6577758 | J20: =IF(I20=0,"",I20/I$11) -> 0.0055002885 | K20: =SUM(K21:K27) -> 2830373 | L20: =IF(K20=0,"",K20/K$11) -> 0.0045553353
B21: 受取利息 | D21: =IF(C21=0,"",C21/C$11) | E21: 1252 | F21: =IF(E21=0,"",E21/E$11) -> 1.0623772e-06 | G21: 84858 | H21: =IF(G21=0,"",G21/G$11) -> 7.1795077e-05 | I21: 267463 | J21: =IF(I21=0,"",I21/I$11) -> 0.00022365123 | K21: 161697 | L21: =IF(K21=0,"",K21/K$11) -> 0.00026024275
B22: 受取配当金 | D22: =IF(C22=0,"",C22/C$11) | E22: 30500 | F22: =IF(E22=0,"",E22/E$11) -> 2.5880596e-05 | G22: 30500 | H22: =IF(G22=0,"",G22/G$11) -> 2.5804872e-05 | I22: 30500 | J22: =IF(I22=0,"",I22/I$11) -> 2.5503948e-05 | K22: 30950 | L22: =IF(K22=0,"",K22/K$11) -> 4.9812385e-05
B23: 受取延滞料 | D23: =IF(C23=0,"",C23/C$11) | E23: 170242 | F23: =IF(E23=0,"",E23/E$11) -> 0.00014445785 | G23: 147416 | H23: =IF(G23=0,"",G23/G$11) -> 0.00012472298 | I23: 96879 | J23: =IF(I23=0,"",I23/I$11) -> 8.1009738e-05 | K23: 58794 | L23: =IF(K23=0,"",K23/K$11) -> 9.4625827e-05
B24: 受取奨励金 | D24: =IF(C24=0,"",C24/C$11) | E24: 2284370 | F24: =IF(E24=0,"",E24/E$11) -> 0.0019383887 | G24: 2406729 | H24: =IF(G24=0,"",G24/G$11) -> 0.0020362405 | I24: 2513377 | J24: =IF(I24=0,"",I24/I$11) -> 0.0021016733 | K24: 1184146 | L24: =IF(K24=0,"",K24/K$11) -> 0.0019058202
B25: 受取運賃・配達収入 | D25: =IF(C25=0,"",C25/C$11) | F25: =IF(E25=0,"",E25/E$11) | H25: =IF(G25=0,"",G25/G$11) | J25: =IF(I25=0,"",I25/I$11) | K25: 163350 | L25: =IF(K25=0,"",K25/K$11) -> 0.00026290317
B26: 雑収入 | D26: =IF(C26=0,"",C26/C$11) | E26: 8141731 | F26: =IF(E26=0,"",E26/E$11) -> 0.006908618 | G26: 8067387 | H26: =IF(G26=0,"",G26/G$11) -> 0.0068255046 | I26: 3669539 | J26: =IF(I26=0,"",I26/I$11) -> 0.0030684502 | K26: 1231436 | L26: =IF(K26=0,"",K26/K$11) -> 0.001981931
D27: =IF(C27=0,"",C27/C$11) | F27: =IF(E27=0,"",E27/E$11) | H27: =IF(G27=0,"",G27/G$11) | J27: =IF(I27=0,"",I27/I$11) | L27: =IF(K27=0,"",K27/K$11)
B28: 営業外費用 | C28: =SUM(C29:C35) -> 0 | D28: =IF(C28=0,"",C28/C$11) | E28: =SUM(E29:E35) -> 4068303 | F28: =IF(E28=0,"",E28/E$11) -> 0.0034521346 | G28: =SUM(G29:G35) -> 4132569 | H28: =IF(G28=0,"",G28/G$11) -> 0.003496407 | I28: =SUM(I29:I35) -> 4369886 | J28: =IF(I28=0,"",I28/I$11) -> 0.0036540769 | K28: =SUM(K29:K35) -> 2090167 | L28: =IF(K28=0,"",K28/K$11) -> 0.003364013
B29: 支払利息 | D29: =IF(C29=0,"",C29/C$11) | E29: 3962441 | F29: =IF(E29=0,"",E29/E$11) -> 0.003362306 | G29: 4040547 | H29: =IF(G29=0,"",G29/G$11) -> 0.0034185508 | I29: 3895556 | J29: =IF(I29=0,"",I29/I$11) -> 0.0032574445 | K29: 2090167 | L29: =IF(K29=0,"",K29/K$11) -> 0.003364013
B30: 出荷奨励金 | D30: =IF(C30=0,"",C30/C$11) | E30: 105862 | F30: =IF(E30=0,"",E30/E$11) -> 8.9828578e-05 | G30: 92022 | H30: =IF(G30=0,"",G30/G$11) -> 7.785626e-05 | I30: 94929 | J30: =IF(I30=0,"",I30/I$11) -> 7.9379157e-05 | L30: =IF(K30=0,"",K30/K$11)
B31: 雑損失 | D31: =IF(C31=0,"",C31/C$11) | F31: =IF(E31=0,"",E31/E$11) | H31: =IF(G31=0,"",G31/G$11) | I31: 379401 | J31: =IF(I31=0,"",I31/I$11) -> 0.00031725323 | L31: =IF(K31=0,"",K31/K$11)
D32: =IF(C32=0,"",C32/C$11) | F32: =IF(E32=0,"",E32/E$11) | H32: =IF(G32=0,"",G32/G$11) | J32: =IF(I32=0,"",I32/I$11) | L32: =IF(K32=0,"",K32/K$11)
D33: =IF(C33=0,"",C33/C$11) | F33: =IF(E33=0,"",E33/E$11) | H33: =IF(G33=0,"",G33/G$11) | J33: =IF(I33=0,"",I33/I$11) | L33: =IF(K33=0,"",K33/K$11)
D34: =IF(C34=0,"",C34/C$11) | F34: =IF(E34=0,"",E34/E$11) | H34: =IF(G34=0,"",G34/G$11) | J34: =IF(I34=0,"",I34/I$11) | L34: =IF(K34=0,"",K34/K$11)
D35: =IF(C35=0,"",C35/C$11) | F35: =IF(E35=0,"",E35/E$11) | H35: =IF(G35=0,"",G35/G$11) | J35: =IF(I35=0,"",I35/I$11) | L35: =IF(K35=0,"",K35/K$11)
B36: 経常利益 | C36: =C19+C20-C28 -> 0 | D36: =IF(C36=0,"",C36/C$11) | E36: =E19+E20-E28 -> 11316540 | F36: =IF(E36=0,"",E36/E$11) -> 0.0096025835 | G36: =G19+G20-G28 -> 2181381 | H36: =IF(G36=0,"",G36/G$11) -> 0.0018455822 | I36: =I19+I20-I28 -> 8067784 | J36: =IF(I36=0,"",I36/I$11) -> 0.0067462408 | K36: =K19+K20-K28 -> 21165907 | L36: =IF(K36=0,"",K36/K$11) -> 0.034065405
B37: 特別利益 | C37: =SUM(C38:C43) -> 0 | D37: =IF(C37=0,"",C37/C$11) | E37: =SUM(E38:E43) -> 1887177 | F37: =IF(E37=0,"",E37/E$11) -> 0.001601353 | G37: =SUM(G38:G43) -> 1845918 | H37: =IF(G37=0,"",G37/G$11) -> 0.0015617599 | I37: =SUM(I38:I43) -> 234000 | J37: =IF(I37=0,"",I37/I$11) -> 0.00019566964 | K37: =SUM(K38:K43) -> 0 | L37: =IF(K37=0,"",K37/K$11)
B38: 固定資産売却益 | D38: =IF(C38=0,"",C38/C$11) | E38: 1711177 | F38: =IF(E38=0,"",E38/E$11) -> 0.0014520092 | G38: 1608918 | H38: =IF(G38=0,"",G38/G$11) -> 0.0013612434 | J38: =IF(I38=0,"",I38/I$11) | L38: =IF(K38=0,"",K38/K$11)
B39: 貸倒引当金戻入 | D39: =IF(C39=0,"",C39/C$11) | E39: 176000 | F39: =IF(E39=0,"",E39/E$11) -> 0.00014934377 | G39: 237000 | H39: =IF(G39=0,"",G39/G$11) -> 0.00020051655 | I39: 234000 | J39: =IF(I39=0,"",I39/I$11) -> 0.00019566964 | L39: =IF(K39=0,"",K39/K$11)
D40: =IF(C40=0,"",C40/C$11) | F40: =IF(E40=0,"",E40/E$11) | H40: =IF(G40=0,"",G40/G$11) | J40: =IF(I40=0,"",I40/I$11) | L40: =IF(K40=0,"",K40/K$11)
...

Sheet CR
H4: (単位：千円)
B5: 科目 | C5: ='BS(借方)'!C4 -> ●●年●月期 | E5: ='BS(借方)'!D4 -> 24年3月期 | G5: ='BS(借方)'!E4 -> 25年3月期 | I5: ='BS(借方)'!F4 -> 26年3月期 | K5: ='BS(借方)'!G4 -> 27年3月期 4〜9月TB
C6: 帳簿価額 | D6: 売上高比 | E6: 帳簿価額 | F6: 売上高比 | G6: 帳簿価額 | H6: 売上高比 | I6: 帳簿価額 | J6: 売上高比 | K6: 帳簿価額 | L6: 売上高比
A7: IMに貼るときは非表示→ | B7: 売上 | C7: =PL!C11 -> 0 | D7: - | E7: =PL!E11 -> 1178489098 | F7: - | G7: =PL!G11 -> 1181947340 | H7: - | I7: =PL!I11 -> 1195893269 | J7: - | K7: =PL!K11 -> 621331427 | L7: -
B8: 期首原材料棚卸高 | D8: =IF(C8=0,"",C8/C$7) | F8: =IF(E8=0,"",E8/E$7) | H8: =IF(G8=0,"",G8/G$7) | J8: =IF(I8=0,"",I8/I$7) | L8: =IF(K8=0,"",K8/K$7)
B9: 原材料仕入高 | D9: =IF(C9=0,"",C9/C$7) | F9: =IF(E9=0,"",E9/E$7) | H9: =IF(G9=0,"",G9/G$7) | J9: =IF(I9=0,"",I9/I$7) | L9: =IF(K9=0,"",K9/K$7)
B10: 小計 | D10: =IF(C10=0,"",C10/C$7) | F10: =IF(E10=0,"",E10/E$7) | H10: =IF(G10=0,"",G10/G$7) | J10: =IF(I10=0,"",I10/I$7) | L10: =IF(K10=0,"",K10/K$7)
B11: 期末原材料棚卸高 | D11: =IF(C11=0,"",C11/C$7) | F11: =IF(E11=0,"",E11/E$7) | H11: =IF(G11=0,"",G11/G$7) | J11: =IF(I11=0,"",I11/I$7) | L11: =IF(K11=0,"",K11/K$7)
D12: =IF(C12=0,"",C12/C$7) | F12: =IF(E12=0,"",E12/E$7) | H12: =IF(G12=0,"",G12/G$7) | J12: =IF(I12=0,"",I12/I$7) | L12: =IF(K12=0,"",K12/K$7)
D13: =IF(C13=0,"",C13/C$7) | F13: =IF(E13=0,"",E13/E$7) | H13: =IF(G13=0,"",G13/G$7) | J13: =IF(I13=0,"",I13/I$7) | L13: =IF(K13=0,"",K13/K$7)
B14: 材料費 | C14: =SUM(C8:C13) -> 0 | D14: =IF(C14=0,"",C14/C$7) | E14: =SUM(E8:E13) -> 0 | F14: =IF(E14=0,"",E14/E$7) | G14: =SUM(G8:G13) -> 0 | H14: =IF(G14=0,"",G14/G$7) | I14: =SUM(I8:I13) -> 0 | J14: =IF(I14=0,"",I14/I$7) | K14: =SUM(K8:K13) -> 0 | L14: =IF(K14=0,"",K14/K$7)
D15: =IF(C15=0,"",C15/C$7) | F15: =IF(E15=0,"",E15/E$7) | H15: =IF(G15=0,"",G15/G$7) | J15: =IF(I15=0,"",I15/I$7) | L15: =IF(K15=0,"",K15/K$7)
D18: =IF(C18=0,"",C18/C$7) | F18: =IF(E18=0,"",E18/E$7) | H18: =IF(G18=0,"",G18/G$7) | J18: =IF(I18=0,"",I18/I$7) | L18: =IF(K18=0,"",K18/K$7)
D19: =IF(C19=0,"",C19/C$7) | F19: =IF(E19=0,"",E19/E$7) | H19: =IF(G19=0,"",G19/G$7) | J19: =IF(I19=0,"",I19/I$7) | L19: =IF(K19=0,"",K19/K$7)
D20: =IF(C20=0,"",C20/C$7) | F20: =IF(E20=0,"",E20/E$7) | H20: =IF(G20=0,"",G20/G$7) | J20: =IF(I20=0,"",I20/I$7) | L20: =IF(K20=0,"",K20/K$7)
D21: =IF(C21=0,"",C21/C$7) | F21: =IF(E21=0,"",E21/E$7) | H21: =IF(G21=0,"",G21/G$7) | J21: =IF(I21=0,"",I21/I$7) | L21: =IF(K21=0,"",K21/K$7)
D22: =IF(C22=0,"",C22/C$7) | F22: =IF(E22=0,"",E22/E$7) | H22: =IF(G22=0,"",G22/G$7) | J22: =IF(I22=0,"",I22/I$7) | L22: =IF(K22=0,"",K22/K$7)
B23: 労務費 | C23: =SUM(C15:C22) -> 0 | D23: =IF(C23=0,"",C23/C$7) | E23: =SUM(E15:E22) -> 0 | F23: =IF(E23=0,"",E23/E$7) | G23: =SUM(G15:G22) -> 0 | H23: =IF(G23=0,"",G23/G$7) | I23: =SUM(I15:I22) -> 0 | J23: =IF(I23=0,"",I23/I$7) | K23: =SUM(K15:K22) -> 0 | L23: =IF(K23=0,"",K23/K$7)
D24: =IF(C24=0,"",C24/C$7) | F24: =IF(E24=0,"",E24/E$7) | H24: =IF(G24=0,"",G24/G$7) | J24: =IF(I24=0,"",I24/I$7) | L24: =IF(K24=0,"",K24/K$7)
D28: =IF(C28=0,"",C28/C$7) | F28: =IF(E28=0,"",E28/E$7) | H28: =IF(G28=0,"",G28/G$7) | J28: =IF(I28=0,"",I28/I$7) | L28: =IF(K28=0,"",K28/K$7)
D29: =IF(C29=0,"",C29/C$7) | F29: =IF(E29=0,"",E29/E$7) | H29: =IF(G29=0,"",G29/G$7) | J29: =IF(I29=0,"",I29/I$7) | L29: =IF(K29=0,"",K29/K$7)
D30: =IF(C30=0,"",C30/C$7) | F30: =IF(E30=0,"",E30/E$7) | H30: =IF(G30=0,"",G30/G$7) | J30: =IF(I30=0,"",I30/I$7) | L30: =IF(K30=0,"",K30/K$7)
D31: =IF(C31=0,"",C31/C$7) | F31: =IF(E31=0,"",E31/E$7) | H31: =IF(G31=0,"",G31/G$7) | J31: =IF(I31=0,"",I31/I$7) | L31: =IF(K31=0,"",K31/K$7)
D32: =IF(C32=0,"",C32/C$7) | F32: =IF(E32=0,"",E32/E$7) | H32: =IF(G32=0,"",G32/G$7) | J32: =IF(I32=0,"",I32/I$7) | L32: =IF(K32=0,"",K32/K$7)
B33: 外注加工費 | C33: =SUM(C24:C32) -> 0 | D33: =IF(C33=0,"",C33/C$7) | E33: =SUM(E24:E32) -> 0 | F33: =IF(E33=0,"",E33/E$7) | G33: =SUM(G24:G32) -> 0 | H33: =IF(G33=0,"",G33/G$7) | I33: =SUM(I24:I32) -> 0 | J33: =IF(I33=0,"",I33/I$7) | K33: =SUM(K24:K32) -> 0 | L33: =IF(K33=0,"",K33/K$7)
D34: =IF(C34=0,"",C34/C$7) | F34: =IF(E34=0,"",E34/E$7) | H34: =IF(G34=0,"",G34/G$7) | J34: =IF(I34=0,"",I34/I$7) | L34: =IF(K34=0,"",K34/K$7)
D35: =IF(C35=0,"",C35/C$7) | F35: =IF(E35=0,"",E35/E$7) | H35: =IF(G35=0,"",G35/G$7) | J35: =IF(I35=0,"",I35/I$7) | L35: =IF(K35=0,"",K35/K$7)
D36: =IF(C36=0,"",C36/C$7) | F36: =IF(E36=0,"",E36/E$7) | H36: =IF(G36=0,"",G36/G$7) | J36: =IF(I36=0,"",I36/I$7) | L36: =IF(K36=0,"",K36/K$7)
D39: =IF(C39=0,"",C39/C$7) | F39: =IF(E39=0,"",E39/E$7) | H39: =IF(G39=0,"",G39/G$7) | J39: =IF(I39=0,"",I39/I$7) | L39: =IF(K39=0,"",K39/K$7)
D40: =IF(C40=0,"",C40/C$7) | F40: =IF(E40=0,"",E40/E$7) | H40: =IF(G40=0,"",G40/G$7) | J40: =IF(I40=0,"",I40/I$7) | L40: =IF(K40=0,"",K40/K$7)
D41: =IF(C41=0,"",C41/C$7) | F41: =IF(E41=0,"",E41/E$7) | H41: =IF(G41=0,"",G41/G$7) | J41: =IF(I41=0,"",I41/I$7) | L41: =IF(K41=0,"",K41/K$7)
D42: =IF(C42=0,"",C42/C$7) | F42: =IF(E42=0,"",E42/E$7) | H42: =IF(G42=0,"",G42/G$7) | J42: =IF(I42=0,"",I42/I$7) | L42: =IF(K42=0,"",K42/K$7)
D43: =IF(C43=0,"",C43/C$7) | F43: =IF(E43=0,"",E43/E$7) | H43: =IF(G43=0,"",G43/G$7) | J43: =IF(I43=0,"",I43/I$7) | L43: =IF(K43=0,"",K43/K$7)
D44: =IF(C44=0,"",C44/C$7) | F44: =IF(E44=0,"",E44/E$7) | H44: =IF(G44=0,"",G44/G$7) | J44: =IF(I44=0,"",I44/I$7) | L44: =IF(K44=0,"",K44/K$7)
D45: =IF(C45=0,"",C45/C$7) | F45: =IF(E45=0,"",E45/E$7) | H45: =IF(G45=0,"",G45/G$7) | J45: =IF(I45=0,"",I45/I$7) | L45: =IF(K45=0,"",K45/K$7)
B46: 経費 | C46: =SUM(C34:C45) -> 0 | D46: =IF(C46=0,"",C46/C$7) | E46: =SUM(E34:E45) -> 0 | F46: =IF(E46=0,"",E46/E$7) | G46: =SUM(G34:G45) -> 0 | H46: =IF(G46=0,"",G46/G$7) | I46: =SUM(I34:I45) -> 0 | J46: =IF(I46=0,"",I46/I$7) | K46: =SUM(K34:K45) -> 0 | L46: =IF(K46=0,"",K46/K$7)
B47: 当期製造費用 | C47: =C14+C23+C33+C46 -> 0 | D47: =IF(C47=0,"",C47/C$7) | E47: =E14+E23+E33+E46 -> 0 | F47: =IF(E47=0,"",E47/E$7) | G47: =G14+G23+G33+G46 -> 0 | H47: =IF(G47=0,"",G47/G$7) | I47: =I14+I23+I33+I46 -> 0 | J47: =IF(I47=0,"",I47/I$7) | K47: =K14+K23+K33+K46 -> 0 | L47: =IF(K47=0,"",K47/K$7)
B48: 期首仕掛品棚卸高 | D48: =IF(C48=0,"",C48/C$7) | E48: =SUM(E36:E47) -> 0 | F48: =IF(E48=0,"",E48/E$7) | G48: =SUM(G36:G47) -> 0 | H48: =IF(G48=0,"",G48/G$7) | I48: =SUM(I36:I47) -> 0 | J48: =IF(I48=0,"",I48/I$7) | K48: =SUM(K36:K47) -> 0 | L48: =IF(K48=0,"",K48/K$7)
B49: 合計 | C49: =SUM(C47:C48) -> 0 | D49: =IF(C49=0,"",C49/C$7) | E49: =SUM(E47:E48) -> 0 | F49: =IF(E49=0,"",E49/E$7) | G49: =SUM(G47:G48) -> 0 | H49: =IF(G49=0,"",G49/G$7) | I49: =SUM(I47:I48) -> 0 | J49: =IF(I49=0,"",I49/I$7) | K49: =SUM(K47:K48) -> 0 | L49: =IF(K49=0,"",K49/K$7)
B50: 期末仕掛品棚卸高 | D50: =IF(C50=0,"",C50/C$7) | E50: =SUM(E40:E49) -> 0 | F50: =IF(E50=0,"",E50/E$7) | G50: =SUM(G40:G49) -> 0 | H50: =IF(G50=0,"",G50/G$7) | I50: =SUM(I40:I49) -> 0 | J50: =IF(I50=0,"",I50/I$7) | K50: =SUM(K40:K49) -> 0 | L50: =IF(K50=0,"",K50/K$7)
...

Sheet SGA
A1: ■ 貼付範囲 B2:L40 → 企業概要書「販売費及び一般管理費」（売上行・C:D列・空行は非表示）
L2: (単位：千円)
B3: 科目 | C3: ='BS(借方)'!C4 -> ●●年●月期 | E3: ='BS(借方)'!D4 -> 24年3月期 | G3: ='BS(借方)'!E4 -> 25年3月期 | I3: ='BS(借方)'!F4 -> 26年3月期 | K3: ='BS(借方)'!G4 -> 27年3月期 4〜9月TB
C4: 帳簿価額 | D4: 売上高比 | E4: 帳簿価額 | F4: 売上高比 | G4: 帳簿価額 | H4: 売上高比 | I4: 帳簿価額 | J4: 売上高比 | K4: 帳簿価額 | L4: 売上高比
B5: 売上 | C5: =PL!C11 -> 0 | E5: =PL!E11 -> 1178489098 | F5: - | G5: =PL!G11 -> 1181947340 | H5: - | I5: =PL!I11 -> 1195893269 | J5: - | K5: =PL!K11 -> 621331427 | L5: - | M5: ←IMに貼るときは非表示
B6: 役員報酬 | E6: 22200000 | F6: =E6/$E$5 -> 0.01883768 | G6: 22200000 | H6: =G6/$G$5 -> 0.018782563 | I6: 15360000 | J6: =I6/$I$5 -> 0.012843956 | K6: 6150000 | L6: =K6/$K$5 -> 0.009898099
B7: 給料手当 | E7: 73148460 | F7: =E7/$E$5 -> 0.062069696 | G7: 74179162 | H7: =G7/$G$5 -> 0.062760124 | I7: 71673365 | J7: =I7/$I$5 -> 0.059932911 | K7: 30948228 | L7: =K7/$K$5 -> 0.049809533
B8: 賞与 | E8: 6002150 | F8: =E8/$E$5 -> 0.0050930891 | G8: 5692500 | H8: =G8/$G$5 -> 0.0048162044 | J8: =I8/$I$5 -> 0 | L8: =K8/$K$5 -> 0
B9: 退職金共済掛金 | E9: 3175000 | F9: =E9/$E$5 -> 0.0026941276 | G9: 3166000 | H9: =G9/$G$5 -> 0.0026786303 | I9: 3026000 | J9: =I9/$I$5 -> 0.0025303261 | K9: 1139000 | L9: =K9/$K$5 -> 0.0018331601
B10: 退職金 | F10: =E10/$E$5 -> 0 | G10: 356400 | H10: =G10/$G$5 -> 0.00030153628 | I10: 746960 | J10: =I10/$I$5 -> 0.00062460423 | L10: =K10/$K$5 -> 0
B11: 法定福利費 | E11: 15154087 | F11: =E11/$E$5 -> 0.012858911 | G11: 14913183 | H11: =G11/$G$5 -> 0.012617468 | I11: 13295870 | J11: =I11/$I$5 -> 0.01111794 | K11: 5327882 | L11: =K11/$K$5 -> 0.0085749437
B12: 福利厚生費 | E12: 594849 | F12: =E12/$E$5 -> 0.00050475562 | G12: 899852 | H12: =G12/$G$5 -> 0.00076133003 | I12: 460243 | J12: =I12/$I$5 -> 0.00038485291 | K12: 124395 | L12: =K12/$K$5 -> 0.00020020716
B13: 広告宣伝費 | E13: 203020 | F13: =E13/$E$5 -> 0.00017227143 | G13: 114444 | H13: =G13/$G$5 -> 9.6826649e-05 | I13: 89300 | J13: =I13/$I$5 -> 7.4672216e-05 | K13: 10000 | L13: =K13/$K$5 -> 1.609447e-05
B14: 旅費交通費 | E14: 44957 | F14: =E14/$E$5 -> 3.8147998e-05 | G14: 212048 | H14: =G14/$G$5 -> 0.00017940562 | I14: 78650 | J14: =I14/$I$5 -> 6.5766739e-05 | K14: 9490 | L14: =K14/$K$5 -> 1.5273652e-05
B15: 通信費 | E15: 1434812 | F15: =E15/$E$5 -> 0.0012175013 | G15: 1143086 | H15: =G15/$G$5 -> 0.00096712092 | I15: 1191701 | J15: =I15/$I$5 -> 0.00099649445 | K15: 502790 | L15: =K15/$K$5 -> 0.00080921386
B16: 車両関連費 | E16: 8475295 | F16: =E16/$E$5 -> 0.0071916618 | G16: 10126052 | H16: =G16/$G$5 -> 0.0085672615 | I16: 9861597 | J16: =I16/$I$5 -> 0.0082462183 | K16: 4665234 | L16: =K16/$K$5 -> 0.0075084469
B17: 運賃 | E17: 27546757 | F17: =E17/$E$5 -> 0.023374639 | G17: 29493733 | H17: =G17/$G$5 -> 0.024953509 | I17: 28996599 | J17: =I17/$I$5 -> 0.024246812 | K17: 12047802 | L17: =K17/$K$5 -> 0.019390299
B18: 振込手数料負担金 | E18: 122652 | F18: =E18/$E$5 -> 0.00010407563 | G18: 207322 | H18: =G18/$G$5 -> 0.00017540714 | I18: 215198 | J18: =I18/$I$5 -> 0.0001799475 | K18: 96382 | L18: =K18/$K$5 -> 0.00015512172
B19: 委託手数料 | E19: 3709319 | F19: =E19/$E$5 -> 0.0031475208 | G19: 3538995 | H19: =G19/$G$5 -> 0.002994207 | I19: 4075300 | J19: =I19/$I$5 -> 0.0034077456 | K19: 2223299 | L19: =K19/$K$5 -> 0.0035782819
B20: 接待交際費 | E20: 3474959 | F20: =E20/$E$5 -> 0.002948656 | G20: 2485921 | H20: =G20/$G$5 -> 0.0021032418 | I20: 1580405 | J20: =I20/$I$5 -> 0.0013215268 | K20: 1059003 | L20: =K20/$K$5 -> 0.0017044092
B21: 水道光熱費 | E21: 4423538 | F21: =E21/$E$5 -> 0.0037535672 | G21: 4700697 | H21: =G21/$G$5 -> 0.0039770782 | I21: 4684668 | J21: =I21/$I$5 -> 0.0039172961 | K21: 2318547 | L21: =K21/$K$5 -> 0.0037315785
B22: 消耗品費 | E22: 35750 | F22: =E22/$E$5 -> 3.0335452e-05 | H22: =G22/$G$5 -> 0 | I22: 95055 | J22: =I22/$I$5 -> 7.9484518e-05 | L22: =K22/$K$5 -> 0
B23: 租税公課 | E23: 14464767 | F23: =E23/$E$5 -> 0.012273993 | G23: 12813800 | H23: =G23/$G$5 -> 0.010841261 | I23: 12176834 | J23: =I23/$I$5 -> 0.010182208 | K23: 3616634 | L23: =K23/$K$5 -> 0.0058207807
B24: 支払手数料 | E24: 1546474 | F24: =E24/$E$5 -> 0.0013122514 | G24: 1527460 | H24: =G24/$G$5 -> 0.0012923249 | I24: 1596627 | J24: =I24/$I$5 -> 0.0013350916 | K24: 1290018 | L24: =K24/$K$5 -> 0.0020762156
B25: 諸会費 | E25: 181000 | F25: =E25/$E$5 -> 0.00015358649 | G25: 141000 | H25: =G25/$G$5 -> 0.00011929465 | I25: 138400 | J25: =I25/$I$5 -> 0.00011572939 | K25: 116000 | L25: =K25/$K$5 -> 0.00018669585
B26: 寄付金 | E26: 13000 | F26: =E26/$E$5 -> 1.1031074e-05 | G26: 71000 | H26: =G26/$G$5 -> 6.0070358e-05 | I26: 11000 | J26: =I26/$I$5 -> 9.1981453e-06 | K26: 7000 | L26: =K26/$K$5 -> 1.1266129e-05
B27: リース料 | E27: 4711966 | F27: =E27/$E$5 -> 0.0039983111 | G27: 6710821 | H27: =G27/$G$5 -> 0.0056777665 | I27: 6227194 | J27: =I27/$I$5 -> 0.0052071486 | K27: 3082216 | L27: =K27/$K$5 -> 0.0049606633
B28: 支払保険料 | E28: 2772322 | F28: =E28/$E$5 -> 0.0023524375 | G28: 1431329 | H28: =G28/$G$5 -> 0.0012109922 | I28: 1541660 | J28: =I28/$I$5 -> 0.0012891284 | K28: 325790 | L28: =K28/$K$5 -> 0.00052434174
B29: 修繕費 | E29: 1169740 | F29: =E29/$E$5 -> 0.000992576 | G29: 707846 | H29: =G29/$G$5 -> 0.00059888117 | I29: 123750 | J29: =I29/$I$5 -> 0.00010347913 | K29: 702130 | L29: =K29/$K$5 -> 0.001130041
B30: 事務用消耗品費 | E30: 2033078 | F30: =E30/$E$5 -> 0.0017251564 | G30: 1934919 | H30: =G30/$G$5 -> 0.0016370602 | I30: 2335738 | J30: =I30/$I$5 -> 0.0019531325 | K30: 1408266 | L30: =K30/$K$5 -> 0.0022665295
B31: 減価償却費 | E31: 13663684 | F31: =E31/$E$5 -> 0.011594239 | G31: 12557564 | H31: =G31/$G$5 -> 0.01062447 | I31: 8878970 | J31: =I31/$I$5 -> 0.0074245505 | K31: 3654000 | L31: =K31/$K$5 -> 0.0058809193
B32: 雑費 | E32: 4521805 | F32: =E32/$E$5 -> 0.0038369511 | G32: 4393320 | H32: =G32/$G$5 -> 0.0037170184 | I32: 4689970 | J32: =I32/$I$5 -> 0.0039217296 | K32: 1899133 | L32: =K32/$K$5 -> 0.0030565539
F33: =E33/$E$5 -> 0 | H33: =G33/$G$5 -> 0 | J33: =I33/$I$5 -> 0 | L33: =K33/$K$5 -> 0
B34: 消費税引当金 | F34: =E34/$E$5 -> 0 | H34: =G34/$G$5 -> 0 | J34: =I34/$I$5 -> 0 | K34: 3023000 | L34: =K34/$K$5 -> 0.0048653583
F35: =E35/$E$5 -> 0 | H35: =G35/$G$5 -> 0 | J35: =I35/$I$5 -> 0 | L35: =K35/$K$5 -> 0
F36: =E36/$E$5 -> 0 | H36: =G36/$G$5 -> 0 | J36: =I36/$I$5 -> 0 | L36: =K36/$K$5 -> 0
F37: =E37/$E$5 -> 0 | H37: =G37/$G$5 -> 0 | J37: =I37/$I$5 -> 0 | L37: =K37/$K$5 -> 0
F38: =E38/$E$5 -> 0 | H38: =G38/$G$5 -> 0 | J38: =I38/$I$5 -> 0 | L38: =K38/$K$5 -> 0
F39: =E39/$E$5 -> 0 | H39: =G39/$G$5 -> 0 | J39: =I39/$I$5 -> 0 | L39: =K39/$K$5 -> 0
B40: 販売費および一般管理費合計 | C40: =SUM(C6:C39) -> 0 | E40: =SUM(E6:E39) -> 214823441 | F40: =E40/E5 -> 0.18228717 | G40: =SUM(G6:G39) -> 215718454 | H40: =G40/G5 -> 0.18251105 | I40: =SUM(I6:I39) -> 193151054 | J40: =I40/I5 -> 0.16151195 | K40: =SUM(K6:K39) -> 85746239 | L40: =K40/K5 -> 0.13800403
...

Sheet VR→ 

Sheet 株式価値 
A1: 作業不要（自動作成）
F2: (単位：千円)
C3: min | D3: 差（グラフ作成用） | E3: max
B4: インカム | C4: 0 | D4: 0 | E4: 0 | F4: 100 | I4: ｚ
B5: マーケット | C5: ='EV EBITDAマルチプル'!K7 -> -87379098 | D5: =E5-C5 -> 37467417 | E5: ='EV EBITDAマルチプル'!M7 -> -49911682 | F5: 0
B6: コスト | C6: =年買法!K6 -> 65761604 | D6: =E6-C6 -> 20886293 | E6: =年買法!M6 -> 86647897 | F6: 0

Sheet 修正BS(借方)
E2: (単位：千円)
B3: 資産の部
B4: 科目 | C4: ='BS(借方)'!F4 -> 26年3月期 | D4: 修正額 | E4: 修正後
B5: 【流動資産】 | C5: =SUM(C6:C19) -> 249704912 | D5: =SUM(D6:D19) -> 203000 | E5: =C5+D5 -> 249907912
B6: ='BS(借方)'!B6 -> 現金及び預金 | C6: ='BS(借方)'!F6 -> 210887077 | E6: =C6+D6 -> 210887077
B7: ='BS(借方)'!B7 -> 売掛金 | C7: ='BS(借方)'!F7 -> 19608899 | E7: =C7+D7 -> 19608899
B8: ='BS(借方)'!B8 -> 資材肥料売掛金 | C8: ='BS(借方)'!F8 -> 1227419 | E8: =C8+D8 -> 1227419
B9: ='BS(借方)'!B9 -> 棚卸資産 | C9: ='BS(借方)'!F9 -> 14596695 | E9: =C9+D9 -> 14596695
B10: ='BS(借方)'!B10 -> 立替金 | C10: ='BS(借方)'!F10 -> 0 | E10: =C10+D10 -> 0
B11: ='BS(借方)'!B11 -> 未収入金 | C11: ='BS(借方)'!F11 -> 3011112 | E11: =C11+D11 -> 3011112
B12: ='BS(借方)'!B12 -> 仮払金 | C12: ='BS(借方)'!F12 -> 493135 | E12: =C12+D12 -> 493135
B13: ='BS(借方)'!B13 -> 前払費用 | C13: ='BS(借方)'!F13 -> 83575 | E13: =C13+D13 -> 83575
B14: ='BS(借方)'!B14 -> 仮払税金等 | C14: ='BS(借方)'!F14 -> 0 | E14: =C14+D14 -> 0
B15: ='BS(借方)'!B15 -> 貸倒引当金 | C15: ='BS(借方)'!F15 -> -203000 | D15: 203000 | E15: =C15+D15 -> 0 | F15: 個別に回収可能性を判断するため全額戻入（貸倒実績は要確認）
B16: ='BS(借方)'!B16 -> 0 | C16: ='BS(借方)'!F16 -> 0 | E16: =C16+D16 -> 0
B17: ='BS(借方)'!B17 -> 0 | C17: ='BS(借方)'!F17 -> 0 | E17: =C17+D17 -> 0
B18: ='BS(借方)'!B18 -> 0 | C18: ='BS(借方)'!F18 -> 0 | E18: =C18+D18 -> 0
E19: =C19+D19 -> 0
B20: 【固定資産】 | C20: =C21+C35+C46 -> 235485192 | D20: =D21+D35+D46 -> -20225824 | E20: =C20+D20 -> 2.1525937e+08
B21: ［有形固定資産］ | C21: =SUM(C22:C34) -> 196905728 | D21: =SUM(D22:D34) -> -25312229 | E21: =C21+D21 -> 1.715935e+08
B22: ='BS(借方)'!B22 -> 建物 | C22: ='BS(借方)'!F22 -> 92065694 | E22: =C22+D22 -> 92065694
B23: ='BS(借方)'!B23 -> 建物付属設備 | C23: ='BS(借方)'!F23 -> 11399836 | E23: =C23+D23 -> 11399836
B24: ='BS(借方)'!B24 -> 構築物 | C24: ='BS(借方)'!F24 -> 284395 | E24: =C24+D24 -> 284395
B25: ='BS(借方)'!B25 -> 機械装置 | C25: ='BS(借方)'!F25 -> 2 | E25: =C25+D25 -> 2
B26: ='BS(借方)'!B26 -> 車両運搬具 | C26: ='BS(借方)'!F26 -> 15 | E26: =C26+D26 -> 15
B27: ='BS(借方)'!B27 -> 工具器具備品 | C27: ='BS(借方)'!F27 -> 18546 | E27: =C27+D27 -> 18546
B28: ='BS(借方)'!B28 -> 土地 | C28: ='BS(借方)'!F28 -> 93137240 | D28: =土地!E8 -> -25312229 | E28: =C28+D28 -> 67825011 | F28: 固定資産税評価額（R8年度）÷0.7で時価を推計（「土地」シート）
B29: ='BS(借方)'!B29 -> 減価償却累計額 | C29: ='BS(借方)'!F29 -> 0 | E29: =C29+D29 -> 0
B30: ='BS(借方)'!B30 -> 0 | C30: ='BS(借方)'!F30 -> 0 | E30: =C30+D30 -> 0
B31: ='BS(借方)'!B31 -> 0 | C31: ='BS(借方)'!F31 -> 0 | E31: =C31+D31 -> 0
B32: ='BS(借方)'!B32 -> 0 | C32: ='BS(借方)'!F32 -> 0 | E32: =C32+D32 -> 0
B33: ='BS(借方)'!B33 -> 0 | C33: ='BS(借方)'!F33 -> 0 | E33: =C33+D33 -> 0
E34: =C34+D34 -> 0
B35: ［無形固定資産］ | C35: =SUM(C36:C45) -> 2527395 | D35: =SUM(D36:D45) -> -2155595 | E35: =C35+D35 -> 371800
B36: ='BS(借方)'!B36 -> 電話加入権 | C36: ='BS(借方)'!F36 -> 2155595 | D36: -2155595 | E36: =C36+D36 -> 0 | F36: 換金価値なしとしてゼロ評価
B37: ='BS(借方)'!B37 -> ソフトウェア | C37: ='BS(借方)'!F37 -> 371800 | E37: =C37+D37 -> 371800
B38: ='BS(借方)'!B38 -> 0 | C38: ='BS(借方)'!F38 -> 0 | E38: =C38+D38 -> 0
B39: ='BS(借方)'!B39 -> 0 | C39: ='BS(借方)'!F39 -> 0 | E39: =C39+D39 -> 0
B40: ='BS(借方)'!B40 -> 0 | C40: ='BS(借方)'!F40 -> 0 | E40: =C40+D40 -> 0
E41: =C41+D41 -> 0
...

Sheet 売掛・棚卸
E2: (単位：千円)
A3: 売掛金 | B3: 相手先 | C3: 帳簿価額 | D3: 評価差額 | E3: 評価額 | F3: 調整事由
B4: 売掛金（青果物） | C4: ='BS(借方)'!F7 -> 19608899 | D4: 0 | E4: =SUM(C4,D4) -> 19608899 | F4: 年齢表未受領のため簿価評価（長期滞留の有無は要確認）
B5: 資材肥料売掛金 | C5: ='BS(借方)'!F8 -> 1227419 | D5: 0 | E5: =SUM(C5,D5) -> 1227419 | F5: 同上
B8: 合計 | C8: =SUM(C4:C7) -> 20836318 | D8: =SUM(D4:D7) -> 0 | E8: =C8+D8 -> 20836318
E12: (単位：千円)
A13: 商品在庫 | B13: 相手先 | C13: 帳簿価額 | D13: 評価差額 | E13: 評価額 | F13: 調整事由
B14: 棚卸資産（青果物・資材） | C14: ='BS(借方)'!F9 -> 14596695 | D14: 0 | E14: =C14+D14 -> 14596695 | F14: 青果物は短期回転。廃棄を要する滞留在庫はなく帳簿は概ね実態どおり（第2回面談）。資材の滞留有無は要確認
B18: 合計 | C18: =SUM(C14:C17) -> 14596695 | D18: =SUM(D14:D17) -> 0 | E18: =C18+D18 -> 14596695

Sheet 減価償却
E2: (単位：千円)
B3: 資産 | C3: 帳簿価額 | D3: 評価差額 | E3: 評価額 | F3: 調整事由
B4: 建物 | C4: ='BS(借方)'!F22 -> 92065694 | D4: 0 | E4: =SUM(C4,D4) -> 92065694 | F4: 固定資産台帳未受領。別表十六で償却不足なしを確認し簿価評価
B5: 建物付属設備 | C5: ='BS(借方)'!F23 -> 11399836 | D5: 0 | E5: =SUM(C5,D5) -> 11399836 | F5: 簿価評価
B6: 構築物 | C6: ='BS(借方)'!F24 -> 284395 | D6: 0 | E6: =SUM(C6,D6) -> 284395 | F6: 簿価評価
B7: 車両運搬具・工具器具備品等 | C7: ='BS(借方)'!F25+'BS(借方)'!F26+'BS(借方)'!F27 -> 18563 | D7: 0 | E7: =SUM(C7,D7) -> 18563 | F7: 簿価評価
B8: 合計 | C8: =SUM(C4:C7) -> 103768488 | D8: =SUM(D4:D7) -> 0 | E8: =C8+D8 -> 103768488

Sheet 土地
F2: (単位：千円)
B3: 内容・所在地 | C3: 地積(㎡) | D3: 帳簿価額 | E3: 評価差額 | F3: 時価評価額 | G3: 調整事由
B4: 本社・市場／鶴岡市宝田一丁目4-2 | C4: 3100.22 | D4: 70757240 | E4: =F4-D4 -> -19526947 | F4: ='不動産(所有)'!I4 -> 51230293 | G4: 固定資産税評価額（R8年度）÷0.7にて時価を推計（鑑定・路線価で要確認）
B5: パッケージ場／鶴岡市宝田一丁目5-1 | C5: 900.5 | D5: 21380000 | E5: =F5-D5 -> -6293860 | F5: ='不動産(所有)'!I10 -> 15086140 | G5: 固定資産税評価額（R8年度）÷0.7にて時価を推計（鑑定・路線価で要確認）
B6: 旧倉庫敷地（駐車場）／東田川郡庄内町長沼字宮前304-7 | C6: 261.81 | D6: 1000000 | E6: =F6-D6 -> 508578.57 | F6: ='不動産(所有)'!I13 -> 1508578.6 | G6: 固定資産税評価額（R8年度）÷0.7にて時価を推計（鑑定・路線価で要確認）
B8: 合計 | C8: =SUM(C4:C7) -> 4262.53 | D8: =SUM(D4:D7) -> 93137240 | E8: =SUM(E4:E7) -> -25312229 | F8: =SUM(F4:F7) -> 67825011

Sheet 保険
E2: (単位：千円)
B3: 保険商品 | C3: 帳簿価額 | D3: 評価差額 | E3: 評価額 | F3: 調整事由
B4: 事業保険積立金 | C4: 0 | D4: =E4-C4 -> 0 | E4: 0 | F4: 2026/3期に全額取崩し済（前期損益修正損20,900千円）。簿外の解約返戻金の有無は要確認
B8: 合計 | C8: =SUM(C4:C7) -> 0 | D8: =SUM(D4:D7) -> 0 | E8: =C8+D8 -> 0

Sheet 有価証券
F2: (単位：千円)
B3: 銘柄 | C3: 数量 | D3: 帳簿価額 | E3: 評価差額 | F3: 評価額 | G3: 調整事由
B4: 株式）フィデアホールディングス | C4: 3000 | D4: 1200000 | E4: =F4-D4 -> 7242000 | F4: =2814*C4 -> 8442000 | G4: 2026年9月18日終値（2,814円）を元に時価を算出（算定日終値で要更新）
B5: 株式）(株)庄果・出資金）鶴岡信用金庫ほか | C5: - | D5: 1400000 | E5: =F5-D5 -> 0 | F5: =D5 -> 1400000 | G5: 取引関係上の保有。市場価格なし（簿価評価）
B9: 合計 | C9: - | D9: =SUM(D4:D8) -> 2600000 | E9: =SUM(E4:E8) -> 7242000 | F9: =D9+E9 -> 9842000

Sheet 修正BS(貸方) 
E2: (単位：千円)
B3: 負債の部
B4: 科目 | C4: ='修正BS(借方)'!C4 -> 26年3月期 | D4: 修正額 | E4: 修正後
B5: 【流動負債】 | C5: =SUM(C6:C17) -> 37279523 | D5: =SUM(D6:D17) -> 0 | E5: =C5+D5 -> 37279523
B6: ='BS (貸方)'!B6 -> 買掛金 | C6: ='BS (貸方)'!F6 -> 26349122 | E6: =C6+D6 -> 26349122
B7: ='BS (貸方)'!B7 -> 未払金 | C7: ='BS (貸方)'!F7 -> 6630301 | E7: =C7+D7 -> 6630301
B8: ='BS (貸方)'!B8 -> 仮受金 | C8: ='BS (貸方)'!F8 -> 0 | E8: =C8+D8 -> 0
B9: ='BS (貸方)'!B9 -> 預り金 | C9: ='BS (貸方)'!F9 -> 281300 | E9: =C9+D9 -> 281300
B10: ='BS (貸方)'!B10 -> 未払法人税等 | C10: ='BS (貸方)'!F10 -> 1851300 | E10: =C10+D10 -> 1851300
B11: ='BS (貸方)'!B11 -> 未払消費税 | C11: ='BS (貸方)'!F11 -> 2167500 | E11: =C11+D11 -> 2167500
B12: ='BS (貸方)'!B12 -> 0 | C12: ='BS (貸方)'!F12 -> 0 | E12: =C12+D12 -> 0
B13: ='BS (貸方)'!B13 -> 0 | C13: ='BS (貸方)'!F13 -> 0 | E13: =C13+D13 -> 0
B14: ='BS (貸方)'!B14 -> 0 | C14: ='BS (貸方)'!F14 -> 0 | E14: =C14+D14 -> 0
B15: ='BS (貸方)'!B15 -> 0 | C15: ='BS (貸方)'!F15 -> 0 | E15: =C15+D15 -> 0
B16: ='BS (貸方)'!B16 -> 0 | C16: ='BS (貸方)'!F16 -> 0 | E16: =C16+D16 -> 0
E17: =C17+D17 -> 0
B18: 【固定負債】 | C18: =SUM(C19:C26) -> 370038000 | D18: =SUM(D19:D26) -> 0 | E18: =C18+D18 -> 370038000
B19: ='BS (貸方)'!B19 -> 長期借入金 | C19: ='BS (貸方)'!F19 -> 361058000 | E19: =C19+D19 -> 361058000
B20: ='BS (貸方)'!B20 -> 預り保証金 | C20: ='BS (貸方)'!F20 -> 8980000 | E20: =C20+D20 -> 8980000
B21: ='BS (貸方)'!B21 -> 0 | C21: ='BS (貸方)'!F21 -> 0 | E21: =C21+D21 -> 0
B22: ='BS (貸方)'!B22 -> 0 | C22: ='BS (貸方)'!F22 -> 0 | E22: =C22+D22 -> 0
B23: ='BS (貸方)'!B23 -> 0 | C23: ='BS (貸方)'!F23 -> 0 | E23: =C23+D23 -> 0
E24: =C24+D24 -> 0
E25: =C25+D25 -> 0
E26: =C26+D26 -> 0
B27: 【繰延税金負債】 | C27: 0 | D27: =税効果!E18 -> 2531300 | E27: =C27+D27 -> 2531300
B28: 負債合計 | C28: =C5+C18+C27 -> 407317523 | D28: =D5+D18+D27 -> 2531300 | E28: =C28+D28 -> 409848823
B34: 純資産の部
B35: 【資本金】 | C35: =SUM(C36:C38) -> 40000000 | D35: =SUM(D36:D38) -> 0 | E35: =C35+D35 -> 40000000
B36: ='BS (貸方)'!B36 -> 資本金 | C36: ='BS (貸方)'!F36 -> 40000000 | E36: =C36+D36 -> 40000000
E37: =C37+D37 -> 0
E38: =C38+D38 -> 0
B39: 【資本剰余金】 | C39: =SUM(C40:C42) -> 0 | D39: =SUM(D40:D42) -> 0 | E39: =C39+D39 -> 0
E40: =C40+D40 -> 0
E41: =C41+D41 -> 0
E42: =C42+D42 -> 0
B43: 【利益剰余金】 | C43: =SUM(C44:C47) -> 37872581 | D43: =SUM(D44:D47) -> 0 | E43: =C43+D43 -> 37872581
B44: ='BS (貸方)'!B44 -> 利益準備金 | C44: ='BS (貸方)'!F44 -> 2080000 | E44: =C44+D44 -> 2080000
B45: ='BS (貸方)'!B45 -> 繰越利益剰余金 | C45: ='BS (貸方)'!F45 -> 35792581 | E45: =C45+D45 -> 35792581
B46: ='BS (貸方)'!B46 -> 0 | C46: ='BS (貸方)'!F46 -> 0 | E46: =C46+D46 -> 0
...

Sheet 未払人件費・賞与
D2: (単位：千円) | E2: (単位：千円) | F2: (単位：千円)
B3: 2026年4月支払給与（3月後半分） | C3: 未払日数 | D3: 未払給与引当額 | E3: 概算社会保険料 | F3: 未払給与引当額
B4: 2837000 | C4: 3/16〜3/31分 | D4: 0 | E4: 0 | F4: 0 | G4: 未払給与2,837千円は未払金に計上済のため追加計上なし
E7: (単位：千円)
B8: 賞与（規定なし・業績連動） | C8: 支給対象月数 | D8: 経過月数 | E8: 引当額 | F8: 概算社会保険料 | G8: 社保考慮後引当不足
B9: 0 | C9: - | D9: - | E9: 0 | F9: 0 | G9: =E9+F9 -> 0 | H9: 賞与規定なし。2026/3期は支給なし。引当不要と判断（要確認）

Sheet 退職金
J2: (単位：千円)
B3: № | C3: 氏名 | D3: 勤続年数(年) | E3: 基本給 | F3: 支給倍率 | G3: 退職理由率 | H3: 要支給額 | I3: 中退共積立額 | J3: 引当不足
C4: 全従業員 | H4: 0 | I4: 0 | J4: =H4-I4 -> 0
B6: ※中小企業退職金共済（掛金3,026千円/年）・オリックス生命で外部積立。退職時の会社の追加持出しは基本的にないとの認識（退職金規程で要確認）。
C10: 合計 | H10: =SUM(H4:H9) -> 0 | I10: =SUM(I4:I9) -> 0 | J10: =H10-I10 -> 0

Sheet 税効果
E2: (単位：千円)
B3: 修正科目 | C3: 適用判定 | D3: 修正額 | E3: 繰延税金資産/負債 | F3: 備考
B4: 貸倒引当金 | C4: 〇 | D4: ='修正BS(借方)'!D15 -> 203000 | E4: =-D4*-0.34 -> 69020 | F4: 戻入益に課税
B5: 土地 | C5: × | D5: ='修正BS(借方)'!D28 -> -25312229 | E5: 0 | F5: 事業用不動産で売却予定がなく、実現可能性が低いため除外
B6: 電話加入権 | C6: × | D6: ='修正BS(借方)'!D36 -> -2155595 | E6: 0 | F6: 流動性がないため除外
B7: 投資有価証券 | C7: 〇 | D7: ='修正BS(借方)'!D47 -> 7242000 | E7: =-D7*-0.34 -> 2462280 | F7: 評価益に課税
B18: 合計 | C18: - | D18: =SUM(D4:D17) -> -20022824 | E18: =SUM(E4:E17) -> 2531300 | F18: 繰延税金負債（評価益×実効税率34%）

Sheet ネットキャッシュ
F2: (単位：千円)
B3: キャッシュライクアイテム | C3: 金額 | E3: デットライクアイテム | F3: 金額
B4: 現金及び預金 | C4: ='修正BS(借方)'!E6 -> 210887077 | E4: 短期借入金
B5: 役員貸付金 | E5: 長期借入金 | F5: ='修正BS(貸方) '!E19 -> 361058000
B6: 従業員貸付金 | E6: 社債
B7: 立替金 | E7: 役員借入金
B8: 保険積立金 | E8: 未払法人税 | F8: ='修正BS(貸方) '!E10 -> 1851300
B9: 投資有価証券（上場株式・時価） | C9: =有価証券!F4 -> 8442000 | E9: 資産除去債務
B10: 売却予定不動産 | E10: 役員退職慰労金
B11: 売却予定車両 | E11: 営業循環外前受金
E12: ファイナンスリース債務
B13: 合計 | C13: =SUM(C4:C12) -> 219329077 | E13: 合計 | F13: =SUM(F4:F12) -> 362909300
B15: ネットキャッシュ | C15: =C13-F13 -> -143580223 | E15: ネットデット | F15: =F13-C13 -> 143580223
B19: ※預り保証金8,980千円・保証金33,303千円は事業上の預託・預り金としてネットキャッシュに含めていない（取扱いは要確認）。(株)庄果株式・信金出資は取引関係上の保有のため除外。

Sheet 修正PL
K2: (単位：千円)
B3: 科目 | C3: ='BS(借方)'!C4 -> ●●年●月期 | F3: ='BS(借方)'!D4 -> 24年3月期 | I3: ='BS(借方)'!E4 -> 25年3月期 | L3: ='BS(借方)'!F4 -> 26年3月期 | O3: ='BS(借方)'!G4 -> 27年3月期 4〜9月TB
C4: 帳簿価額 | D4: 修正額 | E4: 修正後 | F4: 帳簿価額 | G4: 修正額 | H4: 修正後 | I4: 帳簿価額 | J4: 修正額 | K4: 修正後 | L4: 帳簿価額 | M4: 修正額 | N4: 修正後 | O4: 帳簿価額 | P4: 修正額 | Q4: 修正後
B5: =PL!B5 -> 商品売上高 | C5: =PL!C5 -> 0 | E5: =C5+D5 -> 0 | F5: =PL!E5 -> 1179974308 | H5: =F5+G5 -> 1179974308 | I5: =PL!G5 -> 1183308630 | K5: =I5+J5 -> 1183308630 | L5: =PL!I5 -> 1197530299 | N5: =L5+M5 -> 1197530299 | O5: =PL!K5 -> 568871022 | Q5: =O5+P5 -> 568871022
B6: =PL!B6 -> 資材売上高 | C6: =PL!C6 -> 0 | E6: =C6+D6 -> 0 | F6: =PL!E6 -> 0 | H6: =F6+G6 -> 0 | I6: =PL!G6 -> 0 | K6: =I6+J6 -> 0 | L6: =PL!I6 -> 0 | N6: =L6+M6 -> 0 | O6: =PL!K6 -> 5369372 | Q6: =O6+P6 -> 5369372
B7: =PL!B7 -> 資材売上（自社） | C7: =PL!C7 -> 0 | E7: =C7+D7 -> 0 | F7: =PL!E7 -> 0 | H7: =F7+G7 -> 0 | I7: =PL!G7 -> 0 | K7: =I7+J7 -> 0 | L7: =PL!I7 -> 0 | N7: =L7+M7 -> 0 | O7: =PL!K7 -> 9473775 | Q7: =O7+P7 -> 9473775
B8: =PL!B8 -> 主婦センター費 | C8: =PL!C8 -> 0 | E8: =C8+D8 -> 0 | F8: =PL!E8 -> 0 | H8: =F8+G8 -> 0 | I8: =PL!G8 -> 0 | K8: =I8+J8 -> 0 | L8: =PL!I8 -> 0 | N8: =L8+M8 -> 0 | O8: =PL!K8 -> 18416492 | Q8: =O8+P8 -> 18416492
B9: =PL!B9 -> 委託手数料収入 | C9: =PL!C9 -> 0 | E9: =C9+D9 -> 0 | F9: =PL!E9 -> 0 | H9: =F9+G9 -> 0 | I9: =PL!G9 -> 0 | K9: =I9+J9 -> 0 | L9: =PL!I9 -> 0 | N9: =L9+M9 -> 0 | O9: =PL!K9 -> 19958506 | Q9: =O9+P9 -> 19958506
B10: =PL!B10 -> 売上割戻金 | C10: =PL!C10 -> 0 | E10: =C10+D10 -> 0 | F10: =PL!E10 -> -1485210 | H10: =F10+G10 -> -1485210 | I10: =PL!G10 -> -1361290 | K10: =I10+J10 -> -1361290 | L10: =PL!I10 -> -1637030 | N10: =L10+M10 -> -1637030 | O10: =PL!K10 -> -757740 | Q10: =O10+P10 -> -757740
B11: 売上高 | C11: =SUM(C5:C10) -> 0 | D11: =SUM(D5:D10) -> 0 | E11: =C11+D11 -> 0 | F11: =SUM(F5:F10) -> 1178489098 | G11: =SUM(G5:G10) -> 0 | H11: =F11+G11 -> 1178489098 | I11: =SUM(I5:I10) -> 1181947340 | J11: =SUM(J5:J10) -> 0 | K11: =I11+J11 -> 1181947340 | L11: =SUM(L5:L10) -> 1195893269 | M11: =SUM(M5:M10) -> 0 | N11: =L11+M11 -> 1195893269 | O11: =SUM(O5:O10) -> 621331427 | P11: =SUM(P5:P10) -> 0 | Q11: =O11+P11 -> 621331427
B12: =PL!B12 -> 期首棚卸高 | C12: =PL!C12 -> 0 | E12: =C12+D12 -> 0 | F12: =PL!E12 -> 15470384 | H12: =F12+G12 -> 15470384 | I12: =PL!G12 -> 9859795 | K12: =I12+J12 -> 9859795 | L12: =PL!I12 -> 15443609 | N12: =L12+M12 -> 15443609 | O12: =PL!K12 -> 14596695 | Q12: =O12+P12 -> 14596695
B13: =PL!B13 -> 仕入高 | C13: =PL!C13 -> 0 | E13: =C13+D13 -> 0 | F13: =PL!E13 -> 953298320 | H13: =F13+G13 -> 953298320 | I13: =PL!G13 -> 976235640 | K13: =I13+J13 -> 976235640 | L13: =PL!I13 -> 996035389 | N13: =L13+M13 -> 996035389 | O13: =PL!K13 -> 514967990 | Q13: =O13+P13 -> 514967990
B14: =PL!B14 -> 期末棚卸高 | C14: =PL!C14 -> 0 | E14: =C14+D14 -> 0 | F14: =PL!E14 -> -9859795 | H14: =F14+G14 -> -9859795 | I14: =PL!G14 -> -15443609 | K14: =I14+J14 -> -15443609 | L14: =PL!I14 -> -14596695 | N14: =L14+M14 -> -14596695 | O14: =PL!K14 -> -14405198 | Q14: =O14+P14 -> -14405198
B15: =PL!B15 -> 0 | C15: =PL!C15 -> 0 | E15: =C15+D15 -> 0 | F15: =PL!E15 -> 0 | H15: =F15+G15 -> 0 | I15: =PL!G15 -> 0 | K15: =I15+J15 -> 0 | L15: =PL!I15 -> 0 | N15: =L15+M15 -> 0 | O15: =PL!K15 -> 0 | Q15: =O15+P15 -> 0
B16: 売上原価 | C16: =SUM(C12:C15) -> 0 | D16: =SUM(D12:D15) -> 0 | E16: =C16+D16 -> 0 | F16: =SUM(F12:F15) -> 958908909 | G16: =SUM(G12:G15) -> 0 | H16: =F16+G16 -> 958908909 | I16: =SUM(I12:I15) -> 970651826 | J16: =SUM(J12:J15) -> 0 | K16: =I16+J16 -> 970651826 | L16: =SUM(L12:L15) -> 996882303 | M16: =SUM(M12:M15) -> 0 | N16: =L16+M16 -> 996882303 | O16: =SUM(O12:O15) -> 515159487 | P16: =SUM(P12:P15) -> 0 | Q16: =O16+P16 -> 515159487
B17: 売上総利益 | C17: =C11-C16 -> 0 | D17: =D11-D16 -> 0 | E17: =C17+D17 -> 0 | F17: =F11-F16 -> 219580189 | G17: =G11-G16 -> 0 | H17: =F17+G17 -> 219580189 | I17: =I11-I16 -> 211295514 | J17: =J11-J16 -> 0 | K17: =I17+J17 -> 211295514 | L17: =L11-L16 -> 199010966 | M17: =M11-M16 -> 0 | N17: =L17+M17 -> 199010966 | O17: =O11-O16 -> 106171940 | P17: =P11-P16 -> 0 | Q17: =O17+P17 -> 106171940
B18: 販売費及び一般管理費 | C18: =修正SGA!C39 -> 0 | D18: =修正SGA!D39 -> 0 | E18: =C18+D18 -> 0 | F18: =修正SGA!F39 -> 214823441 | G18: =修正SGA!G39 -> -20041508 | H18: =F18+G18 -> 194781933 | I18: =修正SGA!I39 -> 215718454 | J18: =修正SGA!J39 -> -20235707 | K18: =I18+J18 -> 195482747 | L18: =修正SGA!L39 -> 193151054 | M18: =修正SGA!M39 -> -6379024.2 | N18: =L18+M18 -> 1.8677203e+08 | O18: =修正SGA!O39 -> 85746239 | P18: =修正SGA!P39 -> -1406434.1 | Q18: =O18+P18 -> 84339805
B19: 営業利益 | C19: =C17- C18 -> 0 | D19: =D17- D18 -> 0 | E19: =C19+D19 -> 0 | F19: =F17- F18 -> 4756748 | G19: =G17- G18 -> 20041508 | H19: =F19+G19 -> 24798256 | I19: =I17- I18 -> -4422940 | J19: =J17- J18 -> 20235707 | K19: =I19+J19 -> 15812767 | L19: =L17- L18 -> 5859912 | M19: =M17- M18 -> 6379024.2 | N19: =L19+M19 -> 12238936 | O19: =O17- O18 -> 20425701 | P19: =P17- P18 -> 1406434.1 | Q19: =O19+P19 -> 21832135
B20: 営業外収益 | C20: =SUM(C21:C27) -> 0 | D20: =SUM(D21:D27) -> 0 | E20: =C20+D20 -> 0 | F20: =SUM(F21:F27) -> 10628095 | G20: =SUM(G21:G27) -> -2284370 | H20: =F20+G20 -> 8343725 | I20: =SUM(I21:I27) -> 10736890 | J20: =SUM(J21:J27) -> -2406729 | K20: =I20+J20 -> 8330161 | L20: =SUM(L21:L27) -> 6577758 | M20: =SUM(M21:M27) -> -2513377 | N20: =L20+M20 -> 4064381 | O20: =SUM(O21:O27) -> 2830373 | P20: =SUM(P21:P27) -> -1184146 | Q20: =O20+P20 -> 1646227
B21: =PL!B21 -> 受取利息 | C21: =PL!C21 -> 0 | E21: =C21+D21 -> 0 | F21: =PL!E21 -> 1252 | H21: =F21+G21 -> 1252 | I21: =PL!G21 -> 84858 | K21: =I21+J21 -> 84858 | L21: =PL!I21 -> 267463 | N21: =L21+M21 -> 267463 | O21: =PL!K21 -> 161697 | Q21: =O21+P21 -> 161697
B22: =PL!B22 -> 受取配当金 | C22: =PL!C22 -> 0 | E22: =C22+D22 -> 0 | F22: =PL!E22 -> 30500 | H22: =F22+G22 -> 30500 | I22: =PL!G22 -> 30500 | K22: =I22+J22 -> 30500 | L22: =PL!I22 -> 30500 | N22: =L22+M22 -> 30500 | O22: =PL!K22 -> 30950 | Q22: =O22+P22 -> 30950
B23: =PL!B23 -> 受取延滞料 | C23: =PL!C23 -> 0 | E23: =C23+D23 -> 0 | F23: =PL!E23 -> 170242 | H23: =F23+G23 -> 170242 | I23: =PL!G23 -> 147416 | K23: =I23+J23 -> 147416 | L23: =PL!I23 -> 96879 | N23: =L23+M23 -> 96879 | O23: =PL!K23 -> 58794 | Q23: =O23+P23 -> 58794
B24: =PL!B24 -> 受取奨励金 | C24: =PL!C24 -> 0 | E24: =C24+D24 -> 0 | F24: =PL!E24 -> 2284370 | G24: =-修正PL!F69 -> -2284370 | H24: =F24+G24 -> 0 | I24: =PL!G24 -> 2406729 | J24: =-修正PL!I69 -> -2406729 | K24: =I24+J24 -> 0 | L24: =PL!I24 -> 2513377 | M24: =-修正PL!L69 -> -2513377 | N24: =L24+M24 -> 0 | O24: =PL!K24 -> 1184146 | P24: =-修正PL!O69 -> -1184146 | Q24: =O24+P24 -> 0
B25: =PL!B25 -> 受取運賃・配達収入 | C25: =PL!C25 -> 0 | E25: =C25+D25 -> 0 | F25: =PL!E25 -> 0 | H25: =F25+G25 -> 0 | I25: =PL!G25 -> 0 | K25: =I25+J25 -> 0 | L25: =PL!I25 -> 0 | N25: =L25+M25 -> 0 | O25: =PL!K25 -> 163350 | Q25: =O25+P25 -> 163350
B26: =PL!B26 -> 雑収入 | C26: =PL!C26 -> 0 | E26: =C26+D26 -> 0 | F26: =PL!E26 -> 8141731 | H26: =F26+G26 -> 8141731 | I26: =PL!G26 -> 8067387 | K26: =I26+J26 -> 8067387 | L26: =PL!I26 -> 3669539 | N26: =L26+M26 -> 3669539 | O26: =PL!K26 -> 1231436 | Q26: =O26+P26 -> 1231436
E27: =C27+D27 -> 0 | H27: =F27+G27 -> 0 | K27: =I27+J27 -> 0 | N27: =L27+M27 -> 0 | Q27: =O27+P27 -> 0
B28: 営業外費用 | C28: =SUM(C29:C35) -> 0 | D28: =SUM(D29:D35) -> 0 | E28: =C28+D28 -> 0 | F28: =SUM(F29:F35) -> 4068303 | G28: =SUM(G29:G35) -> -105862 | H28: =F28+G28 -> 3962441 | I28: =SUM(I29:I35) -> 4132569 | J28: =SUM(J29:J35) -> -92022 | K28: =I28+J28 -> 4040547 | L28: =SUM(L29:L35) -> 4369886 | M28: =SUM(M29:M35) -> -94929 | N28: =L28+M28 -> 4274957 | O28: =SUM(O29:O35) -> 2090167 | P28: =SUM(P29:P35) -> 0 | Q28: =O28+P28 -> 2090167
B29: =PL!B29 -> 支払利息 | C29: =PL!C29 -> 0 | E29: =C29+D29 -> 0 | F29: =PL!E29 -> 3962441 | H29: =F29+G29 -> 3962441 | I29: =PL!G29 -> 4040547 | K29: =I29+J29 -> 4040547 | L29: =PL!I29 -> 3895556 | N29: =L29+M29 -> 3895556 | O29: =PL!K29 -> 2090167 | Q29: =O29+P29 -> 2090167
B30: =PL!B30 -> 出荷奨励金 | C30: =PL!C30 -> 0 | E30: =C30+D30 -> 0 | F30: =PL!E30 -> 105862 | G30: =-修正PL!F70 -> -105862 | H30: =F30+G30 -> 0 | I30: =PL!G30 -> 92022 | J30: =-修正PL!I70 -> -92022 | K30: =I30+J30 -> 0 | L30: =PL!I30 -> 94929 | M30: =-修正PL!L70 -> -94929 | N30: =L30+M30 -> 0 | O30: =PL!K30 -> 0 | P30: =-修正PL!O70 -> 0 | Q30: =O30+P30 -> 0
B31: =PL!B31 -> 雑損失 | C31: =PL!C31 -> 0 | E31: =C31+D31 -> 0 | F31: =PL!E31 -> 0 | H31: =F31+G31 -> 0 | I31: =PL!G31 -> 0 | K31: =I31+J31 -> 0 | L31: =PL!I31 -> 379401 | N31: =L31+M31 -> 379401 | O31: =PL!K31 -> 0 | Q31: =O31+P31 -> 0
B32: =PL!B32 -> 0 | C32: =PL!C32 -> 0 | E32: =C32+D32 -> 0 | F32: =PL!E32 -> 0 | H32: =F32+G32 -> 0 | I32: =PL!G32 -> 0 | K32: =I32+J32 -> 0 | L32: =PL!I32 -> 0 | N32: =L32+M32 -> 0 | O32: =PL!K32 -> 0 | Q32: =O32+P32 -> 0
B33: =PL!B33 -> 0 | C33: =PL!C33 -> 0 | E33: =C33+D33 -> 0 | F33: =PL!E33 -> 0 | H33: =F33+G33 -> 0 | I33: =PL!G33 -> 0 | K33: =I33+J33 -> 0 | L33: =PL!I33 -> 0 | N33: =L33+M33 -> 0 | O33: =PL!K33 -> 0 | Q33: =O33+P33 -> 0
B34: =PL!B34 -> 0 | C34: =PL!C34 -> 0 | E34: =C34+D34 -> 0 | F34: =PL!E34 -> 0 | H34: =F34+G34 -> 0 | I34: =PL!G34 -> 0 | K34: =I34+J34 -> 0 | L34: =PL!I34 -> 0 | N34: =L34+M34 -> 0 | O34: =PL!K34 -> 0 | Q34: =O34+P34 -> 0
E35: =C35+D35 -> 0 | H35: =F35+G35 -> 0 | K35: =I35+J35 -> 0 | N35: =L35+M35 -> 0 | Q35: =O35+P35 -> 0
B36: 経常利益 | C36: =C19+C20-C28 -> 0 | D36: =D19+D20-D28 -> 0 | E36: =C36+D36 -> 0 | F36: =F19+F20-F28 -> 11316540 | G36: =G19+G20-G28 -> 17863000 | H36: =F36+G36 -> 29179540 | I36: =I19+I20-I28 -> 2181381 | J36: =J19+J20-J28 -> 17921000 | K36: =I36+J36 -> 20102381 | L36: =L19+L20-L28 -> 8067784 | M36: =M19+M20-M28 -> 3960576.2 | N36: =L36+M36 -> 12028360 | O36: =O19+O20-O28 -> 21165907 | P36: =P19+P20-P28 -> 222288.12 | Q36: =O36+P36 -> 21388195
B37: 特別利益 | C37: =SUM(C38:C43) -> 0 | D37: =SUM(D38:D43) -> 0 | E37: =C37+D37 -> 0 | F37: =SUM(F38:F43) -> 1887177 | G37: =SUM(G38:G43) -> 0 | H37: =F37+G37 -> 1887177 | I37: =SUM(I38:I43) -> 1845918 | J37: =SUM(J38:J43) -> 0 | K37: =I37+J37 -> 1845918 | L37: =SUM(L38:L43) -> 234000 | M37: =SUM(M38:M43) -> 0 | N37: =L37+M37 -> 234000 | O37: =SUM(O38:O43) -> 0 | P37: =SUM(P38:P43) -> 0 | Q37: =O37+P37 -> 0
B38: =PL!B38 -> 固定資産売却益 | C38: =PL!C38 -> 0 | E38: =C38+D38 -> 0 | F38: =PL!E38 -> 1711177 | H38: =F38+G38 -> 1711177 | I38: =PL!G38 -> 1608918 | K38: =I38+J38 -> 1608918 | L38: =PL!I38 -> 0 | N38: =L38+M38 -> 0 | O38: =PL!K38 -> 0 | Q38: =O38+P38 -> 0
B39: =PL!B39 -> 貸倒引当金戻入 | C39: =PL!C39 -> 0 | E39: =C39+D39 -> 0 | F39: =PL!E39 -> 176000 | H39: =F39+G39 -> 176000 | I39: =PL!G39 -> 237000 | K39: =I39+J39 -> 237000 | L39: =PL!I39 -> 234000 | N39: =L39+M39 -> 234000 | O39: =PL!K39 -> 0 | Q39: =O39+P39 -> 0
B40: =PL!B40 -> 0 | C40: =PL!C40 -> 0 | E40: =C40+D40 -> 0 | F40: =PL!E40 -> 0 | H40: =F40+G40 -> 0 | I40: =PL!G40 -> 0 | K40: =I40+J40 -> 0 | L40: =PL!I40 -> 0 | N40: =L40+M40 -> 0 | O40: =PL!K40 -> 0 | Q40: =O40+P40 -> 0
B41: =PL!B41 -> 0 | C41: =PL!C41 -> 0 | E41: =C41+D41 -> 0 | F41: =PL!E41 -> 0 | H41: =F41+G41 -> 0 | I41: =PL!G41 -> 0 | K41: =I41+J41 -> 0 | L41: =PL!I41 -> 0 | N41: =L41+M41 -> 0 | O41: =PL!K41 -> 0 | Q41: =O41+P41 -> 0
...

Sheet 修正SGA
K2: (単位：千円)
B3: 科目 | C3: ='BS(借方)'!C4 -> ●●年●月期 | F3: ='BS(借方)'!D4 -> 24年3月期 | I3: ='BS(借方)'!E4 -> 25年3月期 | L3: ='BS(借方)'!F4 -> 26年3月期 | O3: ='BS(借方)'!G4 -> 27年3月期 4〜9月TB
C4: 帳簿価額 | D4: 修正額 | E4: 修正後 | F4: 帳簿価額 | G4: 修正額 | H4: 修正後 | I4: 帳簿価額 | J4: 修正額 | K4: 修正後 | L4: 帳簿価額 | M4: 修正額 | N4: 修正後 | O4: 帳簿価額 | P4: 修正額 | Q4: 修正後
B5: =SGA!B6 -> 役員報酬 | C5: =SGA!C6 -> 0 | E5: =C5+D5 -> 0 | F5: =SGA!E6 -> 22200000 | G5: =-修正PL!F64+修正PL!F65 -> -15240000 | H5: =F5+G5 -> 6960000 | I5: =SGA!G6 -> 22200000 | J5: =-修正PL!I64+修正PL!I65 -> -15240000 | K5: =I5+J5 -> 6960000 | L5: =SGA!I6 -> 15360000 | M5: =-修正PL!L64+修正PL!L65 -> -9000000 | N5: =L5+M5 -> 6360000 | O5: =SGA!K6 -> 6150000 | P5: =-修正PL!O64+修正PL!O65 -> -2970000 | Q5: =O5+P5 -> 3180000
B6: =SGA!B7 -> 給料手当 | C6: =SGA!C7 -> 0 | E6: =C6+D6 -> 0 | F6: =SGA!E7 -> 73148460 | H6: =F6+G6 -> 73148460 | I6: =SGA!G7 -> 74179162 | K6: =I6+J6 -> 74179162 | L6: =SGA!I7 -> 71673365 | N6: =L6+M6 -> 71673365 | O6: =SGA!K7 -> 30948228 | Q6: =O6+P6 -> 30948228
B7: =SGA!B8 -> 賞与 | C7: =SGA!C8 -> 0 | E7: =C7+D7 -> 0 | F7: =SGA!E8 -> 6002150 | G7: =-修正PL!F67 -> 0 | H7: =F7+G7 -> 6002150 | I7: =SGA!G8 -> 5692500 | J7: =-修正PL!I67 -> 0 | K7: =I7+J7 -> 5692500 | L7: =SGA!I8 -> 0 | M7: =-修正PL!L67 -> 6724423.8 | N7: =L7+M7 -> 6724423.8 | O7: =SGA!K8 -> 0 | P7: =-修正PL!O67 -> 3362211.9 | Q7: =O7+P7 -> 3362211.9
B8: =SGA!B9 -> 退職金共済掛金 | C8: =SGA!C9 -> 0 | E8: =C8+D8 -> 0 | F8: =SGA!E9 -> 3175000 | H8: =F8+G8 -> 3175000 | I8: =SGA!G9 -> 3166000 | K8: =I8+J8 -> 3166000 | L8: =SGA!I9 -> 3026000 | N8: =L8+M8 -> 3026000 | O8: =SGA!K9 -> 1139000 | Q8: =O8+P8 -> 1139000
B9: =SGA!B10 -> 退職金 | C9: =SGA!C10 -> 0 | E9: =C9+D9 -> 0 | F9: =SGA!E10 -> 0 | H9: =F9+G9 -> 0 | I9: =SGA!G10 -> 356400 | K9: =I9+J9 -> 356400 | L9: =SGA!I10 -> 746960 | N9: =L9+M9 -> 746960 | O9: =SGA!K10 -> 0 | Q9: =O9+P9 -> 0
B10: =SGA!B11 -> 法定福利費 | C10: =SGA!C11 -> 0 | E10: =C10+D10 -> 0 | F10: =SGA!E11 -> 15154087 | G10: =-修正PL!F64*修正PL!$F$66 -> -2610000 | H10: =F10+G10 -> 12544087 | I10: =SGA!G11 -> 14913183 | J10: =-修正PL!I64*修正PL!$F$66 -> -2610000 | K10: =I10+J10 -> 12303183 | L10: =SGA!I11 -> 13295870 | M10: =-修正PL!L64*修正PL!$F$66 -> -1674000 | N10: =L10+M10 -> 11621870 | O10: =SGA!K11 -> 5327882 | P10: =-修正PL!O64*修正PL!$F$66 -> -607500 | Q10: =O10+P10 -> 4720382
B11: =SGA!B12 -> 福利厚生費 | C11: =SGA!C12 -> 0 | E11: =C11+D11 -> 0 | F11: =SGA!E12 -> 594849 | H11: =F11+G11 -> 594849 | I11: =SGA!G12 -> 899852 | K11: =I11+J11 -> 899852 | L11: =SGA!I12 -> 460243 | N11: =L11+M11 -> 460243 | O11: =SGA!K12 -> 124395 | Q11: =O11+P11 -> 124395
B12: =SGA!B13 -> 広告宣伝費 | C12: =SGA!C13 -> 0 | E12: =C12+D12 -> 0 | F12: =SGA!E13 -> 203020 | H12: =F12+G12 -> 203020 | I12: =SGA!G13 -> 114444 | K12: =I12+J12 -> 114444 | L12: =SGA!I13 -> 89300 | N12: =L12+M12 -> 89300 | O12: =SGA!K13 -> 10000 | Q12: =O12+P12 -> 10000
B13: =SGA!B14 -> 旅費交通費 | C13: =SGA!C14 -> 0 | E13: =C13+D13 -> 0 | F13: =SGA!E14 -> 44957 | H13: =F13+G13 -> 44957 | I13: =SGA!G14 -> 212048 | K13: =I13+J13 -> 212048 | L13: =SGA!I14 -> 78650 | N13: =L13+M13 -> 78650 | O13: =SGA!K14 -> 9490 | Q13: =O13+P13 -> 9490
B14: =SGA!B15 -> 通信費 | C14: =SGA!C15 -> 0 | E14: =C14+D14 -> 0 | F14: =SGA!E15 -> 1434812 | H14: =F14+G14 -> 1434812 | I14: =SGA!G15 -> 1143086 | K14: =I14+J14 -> 1143086 | L14: =SGA!I15 -> 1191701 | N14: =L14+M14 -> 1191701 | O14: =SGA!K15 -> 502790 | Q14: =O14+P14 -> 502790
B15: =SGA!B16 -> 車両関連費 | C15: =SGA!C16 -> 0 | E15: =C15+D15 -> 0 | F15: =SGA!E16 -> 8475295 | H15: =F15+G15 -> 8475295 | I15: =SGA!G16 -> 10126052 | K15: =I15+J15 -> 10126052 | L15: =SGA!I16 -> 9861597 | N15: =L15+M15 -> 9861597 | O15: =SGA!K16 -> 4665234 | Q15: =O15+P15 -> 4665234
B16: =SGA!B17 -> 運賃 | C16: =SGA!C17 -> 0 | E16: =C16+D16 -> 0 | F16: =SGA!E17 -> 27546757 | H16: =F16+G16 -> 27546757 | I16: =SGA!G17 -> 29493733 | K16: =I16+J16 -> 29493733 | L16: =SGA!I17 -> 28996599 | N16: =L16+M16 -> 28996599 | O16: =SGA!K17 -> 12047802 | Q16: =O16+P16 -> 12047802
B17: =SGA!B18 -> 振込手数料負担金 | C17: =SGA!C18 -> 0 | E17: =C17+D17 -> 0 | F17: =SGA!E18 -> 122652 | H17: =F17+G17 -> 122652 | I17: =SGA!G18 -> 207322 | K17: =I17+J17 -> 207322 | L17: =SGA!I18 -> 215198 | N17: =L17+M17 -> 215198 | O17: =SGA!K18 -> 96382 | Q17: =O17+P17 -> 96382
B18: =SGA!B19 -> 委託手数料 | C18: =SGA!C19 -> 0 | E18: =C18+D18 -> 0 | F18: =SGA!E19 -> 3709319 | H18: =F18+G18 -> 3709319 | I18: =SGA!G19 -> 3538995 | K18: =I18+J18 -> 3538995 | L18: =SGA!I19 -> 4075300 | N18: =L18+M18 -> 4075300 | O18: =SGA!K19 -> 2223299 | Q18: =O18+P18 -> 2223299
B19: =SGA!B20 -> 接待交際費 | C19: =SGA!C20 -> 0 | E19: =C19+D19 -> 0 | F19: =SGA!E20 -> 3474959 | H19: =F19+G19 -> 3474959 | I19: =SGA!G20 -> 2485921 | K19: =I19+J19 -> 2485921 | L19: =SGA!I20 -> 1580405 | N19: =L19+M19 -> 1580405 | O19: =SGA!K20 -> 1059003 | Q19: =O19+P19 -> 1059003
B20: =SGA!B21 -> 水道光熱費 | C20: =SGA!C21 -> 0 | E20: =C20+D20 -> 0 | F20: =SGA!E21 -> 4423538 | H20: =F20+G20 -> 4423538 | I20: =SGA!G21 -> 4700697 | K20: =I20+J20 -> 4700697 | L20: =SGA!I21 -> 4684668 | N20: =L20+M20 -> 4684668 | O20: =SGA!K21 -> 2318547 | Q20: =O20+P20 -> 2318547
B21: =SGA!B22 -> 消耗品費 | C21: =SGA!C22 -> 0 | E21: =C21+D21 -> 0 | F21: =SGA!E22 -> 35750 | H21: =F21+G21 -> 35750 | I21: =SGA!G22 -> 0 | K21: =I21+J21 -> 0 | L21: =SGA!I22 -> 95055 | N21: =L21+M21 -> 95055 | O21: =SGA!K22 -> 0 | Q21: =O21+P21 -> 0
B22: =SGA!B23 -> 租税公課 | C22: =SGA!C23 -> 0 | E22: =C22+D22 -> 0 | F22: =SGA!E23 -> 14464767 | H22: =F22+G22 -> 14464767 | I22: =SGA!G23 -> 12813800 | K22: =I22+J22 -> 12813800 | L22: =SGA!I23 -> 12176834 | N22: =L22+M22 -> 12176834 | O22: =SGA!K23 -> 3616634 | Q22: =O22+P22 -> 3616634
... B24: =SGA!B25 -> 諸会費 | C24: =SGA!C25 -> 0 | E24: =C24+D24 -> 0 | F24: =SGA!E25 -> 181000 | H24: =F24+G24 -> 181000 | I24: =SGA!G25 -> 141000 | K24: =I24+J24 -> 141000 | L24: =SGA!I25 -> 138400 | N24: =L24+M24 -> 138400 | O24: =SGA!K25 -> 116000 | Q24: =O24+P24 -> 116000
B25: =SGA!B26 -> 寄付金 | C25: =SGA!C26 -> 0 | E25: =C25+D25 -> 0 | F25: =SGA!E26 -> 13000 | G25: =-修正PL!F68 -> -13000 | H25: =F25+G25 -> 0 | I25: =SGA!G26 -> 71000 | J25: =-修正PL!I68 -> -71000 | K25: =I25+J25 -> 0 | L25: =SGA!I26 -> 11000 | M25: =-修正PL!L68 -> -11000 | N25: =L25+M25 -> 0 | O25: =SGA!K26 -> 7000 | P25: =-修正PL!O68 -> -7000 | Q25: =O25+P25 -> 0
B26: =SGA!B27 -> リース料 | C26: =SGA!C27 -> 0 | E26: =C26+D26 -> 0 | F26: =SGA!E27 -> 4711966 | H26: =F26+G26 -> 4711966 | I26: =SGA!G27 -> 6710821 | K26: =I26+J26 -> 6710821 | L26: =SGA!I27 -> 6227194 | N26: =L26+M26 -> 6227194 | O26: =SGA!K27 -> 3082216 | Q26: =O26+P26 -> 3082216
B27: =SGA!B28 -> 支払保険料 | C27: =SGA!C28 -> 0 | E27: =C27+D27 -> 0 | F27: =SGA!E28 -> 2772322 | H27: =F27+G27 -> 2772322 | I27: =SGA!G28 -> 1431329 | K27: =I27+J27 -> 1431329 | L27: =SGA!I28 -> 1541660 | N27: =L27+M27 -> 1541660 | O27: =SGA!K28 -> 325790 | Q27: =O27+P27 -> 325790
B28: =SGA!B29 -> 修繕費 | C28: =SGA!C29 -> 0 | E28: =C28+D28 -> 0 | F28: =SGA!E29 -> 1169740 | H28: =F28+G28 -> 1169740 | I28: =SGA!G29 -> 707846 | K28: =I28+J28 -> 707846 | L28: =SGA!I29 -> 123750 | N28: =L28+M28 -> 123750 | O28: =SGA!K29 -> 702130 | Q28: =O28+P28 -> 702130
B29: =SGA!B30 -> 事務用消耗品費 | C29: =SGA!C30 -> 0 | E29: =C29+D29 -> 0 | F29: =SGA!E30 -> 2033078 | H29: =F29+G29 -> 2033078 | I29: =SGA!G30 -> 1934919 | K29: =I29+J29 -> 1934919 | L29: =SGA!I30 -> 2335738 | N29: =L29+M29 -> 2335738 | O29: =SGA!K30 -> 1408266 | Q29: =O29+P29 -> 1408266
B30: =SGA!B31 -> 減価償却費 | C30: =SGA!C31 -> 0 | E30: =C30+D30 -> 0 | F30: =SGA!E31 -> 13663684 | H30: =F30+G30 -> 13663684 | I30: =SGA!G31 -> 12557564 | K30: =I30+J30 -> 12557564 | L30: =SGA!I31 -> 8878970 | N30: =L30+M30 -> 8878970 | O30: =SGA!K31 -> 3654000 | Q30: =O30+P30 -> 3654000
B31: =SGA!B32 -> 雑費 | C31: =SGA!C32 -> 0 | E31: =C31+D31 -> 0 | F31: =SGA!E32 -> 4521805 | H31: =F31+G31 -> 4521805 | I31: =SGA!G32 -> 4393320 | K31: =I31+J31 -> 4393320 | L31: =SGA!I32 -> 4689970 | N31: =L31+M31 -> 4689970 | O31: =SGA!K32 -> 1899133 | Q31: =O31+P31 -> 1899133
B32: =SGA!B33 -> 0 | C32: =SGA!C33 -> 0 | E32: =C32+D32 -> 0 | F32: =SGA!E33 -> 0 | H32: =F32+G32 -> 0 | I32: =SGA!G33 -> 0 | K32: =I32+J32 -> 0 | L32: =SGA!I33 -> 0 | N32: =L32+M32 -> 0 | O32: =SGA!K33 -> 0 | Q32: =O32+P32 -> 0
