Workbook

Sheet 前提条件
A1: 海外向け 日本家庭料理メディア事業 収支計画モデル（36ヶ月・3シナリオ）
A2: v2（2026年7月28日・家庭料理モデル）／ 通貨単位：円（$建て商品は為替レートで換算）
A4: ■ 凡例・使い方
A5: 青字のセル … 入力値。ここだけを編集してください（B〜D列のシナリオ別前提値）
A6: 黒字のセル … 数式。編集しないでください
A7: 緑字のセル … 他シートからの参照
A8: 黄色セル … 特に感度の高い主要前提。まずここを自分の実感値に置き換えてください
A9: 月次_保守／月次_標準／月次_強気 の3シートが、それぞれB列／C列／D列の前提で自動計算されます
A10: 実績が出たら「KPI実績入力」シートに記入し、予実差を確認してください
A11: 本ファイルは開いた時点で全数式を自動再計算します（保存済みのキャッシュ値は持ちません）
A13: 【期間の定義】本モデルの1ヶ月目＝「投稿を開始した月」です。実行計画のDay 1〜30（在庫30本の
A14: 撮り溜め期間）はモデルの対象外のため、実際のカレンダー上はモデル+1ヶ月として読んでください。
A17: 項目 | B17: 保守 | C17: 標準 | D17: 強気 | E17: 単位 | F17: 備考・根拠
A18: 共通
A19: 為替レート | B19: 150 | C19: 150 | D19: 150 | E19: 円/$ | F19: 2026年7月時点の概算。変動時はここを更新
A20: ① フォロワー（Instagram＋TikTok 合算）
A21: 月次純増数：1〜3ヶ月目 | B21: 500 | C21: 1500 | D21: 3600 | E21: 人/月 | F21: 在庫30本を投入した立ち上がり期
A22: 月次純増数：4〜6ヶ月目 | B22: 800 | C22: 2600 | D22: 6200 | E22: 人/月 | F22: 週5投稿が定着した状態
A23: 月次純増数：7〜12ヶ月目 | B23: 1100 | C23: 3600 | D23: 8500 | E23: 人/月 | F23: 型が固まり伸びる投稿が読める段階
A24: 月次純増数：13〜24ヶ月目 | B24: 1500 | C24: 5200 | D24: 11500 | E24: 人/月 | F24: 外注編集の投入で本数増
A25: 月次純増数：25〜36ヶ月目 | B25: 1800 | C25: 6300 | D25: 13500 | E25: 人/月
A26: ② メールリスト（＝最重要資産）
A27: フォロワー増分→リスト転換率 | B27: 0.05 | C27: 0.08 | D27: 0.1 | E27: % | F27: リードマグネット経由。カルーセル比率で変動
A28: 広告経由のリスト獲得単価（CPL） | B28: 400 | C28: 250 | D28: 180 | E28: 円/件 | F28: 400円超なら広告を停止する運用ルール
A29: リスト月次解除率 | B29: 0.015 | C29: 0.012 | D29: 0.01 | E29: % | F29: 旅行後に解除されるため一般的な水準より高め
A30: ③ レシピデジタル商品
A31: レシピ商品 価格（〜12ヶ月目） | B31: 24 | C31: 24 | D31: 24 | E31: $ | F31: Weeknight Japanese（60レシピ＋食材置換表）
A32: 平均単価（13ヶ月目〜） | B32: 27 | C32: 32 | D32: 36 | E32: $ | F32: バンドル$45と訪日商品$19の構成を反映
A33: 新規購読者の転換率 | B33: 0.05 | C33: 0.1 | D33: 0.16 | E33: % | F33: レシピ観客にレシピ商品を売るため v1(8%)より高い
A34: 既存リストの月次残存転換率 | B34: 0.002 | C34: 0.003 | D34: 0.005 | E34: % | F34: 時間差での購入。単品商品は既存リストに1回しか売れない
A35: ローンチ月の既存リスト転換率 | B35: 0.022 | C35: 0.045 | D35: 0.08 | E35: % | F35: 5日間シーケンス実施月のみ加算
A36: 返金率 | B36: 0.06 | C36: 0.04 | D36: 0.02 | E36: % | F36: 5%超は商品欠陥のサイン
A37: 販売開始月 | B37: 5 | C37: 5 | D37: 5 | E37: ヶ月目 | F37: リスト300件を満たしてから
A38: ④ アフィリエイト（食材・調理器具）
A39: フォロワー1人あたり月間収益 | B39: 1.5 | C39: 3 | D39: 5.5 | E39: 円/人/月 | F39: Amazon各国・日本食材EC・包丁等。季節性なし
A40: ⑤ 日本食ブランドのタイアップ
A41: 単価 | B41: 100000 | C41: 200000 | D41: 350000 | E41: 円/件 | F41: アフィリ実売数を示せるかで単価が2〜3倍変わる
A42: 件数：10〜12ヶ月目 | B42: 0.3 | C42: 0.5 | D42: 1 | E42: 件/月
A43: 件数：13〜18ヶ月目 | B43: 0.5 | C43: 1 | D43: 2 | E43: 件/月
A44: 件数：19〜24ヶ月目 | B44: 1 | C44: 1.5 | D44: 3 | E44: 件/月
...

Sheet 月次_保守
A1: 月次収支計画 ― 保守シナリオ
A2: 前提条件シートのB列を参照。単位：円
A4: 月 | B4: 年次 | C4: ﾌｫﾛﾜｰ純増 | D4: ﾌｫﾛﾜｰ累計 | E4: 新規ﾘｽﾄ(自然) | F4: 新規ﾘｽﾄ(広告) | G4: 新規ﾘｽﾄ計 | H4: 解除 | I4: ﾒｰﾙﾘｽﾄ累計 | J4: 販売数(通常) | K4: 販売数(ﾛｰﾝﾁ) | L4: 販売数計 | M4: 平均単価 | N4: レシピ商品 | O4: ｱﾌｨﾘｴｲﾄ | P4: ﾀｲｱｯﾌﾟ | Q4: 訪日商品 | R4: 予約代行 | S4: 売上合計 | T4: 食材費 | U4: 英語ﾁｪｯｸ | V4: ﾂｰﾙ | W4: ﾒｰﾙ配信 | X4: 広告費 | Y4: 外注編集 | Z4: 決済手数料 | AA4: 初期投資 | AB4: ｺｽﾄ合計 | AC4: 営業利益 | AD4: 累積営業利益
A5: 1 | B5: =INT(($A5-1)/12)+1 | C5: =IF($A5<=3,前提条件!$B$21,IF($A5<=6,前提条件!$B$22,IF($A5<=12,前提条件!$B$23,IF($A5<=24,前提条件!$B$24,前提条件!$B$25)))) | D5: =$C5 | E5: =ROUND($C5*前提条件!$B$27,0) | F5: =IF($X5=0,0,ROUND($X5/前提条件!$B$28,0)) | G5: =$E5+$F5 | H5: 0 | I5: =$G5 | J5: =IF($A5<前提条件!$B$37,0,ROUND($G5*前提条件!$B$33+0*前提条件!$B$34,0)) | K5: =IF(OR($A5=5,$A5=11,$A5=15,$A5=22,$A5=30),ROUND(0*前提条件!$B$35,0),0) | L5: =$J5+$K5 | M5: =IF($A5<=12,前提条件!$B$31,前提条件!$B$32)*前提条件!$B$19 | N5: =ROUND($L5*$M5*(1-前提条件!$B$36),0) | O5: =ROUND($D5*前提条件!$B$39,0) | P5: =ROUND(IF($A5<10,0,IF($A5<=12,前提条件!$B$42,IF($A5<=18,前提条件!$B$43,IF($A5<=24,前提条件!$B$44,前提条件!$B$45))))*前提条件!$B$41,0) | Q5: =IF($A5<15,0,ROUND($G5*前提条件!$B$48*前提条件!$B$47*前提条件!$B$19,0)) | R5: =IF($A5<20,0,IF($A5<=24,前提条件!$B$51,前提条件!$B$52)*前提条件!$B$50) | S5: =SUM($N5:$R5) | T5: =IF($A5<=6,前提条件!$B$54,IF($A5<=18,前提条件!$B$55,前提条件!$B$56)) | U5: =IF($A5<=12,前提条件!$B$57,前提条件!$B$58) | V5: =前提条件!$B$59 | W5: =IF($A5<=6,0,IF($A5<=12,前提条件!$B$60,IF($A5<=24,前提条件!$B$61,前提条件!$B$62))) | X5: =IF($A5<5,0,IF($A5<=12,前提条件!$B$63,IF($A5<=24,前提条件!$B$64,前提条件!$B$65))) | Y5: =IF($A5<=12,0,IF($A5<=18,前提条件!$B$66,IF($A5<=24,前提条件!$B$67,前提条件!$B$68))) | Z5: =ROUND(($N5+$Q5)*前提条件!$B$69,0) | AA5: =IF($A5=1,前提条件!$B$70,0) | AB5: =SUM($T5:$AA5) | AC5: =$S5-$AB5 | AD5: =$AC5
A6: 2 | B6: =INT(($A6-1)/12)+1 | C6: =IF($A6<=3,前提条件!$B$21,IF($A6<=6,前提条件!$B$22,IF($A6<=12,前提条件!$B$23,IF($A6<=24,前提条件!$B$24,前提条件!$B$25)))) | D6: =$D5+$C6 | E6: =ROUND($C6*前提条件!$B$27,0) | F6: =IF($X6=0,0,ROUND($X6/前提条件!$B$28,0)) | G6: =$E6+$F6 | H6: =ROUND($I5*前提条件!$B$29,0) | I6: =$I5+$G6-$H6 | J6: =IF($A6<前提条件!$B$37,0,ROUND($G6*前提条件!$B$33+$I5*前提条件!$B$34,0)) | K6: =IF(OR($A6=5,$A6=11,$A6=15,$A6=22,$A6=30),ROUND($I5*前提条件!$B$35,0),0) | L6: =$J6+$K6 | M6: =IF($A6<=12,前提条件!$B$31,前提条件!$B$32)*前提条件!$B$19 | N6: =ROUND($L6*$M6*(1-前提条件!$B$36),0) | O6: =ROUND($D6*前提条件!$B$39,0) | P6: =ROUND(IF($A6<10,0,IF($A6<=12,前提条件!$B$42,IF($A6<=18,前提条件!$B$43,IF($A6<=24,前提条件!$B$44,前提条件!$B$45))))*前提条件!$B$41,0) | Q6: =IF($A6<15,0,ROUND($G6*前提条件!$B$48*前提条件!$B$47*前提条件!$B$19,0)) | R6: =IF($A6<20,0,IF($A6<=24,前提条件!$B$51,前提条件!$B$52)*前提条件!$B$50) | S6: =SUM($N6:$R6) | T6: =IF($A6<=6,前提条件!$B$54,IF($A6<=18,前提条件!$B$55,前提条件!$B$56)) | U6: =IF($A6<=12,前提条件!$B$57,前提条件!$B$58) | V6: =前提条件!$B$59 | W6: =IF($A6<=6,0,IF($A6<=12,前提条件!$B$60,IF($A6<=24,前提条件!$B$61,前提条件!$B$62))) | X6: =IF($A6<5,0,IF($A6<=12,前提条件!$B$63,IF($A6<=24,前提条件!$B$64,前提条件!$B$65))) | Y6: =IF($A6<=12,0,IF($A6<=18,前提条件!$B$66,IF($A6<=24,前提条件!$B$67,前提条件!$B$68))) | Z6: =ROUND(($N6+$Q6)*前提条件!$B$69,0) | AA6: =IF($A6=1,前提条件!$B$70,0) | AB6: =SUM($T6:$AA6) | AC6: =$S6-$AB6 | AD6: =$AD5+$AC6
A7: 3 | B7: =INT(($A7-1)/12)+1 | C7: =IF($A7<=3,前提条件!$B$21,IF($A7<=6,前提条件!$B$22,IF($A7<=12,前提条件!$B$23,IF($A7<=24,前提条件!$B$24,前提条件!$B$25)))) | D7: =$D6+$C7 | E7: =ROUND($C7*前提条件!$B$27,0) | F7: =IF($X7=0,0,ROUND($X7/前提条件!$B$28,0)) | G7: =$E7+$F7 | H7: =ROUND($I6*前提条件!$B$29,0) | I7: =$I6+$G7-$H7 | J7: =IF($A7<前提条件!$B$37,0,ROUND($G7*前提条件!$B$33+$I6*前提条件!$B$34,0)) | K7: =IF(OR($A7=5,$A7=11,$A7=15,$A7=22,$A7=30),ROUND($I6*前提条件!$B$35,0),0) | L7: =$J7+$K7 | M7: =IF($A7<=12,前提条件!$B$31,前提条件!$B$32)*前提条件!$B$19 | N7: =ROUND($L7*$M7*(1-前提条件!$B$36),0) | O7: =ROUND($D7*前提条件!$B$39,0) | P7: =ROUND(IF($A7<10,0,IF($A7<=12,前提条件!$B$42,IF($A7<=18,前提条件!$B$43,IF($A7<=24,前提条件!$B$44,前提条件!$B$45))))*前提条件!$B$41,0) | Q7: =IF($A7<15,0,ROUND($G7*前提条件!$B$48*前提条件!$B$47*前提条件!$B$19,0)) | R7: =IF($A7<20,0,IF($A7<=24,前提条件!$B$51,前提条件!$B$52)*前提条件!$B$50) | S7: =SUM($N7:$R7) | T7: =IF($A7<=6,前提条件!$B$54,IF($A7<=18,前提条件!$B$55,前提条件!$B$56)) | U7: =IF($A7<=12,前提条件!$B$57,前提条件!$B$58) | V7: =前提条件!$B$59 | W7: =IF($A7<=6,0,IF($A7<=12,前提条件!$B$60,IF($A7<=24,前提条件!$B$61,前提条件!$B$62))) | X7: =IF($A7<5,0,IF($A7<=12,前提条件!$B$63,IF($A7<=24,前提条件!$B$64,前提条件!$B$65))) | Y7: =IF($A7<=12,0,IF($A7<=18,前提条件!$B$66,IF($A7<=24,前提条件!$B$67,前提条件!$B$68))) | Z7: =ROUND(($N7+$Q7)*前提条件!$B$69,0) | AA7: =IF($A7=1,前提条件!$B$70,0) | AB7: =SUM($T7:$AA7) | AC7: =$S7-$AB7 | AD7: =$AD6+$AC7
A8: 4 | B8: =INT(($A8-1)/12)+1 | C8: =IF($A8<=3,前提条件!$B$21,IF($A8<=6,前提条件!$B$22,IF($A8<=12,前提条件!$B$23,IF($A8<=24,前提条件!$B$24,前提条件!$B$25)))) | D8: =$D7+$C8 | E8: =ROUND($C8*前提条件!$B$27,0) | F8: =IF($X8=0,0,ROUND($X8/前提条件!$B$28,0)) | G8: =$E8+$F8 | H8: =ROUND($I7*前提条件!$B$29,0) | I8: =$I7+$G8-$H8 | J8: =IF($A8<前提条件!$B$37,0,ROUND($G8*前提条件!$B$33+$I7*前提条件!$B$34,0)) | K8: =IF(OR($A8=5,$A8=11,$A8=15,$A8=22,$A8=30),ROUND($I7*前提条件!$B$35,0),0) | L8: =$J8+$K8 | M8: =IF($A8<=12,前提条件!$B$31,前提条件!$B$32)*前提条件!$B$19 | N8: =ROUND($L8*$M8*(1-前提条件!$B$36),0) | O8: =ROUND($D8*前提条件!$B$39,0) | P8: =ROUND(IF($A8<10,0,IF($A8<=12,前提条件!$B$42,IF($A8<=18,前提条件!$B$43,IF($A8<=24,前提条件!$B$44,前提条件!$B$45))))*前提条件!$B$41,0) | Q8: =IF($A8<15,0,ROUND($G8*前提条件!$B$48*前提条件!$B$47*前提条件!$B$19,0)) | R8: =IF($A8<20,0,IF($A8<=24,前提条件!$B$51,前提条件!$B$52)*前提条件!$B$50) | S8: =SUM($N8:$R8) | T8: =IF($A8<=6,前提条件!$B$54,IF($A8<=18,前提条件!$B$55,前提条件!$B$56)) | U8: =IF($A8<=12,前提条件!$B$57,前提条件!$B$58) | V8: =前提条件!$B$59 | W8: =IF($A8<=6,0,IF($A8<=12,前提条件!$B$60,IF($A8<=24,前提条件!$B$61,前提条件!$B$62))) | X8: =IF($A8<5,0,IF($A8<=12,前提条件!$B$63,IF($A8<=24,前提条件!$B$64,前提条件!$B$65))) | Y8: =IF($A8<=12,0,IF($A8<=18,前提条件!$B$66,IF($A8<=24,前提条件!$B$67,前提条件!$B$68))) | Z8: =ROUND(($N8+$Q8)*前提条件!$B$69,0) | AA8: =IF($A8=1,前提条件!$B$70,0) | AB8: =SUM($T8:$AA8) | AC8: =$S8-$AB8 | AD8: =$AD7+$AC8
A9: 5 | B9: =INT(($A9-1)/12)+1 | C9: =IF($A9<=3,前提条件!$B$21,IF($A9<=6,前提条件!$B$22,IF($A9<=12,前提条件!$B$23,IF($A9<=24,前提条件!$B$24,前提条件!$B$25)))) | D9: =$D8+$C9 | E9: =ROUND($C9*前提条件!$B$27,0) | F9: =IF($X9=0,0,ROUND($X9/前提条件!$B$28,0)) | G9: =$E9+$F9 | H9: =ROUND($I8*前提条件!$B$29,0) | I9: =$I8+$G9-$H9 | J9: =IF($A9<前提条件!$B$37,0,ROUND($G9*前提条件!$B$33+$I8*前提条件!$B$34,0)) | K9: =IF(OR($A9=5,$A9=11,$A9=15,$A9=22,$A9=30),ROUND($I8*前提条件!$B$35,0),0) | L9: =$J9+$K9 | M9: =IF($A9<=12,前提条件!$B$31,前提条件!$B$32)*前提条件!$B$19 | N9: =ROUND($L9*$M9*(1-前提条件!$B$36),0) | O9: =ROUND($D9*前提条件!$B$39,0) | P9: =ROUND(IF($A9<10,0,IF($A9<=12,前提条件!$B$42,IF($A9<=18,前提条件!$B$43,IF($A9<=24,前提条件!$B$44,前提条件!$B$45))))*前提条件!$B$41,0) | Q9: =IF($A9<15,0,ROUND($G9*前提条件!$B$48*前提条件!$B$47*前提条件!$B$19,0)) | R9: =IF($A9<20,0,IF($A9<=24,前提条件!$B$51,前提条件!$B$52)*前提条件!$B$50) | S9: =SUM($N9:$R9) | T9: =IF($A9<=6,前提条件!$B$54,IF($A9<=18,前提条件!$B$55,前提条件!$B$56)) | U9: =IF($A9<=12,前提条件!$B$57,前提条件!$B$58) | V9: =前提条件!$B$59 | W9: =IF($A9<=6,0,IF($A9<=12,前提条件!$B$60,IF($A9<=24,前提条件!$B$61,前提条件!$B$62))) | X9: =IF($A9<5,0,IF($A9<=12,前提条件!$B$63,IF($A9<=24,前提条件!$B$64,前提条件!$B$65))) | Y9: =IF($A9<=12,0,IF($A9<=18,前提条件!$B$66,IF($A9<=24,前提条件!$B$67,前提条件!$B$68))) | Z9: =ROUND(($N9+$Q9)*前提条件!$B$69,0) | AA9: =IF($A9=1,前提条件!$B$70,0) | AB9: =SUM($T9:$AA9) | AC9: =$S9-$AB9 | AD9: =$AD8+$AC9
A10: 6 | B10: =INT(($A10-1)/12)+1 | C10: =IF($A10<=3,前提条件!$B$21,IF($A10<=6,前提条件!$B$22,IF($A10<=12,前提条件!$B$23,IF($A10<=24,前提条件!$B$24,前提条件!$B$25)))) | D10: =$D9+$C10 | E10: =ROUND($C10*前提条件!$B$27,0) | F10: =IF($X10=0,0,ROUND($X10/前提条件!$B$28,0)) | G10: =$E10+$F10 | H10: =ROUND($I9*前提条件!$B$29,0) | I10: =$I9+$G10-$H10 | J10: =IF($A10<前提条件!$B$37,0,ROUND($G10*前提条件!$B$33+$I9*前提条件!$B$34,0)) | K10: =IF(OR($A10=5,$A10=11,$A10=15,$A10=22,$A10=30),ROUND($I9*前提条件!$B$35,0),0) | L10: =$J10+$K10 | M10: =IF($A10<=12,前提条件!$B$31,前提条件!$B$32)*前提条件!$B$19 | N10: =ROUND($L10*$M10*(1-前提条件!$B$36),0) | O10: =ROUND($D10*前提条件!$B$39,0) | P10: =ROUND(IF($A10<10,0,IF($A10<=12,前提条件!$B$42,IF($A10<=18,前提条件!$B$43,IF($A10<=24,前提条件!$B$44,前提条件!$B$45))))*前提条件!$B$41,0) | Q10: =IF($A10<15,0,ROUND($G10*前提条件!$B$48*前提条件!$B$47*前提条件!$B$19,0)) | R10: =IF($A10<20,0,IF($A10<=24,前提条件!$B$51,前提条件!$B$52)*前提条件!$B$50) | S10: =SUM($N10:$R10) | T10: =IF($A10<=6,前提条件!$B$54,IF($A10<=18,前提条件!$B$55,前提条件!$B$56)) | U10: =IF($A10<=12,前提条件!$B$57,前提条件!$B$58) | V10: =前提条件!$B$59 | W10: =IF($A10<=6,0,IF($A10<=12,前提条件!$B$60,IF($A10<=24,前提条件!$B$61,前提条件!$B$62))) | X10: =IF($A10<5,0,IF($A10<=12,前提条件!$B$63,IF($A10<=24,前提条件!$B$64,前提条件!$B$65))) | Y10: =IF($A10<=12,0,IF($A10<=18,前提条件!$B$66,IF($A10<=24,前提条件!$B$67,前提条件!$B$68))) | Z10: =ROUND(($N10+$Q10)*前提条件!$B$69,0) | AA10: =IF($A10=1,前提条件!$B$70,0) | AB10: =SUM($T10:$AA10) | AC10: =$S10-$AB10 | AD10: =$AD9+$AC10
A11: 7 | B11: =INT(($A11-1)/12)+1 | C11: =IF($A11<=3,前提条件!$B$21,IF($A11<=6,前提条件!$B$22,IF($A11<=12,前提条件!$B$23,IF($A11<=24,前提条件!$B$24,前提条件!$B$25)))) | D11: =$D10+$C11 | E11: =ROUND($C11*前提条件!$B$27,0) | F11: =IF($X11=0,0,ROUND($X11/前提条件!$B$28,0)) | G11: =$E11+$F11 | H11: =ROUND($I10*前提条件!$B$29,0) | I11: =$I10+$G11-$H11 | J11: =IF($A11<前提条件!$B$37,0,ROUND($G11*前提条件!$B$33+$I10*前提条件!$B$34,0)) | K11: =IF(OR($A11=5,$A11=11,$A11=15,$A11=22,$A11=30),ROUND($I10*前提条件!$B$35,0),0) | L11: =$J11+$K11 | M11: =IF($A11<=12,前提条件!$B$31,前提条件!$B$32)*前提条件!$B$19 | N11: =ROUND($L11*$M11*(1-前提条件!$B$36),0) | O11: =ROUND($D11*前提条件!$B$39,0) | P11: =ROUND(IF($A11<10,0,IF($A11<=12,前提条件!$B$42,IF($A11<=18,前提条件!$B$43,IF($A11<=24,前提条件!$B$44,前提条件!$B$45))))*前提条件!$B$41,0) | Q11: =IF($A11<15,0,ROUND($G11*前提条件!$B$48*前提条件!$B$47*前提条件!$B$19,0)) | R11: =IF($A11<20,0,IF($A11<=24,前提条件!$B$51,前提条件!$B$52)*前提条件!$B$50) | S11: =SUM($N11:$R11) | T11: =IF($A11<=6,前提条件!$B$54,IF($A11<=18,前提条件!$B$55,前提条件!$B$56)) | U11: =IF($A11<=12,前提条件!$B$57,前提条件!$B$58) | V11: =前提条件!$B$59 | W11: =IF($A11<=6,0,IF($A11<=12,前提条件!$B$60,IF($A11<=24,前提条件!$B$61,前提条件!$B$62))) | X11: =IF($A11<5,0,IF($A11<=12,前提条件!$B$63,IF($A11<=24,前提条件!$B$64,前提条件!$B$65))) | Y11: =IF($A11<=12,0,IF($A11<=18,前提条件!$B$66,IF($A11<=24,前提条件!$B$67,前提条件!$B$68))) | Z11: =ROUND(($N11+$Q11)*前提条件!$B$69,0) | AA11: =IF($A11=1,前提条件!$B$70,0) | AB11: =SUM($T11:$AA11) | AC11: =$S11-$AB11 | AD11: =$AD10+$AC11
A12: 8 | B12: =INT(($A12-1)/12)+1 | C12: =IF($A12<=3,前提条件!$B$21,IF($A12<=6,前提条件!$B$22,IF($A12<=12,前提条件!$B$23,IF($A12<=24,前提条件!$B$24,前提条件!$B$25)))) | D12: =$D11+$C12 | E12: =ROUND($C12*前提条件!$B$27,0) | F12: =IF($X12=0,0,ROUND($X12/前提条件!$B$28,0)) | G12: =$E12+$F12 | H12: =ROUND($I11*前提条件!$B$29,0) | I12: =$I11+$G12-$H12 | J12: =IF($A12<前提条件!$B$37,0,ROUND($G12*前提条件!$B$33+$I11*前提条件!$B$34,0)) | K12: =IF(OR($A12=5,$A12=11,$A12=15,$A12=22,$A12=30),ROUND($I11*前提条件!$B$35,0),0) | L12: =$J12+$K12 | M12: =IF($A12<=12,前提条件!$B$31,前提条件!$B$32)*前提条件!$B$19 | N12: =ROUND($L12*$M12*(1-前提条件!$B$36),0) | O12: =ROUND($D12*前提条件!$B$39,0) | P12: =ROUND(IF($A12<10,0,IF($A12<=12,前提条件!$B$42,IF($A12<=18,前提条件!$B$43,IF($A12<=24,前提条件!$B$44,前提条件!$B$45))))*前提条件!$B$41,0) | Q12: =IF($A12<15,0,ROUND($G12*前提条件!$B$48*前提条件!$B$47*前提条件!$B$19,0)) | R12: =IF($A12<20,0,IF($A12<=24,前提条件!$B$51,前提条件!$B$52)*前提条件!$B$50) | S12: =SUM($N12:$R12) | T12: =IF($A12<=6,前提条件!$B$54,IF($A12<=18,前提条件!$B$55,前提条件!$B$56)) | U12: =IF($A12<=12,前提条件!$B$57,前提条件!$B$58) | V12: =前提条件!$B$59 | W12: =IF($A12<=6,0,IF($A12<=12,前提条件!$B$60,IF($A12<=24,前提条件!$B$61,前提条件!$B$62))) | X12: =IF($A12<5,0,IF($A12<=12,前提条件!$B$63,IF($A12<=24,前提条件!$B$64,前提条件!$B$65))) | Y12: =IF($A12<=12,0,IF($A12<=18,前提条件!$B$66,IF($A12<=24,前提条件!$B$67,前提条件!$B$68))) | Z12: =ROUND(($N12+$Q12)*前提条件!$B$69,0) | AA12: =IF($A12=1,前提条件!$B$70,0) | AB12: =SUM($T12:$AA12) | AC12: =$S12-$AB12 | AD12: =$AD11+$AC12
A13: 9 | B13: =INT(($A13-1)/12)+1 | C13: =IF($A13<=3,前提条件!$B$21,IF($A13<=6,前提条件!$B$22,IF($A13<=12,前提条件!$B$23,IF($A13<=24,前提条件!$B$24,前提条件!$B$25)))) | D13: =$D12+$C13 | E13: =ROUND($C13*前提条件!$B$27,0) | F13: =IF($X13=0,0,ROUND($X13/前提条件!$B$28,0)) | G13: =$E13+$F13 | H13: =ROUND($I12*前提条件!$B$29,0) | I13: =$I12+$G13-$H13 | J13: =IF($A13<前提条件!$B$37,0,ROUND($G13*前提条件!$B$33+$I12*前提条件!$B$34,0)) | K13: =IF(OR($A13=5,$A13=11,$A13=15,$A13=22,$A13=30),ROUND($I12*前提条件!$B$35,0),0) | L13: =$J13+$K13 | M13: =IF($A13<=12,前提条件!$B$31,前提条件!$B$32)*前提条件!$B$19 | N13: =ROUND($L13*$M13*(1-前提条件!$B$36),0) | O13: =ROUND($D13*前提条件!$B$39,0) | P13: =ROUND(IF($A13<10,0,IF($A13<=12,前提条件!$B$42,IF($A13<=18,前提条件!$B$43,IF($A13<=24,前提条件!$B$44,前提条件!$B$45))))*前提条件!$B$41,0) | Q13: =IF($A13<15,0,ROUND($G13*前提条件!$B$48*前提条件!$B$47*前提条件!$B$19,0)) | R13: =IF($A13<20,0,IF($A13<=24,前提条件!$B$51,前提条件!$B$52)*前提条件!$B$50) | S13: =SUM($N13:$R13) | T13: =IF($A13<=6,前提条件!$B$54,IF($A13<=18,前提条件!$B$55,前提条件!$B$56)) | U13: =IF($A13<=12,前提条件!$B$57,前提条件!$B$58) | V13: =前提条件!$B$59 | W13: =IF($A13<=6,0,IF($A13<=12,前提条件!$B$60,IF($A13<=24,前提条件!$B$61,前提条件!$B$62))) | X13: =IF($A13<5,0,IF($A13<=12,前提条件!$B$63,IF($A13<=24,前提条件!$B$64,前提条件!$B$65))) | Y13: =IF($A13<=12,0,IF($A13<=18,前提条件!$B$66,IF($A13<=24,前提条件!$B$67,前提条件!$B$68))) | Z13: =ROUND(($N13+$Q13)*前提条件!$B$69,0) | AA13: =IF($A13=1,前提条件!$B$70,0) | AB13: =SUM($T13:$AA13) | AC13: =$S13-$AB13 | AD13: =$AD12+$AC13
A14: 10 | B14: =INT(($A14-1)/12)+1 | C14: =IF($A14<=3,前提条件!$B$21,IF($A14<=6,前提条件!$B$22,IF($A14<=12,前提条件!$B$23,IF($A14<=24,前提条件!$B$24,前提条件!$B$25)))) | D14: =$D13+$C14 | E14: =ROUND($C14*前提条件!$B$27,0) | F14: =IF($X14=0,0,ROUND($X14/前提条件!$B$28,0)) | G14: =$E14+$F14 | H14: =ROUND($I13*前提条件!$B$29,0) | I14: =$I13+$G14-$H14 | J14: =IF($A14<前提条件!$B$37,0,ROUND($G14*前提条件!$B$33+$I13*前提条件!$B$34,0)) | K14: =IF(OR($A14=5,$A14=11,$A14=15,$A14=22,$A14=30),ROUND($I13*前提条件!$B$35,0),0) | L14: =$J14+$K14 | M14: =IF($A14<=12,前提条件!$B$31,前提条件!$B$32)*前提条件!$B$19 | N14: =ROUND($L14*$M14*(1-前提条件!$B$36),0) | O14: =ROUND($D14*前提条件!$B$39,0) | P14: =ROUND(IF($A14<10,0,IF($A14<=12,前提条件!$B$42,IF($A14<=18,前提条件!$B$43,IF($A14<=24,前提条件!$B$44,前提条件!$B$45))))*前提条件!$B$41,0) | Q14: =IF($A14<15,0,ROUND($G14*前提条件!$B$48*前提条件!$B$47*前提条件!$B$19,0)) | R14: =IF($A14<20,0,IF($A14<=24,前提条件!$B$51,前提条件!$B$52)*前提条件!$B$50) | S14: =SUM($N14:$R14) | T14: =IF($A14<=6,前提条件!$B$54,IF($A14<=18,前提条件!$B$55,前提条件!$B$56)) | U14: =IF($A14<=12,前提条件!$B$57,前提条件!$B$58) | V14: =前提条件!$B$59 | W14: =IF($A14<=6,0,IF($A14<=12,前提条件!$B$60,IF($A14<=24,前提条件!$B$61,前提条件!$B$62))) | X14: =IF($A14<5,0,IF($A14<=12,前提条件!$B$63,IF($A14<=24,前提条件!$B$64,前提条件!$B$65))) | Y14: =IF($A14<=12,0,IF($A14<=18,前提条件!$B$66,IF($A14<=24,前提条件!$B$67,前提条件!$B$68))) | Z14: =ROUND(($N14+$Q14)*前提条件!$B$69,0) | AA14: =IF($A14=1,前提条件!$B$70,0) | AB14: =SUM($T14:$AA14) | AC14: =$S14-$AB14 | AD14: =$AD13+$AC14
A15: 11 | B15: =INT(($A15-1)/12)+1 | C15: =IF($A15<=3,前提条件!$B$21,IF($A15<=6,前提条件!$B$22,IF($A15<=12,前提条件!$B$23,IF($A15<=24,前提条件!$B$24,前提条件!$B$25)))) | D15: =$D14+$C15 | E15: =ROUND($C15*前提条件!$B$27,0) | F15: =IF($X15=0,0,ROUND($X15/前提条件!$B$28,0)) | G15: =$E15+$F15 | H15: =ROUND($I14*前提条件!$B$29,0) | I15: =$I14+$G15-$H15 | J15: =IF($A15<前提条件!$B$37,0,ROUND($G15*前提条件!$B$33+$I14*前提条件!$B$34,0)) | K15: =IF(OR($A15=5,$A15=11,$A15=15,$A15=22,$A15=30),ROUND($I14*前提条件!$B$35,0),0) | L15: =$J15+$K15 | M15: =IF($A15<=12,前提条件!$B$31,前提条件!$B$32)*前提条件!$B$19 | N15: =ROUND($L15*$M15*(1-前提条件!$B$36),0) | O15: =ROUND($D15*前提条件!$B$39,0) | P15: =ROUND(IF($A15<10,0,IF($A15<=12,前提条件!$B$42,IF($A15<=18,前提条件!$B$43,IF($A15<=24,前提条件!$B$44,前提条件!$B$45))))*前提条件!$B$41,0) | Q15: =IF($A15<15,0,ROUND($G15*前提条件!$B$48*前提条件!$B$47*前提条件!$B$19,0)) | R15: =IF($A15<20,0,IF($A15<=24,前提条件!$B$51,前提条件!$B$52)*前提条件!$B$50) | S15: =SUM($N15:$R15) | T15: =IF($A15<=6,前提条件!$B$54,IF($A15<=18,前提条件!$B$55,前提条件!$B$56)) | U15: =IF($A15<=12,前提条件!$B$57,前提条件!$B$58) | V15: =前提条件!$B$59 | W15: =IF($A15<=6,0,IF($A15<=12,前提条件!$B$60,IF($A15<=24,前提条件!$B$61,前提条件!$B$62))) | X15: =IF($A15<5,0,IF($A15<=12,前提条件!$B$63,IF($A15<=24,前提条件!$B$64,前提条件!$B$65))) | Y15: =IF($A15<=12,0,IF($A15<=18,前提条件!$B$66,IF($A15<=24,前提条件!$B$67,前提条件!$B$68))) | Z15: =ROUND(($N15+$Q15)*前提条件!$B$69,0) | AA15: =IF($A15=1,前提条件!$B$70,0) | AB15: =SUM($T15:$AA15) | AC15: =$S15-$AB15 | AD15: =$AD14+$AC15
A16: 12 | B16: =INT(($A16-1)/12)+1 | C16: =IF($A16<=3,前提条件!$B$21,IF($A16<=6,前提条件!$B$22,IF($A16<=12,前提条件!$B$23,IF($A16<=24,前提条件!$B$24,前提条件!$B$25)))) | D16: =$D15+$C16 | E16: =ROUND($C16*前提条件!$B$27,0) | F16: =IF($X16=0,0,ROUND($X16/前提条件!$B$28,0)) | G16: =$E16+$F16 | H16: =ROUND($I15*前提条件!$B$29,0) | I16: =$I15+$G16-$H16 | J16: =IF($A16<前提条件!$B$37,0,ROUND($G16*前提条件!$B$33+$I15*前提条件!$B$34,0)) | K16: =IF(OR($A16=5,$A16=11,$A16=15,$A16=22,$A16=30),ROUND($I15*前提条件!$B$35,0),0) | L16: =$J16+$K16 | M16: =IF($A16<=12,前提条件!$B$31,前提条件!$B$32)*前提条件!$B$19 | N16: =ROUND($L16*$M16*(1-前提条件!$B$36),0) | O16: =ROUND($D16*前提条件!$B$39,0) | P16: =ROUND(IF($A16<10,0,IF($A16<=12,前提条件!$B$42,IF($A16<=18,前提条件!$B$43,IF($A16<=24,前提条件!$B$44,前提条件!$B$45))))*前提条件!$B$41,0) | Q16: =IF($A16<15,0,ROUND($G16*前提条件!$B$48*前提条件!$B$47*前提条件!$B$19,0)) | R16: =IF($A16<20,0,IF($A16<=24,前提条件!$B$51,前提条件!$B$52)*前提条件!$B$50) | S16: =SUM($N16:$R16) | T16: =IF($A16<=6,前提条件!$B$54,IF($A16<=18,前提条件!$B$55,前提条件!$B$56)) | U16: =IF($A16<=12,前提条件!$B$57,前提条件!$B$58) | V16: =前提条件!$B$59 | W16: =IF($A16<=6,0,IF($A16<=12,前提条件!$B$60,IF($A16<=24,前提条件!$B$61,前提条件!$B$62))) | X16: =IF($A16<5,0,IF($A16<=12,前提条件!$B$63,IF($A16<=24,前提条件!$B$64,前提条件!$B$65))) | Y16: =IF($A16<=12,0,IF($A16<=18,前提条件!$B$66,IF($A16<=24,前提条件!$B$67,前提条件!$B$68))) | Z16: =ROUND(($N16+$Q16)*前提条件!$B$69,0) | AA16: =IF($A16=1,前提条件!$B$70,0) | AB16: =SUM($T16:$AA16) | AC16: =$S16-$AB16 | AD16: =$AD15+$AC16
A17: 13 | B17: =INT(($A17-1)/12)+1 | C17: =IF($A17<=3,前提条件!$B$21,IF($A17<=6,前提条件!$B$22,IF($A17<=12,前提条件!$B$23,IF($A17<=24,前提条件!$B$24,前提条件!$B$25)))) | D17: =$D16+$C17 | E17: =ROUND($C17*前提条件!$B$27,0) | F17: =IF($X17=0,0,ROUND($X17/前提条件!$B$28,0)) | G17: =$E17+$F17 | H17: =ROUND($I16*前提条件!$B$29,0) | I17: =$I16+$G17-$H17 | J17: =IF($A17<前提条件!$B$37,0,ROUND($G17*前提条件!$B$33+$I16*前提条件!$B$34,0)) | K17: =IF(OR($A17=5,$A17=11,$A17=15,$A17=22,$A17=30),ROUND($I16*前提条件!$B$35,0),0) | L17: =$J17+$K17 | M17: =IF($A17<=12,前提条件!$B$31,前提条件!$B$32)*前提条件!$B$19 | N17: =ROUND($L17*$M17*(1-前提条件!$B$36),0) | O17: =ROUND($D17*前提条件!$B$39,0) | P17: =ROUND(IF($A17<10,0,IF($A17<=12,前提条件!$B$42,IF($A17<=18,前提条件!$B$43,IF($A17<=24,前提条件!$B$44,前提条件!$B$45))))*前提条件!$B$41,0) | Q17: =IF($A17<15,0,ROUND($G17*前提条件!$B$48*前提条件!$B$47*前提条件!$B$19,0)) | R17: =IF($A17<20,0,IF($A17<=24,前提条件!$B$51,前提条件!$B$52)*前提条件!$B$50) | S17: =SUM($N17:$R17) | T17: =IF($A17<=6,前提条件!$B$54,IF($A17<=18,前提条件!$B$55,前提条件!$B$56)) | U17: =IF($A17<=12,前提条件!$B$57,前提条件!$B$58) | V17: =前提条件!$B$59 | W17: =IF($A17<=6,0,IF($A17<=12,前提条件!$B$60,IF($A17<=24,前提条件!$B$61,前提条件!$B$62))) | X17: =IF($A17<5,0,IF($A17<=12,前提条件!$B$63,IF($A17<=24,前提条件!$B$64,前提条件!$B$65))) | Y17: =IF($A17<=12,0,IF($A17<=18,前提条件!$B$66,IF($A17<=24,前提条件!$B$67,前提条件!$B$68))) | Z17: =ROUND(($N17+$Q17)*前提条件!$B$69,0) | AA17: =IF($A17=1,前提条件!$B$70,0) | AB17: =SUM($T17:$AA17) | AC17: =$S17-$AB17 | AD17: =$AD16+$AC17
... A40: 36 | B40: =INT(($A40-1)/12)+1 | C40: =IF($A40<=3,前提条件!$B$21,IF($A40<=6,前提条件!$B$22,IF($A40<=12,前提条件!$B$23,IF($A40<=24,前提条件!$B$24,前提条件!$B$25)))) | D40: =$D39+$C40 | E40: =ROUND($C40*前提条件!$B$27,0) | F40: =IF($X40=0,0,ROUND($X40/前提条件!$B$28,0)) | G40: =$E40+$F40 | H40: =ROUND($I39*前提条件!$B$29,0) | I40: =$I39+$G40-$H40 | J40: =IF($A40<前提条件!$B$37,0,ROUND($G40*前提条件!$B$33+$I39*前提条件!$B$34,0)) | K40: =IF(OR($A40=5,$A40=11,$A40=15,$A40=22,$A40=30),ROUND($I39*前提条件!$B$35,0),0) | L40: =$J40+$K40 | M40: =IF($A40<=12,前提条件!$B$31,前提条件!$B$32)*前提条件!$B$19 | N40: =ROUND($L40*$M40*(1-前提条件!$B$36),0) | O40: =ROUND($D40*前提条件!$B$39,0) | P40: =ROUND(IF($A40<10,0,IF($A40<=12,前提条件!$B$42,IF($A40<=18,前提条件!$B$43,IF($A40<=24,前提条件!$B$44,前提条件!$B$45))))*前提条件!$B$41,0) | Q40: =IF($A40<15,0,ROUND($G40*前提条件!$B$48*前提条件!$B$47*前提条件!$B$19,0)) | R40: =IF($A40<20,0,IF($A40<=24,前提条件!$B$51,前提条件!$B$52)*前提条件!$B$50) | S40: =SUM($N40:$R40) | T40: =IF($A40<=6,前提条件!$B$54,IF($A40<=18,前提条件!$B$55,前提条件!$B$56)) | U40: =IF($A40<=12,前提条件!$B$57,前提条件!$B$58) | V40: =前提条件!$B$59 | W40: =IF($A40<=6,0,IF($A40<=12,前提条件!$B$60,IF($A40<=24,前提条件!$B$61,前提条件!$B$62))) | X40: =IF($A40<5,0,IF($A40<=12,前提条件!$B$63,IF($A40<=24,前提条件!$B$64,前提条件!$B$65))) | Y40: =IF($A40<=12,0,IF($A40<=18,前提条件!$B$66,IF($A40<=24,前提条件!$B$67,前提条件!$B$68))) | Z40: =ROUND(($N40+$Q40)*前提条件!$B$69,0) | AA40: =IF($A40=1,前提条件!$B$70,0) | AB40: =SUM($T40:$AA40) | AC40: =$S40-$AB40 | AD40: =$AD39+$AC40

Sheet 月次_標準
A1: 月次収支計画 ― 標準シナリオ
A2: 前提条件シートのC列を参照。単位：円
A4: 月 | B4: 年次 | C4: ﾌｫﾛﾜｰ純増 | D4: ﾌｫﾛﾜｰ累計 | E4: 新規ﾘｽﾄ(自然) | F4: 新規ﾘｽﾄ(広告) | G4: 新規ﾘｽﾄ計 | H4: 解除 | I4: ﾒｰﾙﾘｽﾄ累計 | J4: 販売数(通常) | K4: 販売数(ﾛｰﾝﾁ) | L4: 販売数計 | M4: 平均単価 | N4: レシピ商品 | O4: ｱﾌｨﾘｴｲﾄ | P4: ﾀｲｱｯﾌﾟ | Q4: 訪日商品 | R4: 予約代行 | S4: 売上合計 | T4: 食材費 | U4: 英語ﾁｪｯｸ | V4: ﾂｰﾙ | W4: ﾒｰﾙ配信 | X4: 広告費 | Y4: 外注編集 | Z4: 決済手数料 | AA4: 初期投資 | AB4: ｺｽﾄ合計 | AC4: 営業利益 | AD4: 累積営業利益
A5: 1 | B5: =INT(($A5-1)/12)+1 | C5: =IF($A5<=3,前提条件!$C$21,IF($A5<=6,前提条件!$C$22,IF($A5<=12,前提条件!$C$23,IF($A5<=24,前提条件!$C$24,前提条件!$C$25)))) | D5: =$C5 | E5: =ROUND($C5*前提条件!$C$27,0) | F5: =IF($X5=0,0,ROUND($X5/前提条件!$C$28,0)) | G5: =$E5+$F5 | H5: 0 | I5: =$G5 | J5: =IF($A5<前提条件!$C$37,0,ROUND($G5*前提条件!$C$33+0*前提条件!$C$34,0)) | K5: =IF(OR($A5=5,$A5=11,$A5=15,$A5=22,$A5=30),ROUND(0*前提条件!$C$35,0),0) | L5: =$J5+$K5 | M5: =IF($A5<=12,前提条件!$C$31,前提条件!$C$32)*前提条件!$C$19 | N5: =ROUND($L5*$M5*(1-前提条件!$C$36),0) | O5: =ROUND($D5*前提条件!$C$39,0) | P5: =ROUND(IF($A5<10,0,IF($A5<=12,前提条件!$C$42,IF($A5<=18,前提条件!$C$43,IF($A5<=24,前提条件!$C$44,前提条件!$C$45))))*前提条件!$C$41,0) | Q5: =IF($A5<15,0,ROUND($G5*前提条件!$C$48*前提条件!$C$47*前提条件!$C$19,0)) | R5: =IF($A5<20,0,IF($A5<=24,前提条件!$C$51,前提条件!$C$52)*前提条件!$C$50) | S5: =SUM($N5:$R5) | T5: =IF($A5<=6,前提条件!$C$54,IF($A5<=18,前提条件!$C$55,前提条件!$C$56)) | U5: =IF($A5<=12,前提条件!$C$57,前提条件!$C$58) | V5: =前提条件!$C$59 | W5: =IF($A5<=6,0,IF($A5<=12,前提条件!$C$60,IF($A5<=24,前提条件!$C$61,前提条件!$C$62))) | X5: =IF($A5<5,0,IF($A5<=12,前提条件!$C$63,IF($A5<=24,前提条件!$C$64,前提条件!$C$65))) | Y5: =IF($A5<=12,0,IF($A5<=18,前提条件!$C$66,IF($A5<=24,前提条件!$C$67,前提条件!$C$68))) | Z5: =ROUND(($N5+$Q5)*前提条件!$C$69,0) | AA5: =IF($A5=1,前提条件!$C$70,0) | AB5: =SUM($T5:$AA5) | AC5: =$S5-$AB5 | AD5: =$AC5
A6: 2 | B6: =INT(($A6-1)/12)+1 | C6: =IF($A6<=3,前提条件!$C$21,IF($A6<=6,前提条件!$C$22,IF($A6<=12,前提条件!$C$23,IF($A6<=24,前提条件!$C$24,前提条件!$C$25)))) | D6: =$D5+$C6 | E6: =ROUND($C6*前提条件!$C$27,0) | F6: =IF($X6=0,0,ROUND($X6/前提条件!$C$28,0)) | G6: =$E6+$F6 | H6: =ROUND($I5*前提条件!$C$29,0) | I6: =$I5+$G6-$H6 | J6: =IF($A6<前提条件!$C$37,0,ROUND($G6*前提条件!$C$33+$I5*前提条件!$C$34,0)) | K6: =IF(OR($A6=5,$A6=11,$A6=15,$A6=22,$A6=30),ROUND($I5*前提条件!$C$35,0),0) | L6: =$J6+$K6 | M6: =IF($A6<=12,前提条件!$C$31,前提条件!$C$32)*前提条件!$C$19 | N6: =ROUND($L6*$M6*(1-前提条件!$C$36),0) | O6: =ROUND($D6*前提条件!$C$39,0) | P6: =ROUND(IF($A6<10,0,IF($A6<=12,前提条件!$C$42,IF($A6<=18,前提条件!$C$43,IF($A6<=24,前提条件!$C$44,前提条件!$C$45))))*前提条件!$C$41,0) | Q6: =IF($A6<15,0,ROUND($G6*前提条件!$C$48*前提条件!$C$47*前提条件!$C$19,0)) | R6: =IF($A6<20,0,IF($A6<=24,前提条件!$C$51,前提条件!$C$52)*前提条件!$C$50) | S6: =SUM($N6:$R6) | T6: =IF($A6<=6,前提条件!$C$54,IF($A6<=18,前提条件!$C$55,前提条件!$C$56)) | U6: =IF($A6<=12,前提条件!$C$57,前提条件!$C$58) | V6: =前提条件!$C$59 | W6: =IF($A6<=6,0,IF($A6<=12,前提条件!$C$60,IF($A6<=24,前提条件!$C$61,前提条件!$C$62))) | X6: =IF($A6<5,0,IF($A6<=12,前提条件!$C$63,IF($A6<=24,前提条件!$C$64,前提条件!$C$65))) | Y6: =IF($A6<=12,0,IF($A6<=18,前提条件!$C$66,IF($A6<=24,前提条件!$C$67,前提条件!$C$68))) | Z6: =ROUND(($N6+$Q6)*前提条件!$C$69,0) | AA6: =IF($A6=1,前提条件!$C$70,0) | AB6: =SUM($T6:$AA6) | AC6: =$S6-$AB6 | AD6: =$AD5+$AC6
A7: 3 | B7: =INT(($A7-1)/12)+1 | C7: =IF($A7<=3,前提条件!$C$21,IF($A7<=6,前提条件!$C$22,IF($A7<=12,前提条件!$C$23,IF($A7<=24,前提条件!$C$24,前提条件!$C$25)))) | D7: =$D6+$C7 | E7: =ROUND($C7*前提条件!$C$27,0) | F7: =IF($X7=0,0,ROUND($X7/前提条件!$C$28,0)) | G7: =$E7+$F7 | H7: =ROUND($I6*前提条件!$C$29,0) | I7: =$I6+$G7-$H7 | J7: =IF($A7<前提条件!$C$37,0,ROUND($G7*前提条件!$C$33+$I6*前提条件!$C$34,0)) | K7: =IF(OR($A7=5,$A7=11,$A7=15,$A7=22,$A7=30),ROUND($I6*前提条件!$C$35,0),0) | L7: =$J7+$K7 | M7: =IF($A7<=12,前提条件!$C$31,前提条件!$C$32)*前提条件!$C$19 | N7: =ROUND($L7*$M7*(1-前提条件!$C$36),0) | O7: =ROUND($D7*前提条件!$C$39,0) | P7: =ROUND(IF($A7<10,0,IF($A7<=12,前提条件!$C$42,IF($A7<=18,前提条件!$C$43,IF($A7<=24,前提条件!$C$44,前提条件!$C$45))))*前提条件!$C$41,0) | Q7: =IF($A7<15,0,ROUND($G7*前提条件!$C$48*前提条件!$C$47*前提条件!$C$19,0)) | R7: =IF($A7<20,0,IF($A7<=24,前提条件!$C$51,前提条件!$C$52)*前提条件!$C$50) | S7: =SUM($N7:$R7) | T7: =IF($A7<=6,前提条件!$C$54,IF($A7<=18,前提条件!$C$55,前提条件!$C$56)) | U7: =IF($A7<=12,前提条件!$C$57,前提条件!$C$58) | V7: =前提条件!$C$59 | W7: =IF($A7<=6,0,IF($A7<=12,前提条件!$C$60,IF($A7<=24,前提条件!$C$61,前提条件!$C$62))) | X7: =IF($A7<5,0,IF($A7<=12,前提条件!$C$63,IF($A7<=24,前提条件!$C$64,前提条件!$C$65))) | Y7: =IF($A7<=12,0,IF($A7<=18,前提条件!$C$66,IF($A7<=24,前提条件!$C$67,前提条件!$C$68))) | Z7: =ROUND(($N7+$Q7)*前提条件!$C$69,0) | AA7: =IF($A7=1,前提条件!$C$70,0) | AB7: =SUM($T7:$AA7) | AC7: =$S7-$AB7 | AD7: =$AD6+$AC7
A8: 4 | B8: =INT(($A8-1)/12)+1 | C8: =IF($A8<=3,前提条件!$C$21,IF($A8<=6,前提条件!$C$22,IF($A8<=12,前提条件!$C$23,IF($A8<=24,前提条件!$C$24,前提条件!$C$25)))) | D8: =$D7+$C8 | E8: =ROUND($C8*前提条件!$C$27,0) | F8: =IF($X8=0,0,ROUND($X8/前提条件!$C$28,0)) | G8: =$E8+$F8 | H8: =ROUND($I7*前提条件!$C$29,0) | I8: =$I7+$G8-$H8 | J8: =IF($A8<前提条件!$C$37,0,ROUND($G8*前提条件!$C$33+$I7*前提条件!$C$34,0)) | K8: =IF(OR($A8=5,$A8=11,$A8=15,$A8=22,$A8=30),ROUND($I7*前提条件!$C$35,0),0) | L8: =$J8+$K8 | M8: =IF($A8<=12,前提条件!$C$31,前提条件!$C$32)*前提条件!$C$19 | N8: =ROUND($L8*$M8*(1-前提条件!$C$36),0) | O8: =ROUND($D8*前提条件!$C$39,0) | P8: =ROUND(IF($A8<10,0,IF($A8<=12,前提条件!$C$42,IF($A8<=18,前提条件!$C$43,IF($A8<=24,前提条件!$C$44,前提条件!$C$45))))*前提条件!$C$41,0) | Q8: =IF($A8<15,0,ROUND($G8*前提条件!$C$48*前提条件!$C$47*前提条件!$C$19,0)) | R8: =IF($A8<20,0,IF($A8<=24,前提条件!$C$51,前提条件!$C$52)*前提条件!$C$50) | S8: =SUM($N8:$R8) | T8: =IF($A8<=6,前提条件!$C$54,IF($A8<=18,前提条件!$C$55,前提条件!$C$56)) | U8: =IF($A8<=12,前提条件!$C$57,前提条件!$C$58) | V8: =前提条件!$C$59 | W8: =IF($A8<=6,0,IF($A8<=12,前提条件!$C$60,IF($A8<=24,前提条件!$C$61,前提条件!$C$62))) | X8: =IF($A8<5,0,IF($A8<=12,前提条件!$C$63,IF($A8<=24,前提条件!$C$64,前提条件!$C$65))) | Y8: =IF($A8<=12,0,IF($A8<=18,前提条件!$C$66,IF($A8<=24,前提条件!$C$67,前提条件!$C$68))) | Z8: =ROUND(($N8+$Q8)*前提条件!$C$69,0) | AA8: =IF($A8=1,前提条件!$C$70,0) | AB8: =SUM($T8:$AA8) | AC8: =$S8-$AB8 | AD8: =$AD7+$AC8
A9: 5 | B9: =INT(($A9-1)/12)+1 | C9: =IF($A9<=3,前提条件!$C$21,IF($A9<=6,前提条件!$C$22,IF($A9<=12,前提条件!$C$23,IF($A9<=24,前提条件!$C$24,前提条件!$C$25)))) | D9: =$D8+$C9 | E9: =ROUND($C9*前提条件!$C$27,0) | F9: =IF($X9=0,0,ROUND($X9/前提条件!$C$28,0)) | G9: =$E9+$F9 | H9: =ROUND($I8*前提条件!$C$29,0) | I9: =$I8+$G9-$H9 | J9: =IF($A9<前提条件!$C$37,0,ROUND($G9*前提条件!$C$33+$I8*前提条件!$C$34,0)) | K9: =IF(OR($A9=5,$A9=11,$A9=15,$A9=22,$A9=30),ROUND($I8*前提条件!$C$35,0),0) | L9: =$J9+$K9 | M9: =IF($A9<=12,前提条件!$C$31,前提条件!$C$32)*前提条件!$C$19 | N9: =ROUND($L9*$M9*(1-前提条件!$C$36),0) | O9: =ROUND($D9*前提条件!$C$39,0) | P9: =ROUND(IF($A9<10,0,IF($A9<=12,前提条件!$C$42,IF($A9<=18,前提条件!$C$43,IF($A9<=24,前提条件!$C$44,前提条件!$C$45))))*前提条件!$C$41,0) | Q9: =IF($A9<15,0,ROUND($G9*前提条件!$C$48*前提条件!$C$47*前提条件!$C$19,0)) | R9: =IF($A9<20,0,IF($A9<=24,前提条件!$C$51,前提条件!$C$52)*前提条件!$C$50) | S9: =SUM($N9:$R9) | T9: =IF($A9<=6,前提条件!$C$54,IF($A9<=18,前提条件!$C$55,前提条件!$C$56)) | U9: =IF($A9<=12,前提条件!$C$57,前提条件!$C$58) | V9: =前提条件!$C$59 | W9: =IF($A9<=6,0,IF($A9<=12,前提条件!$C$60,IF($A9<=24,前提条件!$C$61,前提条件!$C$62))) | X9: =IF($A9<5,0,IF($A9<=12,前提条件!$C$63,IF($A9<=24,前提条件!$C$64,前提条件!$C$65))) | Y9: =IF($A9<=12,0,IF($A9<=18,前提条件!$C$66,IF($A9<=24,前提条件!$C$67,前提条件!$C$68))) | Z9: =ROUND(($N9+$Q9)*前提条件!$C$69,0) | AA9: =IF($A9=1,前提条件!$C$70,0) | AB9: =SUM($T9:$AA9) | AC9: =$S9-$AB9 | AD9: =$AD8+$AC9
A10: 6 | B10: =INT(($A10-1)/12)+1 | C10: =IF($A10<=3,前提条件!$C$21,IF($A10<=6,前提条件!$C$22,IF($A10<=12,前提条件!$C$23,IF($A10<=24,前提条件!$C$24,前提条件!$C$25)))) | D10: =$D9+$C10 | E10: =ROUND($C10*前提条件!$C$27,0) | F10: =IF($X10=0,0,ROUND($X10/前提条件!$C$28,0)) | G10: =$E10+$F10 | H10: =ROUND($I9*前提条件!$C$29,0) | I10: =$I9+$G10-$H10 | J10: =IF($A10<前提条件!$C$37,0,ROUND($G10*前提条件!$C$33+$I9*前提条件!$C$34,0)) | K10: =IF(OR($A10=5,$A10=11,$A10=15,$A10=22,$A10=30),ROUND($I9*前提条件!$C$35,0),0) | L10: =$J10+$K10 | M10: =IF($A10<=12,前提条件!$C$31,前提条件!$C$32)*前提条件!$C$19 | N10: =ROUND($L10*$M10*(1-前提条件!$C$36),0) | O10: =ROUND($D10*前提条件!$C$39,0) | P10: =ROUND(IF($A10<10,0,IF($A10<=12,前提条件!$C$42,IF($A10<=18,前提条件!$C$43,IF($A10<=24,前提条件!$C$44,前提条件!$C$45))))*前提条件!$C$41,0) | Q10: =IF($A10<15,0,ROUND($G10*前提条件!$C$48*前提条件!$C$47*前提条件!$C$19,0)) | R10: =IF($A10<20,0,IF($A10<=24,前提条件!$C$51,前提条件!$C$52)*前提条件!$C$50) | S10: =SUM($N10:$R10) | T10: =IF($A10<=6,前提条件!$C$54,IF($A10<=18,前提条件!$C$55,前提条件!$C$56)) | U10: =IF($A10<=12,前提条件!$C$57,前提条件!$C$58) | V10: =前提条件!$C$59 | W10: =IF($A10<=6,0,IF($A10<=12,前提条件!$C$60,IF($A10<=24,前提条件!$C$61,前提条件!$C$62))) | X10: =IF($A10<5,0,IF($A10<=12,前提条件!$C$63,IF($A10<=24,前提条件!$C$64,前提条件!$C$65))) | Y10: =IF($A10<=12,0,IF($A10<=18,前提条件!$C$66,IF($A10<=24,前提条件!$C$67,前提条件!$C$68))) | Z10: =ROUND(($N10+$Q10)*前提条件!$C$69,0) | AA10: =IF($A10=1,前提条件!$C$70,0) | AB10: =SUM($T10:$AA10) | AC10: =$S10-$AB10 | AD10: =$AD9+$AC10
A11: 7 | B11: =INT(($A11-1)/12)+1 | C11: =IF($A11<=3,前提条件!$C$21,IF($A11<=6,前提条件!$C$22,IF($A11<=12,前提条件!$C$23,IF($A11<=24,前提条件!$C$24,前提条件!$C$25)))) | D11: =$D10+$C11 | E11: =ROUND($C11*前提条件!$C$27,0) | F11: =IF($X11=0,0,ROUND($X11/前提条件!$C$28,0)) | G11: =$E11+$F11 | H11: =ROUND($I10*前提条件!$C$29,0) | I11: =$I10+$G11-$H11 | J11: =IF($A11<前提条件!$C$37,0,ROUND($G11*前提条件!$C$33+$I10*前提条件!$C$34,0)) | K11: =IF(OR($A11=5,$A11=11,$A11=15,$A11=22,$A11=30),ROUND($I10*前提条件!$C$35,0),0) | L11: =$J11+$K11 | M11: =IF($A11<=12,前提条件!$C$31,前提条件!$C$32)*前提条件!$C$19 | N11: =ROUND($L11*$M11*(1-前提条件!$C$36),0) | O11: =ROUND($D11*前提条件!$C$39,0) | P11: =ROUND(IF($A11<10,0,IF($A11<=12,前提条件!$C$42,IF($A11<=18,前提条件!$C$43,IF($A11<=24,前提条件!$C$44,前提条件!$C$45))))*前提条件!$C$41,0) | Q11: =IF($A11<15,0,ROUND($G11*前提条件!$C$48*前提条件!$C$47*前提条件!$C$19,0)) | R11: =IF($A11<20,0,IF($A11<=24,前提条件!$C$51,前提条件!$C$52)*前提条件!$C$50) | S11: =SUM($N11:$R11) | T11: =IF($A11<=6,前提条件!$C$54,IF($A11<=18,前提条件!$C$55,前提条件!$C$56)) | U11: =IF($A11<=12,前提条件!$C$57,前提条件!$C$58) | V11: =前提条件!$C$59 | W11: =IF($A11<=6,0,IF($A11<=12,前提条件!$C$60,IF($A11<=24,前提条件!$C$61,前提条件!$C$62))) | X11: =IF($A11<5,0,IF($A11<=12,前提条件!$C$63,IF($A11<=24,前提条件!$C$64,前提条件!$C$65))) | Y11: =IF($A11<=12,0,IF($A11<=18,前提条件!$C$66,IF($A11<=24,前提条件!$C$67,前提条件!$C$68))) | Z11: =ROUND(($N11+$Q11)*前提条件!$C$69,0) | AA11: =IF($A11=1,前提条件!$C$70,0) | AB11: =SUM($T11:$AA11) | AC11: =$S11-$AB11 | AD11: =$AD10+$AC11
A12: 8 | B12: =INT(($A12-1)/12)+1 | C12: =IF($A12<=3,前提条件!$C$21,IF($A12<=6,前提条件!$C$22,IF($A12<=12,前提条件!$C$23,IF($A12<=24,前提条件!$C$24,前提条件!$C$25)))) | D12: =$D11+$C12 | E12: =ROUND($C12*前提条件!$C$27,0) | F12: =IF($X12=0,0,ROUND($X12/前提条件!$C$28,0)) | G12: =$E12+$F12 | H12: =ROUND($I11*前提条件!$C$29,0) | I12: =$I11+$G12-$H12 | J12: =IF($A12<前提条件!$C$37,0,ROUND($G12*前提条件!$C$33+$I11*前提条件!$C$34,0)) | K12: =IF(OR($A12=5,$A12=11,$A12=15,$A12=22,$A12=30),ROUND($I11*前提条件!$C$35,0),0) | L12: =$J12+$K12 | M12: =IF($A12<=12,前提条件!$C$31,前提条件!$C$32)*前提条件!$C$19 | N12: =ROUND($L12*$M12*(1-前提条件!$C$36),0) | O12: =ROUND($D12*前提条件!$C$39,0) | P12: =ROUND(IF($A12<10,0,IF($A12<=12,前提条件!$C$42,IF($A12<=18,前提条件!$C$43,IF($A12<=24,前提条件!$C$44,前提条件!$C$45))))*前提条件!$C$41,0) | Q12: =IF($A12<15,0,ROUND($G12*前提条件!$C$48*前提条件!$C$47*前提条件!$C$19,0)) | R12: =IF($A12<20,0,IF($A12<=24,前提条件!$C$51,前提条件!$C$52)*前提条件!$C$50) | S12: =SUM($N12:$R12) | T12: =IF($A12<=6,前提条件!$C$54,IF($A12<=18,前提条件!$C$55,前提条件!$C$56)) | U12: =IF($A12<=12,前提条件!$C$57,前提条件!$C$58) | V12: =前提条件!$C$59 | W12: =IF($A12<=6,0,IF($A12<=12,前提条件!$C$60,IF($A12<=24,前提条件!$C$61,前提条件!$C$62))) | X12: =IF($A12<5,0,IF($A12<=12,前提条件!$C$63,IF($A12<=24,前提条件!$C$64,前提条件!$C$65))) | Y12: =IF($A12<=12,0,IF($A12<=18,前提条件!$C$66,IF($A12<=24,前提条件!$C$67,前提条件!$C$68))) | Z12: =ROUND(($N12+$Q12)*前提条件!$C$69,0) | AA12: =IF($A12=1,前提条件!$C$70,0) | AB12: =SUM($T12:$AA12) | AC12: =$S12-$AB12 | AD12: =$AD11+$AC12
A13: 9 | B13: =INT(($A13-1)/12)+1 | C13: =IF($A13<=3,前提条件!$C$21,IF($A13<=6,前提条件!$C$22,IF($A13<=12,前提条件!$C$23,IF($A13<=24,前提条件!$C$24,前提条件!$C$25)))) | D13: =$D12+$C13 | E13: =ROUND($C13*前提条件!$C$27,0) | F13: =IF($X13=0,0,ROUND($X13/前提条件!$C$28,0)) | G13: =$E13+$F13 | H13: =ROUND($I12*前提条件!$C$29,0) | I13: =$I12+$G13-$H13 | J13: =IF($A13<前提条件!$C$37,0,ROUND($G13*前提条件!$C$33+$I12*前提条件!$C$34,0)) | K13: =IF(OR($A13=5,$A13=11,$A13=15,$A13=22,$A13=30),ROUND($I12*前提条件!$C$35,0),0) | L13: =$J13+$K13 | M13: =IF($A13<=12,前提条件!$C$31,前提条件!$C$32)*前提条件!$C$19 | N13: =ROUND($L13*$M13*(1-前提条件!$C$36),0) | O13: =ROUND($D13*前提条件!$C$39,0) | P13: =ROUND(IF($A13<10,0,IF($A13<=12,前提条件!$C$42,IF($A13<=18,前提条件!$C$43,IF($A13<=24,前提条件!$C$44,前提条件!$C$45))))*前提条件!$C$41,0) | Q13: =IF($A13<15,0,ROUND($G13*前提条件!$C$48*前提条件!$C$47*前提条件!$C$19,0)) | R13: =IF($A13<20,0,IF($A13<=24,前提条件!$C$51,前提条件!$C$52)*前提条件!$C$50) | S13: =SUM($N13:$R13) | T13: =IF($A13<=6,前提条件!$C$54,IF($A13<=18,前提条件!$C$55,前提条件!$C$56)) | U13: =IF($A13<=12,前提条件!$C$57,前提条件!$C$58) | V13: =前提条件!$C$59 | W13: =IF($A13<=6,0,IF($A13<=12,前提条件!$C$60,IF($A13<=24,前提条件!$C$61,前提条件!$C$62))) | X13: =IF($A13<5,0,IF($A13<=12,前提条件!$C$63,IF($A13<=24,前提条件!$C$64,前提条件!$C$65))) | Y13: =IF($A13<=12,0,IF($A13<=18,前提条件!$C$66,IF($A13<=24,前提条件!$C$67,前提条件!$C$68))) | Z13: =ROUND(($N13+$Q13)*前提条件!$C$69,0) | AA13: =IF($A13=1,前提条件!$C$70,0) | AB13: =SUM($T13:$AA13) | AC13: =$S13-$AB13 | AD13: =$AD12+$AC13
A14: 10 | B14: =INT(($A14-1)/12)+1 | C14: =IF($A14<=3,前提条件!$C$21,IF($A14<=6,前提条件!$C$22,IF($A14<=12,前提条件!$C$23,IF($A14<=24,前提条件!$C$24,前提条件!$C$25)))) | D14: =$D13+$C14 | E14: =ROUND($C14*前提条件!$C$27,0) | F14: =IF($X14=0,0,ROUND($X14/前提条件!$C$28,0)) | G14: =$E14+$F14 | H14: =ROUND($I13*前提条件!$C$29,0) | I14: =$I13+$G14-$H14 | J14: =IF($A14<前提条件!$C$37,0,ROUND($G14*前提条件!$C$33+$I13*前提条件!$C$34,0)) | K14: =IF(OR($A14=5,$A14=11,$A14=15,$A14=22,$A14=30),ROUND($I13*前提条件!$C$35,0),0) | L14: =$J14+$K14 | M14: =IF($A14<=12,前提条件!$C$31,前提条件!$C$32)*前提条件!$C$19 | N14: =ROUND($L14*$M14*(1-前提条件!$C$36),0) | O14: =ROUND($D14*前提条件!$C$39,0) | P14: =ROUND(IF($A14<10,0,IF($A14<=12,前提条件!$C$42,IF($A14<=18,前提条件!$C$43,IF($A14<=24,前提条件!$C$44,前提条件!$C$45))))*前提条件!$C$41,0) | Q14: =IF($A14<15,0,ROUND($G14*前提条件!$C$48*前提条件!$C$47*前提条件!$C$19,0)) | R14: =IF($A14<20,0,IF($A14<=24,前提条件!$C$51,前提条件!$C$52)*前提条件!$C$50) | S14: =SUM($N14:$R14) | T14: =IF($A14<=6,前提条件!$C$54,IF($A14<=18,前提条件!$C$55,前提条件!$C$56)) | U14: =IF($A14<=12,前提条件!$C$57,前提条件!$C$58) | V14: =前提条件!$C$59 | W14: =IF($A14<=6,0,IF($A14<=12,前提条件!$C$60,IF($A14<=24,前提条件!$C$61,前提条件!$C$62))) | X14: =IF($A14<5,0,IF($A14<=12,前提条件!$C$63,IF($A14<=24,前提条件!$C$64,前提条件!$C$65))) | Y14: =IF($A14<=12,0,IF($A14<=18,前提条件!$C$66,IF($A14<=24,前提条件!$C$67,前提条件!$C$68))) | Z14: =ROUND(($N14+$Q14)*前提条件!$C$69,0) | AA14: =IF($A14=1,前提条件!$C$70,0) | AB14: =SUM($T14:$AA14) | AC14: =$S14-$AB14 | AD14: =$AD13+$AC14
A15: 11 | B15: =INT(($A15-1)/12)+1 | C15: =IF($A15<=3,前提条件!$C$21,IF($A15<=6,前提条件!$C$22,IF($A15<=12,前提条件!$C$23,IF($A15<=24,前提条件!$C$24,前提条件!$C$25)))) | D15: =$D14+$C15 | E15: =ROUND($C15*前提条件!$C$27,0) | F15: =IF($X15=0,0,ROUND($X15/前提条件!$C$28,0)) | G15: =$E15+$F15 | H15: =ROUND($I14*前提条件!$C$29,0) | I15: =$I14+$G15-$H15 | J15: =IF($A15<前提条件!$C$37,0,ROUND($G15*前提条件!$C$33+$I14*前提条件!$C$34,0)) | K15: =IF(OR($A15=5,$A15=11,$A15=15,$A15=22,$A15=30),ROUND($I14*前提条件!$C$35,0),0) | L15: =$J15+$K15 | M15: =IF($A15<=12,前提条件!$C$31,前提条件!$C$32)*前提条件!$C$19 | N15: =ROUND($L15*$M15*(1-前提条件!$C$36),0) | O15: =ROUND($D15*前提条件!$C$39,0) | P15: =ROUND(IF($A15<10,0,IF($A15<=12,前提条件!$C$42,IF($A15<=18,前提条件!$C$43,IF($A15<=24,前提条件!$C$44,前提条件!$C$45))))*前提条件!$C$41,0) | Q15: =IF($A15<15,0,ROUND($G15*前提条件!$C$48*前提条件!$C$47*前提条件!$C$19,0)) | R15: =IF($A15<20,0,IF($A15<=24,前提条件!$C$51,前提条件!$C$52)*前提条件!$C$50) | S15: =SUM($N15:$R15) | T15: =IF($A15<=6,前提条件!$C$54,IF($A15<=18,前提条件!$C$55,前提条件!$C$56)) | U15: =IF($A15<=12,前提条件!$C$57,前提条件!$C$58) | V15: =前提条件!$C$59 | W15: =IF($A15<=6,0,IF($A15<=12,前提条件!$C$60,IF($A15<=24,前提条件!$C$61,前提条件!$C$62))) | X15: =IF($A15<5,0,IF($A15<=12,前提条件!$C$63,IF($A15<=24,前提条件!$C$64,前提条件!$C$65))) | Y15: =IF($A15<=12,0,IF($A15<=18,前提条件!$C$66,IF($A15<=24,前提条件!$C$67,前提条件!$C$68))) | Z15: =ROUND(($N15+$Q15)*前提条件!$C$69,0) | AA15: =IF($A15=1,前提条件!$C$70,0) | AB15: =SUM($T15:$AA15) | AC15: =$S15-$AB15 | AD15: =$AD14+$AC15
A16: 12 | B16: =INT(($A16-1)/12)+1 | C16: =IF($A16<=3,前提条件!$C$21,IF($A16<=6,前提条件!$C$22,IF($A16<=12,前提条件!$C$23,IF($A16<=24,前提条件!$C$24,前提条件!$C$25)))) | D16: =$D15+$C16 | E16: =ROUND($C16*前提条件!$C$27,0) | F16: =IF($X16=0,0,ROUND($X16/前提条件!$C$28,0)) | G16: =$E16+$F16 | H16: =ROUND($I15*前提条件!$C$29,0) | I16: =$I15+$G16-$H16 | J16: =IF($A16<前提条件!$C$37,0,ROUND($G16*前提条件!$C$33+$I15*前提条件!$C$34,0)) | K16: =IF(OR($A16=5,$A16=11,$A16=15,$A16=22,$A16=30),ROUND($I15*前提条件!$C$35,0),0) | L16: =$J16+$K16 | M16: =IF($A16<=12,前提条件!$C$31,前提条件!$C$32)*前提条件!$C$19 | N16: =ROUND($L16*$M16*(1-前提条件!$C$36),0) | O16: =ROUND($D16*前提条件!$C$39,0) | P16: =ROUND(IF($A16<10,0,IF($A16<=12,前提条件!$C$42,IF($A16<=18,前提条件!$C$43,IF($A16<=24,前提条件!$C$44,前提条件!$C$45))))*前提条件!$C$41,0) | Q16: =IF($A16<15,0,ROUND($G16*前提条件!$C$48*前提条件!$C$47*前提条件!$C$19,0)) | R16: =IF($A16<20,0,IF($A16<=24,前提条件!$C$51,前提条件!$C$52)*前提条件!$C$50) | S16: =SUM($N16:$R16) | T16: =IF($A16<=6,前提条件!$C$54,IF($A16<=18,前提条件!$C$55,前提条件!$C$56)) | U16: =IF($A16<=12,前提条件!$C$57,前提条件!$C$58) | V16: =前提条件!$C$59 | W16: =IF($A16<=6,0,IF($A16<=12,前提条件!$C$60,IF($A16<=24,前提条件!$C$61,前提条件!$C$62))) | X16: =IF($A16<5,0,IF($A16<=12,前提条件!$C$63,IF($A16<=24,前提条件!$C$64,前提条件!$C$65))) | Y16: =IF($A16<=12,0,IF($A16<=18,前提条件!$C$66,IF($A16<=24,前提条件!$C$67,前提条件!$C$68))) | Z16: =ROUND(($N16+$Q16)*前提条件!$C$69,0) | AA16: =IF($A16=1,前提条件!$C$70,0) | AB16: =SUM($T16:$AA16) | AC16: =$S16-$AB16 | AD16: =$AD15+$AC16
A17: 13 | B17: =INT(($A17-1)/12)+1 | C17: =IF($A17<=3,前提条件!$C$21,IF($A17<=6,前提条件!$C$22,IF($A17<=12,前提条件!$C$23,IF($A17<=24,前提条件!$C$24,前提条件!$C$25)))) | D17: =$D16+$C17 | E17: =ROUND($C17*前提条件!$C$27,0) | F17: =IF($X17=0,0,ROUND($X17/前提条件!$C$28,0)) | G17: =$E17+$F17 | H17: =ROUND($I16*前提条件!$C$29,0) | I17: =$I16+$G17-$H17 | J17: =IF($A17<前提条件!$C$37,0,ROUND($G17*前提条件!$C$33+$I16*前提条件!$C$34,0)) | K17: =IF(OR($A17=5,$A17=11,$A17=15,$A17=22,$A17=30),ROUND($I16*前提条件!$C$35,0),0) | L17: =$J17+$K17 | M17: =IF($A17<=12,前提条件!$C$31,前提条件!$C$32)*前提条件!$C$19 | N17: =ROUND($L17*$M17*(1-前提条件!$C$36),0) | O17: =ROUND($D17*前提条件!$C$39,0) | P17: =ROUND(IF($A17<10,0,IF($A17<=12,前提条件!$C$42,IF($A17<=18,前提条件!$C$43,IF($A17<=24,前提条件!$C$44,前提条件!$C$45))))*前提条件!$C$41,0) | Q17: =IF($A17<15,0,ROUND($G17*前提条件!$C$48*前提条件!$C$47*前提条件!$C$19,0)) | R17: =IF($A17<20,0,IF($A17<=24,前提条件!$C$51,前提条件!$C$52)*前提条件!$C$50) | S17: =SUM($N17:$R17) | T17: =IF($A17<=6,前提条件!$C$54,IF($A17<=18,前提条件!$C$55,前提条件!$C$56)) | U17: =IF($A17<=12,前提条件!$C$57,前提条件!$C$58) | V17: =前提条件!$C$59 | W17: =IF($A17<=6,0,IF($A17<=12,前提条件!$C$60,IF($A17<=24,前提条件!$C$61,前提条件!$C$62))) | X17: =IF($A17<5,0,IF($A17<=12,前提条件!$C$63,IF($A17<=24,前提条件!$C$64,前提条件!$C$65))) | Y17: =IF($A17<=12,0,IF($A17<=18,前提条件!$C$66,IF($A17<=24,前提条件!$C$67,前提条件!$C$68))) | Z17: =ROUND(($N17+$Q17)*前提条件!$C$69,0) | AA17: =IF($A17=1,前提条件!$C$70,0) | AB17: =SUM($T17:$AA17) | AC17: =$S17-$AB17 | AD17: =$AD16+$AC17
... A40: 36 | B40: =INT(($A40-1)/12)+1 | C40: =IF($A40<=3,前提条件!$C$21,IF($A40<=6,前提条件!$C$22,IF($A40<=12,前提条件!$C$23,IF($A40<=24,前提条件!$C$24,前提条件!$C$25)))) | D40: =$D39+$C40 | E40: =ROUND($C40*前提条件!$C$27,0) | F40: =IF($X40=0,0,ROUND($X40/前提条件!$C$28,0)) | G40: =$E40+$F40 | H40: =ROUND($I39*前提条件!$C$29,0) | I40: =$I39+$G40-$H40 | J40: =IF($A40<前提条件!$C$37,0,ROUND($G40*前提条件!$C$33+$I39*前提条件!$C$34,0)) | K40: =IF(OR($A40=5,$A40=11,$A40=15,$A40=22,$A40=30),ROUND($I39*前提条件!$C$35,0),0) | L40: =$J40+$K40 | M40: =IF($A40<=12,前提条件!$C$31,前提条件!$C$32)*前提条件!$C$19 | N40: =ROUND($L40*$M40*(1-前提条件!$C$36),0) | O40: =ROUND($D40*前提条件!$C$39,0) | P40: =ROUND(IF($A40<10,0,IF($A40<=12,前提条件!$C$42,IF($A40<=18,前提条件!$C$43,IF($A40<=24,前提条件!$C$44,前提条件!$C$45))))*前提条件!$C$41,0) | Q40: =IF($A40<15,0,ROUND($G40*前提条件!$C$48*前提条件!$C$47*前提条件!$C$19,0)) | R40: =IF($A40<20,0,IF($A40<=24,前提条件!$C$51,前提条件!$C$52)*前提条件!$C$50) | S40: =SUM($N40:$R40) | T40: =IF($A40<=6,前提条件!$C$54,IF($A40<=18,前提条件!$C$55,前提条件!$C$56)) | U40: =IF($A40<=12,前提条件!$C$57,前提条件!$C$58) | V40: =前提条件!$C$59 | W40: =IF($A40<=6,0,IF($A40<=12,前提条件!$C$60,IF($A40<=24,前提条件!$C$61,前提条件!$C$62))) | X40: =IF($A40<5,0,IF($A40<=12,前提条件!$C$63,IF($A40<=24,前提条件!$C$64,前提条件!$C$65))) | Y40: =IF($A40<=12,0,IF($A40<=18,前提条件!$C$66,IF($A40<=24,前提条件!$C$67,前提条件!$C$68))) | Z40: =ROUND(($N40+$Q40)*前提条件!$C$69,0) | AA40: =IF($A40=1,前提条件!$C$70,0) | AB40: =SUM($T40:$AA40) | AC40: =$S40-$AB40 | AD40: =$AD39+$AC40

Sheet 月次_強気
A1: 月次収支計画 ― 強気シナリオ
A2: 前提条件シートのD列を参照。単位：円
A4: 月 | B4: 年次 | C4: ﾌｫﾛﾜｰ純増 | D4: ﾌｫﾛﾜｰ累計 | E4: 新規ﾘｽﾄ(自然) | F4: 新規ﾘｽﾄ(広告) | G4: 新規ﾘｽﾄ計 | H4: 解除 | I4: ﾒｰﾙﾘｽﾄ累計 | J4: 販売数(通常) | K4: 販売数(ﾛｰﾝﾁ) | L4: 販売数計 | M4: 平均単価 | N4: レシピ商品 | O4: ｱﾌｨﾘｴｲﾄ | P4: ﾀｲｱｯﾌﾟ | Q4: 訪日商品 | R4: 予約代行 | S4: 売上合計 | T4: 食材費 | U4: 英語ﾁｪｯｸ | V4: ﾂｰﾙ | W4: ﾒｰﾙ配信 | X4: 広告費 | Y4: 外注編集 | Z4: 決済手数料 | AA4: 初期投資 | AB4: ｺｽﾄ合計 | AC4: 営業利益 | AD4: 累積営業利益
A5: 1 | B5: =INT(($A5-1)/12)+1 | C5: =IF($A5<=3,前提条件!$D$21,IF($A5<=6,前提条件!$D$22,IF($A5<=12,前提条件!$D$23,IF($A5<=24,前提条件!$D$24,前提条件!$D$25)))) | D5: =$C5 | E5: =ROUND($C5*前提条件!$D$27,0) | F5: =IF($X5=0,0,ROUND($X5/前提条件!$D$28,0)) | G5: =$E5+$F5 | H5: 0 | I5: =$G5 | J5: =IF($A5<前提条件!$D$37,0,ROUND($G5*前提条件!$D$33+0*前提条件!$D$34,0)) | K5: =IF(OR($A5=5,$A5=11,$A5=15,$A5=22,$A5=30),ROUND(0*前提条件!$D$35,0),0) | L5: =$J5+$K5 | M5: =IF($A5<=12,前提条件!$D$31,前提条件!$D$32)*前提条件!$D$19 | N5: =ROUND($L5*$M5*(1-前提条件!$D$36),0) | O5: =ROUND($D5*前提条件!$D$39,0) | P5: =ROUND(IF($A5<10,0,IF($A5<=12,前提条件!$D$42,IF($A5<=18,前提条件!$D$43,IF($A5<=24,前提条件!$D$44,前提条件!$D$45))))*前提条件!$D$41,0) | Q5: =IF($A5<15,0,ROUND($G5*前提条件!$D$48*前提条件!$D$47*前提条件!$D$19,0)) | R5: =IF($A5<20,0,IF($A5<=24,前提条件!$D$51,前提条件!$D$52)*前提条件!$D$50) | S5: =SUM($N5:$R5) | T5: =IF($A5<=6,前提条件!$D$54,IF($A5<=18,前提条件!$D$55,前提条件!$D$56)) | U5: =IF($A5<=12,前提条件!$D$57,前提条件!$D$58) | V5: =前提条件!$D$59 | W5: =IF($A5<=6,0,IF($A5<=12,前提条件!$D$60,IF($A5<=24,前提条件!$D$61,前提条件!$D$62))) | X5: =IF($A5<5,0,IF($A5<=12,前提条件!$D$63,IF($A5<=24,前提条件!$D$64,前提条件!$D$65))) | Y5: =IF($A5<=12,0,IF($A5<=18,前提条件!$D$66,IF($A5<=24,前提条件!$D$67,前提条件!$D$68))) | Z5: =ROUND(($N5+$Q5)*前提条件!$D$69,0) | AA5: =IF($A5=1,前提条件!$D$70,0) | AB5: =SUM($T5:$AA5) | AC5: =$S5-$AB5 | AD5: =$AC5
A6: 2 | B6: =INT(($A6-1)/12)+1 | C6: =IF($A6<=3,前提条件!$D$21,IF($A6<=6,前提条件!$D$22,IF($A6<=12,前提条件!$D$23,IF($A6<=24,前提条件!$D$24,前提条件!$D$25)))) | D6: =$D5+$C6 | E6: =ROUND($C6*前提条件!$D$27,0) | F6: =IF($X6=0,0,ROUND($X6/前提条件!$D$28,0)) | G6: =$E6+$F6 | H6: =ROUND($I5*前提条件!$D$29,0) | I6: =$I5+$G6-$H6 | J6: =IF($A6<前提条件!$D$37,0,ROUND($G6*前提条件!$D$33+$I5*前提条件!$D$34,0)) | K6: =IF(OR($A6=5,$A6=11,$A6=15,$A6=22,$A6=30),ROUND($I5*前提条件!$D$35,0),0) | L6: =$J6+$K6 | M6: =IF($A6<=12,前提条件!$D$31,前提条件!$D$32)*前提条件!$D$19 | N6: =ROUND($L6*$M6*(1-前提条件!$D$36),0) | O6: =ROUND($D6*前提条件!$D$39,0) | P6: =ROUND(IF($A6<10,0,IF($A6<=12,前提条件!$D$42,IF($A6<=18,前提条件!$D$43,IF($A6<=24,前提条件!$D$44,前提条件!$D$45))))*前提条件!$D$41,0) | Q6: =IF($A6<15,0,ROUND($G6*前提条件!$D$48*前提条件!$D$47*前提条件!$D$19,0)) | R6: =IF($A6<20,0,IF($A6<=24,前提条件!$D$51,前提条件!$D$52)*前提条件!$D$50) | S6: =SUM($N6:$R6) | T6: =IF($A6<=6,前提条件!$D$54,IF($A6<=18,前提条件!$D$55,前提条件!$D$56)) | U6: =IF($A6<=12,前提条件!$D$57,前提条件!$D$58) | V6: =前提条件!$D$59 | W6: =IF($A6<=6,0,IF($A6<=12,前提条件!$D$60,IF($A6<=24,前提条件!$D$61,前提条件!$D$62))) | X6: =IF($A6<5,0,IF($A6<=12,前提条件!$D$63,IF($A6<=24,前提条件!$D$64,前提条件!$D$65))) | Y6: =IF($A6<=12,0,IF($A6<=18,前提条件!$D$66,IF($A6<=24,前提条件!$D$67,前提条件!$D$68))) | Z6: =ROUND(($N6+$Q6)*前提条件!$D$69,0) | AA6: =IF($A6=1,前提条件!$D$70,0) | AB6: =SUM($T6:$AA6) | AC6: =$S6-$AB6 | AD6: =$AD5+$AC6
A7: 3 | B7: =INT(($A7-1)/12)+1 | C7: =IF($A7<=3,前提条件!$D$21,IF($A7<=6,前提条件!$D$22,IF($A7<=12,前提条件!$D$23,IF($A7<=24,前提条件!$D$24,前提条件!$D$25)))) | D7: =$D6+$C7 | E7: =ROUND($C7*前提条件!$D$27,0) | F7: =IF($X7=0,0,ROUND($X7/前提条件!$D$28,0)) | G7: =$E7+$F7 | H7: =ROUND($I6*前提条件!$D$29,0) | I7: =$I6+$G7-$H7 | J7: =IF($A7<前提条件!$D$37,0,ROUND($G7*前提条件!$D$33+$I6*前提条件!$D$34,0)) | K7: =IF(OR($A7=5,$A7=11,$A7=15,$A7=22,$A7=30),ROUND($I6*前提条件!$D$35,0),0) | L7: =$J7+$K7 | M7: =IF($A7<=12,前提条件!$D$31,前提条件!$D$32)*前提条件!$D$19 | N7: =ROUND($L7*$M7*(1-前提条件!$D$36),0) | O7: =ROUND($D7*前提条件!$D$39,0) | P7: =ROUND(IF($A7<10,0,IF($A7<=12,前提条件!$D$42,IF($A7<=18,前提条件!$D$43,IF($A7<=24,前提条件!$D$44,前提条件!$D$45))))*前提条件!$D$41,0) | Q7: =IF($A7<15,0,ROUND($G7*前提条件!$D$48*前提条件!$D$47*前提条件!$D$19,0)) | R7: =IF($A7<20,0,IF($A7<=24,前提条件!$D$51,前提条件!$D$52)*前提条件!$D$50) | S7: =SUM($N7:$R7) | T7: =IF($A7<=6,前提条件!$D$54,IF($A7<=18,前提条件!$D$55,前提条件!$D$56)) | U7: =IF($A7<=12,前提条件!$D$57,前提条件!$D$58) | V7: =前提条件!$D$59 | W7: =IF($A7<=6,0,IF($A7<=12,前提条件!$D$60,IF($A7<=24,前提条件!$D$61,前提条件!$D$62))) | X7: =IF($A7<5,0,IF($A7<=12,前提条件!$D$63,IF($A7<=24,前提条件!$D$64,前提条件!$D$65))) | Y7: =IF($A7<=12,0,IF($A7<=18,前提条件!$D$66,IF($A7<=24,前提条件!$D$67,前提条件!$D$68))) | Z7: =ROUND(($N7+$Q7)*前提条件!$D$69,0) | AA7: =IF($A7=1,前提条件!$D$70,0) | AB7: =SUM($T7:$AA7) | AC7: =$S7-$AB7 | AD7: =$AD6+$AC7
A8: 4 | B8: =INT(($A8-1)/12)+1 | C8: =IF($A8<=3,前提条件!$D$21,IF($A8<=6,前提条件!$D$22,IF($A8<=12,前提条件!$D$23,IF($A8<=24,前提条件!$D$24,前提条件!$D$25)))) | D8: =$D7+$C8 | E8: =ROUND($C8*前提条件!$D$27,0) | F8: =IF($X8=0,0,ROUND($X8/前提条件!$D$28,0)) | G8: =$E8+$F8 | H8: =ROUND($I7*前提条件!$D$29,0) | I8: =$I7+$G8-$H8 | J8: =IF($A8<前提条件!$D$37,0,ROUND($G8*前提条件!$D$33+$I7*前提条件!$D$34,0)) | K8: =IF(OR($A8=5,$A8=11,$A8=15,$A8=22,$A8=30),ROUND($I7*前提条件!$D$35,0),0) | L8: =$J8+$K8 | M8: =IF($A8<=12,前提条件!$D$31,前提条件!$D$32)*前提条件!$D$19 | N8: =ROUND($L8*$M8*(1-前提条件!$D$36),0) | O8: =ROUND($D8*前提条件!$D$39,0) | P8: =ROUND(IF($A8<10,0,IF($A8<=12,前提条件!$D$42,IF($A8<=18,前提条件!$D$43,IF($A8<=24,前提条件!$D$44,前提条件!$D$45))))*前提条件!$D$41,0) | Q8: =IF($A8<15,0,ROUND($G8*前提条件!$D$48*前提条件!$D$47*前提条件!$D$19,0)) | R8: =IF($A8<20,0,IF($A8<=24,前提条件!$D$51,前提条件!$D$52)*前提条件!$D$50) | S8: =SUM($N8:$R8) | T8: =IF($A8<=6,前提条件!$D$54,IF($A8<=18,前提条件!$D$55,前提条件!$D$56)) | U8: =IF($A8<=12,前提条件!$D$57,前提条件!$D$58) | V8: =前提条件!$D$59 | W8: =IF($A8<=6,0,IF($A8<=12,前提条件!$D$60,IF($A8<=24,前提条件!$D$61,前提条件!$D$62))) | X8: =IF($A8<5,0,IF($A8<=12,前提条件!$D$63,IF($A8<=24,前提条件!$D$64,前提条件!$D$65))) | Y8: =IF($A8<=12,0,IF($A8<=18,前提条件!$D$66,IF($A8<=24,前提条件!$D$67,前提条件!$D$68))) | Z8: =ROUND(($N8+$Q8)*前提条件!$D$69,0) | AA8: =IF($A8=1,前提条件!$D$70,0) | AB8: =SUM($T8:$AA8) | AC8: =$S8-$AB8 | AD8: =$AD7+$AC8
A9: 5 | B9: =INT(($A9-1)/12)+1 | C9: =IF($A9<=3,前提条件!$D$21,IF($A9<=6,前提条件!$D$22,IF($A9<=12,前提条件!$D$23,IF($A9<=24,前提条件!$D$24,前提条件!$D$25)))) | D9: =$D8+$C9 | E9: =ROUND($C9*前提条件!$D$27,0) | F9: =IF($X9=0,0,ROUND($X9/前提条件!$D$28,0)) | G9: =$E9+$F9 | H9: =ROUND($I8*前提条件!$D$29,0) | I9: =$I8+$G9-$H9 | J9: =IF($A9<前提条件!$D$37,0,ROUND($G9*前提条件!$D$33+$I8*前提条件!$D$34,0)) | K9: =IF(OR($A9=5,$A9=11,$A9=15,$A9=22,$A9=30),ROUND($I8*前提条件!$D$35,0),0) | L9: =$J9+$K9 | M9: =IF($A9<=12,前提条件!$D$31,前提条件!$D$32)*前提条件!$D$19 | N9: =ROUND($L9*$M9*(1-前提条件!$D$36),0) | O9: =ROUND($D9*前提条件!$D$39,0) | P9: =ROUND(IF($A9<10,0,IF($A9<=12,前提条件!$D$42,IF($A9<=18,前提条件!$D$43,IF($A9<=24,前提条件!$D$44,前提条件!$D$45))))*前提条件!$D$41,0) | Q9: =IF($A9<15,0,ROUND($G9*前提条件!$D$48*前提条件!$D$47*前提条件!$D$19,0)) | R9: =IF($A9<20,0,IF($A9<=24,前提条件!$D$51,前提条件!$D$52)*前提条件!$D$50) | S9: =SUM($N9:$R9) | T9: =IF($A9<=6,前提条件!$D$54,IF($A9<=18,前提条件!$D$55,前提条件!$D$56)) | U9: =IF($A9<=12,前提条件!$D$57,前提条件!$D$58) | V9: =前提条件!$D$59 | W9: =IF($A9<=6,0,IF($A9<=12,前提条件!$D$60,IF($A9<=24,前提条件!$D$61,前提条件!$D$62))) | X9: =IF($A9<5,0,IF($A9<=12,前提条件!$D$63,IF($A9<=24,前提条件!$D$64,前提条件!$D$65))) | Y9: =IF($A9<=12,0,IF($A9<=18,前提条件!$D$66,IF($A9<=24,前提条件!$D$67,前提条件!$D$68))) | Z9: =ROUND(($N9+$Q9)*前提条件!$D$69,0) | AA9: =IF($A9=1,前提条件!$D$70,0) | AB9: =SUM($T9:$AA9) | AC9: =$S9-$AB9 | AD9: =$AD8+$AC9
A10: 6 | B10: =INT(($A10-1)/12)+1 | C10: =IF($A10<=3,前提条件!$D$21,IF($A10<=6,前提条件!$D$22,IF($A10<=12,前提条件!$D$23,IF($A10<=24,前提条件!$D$24,前提条件!$D$25)))) | D10: =$D9+$C10 | E10: =ROUND($C10*前提条件!$D$27,0) | F10: =IF($X10=0,0,ROUND($X10/前提条件!$D$28,0)) | G10: =$E10+$F10 | H10: =ROUND($I9*前提条件!$D$29,0) | I10: =$I9+$G10-$H10 | J10: =IF($A10<前提条件!$D$37,0,ROUND($G10*前提条件!$D$33+$I9*前提条件!$D$34,0)) | K10: =IF(OR($A10=5,$A10=11,$A10=15,$A10=22,$A10=30),ROUND($I9*前提条件!$D$35,0),0) | L10: =$J10+$K10 | M10: =IF($A10<=12,前提条件!$D$31,前提条件!$D$32)*前提条件!$D$19 | N10: =ROUND($L10*$M10*(1-前提条件!$D$36),0) | O10: =ROUND($D10*前提条件!$D$39,0) | P10: =ROUND(IF($A10<10,0,IF($A10<=12,前提条件!$D$42,IF($A10<=18,前提条件!$D$43,IF($A10<=24,前提条件!$D$44,前提条件!$D$45))))*前提条件!$D$41,0) | Q10: =IF($A10<15,0,ROUND($G10*前提条件!$D$48*前提条件!$D$47*前提条件!$D$19,0)) | R10: =IF($A10<20,0,IF($A10<=24,前提条件!$D$51,前提条件!$D$52)*前提条件!$D$50) | S10: =SUM($N10:$R10) | T10: =IF($A10<=6,前提条件!$D$54,IF($A10<=18,前提条件!$D$55,前提条件!$D$56)) | U10: =IF($A10<=12,前提条件!$D$57,前提条件!$D$58) | V10: =前提条件!$D$59 | W10: =IF($A10<=6,0,IF($A10<=12,前提条件!$D$60,IF($A10<=24,前提条件!$D$61,前提条件!$D$62))) | X10: =IF($A10<5,0,IF($A10<=12,前提条件!$D$63,IF($A10<=24,前提条件!$D$64,前提条件!$D$65))) | Y10: =IF($A10<=12,0,IF($A10<=18,前提条件!$D$66,IF($A10<=24,前提条件!$D$67,前提条件!$D$68))) | Z10: =ROUND(($N10+$Q10)*前提条件!$D$69,0) | AA10: =IF($A10=1,前提条件!$D$70,0) | AB10: =SUM($T10:$AA10) | AC10: =$S10-$AB10 | AD10: =$AD9+$AC10
A11: 7 | B11: =INT(($A11-1)/12)+1 | C11: =IF($A11<=3,前提条件!$D$21,IF($A11<=6,前提条件!$D$22,IF($A11<=12,前提条件!$D$23,IF($A11<=24,前提条件!$D$24,前提条件!$D$25)))) | D11: =$D10+$C11 | E11: =ROUND($C11*前提条件!$D$27,0) | F11: =IF($X11=0,0,ROUND($X11/前提条件!$D$28,0)) | G11: =$E11+$F11 | H11: =ROUND($I10*前提条件!$D$29,0) | I11: =$I10+$G11-$H11 | J11: =IF($A11<前提条件!$D$37,0,ROUND($G11*前提条件!$D$33+$I10*前提条件!$D$34,0)) | K11: =IF(OR($A11=5,$A11=11,$A11=15,$A11=22,$A11=30),ROUND($I10*前提条件!$D$35,0),0) | L11: =$J11+$K11 | M11: =IF($A11<=12,前提条件!$D$31,前提条件!$D$32)*前提条件!$D$19 | N11: =ROUND($L11*$M11*(1-前提条件!$D$36),0) | O11: =ROUND($D11*前提条件!$D$39,0) | P11: =ROUND(IF($A11<10,0,IF($A11<=12,前提条件!$D$42,IF($A11<=18,前提条件!$D$43,IF($A11<=24,前提条件!$D$44,前提条件!$D$45))))*前提条件!$D$41,0) | Q11: =IF($A11<15,0,ROUND($G11*前提条件!$D$48*前提条件!$D$47*前提条件!$D$19,0)) | R11: =IF($A11<20,0,IF($A11<=24,前提条件!$D$51,前提条件!$D$52)*前提条件!$D$50) | S11: =SUM($N11:$R11) | T11: =IF($A11<=6,前提条件!$D$54,IF($A11<=18,前提条件!$D$55,前提条件!$D$56)) | U11: =IF($A11<=12,前提条件!$D$57,前提条件!$D$58) | V11: =前提条件!$D$59 | W11: =IF($A11<=6,0,IF($A11<=12,前提条件!$D$60,IF($A11<=24,前提条件!$D$61,前提条件!$D$62))) | X11: =IF($A11<5,0,IF($A11<=12,前提条件!$D$63,IF($A11<=24,前提条件!$D$64,前提条件!$D$65))) | Y11: =IF($A11<=12,0,IF($A11<=18,前提条件!$D$66,IF($A11<=24,前提条件!$D$67,前提条件!$D$68))) | Z11: =ROUND(($N11+$Q11)*前提条件!$D$69,0) | AA11: =IF($A11=1,前提条件!$D$70,0) | AB11: =SUM($T11:$AA11) | AC11: =$S11-$AB11 | AD11: =$AD10+$AC11
A12: 8 | B12: =INT(($A12-1)/12)+1 | C12: =IF($A12<=3,前提条件!$D$21,IF($A12<=6,前提条件!$D$22,IF($A12<=12,前提条件!$D$23,IF($A12<=24,前提条件!$D$24,前提条件!$D$25)))) | D12: =$D11+$C12 | E12: =ROUND($C12*前提条件!$D$27,0) | F12: =IF($X12=0,0,ROUND($X12/前提条件!$D$28,0)) | G12: =$E12+$F12 | H12: =ROUND($I11*前提条件!$D$29,0) | I12: =$I11+$G12-$H12 | J12: =IF($A12<前提条件!$D$37,0,ROUND($G12*前提条件!$D$33+$I11*前提条件!$D$34,0)) | K12: =IF(OR($A12=5,$A12=11,$A12=15,$A12=22,$A12=30),ROUND($I11*前提条件!$D$35,0),0) | L12: =$J12+$K12 | M12: =IF($A12<=12,前提条件!$D$31,前提条件!$D$32)*前提条件!$D$19 | N12: =ROUND($L12*$M12*(1-前提条件!$D$36),0) | O12: =ROUND($D12*前提条件!$D$39,0) | P12: =ROUND(IF($A12<10,0,IF($A12<=12,前提条件!$D$42,IF($A12<=18,前提条件!$D$43,IF($A12<=24,前提条件!$D$44,前提条件!$D$45))))*前提条件!$D$41,0) | Q12: =IF($A12<15,0,ROUND($G12*前提条件!$D$48*前提条件!$D$47*前提条件!$D$19,0)) | R12: =IF($A12<20,0,IF($A12<=24,前提条件!$D$51,前提条件!$D$52)*前提条件!$D$50) | S12: =SUM($N12:$R12) | T12: =IF($A12<=6,前提条件!$D$54,IF($A12<=18,前提条件!$D$55,前提条件!$D$56)) | U12: =IF($A12<=12,前提条件!$D$57,前提条件!$D$58) | V12: =前提条件!$D$59 | W12: =IF($A12<=6,0,IF($A12<=12,前提条件!$D$60,IF($A12<=24,前提条件!$D$61,前提条件!$D$62))) | X12: =IF($A12<5,0,IF($A12<=12,前提条件!$D$63,IF($A12<=24,前提条件!$D$64,前提条件!$D$65))) | Y12: =IF($A12<=12,0,IF($A12<=18,前提条件!$D$66,IF($A12<=24,前提条件!$D$67,前提条件!$D$68))) | Z12: =ROUND(($N12+$Q12)*前提条件!$D$69,0) | AA12: =IF($A12=1,前提条件!$D$70,0) | AB12: =SUM($T12:$AA12) | AC12: =$S12-$AB12 | AD12: =$AD11+$AC12
A13: 9 | B13: =INT(($A13-1)/12)+1 | C13: =IF($A13<=3,前提条件!$D$21,IF($A13<=6,前提条件!$D$22,IF($A13<=12,前提条件!$D$23,IF($A13<=24,前提条件!$D$24,前提条件!$D$25)))) | D13: =$D12+$C13 | E13: =ROUND($C13*前提条件!$D$27,0) | F13: =IF($X13=0,0,ROUND($X13/前提条件!$D$28,0)) | G13: =$E13+$F13 | H13: =ROUND($I12*前提条件!$D$29,0) | I13: =$I12+$G13-$H13 | J13: =IF($A13<前提条件!$D$37,0,ROUND($G13*前提条件!$D$33+$I12*前提条件!$D$34,0)) | K13: =IF(OR($A13=5,$A13=11,$A13=15,$A13=22,$A13=30),ROUND($I12*前提条件!$D$35,0),0) | L13: =$J13+$K13 | M13: =IF($A13<=12,前提条件!$D$31,前提条件!$D$32)*前提条件!$D$19 | N13: =ROUND($L13*$M13*(1-前提条件!$D$36),0) | O13: =ROUND($D13*前提条件!$D$39,0) | P13: =ROUND(IF($A13<10,0,IF($A13<=12,前提条件!$D$42,IF($A13<=18,前提条件!$D$43,IF($A13<=24,前提条件!$D$44,前提条件!$D$45))))*前提条件!$D$41,0) | Q13: =IF($A13<15,0,ROUND($G13*前提条件!$D$48*前提条件!$D$47*前提条件!$D$19,0)) | R13: =IF($A13<20,0,IF($A13<=24,前提条件!$D$51,前提条件!$D$52)*前提条件!$D$50) | S13: =SUM($N13:$R13) | T13: =IF($A13<=6,前提条件!$D$54,IF($A13<=18,前提条件!$D$55,前提条件!$D$56)) | U13: =IF($A13<=12,前提条件!$D$57,前提条件!$D$58) | V13: =前提条件!$D$59 | W13: =IF($A13<=6,0,IF($A13<=12,前提条件!$D$60,IF($A13<=24,前提条件!$D$61,前提条件!$D$62))) | X13: =IF($A13<5,0,IF($A13<=12,前提条件!$D$63,IF($A13<=24,前提条件!$D$64,前提条件!$D$65))) | Y13: =IF($A13<=12,0,IF($A13<=18,前提条件!$D$66,IF($A13<=24,前提条件!$D$67,前提条件!$D$68))) | Z13: =ROUND(($N13+$Q13)*前提条件!$D$69,0) | AA13: =IF($A13=1,前提条件!$D$70,0) | AB13: =SUM($T13:$AA13) | AC13: =$S13-$AB13 | AD13: =$AD12+$AC13
A14: 10 | B14: =INT(($A14-1)/12)+1 | C14: =IF($A14<=3,前提条件!$D$21,IF($A14<=6,前提条件!$D$22,IF($A14<=12,前提条件!$D$23,IF($A14<=24,前提条件!$D$24,前提条件!$D$25)))) | D14: =$D13+$C14 | E14: =ROUND($C14*前提条件!$D$27,0) | F14: =IF($X14=0,0,ROUND($X14/前提条件!$D$28,0)) | G14: =$E14+$F14 | H14: =ROUND($I13*前提条件!$D$29,0) | I14: =$I13+$G14-$H14 | J14: =IF($A14<前提条件!$D$37,0,ROUND($G14*前提条件!$D$33+$I13*前提条件!$D$34,0)) | K14: =IF(OR($A14=5,$A14=11,$A14=15,$A14=22,$A14=30),ROUND($I13*前提条件!$D$35,0),0) | L14: =$J14+$K14 | M14: =IF($A14<=12,前提条件!$D$31,前提条件!$D$32)*前提条件!$D$19 | N14: =ROUND($L14*$M14*(1-前提条件!$D$36),0) | O14: =ROUND($D14*前提条件!$D$39,0) | P14: =ROUND(IF($A14<10,0,IF($A14<=12,前提条件!$D$42,IF($A14<=18,前提条件!$D$43,IF($A14<=24,前提条件!$D$44,前提条件!$D$45))))*前提条件!$D$41,0) | Q14: =IF($A14<15,0,ROUND($G14*前提条件!$D$48*前提条件!$D$47*前提条件!$D$19,0)) | R14: =IF($A14<20,0,IF($A14<=24,前提条件!$D$51,前提条件!$D$52)*前提条件!$D$50) | S14: =SUM($N14:$R14) | T14: =IF($A14<=6,前提条件!$D$54,IF($A14<=18,前提条件!$D$55,前提条件!$D$56)) | U14: =IF($A14<=12,前提条件!$D$57,前提条件!$D$58) | V14: =前提条件!$D$59 | W14: =IF($A14<=6,0,IF($A14<=12,前提条件!$D$60,IF($A14<=24,前提条件!$D$61,前提条件!$D$62))) | X14: =IF($A14<5,0,IF($A14<=12,前提条件!$D$63,IF($A14<=24,前提条件!$D$64,前提条件!$D$65))) | Y14: =IF($A14<=12,0,IF($A14<=18,前提条件!$D$66,IF($A14<=24,前提条件!$D$67,前提条件!$D$68))) | Z14: =ROUND(($N14+$Q14)*前提条件!$D$69,0) | AA14: =IF($A14=1,前提条件!$D$70,0) | AB14: =SUM($T14:$AA14) | AC14: =$S14-$AB14 | AD14: =$AD13+$AC14
A15: 11 | B15: =INT(($A15-1)/12)+1 | C15: =IF($A15<=3,前提条件!$D$21,IF($A15<=6,前提条件!$D$22,IF($A15<=12,前提条件!$D$23,IF($A15<=24,前提条件!$D$24,前提条件!$D$25)))) | D15: =$D14+$C15 | E15: =ROUND($C15*前提条件!$D$27,0) | F15: =IF($X15=0,0,ROUND($X15/前提条件!$D$28,0)) | G15: =$E15+$F15 | H15: =ROUND($I14*前提条件!$D$29,0) | I15: =$I14+$G15-$H15 | J15: =IF($A15<前提条件!$D$37,0,ROUND($G15*前提条件!$D$33+$I14*前提条件!$D$34,0)) | K15: =IF(OR($A15=5,$A15=11,$A15=15,$A15=22,$A15=30),ROUND($I14*前提条件!$D$35,0),0) | L15: =$J15+$K15 | M15: =IF($A15<=12,前提条件!$D$31,前提条件!$D$32)*前提条件!$D$19 | N15: =ROUND($L15*$M15*(1-前提条件!$D$36),0) | O15: =ROUND($D15*前提条件!$D$39,0) | P15: =ROUND(IF($A15<10,0,IF($A15<=12,前提条件!$D$42,IF($A15<=18,前提条件!$D$43,IF($A15<=24,前提条件!$D$44,前提条件!$D$45))))*前提条件!$D$41,0) | Q15: =IF($A15<15,0,ROUND($G15*前提条件!$D$48*前提条件!$D$47*前提条件!$D$19,0)) | R15: =IF($A15<20,0,IF($A15<=24,前提条件!$D$51,前提条件!$D$52)*前提条件!$D$50) | S15: =SUM($N15:$R15) | T15: =IF($A15<=6,前提条件!$D$54,IF($A15<=18,前提条件!$D$55,前提条件!$D$56)) | U15: =IF($A15<=12,前提条件!$D$57,前提条件!$D$58) | V15: =前提条件!$D$59 | W15: =IF($A15<=6,0,IF($A15<=12,前提条件!$D$60,IF($A15<=24,前提条件!$D$61,前提条件!$D$62))) | X15: =IF($A15<5,0,IF($A15<=12,前提条件!$D$63,IF($A15<=24,前提条件!$D$64,前提条件!$D$65))) | Y15: =IF($A15<=12,0,IF($A15<=18,前提条件!$D$66,IF($A15<=24,前提条件!$D$67,前提条件!$D$68))) | Z15: =ROUND(($N15+$Q15)*前提条件!$D$69,0) | AA15: =IF($A15=1,前提条件!$D$70,0) | AB15: =SUM($T15:$AA15) | AC15: =$S15-$AB15 | AD15: =$AD14+$AC15
A16: 12 | B16: =INT(($A16-1)/12)+1 | C16: =IF($A16<=3,前提条件!$D$21,IF($A16<=6,前提条件!$D$22,IF($A16<=12,前提条件!$D$23,IF($A16<=24,前提条件!$D$24,前提条件!$D$25)))) | D16: =$D15+$C16 | E16: =ROUND($C16*前提条件!$D$27,0) | F16: =IF($X16=0,0,ROUND($X16/前提条件!$D$28,0)) | G16: =$E16+$F16 | H16: =ROUND($I15*前提条件!$D$29,0) | I16: =$I15+$G16-$H16 | J16: =IF($A16<前提条件!$D$37,0,ROUND($G16*前提条件!$D$33+$I15*前提条件!$D$34,0)) | K16: =IF(OR($A16=5,$A16=11,$A16=15,$A16=22,$A16=30),ROUND($I15*前提条件!$D$35,0),0) | L16: =$J16+$K16 | M16: =IF($A16<=12,前提条件!$D$31,前提条件!$D$32)*前提条件!$D$19 | N16: =ROUND($L16*$M16*(1-前提条件!$D$36),0) | O16: =ROUND($D16*前提条件!$D$39,0) | P16: =ROUND(IF($A16<10,0,IF($A16<=12,前提条件!$D$42,IF($A16<=18,前提条件!$D$43,IF($A16<=24,前提条件!$D$44,前提条件!$D$45))))*前提条件!$D$41,0) | Q16: =IF($A16<15,0,ROUND($G16*前提条件!$D$48*前提条件!$D$47*前提条件!$D$19,0)) | R16: =IF($A16<20,0,IF($A16<=24,前提条件!$D$51,前提条件!$D$52)*前提条件!$D$50) | S16: =SUM($N16:$R16) | T16: =IF($A16<=6,前提条件!$D$54,IF($A16<=18,前提条件!$D$55,前提条件!$D$56)) | U16: =IF($A16<=12,前提条件!$D$57,前提条件!$D$58) | V16: =前提条件!$D$59 | W16: =IF($A16<=6,0,IF($A16<=12,前提条件!$D$60,IF($A16<=24,前提条件!$D$61,前提条件!$D$62))) | X16: =IF($A16<5,0,IF($A16<=12,前提条件!$D$63,IF($A16<=24,前提条件!$D$64,前提条件!$D$65))) | Y16: =IF($A16<=12,0,IF($A16<=18,前提条件!$D$66,IF($A16<=24,前提条件!$D$67,前提条件!$D$68))) | Z16: =ROUND(($N16+$Q16)*前提条件!$D$69,0) | AA16: =IF($A16=1,前提条件!$D$70,0) | AB16: =SUM($T16:$AA16) | AC16: =$S16-$AB16 | AD16: =$AD15+$AC16
