Workbook

Sheet ルール
B3: 1 | C3: 文字は「游ゴシック」、数字は「Arial」を基本。備考欄などの細かい文章は「游ゴシック Medium」。
B4: 2 | C4: タイトル、合計欄は太字
B5: 3 | C5: 数字は円単位で入力、表示は千円単位に設定済み
B6: 4 | C6: 基本の背景は以下の通り。紺、水色、グレー、白、青。パレットの上部の色。
C8: 線は紺か白か青。
C10: 資産の部
C11: 科目 | D11: ='BS(借方)'!F10 -> 0 | E11: 調整額 | F11: 調整後
C12: 【流動資産】 | D12: =SUM(D13:D26) -> 5000000 | E12: =SUM(E13:E26) -> -500000 | F12: =SUM(F13:F26) -> 4500000
C13: 現金及び預金 | D13: 5000000 | E13: -500000 | F13: =D13+E13 -> 4500000
F14: =D14+E14 -> 0

Sheet 財務入力→

Sheet BS(借方)
C1: ←基本的にはここをつかう→
C2: 1期目 | D2: 2期目 | E2: 3期目 | F2: （4期目） | G2: 進行期
B3: 資産の部
B4: 科目 | C4: 24年1月期 | D4: 25年1月期 | E4: 26年1月期 | F4: ●●年●月期 | G4: ●●年●月 （●か月TB）
B5: 【流動資産】 | C5: =SUM(C6:C19) -> 353922232 | D5: =SUM(D6:D19) -> 309100318 | E5: =SUM(E6:E19) -> 226144406 | F5: =SUM(F6:F19) -> 0 | G5: =SUM(G6:G19) -> 0
B6: 現金及び預金 | C6: 260204106 | D6: 241196237 | E6: 193226490
B7: 売掛金 | C7: 80309192 | D7: 24606051 | E7: 20153150
B8: 貸倒引当金 | C8: -803000 | D8: -246000 | E8: -201000
B9: 商品 | C9: 1377066 | D9: 23573572 | E9: 204834
B10: 証紙 | C10: 48976 | D10: 9771051 | E10: 24020
B11: 前渡金 | C11: 5809100 | D11: 4571906 | E11: 12055237
B12: 立替金 | D12: 79184
B13: 前払費用 | C13: 621392 | D13: 805869 | E13: 640475
B14: 未収入金 | C14: 3228000 | D14: 4742448 | E14: 41200
B15: 仮払税 | C15: 3127400
B20: 【固定資産】 | C20: =C21+C35+C46 -> 140739380 | D20: =D21+D35+D46 -> 228972793 | E20: =E21+E35+E46 -> 323863136 | F20: =F21+F35+F46 -> 0 | G20: =G21+G35+G46 -> 0
B21: ［有形固定資産］ | C21: =SUM(C22:C34) -> 1931618 | D21: =SUM(D22:D34) -> 1479093 | E21: =SUM(E22:E34) -> 1056920 | F21: =SUM(F22:F34) -> 0 | G21: =SUM(G22:G34) -> 0
B22: 建物附属設備 | C22: 830303 | D22: 765648 | E22: 700993
B23: 車両運搬具 | C23: 797788 | D23: 531328 | E23: 264868
B24: 工具器具備品 | C24: 303527 | D24: 182117 | E24: 91059
B35: ［無形固定資産］ | C35: =SUM(C36:C45) -> 0 | D35: =SUM(D36:D45) -> 2688001 | E35: =SUM(E36:E45) -> 2112001 | F35: =SUM(F36:F45) -> 0 | G35: =SUM(G36:G45) -> 0
B36: ソフトウェア | D36: 2688001 | E36: 2112001
B46: ［投資その他資産］ | C46: =SUM(C47:C55) -> 138807762 | D46: =SUM(D47:D55) -> 224805699 | E46: =SUM(E47:E55) -> 320694215 | F46: =SUM(F47:F55) -> 0 | G46: =SUM(G47:G55) -> 0
B47: 投資有価証券 | C47: 112672352 | D47: 188090341 | E47: 275896334
B48: 出資金 | C48: 30000 | D48: 30000 | E48: 30000
B49: 敷金 | C49: 50000 | D49: 50000 | E49: 50000
B50: 差入保証金 | C50: 1263500 | D50: 1263500 | E50: 1263500
B51: 預託金 | C51: 25040 | D51: 25040 | E51: 25040
B52: 保険積立金 | C52: 24766870 | D52: 35346818 | E52: 43326766
B53: 長期前払費用 | E53: 102575
B56: 【繰延資産】 | C56: =SUM(C57:C60) -> 0 | D56: =SUM(D57:D60) -> 0 | E56: =SUM(E57:E60) -> 0 | F56: =SUM(F57:F60) -> 0 | G56: =SUM(G57:G60) -> 0
B61: 資産合計 | C61: =C5+C20+C56 -> 494661612 | D61: =D5+D20+D56 -> 538073111 | E61: =E5+E20+E56 -> 550007542 | F61: =F5+F20+F56 -> 0 | G61: =G5+G20+G56 -> 0
B63: バランスチェック | C63: =EXACT(C61,'BS (貸方)'!C51) -> TRUE | D63: =EXACT(D61,'BS (貸方)'!D51) -> TRUE | E63: =EXACT(E61,'BS (貸方)'!E51) -> TRUE | F63: =EXACT(F61,'BS (貸方)'!F51) -> TRUE | G63: =EXACT(G61,'BS (貸方)'!G51) -> TRUE

Sheet BS (貸方)
E2: (単位：千円)
B3: 負債の部
B4: 科目 | C4: ='BS(借方)'!C4 -> 24年1月期 | D4: ='BS(借方)'!D4 -> 25年1月期 | E4: ='BS(借方)'!E4 -> 26年1月期 | F4: ='BS(借方)'!F4 -> ●●年●月期 | G4: ='BS(借方)'!G4 -> ●●年●月 （●か月TB）
B5: 【流動負債】 | C5: =SUM(C6:C17) -> 47623635 | D5: =SUM(D6:D17) -> 106163378 | E5: =SUM(E6:E17) -> 70491633 | F5: =SUM(F6:F17) -> 0 | G5: =SUM(G6:G17) -> 0
B6: 買掛金 | C6: 42759404 | D6: 51250714 | E6: 9644516
B7: 未払金 | C7: 3911586 | D7: 5447277 | E7: 3947278
B8: 未払法人税等 | C8: 35000 | D8: 19454800 | E8: 2929500
B9: 未払消費税等 | E9: 12017600
B10: 預り金 | C10: 917645 | D10: 154227 | E10: 124739
B11: 仮受金 | D11: 228360
B12: 一年以内返済長期借入金 | D12: 29628000 | E12: 41828000
B18: 【固定負債】 | C18: =SUM(C19:C24) -> 191690000 | D18: =SUM(D19:D24) -> 136004000 | E18: =SUM(E19:E24) -> 145980000 | F18: =SUM(F19:F24) -> 0 | G18: =SUM(G19:G24) -> 0
B19: 長期借入金 | C19: 191690000 | D19: 136004000 | E19: 145980000
B25: 負債合計 | C25: =C5+C18 -> 239313635 | D25: =D5+D18 -> 242167378 | E25: =E5+E18 -> 216471633 | F25: =F5+F18 -> 0 | G25: =G5+G18 -> 0
B34: 純資産の部
B35: 【資本金】 | C35: =SUM(C36:C38) -> 10000000 | D35: =SUM(D36:D38) -> 10000000 | E35: =SUM(E36:E38) -> 10000000 | F35: =SUM(F36:F38) -> 0 | G35: =SUM(G36:G38) -> 0
B36: 資本金 | C36: 10000000 | D36: 10000000 | E36: 10000000
B39: 【資本剰余金】 | C39: =SUM(C40:C42) -> 0 | D39: =SUM(D40:D42) -> 0 | E39: =SUM(E40:E42) -> 0 | F39: =SUM(F40:F42) -> 0 | G39: =SUM(G40:G42) -> 0
B43: 【利益剰余金】 | C43: =SUM(C44:C48) -> 245347977 | D43: =SUM(D44:D48) -> 285905733 | E43: =SUM(E44:E48) -> 323535909 | F43: =SUM(F44:F48) -> 0 | G43: =SUM(G44:G48) -> 0
B44: 繰越利益剰余金 | C44: 245347977 | D44: 285905733 | E44: 323535909
B49: 【自己株式】 | C49: 0 | D49: 0 | E49: 0 | F49: 0 | G49: 0
B50: 純資産合計 | C50: =C35+C39+C43+C49 -> 255347977 | D50: =D35+D39+D43+D49 -> 295905733 | E50: =E35+E39+E43+E49 -> 333535909 | F50: =F35+F39+F43+F49 -> 0 | G50: =G35+G39+G43+G49 -> 0
B51: 負債・純資産合計 | C51: =C25+C50 -> 494661612 | D51: =D25+D50 -> 538073111 | E51: =E25+E50 -> 550007542 | F51: =F25+F50 -> 0 | G51: =G25+G50 -> 0
B53: バランスチェック | C53: =EXACT(C51,'BS(借方)'!C61) -> TRUE | D53: =EXACT(D51,'BS(借方)'!D61) -> TRUE | E53: =EXACT(E51,'BS(借方)'!E61) -> TRUE | F53: =EXACT(F51,'BS(借方)'!F61) -> TRUE | G53: =EXACT(G51,'BS(借方)'!G61) -> TRUE

Sheet PL
H2: (単位：千円)
B3: 科目 | C3: ='BS(借方)'!C4 -> 24年1月期 | E3: ='BS(借方)'!D4 -> 25年1月期 | G3: ='BS(借方)'!E4 -> 26年1月期 | I3: ='BS(借方)'!F4 -> ●●年●月期 | K3: ●年●月期
C4: 帳簿価額 | D4: 売上高比 | E4: 帳簿価額 | F4: 売上高比 | G4: 帳簿価額 | H4: 売上高比 | I4: 帳簿価額 | J4: 売上高比 | K4: 帳簿価額 | L4: 売上高比
B5: 売上高 | C5: 301575965 | D5: =IF(C5=0,"",C5/C$11) -> 0.9520781 | E5: 285379413 | F5: =IF(E5=0,"",E5/E$11) -> 0.6429375 | G5: 387747182 | H5: =IF(G5=0,"",G5/G$11) -> 0.91780019 | J5: =IF(I5=0,"",I5/I$11) | L5: =IF(K5=0,"",K5/K$11)
B6: 輸出売上 | C6: 15179525 | D6: =IF(C6=0,"",C6/C$11) -> 0.0479219 | E6: 158488638 | F6: =IF(E6=0,"",E6/E$11) -> 0.3570625 | G6: 34727325 | H6: =IF(G6=0,"",G6/G$11) -> 0.082199812 | J6: =IF(I6=0,"",I6/I$11) | L6: =IF(K6=0,"",K6/K$11)
D9: =IF(C9=0,"",C9/C$11) | F9: =IF(E9=0,"",E9/E$11) | H9: =IF(G9=0,"",G9/G$11) | J9: =IF(I9=0,"",I9/I$11) | L9: =IF(K9=0,"",K9/K$11)
D10: =IF(C10=0,"",C10/C$11) | F10: =IF(E10=0,"",E10/E$11) | H10: =IF(G10=0,"",G10/G$11) | J10: =IF(I10=0,"",I10/I$11) | L10: =IF(K10=0,"",K10/K$11)
B11: 売上高 | C11: =SUM(C5:C10) -> 316755490 | D11: =IF(C11=0,"",C11/C$11) -> 1 | E11: =SUM(E5:E10) -> 443868051 | F11: =IF(E11=0,"",E11/E$11) -> 1 | G11: =SUM(G5:G10) -> 422474507 | H11: =IF(G11=0,"",G11/G$11) -> 1 | I11: =SUM(I5:I10) -> 0 | J11: =IF(I11=0,"",I11/I$11) | K11: =SUM(K5:K10) -> 0 | L11: =IF(K11=0,"",K11/K$11)
B12: 期首商品棚卸高 | C12: 3024069 | D12: =IF(C12=0,"",C12/C$11) -> 0.0095470137 | E12: 1426042 | F12: =IF(E12=0,"",E12/E$11) -> 0.0032127611 | G12: 33344623 | H12: =IF(G12=0,"",G12/G$11) -> 0.078926947 | J12: =IF(I12=0,"",I12/I$11) | L12: =IF(K12=0,"",K12/K$11)
B13: 当期商品仕入高 | C13: 172656708 | D13: =IF(C13=0,"",C13/C$11) -> 0.54507882 | E13: 237257918 | F13: =IF(E13=0,"",E13/E$11) -> 0.53452353 | G13: 225575333 | H13: =IF(G13=0,"",G13/G$11) -> 0.53393833
B14: （製）支払手数料 | C14: 26573925 | D14: =IF(C14=0,"",C14/C$11) -> 0.083894126 | E14: 50722738 | F14: =IF(E14=0,"",E14/E$11) -> 0.11427436 | G14: 21094265 | H14: =IF(G14=0,"",G14/G$11) -> 0.049930267
B15: （製）サンプル | C15: 6307077 | D15: =IF(C15=0,"",C15/C$11) -> 0.0199115 | E15: 2327904 | F15: =IF(E15=0,"",E15/E$11) -> 0.0052445856 | G15: 2831360 | H15: =IF(G15=0,"",G15/G$11) -> 0.0067018482
B16: 試作費 | C16: 4487974 | D16: =IF(C16=0,"",C16/C$11) -> 0.014168575 | E16: 13796708 | F16: =IF(E16=0,"",E16/E$11) -> 0.031082904 | G16: 3637077 | H16: =IF(G16=0,"",G16/G$11) -> 0.0086089857 | J16: =IF(I16=0,"",I16/I$11) | L16: =IF(K16=0,"",K16/K$11)
B17: （製）外注費 | C17: 8299304 | D17: =IF(C17=0,"",C17/C$11) -> 0.026200979 | E17: 9972324 | F17: =IF(E17=0,"",E17/E$11) -> 0.022466866 | G17: 5262263 | H17: =IF(G17=0,"",G17/G$11) -> 0.012455812 | J17: =IF(I17=0,"",I17/I$11) | L17: =IF(K17=0,"",K17/K$11)
B18: 仕入値引高 | D18: =IF(C18=0,"",C18/C$11) | F18: =IF(E18=0,"",E18/E$11) | G18: -100 | H18: =IF(G18=0,"",G18/G$11) -> -2.3670067e-07 | J18: =IF(I18=0,"",I18/I$11) | L18: =IF(K18=0,"",K18/K$11)
B19: 他勘定振替高 | C19: -6722798 | D19: =IF(C19=0,"",C19/C$11) -> -0.021223935 | E19: -17217311 | F19: =IF(E19=0,"",E19/E$11) -> -0.038789255 | G19: -19844732 | H19: =IF(G19=0,"",G19/G$11) -> -0.046972614
B20: 期末商品棚卸高 | C20: -1426042 | D20: =IF(C20=0,"",C20/C$11) -> -0.0045020277 | E20: -33344623 | F20: =IF(E20=0,"",E20/E$11) -> -0.075122827 | G20: -228854 | H20: =IF(G20=0,"",G20/G$11) -> -0.00054169896
B21: 売上原価 | C21: =SUM(C12:C20) -> 213200217 | D21: =IF(C21=0,"",C21/C$11) -> 0.67307505 | E21: =SUM(E12:E20) -> 264941700 | F21: =IF(E21=0,"",E21/E$11) -> 0.59689293 | G21: =SUM(G12:G20) -> 271671235 | H21: =IF(G21=0,"",G21/G$11) -> 0.64304764 | I21: =SUM(I12:I18) -> 0 | J21: =IF(I21=0,"",I21/I$11) | K21: =SUM(K12:K18) -> 0 | L21: =IF(K21=0,"",K21/K$11)
B22: 売上総利益 | C22: =C11-C21 -> 103555273 | D22: =IF(C22=0,"",C22/C$11) -> 0.32692495 | E22: =E11-E21 -> 178926351 | F22: =IF(E22=0,"",E22/E$11) -> 0.40310707 | G22: =G11-G21 -> 150803272 | H22: =IF(G22=0,"",G22/G$11) -> 0.35695236 | I22: =I11-I21 -> 0 | J22: =IF(I22=0,"",I22/I$11) | K22: =K11-K21 -> 0 | L22: =IF(K22=0,"",K22/K$11)
B23: 販売費及び一般管理費 | C23: =SGA!C40 -> 97395979 | D23: =IF(C23=0,"",C23/C$11) -> 0.30748 | E23: =SGA!E40 -> 100735586 | F23: =IF(E23=0,"",E23/E$11) -> 0.2269494 | G23: =SGA!G40 -> 92289462 | H23: =IF(G23=0,"",G23/G$11) -> 0.21844978 | I23: =SGA!I40 -> 0 | J23: =IF(I23=0,"",I23/I$11) | K23: =SGA!K40 -> 0 | L23: =IF(K23=0,"",K23/K$11)
B24: 営業利益 | C24: =C22- C23 -> 6159294 | D24: =IF(C24=0,"",C24/C$11) -> 0.019444948 | E24: =E22- E23 -> 78190765 | F24: =IF(E24=0,"",E24/E$11) -> 0.17615768 | G24: =G22- G23 -> 58513810 | H24: =IF(G24=0,"",G24/G$11) -> 0.13850258 | I24: =I22- I23 -> 0 | J24: =IF(I24=0,"",I24/I$11) | K24: =K22- K23 -> 0 | L24: =IF(K24=0,"",K24/K$11)
B25: 営業外収益 | C25: =SUM(C26:C32) -> 1358290 | D25: =IF(C25=0,"",C25/C$11) -> 0.004288134 | E25: =SUM(E26:E32) -> 13984344 | F25: =IF(E25=0,"",E25/E$11) -> 0.031505633 | G25: =SUM(G26:G32) -> 8626001 | H25: =IF(G25=0,"",G25/G$11) -> 0.020417802 | I25: =SUM(I26:I32) -> 0 | J25: =IF(I25=0,"",I25/I$11) | K25: =SUM(K26:K32) -> 0 | L25: =IF(K25=0,"",K25/K$11)
B26: 受取利息 | C26: 101059 | D26: =IF(C26=0,"",C26/C$11) -> 0.00031904419 | E26: 1035013 | F26: =IF(E26=0,"",E26/E$11) -> 0.0023318033 | G26: 326339 | H26: =IF(G26=0,"",G26/G$11) -> 0.00077244661 | J26: =IF(I26=0,"",I26/I$11) | L26: =IF(K26=0,"",K26/K$11)
B27: 受取配当金 | C27: 712050 | D27: =IF(C27=0,"",C27/C$11) -> 0.0022479484 | E27: 7151912 | F27: =IF(E27=0,"",E27/E$11) -> 0.016112698 | G27: 7555640 | H27: =IF(G27=0,"",G27/G$11) -> 0.017884251 | J27: =IF(I27=0,"",I27/I$11) | L27: =IF(K27=0,"",K27/K$11)
B28: 貸倒引当金戻入額 | C28: 534000 | D28: =IF(C28=0,"",C28/C$11) -> 0.0016858429 | E28: 803000 | F28: =IF(E28=0,"",E28/E$11) -> 0.0018090962 | G28: 246000 | H28: =IF(G28=0,"",G28/G$11) -> 0.00058228365 | J28: =IF(I28=0,"",I28/I$11) | L28: =IF(K28=0,"",K28/K$11)
B29: 雑収入 | C29: 2197 | D29: =IF(C29=0,"",C29/C$11) -> 6.9359492e-06 | E29: 2195483 | F29: =IF(E29=0,"",E29/E$11) -> 0.0049462515 | G29: 216735 | H29: =IF(G29=0,"",G29/G$11) -> 0.0005130132 | J29: =IF(I29=0,"",I29/I$11) | L29: =IF(K29=0,"",K29/K$11)
B30: 仕入割引 | D30: =IF(C30=0,"",C30/C$11) | F30: =IF(E30=0,"",E30/E$11) | G30: 10455 | H30: =IF(G30=0,"",G30/G$11) -> 2.4747055e-05 | J30: =IF(I30=0,"",I30/I$11) | L30: =IF(K30=0,"",K30/K$11)
B31: 為替差益 | C31: 8984 | D31: =IF(C31=0,"",C31/C$11) -> 2.8362571e-05 | E31: 2798936 | F31: =IF(E31=0,"",E31/E$11) -> 0.0063057839 | G31: 270832 | H31: =IF(G31=0,"",G31/G$11) -> 0.00064106117 | J31: =IF(I31=0,"",I31/I$11) | L31: =IF(K31=0,"",K31/K$11)
D32: =IF(C32=0,"",C32/C$11) | F32: =IF(E32=0,"",E32/E$11) | H32: =IF(G32=0,"",G32/G$11) | J32: =IF(I32=0,"",I32/I$11) | L32: =IF(K32=0,"",K32/K$11)
B33: 営業外費用 | C33: =SUM(C34:C40) -> 852015 | D33: =IF(C33=0,"",C33/C$11) -> 0.0026898192 | E33: =SUM(E34:E40) -> 2246448 | F33: =IF(E33=0,"",E33/E$11) -> 0.0050610716 | G33: =SUM(G34:G40) -> 2196742 | H33: =IF(G33=0,"",G33/G$11) -> 0.0051997031 | I33: =SUM(I34:I40) -> 0 | J33: =IF(I33=0,"",I33/I$11) | K33: =SUM(K34:K40) -> 0 | L33: =IF(K33=0,"",K33/K$11)
B34: 支払利息 | C34: 852015 | D34: =IF(C34=0,"",C34/C$11) -> 0.0026898192 | E34: 1716559 | F34: =IF(E34=0,"",E34/E$11) -> 0.0038672732 | G34: 2196742 | H34: =IF(G34=0,"",G34/G$11) -> 0.0051997031 | J34: =IF(I34=0,"",I34/I$11) | L34: =IF(K34=0,"",K34/K$11)
B35: 雑損失 | D35: =IF(C35=0,"",C35/C$11) | E35: 529889 | F35: =IF(E35=0,"",E35/E$11) -> 0.0011937985 | H35: =IF(G35=0,"",G35/G$11) | J35: =IF(I35=0,"",I35/I$11) | L35: =IF(K35=0,"",K35/K$11)
D36: =IF(C36=0,"",C36/C$11) | F36: =IF(E36=0,"",E36/E$11) | H36: =IF(G36=0,"",G36/G$11) | J36: =IF(I36=0,"",I36/I$11) | L36: =IF(K36=0,"",K36/K$11)
D37: =IF(C37=0,"",C37/C$11) | F37: =IF(E37=0,"",E37/E$11) | H37: =IF(G37=0,"",G37/G$11) | J37: =IF(I37=0,"",I37/I$11) | L37: =IF(K37=0,"",K37/K$11)
D38: =IF(C38=0,"",C38/C$11) | F38: =IF(E38=0,"",E38/E$11) | H38: =IF(G38=0,"",G38/G$11) | J38: =IF(I38=0,"",I38/I$11) | L38: =IF(K38=0,"",K38/K$11)
D39: =IF(C39=0,"",C39/C$11) | F39: =IF(E39=0,"",E39/E$11) | H39: =IF(G39=0,"",G39/G$11) | J39: =IF(I39=0,"",I39/I$11) | L39: =IF(K39=0,"",K39/K$11)
D40: =IF(C40=0,"",C40/C$11) | F40: =IF(E40=0,"",E40/E$11) | H40: =IF(G40=0,"",G40/G$11) | J40: =IF(I40=0,"",I40/I$11) | L40: =IF(K40=0,"",K40/K$11)
B41: 経常利益 | C41: =C24+C25-C33 -> 6665569 | D41: =IF(C41=0,"",C41/C$11) -> 0.021043263 | E41: =E24+E25-E33 -> 89928661 | F41: =IF(E41=0,"",E41/E$11) -> 0.20260224 | G41: =G24+G25-G33 -> 64943069 | H41: =IF(G41=0,"",G41/G$11) -> 0.15372068 | I41: =I24+I25-I33 -> 0 | J41: =IF(I41=0,"",I41/I$11) | K41: =K24+K25-K33 -> 0 | L41: =IF(K41=0,"",K41/K$11)
B42: 特別利益 | C42: =SUM(C43:C48) -> 0 | D42: =IF(C42=0,"",C42/C$11) | E42: =SUM(E43:E48) -> 21984310 | F42: =IF(E42=0,"",E42/E$11) -> 0.049528931 | G42: =SUM(G43:G48) -> 12486495 | H42: =IF(G42=0,"",G42/G$11) -> 0.029555618 | I42: =SUM(I43:I48) -> 0 | J42: =IF(I42=0,"",I42/I$11) | K42: =SUM(K43:K48) -> 0 | L42: =IF(K42=0,"",K42/K$11)
B43: 投資有価証券売却益 | D43: =IF(C43=0,"",C43/C$11) | E43: 21984310 | F43: =IF(E43=0,"",E43/E$11) -> 0.049528931 | G43: 12486495 | H43: =IF(G43=0,"",G43/G$11) -> 0.029555618 | J43: =IF(I43=0,"",I43/I$11) | L43: =IF(K43=0,"",K43/K$11)
...

Sheet CR
H4: (単位：千円)
B5: 科目 | C5: ='BS(借方)'!C4 -> 24年1月期 | E5: ='BS(借方)'!D4 -> 25年1月期 | G5: ='BS(借方)'!E4 -> 26年1月期 | I5: ='BS(借方)'!F4 -> ●●年●月期 | K5: ='BS(借方)'!G4 -> ●●年●月 （●か月TB）
C6: 帳簿価額 | D6: 売上高比 | E6: 帳簿価額 | F6: 売上高比 | G6: 帳簿価額 | H6: 売上高比 | I6: 帳簿価額 | J6: 売上高比 | K6: 帳簿価額 | L6: 売上高比
A7: IMに貼るときは非表示→ | B7: 売上 | C7: =PL!C11 -> 316755490 | D7: - | E7: =PL!E11 -> 443868051 | F7: - | G7: =PL!G11 -> 422474507 | H7: - | I7: =PL!I11 -> 0 | J7: - | K7: =PL!K11 -> 0 | L7: -
D8: =IF(C8=0,"",C8/C$7) | F8: =IF(E8=0,"",E8/E$7) | H8: =IF(G8=0,"",G8/G$7) | J8: =IF(I8=0,"",I8/I$7) | L8: =IF(K8=0,"",K8/K$7)
D9: =IF(C9=0,"",C9/C$7) | F9: =IF(E9=0,"",E9/E$7) | H9: =IF(G9=0,"",G9/G$7) | J9: =IF(I9=0,"",I9/I$7) | L9: =IF(K9=0,"",K9/K$7)
D10: =IF(C10=0,"",C10/C$7) | F10: =IF(E10=0,"",E10/E$7) | H10: =IF(G10=0,"",G10/G$7) | J10: =IF(I10=0,"",I10/I$7) | L10: =IF(K10=0,"",K10/K$7)
D11: =IF(C11=0,"",C11/C$7) | F11: =IF(E11=0,"",E11/E$7) | H11: =IF(G11=0,"",G11/G$7) | J11: =IF(I11=0,"",I11/I$7) | L11: =IF(K11=0,"",K11/K$7)
D12: =IF(C12=0,"",C12/C$7) | F12: =IF(E12=0,"",E12/E$7) | H12: =IF(G12=0,"",G12/G$7) | J12: =IF(I12=0,"",I12/I$7) | L12: =IF(K12=0,"",K12/K$7)
D13: =IF(C13=0,"",C13/C$7) | F13: =IF(E13=0,"",E13/E$7) | H13: =IF(G13=0,"",G13/G$7) | J13: =IF(I13=0,"",I13/I$7) | L13: =IF(K13=0,"",K13/K$7)
B14: 材料費 | C14: =SUM(C8:C13) -> 0 | D14: =IF(C14=0,"",C14/C$7) | E14: =SUM(E8:E13) -> 0 | F14: =IF(E14=0,"",E14/E$7) | G14: =SUM(G8:G13) -> 0 | H14: =IF(G14=0,"",G14/G$7) | I14: =SUM(I8:I13) -> 0 | J14: =IF(I14=0,"",I14/I$7) | K14: =SUM(K8:K13) -> 0 | L14: =IF(K14=0,"",K14/K$7)
D15: =IF(C15=0,"",C15/C$7) | F15: =IF(E15=0,"",E15/E$7) | H15: =IF(G15=0,"",G15/G$7) | J15: =IF(I15=0,"",I15/I$7) | L15: =IF(K15=0,"",K15/K$7)
D18: =IF(C18=0,"",C18/C$7) | F18: =IF(E18=0,"",E18/E$7) | H18: =IF(G18=0,"",G18/G$7) | J18: =IF(I18=0,"",I18/I$7) | L18: =IF(K18=0,"",K18/K$7)
D19: =IF(C19=0,"",C19/C$7) | F19: =IF(E19=0,"",E19/E$7) | H19: =IF(G19=0,"",G19/G$7) | J19: =IF(I19=0,"",I19/I$7) | L19: =IF(K19=0,"",K19/K$7)
D20: =IF(C20=0,"",C20/C$7) | F20: =IF(E20=0,"",E20/E$7) | H20: =IF(G20=0,"",G20/G$7) | J20: =IF(I20=0,"",I20/I$7) | L20: =IF(K20=0,"",K20/K$7)
D21: =IF(C21=0,"",C21/C$7) | F21: =IF(E21=0,"",E21/E$7) | H21: =IF(G21=0,"",G21/G$7) | J21: =IF(I21=0,"",I21/I$7) | L21: =IF(K21=0,"",K21/K$7)
D22: =IF(C22=0,"",C22/C$7) | F22: =IF(E22=0,"",E22/E$7) | H22: =IF(G22=0,"",G22/G$7) | J22: =IF(I22=0,"",I22/I$7) | L22: =IF(K22=0,"",K22/K$7)
B23: 労務費 | C23: =SUM(C15:C22) -> 0 | D23: =IF(C23=0,"",C23/C$7) | E23: =SUM(E15:E22) -> 0 | F23: =IF(E23=0,"",E23/E$7) | G23: =SUM(G15:G22) -> 0 | H23: =IF(G23=0,"",G23/G$7) | I23: =SUM(I15:I22) -> 0 | J23: =IF(I23=0,"",I23/I$7) | K23: =SUM(K15:K22) -> 0 | L23: =IF(K23=0,"",K23/K$7)
D24: =IF(C24=0,"",C24/C$7) | F24: =IF(E24=0,"",E24/E$7) | H24: =IF(G24=0,"",G24/G$7) | J24: =IF(I24=0,"",I24/I$7) | L24: =IF(K24=0,"",K24/K$7)
D28: =IF(C28=0,"",C28/C$7) | F28: =IF(E28=0,"",E28/E$7) | H28: =IF(G28=0,"",G28/G$7) | J28: =IF(I28=0,"",I28/I$7) | L28: =IF(K28=0,"",K28/K$7)
D29: =IF(C29=0,"",C29/C$7) | F29: =IF(E29=0,"",E29/E$7) | H29: =IF(G29=0,"",G29/G$7) | J29: =IF(I29=0,"",I29/I$7) | L29: =IF(K29=0,"",K29/K$7)
D30: =IF(C30=0,"",C30/C$7) | F30: =IF(E30=0,"",E30/E$7) | H30: =IF(G30=0,"",G30/G$7) | J30: =IF(I30=0,"",I30/I$7) | L30: =IF(K30=0,"",K30/K$7)
D31: =IF(C31=0,"",C31/C$7) | F31: =IF(E31=0,"",E31/E$7) | H31: =IF(G31=0,"",G31/G$7) | J31: =IF(I31=0,"",I31/I$7) | L31: =IF(K31=0,"",K31/K$7)
D32: =IF(C32=0,"",C32/C$7) | F32: =IF(E32=0,"",E32/E$7) | H32: =IF(G32=0,"",G32/G$7) | J32: =IF(I32=0,"",I32/I$7) | L32: =IF(K32=0,"",K32/K$7)
B33: 外注加工費 | C33: =SUM(C24:C32) -> 0 | D33: =IF(C33=0,"",C33/C$7) | E33: =SUM(E24:E32) -> 0 | F33: =IF(E33=0,"",E33/E$7) | G33: =SUM(G24:G32) -> 0 | H33: =IF(G33=0,"",G33/G$7) | I33: =SUM(I24:I32) -> 0 | J33: =IF(I33=0,"",I33/I$7) | K33: =SUM(K24:K32) -> 0 | L33: =IF(K33=0,"",K33/K$7)
D34: =IF(C34=0,"",C34/C$7) | F34: =IF(E34=0,"",E34/E$7) | H34: =IF(G34=0,"",G34/G$7) | J34: =IF(I34=0,"",I34/I$7) | L34: =IF(K34=0,"",K34/K$7)
D35: =IF(C35=0,"",C35/C$7) | F35: =IF(E35=0,"",E35/E$7) | H35: =IF(G35=0,"",G35/G$7) | J35: =IF(I35=0,"",I35/I$7) | L35: =IF(K35=0,"",K35/K$7)
D36: =IF(C36=0,"",C36/C$7) | F36: =IF(E36=0,"",E36/E$7) | H36: =IF(G36=0,"",G36/G$7) | J36: =IF(I36=0,"",I36/I$7) | L36: =IF(K36=0,"",K36/K$7)
D39: =IF(C39=0,"",C39/C$7) | F39: =IF(E39=0,"",E39/E$7) | H39: =IF(G39=0,"",G39/G$7) | J39: =IF(I39=0,"",I39/I$7) | L39: =IF(K39=0,"",K39/K$7)
D40: =IF(C40=0,"",C40/C$7) | F40: =IF(E40=0,"",E40/E$7) | H40: =IF(G40=0,"",G40/G$7) | J40: =IF(I40=0,"",I40/I$7) | L40: =IF(K40=0,"",K40/K$7)
D41: =IF(C41=0,"",C41/C$7) | F41: =IF(E41=0,"",E41/E$7) | H41: =IF(G41=0,"",G41/G$7) | J41: =IF(I41=0,"",I41/I$7) | L41: =IF(K41=0,"",K41/K$7)
D42: =IF(C42=0,"",C42/C$7) | F42: =IF(E42=0,"",E42/E$7) | H42: =IF(G42=0,"",G42/G$7) | J42: =IF(I42=0,"",I42/I$7) | L42: =IF(K42=0,"",K42/K$7)
D43: =IF(C43=0,"",C43/C$7) | F43: =IF(E43=0,"",E43/E$7) | H43: =IF(G43=0,"",G43/G$7) | J43: =IF(I43=0,"",I43/I$7) | L43: =IF(K43=0,"",K43/K$7)
D44: =IF(C44=0,"",C44/C$7) | F44: =IF(E44=0,"",E44/E$7) | H44: =IF(G44=0,"",G44/G$7) | J44: =IF(I44=0,"",I44/I$7) | L44: =IF(K44=0,"",K44/K$7)
D45: =IF(C45=0,"",C45/C$7) | F45: =IF(E45=0,"",E45/E$7) | H45: =IF(G45=0,"",G45/G$7) | J45: =IF(I45=0,"",I45/I$7) | L45: =IF(K45=0,"",K45/K$7)
B46: 経費 | C46: =SUM(C34:C45) -> 0 | D46: =IF(C46=0,"",C46/C$7) | E46: =SUM(E34:E45) -> 0 | F46: =IF(E46=0,"",E46/E$7) | G46: =SUM(G34:G45) -> 0 | H46: =IF(G46=0,"",G46/G$7) | I46: =SUM(I34:I45) -> 0 | J46: =IF(I46=0,"",I46/I$7) | K46: =SUM(K34:K45) -> 0 | L46: =IF(K46=0,"",K46/K$7)
B47: 当期製造費用 | C47: =C14+C23+C33+C46 -> 0 | D47: =IF(C47=0,"",C47/C$7) | E47: =E14+E23+E33+E46 -> 0 | F47: =IF(E47=0,"",E47/E$7) | G47: =G14+G23+G33+G46 -> 0 | H47: =IF(G47=0,"",G47/G$7) | I47: =I14+I23+I33+I46 -> 0 | J47: =IF(I47=0,"",I47/I$7) | K47: =K14+K23+K33+K46 -> 0 | L47: =IF(K47=0,"",K47/K$7)
B48: 期首仕掛品棚卸高 | D48: =IF(C48=0,"",C48/C$7) | E48: =SUM(E36:E47) -> 0 | F48: =IF(E48=0,"",E48/E$7) | G48: =SUM(G36:G47) -> 0 | H48: =IF(G48=0,"",G48/G$7) | I48: =SUM(I36:I47) -> 0 | J48: =IF(I48=0,"",I48/I$7) | K48: =SUM(K36:K47) -> 0 | L48: =IF(K48=0,"",K48/K$7)
B49: 合計 | C49: =SUM(C47:C48) -> 0 | D49: =IF(C49=0,"",C49/C$7) | E49: =SUM(E47:E48) -> 0 | F49: =IF(E49=0,"",E49/E$7) | G49: =SUM(G47:G48) -> 0 | H49: =IF(G49=0,"",G49/G$7) | I49: =SUM(I47:I48) -> 0 | J49: =IF(I49=0,"",I49/I$7) | K49: =SUM(K47:K48) -> 0 | L49: =IF(K49=0,"",K49/K$7)
B50: 期末仕掛品棚卸高 | D50: =IF(C50=0,"",C50/C$7) | E50: =SUM(E40:E49) -> 0 | F50: =IF(E50=0,"",E50/E$7) | G50: =SUM(G40:G49) -> 0 | H50: =IF(G50=0,"",G50/G$7) | I50: =SUM(I40:I49) -> 0 | J50: =IF(I50=0,"",I50/I$7) | K50: =SUM(K40:K49) -> 0 | L50: =IF(K50=0,"",K50/K$7)
...

Sheet SGA
H2: (単位：千円)
B3: 科目 | C3: ='BS(借方)'!C4 -> 24年1月期 | E3: ='BS(借方)'!D4 -> 25年1月期 | G3: ='BS(借方)'!E4 -> 26年1月期 | I3: ='BS(借方)'!F4 -> ●●年●月期 | K3: ='BS(借方)'!G4 -> ●●年●月 （●か月TB）
C4: 帳簿価額 | D4: 売上高比 | E4: 帳簿価額 | F4: 売上高比 | G4: 帳簿価額 | H4: 売上高比 | I4: 帳簿価額 | J4: 売上高比 | K4: 帳簿価額 | L4: 売上高比
B5: 売上 | C5: =PL!C11 -> 316755490 | D5: - | E5: =PL!E11 -> 443868051 | F5: - | G5: =PL!G11 -> 422474507 | H5: - | I5: =PL!I11 -> 0 | J5: - | K5: =PL!K11 -> 0 | L5: - | M5: ←IMに貼るときは非表示
B6: 役員報酬 | C6: 1104000 | D6: =IFERROR(C6/$C$5,"") -> 0.0034853382 | E6: 1104000 | F6: =IFERROR(E6/$E$5,"") -> 0.0024872256 | G6: 4094000 | H6: =IFERROR(G6/$G$5,"") -> 0.0096905255 | J6: =IFERROR(I6/$I$5,"") | L6: =IFERROR(K6/$K$5,"")
B7: 役員賞与 | C7: 18000000 | D7: =IFERROR(C7/$C$5,"") -> 0.056826166 | E7: 20000000 | F7: =IFERROR(E7/$E$5,"") -> 0.045058436 | G7: 20000000 | H7: =IFERROR(G7/$G$5,"") -> 0.047340135 | J7: =IFERROR(I7/$I$5,"") | L7: =IFERROR(K7/$K$5,"")
B8: 給料手当 | C8: 33649484 | D8: =IFERROR(C8/$C$5,"") -> 0.10623173 | E8: 29811105 | F8: =IFERROR(E8/$E$5,"") -> 0.067162088 | G8: 27938525 | H8: =IFERROR(G8/$G$5,"") -> 0.066130677 | J8: =IFERROR(I8/$I$5,"") | L8: =IFERROR(K8/$K$5,"")
B9: 雑給 | C9: 2538750 | D9: =IFERROR(C9/$C$5,"") -> 0.0080148571 | E9: 6544740 | F9: =IFERROR(E9/$E$5,"") -> 0.014744787 | G9: 299000 | H9: =IFERROR(G9/$G$5,"") -> 0.00070773501 | J9: =IFERROR(I9/$I$5,"") | L9: =IFERROR(K9/$K$5,"")
B10: 賞与 | C10: 4064600 | D10: =IFERROR(C10/$C$5,"") -> 0.01283198 | F10: =IFERROR(E10/$E$5,"") -> 0 | G10: 6079177 | H10: =IFERROR(G10/$G$5,"") -> 0.014389453 | J10: =IFERROR(I10/$I$5,"") | L10: =IFERROR(K10/$K$5,"")
B11: 法定福利費 | C11: 6407318 | D11: =IFERROR(C11/$C$5,"") -> 0.020227962 | E11: 6394777 | F11: =IFERROR(E11/$E$5,"") -> 0.014406932 | G11: 6366731 | H11: =IFERROR(G11/$G$5,"") -> 0.015070095 | J11: =IFERROR(I11/$I$5,"") | L11: =IFERROR(K11/$K$5,"")
B12: 福利厚生費 | C12: 1932474 | D12: =IFERROR(C12/$C$5,"") -> 0.0061008382 | E12: 422087 | F12: =IFERROR(E12/$E$5,"") -> 0.000950929 | G12: 705804 | H12: =IFERROR(G12/$G$5,"") -> 0.0016706428 | J12: =IFERROR(I12/$I$5,"") | L12: =IFERROR(K12/$K$5,"")
B13: 採用教育費 | C13: 280000 | D13: =IFERROR(C13/$C$5,"") -> 0.00088396258 | E13: 1480000 | F13: =IFERROR(E13/$E$5,"") -> 0.0033343242 | H13: =IFERROR(G13/$G$5,"") -> 0 | J13: =IFERROR(I13/$I$5,"") | L13: =IFERROR(K13/$K$5,"")
B14: 荷造運賃 | C14: 9235586 | D14: =IFERROR(C14/$C$5,"") -> 0.02915683 | E14: 13487346 | F14: =IFERROR(E14/$E$5,"") -> 0.030385936 | G14: 7104880 | H14: =IFERROR(G14/$G$5,"") -> 0.016817299 | J14: =IFERROR(I14/$I$5,"") | L14: =IFERROR(K14/$K$5,"")
B15: 広告宣伝費 | C15: 152187 | D15: =IFERROR(C15/$C$5,"") -> 0.00048045576 | E15: 142619 | F15: =IFERROR(E15/$E$5,"") -> 0.00032130945 | G15: 841073 | H15: =IFERROR(G15/$G$5,"") -> 0.0019908254 | J15: =IFERROR(I15/$I$5,"") | L15: =IFERROR(K15/$K$5,"")
B16: 接待交際費 | C16: 1440144 | D16: =IFERROR(C16/$C$5,"") -> 0.0045465479 | E16: 1738203 | F16: =IFERROR(E16/$E$5,"") -> 0.0039160354 | G16: 2336230 | H16: =IFERROR(G16/$G$5,"") -> 0.0055298721 | J16: =IFERROR(I16/$I$5,"") | L16: =IFERROR(K16/$K$5,"")
B17: 会議費 | C17: 211518 | D17: =IFERROR(C17/$C$5,"") -> 0.00066776427 | E17: 214892 | F17: =IFERROR(E17/$E$5,"") -> 0.00048413487 | G17: 284369 | H17: =IFERROR(G17/$G$5,"") -> 0.00067310334 | J17: =IFERROR(I17/$I$5,"") | L17: =IFERROR(K17/$K$5,"")
B18: 旅費交通費 | C18: 645511 | D18: =IFERROR(C18/$C$5,"") -> 0.0020378842 | E18: 2129949 | F18: =IFERROR(E18/$E$5,"") -> 0.0047986085 | G18: 1018914 | H18: =IFERROR(G18/$G$5,"") -> 0.0024117763 | J18: =IFERROR(I18/$I$5,"") | L18: =IFERROR(K18/$K$5,"")
B19: 通信費 | C19: 1416425 | D19: =IFERROR(C19/$C$5,"") -> 0.0044716668 | E19: 1506325 | F19: =IFERROR(E19/$E$5,"") -> 0.0033936324 | G19: 1506831 | H19: =IFERROR(G19/$G$5,"") -> 0.0035666791 | J19: =IFERROR(I19/$I$5,"") | L19: =IFERROR(K19/$K$5,"")
B20: 販売促進費 | C20: 65128 | D20: =IFERROR(C20/$C$5,"") -> 0.0002056097 | F20: =IFERROR(E20/$E$5,"") -> 0 | H20: =IFERROR(G20/$G$5,"") -> 0 | J20: =IFERROR(I20/$I$5,"") | L20: =IFERROR(K20/$K$5,"")
B21: 事務用消耗品費 | C21: 1145535 | D21: =IFERROR(C21/$C$5,"") -> 0.0036164645 | E21: 1700793 | F21: =IFERROR(E21/$E$5,"") -> 0.0038317536 | G21: 1195194 | H21: =IFERROR(G21/$G$5,"") -> 0.0028290322 | J21: =IFERROR(I21/$I$5,"") | L21: =IFERROR(K21/$K$5,"")
B22: 修繕費 | C22: 44900 | D22: =IFERROR(C22/$C$5,"") -> 0.00014174971 | E22: 190064 | F22: =IFERROR(E22/$E$5,"") -> 0.00042819933 | H22: =IFERROR(G22/$G$5,"") -> 0 | J22: =IFERROR(I22/$I$5,"") | L22: =IFERROR(K22/$K$5,"")
B23: 水道光熱費 | C23: 394299 | D23: =IFERROR(C23/$C$5,"") -> 0.0012448056 | E23: 403021 | F23: =IFERROR(E23/$E$5,"") -> 0.00090797479 | G23: 412583 | H23: =IFERROR(G23/$G$5,"") -> 0.00097658674 | J23: =IFERROR(I23/$I$5,"") | L23: =IFERROR(K23/$K$5,"")
B24: 諸会費 | C24: 57450 | D24: =IFERROR(C24/$C$5,"") -> 0.00018137018 | E24: 36000 | F24: =IFERROR(E24/$E$5,"") -> 8.1105184e-05 | G24: 48000 | H24: =IFERROR(G24/$G$5,"") -> 0.00011361632 | J24: =IFERROR(I24/$I$5,"") | L24: =IFERROR(K24/$K$5,"")
B25: 支払手数料 | C25: 3167934 | D25: =IFERROR(C25/$C$5,"") -> 0.010001197 | E25: 3674031 | F25: =IFERROR(E25/$E$5,"") -> 0.0082773045 | G25: 1179313 | H25: =IFERROR(G25/$G$5,"") -> 0.0027914418 | J25: =IFERROR(I25/$I$5,"") | L25: =IFERROR(K25/$K$5,"")
B26: 車両費 | C26: 650214 | D26: =IFERROR(C26/$C$5,"") -> 0.0020527316 | E26: 478916 | F26: =IFERROR(E26/$E$5,"") -> 0.0010789603 | G26: 716759 | H26: =IFERROR(G26/$G$5,"") -> 0.0016965734 | J26: =IFERROR(I26/$I$5,"") | L26: =IFERROR(K26/$K$5,"")
B27: 地代家賃 | C27: 5430000 | D27: =IFERROR(C27/$C$5,"") -> 0.01714256 | E27: 5430000 | F27: =IFERROR(E27/$E$5,"") -> 0.012233365 | G27: 5500911 | H27: =IFERROR(G27/$G$5,"") -> 0.013020693 | J27: =IFERROR(I27/$I$5,"") | L27: =IFERROR(K27/$K$5,"")
B28: リース料 | C28: 131200 | D28: =IFERROR(C28/$C$5,"") -> 0.00041419961 | E28: 160920 | F28: =IFERROR(E28/$E$5,"") -> 0.00036254017 | G28: 147510 | H28: =IFERROR(G28/$G$5,"") -> 0.00034915716 | J28: =IFERROR(I28/$I$5,"") | L28: =IFERROR(K28/$K$5,"")
B29: 保険料 | C29: 709690 | D29: =IFERROR(C29/$C$5,"") -> 0.0022404979 | E29: 1090090 | F29: =IFERROR(E29/$E$5,"") -> 0.0024558875 | G29: 735330 | H29: =IFERROR(G29/$G$5,"") -> 0.0017405311 | J29: =IFERROR(I29/$I$5,"") | L29: =IFERROR(K29/$K$5,"")
B30: 租税公課 | C30: 234840 | D30: =IFERROR(C30/$C$5,"") -> 0.00074139204 | E30: 175360 | F30: =IFERROR(E30/$E$5,"") -> 0.00039507236 | G30: 269084 | H30: =IFERROR(G30/$G$5,"") -> 0.00063692364 | J30: =IFERROR(I30/$I$5,"") | L30: =IFERROR(K30/$K$5,"")
B31: 支払報酬料 | C31: 755000 | D31: =IFERROR(C31/$C$5,"") -> 0.002383542 | E31: 755000 | F31: =IFERROR(E31/$E$5,"") -> 0.0017009559 | G31: 762000 | H31: =IFERROR(G31/$G$5,"") -> 0.0018036591 | J31: =IFERROR(I31/$I$5,"") | L31: =IFERROR(K31/$K$5,"")
B32: 寄付金 | C32: 50000 | D32: =IFERROR(C32/$C$5,"") -> 0.00015785046 | E32: 200000 | F32: =IFERROR(E32/$E$5,"") -> 0.00045058436 | G32: 50000 | H32: =IFERROR(G32/$G$5,"") -> 0.00011835034 | J32: =IFERROR(I32/$I$5,"") | L32: =IFERROR(K32/$K$5,"")
B33: 研究開発費 | C33: 174503 | D33: =IFERROR(C33/$C$5,"") -> 0.00055090758 | E33: 574824 | F33: =IFERROR(E33/$E$5,"") -> 0.0012950335 | G33: 170367 | H33: =IFERROR(G33/$G$5,"") -> 0.00040325984 | J33: =IFERROR(I33/$I$5,"") | L33: =IFERROR(K33/$K$5,"")
B34: 減価償却費 | C34: 881300 | D34: =IFERROR(C34/$C$5,"") -> 0.0027822722 | E34: 644524 | F34: =IFERROR(E34/$E$5,"") -> 0.0014520622 | G34: 1182673 | H34: =IFERROR(G34/$G$5,"") -> 0.0027993949 | J34: =IFERROR(I34/$I$5,"") | L34: =IFERROR(K34/$K$5,"")
B35: 貸倒引当金繰入額 | C35: 803000 | D35: =IFERROR(C35/$C$5,"") -> 0.0025350784 | E35: 246000 | F35: =IFERROR(E35/$E$5,"") -> 0.00055421876 | G35: 201000 | H35: =IFERROR(G35/$G$5,"") -> 0.00047576835 | J35: =IFERROR(I35/$I$5,"") | L35: =IFERROR(K35/$K$5,"")
B36: 通勤 | C36: 1622989 | D36: =IFERROR(C36/$C$5,"") -> 0.0051237912 | F36: =IFERROR(E36/$E$5,"") -> 0 | G36: 1143204 | H36: =IFERROR(G36/$G$5,"") -> 0.0027059716 | J36: =IFERROR(I36/$I$5,"") | L36: =IFERROR(K36/$K$5,"")
D37: =IFERROR(C37/$C$5,"") -> 0 | F37: =IFERROR(E37/$E$5,"") -> 0 | H37: =IFERROR(G37/$G$5,"") -> 0 | J37: =IFERROR(I37/$I$5,"") | L37: =IFERROR(K37/$K$5,"")
D38: =IFERROR(C38/$C$5,"") -> 0 | F38: =IFERROR(E38/$E$5,"") -> 0 | H38: =IFERROR(G38/$G$5,"") -> 0 | J38: =IFERROR(I38/$I$5,"") | L38: =IFERROR(K38/$K$5,"")
D39: =IFERROR(C39/$C$5,"") -> 0 | F39: =IFERROR(E39/$E$5,"") -> 0 | H39: =IFERROR(G39/$G$5,"") -> 0 | J39: =IFERROR(I39/$I$5,"") | L39: =IFERROR(K39/$K$5,"")
B40: 販売費および一般管理費合計 | C40: =SUM(C6:C39) -> 97395979 | D40: =IFERROR(C40/C5,"") -> 0.30748 | E40: =SUM(E6:E39) -> 100735586 | F40: =IFERROR(E40/E5,"") -> 0.2269494 | G40: =SUM(G6:G39) -> 92289462 | H40: =IFERROR(G40/G5,"") -> 0.21844978 | I40: =SUM(I6:I39) -> 0 | J40: =IFERROR(I40/I5,"") | K40: =SUM(K6:K39) -> 0 | L40: =IFERROR(K40/K5,"")

Sheet VR→ 

Sheet 株式価値 
A1: 作業不要（自動作成）
F2: (単位：千円)
C3: min | D3: 差（グラフ作成用） | E3: max
B4: インカム | C4: 0 | D4: 0 | E4: 0 | F4: 100 | I4: ｚ
B5: マーケット | C5: ='EV EBITDAマルチプル'!K7 -> 1.1220229e+08 | D5: =E5-C5 -> 71189199 | E5: ='EV EBITDAマルチプル'!M7 -> 1.8339149e+08 | F5: 0
B6: コスト | C6: =年買法!K6 -> 33185615 | D6: =E6-C6 -> 51013674 | E6: =年買法!M6 -> 84199289 | F6: 0

Sheet 売掛・棚卸
E2: (単位：千円)
A3: 売掛金 | B3: 相手先 | C3: 帳簿価額 | D3: 評価差額 | E3: 評価額 | F3: 調整事由
B4: （相手先別内訳 未受領） | C4: 20153150 | D4: 0 | F4: 売掛金年齢表・補助残高一覧表が未受領のため個別の回収可能性判断は未実施。帳簿価額により評価する（要確認）。なお貸倒引当金201千円は全額戻入。
B8: 合計 | C8: =SUM(C4:C7) -> 20153150 | D8: =SUM(D4:D7) -> 0 | E8: =C8+D8 -> 20153150
E12: (単位：千円)
A13: 商品在庫 | B13: 相手先 | C13: 帳簿価額 | D13: 評価差額 | E13: 評価額 | F13: 調整事由
B14: 商品 | C14: 204834 | D14: 0 | F14: 令和8年1月期末残高は205千円と僅少。棚卸資産廃棄損が3期連続で計上されており期末在庫は整理済と判断し、帳簿価額により評価する。
B15: 証紙 | C15: 24020 | D15: 0 | F15: 僅少につき帳簿価額により評価する。
B18: 合計 | C18: =SUM(C14:C17) -> 228854 | D18: =SUM(D14:D17) -> 0 | E18: =C18+D18 -> 228854

Sheet 減価償却
E2: (単位：千円)
B3: 資産 | C3: 帳簿価額 | D3: 評価差額 | E3: 評価額 | F3: 調整事由
B4: 建物附属設備 | C4: 700993 | D4: 0 | E4: =SUM(C4,D4) -> 700993 | F4: 減価償却台帳（令和8年1月期）が画像PDFのため個別資産の償却過不足の検証は未実施。有形固定資産・無形固定資産の残高は合計3,169千円と僅少であり、帳簿価額により評価する（要確認）。
B5: 車両運搬具 | C5: 264868 | D5: 0 | E5: =SUM(C5,D5) -> 264868
B6: 工具器具備品 | C6: 91059 | D6: 0 | E6: =SUM(C6,D6) -> 91059
B7: ソフトウェア | C7: 2112001 | D7: 0 | E7: =SUM(C7,D7) -> 2112001
B8: 合計 | C8: =SUM(C4:C7) -> 3168921 | D8: =SUM(D4:D7) -> 0 | E8: =C8+D8 -> 3168921

Sheet 土地
F2: (単位：千円)
B3: 内容・所在地 | C3: 地積(㎡) | D3: 帳簿価額 | E3: 評価差額 | F3: 時価評価額 | G3: 調整事由
B4: 該当なし | G4: 対象会社は土地・建物等の不動産を保有していない（令和8年1月期BSに計上なし、本社は賃借）。したがって不動産の時価評価は実施していない。
B8: 合計 | C8: =SUM(C4:C7) -> 0 | D8: =SUM(D4:D7) -> 0 | E8: =SUM(E4:E7) -> 0 | F8: =SUM(F4:F7) -> 0

Sheet 保険
E2: (単位：千円)
B3: 保険商品 | C3: 帳簿価額 | D3: 評価差額 | E3: 評価額 | F3: 調整事由
B4: 保険積立金（保険会社・商品名 未確認） | C4: 43326766 | D4: =E4-C4 -> 0 | E4: 43326766 | F4: 解約返戻金額の資料が未受領のため帳簿価額により評価する。解約返戻金額の判明後、時価へ更新予定（要確認）。3期連続で特別保険料を計上しており、簿外の返戻金相当額が存在する可能性がある。
B8: 合計 | C8: =SUM(C4:C7) -> 43326766 | D8: =SUM(D4:D7) -> 0 | E8: =C8+D8 -> 43326766

Sheet 有価証券
F2: (単位：千円)
B3: 銘柄 | C3: 数量 | D3: 帳簿価額 | E3: 評価差額 | F3: 評価額 | G3: 調整事由
B4: 投資有価証券（銘柄別内訳 未受領） | C4: - | D4: 275896334 | E4: =F4-D4 -> 0 | F4: 275896334 | G4: 有価証券内訳明細書・証券会社残高証明書が未受領のため帳簿価額により評価する。評価実施日の時価判明後に更新予定（要確認）。総資産の約50%を占める重要科目。
E7: =F7-D7 -> 0
E8: =F8-D8 -> 0
B9: 合計 | C9: - | D9: =SUM(D4:D8) -> 275896334 | E9: =SUM(E4:E8) -> 0 | F9: =D9+E9 -> 275896334

Sheet 未払人件費・賞与
D2: (単位：千円) | E2: (単位：千円) | F2: (単位：千円)
B3: 給与（令和8年1月期） | C3: 未払日数 | D3: 未払給与引当額 | E3: 概算社会保険料 | F3: 未払給与引当額
C4: － | D4: =B4*11/31 -> 0 | E4: =D4*0.15 -> 0 | F4: =D4+E4 -> 0
B6: 就業規則・賃金規程（給与の締日・支払日）が未受領のため、未払給与の引当不足額は算定不能。要確認事項として整理し、本評価では未計上とする。
E7: (単位：千円)
B8: 賞与（令和8年1月期） | C8: 支給対象月数 | D8: 経過月数 | E8: 引当額 | F8: 概算社会保険料 | G8: 社保考慮後引当不足
C9: － | D9: － | E9: =B9*4/6 -> 0 | F9: =E9*0.15 -> 0 | G9: =E9+F9 -> 0
B11: 決算期末（1月31日）時点で夏季賞与の支給対象期間は経過しておらず、冬季賞与は令和7年12月に支給済（給与台帳により確認）。したがって賞与引当不足は生じないものと判断し、追加引当は行わない。

Sheet 退職金
J2: (単位：千円)
B3: № | C3: 氏名 | D3: 勤続年数(年) | E3: 基本給 | F3: 支給倍率 | G3: 退職理由率 | H3: 要支給額 | I3: 中退共積立額 | J3: 引当不足
C10: 合計 | H10: =SUM(H6:H9) -> 0 | I10: =SUM(I6:I9) -> 0 | J10: =H10+I10 -> 0
C12: 退職金規程が未受領であり、中小企業退職金共済等の外部積立の有無も未確認のため、退職給付引当不足額は算定不能。要確認事項として整理し、本評価では未計上とする（従業員7名・平均勤続年数約5年）。

Sheet 税効果
E2: (単位：千円)
B3: 修正科目 | C3: 適用判定 | D3: 修正額 | E3: 繰延税金資産/負債 | F3: 備考
B4: 貸倒引当金 | C4: 〇 | D4: 201000 | E4: =-D4*0.34 -> -68340
B5: 棚卸資産 | C5: 〇 | E5: =-D5*0.34 -> 0 | F5: 評価差額なし
B6: 減価償却資産 | C6: 〇 | E6: =-D6*0.34 -> 0 | F6: 償却過不足未検証のため未評価（要確認）
B7: 投資有価証券 | C7: 〇 | E7: - | F7: 時価資料未受領のため簿価評価（要確認）
B8: 保険積立金 | C8: 〇 | E8: - | F8: 解約返戻金資料未受領のため簿価評価（要確認）
B9: 差入保証金・敷金 | C9: 〇 | E9: =-D9*0.34 -> 0 | F9: 賃貸借契約書の返還条件未確認のため簿価評価（要確認）
B10: 未払給与 | C10: 〇 | E10: =-D10*0.34 -> 0 | F10: 賃金規程未受領のため未計上（要確認）
B11: 賞与引当金 | C11: 〇 | E11: =-D11*0.34 -> 0 | F11: 期末時点で引当不足なし
B12: 退職給付引当金 | C12: 〇 | E12: =-D12*0.34 -> 0 | F12: 退職金規程未受領のため未計上（要確認）
E13: =-D13*0.34 -> 0
E14: =-D14*0.34 -> 0
E15: =-D15*0.34 -> 0
E16: =-D16*0.34 -> 0
E17: =-D17*0.34 -> 0
B18: 合計 | C18: - | D18: =SUM(D4:D17) -> 201000 | E18: =SUM(E4:E17) -> -68340 | F18: 修正額は貸倒引当金の戻入201千円のみであり重要性が乏しいことから、修正貸借対照表上は繰延税金資産／負債を認識せず、「年買法」シートの時価純資産算定において実効税率34%で一括して考慮している。

Sheet ネットキャッシュ
F2: (単位：千円)
B3: キャッシュライクアイテム | C3: 金額 | E3: デットライクアイテム | F3: 金額
B4: 現金及び預金 | C4: ='修正BS(借方)'!E6 -> 193226490 | E4: 一年以内返済長期借入金 | F4: ='修正BS(貸方) '!E11 -> 41828000
B5: 投資有価証券 | C5: ='修正BS(借方)'!E47 -> 0 | E5: 長期借入金 | F5: ='修正BS(貸方) '!E19 -> 145980000
B6: 保険積立金 | C6: ='修正BS(借方)'!E52 -> 0
B13: 合計 | C13: =SUM(C4:C12) -> 193226490 | E13: 合計 | F13: =SUM(F4:F12) -> 187808000
B15: ネットキャッシュ | C15: =C13-F13 -> 5418490

Sheet 修正BS(借方)
E2: (単位：千円)
B3: 資産の部
B4: 科目 | C4: ='BS(借方)'!E4 -> 26年1月期 | D4: 修正額 | E4: 修正後
B5: 【流動資産】 | C5: =SUM(C6:C19) -> 226144406 | D5: =SUM(D6:D19) -> -6369163 | E5: =C5+D5 -> 219775243
B6: 現金及び預金 | C6: 193226490 | E6: =C6+D6 -> 193226490
B7: 売掛金 | C7: 20153150 | E7: =C7+D7 -> 20153150
B8: 貸倒引当金 | C8: -201000 | D8: 201000 | E8: =C8+D8 -> 0
B9: 商品 | C9: 204834 | E9: =C9+D9 -> 204834
B10: 証紙 | C10: 24020 | E10: =C10+D10 -> 24020
B11: 前渡金 | C11: 12055237 | D11: -6570163 | E11: =C11+D11 -> 5485074
B12: 前払費用 | C12: 640475 | E12: =C12+D12 -> 640475
B13: 未収入金 | C13: 41200 | E13: =C13+D13 -> 41200
E14: =C14+D14 -> 0
E15: =C15+D15 -> 0
E16: =C16+D16 -> 0
E17: =C17+D17 -> 0
E18: =C18+D18 -> 0
E19: =C19+D19 -> 0
B20: 【固定資産】 | C20: =C21+C35+C46 -> 323863136 | D20: =D21+D35+D46 -> -319487968 | E20: =C20+D20 -> 4375168
B21: ［有形固定資産］ | C21: =SUM(C22:C34) -> 1056920 | D21: =SUM(D22:D34) -> -264868 | E21: =C21+D21 -> 792052
B22: 建物附属設備 | C22: 700993 | E22: =C22+D22 -> 700993
B23: 車両運搬具 | C23: 264868 | D23: =-C23 -> -264868 | E23: =C23+D23 -> 0
B24: 工具器具備品 | C24: 91059 | E24: =C24+D24 -> 91059
E25: =C25+D25 -> 0
E26: =C26+D26 -> 0
E27: =C27+D27 -> 0
E28: =C28+D28 -> 0
E29: =C29+D29 -> 0
E30: =C30+D30 -> 0
E31: =C31+D31 -> 0
E32: =C32+D32 -> 0
E33: =C33+D33 -> 0
E34: =C34+D34 -> 0
B35: ［無形固定資産］ | C35: =SUM(C36:C45) -> 2112001 | D35: =SUM(D36:D45) -> 0 | E35: =C35+D35 -> 2112001
B36: ソフトウェア | C36: 2112001 | E36: =C36+D36 -> 2112001
E37: =C37+D37 -> 0
E38: =C38+D38 -> 0
E39: =C39+D39 -> 0
E40: =C40+D40 -> 0
E41: =C41+D41 -> 0
...

Sheet 修正BS(貸方) 
E2: (単位：千円)
B3: 負債の部
B4: 科目 | C4: ='BS (貸方)'!E4 -> 26年1月期 | D4: 修正額 | E4: 修正後
B5: 【流動負債】 | C5: =SUM(C6:C17) -> 70491633 | D5: =SUM(D6:D17) -> 0 | E5: =C5+D5 -> 70491633
B6: 買掛金 | C6: 9644516 | E6: =C6+D6 -> 9644516
B7: 未払金 | C7: 3947278 | E7: =C7+D7 -> 3947278
B8: 未払法人税等 | C8: 2929500 | E8: =C8+D8 -> 2929500
B9: 未払消費税等 | C9: 12017600 | E9: =C9+D9 -> 12017600
B10: 預り金 | C10: 124739 | E10: =C10+D10 -> 124739
B11: 一年以内返済長期借入金 | C11: 41828000 | E11: =C11+D11 -> 41828000
E12: =C12+D12 -> 0
E13: =C13+D13 -> 0
E14: =C14+D14 -> 0
E15: =C15+D15 -> 0
E16: =C16+D16 -> 0
E17: =C17+D17 -> 0
B18: 【固定負債】 | C18: =SUM(C19:C26) -> 145980000 | D18: =SUM(D19:D26) -> 0 | E18: =C18+D18 -> 145980000
B19: 長期借入金 | C19: 145980000 | E19: =C19+D19 -> 145980000
E20: =C20+D20 -> 0
E21: =C21+D21 -> 0
E22: =C22+D22 -> 0
E23: =C23+D23 -> 0
E24: =C24+D24 -> 0
E25: =C25+D25 -> 0
E26: =C26+D26 -> 0
B27: 【繰延税金負債】 | C27: 0 | D27: 0 | E27: =C27+D27 -> 0
B28: 負債合計 | C28: =C5+C18+C27 -> 216471633 | D28: =D5+D18+D27 -> 0 | E28: =C28+D28 -> 216471633
B34: 純資産の部
B35: 【資本金】 | C35: =SUM(C36:C38) -> 10000000 | D35: =SUM(D36:D38) -> 0 | E35: =C35+D35 -> 10000000
B36: 資本金 | C36: 10000000 | E36: =C36+D36 -> 10000000
E37: =C37+D37 -> 0
E38: =C38+D38 -> 0
B39: 【資本剰余金】 | C39: =SUM(C40:C42) -> 0 | D39: =SUM(D40:D42) -> 0 | E39: =C39+D39 -> 0
E40: =C40+D40 -> 0
E41: =C41+D41 -> 0
E42: =C42+D42 -> 0
B43: 【利益剰余金】 | C43: =SUM(C44:C47) -> 323535909 | D43: =SUM(D44:D47) -> 0 | E43: =C43+D43 -> 323535909
B44: 繰越利益剰余金 | C44: 323535909 | E44: =C44+D44 -> 323535909
E45: =C45+D45 -> 0
E46: =C46+D46 -> 0
...

Sheet 修正PL
K2: (単位：千円)
B3: 科目 | C3: ='BS(借方)'!C4 -> 24年1月期 | F3: ='BS(借方)'!D4 -> 25年1月期 | I3: ='BS(借方)'!E4 -> 26年1月期 | L3: ='BS(借方)'!F4 -> ●●年●月期 | O3: ='BS(借方)'!G4 -> ●●年●月 （●か月TB）
C4: 帳簿価額 | D4: 修正額 | E4: 修正後 | F4: 帳簿価額 | G4: 修正額 | H4: 修正後 | I4: 帳簿価額 | J4: 修正額 | K4: 修正後 | L4: 帳簿価額 | M4: 修正額 | N4: 修正後 | O4: 帳簿価額 | P4: 修正額 | Q4: 修正後
B5: 売上高 | C5: 301575965 | E5: =C5+D5 -> 301575965 | F5: 285379413 | H5: =F5+G5 -> 285379413 | I5: 387747182 | K5: =I5+J5 -> 387747182 | N5: =L5+M5 -> 0 | Q5: =O5+P5 -> 0
B6: 輸出売上 | C6: 15179525 | E6: =C6+D6 -> 15179525 | F6: 158488638 | H6: =F6+G6 -> 158488638 | I6: 34727325 | K6: =I6+J6 -> 34727325 | N6: =L6+M6 -> 0 | Q6: =O6+P6 -> 0
E7: =C7+D7 -> 0 | H7: =F7+G7 -> 0 | K7: =I7+J7 -> 0 | N7: =L7+M7 -> 0 | Q7: =O7+P7 -> 0
E8: =C8+D8 -> 0 | H8: =F8+G8 -> 0 | K8: =I8+J8 -> 0 | N8: =L8+M8 -> 0 | Q8: =O8+P8 -> 0
B9: 売上高 | C9: =SUM(C5:C8) -> 316755490 | D9: =SUM(D5:D8) -> 0 | E9: =C9+D9 -> 316755490 | F9: =SUM(F5:F8) -> 443868051 | G9: =SUM(G5:G8) -> 0 | H9: =F9+G9 -> 443868051 | I9: =SUM(I5:I8) -> 422474507 | J9: =SUM(J5:J8) -> 0 | K9: =I9+J9 -> 422474507 | L9: =SUM(L5:L8) -> 0 | M9: =SUM(M5:M8) -> 0 | N9: =L9+M9 -> 0 | O9: =SUM(O5:O8) -> 0 | P9: =SUM(P5:P8) -> 0 | Q9: =O9+P9 -> 0
B10: 期首商品棚卸高 | C10: 3024069 | E10: =C10+D10 -> 3024069 | F10: 1426042 | H10: =F10+G10 -> 1426042 | I10: 33344623 | K10: =I10+J10 -> 33344623 | N10: =L10+M10 -> 0 | Q10: =O10+P10 -> 0
B11: 当期商品仕入高 | C11: 172656708 | E11: =C11+D11 -> 172656708 | F11: 237257918 | H11: =F11+G11 -> 237257918 | I11: 225575333 | K11: =I11+J11 -> 225575333 | N11: =L11+M11 -> 0 | Q11: =O11+P11 -> 0
B12: （製）支払手数料 | C12: 26573925 | E12: =C12+D12 -> 26573925 | F12: 50722738 | H12: =F12+G12 -> 50722738 | I12: 21094265 | K12: =I12+J12 -> 21094265 | N12: =L12+M12 -> 0 | Q12: =O12+P12 -> 0
B13: （製）サンプル | C13: 6307077 | E13: =C13+D13 -> 6307077 | F13: 2327904 | H13: =F13+G13 -> 2327904 | I13: 2831360 | K13: =I13+J13 -> 2831360 | N13: =L13+M13 -> 0 | Q13: =O13+P13 -> 0
B14: 試作費 | C14: 4487974 | E14: =C14+D14 -> 4487974 | F14: 13796708 | H14: =F14+G14 -> 13796708 | I14: 3637077 | K14: =I14+J14 -> 3637077 | N14: =L14+M14 -> 0 | Q14: =O14+P14 -> 0
B15: （製）外注費 | C15: 8299304 | E15: =C15+D15 -> 8299304 | F15: 9972324 | H15: =F15+G15 -> 9972324 | I15: 5262263 | K15: =I15+J15 -> 5262263 | N15: =L15+M15 -> 0 | Q15: =O15+P15 -> 0
B16: 仕入値引高 | E16: =C16+D16 -> 0 | H16: =F16+G16 -> 0 | I16: -100 | K16: =I16+J16 -> -100 | N16: =L16+M16 -> 0 | Q16: =O16+P16 -> 0
B17: 他勘定振替高 | C17: -6722798 | D17: =-C17 -> 6722798 | E17: =C17+D17 -> 0 | F17: -17217311 | G17: =-F17 -> 17217311 | H17: =F17+G17 -> 0 | I17: -19844732 | J17: =-I17 -> 19844732 | K17: =I17+J17 -> 0 | N17: =L17+M17 -> 0 | Q17: =O17+P17 -> 0
B18: 期末商品棚卸高 | C18: -1426042 | E18: =C18+D18 -> -1426042 | F18: -33344623 | H18: =F18+G18 -> -33344623 | I18: -228854 | K18: =I18+J18 -> -228854 | N18: =L18+M18 -> 0 | Q18: =O18+P18 -> 0
B19: 売上原価 | C19: =SUM(C10:C18) -> 213200217 | D19: =SUM(D10:D18) -> 6722798 | E19: =C19+D19 -> 219923015 | F19: =SUM(F10:F18) -> 264941700 | G19: =SUM(G10:G18) -> 17217311 | H19: =F19+G19 -> 282159011 | I19: =SUM(I10:I18) -> 271671235 | J19: =SUM(J10:J18) -> 19844732 | K19: =I19+J19 -> 291515967 | L19: =SUM(L10:L18) -> 0 | M19: =SUM(M10:M18) -> 0 | N19: =L19+M19 -> 0 | O19: =SUM(O10:O18) -> 0 | P19: =SUM(P10:P18) -> 0 | Q19: =O19+P19 -> 0
B20: 売上総利益 | C20: =C9-C19 -> 103555273 | D20: =D9-D19 -> -6722798 | E20: =C20+D20 -> 96832475 | F20: =F9-F19 -> 178926351 | G20: =G9-G19 -> -17217311 | H20: =F20+G20 -> 161709040 | I20: =I9-I19 -> 150803272 | J20: =J9-J19 -> -19844732 | K20: =I20+J20 -> 130958540 | L20: =L9-L19 -> 0 | M20: =M9-M19 -> 0 | N20: =L20+M20 -> 0 | O20: =O9-O19 -> 0 | P20: =P9-P19 -> 0 | Q20: =O20+P20 -> 0
B21: 販売費及び一般管理費 | C21: =修正SGA!C39 -> 97395979 | D21: =修正SGA!D39 -> -5212706.5 | E21: =C21+D21 -> 92183272 | F21: =修正SGA!F39 -> 100735586 | G21: =修正SGA!G39 -> -5622703 | H21: =F21+G21 -> 95112883 | I21: =修正SGA!I39 -> 92289462 | J21: =修正SGA!J39 -> -6025730 | K21: =I21+J21 -> 86263732 | N21: =L21+M21 -> 0 | Q21: =O21+P21 -> 0
B22: 営業利益 | C22: =C20- C21 -> 6159294 | D22: =D20- D21 -> -1510091.5 | E22: =C22+D22 -> 4649202.5 | F22: =F20- F21 -> 78190765 | G22: =G20- G21 -> -11594608 | H22: =F22+G22 -> 66596157 | I22: =I20- I21 -> 58513810 | J22: =J20- J21 -> -13819002 | K22: =I22+J22 -> 44694808 | L22: =L20- L21 -> 0 | M22: =M20- M21 -> 0 | N22: =L22+M22 -> 0 | O22: =O20- O21 -> 0 | P22: =P20- P21 -> 0 | Q22: =O22+P22 -> 0
B23: 営業外収益 | C23: =SUM(C24:C29) -> 1358290 | D23: =SUM(D24:D29) -> -1358290 | E23: =C23+D23 -> 0 | F23: =SUM(F24:F29) -> 13984344 | G23: =SUM(G24:G29) -> -13984344 | H23: =F23+G23 -> 0 | I23: =SUM(I24:I29) -> 8626001 | J23: =SUM(J24:J29) -> -8626001 | K23: =I23+J23 -> 0 | L23: =SUM(L24:L29) -> 0 | M23: =SUM(M24:M29) -> 0 | N23: =L23+M23 -> 0 | O23: =SUM(O24:O29) -> 0 | P23: =SUM(P24:P29) -> 0 | Q23: =O23+P23 -> 0
B24: 受取利息 | C24: 101059 | D24: =-C24 -> -101059 | E24: =C24+D24 -> 0 | F24: 1035013 | G24: =-F24 -> -1035013 | H24: =F24+G24 -> 0 | I24: 326339 | J24: =-I24 -> -326339 | K24: =I24+J24 -> 0 | N24: =L24+M24 -> 0 | Q24: =O24+P24 -> 0
B25: 受取配当金 | C25: 712050 | D25: =-C25 -> -712050 | E25: =C25+D25 -> 0 | F25: 7151912 | G25: =-F25 -> -7151912 | H25: =F25+G25 -> 0 | I25: 7555640 | J25: =-I25 -> -7555640 | K25: =I25+J25 -> 0 | N25: =L25+M25 -> 0 | Q25: =O25+P25 -> 0
B26: 貸倒引当金戻入額 | C26: 534000 | D26: =-C26 -> -534000 | E26: =C26+D26 -> 0 | F26: 803000 | G26: =-F26 -> -803000 | H26: =F26+G26 -> 0 | I26: 246000 | J26: =-I26 -> -246000 | K26: =I26+J26 -> 0 | N26: =L26+M26 -> 0 | Q26: =O26+P26 -> 0
B27: 雑収入 | C27: 2197 | D27: =-C27 -> -2197 | E27: =C27+D27 -> 0 | F27: 2195483 | G27: =-F27 -> -2195483 | H27: =F27+G27 -> 0 | I27: 216735 | J27: =-I27 -> -216735 | K27: =I27+J27 -> 0 | N27: =L27+M27 -> 0 | Q27: =O27+P27 -> 0
B28: 仕入割引 | D28: =-C28 -> 0 | E28: =C28+D28 -> 0 | G28: =-F28 -> 0 | H28: =F28+G28 -> 0 | I28: 10455 | J28: =-I28 -> -10455 | K28: =I28+J28 -> 0 | N28: =L28+M28 -> 0 | Q28: =O28+P28 -> 0
B29: 為替差益 | C29: 8984 | D29: =-C29 -> -8984 | E29: =C29+D29 -> 0 | F29: 2798936 | G29: =-F29 -> -2798936 | H29: =F29+G29 -> 0 | I29: 270832 | J29: =-I29 -> -270832 | K29: =I29+J29 -> 0 | N29: =L29+M29 -> 0 | Q29: =O29+P29 -> 0
B30: 営業外費用 | C30: =SUM(C31:C35) -> 852015 | D30: =SUM(D31:D35) -> -852015 | E30: =C30+D30 -> 0 | F30: =SUM(F31:F35) -> 2246448 | G30: =SUM(G31:G35) -> -2246448 | H30: =F30+G30 -> 0 | I30: =SUM(I31:I35) -> 2196742 | J30: =SUM(J31:J35) -> -2196742 | K30: =I30+J30 -> 0 | L30: =SUM(L31:L35) -> 0 | M30: =SUM(M31:M35) -> 0 | N30: =L30+M30 -> 0 | O30: =SUM(O31:O35) -> 0 | P30: =SUM(P31:P35) -> 0 | Q30: =O30+P30 -> 0
B31: 支払利息 | C31: 852015 | D31: =-C31 -> -852015 | E31: =C31+D31 -> 0 | F31: 1716559 | G31: =-F31 -> -1716559 | H31: =F31+G31 -> 0 | I31: 2196742 | J31: =-I31 -> -2196742 | K31: =I31+J31 -> 0 | N31: =L31+M31 -> 0 | Q31: =O31+P31 -> 0
B32: 雑損失 | D32: =-C32 -> 0 | E32: =C32+D32 -> 0 | F32: 529889 | G32: =-F32 -> -529889 | H32: =F32+G32 -> 0 | J32: =-I32 -> 0 | K32: =I32+J32 -> 0 | N32: =L32+M32 -> 0 | Q32: =O32+P32 -> 0
E33: =C33+D33 -> 0 | H33: =F33+G33 -> 0 | K33: =I33+J33 -> 0 | N33: =L33+M33 -> 0 | Q33: =O33+P33 -> 0
E34: =C34+D34 -> 0 | H34: =F34+G34 -> 0 | K34: =I34+J34 -> 0 | N34: =L34+M34 -> 0 | Q34: =O34+P34 -> 0
E35: =C35+D35 -> 0 | H35: =F35+G35 -> 0 | K35: =I35+J35 -> 0 | N35: =L35+M35 -> 0 | Q35: =O35+P35 -> 0
B36: 経常利益 | C36: =C22+C23-C30 -> 6665569 | D36: =D22+D23-D30 -> -2016366.5 | E36: =C36+D36 -> 4649202.5 | F36: =F22+F23-F30 -> 89928661 | G36: =G22+G23-G30 -> -23332504 | H36: =F36+G36 -> 66596157 | I36: =I22+I23-I30 -> 64943069 | J36: =J22+J23-J30 -> -20248261 | K36: =I36+J36 -> 44694808 | L36: =L22+L23-L30 -> 0 | M36: =M22+M23-M30 -> 0 | N36: =L36+M36 -> 0 | O36: =O22+O23-O30 -> 0 | P36: =P22+P23-P30 -> 0 | Q36: =O36+P36 -> 0
B37: 特別利益 | C37: =SUM(C38:C41) -> 0 | D37: =SUM(D38:D41) -> 0 | E37: =C37+D37 -> 0 | F37: =SUM(F38:F41) -> 21984310 | G37: =SUM(G38:G41) -> -21984310 | H37: =F37+G37 -> 0 | I37: =SUM(I38:I41) -> 12486495 | J37: =SUM(J38:J41) -> -12486495 | K37: =I37+J37 -> 0 | L37: =SUM(L38:L41) -> 0 | M37: =SUM(M38:M41) -> 0 | N37: =L37+M37 -> 0 | O37: =SUM(O38:O41) -> 0 | P37: =SUM(P38:P41) -> 0 | Q37: =O37+P37 -> 0
B38: 投資有価証券売却益 | D38: =-C38 -> 0 | E38: =C38+D38 -> 0 | F38: 21984310 | G38: =-F38 -> -21984310 | H38: =F38+G38 -> 0 | I38: 12486495 | J38: =-I38 -> -12486495 | K38: =I38+J38 -> 0 | N38: =L38+M38 -> 0 | Q38: =O38+P38 -> 0
E39: =C39+D39 -> 0 | H39: =F39+G39 -> 0 | K39: =I39+J39 -> 0 | N39: =L39+M39 -> 0 | Q39: =O39+P39 -> 0
E40: =C40+D40 -> 0 | H40: =F40+G40 -> 0 | K40: =I40+J40 -> 0 | N40: =L40+M40 -> 0 | Q40: =O40+P40 -> 0
E41: =C41+D41 -> 0 | H41: =F41+G41 -> 0 | K41: =I41+J41 -> 0 | N41: =L41+M41 -> 0 | Q41: =O41+P41 -> 0
...

Sheet 修正SGA
K2: (単位：千円)
B3: 科目 | C3: ='BS(借方)'!C4 -> 24年1月期 | F3: ='BS(借方)'!D4 -> 25年1月期 | I3: ='BS(借方)'!E4 -> 26年1月期 | L3: ='BS(借方)'!F4 -> ●●年●月期 | O3: ='BS(借方)'!F4 -> ●●年●月期
C4: 帳簿価額 | D4: 修正額 | E4: 修正後 | F4: 帳簿価額 | G4: 修正額 | H4: 修正後 | I4: 帳簿価額 | J4: 修正額 | K4: 修正後 | L4: 帳簿価額 | M4: 修正額 | N4: 修正後 | O4: 帳簿価額 | P4: 修正額 | Q4: 修正後
B5: 役員報酬 | C5: 1104000 | E5: =C5+D5 -> 1104000 | F5: 1104000 | H5: =F5+G5 -> 1104000 | I5: 4094000 | J5: =-1500000-1490000 -> -2990000 | K5: =I5+J5 -> 1104000 | N5: =L5+M5 -> 0 | Q5: =O5+P5 -> 0
B6: 役員賞与 | C6: 18000000 | E6: =C6+D6 -> 18000000 | F6: 20000000 | H6: =F6+G6 -> 20000000 | I6: 20000000 | K6: =I6+J6 -> 20000000 | N6: =L6+M6 -> 0 | Q6: =O6+P6 -> 0
B7: 給料手当 | C7: 33649484 | E7: =C7+D7 -> 33649484 | F7: 29811105 | H7: =F7+G7 -> 29811105 | I7: 27938525 | K7: =I7+J7 -> 27938525 | N7: =L7+M7 -> 0 | Q7: =O7+P7 -> 0
B8: 雑給 | C8: 2538750 | D8: =-C8 -> -2538750 | E8: =C8+D8 -> 0 | F8: 6544740 | G8: =-1500000-1490000 -> -2990000 | H8: =F8+G8 -> 3554740 | I8: 299000 | K8: =I8+J8 -> 299000 | N8: =L8+M8 -> 0 | Q8: =O8+P8 -> 0
B9: 賞与 | C9: 4064600 | E9: =C9+D9 -> 4064600 | H9: =F9+G9 -> 0 | I9: 6079177 | K9: =I9+J9 -> 6079177 | N9: =L9+M9 -> 0 | Q9: =O9+P9 -> 0
B10: 法定福利費 | C10: 6407318 | D10: =(D5+D6+D8)*0.15 -> -380812.5 | E10: =C10+D10 -> 6026505.5 | F10: 6394777 | G10: =(G5+G6+G8)*0.15 -> -448500 | H10: =F10+G10 -> 5946277 | I10: 6366731 | J10: =(J5+J6)*0.15 -> -448500 | K10: =I10+J10 -> 5918231 | N10: =L10+M10 -> 0 | Q10: =O10+P10 -> 0
B11: 福利厚生費 | C11: 1932474 | E11: =C11+D11 -> 1932474 | F11: 422087 | H11: =F11+G11 -> 422087 | I11: 705804 | K11: =I11+J11 -> 705804 | N11: =L11+M11 -> 0 | Q11: =O11+P11 -> 0
B12: 採用教育費 | C12: 280000 | E12: =C12+D12 -> 280000 | F12: 1480000 | H12: =F12+G12 -> 1480000 | K12: =I12+J12 -> 0 | N12: =L12+M12 -> 0 | Q12: =O12+P12 -> 0
B13: 荷造運賃 | C13: 9235586 | E13: =C13+D13 -> 9235586 | F13: 13487346 | H13: =F13+G13 -> 13487346 | I13: 7104880 | K13: =I13+J13 -> 7104880 | N13: =L13+M13 -> 0 | Q13: =O13+P13 -> 0
B14: 広告宣伝費 | C14: 152187 | E14: =C14+D14 -> 152187 | F14: 142619 | H14: =F14+G14 -> 142619 | I14: 841073 | K14: =I14+J14 -> 841073 | N14: =L14+M14 -> 0 | Q14: =O14+P14 -> 0
B15: 接待交際費 | C15: 1440144 | D15: =-C15 -> -1440144 | E15: =C15+D15 -> 0 | F15: 1738203 | G15: =-F15 -> -1738203 | H15: =F15+G15 -> 0 | I15: 2336230 | J15: =-I15 -> -2336230 | K15: =I15+J15 -> 0 | N15: =L15+M15 -> 0 | Q15: =O15+P15 -> 0
B16: 会議費 | C16: 211518 | E16: =C16+D16 -> 211518 | F16: 214892 | H16: =F16+G16 -> 214892 | I16: 284369 | K16: =I16+J16 -> 284369 | N16: =L16+M16 -> 0 | Q16: =O16+P16 -> 0
B17: 旅費交通費 | C17: 645511 | E17: =C17+D17 -> 645511 | F17: 2129949 | H17: =F17+G17 -> 2129949 | I17: 1018914 | K17: =I17+J17 -> 1018914 | N17: =L17+M17 -> 0 | Q17: =O17+P17 -> 0
B18: 通信費 | C18: 1416425 | E18: =C18+D18 -> 1416425 | F18: 1506325 | H18: =F18+G18 -> 1506325 | I18: 1506831 | K18: =I18+J18 -> 1506831 | N18: =L18+M18 -> 0 | Q18: =O18+P18 -> 0
B19: 販売促進費 | C19: 65128 | E19: =C19+D19 -> 65128 | H19: =F19+G19 -> 0 | K19: =I19+J19 -> 0 | N19: =L19+M19 -> 0 | Q19: =O19+P19 -> 0
B20: 事務用消耗品費 | C20: 1145535 | E20: =C20+D20 -> 1145535 | F20: 1700793 | H20: =F20+G20 -> 1700793 | I20: 1195194 | K20: =I20+J20 -> 1195194 | N20: =L20+M20 -> 0 | Q20: =O20+P20 -> 0
B21: 修繕費 | C21: 44900 | E21: =C21+D21 -> 44900 | F21: 190064 | H21: =F21+G21 -> 190064 | K21: =I21+J21 -> 0 | N21: =L21+M21 -> 0 | Q21: =O21+P21 -> 0
B22: 水道光熱費 | C22: 394299 | E22: =C22+D22 -> 394299 | F22: 403021 | H22: =F22+G22 -> 403021 | I22: 412583 | K22: =I22+J22 -> 412583 | N22: =L22+M22 -> 0 | Q22: =O22+P22 -> 0
B23: 諸会費 | C23: 57450 | E23: =C23+D23 -> 57450 | F23: 36000 | H23: =F23+G23 -> 36000 | I23: 48000 | K23: =I23+J23 -> 48000 | N23: =L23+M23 -> 0 | Q23: =O23+P23 -> 0
B24: 支払手数料 | C24: 3167934 | E24: =C24+D24 -> 3167934 | F24: 3674031 | H24: =F24+G24 -> 3674031 | I24: 1179313 | K24: =I24+J24 -> 1179313 | N24: =L24+M24 -> 0 | Q24: =O24+P24 -> 0
B25: 車両費 | C25: 650214 | E25: =C25+D25 -> 650214 | F25: 478916 | H25: =F25+G25 -> 478916 | I25: 716759 | K25: =I25+J25 -> 716759 | N25: =L25+M25 -> 0 | Q25: =O25+P25 -> 0
B26: 地代家賃 | C26: 5430000 | E26: =C26+D26 -> 5430000 | F26: 5430000 | H26: =F26+G26 -> 5430000 | I26: 5500911 | K26: =I26+J26 -> 5500911 | N26: =L26+M26 -> 0 | Q26: =O26+P26 -> 0
B27: リース料 | C27: 131200 | E27: =C27+D27 -> 131200 | F27: 160920 | H27: =F27+G27 -> 160920 | I27: 147510 | K27: =I27+J27 -> 147510 | N27: =L27+M27 -> 0 | Q27: =O27+P27 -> 0
B28: 保険料 | C28: 709690 | E28: =C28+D28 -> 709690 | F28: 1090090 | H28: =F28+G28 -> 1090090 | I28: 735330 | K28: =I28+J28 -> 735330 | N28: =L28+M28 -> 0 | Q28: =O28+P28 -> 0
B29: 租税公課 | C29: 234840 | E29: =C29+D29 -> 234840 | F29: 175360 | H29: =F29+G29 -> 175360 | I29: 269084 | K29: =I29+J29 -> 269084 | N29: =L29+M29 -> 0 | Q29: =O29+P29 -> 0
B30: 支払報酬料 | C30: 755000 | E30: =C30+D30 -> 755000 | F30: 755000 | H30: =F30+G30 -> 755000 | I30: 762000 | K30: =I30+J30 -> 762000 | N30: =L30+M30 -> 0 | Q30: =O30+P30 -> 0
B31: 寄付金 | C31: 50000 | D31: =-C31 -> -50000 | E31: =C31+D31 -> 0 | F31: 200000 | G31: =-F31 -> -200000 | H31: =F31+G31 -> 0 | I31: 50000 | J31: =-I31 -> -50000 | K31: =I31+J31 -> 0 | N31: =L31+M31 -> 0 | Q31: =O31+P31 -> 0
B32: 研究開発費 | C32: 174503 | E32: =C32+D32 -> 174503 | F32: 574824 | H32: =F32+G32 -> 574824 | I32: 170367 | K32: =I32+J32 -> 170367 | N32: =L32+M32 -> 0 | Q32: =O32+P32 -> 0
B33: 減価償却費 | C33: 881300 | E33: =C33+D33 -> 881300 | F33: 644524 | H33: =F33+G33 -> 644524 | I33: 1182673 | K33: =I33+J33 -> 1182673 | N33: =L33+M33 -> 0 | Q33: =O33+P33 -> 0
B34: 貸倒引当金繰入額 | C34: 803000 | D34: =-C34 -> -803000 | E34: =C34+D34 -> 0 | F34: 246000 | G34: =-F34 -> -246000 | H34: =F34+G34 -> 0 | I34: 201000 | J34: =-I34 -> -201000 | K34: =I34+J34 -> 0 | N34: =L34+M34 -> 0 | Q34: =O34+P34 -> 0
B35: 通勤 | C35: 1622989 | E35: =C35+D35 -> 1622989 | H35: =F35+G35 -> 0 | I35: 1143204 | K35: =I35+J35 -> 1143204 | N35: =L35+M35 -> 0 | Q35: =O35+P35 -> 0
E36: =C36+D36 -> 0 | H36: =F36+G36 -> 0 | K36: =I36+J36 -> 0 | N36: =L36+M36 -> 0 | Q36: =O36+P36 -> 0
E37: =C37+D37 -> 0 | H37: =F37+G37 -> 0 | K37: =I37+J37 -> 0 | N37: =L37+M37 -> 0 | Q37: =O37+P37 -> 0
E38: =C38+D38 -> 0 | H38: =F38+G38 -> 0 | K38: =I38+J38 -> 0 | N38: =L38+M38 -> 0 | Q38: =O38+P38 -> 0
B39: 販売費および一般管理費合計 | C39: =SUM(C5:C38) -> 97395979 | D39: =SUM(D5:D38) -> -5212706.5 | E39: =C39+D39 -> 92183272 | F39: =SUM(F5:F38) -> 100735586 | G39: =SUM(G5:G38) -> -5622703 | H39: =F39+G39 -> 95112883 | I39: =SUM(I5:I38) -> 92289462 | J39: =SUM(J5:J38) -> -6025730 | K39: =I39+J39 -> 86263732 | L39: =SUM(L5:L38) -> 0 | M39: =SUM(M5:M38) -> 0 | N39: =L39+M39 -> 0 | O39: =SUM(O5:O38) -> 0 | P39: =SUM(P5:P38) -> 0 | Q39: =O39+P39 -> 0

Sheet 修正CR
K2: (単位：千円)
B3: 科目 | C3: ='BS(借方)'!C4 -> 24年1月期 | F3: ='BS(借方)'!D4 -> 25年1月期 | I3: ='BS(借方)'!E4 -> 26年1月期 | L3: ='BS(借方)'!F4 -> ●●年●月期 | O3: ='BS(借方)'!G4 -> ●●年●月 （●か月TB）
C4: 帳簿価額 | D4: 修正額 | E4: 修正後 | F4: 帳簿価額 | G4: 修正額 | H4: 修正後 | I4: 帳簿価額 | J4: 修正額 | K4: 修正後 | L4: 帳簿価額 | M4: 修正額 | N4: 修正後 | O4: 帳簿価額 | P4: 修正額 | Q4: 修正後
B5: 期首原材料棚卸高 | C5: 500000 | D5: -500000 | E5: =C5+D5 -> 0 | F5: 500000 | G5: -500000 | H5: =F5+G5 -> 0 | I5: 500000 | J5: -500000 | K5: =I5+J5 -> 0 | L5: 500000 | M5: -500000 | N5: =L5+M5 -> 0 | O5: 500000 | P5: -500000 | Q5: =O5+P5 -> 0
B6: 原材料仕入高 | E6: =C6+D6 -> 0 | H6: =F6+G6 -> 0 | K6: =I6+J6 -> 0 | N6: =L6+M6 -> 0 | Q6: =O6+P6 -> 0
B7: 小計 | E7: =C7+D7 -> 0 | H7: =F7+G7 -> 0 | K7: =I7+J7 -> 0 | N7: =L7+M7 -> 0 | Q7: =O7+P7 -> 0
B8: 期末原材料棚卸高 | E8: =C8+D8 -> 0 | H8: =F8+G8 -> 0 | K8: =I8+J8 -> 0 | N8: =L8+M8 -> 0 | Q8: =O8+P8 -> 0
E9: =C9+D9 -> 0 | H9: =F9+G9 -> 0 | K9: =I9+J9 -> 0 | N9: =L9+M9 -> 0 | Q9: =O9+P9 -> 0
E10: =C10+D10 -> 0 | H10: =F10+G10 -> 0 | K10: =I10+J10 -> 0 | N10: =L10+M10 -> 0 | Q10: =O10+P10 -> 0
B11: 材料費 | C11: =SUM(C5:C10) -> 500000 | D11: =SUM(D5:D10) -> -500000 | E11: =C11+D11 -> 0 | F11: =SUM(F5:F10) -> 500000 | G11: =SUM(G5:G10) -> -500000 | H11: =F11+G11 -> 0 | I11: =SUM(I5:I10) -> 500000 | J11: =SUM(J5:J10) -> -500000 | K11: =I11+J11 -> 0 | L11: =SUM(L5:L10) -> 500000 | M11: =SUM(M5:M10) -> -500000 | N11: =L11+M11 -> 0 | O11: =SUM(O5:O10) -> 500000 | P11: =SUM(P5:P10) -> -500000 | Q11: =O11+P11 -> 0
E12: =C12+D12 -> 0 | H12: =F12+G12 -> 0 | K12: =I12+J12 -> 0 | N12: =L12+M12 -> 0 | Q12: =O12+P12 -> 0
E13: =C13+D13 -> 0 | H13: =F13+G13 -> 0 | K13: =I13+J13 -> 0 | N13: =L13+M13 -> 0 | Q13: =O13+P13 -> 0
E14: =C14+D14 -> 0 | H14: =F14+G14 -> 0 | K14: =I14+J14 -> 0 | N14: =L14+M14 -> 0 | Q14: =O14+P14 -> 0
E15: =C15+D15 -> 0 | H15: =F15+G15 -> 0 | K15: =I15+J15 -> 0 | N15: =L15+M15 -> 0 | Q15: =O15+P15 -> 0
E16: =C16+D16 -> 0 | H16: =F16+G16 -> 0 | K16: =I16+J16 -> 0 | N16: =L16+M16 -> 0 | Q16: =O16+P16 -> 0
E17: =C17+D17 -> 0 | H17: =F17+G17 -> 0 | K17: =I17+J17 -> 0 | N17: =L17+M17 -> 0 | Q17: =O17+P17 -> 0
B18: 労務費 | C18: =SUM(C12:C17) -> 0 | D18: =SUM(D12:D17) -> 0 | E18: =C18+D18 -> 0 | F18: =SUM(F12:F17) -> 0 | G18: =SUM(G12:G17) -> 0 | H18: =F18+G18 -> 0 | I18: =SUM(I12:I17) -> 0 | J18: =SUM(J12:J17) -> 0 | K18: =I18+J18 -> 0 | L18: =SUM(L12:L17) -> 0 | M18: =SUM(M12:M17) -> 0 | N18: =L18+M18 -> 0 | O18: =SUM(O12:O17) -> 0 | P18: =SUM(P12:P17) -> 0 | Q18: =O18+P18 -> 0
E19: =C19+D19 -> 0 | H19: =F19+G19 -> 0 | K19: =I19+J19 -> 0 | N19: =L19+M19 -> 0 | Q19: =O19+P19 -> 0
E20: =C20+D20 -> 0 | H20: =F20+G20 -> 0 | K20: =I20+J20 -> 0 | N20: =L20+M20 -> 0 | Q20: =O20+P20 -> 0
E21: =C21+D21 -> 0 | H21: =F21+G21 -> 0 | K21: =I21+J21 -> 0 | N21: =L21+M21 -> 0 | Q21: =O21+P21 -> 0
E22: =C22+D22 -> 0 | H22: =F22+G22 -> 0 | K22: =I22+J22 -> 0 | N22: =L22+M22 -> 0 | Q22: =O22+P22 -> 0
E23: =C23+D23 -> 0 | H23: =F23+G23 -> 0 | K23: =I23+J23 -> 0 | N23: =L23+M23 -> 0 | Q23: =O23+P23 -> 0
E24: =C24+D24 -> 0 | H24: =F24+G24 -> 0 | K24: =I24+J24 -> 0 | N24: =L24+M24 -> 0 | Q24: =O24+P24 -> 0
B25: 外注加工費 | C25: =SUM(C19:C24) -> 0 | D25: =SUM(D19:D24) -> 0 | E25: =C25+D25 -> 0 | F25: =SUM(F19:F24) -> 0 | G25: =SUM(G19:G24) -> 0 | H25: =F25+G25 -> 0 | I25: =SUM(I19:I24) -> 0 | J25: =SUM(J19:J24) -> 0 | K25: =I25+J25 -> 0 | L25: =SUM(L19:L24) -> 0 | M25: =SUM(M19:M24) -> 0 | N25: =L25+M25 -> 0 | O25: =SUM(O19:O24) -> 0 | P25: =SUM(P19:P24) -> 0 | Q25: =O25+P25 -> 0
E26: =C26+D26 -> 0 | H26: =F26+G26 -> 0 | K26: =I26+J26 -> 0 | N26: =L26+M26 -> 0 | Q26: =O26+P26 -> 0
E27: =C27+D27 -> 0 | H27: =F27+G27 -> 0 | K27: =I27+J27 -> 0 | N27: =L27+M27 -> 0 | Q27: =O27+P27 -> 0
E28: =C28+D28 -> 0 | H28: =F28+G28 -> 0 | K28: =I28+J28 -> 0 | N28: =L28+M28 -> 0 | Q28: =O28+P28 -> 0
E29: =C29+D29 -> 0 | H29: =F29+G29 -> 0 | K29: =I29+J29 -> 0 | N29: =L29+M29 -> 0 | Q29: =O29+P29 -> 0
E30: =C30+D30 -> 0 | H30: =F30+G30 -> 0 | K30: =I30+J30 -> 0 | N30: =L30+M30 -> 0 | Q30: =O30+P30 -> 0
E31: =C31+D31 -> 0 | H31: =F31+G31 -> 0 | K31: =I31+J31 -> 0 | N31: =L31+M31 -> 0 | Q31: =O31+P31 -> 0
E32: =C32+D32 -> 0 | H32: =F32+G32 -> 0 | K32: =I32+J32 -> 0 | N32: =L32+M32 -> 0 | Q32: =O32+P32 -> 0
E33: =C33+D33 -> 0 | H33: =F33+G33 -> 0 | K33: =I33+J33 -> 0 | N33: =L33+M33 -> 0 | Q33: =O33+P33 -> 0
E34: =C34+D34 -> 0 | H34: =F34+G34 -> 0 | K34: =I34+J34 -> 0 | N34: =L34+M34 -> 0 | Q34: =O34+P34 -> 0
E35: =C35+D35 -> 0 | H35: =F35+G35 -> 0 | K35: =I35+J35 -> 0 | N35: =L35+M35 -> 0 | Q35: =O35+P35 -> 0
B36: 経費 | C36: =SUM(C26:C35) -> 0 | D36: =SUM(D26:D35) -> 0 | E36: =C36+D36 -> 0 | F36: =SUM(F26:F35) -> 0 | G36: =SUM(G26:G35) -> 0 | H36: =F36+G36 -> 0 | I36: =SUM(I26:I35) -> 0 | J36: =SUM(J26:J35) -> 0 | K36: =I36+J36 -> 0 | L36: =SUM(L26:L35) -> 0 | M36: =SUM(M26:M35) -> 0 | N36: =L36+M36 -> 0 | O36: =SUM(O26:O35) -> 0 | P36: =SUM(P26:P35) -> 0 | Q36: =O36+P36 -> 0
B37: 当期製造費用 | C37: =C11+C18+C25+C36 -> 500000 | D37: =D11+D18+D25+D36 -> -500000 | E37: =C37+D37 -> 0 | F37: =F11+F18+F25+F36 -> 500000 | G37: =G11+G18+G25+G36 -> -500000 | H37: =F37+G37 -> 0 | I37: =I11+I18+I25+I36 -> 500000 | J37: =J11+J18+J25+J36 -> -500000 | K37: =I37+J37 -> 0 | L37: =L11+L18+L25+L36 -> 500000 | M37: =M11+M18+M25+M36 -> -500000 | N37: =L37+M37 -> 0 | O37: =O11+O18+O25+O36 -> 500000 | P37: =P11+P18+P25+P36 -> -500000 | Q37: =O37+P37 -> 0
B38: 期首仕掛品棚卸高 | E38: =C38+D38 -> 0 | H38: =F38+G38 -> 0 | K38: =I38+J38 -> 0 | N38: =L38+M38 -> 0 | Q38: =O38+P38 -> 0
B39: 合計 | C39: =SUM(C37:C38) -> 500000 | D39: =SUM(D37:D38) -> -500000 | E39: =C39+D39 -> 0 | F39: =SUM(F37:F38) -> 500000 | G39: =SUM(G37:G38) -> -500000 | H39: =F39+G39 -> 0 | I39: =SUM(I37:I38) -> 500000 | J39: =SUM(J37:J38) -> -500000 | K39: =I39+J39 -> 0 | L39: =SUM(L37:L38) -> 500000 | M39: =SUM(M37:M38) -> -500000 | N39: =L39+M39 -> 0 | O39: =SUM(O37:O38) -> 500000 | P39: =SUM(P37:P38) -> -500000 | Q39: =O39+P39 -> 0
B40: 期末仕掛品棚卸高 | E40: =C40+D40 -> 0 | H40: =F40+G40 -> 0 | K40: =I40+J40 -> 0 | N40: =L40+M40 -> 0 | Q40: =O40+P40 -> 0
B41: 当期製造原価 | C41: =C39-C40 -> 500000 | D41: =D39-D40 -> -500000 | E41: =C41+D41 -> 0 | F41: =F39-F40 -> 500000 | G41: =G39-G40 -> -500000 | H41: =F41+G41 -> 0 | I41: =I39-I40 -> 500000 | J41: =J39-J40 -> -500000 | K41: =I41+J41 -> 0 | L41: =L39-L40 -> 500000 | M41: =M39-M40 -> -500000 | N41: =L41+M41 -> 0 | O41: =O39-O40 -> 500000 | P41: =P39-P40 -> -500000 | Q41: =O41+P41 -> 0

Sheet 年買法
C2: (単位：千円) | H2: (単位：千円) | M2: (単位：千円)
B3: =修正PL!I3 -> 26年1月期 | C3: 金額 | F3: =修正PL!C3 -> 24年1月期 | G3: =修正PL!F3 -> 25年1月期 | H3: =修正PL!I3 -> 26年1月期 | J3: 営業権倍率 | K3: x1 | L3: x2 | M3: x3
B4: 簿価純資産額 | C4: ='BS (貸方)'!E50 -> 333535909 | E4: 簿価営業利益 | F4: =修正PL!C22 -> 6159294 | G4: =修正PL!F22 -> 78190765 | H4: =修正PL!I22 -> 58513810 | J4: 時価純資産 | K4: =C6 -> 7678778
B5: 修正額 | C5: ='修正BS(貸方) '!D52 -> -325857131 | E5: 修正額 | F5: =修正PL!D22 -> -1510091.5 | G5: =修正PL!G22 -> -11594608 | H5: =修正PL!J22 -> -13819002 | J5: 営業権 | K5: =H10*1 -> 25506837 | L5: =H10*2 -> 51013674 | M5: =H10*3 -> 76520511
B6: 時価純資産 | C6: =SUM(C4:C5) -> 7678778 | E6: 修正後営業利益 | F6: =SUM(F4:F5) -> 4649202.5 | G6: =SUM(G4:G5) -> 66596157 | H6: =SUM(H4:H5) -> 44694808 | J6: 想定株式価値 | K6: =K4+K5 -> 33185615 | L6: =K4+L5 -> 58692452 | M6: =K4+M5 -> 84199289
