Workbook

Sheet ルール
B3: 1 | C3: 文字は「游ゴシック」、数字は「Arial」を基本。備考欄などの細かい文章は「游ゴシック Medium」。
B4: 2 | C4: タイトル、合計欄は太字
B5: 3 | C5: 数字は円単位で入力、表示は千円単位に設定済み
B6: 4 | C6: 基本の背景は以下の通り。紺、水色、グレー、白、青。パレットの上部の色。
C8: 線は紺か白か青。
C10: 資産の部
C11: 科目 | D11: ='BS(借方)'!F10 -> 0 | E11: 調整額 | F11: 調整後
C12: 【流動資産】 | D12: =SUM(D13:D26) -> 5000000 | E12: =SUM(E13:E26) -> -500000 | F12: =SUM(F13:F26) -> 4500000
C13: 現金及び預金 | D13: 5000000 | E13: -500000 | F13: =D13+E13 -> 4500000
F14: =D14+E14 -> 0

Sheet 財務入力→

Sheet BS(借方)
C1: ←基本的にはここをつかう→
C2: 1期目 | D2: 2期目 | E2: 3期目 | F2: （4期目） | G2: 進行期
B3: 資産の部
B4: 科目 | C4: 23年12月期 | D4: 24年12月期 | E4: 25年12月期 | F4: ●●年●月期 | G4: ●●年●月 （●か月TB）
B5: 【流動資産】 | C5: =SUM(C6:C19) -> 119157017 | D5: =SUM(D6:D19) -> 130777358 | E5: =SUM(E6:E19) -> 141385419 | F5: =SUM(F6:F19) -> 0 | G5: =SUM(G6:G19) -> 0
B6: 現金及び預金 | C6: 40642580 | D6: 48852895 | E6: 61842402
B7: 商品 | C7: 32079836 | D7: 30240016 | E7: 26584168
B8: 貯蔵品 | C8: 652076 | D8: 580343 | E8: 619688
B9: 前払費用 | C9: 161700 | D9: 161700 | E9: 161700
B10: 未収入金 | C10: 45757825 | D10: 49800104 | E10: 52401281
B11: 貸倒引当金 | C11: -457000 | D11: -498000 | E11: -524000
B12: 仮払金 | E12: 180
B13: 前払金 | C13: 320000 | D13: 330000 | E13: 300000
B14: 未収還付法人税等 | D14: 1310300
B20: 【固定資産】 | C20: =C21+C35+C46 -> 22989981 | D20: =D21+D35+D46 -> 23828405 | E20: =E21+E35+E46 -> 19843083 | F20: =F21+F35+F46 -> 0 | G20: =G21+G35+G46 -> 0
B21: ［有形固定資産］ | C21: =SUM(C22:C34) -> 12240330 | D21: =SUM(D22:D34) -> 9518592 | E21: =SUM(E22:E34) -> 7402395 | F21: =SUM(F22:F34) -> 0 | G21: =SUM(G22:G34) -> 0
B22: 建物附属設備 | C22: 7282837 | D22: 6298675 | E22: 5361688
B23: 工具器具備品 | C23: 4957493 | D23: 3219917 | E23: 2040707
B35: ［無形固定資産］ | C35: =SUM(C36:C45) -> 3084273 | D35: =SUM(D36:D45) -> 7222851 | E35: =SUM(E36:E45) -> 4816004 | F35: =SUM(F36:F45) -> 0 | G35: =SUM(G36:G45) -> 0
B36: ソフトウェア | C36: 3084273 | D36: 7222851 | E36: 4816004
B46: ［投資その他資産］ | C46: =SUM(C47:C55) -> 7665378 | D46: =SUM(D47:D55) -> 7086962 | E46: =SUM(E47:E55) -> 7624684 | F46: =SUM(F47:F55) -> 0 | G46: =SUM(G47:G55) -> 0
B47: 差入保証金 | C47: 6513280 | D47: 6513280 | E47: 6639280
B48: 長期前払費用 | C48: 1152098 | D48: 573682 | E48: 985404
B56: 【繰延資産】 | C56: =SUM(C57:C60) -> 0 | D56: =SUM(D57:D60) -> 0 | E56: =SUM(E57:E60) -> 0 | F56: =SUM(F57:F60) -> 0 | G56: =SUM(G57:G60) -> 0
B61: 資産合計 | C61: =C5+C20+C56 -> 142146998 | D61: =D5+D20+D56 -> 154605763 | E61: =E5+E20+E56 -> 161228502 | F61: =F5+F20+F56 -> 0 | G61: =G5+G20+G56 -> 0
B63: バランスチェック | C63: =EXACT(C61,'BS (貸方)'!C51) -> TRUE | D63: =EXACT(D61,'BS (貸方)'!D51) -> TRUE | E63: =EXACT(E61,'BS (貸方)'!E51) -> TRUE | F63: =EXACT(F61,'BS (貸方)'!F51) -> TRUE | G63: =EXACT(G61,'BS (貸方)'!G51) -> TRUE

Sheet BS (貸方)
E2: (単位：千円)
B3: 負債の部
B4: 科目 | C4: ='BS(借方)'!C4 -> 23年12月期 | D4: ='BS(借方)'!D4 -> 24年12月期 | E4: ='BS(借方)'!E4 -> 25年12月期 | F4: ='BS(借方)'!F4 -> ●●年●月期 | G4: ='BS(借方)'!G4 -> ●●年●月 （●か月TB）
B5: 【流動負債】 | C5: =SUM(C6:C17) -> 40847644 | D5: =SUM(D6:D17) -> 44626188 | E5: =SUM(E6:E17) -> 41577715 | F5: =SUM(F6:F17) -> 0 | G5: =SUM(G6:G17) -> 0
B6: 買掛金 | C6: 23388161 | D6: 32912766 | E6: 26935462
B7: 短期借入金 | C7: 8000000 | D7: 8000000 | E7: 8000000
B8: 未払金 | C8: 3614783 | D8: 3648822 | E8: 3541353
B9: 未払法人税等 | C9: 5844700 | D9: 64600 | E9: 3100900
B18: 【固定負債】 | C18: =SUM(C19:C24) -> 47200000 | D18: =SUM(D19:D24) -> 47200000 | E18: =SUM(E19:E24) -> 47200000 | F18: =SUM(F19:F24) -> 0 | G18: =SUM(G19:G24) -> 0
B19: 長期借入金 | C19: 47200000 | D19: 47200000 | E19: 47200000
B25: 負債合計 | C25: =C5+C18 -> 88047644 | D25: =D5+D18 -> 91826188 | E25: =E5+E18 -> 88777715 | F25: =F5+F18 -> 0 | G25: =G5+G18 -> 0
B34: 純資産の部
B35: 【資本金】 | C35: =SUM(C36:C38) -> 9000000 | D35: =SUM(D36:D38) -> 9000000 | E35: =SUM(E36:E38) -> 9000000 | F35: =SUM(F36:F38) -> 0 | G35: =SUM(G36:G38) -> 0
B36: 資本金 | C36: 9000000 | D36: 9000000 | E36: 9000000
B39: 【資本剰余金】 | C39: =SUM(C40:C42) -> 1000000 | D39: =SUM(D40:D42) -> 1000000 | E39: =SUM(E40:E42) -> 1000000 | F39: =SUM(F40:F42) -> 0 | G39: =SUM(G40:G42) -> 0
B40: 資本準備金 | C40: 1000000 | D40: 1000000 | E40: 1000000
B43: 【利益剰余金】 | C43: =SUM(C44:C48) -> 44099354 | D43: =SUM(D44:D48) -> 52779575 | E43: =SUM(E44:E48) -> 62450787 | F43: =SUM(F44:F48) -> 0 | G43: =SUM(G44:G48) -> 0
B44: 繰越利益剰余金 | C44: 44099354 | D44: 52779575 | E44: 62450787
B49: 【自己株式】 | C49: 0 | D49: 0 | E49: 0 | F49: 0 | G49: 0
B50: 純資産合計 | C50: =C35+C39+C43+C49 -> 54099354 | D50: =D35+D39+D43+D49 -> 62779575 | E50: =E35+E39+E43+E49 -> 72450787 | F50: =F35+F39+F43+F49 -> 0 | G50: =G35+G39+G43+G49 -> 0
B51: 負債・純資産合計 | C51: =C25+C50 -> 142146998 | D51: =D25+D50 -> 154605763 | E51: =E25+E50 -> 161228502 | F51: =F25+F50 -> 0 | G51: =G25+G50 -> 0
B53: バランスチェック | C53: =EXACT(C51,'BS(借方)'!C61) -> TRUE | D53: =EXACT(D51,'BS(借方)'!D61) -> TRUE | E53: =EXACT(E51,'BS(借方)'!E61) -> TRUE | F53: =EXACT(F51,'BS(借方)'!F61) -> TRUE | G53: =EXACT(G51,'BS(借方)'!G61) -> TRUE

Sheet PL
H2: (単位：千円)
B3: 科目 | C3: ='BS(借方)'!C4 -> 23年12月期 | E3: ='BS(借方)'!D4 -> 24年12月期 | G3: ='BS(借方)'!E4 -> 25年12月期 | I3: ='BS(借方)'!F4 -> ●●年●月期 | K3: ='BS(借方)'!G4 -> ●●年●月 （●か月TB）
C4: 帳簿価額 | D4: 売上高比 | E4: 帳簿価額 | F4: 売上高比 | G4: 帳簿価額 | H4: 売上高比 | I4: 帳簿価額 | J4: 売上高比 | K4: 帳簿価額 | L4: 売上高比
B5: 売上高 | C5: 325866987 | D5: =IF(C5=0,"",C5/C$11) -> 1 | E5: 346561600 | F5: =IF(E5=0,"",E5/E$11) -> 1 | G5: 357540639 | H5: =IF(G5=0,"",G5/G$11) -> 1 | J5: =IF(I5=0,"",I5/I$11) | L5: =IF(K5=0,"",K5/K$11)
D6: =IF(C6=0,"",C6/C$11) | F6: =IF(E6=0,"",E6/E$11) | H6: =IF(G6=0,"",G6/G$11) | J6: =IF(I6=0,"",I6/I$11) | L6: =IF(K6=0,"",K6/K$11)
D7: =IF(C7=0,"",C7/C$11) | F7: =IF(E7=0,"",E7/E$11) | H7: =IF(G7=0,"",G7/G$11) | J7: =IF(I7=0,"",I7/I$11) | L7: =IF(K7=0,"",K7/K$11)
D8: =IF(C8=0,"",C8/C$11) | F8: =IF(E8=0,"",E8/E$11) | H8: =IF(G8=0,"",G8/G$11) | J8: =IF(I8=0,"",I8/I$11) | L8: =IF(K8=0,"",K8/K$11)
D9: =IF(C9=0,"",C9/C$11) | F9: =IF(E9=0,"",E9/E$11) | H9: =IF(G9=0,"",G9/G$11) | J9: =IF(I9=0,"",I9/I$11) | L9: =IF(K9=0,"",K9/K$11)
D10: =IF(C10=0,"",C10/C$11) | F10: =IF(E10=0,"",E10/E$11) | H10: =IF(G10=0,"",G10/G$11) | J10: =IF(I10=0,"",I10/I$11) | L10: =IF(K10=0,"",K10/K$11)
B11: 売上高 | C11: =SUM(C5:C10) -> 325866987 | D11: =IF(C11=0,"",C11/C$11) -> 1 | E11: =SUM(E5:E10) -> 346561600 | F11: =IF(E11=0,"",E11/E$11) -> 1 | G11: =SUM(G5:G10) -> 357540639 | H11: =IF(G11=0,"",G11/G$11) -> 1 | I11: =SUM(I5:I10) -> 0 | J11: =IF(I11=0,"",I11/I$11) | K11: =SUM(K5:K10) -> 0 | L11: =IF(K11=0,"",K11/K$11)
B12: 期首商品棚卸高 | C12: 28930577 | D12: =IF(C12=0,"",C12/C$11) -> 0.088780325 | E12: 32079836 | F12: =IF(E12=0,"",E12/E$11) -> 0.092566043 | G12: 30240016 | H12: =IF(G12=0,"",G12/G$11) -> 0.084577843 | J12: =IF(I12=0,"",I12/I$11) | L12: =IF(K12=0,"",K12/K$11)
B13: 当期商品仕入高 | C13: 162685310 | D13: =IF(C13=0,"",C13/C$11) -> 0.49923839 | E13: 179686065 | F13: =IF(E13=0,"",E13/E$11) -> 0.51848233 | G13: 193114742 | H13: =IF(G13=0,"",G13/G$11) -> 0.5401197 | J13: =IF(I13=0,"",I13/I$11) | L13: =IF(K13=0,"",K13/K$11)
B14: 仕入値引戻し高 | C14: -18920 | D14: =IF(C14=0,"",C14/C$11) -> -5.8060499e-05 | F14: =IF(E14=0,"",E14/E$11) | H14: =IF(G14=0,"",G14/G$11) | J14: =IF(I14=0,"",I14/I$11) | L14: =IF(K14=0,"",K14/K$11)
B15: 期末商品棚卸高 | C15: -32079836 | D15: =IF(C15=0,"",C15/C$11) -> -0.098444572 | E15: -30240016 | F15: =IF(E15=0,"",E15/E$11) -> -0.087257261 | G15: -26584168 | H15: =IF(G15=0,"",G15/G$11) -> -0.074352857 | J15: =IF(I15=0,"",I15/I$11) | L15: =IF(K15=0,"",K15/K$11)
B16: 売上原価 | C16: =SUM(C12:C15) -> 159517131 | D16: =IF(C16=0,"",C16/C$11) -> 0.48951608 | E16: =SUM(E12:E15) -> 181525885 | F16: =IF(E16=0,"",E16/E$11) -> 0.52379111 | G16: =SUM(G12:G15) -> 196770590 | H16: =IF(G16=0,"",G16/G$11) -> 0.55034468 | I16: =SUM(I12:I15) -> 0 | J16: =IF(I16=0,"",I16/I$11) | K16: =SUM(K12:K15) -> 0 | L16: =IF(K16=0,"",K16/K$11)
B17: 売上総利益 | C17: =C11-C16 -> 166349856 | D17: =IF(C17=0,"",C17/C$11) -> 0.51048392 | E17: =E11-E16 -> 165035715 | F17: =IF(E17=0,"",E17/E$11) -> 0.47620889 | G17: =G11-G16 -> 160770049 | H17: =IF(G17=0,"",G17/G$11) -> 0.44965532 | I17: =I11-I16 -> 0 | J17: =IF(I17=0,"",I17/I$11) | K17: =K11-K16 -> 0 | L17: =IF(K17=0,"",K17/K$11)
B18: 販売費及び一般管理費 | C18: =SGA!C40 -> 145464229 | D18: =IF(C18=0,"",C18/C$11) -> 0.44639143 | E18: =SGA!E40 -> 154261272 | F18: =IF(E18=0,"",E18/E$11) -> 0.44511934 | G18: =SGA!G40 -> 147845764 | H18: =IF(G18=0,"",G18/G$11) -> 0.41350758 | I18: =SGA!I40 -> 0 | J18: =IF(I18=0,"",I18/I$11) | K18: =SGA!K40 -> 0 | L18: =IF(K18=0,"",K18/K$11)
B19: 営業利益 | C19: =C17- C18 -> 20885627 | D19: =IF(C19=0,"",C19/C$11) -> 0.064092491 | E19: =E17- E18 -> 10774443 | F19: =IF(E19=0,"",E19/E$11) -> 0.031089547 | G19: =G17- G18 -> 12924285 | H19: =IF(G19=0,"",G19/G$11) -> 0.036147737 | I19: =I17- I18 -> 0 | J19: =IF(I19=0,"",I19/I$11) | K19: =K17- K18 -> 0 | L19: =IF(K19=0,"",K19/K$11)
B20: 営業外収益 | C20: =SUM(C21:C27) -> 1273342 | D20: =IF(C20=0,"",C20/C$11) -> 0.0039075514 | E20: =SUM(E21:E27) -> 2398375 | F20: =IF(E20=0,"",E20/E$11) -> 0.0069204869 | G20: =SUM(G21:G27) -> 1051276 | H20: =IF(G20=0,"",G20/G$11) -> 0.0029402979 | I20: =SUM(I21:I27) -> 0 | J20: =IF(I20=0,"",I20/I$11) | K20: =SUM(K21:K27) -> 0 | L20: =IF(K20=0,"",K20/K$11)
B21: 受取利息 | C21: 292 | D21: =IF(C21=0,"",C21/C$11) -> 8.9607113e-07 | E21: 3285 | F21: =IF(E21=0,"",E21/E$11) -> 9.4788344e-06 | G21: 76490 | H21: =IF(G21=0,"",G21/G$11) -> 0.00021393372 | J21: =IF(I21=0,"",I21/I$11) | L21: =IF(K21=0,"",K21/K$11)
B22: 仕入割引 | C22: 211750 | D22: =IF(C22=0,"",C22/C$11) -> 0.00064980501 | E22: 52250 | F22: =IF(E22=0,"",E22/E$11) -> 0.00015076685 | H22: =IF(G22=0,"",G22/G$11) | J22: =IF(I22=0,"",I22/I$11) | L22: =IF(K22=0,"",K22/K$11)
B23: 貸倒引当金戻入額 | C23: 448000 | D23: =IF(C23=0,"",C23/C$11) -> 0.0013747941 | E23: 457000 | F23: =IF(E23=0,"",E23/E$11) -> 0.0013186689 | G23: 498000 | H23: =IF(G23=0,"",G23/G$11) -> 0.0013928487 | J23: =IF(I23=0,"",I23/I$11) | L23: =IF(K23=0,"",K23/K$11)
B24: 雑収入 | C24: 613300 | D24: =IF(C24=0,"",C24/C$11) -> 0.0018820563 | E24: 1885840 | F24: =IF(E24=0,"",E24/E$11) -> 0.0054415723 | G24: 476786 | H24: =IF(G24=0,"",G24/G$11) -> 0.0013335155 | J24: =IF(I24=0,"",I24/I$11) | L24: =IF(K24=0,"",K24/K$11)
D25: =IF(C25=0,"",C25/C$11) | F25: =IF(E25=0,"",E25/E$11) | H25: =IF(G25=0,"",G25/G$11) | J25: =IF(I25=0,"",I25/I$11) | L25: =IF(K25=0,"",K25/K$11)
D26: =IF(C26=0,"",C26/C$11) | F26: =IF(E26=0,"",E26/E$11) | H26: =IF(G26=0,"",G26/G$11) | J26: =IF(I26=0,"",I26/I$11) | L26: =IF(K26=0,"",K26/K$11)
D27: =IF(C27=0,"",C27/C$11) | F27: =IF(E27=0,"",E27/E$11) | H27: =IF(G27=0,"",G27/G$11) | J27: =IF(I27=0,"",I27/I$11) | L27: =IF(K27=0,"",K27/K$11)
B28: 営業外費用 | C28: =SUM(C29:C35) -> 230000 | D28: =IF(C28=0,"",C28/C$11) -> 0.00070580945 | E28: =SUM(E29:E35) -> 2287900 | F28: =IF(E28=0,"",E28/E$11) -> 0.0066017124 | G28: =SUM(G29:G35) -> 90040 | H28: =IF(G28=0,"",G28/G$11) -> 0.00025183151 | I28: =SUM(I29:I35) -> 0 | J28: =IF(I28=0,"",I28/I$11) | K28: =SUM(K29:K35) -> 0 | L28: =IF(K28=0,"",K28/K$11)
B29: 支払利息 | C29: 80000 | D29: =IF(C29=0,"",C29/C$11) -> 0.00024549894 | E29: 80000 | F29: =IF(E29=0,"",E29/E$11) -> 0.00023083919 | G29: 80000 | H29: =IF(G29=0,"",G29/G$11) -> 0.00022375079 | J29: =IF(I29=0,"",I29/I$11) | L29: =IF(K29=0,"",K29/K$11)
B30: 雑損失 | C30: 150000 | D30: =IF(C30=0,"",C30/C$11) -> 0.00046031051 | E30: 1649900 | F30: =IF(E30=0,"",E30/E$11) -> 0.0047607698 | G30: 10040 | H30: =IF(G30=0,"",G30/G$11) -> 2.8080724e-05 | J30: =IF(I30=0,"",I30/I$11) | L30: =IF(K30=0,"",K30/K$11)
B31: 固定資産圧縮損 | D31: =IF(C31=0,"",C31/C$11) | E31: 558000 | F31: =IF(E31=0,"",E31/E$11) -> 0.0016101034 | H31: =IF(G31=0,"",G31/G$11) | J31: =IF(I31=0,"",I31/I$11) | L31: =IF(K31=0,"",K31/K$11)
D32: =IF(C32=0,"",C32/C$11) | F32: =IF(E32=0,"",E32/E$11) | H32: =IF(G32=0,"",G32/G$11) | J32: =IF(I32=0,"",I32/I$11) | L32: =IF(K32=0,"",K32/K$11)
D33: =IF(C33=0,"",C33/C$11) | F33: =IF(E33=0,"",E33/E$11) | H33: =IF(G33=0,"",G33/G$11) | J33: =IF(I33=0,"",I33/I$11) | L33: =IF(K33=0,"",K33/K$11)
D34: =IF(C34=0,"",C34/C$11) | F34: =IF(E34=0,"",E34/E$11) | H34: =IF(G34=0,"",G34/G$11) | J34: =IF(I34=0,"",I34/I$11) | L34: =IF(K34=0,"",K34/K$11)
D35: =IF(C35=0,"",C35/C$11) | F35: =IF(E35=0,"",E35/E$11) | H35: =IF(G35=0,"",G35/G$11) | J35: =IF(I35=0,"",I35/I$11) | L35: =IF(K35=0,"",K35/K$11)
B36: 経常利益 | C36: =C19+C20-C28 -> 21928969 | D36: =IF(C36=0,"",C36/C$11) -> 0.067294233 | E36: =E19+E20-E28 -> 10884918 | F36: =IF(E36=0,"",E36/E$11) -> 0.031408321 | G36: =G19+G20-G28 -> 13885521 | H36: =IF(G36=0,"",G36/G$11) -> 0.038836203 | I36: =I19+I20-I28 -> 0 | J36: =IF(I36=0,"",I36/I$11) | K36: =K19+K20-K28 -> 0 | L36: =IF(K36=0,"",K36/K$11)
B37: 特別利益 | C37: =SUM(C38:C43) -> 0 | D37: =IF(C37=0,"",C37/C$11) | E37: =SUM(E38:E43) -> 0 | F37: =IF(E37=0,"",E37/E$11) | G37: =SUM(G38:G43) -> 0 | H37: =IF(G37=0,"",G37/G$11) | I37: =SUM(I38:I43) -> 0 | J37: =IF(I37=0,"",I37/I$11) | K37: =SUM(K38:K43) -> 0 | L37: =IF(K37=0,"",K37/K$11)
D38: =IF(C38=0,"",C38/C$11) | F38: =IF(E38=0,"",E38/E$11) | H38: =IF(G38=0,"",G38/G$11) | J38: =IF(I38=0,"",I38/I$11) | L38: =IF(K38=0,"",K38/K$11)
D39: =IF(C39=0,"",C39/C$11) | F39: =IF(E39=0,"",E39/E$11) | H39: =IF(G39=0,"",G39/G$11) | J39: =IF(I39=0,"",I39/I$11) | L39: =IF(K39=0,"",K39/K$11)
D40: =IF(C40=0,"",C40/C$11) | F40: =IF(E40=0,"",E40/E$11) | H40: =IF(G40=0,"",G40/G$11) | J40: =IF(I40=0,"",I40/I$11) | L40: =IF(K40=0,"",K40/K$11)
D41: =IF(C41=0,"",C41/C$11) | F41: =IF(E41=0,"",E41/E$11) | H41: =IF(G41=0,"",G41/G$11) | J41: =IF(I41=0,"",I41/I$11) | L41: =IF(K41=0,"",K41/K$11)
...

Sheet CR
H4: (単位：千円)
B5: 科目 | C5: ='BS(借方)'!C4 -> 23年12月期 | E5: ='BS(借方)'!D4 -> 24年12月期 | G5: ='BS(借方)'!E4 -> 25年12月期 | I5: ='BS(借方)'!F4 -> ●●年●月期 | K5: ='BS(借方)'!G4 -> ●●年●月 （●か月TB）
C6: 帳簿価額 | D6: 売上高比 | E6: 帳簿価額 | F6: 売上高比 | G6: 帳簿価額 | H6: 売上高比 | I6: 帳簿価額 | J6: 売上高比 | K6: 帳簿価額 | L6: 売上高比
A7: IMに貼るときは非表示→ | B7: 売上 | C7: =PL!C11 -> 325866987 | D7: - | E7: =PL!E11 -> 346561600 | F7: - | G7: =PL!G11 -> 357540639 | H7: - | I7: =PL!I11 -> 0 | J7: - | K7: =PL!K11 -> 0 | L7: -
B8: 期首原材料棚卸高 | D8: =IF(C8=0,"",C8/C$7) | F8: =IF(E8=0,"",E8/E$7) | H8: =IF(G8=0,"",G8/G$7) | J8: =IF(I8=0,"",I8/I$7) | L8: =IF(K8=0,"",K8/K$7)
B9: 原材料仕入高 | D9: =IF(C9=0,"",C9/C$7) | F9: =IF(E9=0,"",E9/E$7) | H9: =IF(G9=0,"",G9/G$7) | J9: =IF(I9=0,"",I9/I$7) | L9: =IF(K9=0,"",K9/K$7)
B10: 小計 | D10: =IF(C10=0,"",C10/C$7) | F10: =IF(E10=0,"",E10/E$7) | H10: =IF(G10=0,"",G10/G$7) | J10: =IF(I10=0,"",I10/I$7) | L10: =IF(K10=0,"",K10/K$7)
B11: 期末原材料棚卸高 | D11: =IF(C11=0,"",C11/C$7) | F11: =IF(E11=0,"",E11/E$7) | H11: =IF(G11=0,"",G11/G$7) | J11: =IF(I11=0,"",I11/I$7) | L11: =IF(K11=0,"",K11/K$7)
D12: =IF(C12=0,"",C12/C$7) | F12: =IF(E12=0,"",E12/E$7) | H12: =IF(G12=0,"",G12/G$7) | J12: =IF(I12=0,"",I12/I$7) | L12: =IF(K12=0,"",K12/K$7)
D13: =IF(C13=0,"",C13/C$7) | F13: =IF(E13=0,"",E13/E$7) | H13: =IF(G13=0,"",G13/G$7) | J13: =IF(I13=0,"",I13/I$7) | L13: =IF(K13=0,"",K13/K$7)
B14: 材料費 | C14: =SUM(C8:C13) -> 0 | D14: =IF(C14=0,"",C14/C$7) | E14: =SUM(E8:E13) -> 0 | F14: =IF(E14=0,"",E14/E$7) | G14: =SUM(G8:G13) -> 0 | H14: =IF(G14=0,"",G14/G$7) | I14: =SUM(I8:I13) -> 0 | J14: =IF(I14=0,"",I14/I$7) | K14: =SUM(K8:K13) -> 0 | L14: =IF(K14=0,"",K14/K$7)
D15: =IF(C15=0,"",C15/C$7) | F15: =IF(E15=0,"",E15/E$7) | H15: =IF(G15=0,"",G15/G$7) | J15: =IF(I15=0,"",I15/I$7) | L15: =IF(K15=0,"",K15/K$7)
D18: =IF(C18=0,"",C18/C$7) | F18: =IF(E18=0,"",E18/E$7) | H18: =IF(G18=0,"",G18/G$7) | J18: =IF(I18=0,"",I18/I$7) | L18: =IF(K18=0,"",K18/K$7)
D19: =IF(C19=0,"",C19/C$7) | F19: =IF(E19=0,"",E19/E$7) | H19: =IF(G19=0,"",G19/G$7) | J19: =IF(I19=0,"",I19/I$7) | L19: =IF(K19=0,"",K19/K$7)
D20: =IF(C20=0,"",C20/C$7) | F20: =IF(E20=0,"",E20/E$7) | H20: =IF(G20=0,"",G20/G$7) | J20: =IF(I20=0,"",I20/I$7) | L20: =IF(K20=0,"",K20/K$7)
D21: =IF(C21=0,"",C21/C$7) | F21: =IF(E21=0,"",E21/E$7) | H21: =IF(G21=0,"",G21/G$7) | J21: =IF(I21=0,"",I21/I$7) | L21: =IF(K21=0,"",K21/K$7)
D22: =IF(C22=0,"",C22/C$7) | F22: =IF(E22=0,"",E22/E$7) | H22: =IF(G22=0,"",G22/G$7) | J22: =IF(I22=0,"",I22/I$7) | L22: =IF(K22=0,"",K22/K$7)
B23: 労務費 | C23: =SUM(C15:C22) -> 0 | D23: =IF(C23=0,"",C23/C$7) | E23: =SUM(E15:E22) -> 0 | F23: =IF(E23=0,"",E23/E$7) | G23: =SUM(G15:G22) -> 0 | H23: =IF(G23=0,"",G23/G$7) | I23: =SUM(I15:I22) -> 0 | J23: =IF(I23=0,"",I23/I$7) | K23: =SUM(K15:K22) -> 0 | L23: =IF(K23=0,"",K23/K$7)
D24: =IF(C24=0,"",C24/C$7) | F24: =IF(E24=0,"",E24/E$7) | H24: =IF(G24=0,"",G24/G$7) | J24: =IF(I24=0,"",I24/I$7) | L24: =IF(K24=0,"",K24/K$7)
D28: =IF(C28=0,"",C28/C$7) | F28: =IF(E28=0,"",E28/E$7) | H28: =IF(G28=0,"",G28/G$7) | J28: =IF(I28=0,"",I28/I$7) | L28: =IF(K28=0,"",K28/K$7)
D29: =IF(C29=0,"",C29/C$7) | F29: =IF(E29=0,"",E29/E$7) | H29: =IF(G29=0,"",G29/G$7) | J29: =IF(I29=0,"",I29/I$7) | L29: =IF(K29=0,"",K29/K$7)
D30: =IF(C30=0,"",C30/C$7) | F30: =IF(E30=0,"",E30/E$7) | H30: =IF(G30=0,"",G30/G$7) | J30: =IF(I30=0,"",I30/I$7) | L30: =IF(K30=0,"",K30/K$7)
D31: =IF(C31=0,"",C31/C$7) | F31: =IF(E31=0,"",E31/E$7) | H31: =IF(G31=0,"",G31/G$7) | J31: =IF(I31=0,"",I31/I$7) | L31: =IF(K31=0,"",K31/K$7)
D32: =IF(C32=0,"",C32/C$7) | F32: =IF(E32=0,"",E32/E$7) | H32: =IF(G32=0,"",G32/G$7) | J32: =IF(I32=0,"",I32/I$7) | L32: =IF(K32=0,"",K32/K$7)
B33: 外注加工費 | C33: =SUM(C24:C32) -> 0 | D33: =IF(C33=0,"",C33/C$7) | E33: =SUM(E24:E32) -> 0 | F33: =IF(E33=0,"",E33/E$7) | G33: =SUM(G24:G32) -> 0 | H33: =IF(G33=0,"",G33/G$7) | I33: =SUM(I24:I32) -> 0 | J33: =IF(I33=0,"",I33/I$7) | K33: =SUM(K24:K32) -> 0 | L33: =IF(K33=0,"",K33/K$7)
D34: =IF(C34=0,"",C34/C$7) | F34: =IF(E34=0,"",E34/E$7) | H34: =IF(G34=0,"",G34/G$7) | J34: =IF(I34=0,"",I34/I$7) | L34: =IF(K34=0,"",K34/K$7)
D35: =IF(C35=0,"",C35/C$7) | F35: =IF(E35=0,"",E35/E$7) | H35: =IF(G35=0,"",G35/G$7) | J35: =IF(I35=0,"",I35/I$7) | L35: =IF(K35=0,"",K35/K$7)
D36: =IF(C36=0,"",C36/C$7) | F36: =IF(E36=0,"",E36/E$7) | H36: =IF(G36=0,"",G36/G$7) | J36: =IF(I36=0,"",I36/I$7) | L36: =IF(K36=0,"",K36/K$7)
D39: =IF(C39=0,"",C39/C$7) | F39: =IF(E39=0,"",E39/E$7) | H39: =IF(G39=0,"",G39/G$7) | J39: =IF(I39=0,"",I39/I$7) | L39: =IF(K39=0,"",K39/K$7)
D40: =IF(C40=0,"",C40/C$7) | F40: =IF(E40=0,"",E40/E$7) | H40: =IF(G40=0,"",G40/G$7) | J40: =IF(I40=0,"",I40/I$7) | L40: =IF(K40=0,"",K40/K$7)
D41: =IF(C41=0,"",C41/C$7) | F41: =IF(E41=0,"",E41/E$7) | H41: =IF(G41=0,"",G41/G$7) | J41: =IF(I41=0,"",I41/I$7) | L41: =IF(K41=0,"",K41/K$7)
D42: =IF(C42=0,"",C42/C$7) | F42: =IF(E42=0,"",E42/E$7) | H42: =IF(G42=0,"",G42/G$7) | J42: =IF(I42=0,"",I42/I$7) | L42: =IF(K42=0,"",K42/K$7)
D43: =IF(C43=0,"",C43/C$7) | F43: =IF(E43=0,"",E43/E$7) | H43: =IF(G43=0,"",G43/G$7) | J43: =IF(I43=0,"",I43/I$7) | L43: =IF(K43=0,"",K43/K$7)
D44: =IF(C44=0,"",C44/C$7) | F44: =IF(E44=0,"",E44/E$7) | H44: =IF(G44=0,"",G44/G$7) | J44: =IF(I44=0,"",I44/I$7) | L44: =IF(K44=0,"",K44/K$7)
D45: =IF(C45=0,"",C45/C$7) | F45: =IF(E45=0,"",E45/E$7) | H45: =IF(G45=0,"",G45/G$7) | J45: =IF(I45=0,"",I45/I$7) | L45: =IF(K45=0,"",K45/K$7)
B46: 経費 | C46: =SUM(C34:C45) -> 0 | D46: =IF(C46=0,"",C46/C$7) | E46: =SUM(E34:E45) -> 0 | F46: =IF(E46=0,"",E46/E$7) | G46: =SUM(G34:G45) -> 0 | H46: =IF(G46=0,"",G46/G$7) | I46: =SUM(I34:I45) -> 0 | J46: =IF(I46=0,"",I46/I$7) | K46: =SUM(K34:K45) -> 0 | L46: =IF(K46=0,"",K46/K$7)
B47: 当期製造費用 | C47: =C14+C23+C33+C46 -> 0 | D47: =IF(C47=0,"",C47/C$7) | E47: =E14+E23+E33+E46 -> 0 | F47: =IF(E47=0,"",E47/E$7) | G47: =G14+G23+G33+G46 -> 0 | H47: =IF(G47=0,"",G47/G$7) | I47: =I14+I23+I33+I46 -> 0 | J47: =IF(I47=0,"",I47/I$7) | K47: =K14+K23+K33+K46 -> 0 | L47: =IF(K47=0,"",K47/K$7)
B48: 期首仕掛品棚卸高 | D48: =IF(C48=0,"",C48/C$7) | E48: =SUM(E36:E47) -> 0 | F48: =IF(E48=0,"",E48/E$7) | G48: =SUM(G36:G47) -> 0 | H48: =IF(G48=0,"",G48/G$7) | I48: =SUM(I36:I47) -> 0 | J48: =IF(I48=0,"",I48/I$7) | K48: =SUM(K36:K47) -> 0 | L48: =IF(K48=0,"",K48/K$7)
B49: 合計 | C49: =SUM(C47:C48) -> 0 | D49: =IF(C49=0,"",C49/C$7) | E49: =SUM(E47:E48) -> 0 | F49: =IF(E49=0,"",E49/E$7) | G49: =SUM(G47:G48) -> 0 | H49: =IF(G49=0,"",G49/G$7) | I49: =SUM(I47:I48) -> 0 | J49: =IF(I49=0,"",I49/I$7) | K49: =SUM(K47:K48) -> 0 | L49: =IF(K49=0,"",K49/K$7)
B50: 期末仕掛品棚卸高 | D50: =IF(C50=0,"",C50/C$7) | E50: =SUM(E40:E49) -> 0 | F50: =IF(E50=0,"",E50/E$7) | G50: =SUM(G40:G49) -> 0 | H50: =IF(G50=0,"",G50/G$7) | I50: =SUM(I40:I49) -> 0 | J50: =IF(I50=0,"",I50/I$7) | K50: =SUM(K40:K49) -> 0 | L50: =IF(K50=0,"",K50/K$7)
...

Sheet SGA
H2: (単位：千円)
B3: 科目 | C3: ='BS(借方)'!C4 -> 23年12月期 | E3: ='BS(借方)'!D4 -> 24年12月期 | G3: ='BS(借方)'!E4 -> 25年12月期 | I3: ='BS(借方)'!F4 -> ●●年●月期 | K3: ='BS(借方)'!G4 -> ●●年●月 （●か月TB）
C4: 帳簿価額 | D4: 売上高比 | E4: 帳簿価額 | F4: 売上高比 | G4: 帳簿価額 | H4: 売上高比 | I4: 帳簿価額 | J4: 売上高比 | K4: 帳簿価額 | L4: 売上高比
B5: 売上 | C5: =PL!C11 -> 325866987 | D5: - | E5: =PL!E11 -> 346561600 | F5: - | G5: =PL!G11 -> 357540639 | H5: - | I5: =PL!I11 -> 0 | J5: - | K5: =PL!K11 -> 0 | L5: - | M5: ←IMに貼るときは非表示
B6: 役員報酬 | C6: 10500000 | D6: =C6/$C$5 -> 0.032221736 | E6: 17120000 | F6: =E6/$E$5 -> 0.049399587 | G6: 11870000 | H6: =G6/$G$5 -> 0.033199023 | J6: =IFERROR(I6/$I$5,"") | L6: =IFERROR(K6/$K$5,"")
B7: 給料手当 | C7: 64348988 | D7: =C7/$C$5 -> 0.1974701 | E7: 65194441 | F7: =E7/$E$5 -> 0.1881179 | G7: 64753816 | H7: =G7/$G$5 -> 0.18110897 | J7: =IFERROR(I7/$I$5,"") | L7: =IFERROR(K7/$K$5,"")
B8: 賞与 | C8: 3549000 | D8: =C8/$C$5 -> 0.010890947 | E8: 3405000 | F8: =E8/$E$5 -> 0.0098250931 | G8: 3197000 | H8: =G8/$G$5 -> 0.0089416409 | J8: =IFERROR(I8/$I$5,"") | L8: =IFERROR(K8/$K$5,"")
B9: 退職金 | C9: 370000 | D9: =C9/$C$5 -> 0.0011354326 | F9: =E9/$E$5 -> 0 | H9: =G9/$G$5 -> 0 | J9: =IFERROR(I9/$I$5,"") | L9: =IFERROR(K9/$K$5,"")
B10: 法定福利費 | C10: 11424051 | D10: =C10/$C$5 -> 0.035057405 | E10: 12207732 | F10: =E10/$E$5 -> 0.035225288 | G10: 10842135 | H10: =G10/$G$5 -> 0.030324203 | J10: =IFERROR(I10/$I$5,"") | L10: =IFERROR(K10/$K$5,"")
B11: 福利厚生費 | C11: 1851569 | D11: =C11/$C$5 -> 0.0056819778 | E11: 2218165 | F11: =E11/$E$5 -> 0.0064004927 | G11: 2913601 | H11: =G11/$G$5 -> 0.0081490065 | J11: =IFERROR(I11/$I$5,"") | L11: =IFERROR(K11/$K$5,"")
B12: 採用教育費 | C12: 291360 | D12: =C12/$C$5 -> 0.00089410714 | E12: 184800 | F12: =E12/$E$5 -> 0.00053323854 | G12: 88700 | H12: =G12/$G$5 -> 0.00024808369 | J12: =IFERROR(I12/$I$5,"") | L12: =IFERROR(K12/$K$5,"")
B13: 広告宣伝費 | C13: 1200593 | D13: =C13/$C$5 -> 0.0036843039 | E13: 1208388 | F13: =E13/$E$5 -> 0.0034867914 | G13: 1053123 | H13: =G13/$G$5 -> 0.0029454638 | J13: =IFERROR(I13/$I$5,"") | L13: =IFERROR(K13/$K$5,"")
B14: 接待交際費 | C14: 547960 | D14: =C14/$C$5 -> 0.001681545 | E14: 180010 | F14: =E14/$E$5 -> 0.00051941704 | G14: 86721 | H14: =G14/$G$5 -> 0.00024254865 | J14: =IFERROR(I14/$I$5,"") | L14: =IFERROR(K14/$K$5,"")
B15: 会議費 | C15: 272805 | D15: =C15/$C$5 -> 0.00083716673 | E15: 366979 | F15: =E15/$E$5 -> 0.0010589142 | G15: 459575 | H15: =G15/$G$5 -> 0.0012853784 | J15: =IFERROR(I15/$I$5,"") | L15: =IFERROR(K15/$K$5,"")
B16: 旅費交通費 | C16: 2801560 | D16: =C16/$C$5 -> 0.0085972501 | E16: 2701132 | F16: =E16/$E$5 -> 0.0077940891 | G16: 2770899 | H16: =G16/$G$5 -> 0.0077498855 | J16: =IFERROR(I16/$I$5,"") | L16: =IFERROR(K16/$K$5,"")
B17: 通信費 | C17: 1043002 | D17: =C17/$C$5 -> 0.0032006986 | E17: 1254118 | F17: =E17/$E$5 -> 0.0036187448 | G17: 1367473 | H17: =G17/$G$5 -> 0.0038246645 | J17: =IFERROR(I17/$I$5,"") | L17: =IFERROR(K17/$K$5,"")
B18: 消耗品費 | C18: 2345684 | D18: =C18/$C$5 -> 0.0071982867 | E18: 4467693 | F18: =E18/$E$5 -> 0.012891483 | G18: 3124510 | H18: =G18/$G$5 -> 0.0087388947 | J18: =IFERROR(I18/$I$5,"") | L18: =IFERROR(K18/$K$5,"")
B19: 事務用消耗品費 | C19: 1991419 | D19: =C19/$C$5 -> 0.0061111407 | E19: 1929685 | F19: =E19/$E$5 -> 0.0055680866 | G19: 1771435 | H19: =G19/$G$5 -> 0.0049544997 | J19: =IFERROR(I19/$I$5,"") | L19: =IFERROR(K19/$K$5,"")
B20: 修繕費 | C20: 805390 | D20: =C20/$C$5 -> 0.0024715299 | E20: 926390 | F20: =E20/$E$5 -> 0.002673089 | G20: 532686 | H20: =G20/$G$5 -> 0.0014898614 | J20: =IFERROR(I20/$I$5,"") | L20: =IFERROR(K20/$K$5,"")
B21: 水道光熱費 | C21: 1033592 | D21: =C21/$C$5 -> 0.0031718218 | E21: 1113959 | F21: =E21/$E$5 -> 0.0032143175 | G21: 1037468 | H21: =G21/$G$5 -> 0.0029016785 | J21: =IFERROR(I21/$I$5,"") | L21: =IFERROR(K21/$K$5,"")
... B34: 管理諸費 | C34: 3649888 | D34: =C34/$C$5 -> 0.011200545 | E34: 3432539 | F34: =E34/$E$5 -> 0.0099045567 | G34: 3705328 | H34: =G34/$G$5 -> 0.010363376 | J34: =IFERROR(I34/$I$5,"") | L34: =IFERROR(K34/$K$5,"")
D35: =C35/$C$5 -> 0 | F35: =E35/$E$5 -> 0 | H35: =G35/$G$5 -> 0 | J35: =IFERROR(I35/$I$5,"") | L35: =IFERROR(K35/$K$5,"")
D36: =C36/$C$5 -> 0 | F36: =E36/$E$5 -> 0 | H36: =G36/$G$5 -> 0 | J36: =IFERROR(I36/$I$5,"") | L36: =IFERROR(K36/$K$5,"")
D37: =C37/$C$5 -> 0 | F37: =E37/$E$5 -> 0 | H37: =G37/$G$5 -> 0 | J37: =IFERROR(I37/$I$5,"") | L37: =IFERROR(K37/$K$5,"")
D38: =C38/$C$5 -> 0 | F38: =E38/$E$5 -> 0 | H38: =G38/$G$5 -> 0 | J38: =IFERROR(I38/$I$5,"") | L38: =IFERROR(K38/$K$5,"")
D39: =C39/$C$5 -> 0 | F39: =E39/$E$5 -> 0 | H39: =G39/$G$5 -> 0 | J39: =IFERROR(I39/$I$5,"") | L39: =IFERROR(K39/$K$5,"")
B40: 販売費および一般管理費合計 | C40: =SUM(C6:C39) -> 145464229 | D40: =C40/C5 -> 0.44639143 | E40: =SUM(E6:E39) -> 154261272 | F40: =E40/E5 -> 0.44511934 | G40: =SUM(G6:G39) -> 147845764 | H40: =G40/G5 -> 0.41350758 | I40: =SUM(I6:I39) -> 0 | J40: =IFERROR(I40/I5,"") | K40: =SUM(K6:K39) -> 0 | L40: =IFERROR(K40/K5,"")

Sheet VR→ 

Sheet 株式価値 
A1: 作業不要（自動作成）
F2: (単位：千円)
C3: min | D3: 差（グラフ作成用） | E3: max
B4: インカム | C4: 0 | D4: 0 | E4: 0 | F4: 100 | I4: ｚ
B5: マーケット | C5: ='EV EBITDAマルチプル'!K7 -> 1069000000 | D5: =E5-C5 -> 546000000 | E5: ='EV EBITDAマルチプル'!M7 -> 1615000000 | F5: 0
B6: コスト | C6: =年買法!K6 -> 571000000 | D6: =E6-C6 -> 542000000 | E6: =年買法!M6 -> 1113000000 | F6: 0

Sheet 修正BS(借方)
E2: (単位：千円)
B3: 資産の部
B4: 科目 | C4: ='BS(借方)'!E4 -> 25年12月期 | D4: 修正額 | E4: 修正後
B5: 【流動資産】 | C5: =SUM(C6:C19) -> 141385419 | D5: =SUM(D6:D19) -> 0 | E5: =C5+D5 -> 141385419
B6: ='BS(借方)'!B6 -> 現金及び預金 | C6: ='BS(借方)'!E6 -> 61842402 | E6: =C6+D6 -> 61842402
B7: ='BS(借方)'!B7 -> 商品 | C7: ='BS(借方)'!E7 -> 26584168 | E7: =C7+D7 -> 26584168
B8: ='BS(借方)'!B8 -> 貯蔵品 | C8: ='BS(借方)'!E8 -> 619688 | E8: =C8+D8 -> 619688
B9: ='BS(借方)'!B9 -> 前払費用 | C9: ='BS(借方)'!E9 -> 161700 | E9: =C9+D9 -> 161700
B10: ='BS(借方)'!B10 -> 未収入金 | C10: ='BS(借方)'!E10 -> 52401281 | E10: =C10+D10 -> 52401281
B11: ='BS(借方)'!B11 -> 貸倒引当金 | C11: ='BS(借方)'!E11 -> -524000 | D11: =-C11 | E11: =C11+D11 -> -524000
B12: ='BS(借方)'!B12 -> 仮払金 | C12: ='BS(借方)'!E12 -> 180 | E12: =C12+D12 -> 180
B13: ='BS(借方)'!B13 -> 前払金 | C13: ='BS(借方)'!E13 -> 300000 | E13: =C13+D13 -> 300000
B14: ='BS(借方)'!B14 -> 未収還付法人税等 | C14: ='BS(借方)'!E14 -> 0 | E14: =C14+D14 -> 0
B15: ='BS(借方)'!B15 -> 0 | C15: ='BS(借方)'!E15 -> 0 | E15: =C15+D15 -> 0
B16: ='BS(借方)'!B16 -> 0 | C16: ='BS(借方)'!E16 -> 0 | E16: =C16+D16 -> 0
B17: ='BS(借方)'!B17 -> 0 | C17: ='BS(借方)'!E17 -> 0 | E17: =C17+D17 -> 0
B18: ='BS(借方)'!B18 -> 0 | C18: ='BS(借方)'!E18 -> 0 | E18: =C18+D18 -> 0
E19: =C19+D19 -> 0
B20: 【固定資産】 | C20: =C21+C35+C46 -> 19843083 | D20: =D21+D35+D46 -> 0 | E20: =C20+D20 -> 19843083
B21: ［有形固定資産］ | C21: =SUM(C22:C34) -> 7402395 | D21: =SUM(D22:D34) -> 0 | E21: =C21+D21 -> 7402395
B22: ='BS(借方)'!B22 -> 建物附属設備 | C22: ='BS(借方)'!E22 -> 5361688 | E22: =C22+D22 -> 5361688
B23: ='BS(借方)'!B23 -> 工具器具備品 | C23: ='BS(借方)'!E23 -> 2040707 | E23: =C23+D23 -> 2040707
B24: ='BS(借方)'!B24 -> 0 | C24: ='BS(借方)'!E24 -> 0 | E24: =C24+D24 -> 0
B25: ='BS(借方)'!B25 -> 0 | C25: ='BS(借方)'!E25 -> 0 | E25: =C25+D25 -> 0
B26: ='BS(借方)'!B26 -> 0 | C26: ='BS(借方)'!E26 -> 0 | E26: =C26+D26 -> 0
B27: ='BS(借方)'!B27 -> 0 | C27: ='BS(借方)'!E27 -> 0 | E27: =C27+D27 -> 0
B28: ='BS(借方)'!B28 -> 0 | C28: ='BS(借方)'!E28 -> 0 | E28: =C28+D28 -> 0
B29: ='BS(借方)'!B29 -> 0 | C29: ='BS(借方)'!E29 -> 0 | E29: =C29+D29 -> 0
B30: ='BS(借方)'!B30 -> 0 | C30: ='BS(借方)'!E30 -> 0 | E30: =C30+D30 -> 0
B31: ='BS(借方)'!B31 -> 0 | C31: ='BS(借方)'!E31 -> 0 | E31: =C31+D31 -> 0
B32: ='BS(借方)'!B32 -> 0 | C32: ='BS(借方)'!E32 -> 0 | E32: =C32+D32 -> 0
B33: ='BS(借方)'!B33 -> 0 | C33: ='BS(借方)'!E33 -> 0 | E33: =C33+D33 -> 0
E34: =C34+D34 -> 0
B35: ［無形固定資産］ | C35: =SUM(C36:C45) -> 4816004 | D35: =SUM(D36:D45) -> 0 | E35: =C35+D35 -> 4816004
B36: ='BS(借方)'!B36 -> ソフトウェア | C36: ='BS(借方)'!E36 -> 4816004 | E36: =C36+D36 -> 4816004
B37: ='BS(借方)'!B37 -> 0 | C37: ='BS(借方)'!E37 -> 0 | E37: =C37+D37 -> 0
B38: ='BS(借方)'!B38 -> 0 | C38: ='BS(借方)'!E38 -> 0 | E38: =C38+D38 -> 0
B39: ='BS(借方)'!B39 -> 0 | C39: ='BS(借方)'!E39 -> 0 | E39: =C39+D39 -> 0
B40: ='BS(借方)'!B40 -> 0 | C40: ='BS(借方)'!E40 -> 0 | E40: =C40+D40 -> 0
E41: =C41+D41 -> 0
...

Sheet 売掛・棚卸
E2: (単位：千円)
A3: 未収入金 | B3: 相手先 | C3: 帳簿価額 | D3: 評価差額 | E3: 評価額 | F3: 調整事由
B4: 社会保険診療報酬支払基金（神奈川県） | C4: 35166706 | D4: 0 | E4: =SUM(C4,D4) -> 0 | F4: 診療報酬の請求債権。公的保険者に対する債権であり貸倒リスクは実質的にないため帳簿価額により評価する。
B5: 神奈川県国民健康保険団体連合会 | C5: 16411998 | D5: 0 | E5: =SUM(C5,D5) -> 3087.5 | F5: 診療報酬16,270,584円及び介護給付費141,414円。同上。
B6: その他（㈱パーク24・窓口未収金等） | C6: 822577 | D6: 0 | E6: =SUM(C6,D6) -> 8287 | F6: ㈱パーク24 546千円ほか小口7件。内容は要確認。
E7: =SUM(C7,D7) -> 88980
B8: 合計 | C8: =SUM(C4:C7) -> 125963 | D8: =SUM(D4:D7) -> -25608.5 | E8: =C8+D8 -> 100354.5
E12: (単位：千円)
A13: 商品在庫 | B13: 相手先 | C13: 帳簿価額 | D13: 評価差額 | E13: 評価額 | F13: 調整事由
B14: 商品（薬品等） | C14: 26584168 | D14: 0 | E14: =SUM(C14,D14) | F14: 内訳書上は「薬品等（明細書会社保存）」の一括表示。品目別明細・使用期限別の滞留状況が未確認のため帳簿価額により評価する（要確認）。評価方法は最終仕入原価法。
B15: 貯蔵品（薬袋等） | C15: 619688 | D15: 0 | E15: =SUM(C15,D15) | F15: 長期滞留在庫であり、0円評価とする
E16: =SUM(C16,D16)
E17: =SUM(C17,D17)
B18: 合計 | C18: =SUM(C14:C17) -> 400447 | D18: =SUM(D14:D17) -> -130922 | E18: =C18+D18 -> 269525

Sheet 減価償却
E2: (単位：千円)
B3: 資産 | C3: 帳簿価額 | D3: 評価差額 | E3: 評価額 | F3: 調整事由
B4: 建物附属設備 | C4: 5361688 | D4: 0 | E4: =SUM(C4,D4) -> 0 | F4: 固定資産台帳が未受領のため個別資産の償却過不足の検証は未実施。税法基準（定率法・建物附属設備は定額法、ソフトウェアは定額法）により継続的に償却されており、帳簿価額により評価する（要確認）。店舗はいずれも賃借であり、有形固定資産の大宗は内装造作と推察される。
B5: 工具器具備品 | C5: 2040707 | D5: 0 | E5: =SUM(C5,D5) -> 3087.5 | F5: 消却不足額を減額
B6: ソフトウェア | C6: 4816004 | D6: 0 | E6: =SUM(C6,D6) -> 8287 | F6: 消却不足額を減額
E7: =SUM(C7,D7) -> 88980
B8: 合計 | C8: =SUM(C4:C7) -> 125963 | D8: =SUM(D4:D7) -> -25608.5 | E8: =C8+D8 -> 100354.5

Sheet 土地
F2: (単位：千円)
B3: 内容・所在地 | C3: 地積(㎡) | D3: 帳簿価額 | E3: 評価差額 | F3: 時価評価額 | G3: 調整事由
B4: 該当なし | C4: 500 | D4: 5000000 | E4: =F4-D4 -> -2000000 | F4: 3000000 | G4: 対象会社は土地・建物等の不動産を保有していない。店舗3件・駐車場4件はいずれも賃借（地代家賃等の内訳書により確認）。したがって不動産の時価評価は実施していない。
E5: =F5-D5 -> 2000000
E6: =F6-D6 -> 2000000
E7: =F7-D7 -> 0
B8: 合計 | C8: =SUM(C4:C7) -> 1000 | D8: =SUM(D4:D7) -> 15000000 | E8: =SUM(E4:E7) -> 2000000 | F8: =SUM(F4:F7) -> 17000000

Sheet 保険
E2: (単位：千円)
B3: 保険商品 | C3: 帳簿価額 | D3: 評価差額 | E3: 評価額 | F3: 調整事由
B4: 中小企業倒産防止共済（簿外） | C4: 0 | D4: =E4-C4 -> 5000000 | E4: 0 | F4: 令和7年12月期BSに保険積立金の計上はないが、雑益の内訳書に「倒産防止共済金 前納減額金 9,720円」の計上があり、掛金を全額損金算入している簿外の積立が存在すると認められる。解約手当金額（最大800万円）は時価純資産の加算要素となるため、加入時期・掛金月額・納付済掛金総額を要確認。金額が特定できないため本評価では未計上とする。
B5: 生命保険等 | C5: 0 | E5: 0 | F5: 保険料1,603千円（令和7年12月期）の内訳・保険証券が未受領のため、掛捨て以外の積立性保険の有無は未確認（要確認）。
B8: 合計 | C8: =SUM(C4:C7) -> 10000000 | D8: =SUM(D4:D7) -> 5000000 | E8: =C8+D8 -> 15000000

Sheet 有価証券
F2: (単位：千円)
B3: 銘柄 | C3: 数量 | D3: 帳簿価額 | E3: 評価差額 | F3: 評価額 | G3: 調整事由
B4: 該当なし | C4: 1000 | D4: 0 | E4: =F4-D4 -> 5000000 | F4: 0 | G4: 令和7年12月期BSに有価証券・投資有価証券の計上はない。貸付金及び受取利息の内訳書上、役員貸付金・従業員貸付金の計上もない。
E5: =F5-D5 -> 3000000
E7: =F7-D7 -> 0
E8: =F8-D8 -> 0
B9: 合計 | C9: - | D9: =SUM(D4:D8) -> 20000000 | E9: =SUM(E4:E8) -> 8000000 | F9: =D9+E9 -> 28000000

Sheet 修正BS(貸方) 
E2: (単位：千円)
B3: 負債の部
B4: 科目 | C4: ='修正BS(借方)'!C4 -> 25年12月期 | D4: 修正額 | E4: 修正後
B5: 【流動負債】 | C5: =SUM(C6:C17) -> 41577715 | D5: =SUM(D6:D17) -> 0 | E5: =C5+D5 -> 41577715
B6: ='BS (貸方)'!B6 -> 買掛金 | C6: ='BS (貸方)'!E6 -> 26935462 | E6: =C6+D6 -> 26935462
B7: ='BS (貸方)'!B7 -> 短期借入金 | C7: ='BS (貸方)'!E7 -> 8000000 | E7: =C7+D7 -> 8000000
B8: ='BS (貸方)'!B8 -> 未払金 | C8: ='BS (貸方)'!E8 -> 3541353 | E8: =C8+D8 -> 3541353
B9: ='BS (貸方)'!B9 -> 未払法人税等 | C9: ='BS (貸方)'!E9 -> 3100900 | E9: =C9+D9 -> 3100900
B10: ='BS (貸方)'!B10 -> 0 | C10: ='BS (貸方)'!E10 -> 0 | E10: =C10+D10 -> 0
B11: ='BS (貸方)'!B11 -> 0 | C11: ='BS (貸方)'!E11 -> 0 | E11: =C11+D11 -> 0
B12: ='BS (貸方)'!B12 -> 0 | C12: ='BS (貸方)'!E12 -> 0 | E12: =C12+D12 -> 0
B13: ='BS (貸方)'!B13 -> 0 | C13: ='BS (貸方)'!E13 -> 0 | E13: =C13+D13 -> 0
B14: ='BS (貸方)'!B14 -> 0 | C14: ='BS (貸方)'!E14 -> 0 | E14: =C14+D14 -> 0
B15: ='BS (貸方)'!B15 -> 0 | C15: ='BS (貸方)'!E15 -> 0 | E15: =C15+D15 -> 0
B16: ='BS (貸方)'!B16 -> 0 | C16: ='BS (貸方)'!E16 -> 0 | E16: =C16+D16 -> 0
E17: =C17+D17 -> 0
B18: 【固定負債】 | C18: =SUM(C19:C26) -> 47200000 | D18: =SUM(D19:D26) -> 0 | E18: =C18+D18 -> 47200000
B19: ='BS (貸方)'!B19 -> 長期借入金 | C19: ='BS (貸方)'!E19 -> 47200000 | E19: =C19+D19 -> 47200000
B20: ='BS (貸方)'!B20 -> 0 | C20: ='BS (貸方)'!E20 -> 0 | E20: =C20+D20 -> 0
B21: ='BS (貸方)'!B21 -> 0 | C21: ='BS (貸方)'!E21 -> 0 | E21: =C21+D21 -> 0
B22: ='BS (貸方)'!B22 -> 0 | C22: ='BS (貸方)'!E22 -> 0 | E22: =C22+D22 -> 0
B23: ='BS (貸方)'!B23 -> 0 | C23: ='BS (貸方)'!E23 -> 0 | E23: =C23+D23 -> 0
E24: =C24+D24 -> 0
E25: =C25+D25 -> 0
E26: =C26+D26 -> 0
B27: 【繰延税金負債】 | C27: 0 | D27: =ROUND(MAX(0,('修正BS(借方)'!D5+'修正BS(借方)'!D20+'修正BS(借方)'!D56-('修正BS(貸方) '!D5+'修正BS(貸方) '!D18))*0.34),0) | E27: =C27+D27 -> 0
B28: 負債合計 | C28: =C5+C18+C27 -> 88777715 | D28: =D5+D18+D27 -> 0 | E28: =C28+D28 -> 88777715
B34: 純資産の部
B35: 【資本金】 | C35: =SUM(C36:C38) -> 9000000 | D35: =SUM(D36:D38) -> 0 | E35: =C35+D35 -> 9000000
B36: ='BS (貸方)'!B36 -> 資本金 | C36: ='BS (貸方)'!E36 -> 9000000 | E36: =C36+D36 -> 9000000
E37: =C37+D37 -> 0
E38: =C38+D38 -> 0
B39: 【資本剰余金】 | C39: =SUM(C40:C42) -> 1000000 | D39: =SUM(D40:D42) -> 0 | E39: =C39+D39 -> 1000000
B40: ='BS (貸方)'!B40 -> 資本準備金 | C40: ='BS (貸方)'!E40 -> 1000000 | E40: =C40+D40 -> 1000000
E41: =C41+D41 -> 0
E42: =C42+D42 -> 0
B43: 【利益剰余金】 | C43: =SUM(C44:C47) -> 62450787 | D43: =SUM(D44:D47) -> 0 | E43: =C43+D43 -> 62450787
B44: ='BS (貸方)'!B44 -> 繰越利益剰余金 | C44: ='BS (貸方)'!E44 -> 62450787 | E44: =C44+D44 -> 62450787
B45: ='BS (貸方)'!B45 -> 0 | C45: ='BS (貸方)'!E45 -> 0 | E45: =C45+D45 -> 0
B46: ='BS (貸方)'!B46 -> 0 | C46: ='BS (貸方)'!E46 -> 0 | E46: =C46+D46 -> 0
...

Sheet 未払人件費・賞与
D2: (単位：千円) | E2: (単位：千円) | F2: (単位：千円)
B3: ●年●月支払給与 | C3: 未払日数 | D3: 未払給与引当額 | E3: 概算社会保険料 | F3: 未払給与引当額
B4: － | C4: － | D4: － | E4: － | F4: －
B6: 就業規則・賃金規程（給与の締日・支払日）が未受領のため、未払給与の引当不足額は算定不能。要確認事項として整理し、本評価では未計上とする。
E7: (単位：千円)
B8: ●年●月支払予定賞与 | C8: 支給対象月数 | D8: 経過月数 | E8: 引当額 | F8: 概算社会保険料 | G8: 社保考慮後引当不足
B9: － | C9: － | D9: － | E9: － | F9: － | G9: －
B11: 未払金の内訳書に「港北年金事務所 2,349,413円（11月分・賞与分社会保険料）」の計上があり、賞与に係る社会保険料は未払計上されている。賞与支給規程・支給月が未確認のため賞与引当不足額は算定不能。本評価では未計上とする（要確認）。

Sheet 退職金
J2: (単位：千円)
B3: № | C3: 氏名 | D3: 勤続年数(年) | E3: 基本給 | F3: 支給倍率 | G3: 退職理由率 | H3: 要支給額 | I3: 中退共積立額 | J3: 引当不足
B4: 1 | C4: －
B5: 2
B6: 3
B7: 4
B8: 5
C10: 合計 | H10: =SUM(H6:H9) -> 0 | I10: =SUM(I6:I9) -> 0 | J10: =H10+I10 -> 0
B12: 退職金規程・従業員名簿が未受領のため退職給付引当不足額は算定不能。令和5年12月期に退職金370千円の支給実績があり、規程の有無を含め要確認。本評価では未計上とする。

Sheet 税効果
E2: (単位：千円)
B3: 修正科目 | C3: 適用判定 | D3: 修正額 | E3: 繰延税金資産/負債 | F3: 備考
B4: 貸倒引当金 | C4: 〇 | D4: 524000 | E4: =-D4*0.34 | F4: 全額戻入。将来加算一時差異
B5: 長期前払費用 | C5: 〇 | D5: -985404 | E5: =-D5*0.34 | F5: 賃貸借契約の更新料の未償却分を全額控除。将来減算一時差異
B6: 未収入金 | C6: 〇 | E6: =-D6*0.34 | F6: 98.4%が社会保険診療報酬支払基金・国保連に対する債権であり簿価評価
B7: 商品・貯蔵品 | C7: 〇 | E7: =-D7*0.34 | F7: 品目別明細・滞留状況が未確認のため簿価評価（要確認）
B8: 減価償却資産 | C8: 〇 | E8: =-D8*0.34 | F8: 固定資産台帳が未受領のため償却過不足未検証（要確認）
B9: ソフトウェア | C9: 〇 | E9: =-D9*0.34 | F9: 自社利用の業務システムであり、事業継続を前提に簿価評価
B10: 差入保証金 | C10: 〇 | E10: =-D10*0.34 | F10: 店舗・駐車場7件の保証金。返還条件・原状回復義務が未確認のため簿価評価（要確認）
B11: 倒産防止共済（簿外） | C11: 〇 | E11: =-D11*0.34 | F11: 解約手当金額が未確認のため未計上。判明後は加算要素（要確認）
B12: 未払給与（未払残業代） | C12: 〇 | E12: =-D12*0.34 | F12: 就業規則・賃金規程が未受領のため未計上（要確認）
B13: 賞与引当金 | C13: 〇 | E13: =-D13*0.34 | F13: 賞与に係る社会保険料は未払計上済。引当不足額は未確認のため未計上（要確認）
B14: 退職給付引当金 | C14: 〇 | E14: =-D14*0.34 | F14: 退職金規程が未受領のため未計上（要確認）
E15: =-D15*0.34
E16: =-D16*0.34
E17: =-D17*0.34
B18: 合計 | C18: - | D18: =SUM(D4:D17) -> -5000000 | E18: =SUM(E4:E17) -> 1700000 | F18: 修正額の純額は△461千円（貸倒引当金の戻入524千円－長期前払費用の控除985千円）であり、実効税率34%による繰延税金資産157千円を修正貸借対照表上の【繰延税金資産】に計上している。

Sheet ネットキャッシュ
F2: (単位：千円)
B3: キャッシュライクアイテム | C3: 金額 | E3: デットライクアイテム | F3: 金額
B4: 現金及び預金 | C4: ='修正BS(借方)'!E6 | E4: 短期借入金 | F4: ='修正BS(貸方) '!E7
E5: 長期借入金 | F5: ='修正BS(貸方) '!E19
B13: 合計 | C13: =SUM(C4:C12) -> 0 | E13: 合計 | F13: =SUM(F4:F12) -> 0
B15: ネットキャッシュ | C15: =C13-F13 -> 0

Sheet 修正PL
K2: (単位：千円)
B3: 科目 | C3: ='BS(借方)'!C4 -> 23年12月期 | F3: ='BS(借方)'!D4 -> 24年12月期 | I3: ='BS(借方)'!E4 -> 25年12月期 | L3: ='BS(借方)'!F4 -> ●●年●月期 | O3: ='BS(借方)'!G4 -> ●●年●月 （●か月TB）
C4: 帳簿価額 | D4: 修正額 | E4: 修正後 | F4: 帳簿価額 | G4: 修正額 | H4: 修正後 | I4: 帳簿価額 | J4: 修正額 | K4: 修正後 | L4: 帳簿価額 | M4: 修正額 | N4: 修正後 | O4: 帳簿価額 | P4: 修正額 | Q4: 修正後
B5: =PL!B5 -> 売上高 | C5: =PL!C5 -> 325866987 | E5: =C5+D5 -> 325866987 | F5: =PL!E5 -> 346561600 | H5: =F5+G5 -> 346561600 | I5: =PL!G5 -> 357540639 | K5: =I5+J5 -> 357540639 | L5: =PL!I5 -> 0 | N5: =L5+M5 -> 0 | O5: =PL!K5 -> 0 | Q5: =O5+P5 -> 0
B6: =PL!B6 -> 0 | C6: =PL!C6 -> 0 | E6: =C6+D6 -> 0 | F6: =PL!E6 -> 0 | H6: =F6+G6 -> 0 | I6: =PL!G6 -> 0 | K6: =I6+J6 -> 0 | L6: =PL!I6 -> 0 | N6: =L6+M6 -> 0 | O6: =PL!K6 -> 0 | Q6: =O6+P6 -> 0
B7: =PL!B7 -> 0 | C7: =PL!C7 -> 0 | E7: =C7+D7 -> 0 | F7: =PL!E7 -> 0 | H7: =F7+G7 -> 0 | I7: =PL!G7 -> 0 | K7: =I7+J7 -> 0 | L7: =PL!I7 -> 0 | N7: =L7+M7 -> 0 | O7: =PL!K7 -> 0 | Q7: =O7+P7 -> 0
B8: =PL!B8 -> 0 | C8: =PL!C8 -> 0 | E8: =C8+D8 -> 0 | F8: =PL!E8 -> 0 | H8: =F8+G8 -> 0 | I8: =PL!G8 -> 0 | K8: =I8+J8 -> 0 | L8: =PL!I8 -> 0 | N8: =L8+M8 -> 0 | O8: =PL!K8 -> 0 | Q8: =O8+P8 -> 0
B9: =PL!B9 -> 0 | C9: =PL!C9 -> 0 | E9: =C9+D9 -> 0 | F9: =PL!E9 -> 0 | H9: =F9+G9 -> 0 | I9: =PL!G9 -> 0 | K9: =I9+J9 -> 0 | L9: =PL!I9 -> 0 | N9: =L9+M9 -> 0 | O9: =PL!K9 -> 0 | Q9: =O9+P9 -> 0
E10: =C10+D10 -> 0 | H10: =F10+G10 -> 0 | K10: =I10+J10 -> 0 | N10: =L10+M10 -> 0 | Q10: =O10+P10 -> 0
B11: 売上高 | C11: =SUM(C5:C10) -> 325866987 | D11: =SUM(D5:D10) -> 0 | E11: =C11+D11 -> 325866987 | F11: =SUM(F5:F10) -> 346561600 | G11: =SUM(G5:G10) -> 0 | H11: =F11+G11 -> 346561600 | I11: =SUM(I5:I10) -> 357540639 | J11: =SUM(J5:J10) -> 0 | K11: =I11+J11 -> 357540639 | L11: =SUM(L5:L10) -> 0 | M11: =SUM(M5:M10) -> 0 | N11: =L11+M11 -> 0 | O11: =SUM(O5:O10) -> 0 | P11: =SUM(P5:P10) -> 0 | Q11: =O11+P11 -> 0
B12: =PL!B12 -> 期首商品棚卸高 | C12: =PL!C12 -> 28930577 | E12: =C12+D12 -> 28930577 | F12: =PL!E12 -> 32079836 | H12: =F12+G12 -> 32079836 | I12: =PL!G12 -> 30240016 | K12: =I12+J12 -> 30240016 | L12: =PL!I12 -> 0 | N12: =L12+M12 -> 0 | O12: =PL!K12 -> 0 | Q12: =O12+P12 -> 0
B13: =PL!B13 -> 当期商品仕入高 | C13: =PL!C13 -> 162685310 | E13: =C13+D13 -> 162685310 | F13: =PL!E13 -> 179686065 | H13: =F13+G13 -> 179686065 | I13: =PL!G13 -> 193114742 | K13: =I13+J13 -> 193114742 | L13: =PL!I13 -> 0 | N13: =L13+M13 -> 0 | O13: =PL!K13 -> 0 | Q13: =O13+P13 -> 0
B14: =PL!B14 -> 仕入値引戻し高 | C14: =PL!C14 -> -18920 | E14: =C14+D14 -> -18920 | F14: =PL!E14 -> 0 | H14: =F14+G14 -> 0 | I14: =PL!G14 -> 0 | K14: =I14+J14 -> 0 | L14: =PL!I14 -> 0 | N14: =L14+M14 -> 0 | O14: =PL!K14 -> 0 | Q14: =O14+P14 -> 0
B15: =PL!B15 -> 期末商品棚卸高 | C15: =PL!C15 -> -32079836 | E15: =C15+D15 -> -32079836 | F15: =PL!E15 -> -30240016 | H15: =F15+G15 -> -30240016 | I15: =PL!G15 -> -26584168 | K15: =I15+J15 -> -26584168 | L15: =PL!I15 -> 0 | N15: =L15+M15 -> 0 | O15: =PL!K15 -> 0 | Q15: =O15+P15 -> 0
B16: 売上原価 | C16: =SUM(C12:C15) -> 159517131 | D16: =SUM(D12:D15) -> 0 | E16: =C16+D16 -> 159517131 | F16: =SUM(F12:F15) -> 181525885 | G16: =SUM(G12:G15) -> 0 | H16: =F16+G16 -> 181525885 | I16: =SUM(I12:I15) -> 196770590 | J16: =SUM(J12:J15) -> 0 | K16: =I16+J16 -> 196770590 | L16: =SUM(L12:L15) -> 0 | M16: =SUM(M12:M15) -> 0 | N16: =L16+M16 -> 0 | O16: =SUM(O12:O15) -> 0 | P16: =SUM(P12:P15) -> 0 | Q16: =O16+P16 -> 0
B17: 売上総利益 | C17: =C11-C16 -> 166349856 | D17: =D11-D16 -> 0 | E17: =C17+D17 -> 166349856 | F17: =F11-F16 -> 165035715 | G17: =G11-G16 -> 0 | H17: =F17+G17 -> 165035715 | I17: =I11-I16 -> 160770049 | J17: =J11-J16 -> 0 | K17: =I17+J17 -> 160770049 | L17: =L11-L16 -> 0 | M17: =M11-M16 -> 0 | N17: =L17+M17 -> 0 | O17: =O11-O16 -> 0 | P17: =P11-P16 -> 0 | Q17: =O17+P17 -> 0
B18: 販売費及び一般管理費 | C18: =修正SGA!C39 -> 145464229 | D18: =修正SGA!D39 | E18: =C18+D18 -> 145464229 | F18: =修正SGA!F39 -> 154261272 | G18: =修正SGA!G39 | H18: =F18+G18 -> 154261272 | I18: =修正SGA!I39 -> 147845764 | J18: =修正SGA!J39 | K18: =I18+J18 -> 147845764 | L18: =修正SGA!L39 -> 0 | N18: =L18+M18 -> 0 | O18: =修正SGA!O39 -> 0 | Q18: =O18+P18 -> 0
B19: 営業利益 | C19: =C17- C18 -> 20885627 | D19: =D17- D18 -> 0 | E19: =C19+D19 -> 20885627 | F19: =F17- F18 -> 10774443 | G19: =G17- G18 -> 0 | H19: =F19+G19 -> 10774443 | I19: =I17- I18 -> 12924285 | J19: =J17- J18 -> 0 | K19: =I19+J19 -> 12924285 | L19: =L17- L18 -> 0 | M19: =M17- M18 -> 0 | N19: =L19+M19 -> 0 | O19: =O17- O18 -> 0 | P19: =P17- P18 -> 0 | Q19: =O19+P19 -> 0
B20: 営業外収益 | C20: =SUM(C21:C27) -> 1273342 | D20: =SUM(D21:D27) -> 0 | E20: =C20+D20 -> 1273342 | F20: =SUM(F21:F27) -> 2398375 | G20: =SUM(G21:G27) -> 0 | H20: =F20+G20 -> 2398375 | I20: =SUM(I21:I27) -> 1051276 | J20: =SUM(J21:J27) -> 0 | K20: =I20+J20 -> 1051276 | L20: =SUM(L21:L27) -> 0 | M20: =SUM(M21:M27) -> 0 | N20: =L20+M20 -> 0 | O20: =SUM(O21:O27) -> 0 | P20: =SUM(P21:P27) -> 0 | Q20: =O20+P20 -> 0
B21: =PL!B21 -> 受取利息 | C21: =PL!C21 -> 292 | D21: =-C21 | E21: =C21+D21 -> 292 | F21: =PL!E21 -> 3285 | G21: =-F21 | H21: =F21+G21 -> 3285 | I21: =PL!G21 -> 76490 | J21: =-I21 | K21: =I21+J21 -> 76490 | L21: =PL!I21 -> 0 | N21: =L21+M21 -> 0 | O21: =PL!K21 -> 0 | Q21: =O21+P21 -> 0
B22: =PL!B22 -> 仕入割引 | C22: =PL!C22 -> 211750 | D22: =-C22 | E22: =C22+D22 -> 211750 | F22: =PL!E22 -> 52250 | G22: =-F22 | H22: =F22+G22 -> 52250 | I22: =PL!G22 -> 0 | J22: =-I22 | K22: =I22+J22 -> 0 | L22: =PL!I22 -> 0 | N22: =L22+M22 -> 0 | O22: =PL!K22 -> 0 | Q22: =O22+P22 -> 0
B23: =PL!B23 -> 貸倒引当金戻入額 | C23: =PL!C23 -> 448000 | D23: =-C23 | E23: =C23+D23 -> 448000 | F23: =PL!E23 -> 457000 | G23: =-F23 | H23: =F23+G23 -> 457000 | I23: =PL!G23 -> 498000 | J23: =-I23 | K23: =I23+J23 -> 498000 | L23: =PL!I23 -> 0 | N23: =L23+M23 -> 0 | O23: =PL!K23 -> 0 | Q23: =O23+P23 -> 0
B24: =PL!B24 -> 雑収入 | C24: =PL!C24 -> 613300 | D24: =-C24 | E24: =C24+D24 -> 613300 | F24: =PL!E24 -> 1885840 | G24: =-F24 | H24: =F24+G24 -> 1885840 | I24: =PL!G24 -> 476786 | J24: =-I24 | K24: =I24+J24 -> 476786 | L24: =PL!I24 -> 0 | N24: =L24+M24 -> 0 | O24: =PL!K24 -> 0 | Q24: =O24+P24 -> 0
B25: =PL!B25 -> 0 | C25: =PL!C25 -> 0 | E25: =C25+D25 -> 0 | F25: =PL!E25 -> 0 | H25: =F25+G25 -> 0 | I25: =PL!G25 -> 0 | K25: =I25+J25 -> 0 | L25: =PL!I25 -> 0 | N25: =L25+M25 -> 0 | O25: =PL!K25 -> 0 | Q25: =O25+P25 -> 0
B26: =PL!B26 -> 0 | C26: =PL!C26 -> 0 | E26: =C26+D26 -> 0 | F26: =PL!E26 -> 0 | H26: =F26+G26 -> 0 | I26: =PL!G26 -> 0 | K26: =I26+J26 -> 0 | L26: =PL!I26 -> 0 | N26: =L26+M26 -> 0 | O26: =PL!K26 -> 0 | Q26: =O26+P26 -> 0
E27: =C27+D27 -> 0 | H27: =F27+G27 -> 0 | K27: =I27+J27 -> 0 | N27: =L27+M27 -> 0 | Q27: =O27+P27 -> 0
B28: 営業外費用 | C28: =SUM(C29:C35) -> 230000 | D28: =SUM(D29:D35) -> 0 | E28: =C28+D28 -> 230000 | F28: =SUM(F29:F35) -> 2287900 | G28: =SUM(G29:G35) -> 0 | H28: =F28+G28 -> 2287900 | I28: =SUM(I29:I35) -> 90040 | J28: =SUM(J29:J35) -> 0 | K28: =I28+J28 -> 90040 | L28: =SUM(L29:L35) -> 0 | M28: =SUM(M29:M35) -> 0 | N28: =L28+M28 -> 0 | O28: =SUM(O29:O35) -> 0 | P28: =SUM(P29:P35) -> 0 | Q28: =O28+P28 -> 0
B29: =PL!B29 -> 支払利息 | C29: =PL!C29 -> 80000 | D29: =-C29 | E29: =C29+D29 -> 80000 | F29: =PL!E29 -> 80000 | G29: =-F29 | H29: =F29+G29 -> 80000 | I29: =PL!G29 -> 80000 | J29: =-I29 | K29: =I29+J29 -> 80000 | L29: =PL!I29 -> 0 | N29: =L29+M29 -> 0 | O29: =PL!K29 -> 0 | Q29: =O29+P29 -> 0
B30: =PL!B30 -> 雑損失 | C30: =PL!C30 -> 150000 | D30: =-C30 | E30: =C30+D30 -> 150000 | F30: =PL!E30 -> 1649900 | G30: =-F30 | H30: =F30+G30 -> 1649900 | I30: =PL!G30 -> 10040 | J30: =-I30 | K30: =I30+J30 -> 10040 | L30: =PL!I30 -> 0 | N30: =L30+M30 -> 0 | O30: =PL!K30 -> 0 | Q30: =O30+P30 -> 0
B31: =PL!B31 -> 固定資産圧縮損 | C31: =PL!C31 -> 0 | D31: =-C31 | E31: =C31+D31 -> 0 | F31: =PL!E31 -> 558000 | G31: =-F31 | H31: =F31+G31 -> 558000 | I31: =PL!G31 -> 0 | J31: =-I31 | K31: =I31+J31 -> 0 | L31: =PL!I31 -> 0 | N31: =L31+M31 -> 0 | O31: =PL!K31 -> 0 | Q31: =O31+P31 -> 0
B32: =PL!B32 -> 0 | C32: =PL!C32 -> 0 | E32: =C32+D32 -> 0 | F32: =PL!E32 -> 0 | H32: =F32+G32 -> 0 | I32: =PL!G32 -> 0 | K32: =I32+J32 -> 0 | L32: =PL!I32 -> 0 | N32: =L32+M32 -> 0 | O32: =PL!K32 -> 0 | Q32: =O32+P32 -> 0
B33: =PL!B33 -> 0 | C33: =PL!C33 -> 0 | E33: =C33+D33 -> 0 | F33: =PL!E33 -> 0 | H33: =F33+G33 -> 0 | I33: =PL!G33 -> 0 | K33: =I33+J33 -> 0 | L33: =PL!I33 -> 0 | N33: =L33+M33 -> 0 | O33: =PL!K33 -> 0 | Q33: =O33+P33 -> 0
B34: =PL!B34 -> 0 | C34: =PL!C34 -> 0 | E34: =C34+D34 -> 0 | F34: =PL!E34 -> 0 | H34: =F34+G34 -> 0 | I34: =PL!G34 -> 0 | K34: =I34+J34 -> 0 | L34: =PL!I34 -> 0 | N34: =L34+M34 -> 0 | O34: =PL!K34 -> 0 | Q34: =O34+P34 -> 0
E35: =C35+D35 -> 0 | H35: =F35+G35 -> 0 | K35: =I35+J35 -> 0 | N35: =L35+M35 -> 0 | Q35: =O35+P35 -> 0
B36: 経常利益 | C36: =C19+C20-C28 -> 21928969 | D36: =D19+D20-D28 -> 0 | E36: =C36+D36 -> 21928969 | F36: =F19+F20-F28 -> 10884918 | G36: =G19+G20-G28 -> 0 | H36: =F36+G36 -> 10884918 | I36: =I19+I20-I28 -> 13885521 | J36: =J19+J20-J28 -> 0 | K36: =I36+J36 -> 13885521 | L36: =L19+L20-L28 -> 0 | M36: =M19+M20-M28 -> 0 | N36: =L36+M36 -> 0 | O36: =O19+O20-O28 -> 0 | P36: =P19+P20-P28 -> 0 | Q36: =O36+P36 -> 0
B37: 特別利益 | C37: =SUM(C38:C43) -> 0 | D37: =SUM(D38:D43) -> 0 | E37: =C37+D37 -> 0 | F37: =SUM(F38:F43) -> 0 | G37: =SUM(G38:G43) -> 0 | H37: =F37+G37 -> 0 | I37: =SUM(I38:I43) -> 0 | J37: =SUM(J38:J43) -> 0 | K37: =I37+J37 -> 0 | L37: =SUM(L38:L43) -> 0 | M37: =SUM(M38:M43) -> 0 | N37: =L37+M37 -> 0 | O37: =SUM(O38:O43) -> 0 | P37: =SUM(P38:P43) -> 0 | Q37: =O37+P37 -> 0
B38: =PL!B38 -> 0 | C38: =PL!C38 -> 0 | E38: =C38+D38 -> 0 | F38: =PL!E38 -> 0 | H38: =F38+G38 -> 0 | I38: =PL!G38 -> 0 | K38: =I38+J38 -> 0 | L38: =PL!I38 -> 0 | N38: =L38+M38 -> 0 | O38: =PL!K38 -> 0 | Q38: =O38+P38 -> 0
B39: =PL!B39 -> 0 | C39: =PL!C39 -> 0 | E39: =C39+D39 -> 0 | F39: =PL!E39 -> 0 | H39: =F39+G39 -> 0 | I39: =PL!G39 -> 0 | K39: =I39+J39 -> 0 | L39: =PL!I39 -> 0 | N39: =L39+M39 -> 0 | O39: =PL!K39 -> 0 | Q39: =O39+P39 -> 0
B40: =PL!B40 -> 0 | C40: =PL!C40 -> 0 | E40: =C40+D40 -> 0 | F40: =PL!E40 -> 0 | H40: =F40+G40 -> 0 | I40: =PL!G40 -> 0 | K40: =I40+J40 -> 0 | L40: =PL!I40 -> 0 | N40: =L40+M40 -> 0 | O40: =PL!K40 -> 0 | Q40: =O40+P40 -> 0
B41: =PL!B41 -> 0 | C41: =PL!C41 -> 0 | E41: =C41+D41 -> 0 | F41: =PL!E41 -> 0 | H41: =F41+G41 -> 0 | I41: =PL!G41 -> 0 | K41: =I41+J41 -> 0 | L41: =PL!I41 -> 0 | N41: =L41+M41 -> 0 | O41: =PL!K41 -> 0 | Q41: =O41+P41 -> 0
...

Sheet 修正SGA
K2: (単位：千円)
B3: 科目 | C3: ='BS(借方)'!C4 -> 23年12月期 | F3: ='BS(借方)'!D4 -> 24年12月期 | I3: ='BS(借方)'!E4 -> 25年12月期 | L3: ='BS(借方)'!F4 -> ●●年●月期 | O3: ='BS(借方)'!G4 -> ●●年●月 （●か月TB）
C4: 帳簿価額 | D4: 修正額 | E4: 修正後 | F4: 帳簿価額 | G4: 修正額 | H4: 修正後 | I4: 帳簿価額 | J4: 修正額 | K4: 修正後 | L4: 帳簿価額 | M4: 修正額 | N4: 修正後 | O4: 帳簿価額 | P4: 修正額 | Q4: 修正後
B5: =SGA!B6 -> 役員報酬 | C5: =SGA!C6 -> 10500000 | E5: =C5+D5 -> 10500000 | F5: =SGA!E6 -> 17120000 | H5: =F5+G5 -> 17120000 | I5: =SGA!G6 -> 11870000 | K5: =I5+J5 -> 11870000 | L5: =SGA!I6 -> 0 | N5: =L5+M5 -> 0 | O5: =SGA!K6 -> 0 | Q5: =O5+P5 -> 0
B6: =SGA!B7 -> 給料手当 | C6: =SGA!C7 -> 64348988 | E6: =C6+D6 -> 64348988 | F6: =SGA!E7 -> 65194441 | H6: =F6+G6 -> 65194441 | I6: =SGA!G7 -> 64753816 | K6: =I6+J6 -> 64753816 | L6: =SGA!I7 -> 0 | N6: =L6+M6 -> 0 | O6: =SGA!K7 -> 0 | Q6: =O6+P6 -> 0
B7: =SGA!B8 -> 賞与 | C7: =SGA!C8 -> 3549000 | E7: =C7+D7 -> 3549000 | F7: =SGA!E8 -> 3405000 | H7: =F7+G7 -> 3405000 | I7: =SGA!G8 -> 3197000 | K7: =I7+J7 -> 3197000 | L7: =SGA!I8 -> 0 | N7: =L7+M7 -> 0 | O7: =SGA!K8 -> 0 | Q7: =O7+P7 -> 0
B8: =SGA!B9 -> 退職金 | C8: =SGA!C9 -> 370000 | D8: =-C8 | E8: =C8+D8 -> 370000 | F8: =SGA!E9 -> 0 | H8: =F8+G8 -> 0 | I8: =SGA!G9 -> 0 | K8: =I8+J8 -> 0 | L8: =SGA!I9 -> 0 | N8: =L8+M8 -> 0 | O8: =SGA!K9 -> 0 | Q8: =O8+P8 -> 0
B9: =SGA!B10 -> 法定福利費 | C9: =SGA!C10 -> 11424051 | E9: =C9+D9 -> 11424051 | F9: =SGA!E10 -> 12207732 | H9: =F9+G9 -> 12207732 | I9: =SGA!G10 -> 10842135 | K9: =I9+J9 -> 10842135 | L9: =SGA!I10 -> 0 | N9: =L9+M9 -> 0 | O9: =SGA!K10 -> 0 | Q9: =O9+P9 -> 0
B10: =SGA!B11 -> 福利厚生費 | C10: =SGA!C11 -> 1851569 | E10: =C10+D10 -> 1851569 | F10: =SGA!E11 -> 2218165 | H10: =F10+G10 -> 2218165 | I10: =SGA!G11 -> 2913601 | K10: =I10+J10 -> 2913601 | L10: =SGA!I11 -> 0 | N10: =L10+M10 -> 0 | O10: =SGA!K11 -> 0 | Q10: =O10+P10 -> 0
B11: =SGA!B12 -> 採用教育費 | C11: =SGA!C12 -> 291360 | E11: =C11+D11 -> 291360 | F11: =SGA!E12 -> 184800 | H11: =F11+G11 -> 184800 | I11: =SGA!G12 -> 88700 | K11: =I11+J11 -> 88700 | L11: =SGA!I12 -> 0 | N11: =L11+M11 -> 0 | O11: =SGA!K12 -> 0 | Q11: =O11+P11 -> 0
B12: =SGA!B13 -> 広告宣伝費 | C12: =SGA!C13 -> 1200593 | E12: =C12+D12 -> 1200593 | F12: =SGA!E13 -> 1208388 | H12: =F12+G12 -> 1208388 | I12: =SGA!G13 -> 1053123 | K12: =I12+J12 -> 1053123 | L12: =SGA!I13 -> 0 | N12: =L12+M12 -> 0 | O12: =SGA!K13 -> 0 | Q12: =O12+P12 -> 0
B13: =SGA!B14 -> 接待交際費 | C13: =SGA!C14 -> 547960 | E13: =C13+D13 -> 547960 | F13: =SGA!E14 -> 180010 | H13: =F13+G13 -> 180010 | I13: =SGA!G14 -> 86721 | K13: =I13+J13 -> 86721 | L13: =SGA!I14 -> 0 | N13: =L13+M13 -> 0 | O13: =SGA!K14 -> 0 | Q13: =O13+P13 -> 0
B14: =SGA!B15 -> 会議費 | C14: =SGA!C15 -> 272805 | E14: =C14+D14 -> 272805 | F14: =SGA!E15 -> 366979 | H14: =F14+G14 -> 366979 | I14: =SGA!G15 -> 459575 | K14: =I14+J14 -> 459575 | L14: =SGA!I15 -> 0 | N14: =L14+M14 -> 0 | O14: =SGA!K15 -> 0 | Q14: =O14+P14 -> 0
B15: =SGA!B16 -> 旅費交通費 | C15: =SGA!C16 -> 2801560 | E15: =C15+D15 -> 2801560 | F15: =SGA!E16 -> 2701132 | H15: =F15+G15 -> 2701132 | I15: =SGA!G16 -> 2770899 | K15: =I15+J15 -> 2770899 | L15: =SGA!I16 -> 0 | N15: =L15+M15 -> 0 | O15: =SGA!K16 -> 0 | Q15: =O15+P15 -> 0
B16: =SGA!B17 -> 通信費 | C16: =SGA!C17 -> 1043002 | E16: =C16+D16 -> 1043002 | F16: =SGA!E17 -> 1254118 | H16: =F16+G16 -> 1254118 | I16: =SGA!G17 -> 1367473 | K16: =I16+J16 -> 1367473 | L16: =SGA!I17 -> 0 | N16: =L16+M16 -> 0 | O16: =SGA!K17 -> 0 | Q16: =O16+P16 -> 0
B17: =SGA!B18 -> 消耗品費 | C17: =SGA!C18 -> 2345684 | E17: =C17+D17 -> 2345684 | F17: =SGA!E18 -> 4467693 | H17: =F17+G17 -> 4467693 | I17: =SGA!G18 -> 3124510 | K17: =I17+J17 -> 3124510 | L17: =SGA!I18 -> 0 | N17: =L17+M17 -> 0 | O17: =SGA!K18 -> 0 | Q17: =O17+P17 -> 0
B18: =SGA!B19 -> 事務用消耗品費 | C18: =SGA!C19 -> 1991419 | E18: =C18+D18 -> 1991419 | F18: =SGA!E19 -> 1929685 | H18: =F18+G18 -> 1929685 | I18: =SGA!G19 -> 1771435 | K18: =I18+J18 -> 1771435 | L18: =SGA!I19 -> 0 | N18: =L18+M18 -> 0 | O18: =SGA!K19 -> 0 | Q18: =O18+P18 -> 0
B19: =SGA!B20 -> 修繕費 | C19: =SGA!C20 -> 805390 | E19: =C19+D19 -> 805390 | F19: =SGA!E20 -> 926390 | H19: =F19+G19 -> 926390 | I19: =SGA!G20 -> 532686 | K19: =I19+J19 -> 532686 | L19: =SGA!I20 -> 0 | N19: =L19+M19 -> 0 | O19: =SGA!K20 -> 0 | Q19: =O19+P19 -> 0
B20: =SGA!B21 -> 水道光熱費 | C20: =SGA!C21 -> 1033592 | E20: =C20+D20 -> 1033592 | F20: =SGA!E21 -> 1113959 | H20: =F20+G20 -> 1113959 | I20: =SGA!G21 -> 1037468 | K20: =I20+J20 -> 1037468 | L20: =SGA!I21 -> 0 | N20: =L20+M20 -> 0 | O20: =SGA!K21 -> 0 | Q20: =O20+P20 -> 0
... B29: =SGA!B30 -> 長期前払費用償却 | C29: =SGA!C30 -> 571543 | E29: =C29+D29 -> 571543 | F29: =SGA!E30 -> 578416 | H29: =F29+G29 -> 578416 | I29: =SGA!G30 -> 579928 | K29: =I29+J29 -> 579928 | L29: =SGA!I30 -> 0 | N29: =L29+M29 -> 0 | O29: =SGA!K30 -> 0 | Q29: =O29+P29 -> 0
B30: =SGA!B31 -> 貸倒引当金繰入額 | C30: =SGA!C31 -> 457000 | D30: =-C30 | E30: =C30+D30 -> 457000 | F30: =SGA!E31 -> 498000 | G30: =-F30 | H30: =F30+G30 -> 498000 | I30: =SGA!G31 -> 524000 | J30: =-I30 | K30: =I30+J30 -> 524000 | L30: =SGA!I31 -> 0 | N30: =L30+M30 -> 0 | O30: =SGA!K31 -> 0 | Q30: =O30+P30 -> 0
B31: =SGA!B32 -> 雑費 | C31: =SGA!C32 -> 227878 | E31: =C31+D31 -> 227878 | F31: =SGA!E32 -> 290290 | H31: =F31+G31 -> 290290 | I31: =SGA!G32 -> 435586 | K31: =I31+J31 -> 435586 | L31: =SGA!I32 -> 0 | N31: =L31+M31 -> 0 | O31: =SGA!K32 -> 0 | Q31: =O31+P31 -> 0
B32: =SGA!B33 -> 派遣料 | C32: =SGA!C33 -> 2346637 | E32: =C32+D32 -> 2346637 | F32: =SGA!E33 -> 1711213 | H32: =F32+G32 -> 1711213 | I32: =SGA!G33 -> 2846031 | K32: =I32+J32 -> 2846031 | L32: =SGA!I33 -> 0 | N32: =L32+M32 -> 0 | O32: =SGA!K33 -> 0 | Q32: =O32+P32 -> 0
B33: =SGA!B34 -> 管理諸費 | C33: =SGA!C34 -> 3649888 | E33: =C33+D33 -> 3649888 | F33: =SGA!E34 -> 3432539 | H33: =F33+G33 -> 3432539 | I33: =SGA!G34 -> 3705328 | K33: =I33+J33 -> 3705328 | L33: =SGA!I34 -> 0 | N33: =L33+M33 -> 0 | O33: =SGA!K34 -> 0 | Q33: =O33+P33 -> 0
B34: =SGA!B35 -> 0 | C34: =SGA!C35 -> 0 | E34: =C34+D34 -> 0 | F34: =SGA!E35 -> 0 | H34: =F34+G34 -> 0 | I34: =SGA!G35 -> 0 | K34: =I34+J34 -> 0 | L34: =SGA!I35 -> 0 | N34: =L34+M34 -> 0 | O34: =SGA!K35 -> 0 | Q34: =O34+P34 -> 0
E35: =C35+D35 -> 0 | H35: =F35+G35 -> 0 | K35: =I35+J35 -> 0 | N35: =L35+M35 -> 0 | Q35: =O35+P35 -> 0
E36: =C36+D36 -> 0 | H36: =F36+G36 -> 0 | K36: =I36+J36 -> 0 | N36: =L36+M36 -> 0 | Q36: =O36+P36 -> 0
E37: =C37+D37 -> 0 | H37: =F37+G37 -> 0 | K37: =I37+J37 -> 0 | N37: =L37+M37 -> 0 | Q37: =O37+P37 -> 0
E38: =C38+D38 -> 0 | H38: =F38+G38 -> 0 | K38: =I38+J38 -> 0 | N38: =L38+M38 -> 0 | Q38: =O38+P38 -> 0
B39: 販売費および一般管理費合計 | C39: =SUM(C5:C38) -> 145464229 | D39: =SUM(D5:D38) -> 0 | E39: =C39+D39 -> 145464229 | F39: =SUM(F5:F38) -> 154261272 | G39: =SUM(G5:G38) -> 0 | H39: =F39+G39 -> 154261272 | I39: =SUM(I5:I38) -> 147845764 | J39: =SUM(J5:J38) -> 0 | K39: =I39+J39 -> 147845764 | L39: =SUM(L5:L38) -> 0 | M39: =SUM(M5:M38) -> 0 | N39: =L39+M39 -> 0 | O39: =SUM(O5:O38) -> 0 | P39: =SUM(P5:P38) -> 0 | Q39: =O39+P39 -> 0

Sheet 修正CR
K2: (単位：千円)
B3: 科目 | C3: ='BS(借方)'!C4 -> 23年12月期 | F3: ='BS(借方)'!D4 -> 24年12月期 | I3: ='BS(借方)'!E4 -> 25年12月期 | L3: ='BS(借方)'!F4 -> ●●年●月期 | O3: ='BS(借方)'!G4 -> ●●年●月 （●か月TB）
C4: 帳簿価額 | D4: 修正額 | E4: 修正後 | F4: 帳簿価額 | G4: 修正額 | H4: 修正後 | I4: 帳簿価額 | J4: 修正額 | K4: 修正後 | L4: 帳簿価額 | M4: 修正額 | N4: 修正後 | O4: 帳簿価額 | P4: 修正額 | Q4: 修正後
B5: 期首原材料棚卸高 | C5: 500000 | D5: -500000 | E5: =C5+D5 -> 0 | F5: 500000 | G5: -500000 | H5: =F5+G5 -> 0 | I5: 500000 | J5: -500000 | K5: =I5+J5 -> 0 | L5: 500000 | M5: -500000 | N5: =L5+M5 -> 0 | O5: 500000 | P5: -500000 | Q5: =O5+P5 -> 0
B6: 原材料仕入高 | E6: =C6+D6 -> 0 | H6: =F6+G6 -> 0 | K6: =I6+J6 -> 0 | N6: =L6+M6 -> 0 | Q6: =O6+P6 -> 0
B7: 小計 | E7: =C7+D7 -> 0 | H7: =F7+G7 -> 0 | K7: =I7+J7 -> 0 | N7: =L7+M7 -> 0 | Q7: =O7+P7 -> 0
B8: 期末原材料棚卸高 | E8: =C8+D8 -> 0 | H8: =F8+G8 -> 0 | K8: =I8+J8 -> 0 | N8: =L8+M8 -> 0 | Q8: =O8+P8 -> 0
E9: =C9+D9 -> 0 | H9: =F9+G9 -> 0 | K9: =I9+J9 -> 0 | N9: =L9+M9 -> 0 | Q9: =O9+P9 -> 0
E10: =C10+D10 -> 0 | H10: =F10+G10 -> 0 | K10: =I10+J10 -> 0 | N10: =L10+M10 -> 0 | Q10: =O10+P10 -> 0
B11: 材料費 | C11: =SUM(C5:C10) -> 500000 | D11: =SUM(D5:D10) -> -500000 | E11: =C11+D11 -> 0 | F11: =SUM(F5:F10) -> 500000 | G11: =SUM(G5:G10) -> -500000 | H11: =F11+G11 -> 0 | I11: =SUM(I5:I10) -> 500000 | J11: =SUM(J5:J10) -> -500000 | K11: =I11+J11 -> 0 | L11: =SUM(L5:L10) -> 500000 | M11: =SUM(M5:M10) -> -500000 | N11: =L11+M11 -> 0 | O11: =SUM(O5:O10) -> 500000 | P11: =SUM(P5:P10) -> -500000 | Q11: =O11+P11 -> 0
E12: =C12+D12 -> 0 | H12: =F12+G12 -> 0 | K12: =I12+J12 -> 0 | N12: =L12+M12 -> 0 | Q12: =O12+P12 -> 0
E13: =C13+D13 -> 0 | H13: =F13+G13 -> 0 | K13: =I13+J13 -> 0 | N13: =L13+M13 -> 0 | Q13: =O13+P13 -> 0
E14: =C14+D14 -> 0 | H14: =F14+G14 -> 0 | K14: =I14+J14 -> 0 | N14: =L14+M14 -> 0 | Q14: =O14+P14 -> 0
E15: =C15+D15 -> 0 | H15: =F15+G15 -> 0 | K15: =I15+J15 -> 0 | N15: =L15+M15 -> 0 | Q15: =O15+P15 -> 0
E16: =C16+D16 -> 0 | H16: =F16+G16 -> 0 | K16: =I16+J16 -> 0 | N16: =L16+M16 -> 0 | Q16: =O16+P16 -> 0
E17: =C17+D17 -> 0 | H17: =F17+G17 -> 0 | K17: =I17+J17 -> 0 | N17: =L17+M17 -> 0 | Q17: =O17+P17 -> 0
B18: 労務費 | C18: =SUM(C12:C17) -> 0 | D18: =SUM(D12:D17) -> 0 | E18: =C18+D18 -> 0 | F18: =SUM(F12:F17) -> 0 | G18: =SUM(G12:G17) -> 0 | H18: =F18+G18 -> 0 | I18: =SUM(I12:I17) -> 0 | J18: =SUM(J12:J17) -> 0 | K18: =I18+J18 -> 0 | L18: =SUM(L12:L17) -> 0 | M18: =SUM(M12:M17) -> 0 | N18: =L18+M18 -> 0 | O18: =SUM(O12:O17) -> 0 | P18: =SUM(P12:P17) -> 0 | Q18: =O18+P18 -> 0
E19: =C19+D19 -> 0 | H19: =F19+G19 -> 0 | K19: =I19+J19 -> 0 | N19: =L19+M19 -> 0 | Q19: =O19+P19 -> 0
E20: =C20+D20 -> 0 | H20: =F20+G20 -> 0 | K20: =I20+J20 -> 0 | N20: =L20+M20 -> 0 | Q20: =O20+P20 -> 0
E21: =C21+D21 -> 0 | H21: =F21+G21 -> 0 | K21: =I21+J21 -> 0 | N21: =L21+M21 -> 0 | Q21: =O21+P21 -> 0
E22: =C22+D22 -> 0 | H22: =F22+G22 -> 0 | K22: =I22+J22 -> 0 | N22: =L22+M22 -> 0 | Q22: =O22+P22 -> 0
E23: =C23+D23 -> 0 | H23: =F23+G23 -> 0 | K23: =I23+J23 -> 0 | N23: =L23+M23 -> 0 | Q23: =O23+P23 -> 0
E24: =C24+D24 -> 0 | H24: =F24+G24 -> 0 | K24: =I24+J24 -> 0 | N24: =L24+M24 -> 0 | Q24: =O24+P24 -> 0
B25: 外注加工費 | C25: =SUM(C19:C24) -> 0 | D25: =SUM(D19:D24) -> 0 | E25: =C25+D25 -> 0 | F25: =SUM(F19:F24) -> 0 | G25: =SUM(G19:G24) -> 0 | H25: =F25+G25 -> 0 | I25: =SUM(I19:I24) -> 0 | J25: =SUM(J19:J24) -> 0 | K25: =I25+J25 -> 0 | L25: =SUM(L19:L24) -> 0 | M25: =SUM(M19:M24) -> 0 | N25: =L25+M25 -> 0 | O25: =SUM(O19:O24) -> 0 | P25: =SUM(P19:P24) -> 0 | Q25: =O25+P25 -> 0
E26: =C26+D26 -> 0 | H26: =F26+G26 -> 0 | K26: =I26+J26 -> 0 | N26: =L26+M26 -> 0 | Q26: =O26+P26 -> 0
E27: =C27+D27 -> 0 | H27: =F27+G27 -> 0 | K27: =I27+J27 -> 0 | N27: =L27+M27 -> 0 | Q27: =O27+P27 -> 0
E28: =C28+D28 -> 0 | H28: =F28+G28 -> 0 | K28: =I28+J28 -> 0 | N28: =L28+M28 -> 0 | Q28: =O28+P28 -> 0
E29: =C29+D29 -> 0 | H29: =F29+G29 -> 0 | K29: =I29+J29 -> 0 | N29: =L29+M29 -> 0 | Q29: =O29+P29 -> 0
E30: =C30+D30 -> 0 | H30: =F30+G30 -> 0 | K30: =I30+J30 -> 0 | N30: =L30+M30 -> 0 | Q30: =O30+P30 -> 0
E31: =C31+D31 -> 0 | H31: =F31+G31 -> 0 | K31: =I31+J31 -> 0 | N31: =L31+M31 -> 0 | Q31: =O31+P31 -> 0
E32: =C32+D32 -> 0 | H32: =F32+G32 -> 0 | K32: =I32+J32 -> 0 | N32: =L32+M32 -> 0 | Q32: =O32+P32 -> 0
E33: =C33+D33 -> 0 | H33: =F33+G33 -> 0 | K33: =I33+J33 -> 0 | N33: =L33+M33 -> 0 | Q33: =O33+P33 -> 0
E34: =C34+D34 -> 0 | H34: =F34+G34 -> 0 | K34: =I34+J34 -> 0 | N34: =L34+M34 -> 0 | Q34: =O34+P34 -> 0
E35: =C35+D35 -> 0 | H35: =F35+G35 -> 0 | K35: =I35+J35 -> 0 | N35: =L35+M35 -> 0 | Q35: =O35+P35 -> 0
B36: 経費 | C36: =SUM(C26:C35) -> 0 | D36: =SUM(D26:D35) -> 0 | E36: =C36+D36 -> 0 | F36: =SUM(F26:F35) -> 0 | G36: =SUM(G26:G35) -> 0 | H36: =F36+G36 -> 0 | I36: =SUM(I26:I35) -> 0 | J36: =SUM(J26:J35) -> 0 | K36: =I36+J36 -> 0 | L36: =SUM(L26:L35) -> 0 | M36: =SUM(M26:M35) -> 0 | N36: =L36+M36 -> 0 | O36: =SUM(O26:O35) -> 0 | P36: =SUM(P26:P35) -> 0 | Q36: =O36+P36 -> 0
B37: 当期製造費用 | C37: =C11+C18+C25+C36 -> 500000 | D37: =D11+D18+D25+D36 -> -500000 | E37: =C37+D37 -> 0 | F37: =F11+F18+F25+F36 -> 500000 | G37: =G11+G18+G25+G36 -> -500000 | H37: =F37+G37 -> 0 | I37: =I11+I18+I25+I36 -> 500000 | J37: =J11+J18+J25+J36 -> -500000 | K37: =I37+J37 -> 0 | L37: =L11+L18+L25+L36 -> 500000 | M37: =M11+M18+M25+M36 -> -500000 | N37: =L37+M37 -> 0 | O37: =O11+O18+O25+O36 -> 500000 | P37: =P11+P18+P25+P36 -> -500000 | Q37: =O37+P37 -> 0
B38: 期首仕掛品棚卸高 | E38: =C38+D38 -> 0 | H38: =F38+G38 -> 0 | K38: =I38+J38 -> 0 | N38: =L38+M38 -> 0 | Q38: =O38+P38 -> 0
B39: 合計 | C39: =SUM(C37:C38) -> 500000 | D39: =SUM(D37:D38) -> -500000 | E39: =C39+D39 -> 0 | F39: =SUM(F37:F38) -> 500000 | G39: =SUM(G37:G38) -> -500000 | H39: =F39+G39 -> 0 | I39: =SUM(I37:I38) -> 500000 | J39: =SUM(J37:J38) -> -500000 | K39: =I39+J39 -> 0 | L39: =SUM(L37:L38) -> 500000 | M39: =SUM(M37:M38) -> -500000 | N39: =L39+M39 -> 0 | O39: =SUM(O37:O38) -> 500000 | P39: =SUM(P37:P38) -> -500000 | Q39: =O39+P39 -> 0
B40: 期末仕掛品棚卸高 | E40: =C40+D40 -> 0 | H40: =F40+G40 -> 0 | K40: =I40+J40 -> 0 | N40: =L40+M40 -> 0 | Q40: =O40+P40 -> 0
B41: 当期製造原価 | C41: =C39-C40 -> 500000 | D41: =D39-D40 -> -500000 | E41: =C41+D41 -> 0 | F41: =F39-F40 -> 500000 | G41: =G39-G40 -> -500000 | H41: =F41+G41 -> 0 | I41: =I39-I40 -> 500000 | J41: =J39-J40 -> -500000 | K41: =I41+J41 -> 0 | L41: =L39-L40 -> 500000 | M41: =M39-M40 -> -500000 | N41: =L41+M41 -> 0 | O41: =O39-O40 -> 500000 | P41: =P39-P40 -> -500000 | Q41: =O41+P41 -> 0

Sheet 年買法
C2: (単位：千円) | H2: (単位：千円) | M2: (単位：千円)
B3: =修正PL!I3 | C3: 金額 | F3: =修正PL!C3 | G3: =修正PL!F3 | H3: =修正PL!I3 | J3: 営業権倍率 | K3: x1 | L3: x2 | M3: x3
B4: 簿価純資産額 | C4: ='BS (貸方)'!E50 | E4: 簿価営業利益 | F4: =修正PL!C19 | G4: =修正PL!F19 | H4: =修正PL!I19 | J4: 時価純資産 | K4: =C7
B5: 修正額 | C5: ='修正BS(貸方) '!D50 | E5: 修正額 | F5: =修正PL!D19 | G5: =修正PL!G19 | H5: =修正PL!J19 | J5: 営業権 | K5: =H10*1 | L5: =H10*2 | M5: =H10*3
