Workbook

Sheet ルール
B2: 案件マスター 作成ルール
B3: 1. 文字は「游ゴシック」、数字は「Arial」。備考欄などの細かい文章は「游ゴシック Medium」
B4: 2. タイトル・合計欄は太字
B5: 3. 数字は円単位で入力する。表示は千円単位に設定済み（千円で入力しないこと）
B6: 4. 背景は紺・水色・グレー・白・青。線は紺・白・青
B7: 5. 数値の原本は本ファイルのみ。概要書・評価書・ノンネームシートは本ファイルから転記する
B8: 6. 未確認事項は推測で埋めず「要確認」と記載し、「その他」シートに集約する
B10: 【本ファイルの出所】
B11: ・第64〜66期（2023年3月期〜2025年3月期）の決算数値：受領した既存の企業概要書（財務表）から転記
B12: ・第67期（2026年3月期）の決算数値：第67期決算報告書・勘定科目内訳書・法人税申告書から転記
B13: ・減価償却：第67期 減価償却計算書（合計表・明細）
B14: ・登記情報：履歴事項（2026年9月9日現在）
B15: ・転記後、4期すべてで資産合計・負債純資産合計・営業利益〜当期純利益・純資産の期間連続性が決算書記載値と一致することを確認済み

Sheet 財務入力→
B2: 財務入力 セクション

Sheet BS(借方)
B2: 貸借対照表（資産の部） 単位：千円（入力は円）
C3: 第64期 | D3: 第65期 | E3: 第66期 | F3: 第67期
B4: 科目 | C4: 2023年3月期 | D4: 2024年3月期 | E4: 2025年3月期 | F4: 2026年3月期 | G4: 進行期TB | H4: 備考
B5: （現金・預金） | C5: =SUM(C6:C11) -> 122956747 | D5: =SUM(D6:D11) -> 119371880 | E5: =SUM(E6:E11) -> 84662407 | F5: =SUM(F6:F11) -> 75962050
B6: 現金 | C6: 1522482 | D6: 3464228 | E6: 2183725 | F6: 3077481
B7: 当座預金 | C7: 25178691 | D7: 18567463 | E7: 28531948 | F7: 17248373
B8: 普通預金 | C8: 39607004 | D8: 54198593 | E8: 15944998 | F8: 19872670
B9: 定期預金 | C9: 16400786 | D9: 16400803 | E9: 26400820 | F9: 26401032 | H9: 67期：預貯金内訳書の定期預金計19,601,032円と差異6,800,000円（受取利息内訳では栃木銀行定期10,400,000円）→要確認
B10: 定期積金 | C10: 23253671 | D10: 16203941 | E10: 0 | F10: 0
B11: 諸掛金（生命保険積立） | C11: 16994113 | D11: 10536852 | E11: 11600916 | F11: 9362494 | H11: 67期内訳書：大同生命8,461,965円・第一生命900,529円。現預金に含めて表示されているが実態は保険積立金
B12: （当座資産） | C12: =SUM(C13:C14) -> 21685368 | D12: =SUM(D13:D14) -> 29802902 | E12: =SUM(E13:E14) -> 28300741 | F12: =SUM(F13:F14) -> 28798405
B13: 受取手形 | C13: 0 | D13: 0 | E13: 0 | F13: 0
B14: 売掛金 | C14: 21685368 | D14: 29802902 | E14: 28300741 | F14: 28798405 | H14: 67期内訳書：上位7社＋その他。合計が残高を1,723,680円超過（(株)小野田商店の重複計上と推察）→要確認
B15: （棚卸資産） | C15: =SUM(C16:C19) -> 27194459 | D15: =SUM(D16:D19) -> 30950673 | E15: =SUM(E16:E19) -> 36589789 | F15: =SUM(F16:F19) -> 34490885
B16: 棚卸商品 | C16: 14642199 | D16: 15901958 | E16: 13824517 | F16: 20660679
B17: 棚卸原材料 | C17: 11853408 | D17: 14319679 | E17: 22007284 | F17: 12953022
B18: 仕掛品 | C18: 698852 | D18: 729036 | E18: 757988 | F18: 877184
B19: 貯蔵品 | C19: 0 | D19: 0 | E19: 0 | F19: 0
B20: （流動資産諸口） | C20: =SUM(C21:C27) -> 4369613 | D20: =SUM(D21:D27) -> 4806979 | E20: =SUM(E21:E27) -> 4572512 | F20: =SUM(F21:F27) -> 3063104
B21: 前渡金 | C21: 0 | D21: 638000 | E21: 638000 | F21: 0
B22: 仮払金 | C22: 0 | D22: 4932 | E22: 0 | F22: 0
B23: 貸付金 | C23: 0 | D23: 390000 | E23: 578745 | F23: 214933 | H23: 従業員への生活資金貸付
B24: 預け金 | C24: 200000 | D24: 200000 | E24: 200000 | F24: 200000
B25: 立替金 | C25: 0 | D25: 0 | E25: 0 | F25: 0
B26: 未収金 | C26: 1780000 | D26: 2441235 | E26: 2333092 | F26: 2354696 | H26: 67期：消費税還付等
B27: 前払費用 | C27: 2389613 | D27: 1132812 | E27: 822675 | F27: 293475
B28: 流動資産合計 | C28: =C5+C12+C15+C20 -> 176206187 | D28: =D5+D12+D15+D20 -> 184932434 | E28: =E5+E12+E15+E20 -> 154125449 | F28: =F5+F12+F15+F20 -> 142314444
B29: （有形固定資産） | C29: =SUM(C30:C35) -> 410452212 | D29: =SUM(D30:D35) -> 416750652 | E29: =SUM(E30:E35) -> 406411950 | F29: =SUM(F30:F35) -> 409715275
B30: 建物 | C30: 259241627 | D30: 259241627 | E30: 259241627 | F30: 259241627 | H30: 67期は償却計上なし（償却不足額21,745,406円）。主たる工場建物は1991年取得
B31: 構築物 | C31: 2116299 | D31: 2116299 | E31: 2116299 | F31: 2116299 | H31: 67期は償却計上なし（償却不足額447,749円）
B32: 機械 | C32: 96493939 | D32: 103379540 | E32: 94933538 | F32: 99691427 | H32: 67期償却不足額3,092,403円
B33: 車両運搬具 | C33: 8635754 | D33: 6374671 | E33: 5554052 | F33: 4905291
B34: 器具備品 | C34: 3522674 | D34: 5196596 | E34: 4124515 | F34: 3318712
B35: 土地 | C35: 40441919 | D35: 40441919 | E35: 40441919 | F35: 40441919
B36: （無形固定資産） | C36: =SUM(C37:C37) -> 354300 | D36: =SUM(D37:D37) -> 354300 | E36: =SUM(E37:E37) -> 354300 | F36: =SUM(F37:F37) -> 354300
B37: 特許商標権 | C37: 354300 | D37: 354300 | E37: 354300 | F37: 354300
B38: （投資その他の資産） | C38: =SUM(C39:C40) -> 2945000 | D38: =SUM(D39:D40) -> 820000 | E38: =SUM(E39:E40) -> 820000 | F38: =SUM(F39:F40) -> 820000
B39: 出資金 | C39: 2945000 | D39: 820000 | E39: 820000 | F39: 820000 | H39: 越谷市工業団地組合800,000円ほか
B40: 長期貸付金 | C40: 0 | D40: 0 | E40: 0 | F40: 0
B41: 固定資産合計 | C41: =C29+C36+C38 -> 413751512 | D41: =D29+D36+D38 -> 417924952 | E41: =E29+E36+E38 -> 407586250 | F41: =F29+F36+F38 -> 410889575
...

Sheet BS (貸方)
B2: 貸借対照表（負債・純資産の部） 単位：千円（入力は円）
B4: 科目 | C4: ='BS(借方)'!C4 -> 2023年3月期 | D4: ='BS(借方)'!D4 -> 2024年3月期 | E4: ='BS(借方)'!E4 -> 2025年3月期 | F4: ='BS(借方)'!F4 -> 2026年3月期 | G4: 進行期TB | H4: 備考
B5: （流動負債） | C5: =SUM(C6:C12) -> 119983523 | D5: =SUM(D6:D12) -> 157820031 | E5: =SUM(E6:E12) -> 114978167 | F5: =SUM(F6:F12) -> 122891823
B6: 支払手形 | C6: 15964813 | D6: 20349325 | E6: 16479666 | F6: 16135488
B7: 買掛金 | C7: 9398537 | D7: 6615198 | E7: 4781682 | F7: 8358184
B8: 短期借入金 | C8: 80000000 | D8: 110000000 | E8: 80000000 | F8: 80000000 | H8: 67期：借入金内訳書（短期・長期合計461,024千円、うち代表者借入14,000千円）
B9: 未払金 | C9: 11656596 | D9: 17794210 | E9: 10599418 | F9: 15721057 | H9: 67期内訳書計15,715,659円とBS残高に5,398円差異。3月分給与5,720,681円・未払消費税1,676,200円を含む
B10: 預り金 | C10: 2598077 | D10: 2698218 | E10: 2754101 | F10: 2189894
B11: 仮受金 | C11: 5500 | D11: 3080 | E11: 3300 | F11: 0
B12: 税金引当金（未払法人税等） | C12: 360000 | D12: 360000 | E12: 360000 | F12: 487200
B13: （固定負債） | C13: =SUM(C14:C14) -> 450156000 | D13: =SUM(D14:D14) -> 402787000 | E13: =SUM(E14:E14) -> 398822000 | F13: =SUM(F14:F14) -> 381024000
B14: 長期借入金 | C14: 450156000 | D14: 402787000 | E14: 398822000 | F14: 381024000 | H14: うち日本政策金融公庫の資本性ローン105,420千円（67期）
B15: 負債合計 | C15: =C5+C13 -> 570139523 | D15: =D5+D13 -> 560607031 | E15: =E5+E13 -> 513800167 | F15: =F5+F13 -> 503915823
B16: （純資産の部）
B17: 資本金 | C17: 11000000 | D17: 11000000 | E17: 11000000 | F17: 11000000 | H17: 2026年5月15日付で10,000千円に減資（登記）
B18: 利益準備金 | C18: 5000000 | D18: 5000000 | E18: 5000000 | F18: 5000000
B19: 別途積立金 | C19: 10000000 | D19: 10000000 | E19: 10000000 | F19: 10000000
B20: 繰越利益剰余金 | C20: -6181824 | D20: 16250355 | E20: 21911532 | F20: 23288196
B21: 純資産合計 | C21: =SUM(C17:C20) -> 19818176 | D21: =SUM(D17:D20) -> 42250355 | E21: =SUM(E17:E20) -> 47911532 | F21: =SUM(F17:F20) -> 49288196
B22: 負債・純資産合計 | C22: =C15+C21 -> 589957699 | D22: =D15+D21 -> 602857386 | E22: =E15+E21 -> 561711699 | F22: =F15+F21 -> 553204019
B24: 有利子負債合計（短期＋長期借入金） | C24: =C8+C14 -> 530156000 | D24: =D8+D14 -> 512787000 | E24: =E8+E14 -> 478822000 | F24: =F8+F14 -> 461024000

Sheet PL
B2: 損益計算書 単位：千円（入力は円） ※2列1組（帳簿価額／売上高比）
B4: 科目 | C4: ='BS(借方)'!C4 -> 2023年3月期 | E4: ='BS(借方)'!D4 -> 2024年3月期 | G4: ='BS(借方)'!E4 -> 2025年3月期 | I4: ='BS(借方)'!F4 -> 2026年3月期 | K4: 備考
B5: 売上高 | C5: =SUM(C6:C8) -> 284840729 | D5: =IFERROR(C5/C$5,0) -> 1 | E5: =SUM(E6:E8) -> 376221193 | F5: =IFERROR(E5/E$5,0) -> 1 | G5: =SUM(G6:G8) -> 382684537 | H5: =IFERROR(G5/G$5,0) -> 1 | I5: =SUM(I6:I8) -> 405963400 | J5: =IFERROR(I5/I$5,0) -> 1
B6: 売上（製氷・加工氷・商品） | C6: 278785769 | D6: =IFERROR(C6/C$5,0) -> 0.97874265 | E6: 369928091 | F6: =IFERROR(E6/E$5,0) -> 0.98327287 | G6: 376242652 | H6: =IFERROR(G6/G$5,0) -> 0.98316659 | I6: 399993563 | J6: =IFERROR(I6/I$5,0) -> 0.98529464
B7: 保管料（冷蔵保管） | C7: 6025110 | D7: =IFERROR(C7/C$5,0) -> 0.021152558 | E7: 6273202 | F7: =IFERROR(E7/E$5,0) -> 0.016674239 | G7: 6441885 | H7: =IFERROR(G7/G$5,0) -> 0.016833408 | I7: 5969837 | J7: =IFERROR(I7/I$5,0) -> 0.014705358
B8: 受入手数料 | C8: 29850 | D8: =IFERROR(C8/C$5,0) -> 0.00010479541 | E8: 19900 | F8: =IFERROR(E8/E$5,0) -> 5.2894415e-05 | G8: 0 | H8: =IFERROR(G8/G$5,0) -> 0 | I8: 0 | J8: =IFERROR(I8/I$5,0) -> 0
B9: 売上原価 | C9: =C13+C14 -> 238592970 | D9: =IFERROR(C9/C$5,0) -> 0.83763643 | E9: =E13+E14 -> 279653851 | F9: =IFERROR(E9/E$5,0) -> 0.74332296 | G9: =G13+G14 -> 297300134 | H9: =IFERROR(G9/G$5,0) -> 0.77688045 | I9: =I13+I14 -> 316589415 | J9: =IFERROR(I9/I$5,0) -> 0.77984719
B10: 期首商品棚卸高 | C10: 14945432 | D10: =IFERROR(C10/C$5,0) -> 0.052469435 | E10: 14642199 | F10: =IFERROR(E10/E$5,0) -> 0.038919123 | G10: 15901958 | H10: =IFERROR(G10/G$5,0) -> 0.041553699 | I10: 13824517 | J10: =IFERROR(I10/I$5,0) -> 0.034053604
B11: 商品仕入高 | C11: 15151075 | D11: =IFERROR(C11/C$5,0) -> 0.053191392 | E11: 32597105 | F11: =IFERROR(E11/E$5,0) -> 0.086643458 | G11: 42388144 | H11: =IFERROR(G11/G$5,0) -> 0.11076524 | I11: 41445951 | J11: =IFERROR(I11/I$5,0) -> 0.10209283
B12: 期末商品棚卸高 | C12: ='BS(借方)'!C16 -> 14642199 | D12: =IFERROR(C12/C$5,0) -> 0.051404864 | E12: ='BS(借方)'!D16 -> 15901958 | F12: =IFERROR(E12/E$5,0) -> 0.042267576 | G12: ='BS(借方)'!E16 -> 13824517 | H12: =IFERROR(G12/G$5,0) -> 0.0361251 | I12: ='BS(借方)'!F16 -> 20660679 | J12: =IFERROR(I12/I$5,0) -> 0.05089296
B13: 商品売上原価 | C13: =C10+C11-C12 -> 15454308 | D13: =IFERROR(C13/C$5,0) -> 0.054255963 | E13: =E10+E11-E12 -> 31337346 | F13: =IFERROR(E13/E$5,0) -> 0.083295005 | G13: =G10+G11-G12 -> 44465585 | H13: =IFERROR(G13/G$5,0) -> 0.11619384 | I13: =I10+I11-I12 -> 34609789 | J13: =IFERROR(I13/I$5,0) -> 0.085253471
B14: 当期製品製造原価 | C14: =CR!C45 -> 223138662 | D14: =IFERROR(C14/C$5,0) -> 0.78338046 | E14: =CR!D45 -> 248316505 | F14: =IFERROR(E14/E$5,0) -> 0.66002796 | G14: =CR!E45 -> 252834549 | H14: =IFERROR(G14/G$5,0) -> 0.66068661 | I14: =CR!F45 -> 281979626 | J14: =IFERROR(I14/I$5,0) -> 0.69459371
B15: 売上総利益 | C15: =C5-C9 -> 46247759 | D15: =IFERROR(C15/C$5,0) -> 0.16236357 | E15: =E5-E9 -> 96567342 | F15: =IFERROR(E15/E$5,0) -> 0.25667704 | G15: =G5-G9 -> 85384403 | H15: =IFERROR(G15/G$5,0) -> 0.22311955 | I15: =I5-I9 -> 89373985 | J15: =IFERROR(I15/I$5,0) -> 0.22015281
B16: 販売費及び一般管理費 | C16: =SUM(C17:C23) -> 54495280 | D16: =IFERROR(C16/C$5,0) -> 0.19131843 | E16: =SUM(E17:E23) -> 71242323 | F16: =IFERROR(E16/E$5,0) -> 0.18936287 | G16: =SUM(G17:G23) -> 71725529 | H16: =IFERROR(G16/G$5,0) -> 0.1874273 | I16: =SUM(I17:I23) -> 81348592 | J16: =IFERROR(I16/I$5,0) -> 0.20038405
B17: 給与関係費 | C17: =SGA!C5 -> 21464143 | D17: =IFERROR(C17/C$5,0) -> 0.075354894 | E17: =SGA!D5 -> 21065469 | F17: =IFERROR(E17/E$5,0) -> 0.055992244 | G17: =SGA!E5 -> 23458472 | H17: =IFERROR(G17/G$5,0) -> 0.061299765 | I17: =SGA!F5 -> 23527651 | J17: =IFERROR(I17/I$5,0) -> 0.057955104
B18: 資産管理費 | C18: =SGA!C14 -> 5426413 | D18: =IFERROR(C18/C$5,0) -> 0.019050692 | E18: =SGA!D14 -> 5193598 | F18: =IFERROR(E18/E$5,0) -> 0.01380464 | G18: =SGA!E14 -> 5119422 | H18: =IFERROR(G18/G$5,0) -> 0.013377656 | I18: =SGA!F14 -> 6634973 | J18: =IFERROR(I18/I$5,0) -> 0.016343771
B19: 輸送関係費 | C19: =SGA!C25 -> 20950477 | D19: =IFERROR(C19/C$5,0) -> 0.07355155 | E19: =SGA!D25 -> 33504224 | F19: =IFERROR(E19/E$5,0) -> 0.08905459 | G19: =SGA!E25 -> 29684699 | H19: =IFERROR(G19/G$5,0) -> 0.077569633 | I19: =SGA!F25 -> 37540944 | J19: =IFERROR(I19/I$5,0) -> 0.092473716
B20: 交際販売関係費 | C20: =SGA!C30 -> 799841 | D20: =IFERROR(C20/C$5,0) -> 0.0028080289 | E20: =SGA!D30 -> 950969 | F20: =IFERROR(E20/E$5,0) -> 0.0025276859 | G20: =SGA!E30 -> 964692 | H20: =IFERROR(G20/G$5,0) -> 0.0025208544 | I20: =SGA!F30 -> 830503 | J20: =IFERROR(I20/I$5,0) -> 0.0020457583
B21: 事務処理費 | C21: =SGA!C34 -> 4117984 | D21: =IFERROR(C21/C$5,0) -> 0.014457146 | E21: =SGA!D34 -> 5359472 | F21: =IFERROR(E21/E$5,0) -> 0.014245535 | G21: =SGA!E34 -> 4946870 | H21: =IFERROR(G21/G$5,0) -> 0.012926757 | I21: =SGA!F34 -> 6820643 | J21: =IFERROR(I21/I$5,0) -> 0.016801128
B22: その他 | C22: =SGA!C42 -> 1736422 | D22: =IFERROR(C22/C$5,0) -> 0.0060961156 | E22: =SGA!D42 -> 5168591 | F22: =IFERROR(E22/E$5,0) -> 0.013738171 | G22: =SGA!E42 -> 4395505 | H22: =IFERROR(G22/G$5,0) -> 0.011485975 | I22: =SGA!F42 -> 4229217 | J22: =IFERROR(I22/I$5,0) -> 0.01041773
B23: 支払手数料（一般業務費） | C23: 0 | D23: =IFERROR(C23/C$5,0) -> 0 | E23: 0 | F23: =IFERROR(E23/E$5,0) -> 0 | G23: 3155869 | H23: =IFERROR(G23/G$5,0) -> 0.0082466593 | I23: 1764661 | J23: =IFERROR(I23/I$5,0) -> 0.0043468475 | K23: 66期から計上。内容（一過性の専門家報酬等か）は要確認
B24: 営業利益 | C24: =C15-C16 -> -8247521 | D24: =IFERROR(C24/C$5,0) -> -0.028954851 | E24: =E15-E16 -> 25325019 | F24: =IFERROR(E24/E$5,0) -> 0.067314174 | G24: =G15-G16 -> 13658874 | H24: =IFERROR(G24/G$5,0) -> 0.035692255 | I24: =I15-I16 -> 8025393 | J24: =IFERROR(I24/I$5,0) -> 0.01976876
B25: 営業外収益 | C25: =SUM(C26:C29) -> 1258409 | D25: =IFERROR(C25/C$5,0) -> 0.0044179391 | E25: =SUM(E26:E29) -> 8814192 | F25: =IFERROR(E25/E$5,0) -> 0.023428218 | G25: =SUM(G26:G29) -> 380769 | H25: =IFERROR(G25/G$5,0) -> 0.00099499448 | I25: =SUM(I26:I29) -> 2783309 | J25: =IFERROR(I25/I$5,0) -> 0.0068560589
B26: 受取利息 | C26: 7377 | D26: =IFERROR(C26/C$5,0) -> 2.5898684e-05 | E26: 331584 | F26: =IFERROR(E26/E$5,0) -> 0.00088135386 | G26: 38636 | H26: =IFERROR(G26/G$5,0) -> 0.00010096044 | I26: 96106 | J26: =IFERROR(I26/I$5,0) -> 0.00023673563
B27: 受取配当金 | C27: 200 | D27: =IFERROR(C27/C$5,0) -> 7.0214678e-07 | E27: 200 | F27: =IFERROR(E27/E$5,0) -> 5.3160216e-07 | G27: 200 | H27: =IFERROR(G27/G$5,0) -> 5.2262368e-07 | I27: 200 | J27: =IFERROR(I27/I$5,0) -> 4.9265525e-07
B28: 雑収入 | C28: 1250832 | D28: =IFERROR(C28/C$5,0) -> 0.0043913383 | E28: 8482408 | F28: =IFERROR(E28/E$5,0) -> 0.022546332 | G28: 341933 | H28: =IFERROR(G28/G$5,0) -> 0.00089351141 | I28: 2687003 | J28: =IFERROR(I28/I$5,0) -> 0.0066188307 | K28: 67期：無配当保険満期返戻金2,295,725円を含む（非経常）。65期8,482,408円の内容は要確認
B29: 有価証券売却益 | C29: 0 | D29: =IFERROR(C29/C$5,0) -> 0 | E29: 0 | F29: =IFERROR(E29/E$5,0) -> 0 | G29: 0 | H29: =IFERROR(G29/G$5,0) -> 0 | I29: 0 | J29: =IFERROR(I29/I$5,0) -> 0
B30: 営業外費用 | C30: =SUM(C31:C33) -> 6275611 | D30: =IFERROR(C30/C$5,0) -> 0.022032 | E30: =SUM(E31:E33) -> 11347032 | F30: =IFERROR(E30/E$5,0) -> 0.030160534 | G30: =SUM(G31:G33) -> 8018466 | H30: =IFERROR(G30/G$5,0) -> 0.020953201 | I30: =SUM(I31:I33) -> 8944838 | J30: =IFERROR(I30/I$5,0) -> 0.022033607
B31: 支払利息 | C31: 6117321 | D31: =IFERROR(C31/C$5,0) -> 0.021476286 | E31: 6154983 | F31: =IFERROR(E31/E$5,0) -> 0.016360011 | G31: 8018466 | H31: =IFERROR(G31/G$5,0) -> 0.020953201 | I31: 8406588 | J31: =IFERROR(I31/I$5,0) -> 0.020707749
B32: 雑損 | C32: 158290 | D32: =IFERROR(C32/C$5,0) -> 0.00055571407 | E32: 5192049 | F32: =IFERROR(E32/E$5,0) -> 0.013800522 | G32: 0 | H32: =IFERROR(G32/G$5,0) -> 0 | I32: 538250 | J32: =IFERROR(I32/I$5,0) -> 0.0013258584 | K32: 65期5,192,049円の内容は要確認。67期は資産廃棄
B33: 有価証券売却損 | C33: 0 | D33: =IFERROR(C33/C$5,0) -> 0 | E33: 0 | F33: =IFERROR(E33/E$5,0) -> 0 | G33: 0 | H33: =IFERROR(G33/G$5,0) -> 0 | I33: 0 | J33: =IFERROR(I33/I$5,0) -> 0
B34: 経常利益 | C34: =C24+C25-C30 -> -13264723 | D34: =IFERROR(C34/C$5,0) -> -0.046568913 | E34: =E24+E25-E30 -> 22792179 | F34: =IFERROR(E34/E$5,0) -> 0.060581858 | G34: =G24+G25-G30 -> 6021177 | H34: =IFERROR(G34/G$5,0) -> 0.015734048 | I34: =I24+I25-I30 -> 1863864 | J34: =IFERROR(I34/I$5,0) -> 0.0045912119
B35: 特別利益 | C35: 0 | D35: =IFERROR(C35/C$5,0) -> 0 | E35: 0 | F35: =IFERROR(E35/E$5,0) -> 0 | G35: 0 | H35: =IFERROR(G35/G$5,0) -> 0 | I35: 0 | J35: =IFERROR(I35/I$5,0) -> 0
B36: 特別損失 | C36: 0 | D36: =IFERROR(C36/C$5,0) -> 0 | E36: 0 | F36: =IFERROR(E36/E$5,0) -> 0 | G36: 0 | H36: =IFERROR(G36/G$5,0) -> 0 | I36: 0 | J36: =IFERROR(I36/I$5,0) -> 0
B37: 税引前当期純利益 | C37: =C34+C35-C36 -> -13264723 | D37: =IFERROR(C37/C$5,0) -> -0.046568913 | E37: =E34+E35-E36 -> 22792179 | F37: =IFERROR(E37/E$5,0) -> 0.060581858 | G37: =G34+G35-G36 -> 6021177 | H37: =IFERROR(G37/G$5,0) -> 0.015734048 | I37: =I34+I35-I36 -> 1863864 | J37: =IFERROR(I37/I$5,0) -> 0.0045912119
B38: 法人税等 | C38: 360000 | D38: =IFERROR(C38/C$5,0) -> 0.0012638642 | E38: 360000 | F38: =IFERROR(E38/E$5,0) -> 0.00095688389 | G38: 360000 | H38: =IFERROR(G38/G$5,0) -> 0.00094072262 | I38: 487200 | J38: =IFERROR(I38/I$5,0) -> 0.0012001082 | K38: 均等割中心。67期は繰越欠損金1,356,059円を使用し所得517,708円
B39: 当期純利益 | C39: =C37-C38 -> -13624723 | D39: =IFERROR(C39/C$5,0) -> -0.047832777 | E39: =E37-E38 -> 22432179 | F39: =IFERROR(E39/E$5,0) -> 0.059624974 | G39: =G37-G38 -> 5661177 | H39: =IFERROR(G39/G$5,0) -> 0.014793326 | I39: =I37-I38 -> 1376664 | J39: =IFERROR(I39/I$5,0) -> 0.0033911037
B41: （参考）減価償却費（製造原価＋販管費） | C41: =CR!C39+SGA!C44 -> 19763 | D41: =IFERROR(C41/C$5,0) -> 6.9382634e-05 | E41: =CR!D39+SGA!D44 -> 11322083 | F41: =IFERROR(E41/E$5,0) -> 0.030094219 | G41: =CR!E39+SGA!E44 -> 20417838 | H41: =IFERROR(G41/G$5,0) -> 0.053354228 | I41: =CR!F39+SGA!F44 -> 22335325 | J41: =IFERROR(I41/I$5,0) -> 0.055018076
B42: （参考）EBITDA（営業利益＋減価償却費） | C42: =C24+C41 -> -8227758 | D42: =IFERROR(C42/C$5,0) -> -0.028885469 | E42: =E24+E41 -> 36647102 | F42: =IFERROR(E42/E$5,0) -> 0.097408393 | G42: =G24+G41 -> 34076712 | H42: =IFERROR(G42/G$5,0) -> 0.089046483 | I42: =I24+I41 -> 30360718 | J42: =IFERROR(I42/I$5,0) -> 0.074786835
B63: 当期純利益の整合チェック（純資産増減＝当期純利益） | C63: =EXACT(C39,-13624723) -> TRUE | E63: =EXACT(E39,'BS (貸方)'!D21-'BS (貸方)'!C21) -> TRUE | G63: =EXACT(G39,'BS (貸方)'!E21-'BS (貸方)'!D21) -> TRUE | I63: =EXACT(I39,'BS (貸方)'!F21-'BS (貸方)'!E21) -> TRUE
...

Sheet CR
B2: 製造原価報告書 単位：千円（入力は円）
B4: 科目 | C4: ='BS(借方)'!C4 -> 2023年3月期 | D4: ='BS(借方)'!D4 -> 2024年3月期 | E4: ='BS(借方)'!E4 -> 2025年3月期 | F4: ='BS(借方)'!F4 -> 2026年3月期 | G4: 備考
B5: 【原材料費】 | C5: =C6+C7-C8 -> 66758150 | D5: =D6+D7-D8 -> 80790239 | E5: =E6+E7-E8 -> 72296148 | F5: =F6+F7-F8 -> 86166769
B6: 原材料期首棚卸高 | C6: 11620024 | D6: 11853408 | E6: 14319679 | F6: 22007284
B7: 原材料仕入高 | C7: 66991534 | D7: 83256510 | E7: 79983753 | F7: 77112507
B8: 原材料期末棚卸高 | C8: 11853408 | D8: 14319679 | E8: 22007284 | F8: 12953022
B9: 【労務費】 | C9: =SUM(C10:C15) -> 86672116 | D9: =SUM(D10:D15) -> 96715793 | E9: =SUM(E10:E15) -> 84347119 | F9: =SUM(F10:F15) -> 99952707
B10: 給与 | C10: 66415913 | D10: 75755387 | E10: 63545229 | F10: 69596465
B11: 賞与 | C11: 5935000 | D11: 5940000 | E11: 4920000 | F11: 8563512
B12: 退職給与 | C12: 0 | D12: 0 | E12: 0 | F12: 6177985 | G12: 67期6,177,985円は過去3期に発生のない臨時的支出と推察（退職者・規程は要確認）
B13: 法定福利費 | C13: 11278957 | D13: 12199418 | E13: 12503714 | F13: 12962279
B14: 厚生福利費 | C14: 1758045 | D14: 1788084 | E14: 2220489 | F14: 1376127
B15: 通勤費 | C15: 1284201 | D15: 1032904 | E15: 1157687 | F15: 1276339
B16: 【製造経費】 | C16: =SUM(C17:C39) -> 66816119 | D16: =SUM(D17:D39) -> 65159918 | E16: =SUM(E17:E39) -> 82593608 | F16: =SUM(F17:F39) -> 84544559
B17: 設備保守料 | C17: 2473700 | D17: 1779600 | E17: 1717600 | F17: 1768400
B18: 損害保険料 | C18: 908176 | D18: 912237 | E18: 940667 | F18: 1191590
B19: 備品費 | C19: 30000 | D19: 302800 | E19: 2764152 | F19: 2568782
B20: 地代家賃 | C20: 0 | D20: 0 | E20: 0 | F20: 0
B21: 借上料 | C21: 5244500 | D21: 5010000 | E21: 5010000 | F21: 5046600
B22: 修繕費 | C22: 3238944 | D22: 4172889 | E22: 6553786 | F22: 7541725
B23: 光熱費 | C23: 4000 | D23: 1372 | E23: 1233 | F23: 1530
B24: 動力費 | C24: 42893945 | D24: 32385919 | E24: 33957442 | F24: 33684675 | G24: 電力料。64期は電気料金高騰期
B25: 薬品諸油費 | C25: 2657460 | D25: 3426660 | E25: 3972450 | F25: 3512750
B26: 消耗品費 | C26: 1563032 | D26: 597514 | E26: 745684 | F26: 1236794
B27: 衛生費 | C27: 1348895 | D27: 1311634 | E27: 1299930 | F27: 1077282
B28: 原水処理費 | C28: 0 | D28: 0 | E28: 0 | F28: 0
B29: 車輛関係費 | C29: 937900 | D29: 2064340 | E29: 1566120 | F29: 1053620
B30: 車輛保険料 | C30: 73890 | D30: 74730 | E30: 77670 | F30: 81960
B31: 事務関係費 | C31: 0 | D31: 0 | E31: 0 | F31: 0
B32: 通信費 | C32: 7800 | D32: 6650 | E32: 6200 | F32: 11950
B33: 新聞図書費 | C33: 50004 | D33: 38159 | E33: 21489 | F33: 21488
B34: 旅費交通費 | C34: 0 | D34: 0 | E34: 0 | F34: 0
B35: 会議研修費 | C35: 4111 | D35: 2140 | E35: 889 | F35: 167000
B36: 組合費 | C36: 426573 | D36: 411300 | E36: 411600 | F36: 475100
... B38: 税金公課 | C38: 3258900 | D38: 3254700 | E38: 3212900 | F38: 3228200
B39: 減価償却費 | C39: 19763 | D39: 8323500 | E39: 17893259 | F39: 19820169 | G39: 64期はほぼ償却計上なし（19,763円）
B40: 【外注加工費】 | C40: =SUM(C41:C41) -> 2915685 | D40: =SUM(D41:D41) -> 5680739 | E40: =SUM(E41:E41) -> 13626626 | F40: =SUM(F41:F41) -> 11434787
B41: 外注作業費 | C41: 2915685 | D41: 5680739 | E41: 13626626 | F41: 11434787
B42: 【製造勘定】 | C42: =C43-C44 -> -23408 | D42: =D43-D44 -> -30184 | E42: =E43-E44 -> -28952 | F42: =F43-F44 -> -119196
B43: 期首仕掛品 | C43: 675444 | D43: 698852 | E43: 729036 | F43: 757988
...

Sheet SGA
B2: 販売費及び一般管理費 単位：千円（入力は円）
B4: 科目 | C4: ='BS(借方)'!C4 -> 2023年3月期 | D4: ='BS(借方)'!D4 -> 2024年3月期 | E4: ='BS(借方)'!E4 -> 2025年3月期 | F4: ='BS(借方)'!F4 -> 2026年3月期 | G4: 備考
B5: （給与関係費） | C5: =SUM(C6:C13) -> 21464143 | D5: =SUM(D6:D13) -> 21065469 | E5: =SUM(E6:E13) -> 23458472 | F5: =SUM(F6:F13) -> 23527651
B6: 役員報酬 | C6: 7200000 | D6: 7200000 | E6: 7200000 | F6: 7200000 | G6: 代表取締役 小野田洋 月額600千円
B7: 給与 | C7: 10599473 | D7: 10109435 | E7: 11966797 | F7: 11506863
B8: 賞与 | C8: 723000 | D8: 730000 | E8: 972000 | F8: 1413000
B9: 退職給与 | C9: 0 | D9: 307000 | E9: 0 | F9: 0
B10: 法定福利費 | C10: 2715216 | D10: 2540936 | E10: 3066033 | F10: 3153781
B11: 退職共済金 | C11: 120000 | D11: 120000 | E11: 120000 | F11: 120000
B12: 福利厚生費 | C12: 4720 | D12: 0 | E12: 0 | F12: 4802
B13: 通勤費 | C13: 101734 | D13: 58098 | E13: 133642 | F13: 129205
B14: （資産管理費） | C14: =SUM(C15:C24) -> 5426413 | D14: =SUM(D15:D24) -> 5193598 | E14: =SUM(E15:E24) -> 5119422 | F14: =SUM(F15:F24) -> 6634973
B15: 設備保守料 | C15: 104072 | D15: 225000 | E15: 30000 | F15: 45000
B16: 損害保険料 | C16: 0 | D16: 0 | E16: 0 | F16: 0
B17: 備品費 | C17: 165982 | D17: 522466 | E17: 14000 | F17: 260939
B18: 地代家賃 | C18: 1745460 | D18: 1745460 | E18: 1745460 | F18: 1745460 | G18: 駐車場（代表者から賃借）545,460円＋松戸営業所店舗1,200,000円
B19: 借上料 | C19: 1036800 | D19: 352960 | E19: 935400 | F19: 1755600
B20: 修繕費 | C20: 47000 | D20: 679400 | E20: 183340 | F20: 1052000
B21: 水道料 | C21: 14765 | D21: 16818 | E21: 16576 | F21: 27318
B22: 光熱費 | C22: 0 | D22: 0 | E22: 0 | F22: 0
B23: 動力費 | C23: 2122258 | D23: 1597398 | E23: 1746387 | F23: 1702675
B24: 消耗品費 | C24: 190076 | D24: 54096 | E24: 448259 | F24: 45981
B25: （輸送関係費） | C25: =SUM(C26:C29) -> 20950477 | D25: =SUM(D26:D29) -> 33504224 | E25: =SUM(E26:E29) -> 29684699 | F25: =SUM(F26:F29) -> 37540944
B26: 車輛関係費 | C26: 6731950 | D26: 9546435 | E26: 6157562 | F26: 8554275
B27: 車輛保険料 | C27: 865490 | D27: 864014 | E27: 676560 | F27: 626800
B28: 車輛借上料 | C28: 350000 | D28: 1050000 | E28: 1281000 | F28: 790000
B29: 運賃 | C29: 13003037 | D29: 22043775 | E29: 21569577 | F29: 27569869 | G29: 配送委託（倉橋運送・鴻池運輸等）
B30: （交際販売関係費） | C30: =SUM(C31:C33) -> 799841 | D30: =SUM(D31:D33) -> 950969 | E30: =SUM(E31:E33) -> 964692 | F30: =SUM(F31:F33) -> 830503
B31: 交際接待費 | C31: 76950 | D31: 94000 | E31: 47000 | F31: 46000
B32: 販売関係費 | C32: 80600 | D32: 91891 | E32: 33634 | F32: 65103
B33: 広告宣伝費 | C33: 642291 | D33: 765078 | E33: 884058 | F33: 719400
B34: （事務処理費） | C34: =SUM(C35:C41) -> 4117984 | D34: =SUM(D35:D41) -> 5359472 | E34: =SUM(E35:E41) -> 4946870 | F34: =SUM(F35:F41) -> 6820643
B35: 事務関係費 | C35: 2036272 | D35: 2269239 | E35: 2256449 | F35: 4667404
B36: 通信費 | C36: 1100453 | D36: 1250200 | E36: 1097345 | F36: 1272153
B37: 新聞図書費 | C37: 29483 | D37: 0 | E37: 0 | F37: 0
B38: 旅費交通費 | C38: 510856 | D38: 498435 | E38: 233772 | F38: 354877
B39: 会議研修費 | C39: 322 | D39: 0 | E39: 0 | F39: 0
B40: 組合費 | C40: 58000 | D40: 58000 | E40: 58000 | F40: 70000
B41: 雑費 | C41: 382598 | D41: 1283598 | E41: 1301304 | F41: 456209
B42: （その他） | C42: =SUM(C43:C44) -> 1736422 | D42: =SUM(D43:D44) -> 5168591 | E42: =SUM(E43:E44) -> 4395505 | F42: =SUM(F43:F44) -> 4229217
...

Sheet VR→
B2: VR セクション

Sheet 株式価値 
B2: 株式価値の試算結果（サマリー） 単位：千円
B4: 手法 | C4: 下限 | D4: 中央 | E4: 上限 | F4: 備考
B5: コストアプローチ（年買法） | C5: =年買法!C16 -> -70667235 | D5: =年買法!D16 -> -59892236 | E5: =年買法!E16 -> -49117237 | F5: 時価純資産がマイナスのため、営業権を加算しても株式価値はマイナス
B6: マーケットアプローチ（EV/EBITDA法） | C6: ='EV EBITDAマルチプル'!C17 -> -310194459 | D6: ='EV EBITDAマルチプル'!D17 -> -285076229 | E6: ='EV EBITDAマルチプル'!E17 -> -259957999 | F6: 有利子負債（461,024千円）が事業価値を上回るためマイナス
B7: （参考）時価純資産 | C7: ='修正BS(貸方) '!E14 -> -81442234 | D7: ='修正BS(貸方) '!E14 -> -81442234 | E7: ='修正BS(貸方) '!E14 -> -81442234
B8: （参考）簿価純資産 | C8: ='BS (貸方)'!F21 -> 49288196 | D8: ='BS (貸方)'!F21 -> 49288196 | E8: ='BS (貸方)'!F21 -> 49288196
B9: （参考）事業価値EV（ディスカウント後） | C9: ='EV EBITDAマルチプル'!C15 -> 75354691 | D9: ='EV EBITDAマルチプル'!D15 -> 100472921 | E9: ='EV EBITDAマルチプル'!E15 -> 125591151
B10: （参考）ネットデット | C10: =-ネットキャッシュ!C12 -> 385549150 | D10: =-ネットキャッシュ!C12 -> 385549150 | E10: =-ネットキャッシュ!C12 -> 385549150
B11: （感応度）年買法・建物簿価評価の場合 | C11: =年買法!C22 -> 97352800 | D11: =年買法!D22 -> 108127799 | E11: =年買法!E22 -> 118902798 | F11: 建物の評価替えを行わない場合。買手が建物の残存価値をどう見るかで大きく変動
B12: 結論：算定上の株式価値 | C12: =MAX(0,MAX(C5:E6)) -> 0 | F12: 基本ケース（建物＝固定資産税評価額）では両手法とも算定上マイナスで、株式価値は備忘価額程度。ただし建物を簿価評価すると年買法はプラス（11行）に転じるため、建物時価の検証が最重要。実質的な交渉論点は有利子負債の承継・代表者保証の解除・担保差替え

Sheet 修正BS(借方)
B2: 修正貸借対照表（資産の部） 評価基準日：2026年3月31日 単位：千円
B4: 科目 | C4: 簿価 | D4: 修正額 | E4: 修正後 | F4: 修正内容
B5: 現金及び預金（保険積立除く） | C5: ='BS(借方)'!F6+'BS(借方)'!F7+'BS(借方)'!F8+'BS(借方)'!F9+'BS(借方)'!F10 -> 66599556 | D5: 0 | E5: =C5+D5 -> 66599556 | F5: 定期預金の内訳差異6,800千円は要確認
B6: 売掛金 | C6: ='BS(借方)'!F14 -> 28798405 | D6: 0 | E6: =C6+D6 -> 28798405 | F6: 年齢表未受領のため簿価
B7: 棚卸資産 | C7: ='BS(借方)'!F15 -> 34490885 | D7: 0 | E7: =C7+D7 -> 34490885 | F7: 滞留在庫は要確認のため簿価
B8: その他流動資産 | C8: ='BS(借方)'!F20 -> 3063104 | D8: 0 | E8: =C8+D8 -> 3063104 | F8: 従業員貸付金・未収金・前払費用等
B9: 保険積立金 | C9: ='BS(借方)'!F11 -> 9362494 | D9: =保険!E7 -> 0 | E9: =C9+D9 -> 9362494 | F9: 解約返戻金未受領のため簿価（要確認）
B10: 建物 | C10: ='BS(借方)'!F30 -> 259241627 | D10: =土地!J6 -> -168020035 | E10: =C10+D10 -> 91221592 | F10: 固定資産税評価額へ評価替え
B11: 構築物 | C11: ='BS(借方)'!F31 -> 2116299 | D11: =減価償却!I6 -> -447749 | E11: =C11+D11 -> 1668550 | F11: 当期償却不足額を減額
B12: 機械 | C12: ='BS(借方)'!F32 -> 99691427 | D12: =減価償却!I7 -> -3092403 | E12: =C12+D12 -> 96599024 | F12: 当期償却不足額を減額
B13: 車両運搬具・器具備品 | C13: ='BS(借方)'!F33+'BS(借方)'!F34 -> 8224003 | D13: 0 | E13: =C13+D13 -> 8224003 | F13: 償却不足なし
B14: 土地 | C14: ='BS(借方)'!F35 -> 40441919 | D14: =土地!J5 -> 40829757 | E14: =C14+D14 -> 81271676 | F14: 固定資産税評価額÷0.7
B15: 特許商標権 | C15: ='BS(借方)'!F37 -> 354300 | D15: 0 | E15: =C15+D15 -> 354300 | F15: 簿価（商標の内容は要確認）
B16: 出資金 | C16: ='BS(借方)'!F39 -> 820000 | D16: 0 | E16: =C16+D16 -> 820000 | F16: 簿価
B17: 資産合計 | C17: =SUM(C5:C16) -> 553204019 | D17: =SUM(D5:D16) -> -130730430 | E17: =SUM(E5:E16) -> 422473589
B18: 簿価の検算（BS資産合計との一致） | C18: =EXACT(C17,'BS(借方)'!F42) -> TRUE

Sheet 修正BS(貸方) 
B2: 修正貸借対照表（負債・純資産の部） 評価基準日：2026年3月31日 単位：千円
B4: 科目 | C4: 簿価 | D4: 修正額 | E4: 修正後 | F4: 修正内容
B5: 支払手形・買掛金 | C5: ='BS (貸方)'!F6+'BS (貸方)'!F7 -> 24493672 | D5: 0 | E5: =C5+D5 -> 24493672 | F5: —
B6: 借入金（短期・長期） | C6: ='BS (貸方)'!F24 -> 461024000 | D6: 0 | E6: =C6+D6 -> 461024000 | F6: 代表者借入14,000千円・公庫資本性ローン105,420千円を含む
B7: 未払金 | C7: ='BS (貸方)'!F9 -> 15721057 | D7: 0 | E7: =C7+D7 -> 15721057 | F7: 3月分給与・未払消費税を含む
B8: 未払法人税等 | C8: ='BS (貸方)'!F12 -> 487200 | D8: 0 | E8: =C8+D8 -> 487200 | F8: —
B9: その他流動負債 | C9: ='BS (貸方)'!F10+'BS (貸方)'!F11 -> 2189894 | D9: 0 | E9: =C9+D9 -> 2189894 | F9: —
B10: 賞与引当金 | C10: =0 -> 0 | D10: 0 | E10: =C10+D10 -> 0 | F10: 支給規程未確認のため未計上（要確認）
B11: 退職給付引当金 | C11: =0 -> 0 | D11: 0 | E11: =C11+D11 -> 0 | F11: 退職金規程未確認のため未計上（要確認）
B12: 負債合計 | C12: =SUM(C5:C11) -> 503915823 | D12: =SUM(D5:D11) -> 0 | E12: =SUM(E5:E11) -> 503915823
B13: 評価差額に係る税効果 | C13: 0 | D13: =税効果!C8 -> 0 | E13: =C13+D13 -> 0 | F13: 「税効果」シート参照
B14: 純資産（時価純資産） | C14: ='修正BS(借方)'!C17-C12-C13 -> 49288196 | D14: ='修正BS(借方)'!D17-D12-D13 -> -130730430 | E14: ='修正BS(借方)'!E17-E12-E13 -> -81442234
B15: 簿価純資産の検算（BS純資産との一致） | C15: =EXACT(C14,'BS (貸方)'!F21) -> TRUE

Sheet 売掛・棚卸
B2: 売掛金・棚卸資産の評価
B4: 売掛金：年齢表・補助残高一覧が未受領のため簿価評価（要確認）。月末締め翌月末回収（法人事業概況説明書）。
B5: 67期内訳書の上位先合計が残高を1,723,680円超過しており、(株)小野田商店の計上区分を確認する（要確認）。
B6: (株)小野田商店は代表者と同姓であり、関連当事者取引か否かを確認する（要確認）。
B7: 棚卸資産：実地棚卸（2026年3月31日実施）に基づく計上。商品20,661千円（加工氷・袋氷等）、原材料12,953千円（ロール・段ボール・ビニール袋等）。滞留・陳腐化の有無は要確認のため簿価評価。

Sheet 減価償却
B2: 減価償却資産の検討（評価基準日：2026年3月31日）
B4: 科目 | C4: 件数 | D4: 取得価額 | E4: 期末簿価 | F4: 当期償却額 | G4: 当期償却不足額 | H4: 償却累計額 | I4: 修正額 | J4: 評価の考え方
B5: 建物 | C5: 5 | D5: 325235134 | E5: 259241627 | F5: 0 | G5: 21745406 | H5: 65993507 | I5: 0 | J5: 「土地」シートで固定資産税評価額へ評価替え（本シートでは修正しない）
B6: 構築物 | C6: 12 | D6: 14745890 | E6: 2116299 | F6: 0 | G6: 447749 | H6: 12629591 | I6: =-G6 -> -447749 | J6: 当期償却不足額を減額（累積不足額は資料不足のため未反映・要確認）
B7: 機械 | C7: 127 | D7: 374955783 | E7: 99691427 | F7: 19089010 | G7: 3092403 | H7: 275264355 | I7: =-G7 -> -3092403 | J7: 当期償却不足額を減額（累積不足額は資料不足のため未反映・要確認）
B8: 車両運搬具 | C8: 23 | D8: 49704921 | E8: 4905291 | F8: 2440512 | G8: 0 | H8: 44261381 | I8: 0 | J8: 償却不足なし。簿価評価
B9: 器具備品 | C9: 18 | D9: 9896000 | E9: 3318712 | F9: 805803 | G9: 0 | H9: 6577288 | I9: 0 | J9: 償却不足なし。簿価評価
B10: 合計 | D10: =SUM(D5:D9) -> 774537728 | E10: =SUM(E5:E9) -> 369273356 | F10: =SUM(F5:F9) -> 22335325 | G10: =SUM(G5:G9) -> 25285558 | H10: =SUM(H5:H9) -> 404726122 | I10: =SUM(I5:I9) -> -3540152
B12: ※主たる工場建物（越谷工場本体、1991年3月取得、取得価額302,052千円、旧定率法・耐用年数26年）は償却累計額55,762千円にとどまり、税務上の償却可能限度に対し大幅な償却不足の状態。
B13: ※機械の当期償却額は管理費108,503円＋製造費18,980,507円。当期償却額合計22,335,325円はPLの減価償却費（製造19,820,169円＋販管2,515,156円）と一致。

Sheet 土地
B2: 不動産（土地・建物）の時価評価
B4: 種類 | C4: 区分 | D4: 所在地 | E4: 面積（㎡） | F4: 簿価 | G4: 固定資産税評価額 | H4: 割戻率 | I4: 時価 | J4: 修正額 | K4: 評価の考え方
B5: 土地 | C5: 越谷工場 | D5: 埼玉県越谷市大字平方999-4 | E5: 2145.18 | F5: ='BS(借方)'!F35 -> 40441919 | G5: 56890173 | H5: 0.7 | I5: =ROUND(G5/H5,0) -> 81271676 | J5: =I5-F5 -> 40829757 | K5: 固定資産税評価額は公示価格水準の概ね7割とされるため÷0.7で時価を推計。路線価による検証は要確認
B6: 建物 | C6: 越谷工場 | D6: 埼玉県越谷市大字平方999-4 | E6: 2093.87 | F6: ='BS(借方)'!F30 -> 259241627 | G6: 91221592 | H6: 1 | I6: =ROUND(G6/H6,0) -> 91221592 | J6: =I6-F6 -> -168020035 | K6: 建物は固定資産税評価額を時価相当額とみなす（再調達原価法による検証は未実施）。簿価は会計上の償却停止により実態を大きく上回る
B7: 合計 | F7: =SUM(F5:F6) -> 299683546 | G7: =SUM(G5:G6) -> 148111765 | I7: =SUM(I5:I6) -> 172493268 | J7: =SUM(J5:J6) -> -127190278
B9: ※固定資産税評価額は受領資料（2025年3月期時点の所有物件一覧）記載値。最新年度の評価証明書で更新要。建物の面積は登記2,093.87㎡／内訳書2,065.00㎡で差異あり（要確認）。
B10: ※代表者個人所有の土地（栃木銀行・商工中金の担保提供）は会社資産ではないため評価対象外。所在地・面積・譲渡後の取扱いは要確認。

Sheet 保険
B2: 保険積立金の評価
B4: 保険会社 | C4: 簿価 | D4: 解約返戻金 | E4: 修正額 | F4: 備考
B5: 大同生命保険 | C5: 8461965 | D5: =C5 -> 8461965 | E5: =D5-C5 -> 0 | F5: 解約返戻金額の資料未受領のため簿価評価（要確認）。被保険者・契約形態も要確認
B6: 第一生命保険 | C6: 900529 | D6: =C6 -> 900529 | E6: =D6-C6 -> 0 | F6: 解約返戻金額の資料未受領のため簿価評価（要確認）。被保険者・契約形態も要確認
B7: 合計 | C7: =SUM(C5:C6) -> 9362494 | D7: =SUM(D5:D6) -> 9362494 | E7: =SUM(E5:E6) -> 0
B9: ※BS上は現預金の「諸掛金」に含めて表示。評価上は保険積立金として区分する。67期に無配当満期定期保険の返戻金2,295,725円を雑収入計上。

Sheet 有価証券
B2: 有価証券の評価
B4: 該当なし：上場有価証券の保有なし。
B5: 出資金820,000円（越谷市工業団地組合800,000円、埼玉縣信用金庫10,000円ほか）は換金性に乏しいが少額のため簿価評価。

Sheet 未払人件費・賞与
B2: 未払人件費・賞与引当の検討
B4: 給与：月末締め翌月20日払い。3月分給与5,720,681円は未払金に計上済みのため追加計上なし。
B5: 賞与：賞与引当金の計上なし。支給時期・支給対象期間が未確認のため評価上も未計上（要確認：支給規程・夏季賞与の算定期間）。

Sheet 退職金
B2: 退職給付債務の検討
B4: 退職給付引当金の計上なし。販管費に退職共済金120,000円／年（中小企業退職金共済と推察）。
B5: 67期に製造原価の退職給与6,177,985円が発生（過去3期は発生なし）。退職金規程の有無・社内積立部分の要支給額は未確認のため、評価上は債務計上せず（要確認）。

Sheet 税効果
B2: 評価差額に係る税効果
B5: 評価差額（資産修正額合計－負債修正額合計） | C5: ='修正BS(借方)'!D17-'修正BS(貸方) '!D12 -> -130730430
B6: 実効税率 | C6: 0.34
B7: 税効果（評価益の場合のみ繰延税金負債を認識） | C7: =IF(C5>0,ROUND(C5*C6,0),0) -> 0
B8: 修正BSへ反映する税効果（負債） | C8: =C7 -> 0
B10: 評価差額が純額で評価損（含み損）となる場合、繰延税金資産の回収可能性（課税所得の見込み）が不確実なため保守的に認識しない。土地の評価益に対応する税効果は建物の評価損と相殺して判定。

Sheet ネットキャッシュ
B2: ネットキャッシュの算定（評価基準日：2026年3月31日）
B4: 項目 | C4: 金額 | D4: 判断根拠
B5: 現金及び預金（保険積立除く） | C5: ='修正BS(借方)'!E5 -> 66599556 | D5: キャッシュライク
B6: 保険積立金 | C6: ='修正BS(借方)'!E9 -> 9362494 | D6: 換金可能な非事業用資産としてキャッシュライク（解約返戻金で要更新）
B7: キャッシュライク計 | C7: =C5+C6 -> 75962050
B8: 借入金（金融機関） | C8: ='修正BS(貸方) '!E6-14000000 -> 447024000 | D8: 有利子負債。うち日本公庫資本性ローン105,420千円を含む
B9: 代表者借入金 | C9: =14000000 -> 14000000 | D9: 代表者からの借入。クロージング時の返済／放棄の取扱いは要協議
B10: 未払法人税等 | C10: ='修正BS(貸方) '!E8 -> 487200 | D10: デットライク
B11: デットライク計 | C11: =SUM(C8:C10) -> 461511200
B12: ネットキャッシュ（△はネットデット） | C12: =C7-C11 -> -385549150
B14: （参考）資本性ローンを資本とみなした場合のネットキャッシュ | C14: =C12+105420000 -> -280129150
B15: ※日本政策金融公庫の資本性ローンは金融機関の債務者区分上は自己資本とみなされるが、期限一括返済の債務であり評価上は有利子負債として扱う。

Sheet 修正PL
B2: 正常収益力の算定（修正損益計算書） 単位：千円
B4: 科目 | C4: 2024年3月期 | F4: 2025年3月期 | I4: 2026年3月期 | L4: 備考
C5: 帳簿価額 | D5: 修正額 | E5: 修正後 | F5: 帳簿価額 | G5: 修正額 | H5: 修正後 | I5: 帳簿価額 | J5: 修正額 | K5: 修正後
B6: 売上高 | C6: =PL!E5 -> 376221193 | D6: 0 | E6: =C6+D6 -> 376221193 | F6: =PL!G5 -> 382684537 | G6: 0 | H6: =F6+G6 -> 382684537 | I6: =PL!I5 -> 405963400 | J6: 0 | K6: =I6+J6 -> 405963400
B7: 売上原価 | C7: =PL!E9 -> 279653851 | D7: =修正CR!D41 -> 0 | E7: =C7+D7 -> 279653851 | F7: =PL!G9 -> 297300134 | G7: =修正CR!G41 -> 0 | H7: =F7+G7 -> 297300134 | I7: =PL!I9 -> 316589415 | J7: =修正CR!J41 -> -6177985 | K7: =I7+J7 -> 310411430
B8: 売上総利益 | C8: =PL!E15 -> 96567342 | D8: =D6-D7 -> 0 | E8: =C8+D8 -> 96567342 | F8: =PL!G15 -> 85384403 | G8: =G6-G7 -> 0 | H8: =F8+G8 -> 85384403 | I8: =PL!I15 -> 89373985 | J8: =J6-J7 -> 6177985 | K8: =I8+J8 -> 95551970
B9: 販売費及び一般管理費 | C9: =PL!E16 -> 71242323 | D9: =修正SGA!D40 -> -307000 | E9: =C9+D9 -> 70935323 | F9: =PL!G16 -> 71725529 | G9: =修正SGA!G40 -> 0 | H9: =F9+G9 -> 71725529 | I9: =PL!I16 -> 81348592 | J9: =修正SGA!J40 -> 0 | K9: =I9+J9 -> 81348592
B10: 営業利益 | C10: =PL!E24 -> 25325019 | D10: =D8-D9 -> 307000 | E10: =C10+D10 -> 25632019 | F10: =PL!G24 -> 13658874 | G10: =G8-G9 -> 0 | H10: =F10+G10 -> 13658874 | I10: =PL!I24 -> 8025393 | J10: =J8-J9 -> 6177985 | K10: =I10+J10 -> 14203378
B11: 減価償却費 | C11: =PL!E41 -> 11322083 | D11: 0 | E11: =C11+D11 -> 11322083 | F11: =PL!G41 -> 20417838 | G11: 0 | H11: =F11+G11 -> 20417838 | I11: =PL!I41 -> 22335325 | J11: 0 | K11: =I11+J11 -> 22335325
B12: EBITDA | C12: =C10+C11 -> 36647102 | D12: =D10+D11 -> 307000 | E12: =E10+E11 -> 36954102 | F12: =F10+F11 -> 34076712 | G12: =G10+G11 -> 0 | H12: =H10+H11 -> 34076712 | I12: =I10+I11 -> 30360718 | J12: =J10+J11 -> 6177985 | K12: =K10+K11 -> 36538703
B14: 【調整項目】（＋は利益に加算）
B15: 退職給与（製造原価・販管費） | D15: =SGA!D9+CR!D12 -> 307000 | G15: =SGA!E9+CR!E12 -> 0 | J15: =SGA!F9+CR!F12 -> 6177985 | L15: 退職者に対する臨時的な支出と推察し加算（退職金規程・対象者は要確認）
B16: 役員報酬（新体制の標準報酬へ置換） | D16: 0 | G16: 0 | J16: 0 | L16: 現行7,200千円／年は経営者報酬として過大ではなく、後任経営者の標準報酬と同水準と想定し調整なし
B17: 調整額合計 | D17: =SUM(D15:D16) -> 307000 | G17: =SUM(G15:G16) -> 0 | J17: =SUM(J15:J16) -> 6177985
B18: 検算（調整額合計＝営業利益の修正額） | D18: =EXACT(D17,D10) -> TRUE | G18: =EXACT(G17,G10) -> TRUE | J18: =EXACT(J17,J10) -> TRUE
B20: 【調整しなかった項目と理由】
B21: ・減価償却費：建物は会計上償却を停止しており、営業利益ベースの収益力は償却負担を過少に織り込んでいる可能性がある。このためEBITDAベースのマーケットアプローチを重視する。
B22: ・支払手数料（66期3,155,869円・67期1,764,661円）：内容未確認のため調整せず。一過性の専門家報酬等であれば加算余地あり（要確認）。
B23: ・地代家賃（代表者からの駐車場賃借545,460円／年）：譲渡後も継続利用を前提に調整せず。条件は要協議。
B24: ・雑収入の保険返戻金（67期2,295,725円）：営業外項目のため営業利益・EBITDAに影響なし。

Sheet 修正SGA
B2: 販売費及び一般管理費の修正 単位：千円
B4: 科目 | C4: 2024年3月期 | F4: 2025年3月期 | I4: 2026年3月期 | L4: 修正理由
C5: 帳簿価額 | D5: 修正額 | E5: 修正後 | F5: 帳簿価額 | G5: 修正額 | H5: 修正後 | I5: 帳簿価額 | J5: 修正額 | K5: 修正後
B6: 給与関係費／役員報酬 | C6: =SGA!D6 -> 7200000 | D6: 0 | E6: =C6+D6 -> 7200000 | F6: =SGA!E6 -> 7200000 | G6: 0 | H6: =F6+G6 -> 7200000 | I6: =SGA!F6 -> 7200000 | J6: 0 | K6: =I6+J6 -> 7200000
B7: 給与関係費／給与 | C7: =SGA!D7 -> 10109435 | D7: 0 | E7: =C7+D7 -> 10109435 | F7: =SGA!E7 -> 11966797 | G7: 0 | H7: =F7+G7 -> 11966797 | I7: =SGA!F7 -> 11506863 | J7: 0 | K7: =I7+J7 -> 11506863
B8: 給与関係費／賞与 | C8: =SGA!D8 -> 730000 | D8: 0 | E8: =C8+D8 -> 730000 | F8: =SGA!E8 -> 972000 | G8: 0 | H8: =F8+G8 -> 972000 | I8: =SGA!F8 -> 1413000 | J8: 0 | K8: =I8+J8 -> 1413000
B9: 給与関係費／退職給与 | C9: =SGA!D9 -> 307000 | D9: =-C9 -> -307000 | E9: =C9+D9 -> 0 | F9: =SGA!E9 -> 0 | G9: =-F9 -> 0 | H9: =F9+G9 -> 0 | I9: =SGA!F9 -> 0 | J9: =-I9 -> 0 | K9: =I9+J9 -> 0 | L9: 臨時的な退職金支出として控除（要確認）
B10: 給与関係費／法定福利費 | C10: =SGA!D10 -> 2540936 | D10: 0 | E10: =C10+D10 -> 2540936 | F10: =SGA!E10 -> 3066033 | G10: 0 | H10: =F10+G10 -> 3066033 | I10: =SGA!F10 -> 3153781 | J10: 0 | K10: =I10+J10 -> 3153781
B11: 給与関係費／退職共済金 | C11: =SGA!D11 -> 120000 | D11: 0 | E11: =C11+D11 -> 120000 | F11: =SGA!E11 -> 120000 | G11: 0 | H11: =F11+G11 -> 120000 | I11: =SGA!F11 -> 120000 | J11: 0 | K11: =I11+J11 -> 120000
B12: 給与関係費／福利厚生費 | C12: =SGA!D12 -> 0 | D12: 0 | E12: =C12+D12 -> 0 | F12: =SGA!E12 -> 0 | G12: 0 | H12: =F12+G12 -> 0 | I12: =SGA!F12 -> 4802 | J12: 0 | K12: =I12+J12 -> 4802
B13: 給与関係費／通勤費 | C13: =SGA!D13 -> 58098 | D13: 0 | E13: =C13+D13 -> 58098 | F13: =SGA!E13 -> 133642 | G13: 0 | H13: =F13+G13 -> 133642 | I13: =SGA!F13 -> 129205 | J13: 0 | K13: =I13+J13 -> 129205
B14: 資産管理費／設備保守料 | C14: =SGA!D15 -> 225000 | D14: 0 | E14: =C14+D14 -> 225000 | F14: =SGA!E15 -> 30000 | G14: 0 | H14: =F14+G14 -> 30000 | I14: =SGA!F15 -> 45000 | J14: 0 | K14: =I14+J14 -> 45000
B15: 資産管理費／損害保険料 | C15: =SGA!D16 -> 0 | D15: 0 | E15: =C15+D15 -> 0 | F15: =SGA!E16 -> 0 | G15: 0 | H15: =F15+G15 -> 0 | I15: =SGA!F16 -> 0 | J15: 0 | K15: =I15+J15 -> 0
B16: 資産管理費／備品費 | C16: =SGA!D17 -> 522466 | D16: 0 | E16: =C16+D16 -> 522466 | F16: =SGA!E17 -> 14000 | G16: 0 | H16: =F16+G16 -> 14000 | I16: =SGA!F17 -> 260939 | J16: 0 | K16: =I16+J16 -> 260939
B17: 資産管理費／地代家賃 | C17: =SGA!D18 -> 1745460 | D17: 0 | E17: =C17+D17 -> 1745460 | F17: =SGA!E18 -> 1745460 | G17: 0 | H17: =F17+G17 -> 1745460 | I17: =SGA!F18 -> 1745460 | J17: 0 | K17: =I17+J17 -> 1745460
B18: 資産管理費／借上料 | C18: =SGA!D19 -> 352960 | D18: 0 | E18: =C18+D18 -> 352960 | F18: =SGA!E19 -> 935400 | G18: 0 | H18: =F18+G18 -> 935400 | I18: =SGA!F19 -> 1755600 | J18: 0 | K18: =I18+J18 -> 1755600
B19: 資産管理費／修繕費 | C19: =SGA!D20 -> 679400 | D19: 0 | E19: =C19+D19 -> 679400 | F19: =SGA!E20 -> 183340 | G19: 0 | H19: =F19+G19 -> 183340 | I19: =SGA!F20 -> 1052000 | J19: 0 | K19: =I19+J19 -> 1052000
B20: 資産管理費／水道料 | C20: =SGA!D21 -> 16818 | D20: 0 | E20: =C20+D20 -> 16818 | F20: =SGA!E21 -> 16576 | G20: 0 | H20: =F20+G20 -> 16576 | I20: =SGA!F21 -> 27318 | J20: 0 | K20: =I20+J20 -> 27318
B21: 資産管理費／光熱費 | C21: =SGA!D22 -> 0 | D21: 0 | E21: =C21+D21 -> 0 | F21: =SGA!E22 -> 0 | G21: 0 | H21: =F21+G21 -> 0 | I21: =SGA!F22 -> 0 | J21: 0 | K21: =I21+J21 -> 0
B22: 資産管理費／動力費 | C22: =SGA!D23 -> 1597398 | D22: 0 | E22: =C22+D22 -> 1597398 | F22: =SGA!E23 -> 1746387 | G22: 0 | H22: =F22+G22 -> 1746387 | I22: =SGA!F23 -> 1702675 | J22: 0 | K22: =I22+J22 -> 1702675
B23: 資産管理費／消耗品費 | C23: =SGA!D24 -> 54096 | D23: 0 | E23: =C23+D23 -> 54096 | F23: =SGA!E24 -> 448259 | G23: 0 | H23: =F23+G23 -> 448259 | I23: =SGA!F24 -> 45981 | J23: 0 | K23: =I23+J23 -> 45981
B24: 輸送関係費／車輛関係費 | C24: =SGA!D26 -> 9546435 | D24: 0 | E24: =C24+D24 -> 9546435 | F24: =SGA!E26 -> 6157562 | G24: 0 | H24: =F24+G24 -> 6157562 | I24: =SGA!F26 -> 8554275 | J24: 0 | K24: =I24+J24 -> 8554275
B25: 輸送関係費／車輛保険料 | C25: =SGA!D27 -> 864014 | D25: 0 | E25: =C25+D25 -> 864014 | F25: =SGA!E27 -> 676560 | G25: 0 | H25: =F25+G25 -> 676560 | I25: =SGA!F27 -> 626800 | J25: 0 | K25: =I25+J25 -> 626800
B26: 輸送関係費／車輛借上料 | C26: =SGA!D28 -> 1050000 | D26: 0 | E26: =C26+D26 -> 1050000 | F26: =SGA!E28 -> 1281000 | G26: 0 | H26: =F26+G26 -> 1281000 | I26: =SGA!F28 -> 790000 | J26: 0 | K26: =I26+J26 -> 790000
B27: 輸送関係費／運賃 | C27: =SGA!D29 -> 22043775 | D27: 0 | E27: =C27+D27 -> 22043775 | F27: =SGA!E29 -> 21569577 | G27: 0 | H27: =F27+G27 -> 21569577 | I27: =SGA!F29 -> 27569869 | J27: 0 | K27: =I27+J27 -> 27569869
B28: 交際販売関係費／交際接待費 | C28: =SGA!D31 -> 94000 | D28: 0 | E28: =C28+D28 -> 94000 | F28: =SGA!E31 -> 47000 | G28: 0 | H28: =F28+G28 -> 47000 | I28: =SGA!F31 -> 46000 | J28: 0 | K28: =I28+J28 -> 46000
B29: 交際販売関係費／販売関係費 | C29: =SGA!D32 -> 91891 | D29: 0 | E29: =C29+D29 -> 91891 | F29: =SGA!E32 -> 33634 | G29: 0 | H29: =F29+G29 -> 33634 | I29: =SGA!F32 -> 65103 | J29: 0 | K29: =I29+J29 -> 65103
B30: 交際販売関係費／広告宣伝費 | C30: =SGA!D33 -> 765078 | D30: 0 | E30: =C30+D30 -> 765078 | F30: =SGA!E33 -> 884058 | G30: 0 | H30: =F30+G30 -> 884058 | I30: =SGA!F33 -> 719400 | J30: 0 | K30: =I30+J30 -> 719400
B31: 事務処理費／事務関係費 | C31: =SGA!D35 -> 2269239 | D31: 0 | E31: =C31+D31 -> 2269239 | F31: =SGA!E35 -> 2256449 | G31: 0 | H31: =F31+G31 -> 2256449 | I31: =SGA!F35 -> 4667404 | J31: 0 | K31: =I31+J31 -> 4667404
B32: 事務処理費／通信費 | C32: =SGA!D36 -> 1250200 | D32: 0 | E32: =C32+D32 -> 1250200 | F32: =SGA!E36 -> 1097345 | G32: 0 | H32: =F32+G32 -> 1097345 | I32: =SGA!F36 -> 1272153 | J32: 0 | K32: =I32+J32 -> 1272153
B33: 事務処理費／新聞図書費 | C33: =SGA!D37 -> 0 | D33: 0 | E33: =C33+D33 -> 0 | F33: =SGA!E37 -> 0 | G33: 0 | H33: =F33+G33 -> 0 | I33: =SGA!F37 -> 0 | J33: 0 | K33: =I33+J33 -> 0
B34: 事務処理費／旅費交通費 | C34: =SGA!D38 -> 498435 | D34: 0 | E34: =C34+D34 -> 498435 | F34: =SGA!E38 -> 233772 | G34: 0 | H34: =F34+G34 -> 233772 | I34: =SGA!F38 -> 354877 | J34: 0 | K34: =I34+J34 -> 354877
B35: 事務処理費／会議研修費 | C35: =SGA!D39 -> 0 | D35: 0 | E35: =C35+D35 -> 0 | F35: =SGA!E39 -> 0 | G35: 0 | H35: =F35+G35 -> 0 | I35: =SGA!F39 -> 0 | J35: 0 | K35: =I35+J35 -> 0
B36: 事務処理費／組合費 | C36: =SGA!D40 -> 58000 | D36: 0 | E36: =C36+D36 -> 58000 | F36: =SGA!E40 -> 58000 | G36: 0 | H36: =F36+G36 -> 58000 | I36: =SGA!F40 -> 70000 | J36: 0 | K36: =I36+J36 -> 70000
B37: 事務処理費／雑費 | C37: =SGA!D41 -> 1283598 | D37: 0 | E37: =C37+D37 -> 1283598 | F37: =SGA!E41 -> 1301304 | G37: 0 | H37: =F37+G37 -> 1301304 | I37: =SGA!F41 -> 456209 | J37: 0 | K37: =I37+J37 -> 456209
B38: その他／税金公課 | C38: =SGA!D43 -> 2170008 | D38: 0 | E38: =C38+D38 -> 2170008 | F38: =SGA!E43 -> 1870926 | G38: 0 | H38: =F38+G38 -> 1870926 | I38: =SGA!F43 -> 1714061 | J38: 0 | K38: =I38+J38 -> 1714061
B39: その他／減価償却費 | C39: =SGA!D44 -> 2998583 | D39: 0 | E39: =C39+D39 -> 2998583 | F39: =SGA!E44 -> 2524579 | G39: 0 | H39: =F39+G39 -> 2524579 | I39: =SGA!F44 -> 2515156 | J39: 0 | K39: =I39+J39 -> 2515156
B40: 合計 | C40: =SUM(C6:C39) -> 71242323 | D40: =SUM(D6:D39) -> -307000 | E40: =SUM(E6:E39) -> 70935323 | F40: =SUM(F6:F39) -> 68569660 | G40: =SUM(G6:G39) -> 0 | H40: =SUM(H6:H39) -> 68569660 | I40: =SUM(I6:I39) -> 79583931 | J40: =SUM(J6:J39) -> 0 | K40: =SUM(K6:K39) -> 79583931
B41: 検算（帳簿価額合計＝原本シート） | C41: =EXACT(C40,SGA!D45) -> TRUE | F41: =EXACT(F40,SGA!E45) -> TRUE | I41: =EXACT(I40,SGA!F45) -> TRUE

Sheet 修正CR
B2: 製造原価の修正 単位：千円
B4: 科目 | C4: 2024年3月期 | F4: 2025年3月期 | I4: 2026年3月期 | L4: 修正理由
C5: 帳簿価額 | D5: 修正額 | E5: 修正後 | F5: 帳簿価額 | G5: 修正額 | H5: 修正後 | I5: 帳簿価額 | J5: 修正額 | K5: 修正後
B6: 原材料費／原材料期首棚卸高 | C6: =CR!D6 -> 11853408 | D6: 0 | E6: =C6+D6 -> 11853408 | F6: =CR!E6 -> 14319679 | G6: 0 | H6: =F6+G6 -> 14319679 | I6: =CR!F6 -> 22007284 | J6: 0 | K6: =I6+J6 -> 22007284
B7: 原材料費／原材料仕入高 | C7: =CR!D7 -> 83256510 | D7: 0 | E7: =C7+D7 -> 83256510 | F7: =CR!E7 -> 79983753 | G7: 0 | H7: =F7+G7 -> 79983753 | I7: =CR!F7 -> 77112507 | J7: 0 | K7: =I7+J7 -> 77112507
B8: 原材料費／原材料期末棚卸高 | C8: =CR!D8 -> 14319679 | D8: 0 | E8: =C8+D8 -> 14319679 | F8: =CR!E8 -> 22007284 | G8: 0 | H8: =F8+G8 -> 22007284 | I8: =CR!F8 -> 12953022 | J8: 0 | K8: =I8+J8 -> 12953022
B9: 労務費／給与 | C9: =CR!D10 -> 75755387 | D9: 0 | E9: =C9+D9 -> 75755387 | F9: =CR!E10 -> 63545229 | G9: 0 | H9: =F9+G9 -> 63545229 | I9: =CR!F10 -> 69596465 | J9: 0 | K9: =I9+J9 -> 69596465
B10: 労務費／賞与 | C10: =CR!D11 -> 5940000 | D10: 0 | E10: =C10+D10 -> 5940000 | F10: =CR!E11 -> 4920000 | G10: 0 | H10: =F10+G10 -> 4920000 | I10: =CR!F11 -> 8563512 | J10: 0 | K10: =I10+J10 -> 8563512
B11: 労務費／退職給与 | C11: =CR!D12 -> 0 | D11: =-C11 -> 0 | E11: =C11+D11 -> 0 | F11: =CR!E12 -> 0 | G11: =-F11 -> 0 | H11: =F11+G11 -> 0 | I11: =CR!F12 -> 6177985 | J11: =-I11 -> -6177985 | K11: =I11+J11 -> 0 | L11: 臨時的な退職金支出として控除（要確認）
B12: 労務費／法定福利費 | C12: =CR!D13 -> 12199418 | D12: 0 | E12: =C12+D12 -> 12199418 | F12: =CR!E13 -> 12503714 | G12: 0 | H12: =F12+G12 -> 12503714 | I12: =CR!F13 -> 12962279 | J12: 0 | K12: =I12+J12 -> 12962279
B13: 労務費／厚生福利費 | C13: =CR!D14 -> 1788084 | D13: 0 | E13: =C13+D13 -> 1788084 | F13: =CR!E14 -> 2220489 | G13: 0 | H13: =F13+G13 -> 2220489 | I13: =CR!F14 -> 1376127 | J13: 0 | K13: =I13+J13 -> 1376127
B14: 労務費／通勤費 | C14: =CR!D15 -> 1032904 | D14: 0 | E14: =C14+D14 -> 1032904 | F14: =CR!E15 -> 1157687 | G14: 0 | H14: =F14+G14 -> 1157687 | I14: =CR!F15 -> 1276339 | J14: 0 | K14: =I14+J14 -> 1276339
B15: 製造経費／設備保守料 | C15: =CR!D17 -> 1779600 | D15: 0 | E15: =C15+D15 -> 1779600 | F15: =CR!E17 -> 1717600 | G15: 0 | H15: =F15+G15 -> 1717600 | I15: =CR!F17 -> 1768400 | J15: 0 | K15: =I15+J15 -> 1768400
B16: 製造経費／損害保険料 | C16: =CR!D18 -> 912237 | D16: 0 | E16: =C16+D16 -> 912237 | F16: =CR!E18 -> 940667 | G16: 0 | H16: =F16+G16 -> 940667 | I16: =CR!F18 -> 1191590 | J16: 0 | K16: =I16+J16 -> 1191590
B17: 製造経費／備品費 | C17: =CR!D19 -> 302800 | D17: 0 | E17: =C17+D17 -> 302800 | F17: =CR!E19 -> 2764152 | G17: 0 | H17: =F17+G17 -> 2764152 | I17: =CR!F19 -> 2568782 | J17: 0 | K17: =I17+J17 -> 2568782
B18: 製造経費／地代家賃 | C18: =CR!D20 -> 0 | D18: 0 | E18: =C18+D18 -> 0 | F18: =CR!E20 -> 0 | G18: 0 | H18: =F18+G18 -> 0 | I18: =CR!F20 -> 0 | J18: 0 | K18: =I18+J18 -> 0
B19: 製造経費／借上料 | C19: =CR!D21 -> 5010000 | D19: 0 | E19: =C19+D19 -> 5010000 | F19: =CR!E21 -> 5010000 | G19: 0 | H19: =F19+G19 -> 5010000 | I19: =CR!F21 -> 5046600 | J19: 0 | K19: =I19+J19 -> 5046600
B20: 製造経費／修繕費 | C20: =CR!D22 -> 4172889 | D20: 0 | E20: =C20+D20 -> 4172889 | F20: =CR!E22 -> 6553786 | G20: 0 | H20: =F20+G20 -> 6553786 | I20: =CR!F22 -> 7541725 | J20: 0 | K20: =I20+J20 -> 7541725
B21: 製造経費／光熱費 | C21: =CR!D23 -> 1372 | D21: 0 | E21: =C21+D21 -> 1372 | F21: =CR!E23 -> 1233 | G21: 0 | H21: =F21+G21 -> 1233 | I21: =CR!F23 -> 1530 | J21: 0 | K21: =I21+J21 -> 1530
B22: 製造経費／動力費 | C22: =CR!D24 -> 32385919 | D22: 0 | E22: =C22+D22 -> 32385919 | F22: =CR!E24 -> 33957442 | G22: 0 | H22: =F22+G22 -> 33957442 | I22: =CR!F24 -> 33684675 | J22: 0 | K22: =I22+J22 -> 33684675
B23: 製造経費／薬品諸油費 | C23: =CR!D25 -> 3426660 | D23: 0 | E23: =C23+D23 -> 3426660 | F23: =CR!E25 -> 3972450 | G23: 0 | H23: =F23+G23 -> 3972450 | I23: =CR!F25 -> 3512750 | J23: 0 | K23: =I23+J23 -> 3512750
B24: 製造経費／消耗品費 | C24: =CR!D26 -> 597514 | D24: 0 | E24: =C24+D24 -> 597514 | F24: =CR!E26 -> 745684 | G24: 0 | H24: =F24+G24 -> 745684 | I24: =CR!F26 -> 1236794 | J24: 0 | K24: =I24+J24 -> 1236794
B25: 製造経費／衛生費 | C25: =CR!D27 -> 1311634 | D25: 0 | E25: =C25+D25 -> 1311634 | F25: =CR!E27 -> 1299930 | G25: 0 | H25: =F25+G25 -> 1299930 | I25: =CR!F27 -> 1077282 | J25: 0 | K25: =I25+J25 -> 1077282
B26: 製造経費／原水処理費 | C26: =CR!D28 -> 0 | D26: 0 | E26: =C26+D26 -> 0 | F26: =CR!E28 -> 0 | G26: 0 | H26: =F26+G26 -> 0 | I26: =CR!F28 -> 0 | J26: 0 | K26: =I26+J26 -> 0
... B37: 製造経費／減価償却費 | C37: =CR!D39 -> 8323500 | D37: 0 | E37: =C37+D37 -> 8323500 | F37: =CR!E39 -> 17893259 | G37: 0 | H37: =F37+G37 -> 17893259 | I37: =CR!F39 -> 19820169 | J37: 0 | K37: =I37+J37 -> 19820169
B38: 外注加工費／外注作業費 | C38: =CR!D41 -> 5680739 | D38: 0 | E38: =C38+D38 -> 5680739 | F38: =CR!E41 -> 13626626 | G38: 0 | H38: =F38+G38 -> 13626626 | I38: =CR!F41 -> 11434787 | J38: 0 | K38: =I38+J38 -> 11434787
B39: 製造勘定／期首仕掛品 | C39: =CR!D43 -> 698852 | D39: 0 | E39: =C39+D39 -> 698852 | F39: =CR!E43 -> 729036 | G39: 0 | H39: =F39+G39 -> 729036 | I39: =CR!F43 -> 757988 | J39: 0 | K39: =I39+J39 -> 757988
B40: 製造勘定／期末仕掛品 | C40: =CR!D44 -> 729036 | D40: 0 | E40: =C40+D40 -> 729036 | F40: =CR!E44 -> 757988 | G40: 0 | H40: =F40+G40 -> 757988 | I40: =CR!F44 -> 877184 | J40: 0 | K40: =I40+J40 -> 877184
B41: 製造原価合計 | C41: =C6+C7-C8+C9+C10+C11+C12+C13+C14+C15+C16+C17+C18+C19+C20+C21+C22+C23+C24+C25+C26+C27+C28+C29+C30+C31+C32+C33+C34+C35+C36+C37+C38+C39-C40 -> 248316505 | D41: =D6+D7-D8+D9+D10+D11+D12+D13+D14+D15+D16+D17+D18+D19+D20+D21+D22+D23+D24+D25+D26+D27+D28+D29+D30+D31+D32+D33+D34+D35+D36+D37+D38+D39-D40 -> 0 | E41: =E6+E7-E8+E9+E10+E11+E12+E13+E14+E15+E16+E17+E18+E19+E20+E21+E22+E23+E24+E25+E26+E27+E28+E29+E30+E31+E32+E33+E34+E35+E36+E37+E38+E39-E40 -> 248316505 | F41: =F6+F7-F8+F9+F10+F11+F12+F13+F14+F15+F16+F17+F18+F19+F20+F21+F22+F23+F24+F25+F26+F27+F28+F29+F30+F31+F32+F33+F34+F35+F36+F37+F38+F39-F40 -> 252834549 | G41: =G6+G7-G8+G9+G10+G11+G12+G13+G14+G15+G16+G17+G18+G19+G20+G21+G22+G23+G24+G25+G26+G27+G28+G29+G30+G31+G32+G33+G34+G35+G36+G37+G38+G39-G40 -> 0 | H41: =H6+H7-H8+H9+H10+H11+H12+H13+H14+H15+H16+H17+H18+H19+H20+H21+H22+H23+H24+H25+H26+H27+H28+H29+H30+H31+H32+H33+H34+H35+H36+H37+H38+H39-H40 -> 252834549 | I41: =I6+I7-I8+I9+I10+I11+I12+I13+I14+I15+I16+I17+I18+I19+I20+I21+I22+I23+I24+I25+I26+I27+I28+I29+I30+I31+I32+I33+I34+I35+I36+I37+I38+I39-I40 -> 281979626 | J41: =J6+J7-J8+J9+J10+J11+J12+J13+J14+J15+J16+J17+J18+J19+J20+J21+J22+J23+J24+J25+J26+J27+J28+J29+J30+J31+J32+J33+J34+J35+J36+J37+J38+J39-J40 -> -6177985 | K41: =K6+K7-K8+K9+K10+K11+K12+K13+K14+K15+K16+K17+K18+K19+K20+K21+K22+K23+K24+K25+K26+K27+K28+K29+K30+K31+K32+K33+K34+K35+K36+K37+K38+K39-K40 -> 275801641
B42: 検算（帳簿価額合計＝原本シート） | C42: =EXACT(C41,CR!D45) -> TRUE | F42: =EXACT(F41,CR!E45) -> TRUE | I42: =EXACT(I41,CR!F45) -> TRUE

Sheet 年買法
B2: 年買法（時価純資産＋営業権） 単位：千円
B4: 項目 | C4: 2024年3月期 | D4: 2025年3月期 | E4: 2026年3月期 | F4: 合計／備考
B5: 修正後営業利益 | C5: =修正PL!E10 -> 25632019 | D5: =修正PL!H10 -> 13658874 | E5: =修正PL!K10 -> 14203378
B6: 税考慮額（△34%） | C6: =-ROUND(MAX(C5,0)*0.34,0) -> -8714886 | D6: =-ROUND(MAX(D5,0)*0.34,0) -> -4644017 | E6: =-ROUND(MAX(E5,0)*0.34,0) -> -4829149
B7: 税考慮後営業利益 | C7: =C5+C6 -> 16917133 | D7: =D5+D6 -> 9014857 | E7: =E5+E6 -> 9374229
B8: 加重 | C8: 0.2 | D8: 0.3 | E8: 0.5
B9: 加重後 | C9: =ROUND(C7*C8,0) -> 3383427 | D9: =ROUND(D7*D8,0) -> 2704457 | E9: =ROUND(E7*E8,0) -> 4687115
B10: 基準営業利益（加重平均） | F10: =SUM(C9:E9) -> 10774999 | G10: 加重平均は加重後の行（9行）のみを合計（修正額行を含めない）
C12: 下限（1年） | D12: 中央（2年） | E12: 上限（3年）
B13: 営業権倍率（年） | C13: 1 | D13: 2 | E13: 3
B14: 営業権 | C14: =ROUND($F$10*C13,0) -> 10774999 | D14: =ROUND($F$10*D13,0) -> 21549998 | E14: =ROUND($F$10*E13,0) -> 32324997
B15: 時価純資産 | C15: ='修正BS(貸方) '!E14 -> -81442234 | D15: ='修正BS(貸方) '!E14 -> -81442234 | E15: ='修正BS(貸方) '!E14 -> -81442234
B16: 想定株式価値（時価純資産＋営業権） | C16: =C14+C15 -> -70667235 | D16: =D14+D15 -> -59892236 | E16: =E14+E15 -> -49117237
B17: 株式価値（マイナスは0円表示） | C17: =MAX(C16,0) -> 0 | D17: =MAX(D16,0) -> 0 | E17: =MAX(E16,0) -> 0
B19: ※営業権倍率1〜3年は国内中小企業M&Aのボリュームゾーン。加重は直近期50%・前期30%・前々期20%。税考慮は営業利益がマイナスの期は0。
B21: （感応度）建物を簿価で評価した場合の時価純資産 | C21: =C15-土地!J6 -> 86577801 | D21: =D15-土地!J6 -> 86577801 | E21: =E15-土地!J6 -> 86577801
B22: （感応度）同 想定株式価値 | C22: =C14+C21 -> 97352800 | D22: =D14+D21 -> 108127799 | E22: =E14+E21 -> 118902798
B23: ※建物の評価方法（固定資産税評価額／簿価）が結論を左右するため感応度を併記。簿価は会計上の償却停止により過大であり、本評価の基本ケースは固定資産税評価額。

Sheet EV EBITDAマルチプル
B2: EV/EBITDAマルチプル法 単位：千円
B4: 項目 | C4: 2024年3月期 | D4: 2025年3月期 | E4: 2026年3月期 | F4: 合計／備考
B5: 修正後EBITDA | C5: =修正PL!E12 -> 36954102 | D5: =修正PL!H12 -> 34076712 | E5: =修正PL!K12 -> 36538703
B6: 加重 | C6: 0.2 | D6: 0.3 | E6: 0.5
B7: 加重後 | C7: =ROUND(C5*C6,0) -> 7390820 | D7: =ROUND(D5*D6,0) -> 10223014 | E7: =ROUND(E5*E6,0) -> 18269352
B8: 基準EBITDA（加重平均） | F8: =SUM(C7:E7) -> 35883186
B9: （参考）修正後EBITDA 3期単純平均 | F9: =ROUND(AVERAGE(C5:E5),0) -> 35856506
C11: 下限（3倍） | D11: 中央（4倍） | E11: 上限（5倍）
B12: EV/EBITDA倍率 | C12: 3 | D12: 4 | E12: 5
B13: 事業価値（EV） | C13: =ROUND($F$8*C12,0) -> 107649558 | D13: =ROUND($F$8*D12,0) -> 143532744 | E13: =ROUND($F$8*E12,0) -> 179415930
B14: 非流動性ディスカウント（△30%） | C14: =-ROUND(C13*0.3,0) -> -32294867 | D14: =-ROUND(D13*0.3,0) -> -43059823 | E14: =-ROUND(E13*0.3,0) -> -53824779
B15: ディスカウント後事業価値 | C15: =C13+C14 -> 75354691 | D15: =D13+D14 -> 100472921 | E15: =E13+E14 -> 125591151
B16: ネットキャッシュ（△はネットデット） | C16: =ネットキャッシュ!C12 -> -385549150 | D16: =ネットキャッシュ!C12 -> -385549150 | E16: =ネットキャッシュ!C12 -> -385549150
B17: 想定株式価値 | C17: =C15+C16 -> -310194459 | D17: =D15+D16 -> -285076229 | E17: =E15+E16 -> -259957999
B18: 株式価値（マイナスは0円表示） | C18: =MAX(C17,0) -> 0 | D18: =MAX(D17,0) -> 0 | E18: =MAX(E17,0) -> 0
B20: （参考）資本性ローンを資本とみなした場合の株式価値 | C20: =C15+ネットキャッシュ!C14 -> -204774459 | D20: =D15+ネットキャッシュ!C14 -> -179656229 | E20: =E15+ネットキャッシュ!C14 -> -154537999
B22: ※非流動性ディスカウント：上場会社の株価倍率には市場性（流動性）が織込まれているため、非上場株式への適用にあたり控除。コストアプローチには適用しない。

Sheet 参照企業
B2: 類似上場会社（EV/EBITDA倍率の参照）
B4: コード | C4: 会社名 | D4: 事業 | E4: EV/EBITDA | F4: 備考
B5: 2874 | C5: (株)ヨコレイ | D5: 冷蔵倉庫・食品販売 | E5: 要更新 | F5: 算定日時点の株価・直近決算で更新する
B6: 2871 | C6: (株)ニチレイ | D6: 低温物流・加工食品 | E6: 要更新 | F6: 算定日時点の株価・直近決算で更新する
B7: 9369 | C7: (株)キユーソー流通システム | D7: 食品物流（低温） | E7: 要更新 | F7: 算定日時点の株価・直近決算で更新する
B8: 9351 | C8: 東洋埠頭(株) | D8: 冷蔵倉庫・港湾 | E8: 要更新 | F8: 算定日時点の株価・直近決算で更新する
B9: 2884 | C9: ヨシムラ・フード・HD | D9: 食品製造（中小企業M&A型） | E9: 要更新 | F9: 算定日時点の株価・直近決算で更新する
B11: ※製氷専業の上場会社は存在しないため、低温物流・食品製造を参照。倍率は算定日時点で更新する前提であり、本試算では中小企業M&Aの実務レンジ3〜5倍を採用。

Sheet IM→
B2: IM セクション

Sheet 案件サマリー
B2: 案件サマリー（概要書「基本情報」「財務ハイライト」の貼付元）
B4: 財務サマリー（千円） | C4: ='BS(借方)'!C4 -> 2023年3月期 | D4: ='BS(借方)'!D4 -> 2024年3月期 | E4: ='BS(借方)'!E4 -> 2025年3月期 | F4: ='BS(借方)'!F4 -> 2026年3月期 | H4: 会社概要
B5: 売上高 | C5: =PLハイライト!C5 -> 284840729 | D5: =PLハイライト!D5 -> 376221193 | E5: =PLハイライト!E5 -> 382684537 | F5: =PLハイライト!F5 -> 405963400 | H5: 会社名 | I5: =会社概要!C5 -> 越ヶ谷製氷冷蔵株式会社
B6: 売上総利益 | C6: =PLハイライト!C7 -> 46247759 | D6: =PLハイライト!D7 -> 96567342 | E6: =PLハイライト!E7 -> 85384403 | F6: =PLハイライト!F7 -> 89373985 | H6: 本店所在地 | I6: =会社概要!C7 -> 埼玉県越谷市蒲生寿町19番15号
B7: 営業利益 | C7: =PLハイライト!C9 -> -8247521 | D7: =PLハイライト!D9 -> 25325019 | E7: =PLハイライト!E9 -> 13658874 | F7: =PLハイライト!F9 -> 8025393 | H7: 工場・営業所 | I7: =会社概要!C8 -> 越谷工場：埼玉県越谷市大字平方999-4（平方工業団地内）／松戸営業所：千葉県松戸市稔台5-14-3
B8: 経常利益 | C8: =PLハイライト!C11 -> -13264723 | D8: =PLハイライト!D11 -> 22792179 | E8: =PLハイライト!E11 -> 6021177 | F8: =PLハイライト!F11 -> 1863864 | H8: 設立 | I8: =会社概要!C9 -> 1960年（昭和35年）3月18日
B9: 当期純利益 | C9: =PLハイライト!C13 -> -13624723 | D9: =PLハイライト!D13 -> 22432179 | E9: =PLハイライト!E13 -> 5661177 | F9: =PLハイライト!F13 -> 1376664 | H9: 資本金 | I9: =会社概要!C10 -> 10,000千円（2026年5月15日に11,000千円から減資）
B10: 減価償却費 | C10: =PLハイライト!C14 -> 19763 | D10: =PLハイライト!D14 -> 11322083 | E10: =PLハイライト!E14 -> 20417838 | F10: =PLハイライト!F14 -> 22335325 | H10: 代表者 | I10: =会社概要!C11 -> 代表取締役 小野田 洋
B11: 調整後EBITDA | C11: =PLハイライト!C19 -> -8227758 | D11: =PLハイライト!D19 -> 36954102 | E11: =PLハイライト!E19 -> 34076712 | F11: =PLハイライト!F19 -> 36538703 | H11: 株主 | I11: =会社概要!C12 -> 小野田 洋 100%（発行済株式数は登記22,000株／申告書220株で相違・要確認）
B12: 総資産 | C12: =BSハイライト!C16 -> 589957699 | D12: =BSハイライト!D16 -> 602857386 | E12: =BSハイライト!E16 -> 561711699 | F12: =BSハイライト!F16 -> 553204019 | H12: 従業員数 | I12: =会社概要!C14 -> 25名（常勤役員1名・従業員24名、2026年3月期末）
B13: 純資産 | C13: =BSハイライト!C21 -> 19818176 | D13: =BSハイライト!D21 -> 42250355 | E13: =BSハイライト!E21 -> 47911532 | F13: =BSハイライト!F21 -> 49288196 | H13: 事業内容 | I13: =会社概要!C15 -> 純氷（角氷・加工氷・袋氷・特殊氷）の製造及び卸小売販売、ドライアイス等の商品販売、冷蔵保管
B14: 借入金 | C14: =BSハイライト!C18 -> 530156000 | D14: =BSハイライト!D18 -> 512787000 | E14: =BSハイライト!E18 -> 478822000 | F14: =BSハイライト!F18 -> 461024000 | H14: 主要取引先 | I14: =会社概要!C16 -> (株)日本アクセス／(株)日本橋冷凍手島商店／三菱食品(株)／金木屋商事(株)／(株)クールテックサガワ 他
B15: 現預金 | C15: =BSハイライト!C5 -> 105962634 | D15: =BSハイライト!D5 -> 108835028 | E15: =BSハイライト!E5 -> 73061491 | F15: =BSハイライト!F5 -> 66599556 | H15: 主要設備 | I15: =会社概要!C17 -> 製氷設備4台（日産40トン）、袋詰砕氷設備1台（日産2,500ケース）、冷蔵設備3台（F級1,000トン）
B16: 調整後EBITDA 直近3期平均 | F16: =PLハイライト!F20 -> 35856506 | H16: 売上高 | I16: =会社概要!C19 -> 405,963千円（2026年3月期）
H17: 譲渡理由 | I17: =会社概要!C21 -> 後継者不在
H18: 譲渡スキーム | I18: =会社概要!C22 -> 株式100%譲渡

Sheet 会社概要
B2: 会社概要
B4: 項目 | C4: 内容 | D4: 出所
B5: 会社名 | C5: 越ヶ谷製氷冷蔵株式会社 | D5: 登記
B6: ブランド | C6: 純氷「キングアイス」 | D6: 公式サイト（king-ice.com）
B7: 本店所在地 | C7: 埼玉県越谷市蒲生寿町19番15号 | D7: 登記
B8: 工場・営業所 | C8: 越谷工場：埼玉県越谷市大字平方999-4（平方工業団地内）／松戸営業所：千葉県松戸市稔台5-14-3 | D8: 勘定科目内訳書
B9: 設立 | C9: 1960年（昭和35年）3月18日 | D9: 登記
B10: 資本金 | C10: 10,000千円（2026年5月15日に11,000千円から減資） | D10: 登記
B11: 代表者 | C11: 代表取締役 小野田 洋 | D11: 登記
B12: 株主 | C12: 小野田 洋 100%（発行済株式数は登記22,000株／申告書220株で相違・要確認） | D12: 登記・法人税申告書
B13: 役員 | C13: 取締役1名（代表取締役のみ）／取締役会・監査役 設置なし | D13: 登記
B14: 従業員数 | C14: 25名（常勤役員1名・従業員24名、2026年3月期末） | D14: 法人事業概況説明書
B15: 事業内容 | C15: 純氷（角氷・加工氷・袋氷・特殊氷）の製造及び卸小売販売、ドライアイス等の商品販売、冷蔵保管 | D15: 登記・概況説明書
... B18: 許認可 | C18: 営業許可（氷雪製造業）、食品営業許可（氷雪販売業） | D18: 受領資料
B19: 売上高 | C19: =TEXT(ROUND(PL!I5/1000,0),"#,##0")&"千円（2026年3月期）" -> 405,963千円（2026年3月期） | D19: マスターPL
B20: 取引金融機関 | C20: 日本政策金融公庫、栃木銀行、商工組合中央金庫、足利銀行、埼玉縣信用金庫、埼玉りそな銀行 | D20: 借入金内訳書
B21: 譲渡理由 | C21: 後継者不在 | D21: ヒアリング（受領資料）
B22: 譲渡スキーム | C22: 株式100%譲渡 | D22: 同上

Sheet PLハイライト
B2: PLハイライト 単位：千円
B4: 科目 | C4: ='BS(借方)'!C4 -> 2023年3月期 | D4: ='BS(借方)'!D4 -> 2024年3月期 | E4: ='BS(借方)'!E4 -> 2025年3月期 | F4: ='BS(借方)'!F4 -> 2026年3月期 | G4: 備考
B5: 売上高 | C5: =PL!C5 -> 284840729 | D5: =PL!E5 -> 376221193 | E5: =PL!G5 -> 382684537 | F5: =PL!I5 -> 405963400
B6: 前期比 | C6: =0 -> 0 | D6: =IFERROR(D5/C5,0) -> 1.3208125 | E6: =IFERROR(E5/D5,0) -> 1.0171796 | F6: =IFERROR(F5/E5,0) -> 1.0608304
B7: 売上総利益 | C7: =PL!C15 -> 46247759 | D7: =PL!E15 -> 96567342 | E7: =PL!G15 -> 85384403 | F7: =PL!I15 -> 89373985
B8: 売上総利益率 | C8: =IFERROR(C7/C5,0) -> 0.16236357 | D8: =IFERROR(D7/D5,0) -> 0.25667704 | E8: =IFERROR(E7/E5,0) -> 0.22311955 | F8: =IFERROR(F7/F5,0) -> 0.22015281
B9: 営業利益 | C9: =PL!C24 -> -8247521 | D9: =PL!E24 -> 25325019 | E9: =PL!G24 -> 13658874 | F9: =PL!I24 -> 8025393
B10: 営業利益率 | C10: =IFERROR(C9/C5,0) -> -0.028954851 | D10: =IFERROR(D9/D5,0) -> 0.067314174 | E10: =IFERROR(E9/E5,0) -> 0.035692255 | F10: =IFERROR(F9/F5,0) -> 0.01976876
B11: 経常利益 | C11: =PL!C34 -> -13264723 | D11: =PL!E34 -> 22792179 | E11: =PL!G34 -> 6021177 | F11: =PL!I34 -> 1863864
B12: 経常利益率 | C12: =IFERROR(C11/C5,0) -> -0.046568913 | D12: =IFERROR(D11/D5,0) -> 0.060581858 | E12: =IFERROR(E11/E5,0) -> 0.015734048 | F12: =IFERROR(F11/F5,0) -> 0.0045912119
B13: 当期純利益 | C13: =PL!C39 -> -13624723 | D13: =PL!E39 -> 22432179 | E13: =PL!G39 -> 5661177 | F13: =PL!I39 -> 1376664
B14: 減価償却費 | C14: =PL!C41 -> 19763 | D14: =PL!E41 -> 11322083 | E14: =PL!G41 -> 20417838 | F14: =PL!I41 -> 22335325
B15: EBITDA（営業利益＋減価償却費） | C15: =PL!C42 -> -8227758 | D15: =PL!E42 -> 36647102 | E15: =PL!G42 -> 34076712 | F15: =PL!I42 -> 30360718
B16: 【調整項目】
B17: 退職給与（臨時的支出） | C17: =0 -> 0 | D17: =修正PL!D15 -> 307000 | E17: =修正PL!G15 -> 0 | F17: =修正PL!J15 -> 6177985
B18: 役員報酬 | C18: =0 -> 0 | D18: =修正PL!D16 -> 0 | E18: =修正PL!G16 -> 0 | F18: =修正PL!J16 -> 0
B19: 調整後EBITDA | C19: =C15+C17+C18 -> -8227758 | D19: =D15+D17+D18 -> 36954102 | E19: =E15+E17+E18 -> 34076712 | F19: =F15+F17+F18 -> 36538703
B20: 調整後EBITDA 直近3期平均 | F20: =ROUND(AVERAGE(D19:F19),0) -> 35856506
B21: 調整後EBITDA 直近2期平均 | F21: =ROUND(AVERAGE(E19:F19),0) -> 35307708
B22: 検算（26/3期 調整後EBITDA＝修正PLの修正後EBITDA） | F22: =EXACT(F19,修正PL!K12) -> TRUE
B24: ※調整方針は評価書（修正PL）と同一。23/3期は評価の対象期間外のため調整なし。

Sheet BSハイライト
B2: BSハイライト 単位：千円
B4: 科目 | C4: ='BS(借方)'!C4 -> 2023年3月期 | D4: ='BS(借方)'!D4 -> 2024年3月期 | E4: ='BS(借方)'!E4 -> 2025年3月期 | F4: ='BS(借方)'!F4 -> 2026年3月期 | G4: 備考
B5: 現預金（保険積立除く） | C5: ='BS(借方)'!C6+'BS(借方)'!C7+'BS(借方)'!C8+'BS(借方)'!C9+'BS(借方)'!C10 -> 105962634 | D5: ='BS(借方)'!D6+'BS(借方)'!D7+'BS(借方)'!D8+'BS(借方)'!D9+'BS(借方)'!D10 -> 108835028 | E5: ='BS(借方)'!E6+'BS(借方)'!E7+'BS(借方)'!E8+'BS(借方)'!E9+'BS(借方)'!E10 -> 73061491 | F5: ='BS(借方)'!F6+'BS(借方)'!F7+'BS(借方)'!F8+'BS(借方)'!F9+'BS(借方)'!F10 -> 66599556
B6: 保険積立金 | C6: ='BS(借方)'!C11 -> 16994113 | D6: ='BS(借方)'!D11 -> 10536852 | E6: ='BS(借方)'!E11 -> 11600916 | F6: ='BS(借方)'!F11 -> 9362494
B7: 売掛金 | C7: ='BS(借方)'!C12 -> 21685368 | D7: ='BS(借方)'!D12 -> 29802902 | E7: ='BS(借方)'!E12 -> 28300741 | F7: ='BS(借方)'!F12 -> 28798405
B8: 棚卸資産 | C8: ='BS(借方)'!C15 -> 27194459 | D8: ='BS(借方)'!D15 -> 30950673 | E8: ='BS(借方)'!E15 -> 36589789 | F8: ='BS(借方)'!F15 -> 34490885
B9: その他流動資産 | C9: ='BS(借方)'!C20 -> 4369613 | D9: ='BS(借方)'!D20 -> 4806979 | E9: ='BS(借方)'!E20 -> 4572512 | F9: ='BS(借方)'!F20 -> 3063104
B10: 流動資産合計 | C10: ='BS(借方)'!C28 -> 176206187 | D10: ='BS(借方)'!D28 -> 184932434 | E10: ='BS(借方)'!E28 -> 154125449 | F10: ='BS(借方)'!F28 -> 142314444
B11: 建物・構築物 | C11: ='BS(借方)'!C30+'BS(借方)'!C31 -> 261357926 | D11: ='BS(借方)'!D30+'BS(借方)'!D31 -> 261357926 | E11: ='BS(借方)'!E30+'BS(借方)'!E31 -> 261357926 | F11: ='BS(借方)'!F30+'BS(借方)'!F31 -> 261357926
B12: 機械・車両・器具 | C12: ='BS(借方)'!C32+'BS(借方)'!C33+'BS(借方)'!C34 -> 108652367 | D12: ='BS(借方)'!D32+'BS(借方)'!D33+'BS(借方)'!D34 -> 114950807 | E12: ='BS(借方)'!E32+'BS(借方)'!E33+'BS(借方)'!E34 -> 104612105 | F12: ='BS(借方)'!F32+'BS(借方)'!F33+'BS(借方)'!F34 -> 107915430
B13: 土地 | C13: ='BS(借方)'!C35 -> 40441919 | D13: ='BS(借方)'!D35 -> 40441919 | E13: ='BS(借方)'!E35 -> 40441919 | F13: ='BS(借方)'!F35 -> 40441919
B14: 無形固定資産・投資等 | C14: ='BS(借方)'!C36+'BS(借方)'!C38 -> 3299300 | D14: ='BS(借方)'!D36+'BS(借方)'!D38 -> 1174300 | E14: ='BS(借方)'!E36+'BS(借方)'!E38 -> 1174300 | F14: ='BS(借方)'!F36+'BS(借方)'!F38 -> 1174300
B15: 固定資産合計 | C15: ='BS(借方)'!C41 -> 413751512 | D15: ='BS(借方)'!D41 -> 417924952 | E15: ='BS(借方)'!E41 -> 407586250 | F15: ='BS(借方)'!F41 -> 410889575
B16: 資産合計 | C16: ='BS(借方)'!C42 -> 589957699 | D16: ='BS(借方)'!D42 -> 602857386 | E16: ='BS(借方)'!E42 -> 561711699 | F16: ='BS(借方)'!F42 -> 553204019
B17: 支払手形・買掛金 | C17: ='BS (貸方)'!C6+'BS (貸方)'!C7 -> 25363350 | D17: ='BS (貸方)'!D6+'BS (貸方)'!D7 -> 26964523 | E17: ='BS (貸方)'!E6+'BS (貸方)'!E7 -> 21261348 | F17: ='BS (貸方)'!F6+'BS (貸方)'!F7 -> 24493672
B18: 借入金（短期・長期） | C18: ='BS (貸方)'!C24 -> 530156000 | D18: ='BS (貸方)'!D24 -> 512787000 | E18: ='BS (貸方)'!E24 -> 478822000 | F18: ='BS (貸方)'!F24 -> 461024000
