Workbook

Sheet ルール
B3: 1 | C3: 文字は「游ゴシック」、数字は「Arial」を基本。備考欄などの細かい文章は「游ゴシック Medium」。
B4: 2 | C4: タイトル、合計欄は太字
B5: 3 | C5: 数字は円単位で入力、表示は千円単位に設定済み
B6: 4 | C6: 基本の背景は以下の通り。紺、水色、グレー、白、青。パレットの上部の色。
C8: 線は紺か白か青。
C10: 資産の部
C11: 科目 | D11: ='BS(借方)'!F10 -> 0 | E11: 調整額 | F11: 調整後
C12: 【流動資産】 | D12: =SUM(D13:D26) -> 5000000 | E12: =SUM(E13:E26) -> -500000 | F12: =SUM(F13:F26) -> 4500000
C13: 現金及び預金 | D13: 5000000 | E13: -500000 | F13: =D13+E13 -> 4500000
F14: =D14+E14 -> 0

Sheet 財務入力→

Sheet BS(借方)
C1: ←基本的にはここをつかう→
C2: 1期目 | D2: 2期目 | E2: 3期目 | F2: （4期目） | G2: 進行期
B3: 資産の部
B4: 科目 | C4: － | D4: 23年11月期 | E4: 24年11月期 | F4: 25年11月期 | G4: 26年11月期 （7か月TB）
B5: 【流動資産】 | C5: =SUM(C6:C19) -> 0 | D5: =SUM(D6:D19) -> 116930952 | E5: =SUM(E6:E19) -> 188786028 | F5: =SUM(F6:F19) -> 150113194 | G5: =SUM(G6:G19) -> 92091317
B6: 現金及び預金 | D6: 13655404 | E6: 17627838 | F6: 10140492 | G6: 14792479
B7: 売掛金 | D7: 28157886 | E7: 39602581 | F7: 27628072 | G7: 16678270
B8: 商品 | D8: 70917819 | E8: 127080914 | F8: 106017284 | G8: 58445785
B9: 貯蔵品 | D9: 150000 | E9: 150000 | F9: 150000 | G9: 150000
B10: 前渡金 | D10: 1200000
B11: 前払費用 | D11: 2837243 | E11: 4237195 | F11: 3991637 | G11: 392743
B12: 未収入金 | E12: 87500 | F12: 30800
B13: 未収還付法人税等 | D13: 12600 | F13: 504909
B14: 仮払金 | F14: 1650000 | G14: 1677040
B15: 立替金 | G15: -45000
B20: 【固定資産】 | C20: =C21+C35+C46 -> 0 | D20: =D21+D35+D46 -> 68592308 | E20: =E21+E35+E46 -> 95384583 | F20: =F21+F35+F46 -> 85271983 | G20: =G21+G35+G46 -> 86018013
B21: ［有形固定資産］ | C21: =SUM(C22:C34) -> 0 | D21: =SUM(D22:D34) -> 42883311 | E21: =SUM(E22:E34) -> 63570009 | F21: =SUM(F22:F34) -> 54658019 | G21: =SUM(G22:G34) -> 57570649
B22: 建物 | D22: 25512741 | E22: 45557783 | F22: 44397084
B23: 建物付属設備 | G23: 44397084
B24: 構築物 | G24: 2475000
B25: 車両運搬具 | D25: 15882874 | E25: 10609341 | F25: 1057574 | G25: 1495204
B26: 工具器具及び備品 | D26: 1246562 | E26: 7402885 | F26: 6044761 | G26: 6044761
B27: 土地 | F27: 2974400 | G27: 2974400
B28: その他の有形固定資産 | D28: 241134 | F28: 184200 | G28: 184200
B35: ［無形固定資産］ | C35: =SUM(C36:C45) -> 0 | D35: =SUM(D36:D45) -> 0 | E35: =SUM(E36:E45) -> 0 | F35: =SUM(F36:F45) -> 0 | G35: =SUM(G36:G45) -> 0
B46: ［投資その他資産］ | C46: =SUM(C47:C55) -> 0 | D46: =SUM(D47:D55) -> 25708997 | E46: =SUM(E47:E55) -> 31814574 | F46: =SUM(F47:F55) -> 30613964 | G46: =SUM(G47:G55) -> 28447364
B47: リサイクル預託金 | D47: 58820 | E47: 58820 | F47: 31500 | G47: 31500
B48: 長期前払費用 | D48: 3335613 | E48: 2513170 | F48: 1711860 | G48: 1711860
B49: 差入保証金 | D49: 20641800 | E49: 27656200 | F49: 27370600 | G49: 25204000
B50: 営業権 | D50: 1672764 | E50: 1586384 | F50: 1500004 | G50: 1500004
B56: 【繰延資産】 | C56: =SUM(C57:C60) -> 0 | D56: =SUM(D57:D60) -> 0 | E56: =SUM(E57:E60) -> 0 | F56: =SUM(F57:F60) -> 0 | G56: =SUM(G57:G60) -> 0
B61: 資産合計 | C61: =C5+C20+C56 -> 0 | D61: =D5+D20+D56 -> 185523260 | E61: =E5+E20+E56 -> 284170611 | F61: =F5+F20+F56 -> 235385177 | G61: =G5+G20+G56 -> 178109330
B63: バランスチェック | C63: =EXACT(C61,'BS (貸方)'!C51) -> 1 | D63: =EXACT(D61,'BS (貸方)'!D51) -> 1 | E63: =EXACT(E61,'BS (貸方)'!E51) -> 1 | F63: =EXACT(F61,'BS (貸方)'!F51) -> 1 | G63: =EXACT(G61,'BS (貸方)'!G51) -> 1

Sheet BS (貸方)
E2: (単位：千円)
B3: 負債の部
B4: 科目 | C4: ='BS(借方)'!C4 -> － | D4: ='BS(借方)'!D4 -> 23年11月期 | E4: ='BS(借方)'!E4 -> 24年11月期 | F4: ='BS(借方)'!F4 -> 25年11月期 | G4: ='BS(借方)'!G4 -> 26年11月期 （7か月TB）
B5: 【流動負債】 | C5: =SUM(C6:C17) -> 0 | D5: =SUM(D6:D17) -> 30379997 | E5: =SUM(E6:E17) -> 47366299 | F5: =SUM(F6:F17) -> 47672202 | G5: =SUM(G6:G17) -> 33413938
B6: 買掛金 | D6: 10175789 | E6: 14254641 | F6: 9202412 | G6: 7003448
B7: 短期借入金 | G7: 3153
B8: 未払金 | F8: 714227
B9: 未払費用 | D9: 12571145 | E9: 24016295 | F9: 20113617 | G9: 9578501
B10: 未払法人税等 | D10: 229900 | E10: 961500 | F10: 242500
B11: 未払消費税等 | D11: 3644800 | E11: 3776100 | F11: 11784100 | G11: 7438091
B12: 預り金 | D12: 614470 | E12: 606685 | F12: 2391530 | G12: 1600194
B13: カード未払金 | D13: 3143893 | E13: 3751078 | F13: 3223816 | G13: 7790551
B18: 【固定負債】 | C18: =SUM(C19:C24) -> 0 | D18: =SUM(D19:D24) -> 149815893 | E18: =SUM(E19:E24) -> 230502580 | F18: =SUM(F19:F24) -> 201769790 | G18: =SUM(G19:G24) -> 196939108
B19: 長期借入金 | D19: 134042000 | E19: 218455000 | F19: 191858000 | G19: 191858000
B20: 役員借入金 | D20: 1121593 | F20: 7565770 | G20: 3402888
B21: 長期未払金 | D21: 14652300 | E21: 12047580 | F21: 2346020 | G21: 1678220
B25: 負債合計 | C25: =C5+C18 -> 0 | D25: =D5+D18 -> 180195890 | E25: =E5+E18 -> 277868879 | F25: =F5+F18 -> 249441992 | G25: =G5+G18 -> 230353046
B34: 純資産の部
B35: 【資本金】 | C35: =SUM(C36:C38) -> 0 | D35: =SUM(D36:D38) -> 1000000 | E35: =SUM(E36:E38) -> 1000000 | F35: =SUM(F36:F38) -> 1000000 | G35: =SUM(G36:G38) -> 1000000
B36: 資本金 | D36: 1000000 | E36: 1000000 | F36: 1000000 | G36: 1000000
B39: 【資本剰余金】 | C39: =SUM(C40:C42) -> 0 | D39: =SUM(D40:D42) -> 0 | E39: =SUM(E40:E42) -> 0 | F39: =SUM(F40:F42) -> 0 | G39: =SUM(G40:G42) -> 0
B43: 【利益剰余金】 | C43: =SUM(C44:C48) -> 0 | D43: =SUM(D44:D48) -> 4327370 | E43: =SUM(E44:E48) -> 5301732 | F43: =SUM(F44:F48) -> -15056815 | G43: =SUM(G44:G48) -> -53243716
B44: 繰越利益剰余金 | D44: 4327370 | E44: 5301732 | F44: -15056815 | G44: -53243716
B49: 【自己株式】 | C49: 0 | D49: 0 | E49: 0 | F49: 0 | G49: 0
B50: 純資産合計 | C50: =C35+C39+C43+C49 -> 0 | D50: =D35+D39+D43+D49 -> 5327370 | E50: =E35+E39+E43+E49 -> 6301732 | F50: =F35+F39+F43+F49 -> -14056815 | G50: =G35+G39+G43+G49 -> -52243716
B51: 負債・純資産合計 | C51: =C25+C50 -> 0 | D51: =D25+D50 -> 185523260 | E51: =E25+E50 -> 284170611 | F51: =F25+F50 -> 235385177 | G51: =G25+G50 -> 178109330
B53: バランスチェック | C53: =EXACT(C51,'BS(借方)'!C61) -> 1 | D53: =EXACT(D51,'BS(借方)'!D61) -> 1 | E53: =EXACT(E51,'BS(借方)'!E61) -> 1 | F53: =EXACT(F51,'BS(借方)'!F61) -> 1 | G53: =EXACT(G51,'BS(借方)'!G61) -> 1

Sheet PL
H2: (単位：千円)
B3: 科目 | C3: ='BS(借方)'!C4 -> － | E3: ='BS(借方)'!D4 -> 23年11月期 | G3: ='BS(借方)'!E4 -> 24年11月期 | I3: ='BS(借方)'!F4 -> 25年11月期 | K3: ='BS(借方)'!G4 -> 26年11月期 （7か月TB）
C4: 帳簿価額 | D4: 売上高比 | E4: 帳簿価額 | F4: 売上高比 | G4: 帳簿価額 | H4: 売上高比 | I4: 帳簿価額 | J4: 売上高比 | K4: 帳簿価額 | L4: 売上高比
B5: 生体売上高 | D5: =IFERROR(IF(C5=0,"",C5/C$11),"") | E5: 293213620 | F5: =IFERROR(IF(E5=0,"",E5/E$11),"") -> 0.61803566 | G5: 333089628 | H5: =IFERROR(IF(G5=0,"",G5/G$11),"") -> 0.6179369 | I5: 338295378 | J5: =IFERROR(IF(I5=0,"",I5/I$11),"") -> 0.60584097 | K5: 165116994 | L5: =IFERROR(IF(K5=0,"",K5/K$11),"") -> 0.59149188
B6: サービス売上高 | D6: =IFERROR(IF(C6=0,"",C6/C$11),"") | E6: 65655525 | F6: =IFERROR(IF(E6=0,"",E6/E$11),"") -> 0.13838871 | G6: 60897406 | H6: =IFERROR(IF(G6=0,"",G6/G$11),"") -> 0.11297486 | I6: 52699187 | J6: =IFERROR(IF(I6=0,"",I6/I$11),"") -> 0.09437707 | K6: 32791687 | L6: =IFERROR(IF(K6=0,"",K6/K$11),"") -> 0.11746832
B7: 物販売上高 | D7: =IFERROR(IF(C7=0,"",C7/C$11),"") | E7: 115559176 | F7: =IFERROR(IF(E7=0,"",E7/E$11),"") -> 0.24357563 | G7: 145047985 | H7: =IFERROR(IF(G7=0,"",G7/G$11),"") -> 0.26908824 | I7: 167395169 | J7: =IFERROR(IF(I7=0,"",I7/I$11),"") -> 0.29978196 | K7: 81244762 | L7: =IFERROR(IF(K7=0,"",K7/K$11),"") -> 0.2910398
D8: =IFERROR(IF(C8=0,"",C8/C$11),"") | F8: =IFERROR(IF(E8=0,"",E8/E$11),"") | H8: =IFERROR(IF(G8=0,"",G8/G$11),"") | J8: =IFERROR(IF(I8=0,"",I8/I$11),"") | L8: =IFERROR(IF(K8=0,"",K8/K$11),"")
D9: =IFERROR(IF(C9=0,"",C9/C$11),"") | F9: =IFERROR(IF(E9=0,"",E9/E$11),"") | H9: =IFERROR(IF(G9=0,"",G9/G$11),"") | J9: =IFERROR(IF(I9=0,"",I9/I$11),"") | L9: =IFERROR(IF(K9=0,"",K9/K$11),"")
D10: =IFERROR(IF(C10=0,"",C10/C$11),"") | F10: =IFERROR(IF(E10=0,"",E10/E$11),"") | H10: =IFERROR(IF(G10=0,"",G10/G$11),"") | J10: =IFERROR(IF(I10=0,"",I10/I$11),"") | L10: =IFERROR(IF(K10=0,"",K10/K$11),"")
B11: 売上高 | C11: =SUM(C5:C10) -> 0 | D11: =IFERROR(IF(C11=0,"",C11/C$11),"") | E11: =SUM(E5:E10) -> 474428321 | F11: =IFERROR(IF(E11=0,"",E11/E$11),"") -> 1 | G11: =SUM(G5:G10) -> 539035019 | H11: =IFERROR(IF(G11=0,"",G11/G$11),"") -> 1 | I11: =SUM(I5:I10) -> 558389734 | J11: =IFERROR(IF(I11=0,"",I11/I$11),"") -> 1 | K11: =SUM(K5:K10) -> 279153443 | L11: =IFERROR(IF(K11=0,"",K11/K$11),"") -> 1
B12: 期首棚卸高 | D12: =IFERROR(IF(C12=0,"",C12/C$11),"") | E12: 39485899 | F12: =IFERROR(IF(E12=0,"",E12/E$11),"") -> 0.083228377 | G12: 70917819 | H12: =IFERROR(IF(G12=0,"",G12/G$11),"") -> 0.1315644 | I12: 127080914 | J12: =IFERROR(IF(I12=0,"",I12/I$11),"") -> 0.22758462 | K12: 106017284 | L12: =IFERROR(IF(K12=0,"",K12/K$11),"") -> 0.37978139
B13: 商品仕入高 | D13: =IFERROR(IF(C13=0,"",C13/C$11),"") | E13: 183853875 | F13: =IFERROR(IF(E13=0,"",E13/E$11),"") -> 0.38752719 | G13: 220800993 | H13: =IFERROR(IF(G13=0,"",G13/G$11),"") -> 0.40962272 | I13: 182243467 | J13: =IFERROR(IF(I13=0,"",I13/I$11),"") -> 0.32637324 | K13: 92273907 | L13: =IFERROR(IF(K13=0,"",K13/K$11),"") -> 0.33054906
B14: 外注費 | D14: =IFERROR(IF(C14=0,"",C14/C$11),"") | E14: 29627732 | F14: =IFERROR(IF(E14=0,"",E14/E$11),"") -> 0.062449333 | G14: 31465971 | H14: =IFERROR(IF(G14=0,"",G14/G$11),"") -> 0.058374632 | I14: 25058151 | J14: =IFERROR(IF(I14=0,"",I14/I$11),"") -> 0.044875737 | K14: 8916840 | L14: =IFERROR(IF(K14=0,"",K14/K$11),"") -> 0.031942432
B15: 他勘定振替高 | D15: =IFERROR(IF(C15=0,"",C15/C$11),"") | F15: =IFERROR(IF(E15=0,"",E15/E$11),"") | H15: =IFERROR(IF(G15=0,"",G15/G$11),"") | J15: =IFERROR(IF(I15=0,"",I15/I$11),"") | K15: -44000000 | L15: =IFERROR(IF(K15=0,"",K15/K$11),"") -> -0.15761941
B16: 期末棚卸高 | D16: =IFERROR(IF(C16=0,"",C16/C$11),"") | E16: -70917819 | F16: =IFERROR(IF(E16=0,"",E16/E$11),"") -> -0.14948058 | G16: -127080914 | H16: =IFERROR(IF(G16=0,"",G16/G$11),"") -> -0.23575632 | I16: -106017284 | J16: =IFERROR(IF(I16=0,"",I16/I$11),"") -> -0.18986252 | K16: -58445785 | L16: =IFERROR(IF(K16=0,"",K16/K$11),"") -> -0.20936795
B17: 売上原価 | C17: =SUM(C12:C16) -> 0 | D17: =IFERROR(IF(C17=0,"",C17/C$11),"") | E17: =SUM(E12:E16) -> 182049687 | F17: =IFERROR(IF(E17=0,"",E17/E$11),"") -> 0.38372432 | G17: =SUM(G12:G16) -> 196103869 | H17: =IFERROR(IF(G17=0,"",G17/G$11),"") -> 0.36380543 | I17: =SUM(I12:I16) -> 228365248 | J17: =IFERROR(IF(I17=0,"",I17/I$11),"") -> 0.40897107 | K17: =SUM(K12:K16) -> 104762246 | L17: =IFERROR(IF(K17=0,"",K17/K$11),"") -> 0.37528552
B18: 売上総利益 | C18: =C11-C17 -> 0 | D18: =IFERROR(IF(C18=0,"",C18/C$11),"") | E18: =E11-E17 -> 292378634 | F18: =IFERROR(IF(E18=0,"",E18/E$11),"") -> 0.61627568 | G18: =G11-G17 -> 342931150 | H18: =IFERROR(IF(G18=0,"",G18/G$11),"") -> 0.63619457 | I18: =I11-I17 -> 330024486 | J18: =IFERROR(IF(I18=0,"",I18/I$11),"") -> 0.59102893 | K18: =K11-K17 -> 174391197 | L18: =IFERROR(IF(K18=0,"",K18/K$11),"") -> 0.62471448
B19: 販売費及び一般管理費 | C19: =SGA!C40 -> 0 | D19: =IFERROR(IF(C19=0,"",C19/C$11),"") | E19: =SGA!E40 -> 290037494 | F19: =IFERROR(IF(E19=0,"",E19/E$11),"") -> 0.61134102 | G19: =SGA!G40 -> 339909050 | H19: =IFERROR(IF(G19=0,"",G19/G$11),"") -> 0.63058807 | I19: =SGA!I40 -> 349576223 | J19: =IFERROR(IF(I19=0,"",I19/I$11),"") -> 0.62604343 | K19: =SGA!K40 -> 167754348 | L19: =IFERROR(IF(K19=0,"",K19/K$11),"") -> 0.60093956
B20: 営業利益 | C20: =C18- C19 -> 0 | D20: =IFERROR(IF(C20=0,"",C20/C$11),"") | E20: =E18- E19 -> 2341140 | F20: =IFERROR(IF(E20=0,"",E20/E$11),"") -> 0.0049346548 | G20: =G18- G19 -> 3022100 | H20: =IFERROR(IF(G20=0,"",G20/G$11),"") -> 0.0056065003 | I20: =I18- I19 -> -19551737 | J20: =IFERROR(IF(I20=0,"",I20/I$11),"") -> -0.035014499 | K20: =K18- K19 -> 6636849 | L20: =IFERROR(IF(K20=0,"",K20/K$11),"") -> 0.023774914
B21: 営業外収益 | C21: =SUM(C22:C28) -> 0 | D21: =IFERROR(IF(C21=0,"",C21/C$11),"") | E21: =SUM(E22:E28) -> 1321452 | F21: =IFERROR(IF(E21=0,"",E21/E$11),"") -> 0.0027853565 | G21: =SUM(G22:G28) -> 2383452 | H21: =IFERROR(IF(G21=0,"",G21/G$11),"") -> 0.0044217016 | I21: =SUM(I22:I28) -> 3631958 | J21: =IFERROR(IF(I21=0,"",I21/I$11),"") -> 0.0065043424 | K21: =SUM(K22:K28) -> 1059276 | L21: =IFERROR(IF(K21=0,"",K21/K$11),"") -> 0.0037946012
B22: 受取利息 | D22: =IFERROR(IF(C22=0,"",C22/C$11),"") | E22: 193 | F22: =IFERROR(IF(E22=0,"",E22/E$11),"") -> 4.0680539e-07 | G22: 4702 | H22: =IFERROR(IF(G22=0,"",G22/G$11),"") -> 8.7229954e-06 | I22: 24608 | J22: =IFERROR(IF(I22=0,"",I22/I$11),"") -> 4.4069578e-05 | K22: 6446 | L22: =IFERROR(IF(K22=0,"",K22/K$11),"") -> 2.3091243e-05
B23: 受取配当金 | D23: =IFERROR(IF(C23=0,"",C23/C$11),"") | E23: 188 | F23: =IFERROR(IF(E23=0,"",E23/E$11),"") -> 3.9626639e-07 | G23: 376 | H23: =IFERROR(IF(G23=0,"",G23/G$11),"") -> 6.9754281e-07 | I23: 282 | J23: =IFERROR(IF(I23=0,"",I23/I$11),"") -> 5.0502361e-07 | K23: 300 | L23: =IFERROR(IF(K23=0,"",K23/K$11),"") -> 1.0746778e-06
B24: 雑収入 | D24: =IFERROR(IF(C24=0,"",C24/C$11),"") | E24: 1321071 | F24: =IFERROR(IF(E24=0,"",E24/E$11),"") -> 0.0027845534 | G24: 2378374 | H24: =IFERROR(IF(G24=0,"",G24/G$11),"") -> 0.0044122811 | I24: 3607068 | J24: =IFERROR(IF(I24=0,"",I24/I$11),"") -> 0.0064597678 | K24: 1052530 | L24: =IFERROR(IF(K24=0,"",K24/K$11),"") -> 0.0037704353
D25: =IFERROR(IF(C25=0,"",C25/C$11),"") | F25: =IFERROR(IF(E25=0,"",E25/E$11),"") | H25: =IFERROR(IF(G25=0,"",G25/G$11),"") | J25: =IFERROR(IF(I25=0,"",I25/I$11),"") | L25: =IFERROR(IF(K25=0,"",K25/K$11),"")
D26: =IFERROR(IF(C26=0,"",C26/C$11),"") | F26: =IFERROR(IF(E26=0,"",E26/E$11),"") | H26: =IFERROR(IF(G26=0,"",G26/G$11),"") | J26: =IFERROR(IF(I26=0,"",I26/I$11),"") | L26: =IFERROR(IF(K26=0,"",K26/K$11),"")
D27: =IFERROR(IF(C27=0,"",C27/C$11),"") | F27: =IFERROR(IF(E27=0,"",E27/E$11),"") | H27: =IFERROR(IF(G27=0,"",G27/G$11),"") | J27: =IFERROR(IF(I27=0,"",I27/I$11),"") | L27: =IFERROR(IF(K27=0,"",K27/K$11),"")
D28: =IFERROR(IF(C28=0,"",C28/C$11),"") | F28: =IFERROR(IF(E28=0,"",E28/E$11),"") | H28: =IFERROR(IF(G28=0,"",G28/G$11),"") | J28: =IFERROR(IF(I28=0,"",I28/I$11),"") | L28: =IFERROR(IF(K28=0,"",K28/K$11),"")
B29: 営業外費用 | C29: =SUM(C30:C36) -> 0 | D29: =IFERROR(IF(C29=0,"",C29/C$11),"") | E29: =SUM(E30:E36) -> 1134221 | F29: =IFERROR(IF(E29=0,"",E29/E$11),"") -> 0.002390711 | G29: =SUM(G30:G36) -> 2295915 | H29: =IFERROR(IF(G29=0,"",G29/G$11),"") -> 0.0042593058 | I29: =SUM(I30:I36) -> 2655577 | J29: =IFERROR(IF(I29=0,"",I29/I$11),"") -> 0.0047557769 | K29: =SUM(K30:K36) -> 1881979 | L29: =IFERROR(IF(K29=0,"",K29/K$11),"") -> 0.0067417367
B30: 支払利息 | D30: =IFERROR(IF(C30=0,"",C30/C$11),"") | E30: 1134221 | F30: =IFERROR(IF(E30=0,"",E30/E$11),"") -> 0.002390711 | G30: 1787923 | H30: =IFERROR(IF(G30=0,"",G30/G$11),"") -> 0.0033168958 | I30: 2590791 | J30: =IFERROR(IF(I30=0,"",I30/I$11),"") -> 0.004639754 | K30: 1881899 | L30: =IFERROR(IF(K30=0,"",K30/K$11),"") -> 0.0067414501
B31: 雑損失 | D31: =IFERROR(IF(C31=0,"",C31/C$11),"") | F31: =IFERROR(IF(E31=0,"",E31/E$11),"") | G31: 507992 | H31: =IFERROR(IF(G31=0,"",G31/G$11),"") -> 0.00094241001 | I31: 64786 | J31: =IFERROR(IF(I31=0,"",I31/I$11),"") -> 0.00011602291 | K31: 80 | L31: =IFERROR(IF(K31=0,"",K31/K$11),"") -> 2.8658074e-07
D32: =IFERROR(IF(C32=0,"",C32/C$11),"") | F32: =IFERROR(IF(E32=0,"",E32/E$11),"") | H32: =IFERROR(IF(G32=0,"",G32/G$11),"") | J32: =IFERROR(IF(I32=0,"",I32/I$11),"") | L32: =IFERROR(IF(K32=0,"",K32/K$11),"")
D33: =IFERROR(IF(C33=0,"",C33/C$11),"") | F33: =IFERROR(IF(E33=0,"",E33/E$11),"") | H33: =IFERROR(IF(G33=0,"",G33/G$11),"") | J33: =IFERROR(IF(I33=0,"",I33/I$11),"") | L33: =IFERROR(IF(K33=0,"",K33/K$11),"")
D34: =IFERROR(IF(C34=0,"",C34/C$11),"") | F34: =IFERROR(IF(E34=0,"",E34/E$11),"") | H34: =IFERROR(IF(G34=0,"",G34/G$11),"") | J34: =IFERROR(IF(I34=0,"",I34/I$11),"") | L34: =IFERROR(IF(K34=0,"",K34/K$11),"")
D35: =IFERROR(IF(C35=0,"",C35/C$11),"") | F35: =IFERROR(IF(E35=0,"",E35/E$11),"") | H35: =IFERROR(IF(G35=0,"",G35/G$11),"") | J35: =IFERROR(IF(I35=0,"",I35/I$11),"") | L35: =IFERROR(IF(K35=0,"",K35/K$11),"")
D36: =IFERROR(IF(C36=0,"",C36/C$11),"") | F36: =IFERROR(IF(E36=0,"",E36/E$11),"") | H36: =IFERROR(IF(G36=0,"",G36/G$11),"") | J36: =IFERROR(IF(I36=0,"",I36/I$11),"") | L36: =IFERROR(IF(K36=0,"",K36/K$11),"")
B37: 経常利益 | C37: =C20+C21-C29 -> 0 | D37: =IFERROR(IF(C37=0,"",C37/C$11),"") | E37: =E20+E21-E29 -> 2528371 | F37: =IFERROR(IF(E37=0,"",E37/E$11),"") -> 0.0053293003 | G37: =G20+G21-G29 -> 3109637 | H37: =IFERROR(IF(G37=0,"",G37/G$11),"") -> 0.0057688961 | I37: =I20+I21-I29 -> -18575356 | J37: =IFERROR(IF(I37=0,"",I37/I$11),"") -> -0.033265934 | K37: =K20+K21-K29 -> 5814146 | L37: =IFERROR(IF(K37=0,"",K37/K$11),"") -> 0.020827778
B38: 特別利益 | C38: =SUM(C39:C44) -> 0 | D38: =IFERROR(IF(C38=0,"",C38/C$11),"") | E38: =SUM(E39:E44) -> 0 | F38: =IFERROR(IF(E38=0,"",E38/E$11),"") | G38: =SUM(G39:G44) -> 0 | H38: =IFERROR(IF(G38=0,"",G38/G$11),"") | I38: =SUM(I39:I44) -> 0 | J38: =IFERROR(IF(I38=0,"",I38/I$11),"") | K38: =SUM(K39:K44) -> 0 | L38: =IFERROR(IF(K38=0,"",K38/K$11),"")
D39: =IFERROR(IF(C39=0,"",C39/C$11),"") | F39: =IFERROR(IF(E39=0,"",E39/E$11),"") | H39: =IFERROR(IF(G39=0,"",G39/G$11),"") | J39: =IFERROR(IF(I39=0,"",I39/I$11),"") | L39: =IFERROR(IF(K39=0,"",K39/K$11),"")
D40: =IFERROR(IF(C40=0,"",C40/C$11),"") | F40: =IFERROR(IF(E40=0,"",E40/E$11),"") | H40: =IFERROR(IF(G40=0,"",G40/G$11),"") | J40: =IFERROR(IF(I40=0,"",I40/I$11),"") | L40: =IFERROR(IF(K40=0,"",K40/K$11),"")
D41: =IFERROR(IF(C41=0,"",C41/C$11),"") | F41: =IFERROR(IF(E41=0,"",E41/E$11),"") | H41: =IFERROR(IF(G41=0,"",G41/G$11),"") | J41: =IFERROR(IF(I41=0,"",I41/I$11),"") | L41: =IFERROR(IF(K41=0,"",K41/K$11),"")
...

Sheet CR
B2: ※対象会社は小売業であり製造原価報告書は作成されていないため、本シートは使用しない。
H4: (単位：千円)
B5: 科目 | C5: ='BS(借方)'!C4 -> － | E5: ='BS(借方)'!D4 -> 23年11月期 | G5: ='BS(借方)'!E4 -> 24年11月期 | I5: ='BS(借方)'!F4 -> 25年11月期 | K5: ='BS(借方)'!G4 -> 26年11月期 （7か月TB）
C6: 帳簿価額 | D6: 売上高比 | E6: 帳簿価額 | F6: 売上高比 | G6: 帳簿価額 | H6: 売上高比 | I6: 帳簿価額 | J6: 売上高比 | K6: 帳簿価額 | L6: 売上高比
A7: IMに貼るときは非表示→ | B7: 売上 | C7: =PL!C11 -> 0 | D7: - | E7: =PL!E11 -> 474428321 | F7: - | G7: =PL!G11 -> 539035019 | H7: - | I7: =PL!I11 -> 558389734 | J7: - | K7: =PL!K11 -> 279153443 | L7: -
B8: 期首原材料棚卸高 | D8: =IFERROR(IF(C8=0,"",C8/C$7),"") | F8: =IFERROR(IF(E8=0,"",E8/E$7),"") | H8: =IFERROR(IF(G8=0,"",G8/G$7),"") | J8: =IFERROR(IF(I8=0,"",I8/I$7),"") | L8: =IFERROR(IF(K8=0,"",K8/K$7),"")
B9: 原材料仕入高 | D9: =IFERROR(IF(C9=0,"",C9/C$7),"") | F9: =IFERROR(IF(E9=0,"",E9/E$7),"") | H9: =IFERROR(IF(G9=0,"",G9/G$7),"") | J9: =IFERROR(IF(I9=0,"",I9/I$7),"") | L9: =IFERROR(IF(K9=0,"",K9/K$7),"")
B10: 小計 | D10: =IFERROR(IF(C10=0,"",C10/C$7),"") | F10: =IFERROR(IF(E10=0,"",E10/E$7),"") | H10: =IFERROR(IF(G10=0,"",G10/G$7),"") | J10: =IFERROR(IF(I10=0,"",I10/I$7),"") | L10: =IFERROR(IF(K10=0,"",K10/K$7),"")
B11: 期末原材料棚卸高 | D11: =IFERROR(IF(C11=0,"",C11/C$7),"") | F11: =IFERROR(IF(E11=0,"",E11/E$7),"") | H11: =IFERROR(IF(G11=0,"",G11/G$7),"") | J11: =IFERROR(IF(I11=0,"",I11/I$7),"") | L11: =IFERROR(IF(K11=0,"",K11/K$7),"")
D12: =IFERROR(IF(C12=0,"",C12/C$7),"") | F12: =IFERROR(IF(E12=0,"",E12/E$7),"") | H12: =IFERROR(IF(G12=0,"",G12/G$7),"") | J12: =IFERROR(IF(I12=0,"",I12/I$7),"") | L12: =IFERROR(IF(K12=0,"",K12/K$7),"")
D13: =IFERROR(IF(C13=0,"",C13/C$7),"") | F13: =IFERROR(IF(E13=0,"",E13/E$7),"") | H13: =IFERROR(IF(G13=0,"",G13/G$7),"") | J13: =IFERROR(IF(I13=0,"",I13/I$7),"") | L13: =IFERROR(IF(K13=0,"",K13/K$7),"")
B14: 材料費 | C14: =SUM(C8:C13) -> 0 | D14: =IFERROR(IF(C14=0,"",C14/C$7),"") | E14: =SUM(E8:E13) -> 0 | F14: =IFERROR(IF(E14=0,"",E14/E$7),"") | G14: =SUM(G8:G13) -> 0 | H14: =IFERROR(IF(G14=0,"",G14/G$7),"") | I14: =SUM(I8:I13) -> 0 | J14: =IFERROR(IF(I14=0,"",I14/I$7),"") | K14: =SUM(K8:K13) -> 0 | L14: =IFERROR(IF(K14=0,"",K14/K$7),"")
D15: =IFERROR(IF(C15=0,"",C15/C$7),"") | F15: =IFERROR(IF(E15=0,"",E15/E$7),"") | H15: =IFERROR(IF(G15=0,"",G15/G$7),"") | J15: =IFERROR(IF(I15=0,"",I15/I$7),"") | L15: =IFERROR(IF(K15=0,"",K15/K$7),"")
D18: =IFERROR(IF(C18=0,"",C18/C$7),"") | F18: =IFERROR(IF(E18=0,"",E18/E$7),"") | H18: =IFERROR(IF(G18=0,"",G18/G$7),"") | J18: =IFERROR(IF(I18=0,"",I18/I$7),"") | L18: =IFERROR(IF(K18=0,"",K18/K$7),"")
D19: =IFERROR(IF(C19=0,"",C19/C$7),"") | F19: =IFERROR(IF(E19=0,"",E19/E$7),"") | H19: =IFERROR(IF(G19=0,"",G19/G$7),"") | J19: =IFERROR(IF(I19=0,"",I19/I$7),"") | L19: =IFERROR(IF(K19=0,"",K19/K$7),"")
D20: =IFERROR(IF(C20=0,"",C20/C$7),"") | F20: =IFERROR(IF(E20=0,"",E20/E$7),"") | H20: =IFERROR(IF(G20=0,"",G20/G$7),"") | J20: =IFERROR(IF(I20=0,"",I20/I$7),"") | L20: =IFERROR(IF(K20=0,"",K20/K$7),"")
D21: =IFERROR(IF(C21=0,"",C21/C$7),"") | F21: =IFERROR(IF(E21=0,"",E21/E$7),"") | H21: =IFERROR(IF(G21=0,"",G21/G$7),"") | J21: =IFERROR(IF(I21=0,"",I21/I$7),"") | L21: =IFERROR(IF(K21=0,"",K21/K$7),"")
D22: =IFERROR(IF(C22=0,"",C22/C$7),"") | F22: =IFERROR(IF(E22=0,"",E22/E$7),"") | H22: =IFERROR(IF(G22=0,"",G22/G$7),"") | J22: =IFERROR(IF(I22=0,"",I22/I$7),"") | L22: =IFERROR(IF(K22=0,"",K22/K$7),"")
B23: 労務費 | C23: =SUM(C15:C22) -> 0 | D23: =IFERROR(IF(C23=0,"",C23/C$7),"") | E23: =SUM(E15:E22) -> 0 | F23: =IFERROR(IF(E23=0,"",E23/E$7),"") | G23: =SUM(G15:G22) -> 0 | H23: =IFERROR(IF(G23=0,"",G23/G$7),"") | I23: =SUM(I15:I22) -> 0 | J23: =IFERROR(IF(I23=0,"",I23/I$7),"") | K23: =SUM(K15:K22) -> 0 | L23: =IFERROR(IF(K23=0,"",K23/K$7),"")
D24: =IFERROR(IF(C24=0,"",C24/C$7),"") | F24: =IFERROR(IF(E24=0,"",E24/E$7),"") | H24: =IFERROR(IF(G24=0,"",G24/G$7),"") | J24: =IFERROR(IF(I24=0,"",I24/I$7),"") | L24: =IFERROR(IF(K24=0,"",K24/K$7),"")
D28: =IFERROR(IF(C28=0,"",C28/C$7),"") | F28: =IFERROR(IF(E28=0,"",E28/E$7),"") | H28: =IFERROR(IF(G28=0,"",G28/G$7),"") | J28: =IFERROR(IF(I28=0,"",I28/I$7),"") | L28: =IFERROR(IF(K28=0,"",K28/K$7),"")
D29: =IFERROR(IF(C29=0,"",C29/C$7),"") | F29: =IFERROR(IF(E29=0,"",E29/E$7),"") | H29: =IFERROR(IF(G29=0,"",G29/G$7),"") | J29: =IFERROR(IF(I29=0,"",I29/I$7),"") | L29: =IFERROR(IF(K29=0,"",K29/K$7),"")
D30: =IFERROR(IF(C30=0,"",C30/C$7),"") | F30: =IFERROR(IF(E30=0,"",E30/E$7),"") | H30: =IFERROR(IF(G30=0,"",G30/G$7),"") | J30: =IFERROR(IF(I30=0,"",I30/I$7),"") | L30: =IFERROR(IF(K30=0,"",K30/K$7),"")
D31: =IFERROR(IF(C31=0,"",C31/C$7),"") | F31: =IFERROR(IF(E31=0,"",E31/E$7),"") | H31: =IFERROR(IF(G31=0,"",G31/G$7),"") | J31: =IFERROR(IF(I31=0,"",I31/I$7),"") | L31: =IFERROR(IF(K31=0,"",K31/K$7),"")
D32: =IFERROR(IF(C32=0,"",C32/C$7),"") | F32: =IFERROR(IF(E32=0,"",E32/E$7),"") | H32: =IFERROR(IF(G32=0,"",G32/G$7),"") | J32: =IFERROR(IF(I32=0,"",I32/I$7),"") | L32: =IFERROR(IF(K32=0,"",K32/K$7),"")
B33: 外注加工費 | C33: =SUM(C24:C32) -> 0 | D33: =IFERROR(IF(C33=0,"",C33/C$7),"") | E33: =SUM(E24:E32) -> 0 | F33: =IFERROR(IF(E33=0,"",E33/E$7),"") | G33: =SUM(G24:G32) -> 0 | H33: =IFERROR(IF(G33=0,"",G33/G$7),"") | I33: =SUM(I24:I32) -> 0 | J33: =IFERROR(IF(I33=0,"",I33/I$7),"") | K33: =SUM(K24:K32) -> 0 | L33: =IFERROR(IF(K33=0,"",K33/K$7),"")
D34: =IFERROR(IF(C34=0,"",C34/C$7),"") | F34: =IFERROR(IF(E34=0,"",E34/E$7),"") | H34: =IFERROR(IF(G34=0,"",G34/G$7),"") | J34: =IFERROR(IF(I34=0,"",I34/I$7),"") | L34: =IFERROR(IF(K34=0,"",K34/K$7),"")
D35: =IFERROR(IF(C35=0,"",C35/C$7),"") | F35: =IFERROR(IF(E35=0,"",E35/E$7),"") | H35: =IFERROR(IF(G35=0,"",G35/G$7),"") | J35: =IFERROR(IF(I35=0,"",I35/I$7),"") | L35: =IFERROR(IF(K35=0,"",K35/K$7),"")
D36: =IFERROR(IF(C36=0,"",C36/C$7),"") | F36: =IFERROR(IF(E36=0,"",E36/E$7),"") | H36: =IFERROR(IF(G36=0,"",G36/G$7),"") | J36: =IFERROR(IF(I36=0,"",I36/I$7),"") | L36: =IFERROR(IF(K36=0,"",K36/K$7),"")
D39: =IFERROR(IF(C39=0,"",C39/C$7),"") | F39: =IFERROR(IF(E39=0,"",E39/E$7),"") | H39: =IFERROR(IF(G39=0,"",G39/G$7),"") | J39: =IFERROR(IF(I39=0,"",I39/I$7),"") | L39: =IFERROR(IF(K39=0,"",K39/K$7),"")
D40: =IFERROR(IF(C40=0,"",C40/C$7),"") | F40: =IFERROR(IF(E40=0,"",E40/E$7),"") | H40: =IFERROR(IF(G40=0,"",G40/G$7),"") | J40: =IFERROR(IF(I40=0,"",I40/I$7),"") | L40: =IFERROR(IF(K40=0,"",K40/K$7),"")
D41: =IFERROR(IF(C41=0,"",C41/C$7),"") | F41: =IFERROR(IF(E41=0,"",E41/E$7),"") | H41: =IFERROR(IF(G41=0,"",G41/G$7),"") | J41: =IFERROR(IF(I41=0,"",I41/I$7),"") | L41: =IFERROR(IF(K41=0,"",K41/K$7),"")
D42: =IFERROR(IF(C42=0,"",C42/C$7),"") | F42: =IFERROR(IF(E42=0,"",E42/E$7),"") | H42: =IFERROR(IF(G42=0,"",G42/G$7),"") | J42: =IFERROR(IF(I42=0,"",I42/I$7),"") | L42: =IFERROR(IF(K42=0,"",K42/K$7),"")
D43: =IFERROR(IF(C43=0,"",C43/C$7),"") | F43: =IFERROR(IF(E43=0,"",E43/E$7),"") | H43: =IFERROR(IF(G43=0,"",G43/G$7),"") | J43: =IFERROR(IF(I43=0,"",I43/I$7),"") | L43: =IFERROR(IF(K43=0,"",K43/K$7),"")
D44: =IFERROR(IF(C44=0,"",C44/C$7),"") | F44: =IFERROR(IF(E44=0,"",E44/E$7),"") | H44: =IFERROR(IF(G44=0,"",G44/G$7),"") | J44: =IFERROR(IF(I44=0,"",I44/I$7),"") | L44: =IFERROR(IF(K44=0,"",K44/K$7),"")
D45: =IFERROR(IF(C45=0,"",C45/C$7),"") | F45: =IFERROR(IF(E45=0,"",E45/E$7),"") | H45: =IFERROR(IF(G45=0,"",G45/G$7),"") | J45: =IFERROR(IF(I45=0,"",I45/I$7),"") | L45: =IFERROR(IF(K45=0,"",K45/K$7),"")
B46: 経費 | C46: =SUM(C34:C45) -> 0 | D46: =IFERROR(IF(C46=0,"",C46/C$7),"") | E46: =SUM(E34:E45) -> 0 | F46: =IFERROR(IF(E46=0,"",E46/E$7),"") | G46: =SUM(G34:G45) -> 0 | H46: =IFERROR(IF(G46=0,"",G46/G$7),"") | I46: =SUM(I34:I45) -> 0 | J46: =IFERROR(IF(I46=0,"",I46/I$7),"") | K46: =SUM(K34:K45) -> 0 | L46: =IFERROR(IF(K46=0,"",K46/K$7),"")
B47: 当期製造費用 | C47: =C14+C23+C33+C46 -> 0 | D47: =IFERROR(IF(C47=0,"",C47/C$7),"") | E47: =E14+E23+E33+E46 -> 0 | F47: =IFERROR(IF(E47=0,"",E47/E$7),"") | G47: =G14+G23+G33+G46 -> 0 | H47: =IFERROR(IF(G47=0,"",G47/G$7),"") | I47: =I14+I23+I33+I46 -> 0 | J47: =IFERROR(IF(I47=0,"",I47/I$7),"") | K47: =K14+K23+K33+K46 -> 0 | L47: =IFERROR(IF(K47=0,"",K47/K$7),"")
B48: 期首仕掛品棚卸高 | D48: =IFERROR(IF(C48=0,"",C48/C$7),"") | E48: =SUM(E36:E47) -> 0 | F48: =IFERROR(IF(E48=0,"",E48/E$7),"") | G48: =SUM(G36:G47) -> 0 | H48: =IFERROR(IF(G48=0,"",G48/G$7),"") | I48: =SUM(I36:I47) -> 0 | J48: =IFERROR(IF(I48=0,"",I48/I$7),"") | K48: =SUM(K36:K47) -> 0 | L48: =IFERROR(IF(K48=0,"",K48/K$7),"")
B49: 合計 | C49: =SUM(C47:C48) -> 0 | D49: =IFERROR(IF(C49=0,"",C49/C$7),"") | E49: =SUM(E47:E48) -> 0 | F49: =IFERROR(IF(E49=0,"",E49/E$7),"") | G49: =SUM(G47:G48) -> 0 | H49: =IFERROR(IF(G49=0,"",G49/G$7),"") | I49: =SUM(I47:I48) -> 0 | J49: =IFERROR(IF(I49=0,"",I49/I$7),"") | K49: =SUM(K47:K48) -> 0 | L49: =IFERROR(IF(K49=0,"",K49/K$7),"")
...

Sheet SGA
H2: (単位：千円)
B3: 科目 | C3: ='BS(借方)'!C4 -> － | E3: ='BS(借方)'!D4 -> 23年11月期 | G3: ='BS(借方)'!E4 -> 24年11月期 | I3: ='BS(借方)'!F4 -> 25年11月期 | K3: ='BS(借方)'!G4 -> 26年11月期 （7か月TB）
C4: 帳簿価額 | D4: 売上高比 | E4: 帳簿価額 | F4: 売上高比 | G4: 帳簿価額 | H4: 売上高比 | I4: 帳簿価額 | J4: 売上高比 | K4: 帳簿価額 | L4: 売上高比
B5: 売上 | C5: =PL!C11 -> 0 | D5: - | E5: =PL!E11 -> 474428321 | F5: - | G5: =PL!G11 -> 539035019 | H5: - | I5: =PL!I11 -> 558389734 | J5: - | K5: =PL!K11 -> 279153443 | L5: - | M5: ←IMに貼るときは非表示
B6: 従業員給与 | D6: =IFERROR(C6/$C$5,"") | E6: 112323477 | F6: =IFERROR(E6/$E$5,"") -> 0.23675542 | G6: 115961553 | H6: =IFERROR(G6/$G$5,"") -> 0.21512805 | I6: 127016990 | J6: =IFERROR(I6/$I$5,"") -> 0.22747014 | K6: 64179726 | L6: =IFERROR(K6/$K$5,"") -> 0.22990842
B7: 旅費交通費 | D7: =IFERROR(C7/$C$5,"") | E7: 3152359 | F7: =IFERROR(E7/$E$5,"") -> 0.0066445422 | G7: 4978151 | H7: =IFERROR(G7/$G$5,"") -> 0.0092353016 | I7: 5724652 | J7: =IFERROR(I7/$I$5,"") -> 0.010252072 | K7: 3504938 | L7: =IFERROR(K7/$K$5,"") -> 0.012555597
B8: 広告宣伝費 | D8: =IFERROR(C8/$C$5,"") | E8: 24335030 | F8: =IFERROR(E8/$E$5,"") -> 0.051293375 | G8: 34052424 | H8: =IFERROR(G8/$G$5,"") -> 0.063172935 | I8: 26650854 | J8: =IFERROR(I8/$I$5,"") -> 0.047728052 | K8: 15163208 | L8: =IFERROR(K8/$K$5,"") -> 0.054318542
B9: 発送配達費 | D9: =IFERROR(C9/$C$5,"") | E9: 352787 | F9: =IFERROR(E9/$E$5,"") -> 0.00074360443 | G9: 280605 | H9: =IFERROR(G9/$G$5,"") -> 0.00052056915 | I9: 436931 | J9: =IFERROR(I9/$I$5,"") -> 0.00078248394 | K9: 129150 | L9: =IFERROR(K9/$K$5,"") -> 0.00046264878
B10: ロイヤリティ | D10: =IFERROR(C10/$C$5,"") | E10: 45990311 | F10: =IFERROR(E10/$E$5,"") -> 0.096938376 | G10: 39848148 | H10: =IFERROR(G10/$G$5,"") -> 0.073924971 | I10: 29981679 | J10: =IFERROR(I10/$I$5,"") -> 0.053693106 | K10: 14193011 | L10: =IFERROR(K10/$K$5,"") -> 0.050843045
B11: 会議費 | D11: =IFERROR(C11/$C$5,"") | E11: 189625 | F11: =IFERROR(E11/$E$5,"") -> 0.00039969157 | G11: 484171 | H11: =IFERROR(G11/$G$5,"") -> 0.00089821808 | I11: 1489497 | J11: =IFERROR(I11/$I$5,"") -> 0.0026674864 | K11: 887177 | L11: =IFERROR(K11/$K$5,"") -> 0.003178098
B12: 役員報酬 | D12: =IFERROR(C12/$C$5,"") | E12: 9600000 | F12: =IFERROR(E12/$E$5,"") -> 0.02023488 | G12: 9600000 | H12: =IFERROR(G12/$G$5,"") -> 0.017809604 | I12: 14400000 | J12: =IFERROR(I12/$I$5,"") -> 0.02578844 | K12: 6300000 | L12: =IFERROR(K12/$K$5,"") -> 0.022568233
B13: 法定福利費 | D13: =IFERROR(C13/$C$5,"") | E13: 10104201 | F13: =IFERROR(E13/$E$5,"") -> 0.021297635 | G13: 22242217 | H13: =IFERROR(G13/$G$5,"") -> 0.041263028 | I13: 15295210 | J13: =IFERROR(I13/$I$5,"") -> 0.027391639 | K13: 2778916 | L13: =IFERROR(K13/$K$5,"") -> 0.0099547975
B14: 厚生費 | D14: =IFERROR(C14/$C$5,"") | E14: 2936211 | F14: =IFERROR(E14/$E$5,"") -> 0.0061889455 | G14: 3945609 | H14: =IFERROR(G14/$G$5,"") -> 0.0073197638 | I14: 3862961 | J14: =IFERROR(I14/$I$5,"") -> 0.0069180373 | K14: 1748144 | L14: =IFERROR(K14/$K$5,"") -> 0.006262305
B15: 減価償却費 | D15: =IFERROR(C15/$C$5,"") | E15: 3911003 | F15: =IFERROR(E15/$E$5,"") -> 0.008243612 | G15: 9294598 | H15: =IFERROR(G15/$G$5,"") -> 0.017243032 | I15: 6349173 | J15: =IFERROR(I15/$I$5,"") -> 0.011370505 | L15: =IFERROR(K15/$K$5,"") -> 0
B16: リース料 | D16: =IFERROR(C16/$C$5,"") | E16: 4294932 | F16: =IFERROR(E16/$E$5,"") -> 0.0090528575 | G16: 4554982 | H16: =IFERROR(G16/$G$5,"") -> 0.0084502525 | I16: 7249573 | J16: =IFERROR(I16/$I$5,"") -> 0.012982998 | K16: 4352502 | L16: =IFERROR(K16/$K$5,"") -> 0.01559179
B17: 地代家賃 | D17: =IFERROR(C17/$C$5,"") | E17: 8230492 | F17: =IFERROR(E17/$E$5,"") -> 0.017348231 | G17: 19460488 | H17: =IFERROR(G17/$G$5,"") -> 0.036102456 | I17: 33248832 | J17: =IFERROR(I17/$I$5,"") -> 0.059544132 | K17: 19879129 | L17: =IFERROR(K17/$K$5,"") -> 0.071212194
B18: 修繕費 | D18: =IFERROR(C18/$C$5,"") | E18: 468295 | F18: =IFERROR(E18/$E$5,"") -> 0.00098707219 | G18: 1088033 | H18: =IFERROR(G18/$G$5,"") -> 0.002018483 | I18: 275210 | J18: =IFERROR(I18/$I$5,"") -> 0.00049286365 | K18: 243111 | L18: =IFERROR(K18/$K$5,"") -> 0.00087088663
B19: 事務用消耗品費 | D19: =IFERROR(C19/$C$5,"") | E19: 9801863 | F19: =IFERROR(E19/$E$5,"") -> 0.020660367 | G19: 6407354 | H19: =IFERROR(G19/$G$5,"") -> 0.011886712 | I19: 4371794 | J19: =IFERROR(I19/$I$5,"") -> 0.0078292879 | K19: 1558723 | L19: =IFERROR(K19/$K$5,"") -> 0.0055837499
B20: 通信費 | D20: =IFERROR(C20/$C$5,"") | E20: 2455532 | F20: =IFERROR(E20/$E$5,"") -> 0.0051757703 | G20: 2672628 | H20: =IFERROR(G20/$G$5,"") -> 0.0049581714 | I20: 3045340 | J20: =IFERROR(I20/$I$5,"") -> 0.0054537894 | K20: 2149718 | L20: =IFERROR(K20/$K$5,"") -> 0.0077008472
B21: 水道光熱費 | D21: =IFERROR(C21/$C$5,"") | E21: 2958090 | F21: =IFERROR(E21/$E$5,"") -> 0.006235062 | G21: 3148822 | H21: =IFERROR(G21/$G$5,"") -> 0.0058415908 | I21: 3940893 | J21: =IFERROR(I21/$I$5,"") -> 0.0070576029 | K21: 1714053 | L21: =IFERROR(K21/$K$5,"") -> 0.0061401822
B22: 租税公課 | D22: =IFERROR(C22/$C$5,"") | E22: 8881475 | F22: =IFERROR(E22/$E$5,"") -> 0.018720373 | G22: 10506364 | H22: =IFERROR(G22/$G$5,"") -> 0.01949106 | I22: 20061210 | J22: =IFERROR(I22/$I$5,"") -> 0.035926896 | K22: 5281078 | L22: =IFERROR(K22/$K$5,"") -> 0.01891819
B23: 接待交際費 | D23: =IFERROR(C23/$C$5,"") | E23: 8453145 | F23: =IFERROR(E23/$E$5,"") -> 0.017817539 | G23: 10229520 | H23: =IFERROR(G23/$G$5,"") -> 0.018977468 | I23: 8217611 | J23: =IFERROR(I23/$I$5,"") -> 0.014716623 | K23: 4409532 | L23: =IFERROR(K23/$K$5,"") -> 0.015796087
B24: 保険料 | D24: =IFERROR(C24/$C$5,"") | E24: 2411203 | F24: =IFERROR(E24/$E$5,"") -> 0.0050823336 | G24: 4218242 | H24: =IFERROR(G24/$G$5,"") -> 0.0078255435 | I24: 3876512 | J24: =IFERROR(I24/$I$5,"") -> 0.0069423053 | K24: 1726252 | L24: =IFERROR(K24/$K$5,"") -> 0.0061838822
B25: 備品消耗品費 | D25: =IFERROR(C25/$C$5,"") | E25: 12485436 | F25: =IFERROR(E25/$E$5,"") -> 0.026316802 | G25: 14036551 | H25: =IFERROR(G25/$G$5,"") -> 0.026040147 | I25: 8462064 | J25: =IFERROR(I25/$I$5,"") -> 0.015154405 | K25: 4361180 | L25: =IFERROR(K25/$K$5,"") -> 0.015622877
B26: 管理諸費 | D26: =IFERROR(C26/$C$5,"") | E26: 5563800 | F26: =IFERROR(E26/$E$5,"") -> 0.011727377 | G26: 5027000 | H26: =IFERROR(G26/$G$5,"") -> 0.0093259247 | I26: 5797000 | J26: =IFERROR(I26/$I$5,"") -> 0.010381638 | K26: 3197700 | L26: =IFERROR(K26/$K$5,"") -> 0.01145499
B27: 支払手数料 | D27: =IFERROR(C27/$C$5,"") | E27: 7152851 | F27: =IFERROR(E27/$E$5,"") -> 0.015076779 | G27: 11861229 | H27: =IFERROR(G27/$G$5,"") -> 0.022004561 | I27: 14452516 | J27: =IFERROR(I27/$I$5,"") -> 0.025882489 | K27: 6927603 | L27: =IFERROR(K27/$K$5,"") -> 0.02481647
... B29: 車両費 | D29: =IFERROR(C29/$C$5,"") | E29: 626896 | F29: =IFERROR(E29/$E$5,"") -> 0.0013213714 | G29: 446867 | H29: =IFERROR(G29/$G$5,"") -> 0.00082901293 | I29: 512955 | J29: =IFERROR(I29/$I$5,"") -> 0.00091863258 | K29: 258439 | L29: =IFERROR(K29/$K$5,"") -> 0.0009257955
B30: 研修費 | D30: =IFERROR(C30/$C$5,"") | F30: =IFERROR(E30/$E$5,"") -> 0 | G30: 103345 | H30: =IFERROR(G30/$G$5,"") -> 0.00019172224 | I30: 173500 | J30: =IFERROR(I30/$I$5,"") -> 0.00031071488 | K30: 88900 | L30: =IFERROR(K30/$K$5,"") -> 0.00031846285
B31: 雑費 | D31: =IFERROR(C31/$C$5,"") | E31: 3334480 | F31: =IFERROR(E31/$E$5,"") -> 0.0070284168 | G31: 5436149 | H31: =IFERROR(G31/$G$5,"") -> 0.010084964 | I31: 4666766 | J31: =IFERROR(I31/$I$5,"") -> 0.0083575426 | K31: 2718158 | L31: =IFERROR(K31/$K$5,"") -> 0.0097371466
D32: =IFERROR(C32/$C$5,"") | F32: =IFERROR(E32/$E$5,"") -> 0 | H32: =IFERROR(G32/$G$5,"") -> 0 | J32: =IFERROR(I32/$I$5,"") -> 0 | L32: =IFERROR(K32/$K$5,"") -> 0
D33: =IFERROR(C33/$C$5,"") | F33: =IFERROR(E33/$E$5,"") -> 0 | H33: =IFERROR(G33/$G$5,"") -> 0 | J33: =IFERROR(I33/$I$5,"") -> 0 | L33: =IFERROR(K33/$K$5,"") -> 0
D34: =IFERROR(C34/$C$5,"") | F34: =IFERROR(E34/$E$5,"") -> 0 | H34: =IFERROR(G34/$G$5,"") -> 0 | J34: =IFERROR(I34/$I$5,"") -> 0 | L34: =IFERROR(K34/$K$5,"") -> 0
D35: =IFERROR(C35/$C$5,"") | F35: =IFERROR(E35/$E$5,"") -> 0 | H35: =IFERROR(G35/$G$5,"") -> 0 | J35: =IFERROR(I35/$I$5,"") -> 0 | L35: =IFERROR(K35/$K$5,"") -> 0
D36: =IFERROR(C36/$C$5,"") | F36: =IFERROR(E36/$E$5,"") -> 0 | H36: =IFERROR(G36/$G$5,"") -> 0 | J36: =IFERROR(I36/$I$5,"") -> 0 | L36: =IFERROR(K36/$K$5,"") -> 0
D37: =IFERROR(C37/$C$5,"") | F37: =IFERROR(E37/$E$5,"") -> 0 | H37: =IFERROR(G37/$G$5,"") -> 0 | J37: =IFERROR(I37/$I$5,"") -> 0 | L37: =IFERROR(K37/$K$5,"") -> 0
D38: =IFERROR(C38/$C$5,"") | F38: =IFERROR(E38/$E$5,"") -> 0 | H38: =IFERROR(G38/$G$5,"") -> 0 | J38: =IFERROR(I38/$I$5,"") -> 0 | L38: =IFERROR(K38/$K$5,"") -> 0
D39: =IFERROR(C39/$C$5,"") | F39: =IFERROR(E39/$E$5,"") -> 0 | H39: =IFERROR(G39/$G$5,"") -> 0 | J39: =IFERROR(I39/$I$5,"") -> 0 | L39: =IFERROR(K39/$K$5,"") -> 0
B40: 販売費および一般管理費合計 | C40: =SUM(C6:C39) -> 0 | D40: =IFERROR(C40/C5,"") | E40: =SUM(E6:E39) -> 290037494 | F40: =IFERROR(E40/E5,"") -> 0.61134102 | G40: =SUM(G6:G39) -> 339909050 | H40: =IFERROR(G40/G5,"") -> 0.63058807 | I40: =SUM(I6:I39) -> 349576223 | J40: =IFERROR(I40/I5,"") -> 0.62604343 | K40: =SUM(K6:K39) -> 167754348 | L40: =IFERROR(K40/K5,"") -> 0.60093956

Sheet VR→ 

Sheet 評価参考
B2: 参考｜進行期（2026年11月期）7か月実績を年換算した場合の試算
B3: ※不採算2店舗の撤退効果が通期で発現し、進行期7か月の水準が年間を通じて維持されることを前提とした仮説試算であり、評価結果ではない。
C4: (単位：千円)
B5: 進行期7か月 営業利益 | C5: =PLハイライト!G8 -> 6636849 | D5: 月次では減価償却費が未計上のため実質的にEBITDAベース
B6: 正常収益力調整（7か月相当） | C6: =PLハイライト!F17/12*7 -> 11598923 | D6: 第5期の調整項目合計19,884千円を7か月按分
B7: 進行期7か月 修正後EBITDA | C7: =C5+C6 -> 18235772
B8: 年換算 修正後EBITDA | C8: =C7/7*12 -> 31261323 | D8: 7か月実績を12か月へ単純年換算
B9: 減価償却費（通期実績） | C9: =-PLハイライト!F15 -> -6349173 | D9: 第5期の実績額を通期見込みとして控除
B10: 年換算 修正後営業利益 | C10: =C8+C9 -> 24912150
B12: 時価純資産（2026年6月末ベース） | C12: ='BS (貸方)'!G50-'BS(借方)'!G50-'BS(借方)'!G14 -> -55420760 | D12: 進行期末の純資産から営業権・仮払金を控除。棚卸資産の廃棄損は進行期に計上済のため追加の評価減はない
B13: 営業権（年買法・1倍） | C13: =C10*0.66*1 -> 16442019 | D13: 税考慮後営業利益×1倍
B14: 営業権（年買法・3倍） | C14: =C10*0.66*3 -> 49326058 | D14: 税考慮後営業利益×3倍
B15: 想定株式価値（年買法・下限） | C15: =C12+C13 -> -38978741 | D15: 時価純資産＋営業権1倍
B16: 想定株式価値（年買法・上限） | C16: =C12+C14 -> -6094702.2 | D16: 時価純資産＋営業権3倍

Sheet 株式価値 
A1: 作業不要（自動作成）
F2: (単位：千円)
C3: min | D3: 差（グラフ作成用） | E3: max
B4: インカム | C4: 0 | D4: 0 | E4: 0 | F4: 100 | I4: ｚ
B5: マーケット | C5: ='EV EBITDAマルチプル'!K7 -> -140949808 | D5: =E5-C5 -> 32383980 | E5: ='EV EBITDAマルチプル'!M7 -> -108565828 | F5: 0
B6: コスト | C6: =年買法!K6 -> -54971915 | D6: =E6-C6 -> 12469807 | E6: =年買法!M6 -> -42502108 | F6: 0

Sheet 修正BS(借方)
E2: (単位：千円)
B3: 資産の部 | G3: 評価差額の根拠
B4: 科目 | C4: ='BS(借方)'!F4 -> 25年11月期 | D4: 修正額 | E4: 修正後
B5: 【流動資産】 | C5: =SUM(C6:C19) -> 150113194 | D5: =SUM(D6:D19) -> -45650000 | E5: =C5+D5 -> 104463194
B6: ='BS(借方)'!B6 -> 現金及び預金 | C6: ='BS(借方)'!F6 -> 10140492 | E6: =C6+D6 -> 10140492
B7: ='BS(借方)'!B7 -> 売掛金 | C7: ='BS(借方)'!F7 -> 27628072 | E7: =C7+D7 -> 27628072
B8: ='BS(借方)'!B8 -> 商品 | C8: ='BS(借方)'!F8 -> 106017284 | D8: -44000000 | E8: =C8+D8 -> 62017284 | G8: 2026年3月に本社分32,000千円・バックヤード分12,000千円を全額廃棄。基準日時点で既に滞留・陳腐化していたと判断し評価減
B9: ='BS(借方)'!B9 -> 貯蔵品 | C9: ='BS(借方)'!F9 -> 150000 | E9: =C9+D9 -> 150000
B10: ='BS(借方)'!B10 -> 前渡金 | C10: ='BS(借方)'!F10 -> 0 | E10: =C10+D10 -> 0
B11: ='BS(借方)'!B11 -> 前払費用 | C11: ='BS(借方)'!F11 -> 3991637 | E11: =C11+D11 -> 3991637
B12: ='BS(借方)'!B12 -> 未収入金 | C12: ='BS(借方)'!F12 -> 30800 | E12: =C12+D12 -> 30800
B13: ='BS(借方)'!B13 -> 未収還付法人税等 | C13: ='BS(借方)'!F13 -> 504909 | E13: =C13+D13 -> 504909
B14: ='BS(借方)'!B14 -> 仮払金 | C14: ='BS(借方)'!F14 -> 1650000 | D14: -1650000 | E14: =C14+D14 -> 0 | G14: 回収を前提とした支出ではなく資産性が認められないため全額評価減
B15: ='BS(借方)'!B15 -> 立替金 | C15: ='BS(借方)'!F15 -> 0 | E15: =C15+D15 -> 0
B16: ='BS(借方)'!B16 -> 0 | C16: ='BS(借方)'!F16 -> 0 | E16: =C16+D16 -> 0
B17: ='BS(借方)'!B17 -> 0 | C17: ='BS(借方)'!F17 -> 0 | E17: =C17+D17 -> 0
B18: ='BS(借方)'!B18 -> 0 | C18: ='BS(借方)'!F18 -> 0 | E18: =C18+D18 -> 0
E19: =C19+D19 -> 0
B20: 【固定資産】 | C20: =C21+C35+C46 -> 85271983 | D20: =D21+D35+D46 -> -1500004 | E20: =C20+D20 -> 83771979
B21: ［有形固定資産］ | C21: =SUM(C22:C34) -> 54658019 | D21: =SUM(D22:D34) -> 0 | E21: =C21+D21 -> 54658019
B22: ='BS(借方)'!B22 -> 建物 | C22: ='BS(借方)'!F22 -> 44397084 | E22: =C22+D22 -> 44397084
B23: ='BS(借方)'!B23 -> 建物付属設備 | C23: ='BS(借方)'!F23 -> 0 | E23: =C23+D23 -> 0
B24: ='BS(借方)'!B24 -> 構築物 | C24: ='BS(借方)'!F24 -> 0 | E24: =C24+D24 -> 0
B25: ='BS(借方)'!B25 -> 車両運搬具 | C25: ='BS(借方)'!F25 -> 1057574 | E25: =C25+D25 -> 1057574
B26: ='BS(借方)'!B26 -> 工具器具及び備品 | C26: ='BS(借方)'!F26 -> 6044761 | E26: =C26+D26 -> 6044761
B27: ='BS(借方)'!B27 -> 土地 | C27: ='BS(借方)'!F27 -> 2974400 | E27: =C27+D27 -> 2974400
B28: ='BS(借方)'!B28 -> その他の有形固定資産 | C28: ='BS(借方)'!F28 -> 184200 | E28: =C28+D28 -> 184200
B29: ='BS(借方)'!B29 -> 0 | C29: ='BS(借方)'!F29 -> 0 | E29: =C29+D29 -> 0
B30: ='BS(借方)'!B30 -> 0 | C30: ='BS(借方)'!F30 -> 0 | E30: =C30+D30 -> 0
B31: ='BS(借方)'!B31 -> 0 | C31: ='BS(借方)'!F31 -> 0 | E31: =C31+D31 -> 0
B32: ='BS(借方)'!B32 -> 0 | C32: ='BS(借方)'!F32 -> 0 | E32: =C32+D32 -> 0
B33: ='BS(借方)'!B33 -> 0 | C33: ='BS(借方)'!F33 -> 0 | E33: =C33+D33 -> 0
E34: =C34+D34 -> 0
B35: ［無形固定資産］ | C35: =SUM(C36:C45) -> 0 | D35: =SUM(D36:D45) -> 0 | E35: =C35+D35 -> 0
B36: ='BS(借方)'!B36 -> 0 | C36: ='BS(借方)'!F36 -> 0 | E36: =C36+D36 -> 0
B37: ='BS(借方)'!B37 -> 0 | C37: ='BS(借方)'!F37 -> 0 | E37: =C37+D37 -> 0
B38: ='BS(借方)'!B38 -> 0 | C38: ='BS(借方)'!F38 -> 0 | E38: =C38+D38 -> 0
B39: ='BS(借方)'!B39 -> 0 | C39: ='BS(借方)'!F39 -> 0 | E39: =C39+D39 -> 0
B40: ='BS(借方)'!B40 -> 0 | C40: ='BS(借方)'!F40 -> 0 | E40: =C40+D40 -> 0
E41: =C41+D41 -> 0
...

Sheet 売掛・棚卸
E2: (単位：千円)
A3: 売掛金 | B3: 相手先 | C3: 帳簿価額 | D3: 評価差額 | E3: 評価額 | F3: 調整事由
B4: 該当なし | F4: 2025年11月期末の売掛金27,628千円の内訳は㈲ワンラブ（FC本部）17,373千円、カード・PayPay等の決済会社10,255千円。いずれも翌月回収であり滞留債権は認められないため簿価評価とした。
E12: (単位：千円)
A13: 商品在庫 | B13: 相手先 | C13: 帳簿価額 | D13: 評価差額 | E13: 評価額 | F13: 調整事由
B14: 本社（バックヤード含む） | C14: 44000000 | D14: -44000000 | E14: 0 | F14: 2026年3月に本社分32,000千円・バックヤード分12,000千円を全額廃棄。基準日時点で既に滞留・陳腐化していたと判断し全額評価減
B15: 外部保管在庫 | C15: 10000000 | E15: 10000000 | F15: 実在性が未確認のため簿価評価（要確認）。実在しない場合は追加で10,000千円の評価減となる
B16: 店舗在庫（稼働6店舗＋撤退2店舗） | C16: 52017284 | E16: 52017284 | F16: 棚卸表により拠点別残高を確認。滞留・陳腐化は認められないため簿価評価
B17: 合計 | C17: =SUM(C14:C16) -> 106017284 | D17: =SUM(D14:D16) -> -44000000 | E17: =SUM(E14:E16) -> 62017284

Sheet 減価償却
E2: (単位：千円)
B3: 資産 | C3: 帳簿価額 | D3: 評価差額 | E3: 評価額 | F3: 調整事由
B4: 該当なし：減価償却内訳明細書により第5期は適正償却を確認しており、償却不足は認められない。

Sheet 土地
F2: (単位：千円)
B3: 内容・所在地 | C3: 地積(㎡) | D3: 帳簿価額 | E3: 評価差額 | F3: 時価評価額 | G3: 調整事由
B4: 駐車場用地／岐阜県大垣市南若森町字柳原227番3 | C4: 89.4 | D4: 2974400 | F4: 2974400 | G4: 路線価図・固定資産税評価証明が未受領のため簿価評価（要確認）。簿価は33千円/㎡であり大幅な含み損益は生じにくいと推察
B8: 合計 | C8: =C4 -> 89.4 | D8: =D4 -> 2974400 | E8: =SUM(E4:E7) -> 0 | F8: =F4 -> 2974400

Sheet 保険
E2: (単位：千円)
B3: 保険商品 | C3: 帳簿価額 | D3: 評価差額 | E3: 評価額 | F3: 調整事由
B4: 該当なし：保険積立金の計上はない（2025年11月期末残高ゼロ）。

Sheet 有価証券
F2: (単位：千円)
B3: 銘柄 | C3: 数量 | D3: 帳簿価額 | E3: 評価差額 | F3: 評価額 | G3: 調整事由
B4: 該当なし：有価証券・投資有価証券の保有はない（2025年11月期末残高ゼロ）。

Sheet 修正BS(貸方) 
E2: (単位：千円)
B3: 負債の部 | G3: 評価差額の根拠
B4: 科目 | C4: ='修正BS(借方)'!C4 -> 25年11月期 | D4: 修正額 | E4: 修正後
B5: 【流動負債】 | C5: =SUM(C6:C17) -> 47672202 | D5: =SUM(D6:D17) -> 0 | E5: =C5+D5 -> 47672202
B6: ='BS (貸方)'!B6 -> 買掛金 | C6: ='BS (貸方)'!F6 -> 9202412 | E6: =C6+D6 -> 9202412
B7: ='BS (貸方)'!B7 -> 短期借入金 | C7: ='BS (貸方)'!F7 -> 0 | E7: =C7+D7 -> 0
B8: ='BS (貸方)'!B8 -> 未払金 | C8: ='BS (貸方)'!F8 -> 714227 | E8: =C8+D8 -> 714227
B9: ='BS (貸方)'!B9 -> 未払費用 | C9: ='BS (貸方)'!F9 -> 20113617 | E9: =C9+D9 -> 20113617 | G9: 給与の締日から基準日までの経過分が含まれているか要確認。未計上であれば約10,000千円の追加計上余地（賃金台帳では当月締・翌月25日払）
B10: ='BS (貸方)'!B10 -> 未払法人税等 | C10: ='BS (貸方)'!F10 -> 242500 | E10: =C10+D10 -> 242500
B11: ='BS (貸方)'!B11 -> 未払消費税等 | C11: ='BS (貸方)'!F11 -> 11784100 | E11: =C11+D11 -> 11784100
B12: ='BS (貸方)'!B12 -> 預り金 | C12: ='BS (貸方)'!F12 -> 2391530 | E12: =C12+D12 -> 2391530
B13: ='BS (貸方)'!B13 -> カード未払金 | C13: ='BS (貸方)'!F13 -> 3223816 | E13: =C13+D13 -> 3223816
B14: ='BS (貸方)'!B14 -> 0 | C14: ='BS (貸方)'!F14 -> 0 | E14: =C14+D14 -> 0
B15: ='BS (貸方)'!B15 -> 0 | C15: ='BS (貸方)'!F15 -> 0 | E15: =C15+D15 -> 0
B16: ='BS (貸方)'!B16 -> 0 | C16: ='BS (貸方)'!F16 -> 0 | E16: =C16+D16 -> 0
E17: =C17+D17 -> 0
B18: 【固定負債】 | C18: =SUM(C19:C26) -> 201769790 | D18: =SUM(D19:D26) -> 0 | E18: =C18+D18 -> 201769790
B19: ='BS (貸方)'!B19 -> 長期借入金 | C19: ='BS (貸方)'!F19 -> 191858000 | E19: =C19+D19 -> 191858000 | G19: 9本すべて代表者の連帯保証付き。民間6本は信用保証協会の保証付き
B20: ='BS (貸方)'!B20 -> 役員借入金 | C20: ='BS (貸方)'!F20 -> 7565770 | E20: =C20+D20 -> 7565770 | G20: 譲渡時に返済を希望。ネットキャッシュ算定ではデットライクアイテムとして控除
B21: ='BS (貸方)'!B21 -> 長期未払金 | C21: ='BS (貸方)'!F21 -> 2346020 | E21: =C21+D21 -> 2346020
B22: ='BS (貸方)'!B22 -> 0 | C22: ='BS (貸方)'!F22 -> 0 | E22: =C22+D22 -> 0
B23: ='BS (貸方)'!B23 -> 0 | C23: ='BS (貸方)'!F23 -> 0 | E23: =C23+D23 -> 0
E24: =C24+D24 -> 0
E25: =C25+D25 -> 0
E26: =C26+D26 -> 0
B27: 【繰延税金負債】 | C27: 0 | D27: 0 | E27: =C27+D27 -> 0
B28: 負債合計 | C28: =C5+C18+C27 -> 249441992 | D28: =D5+D18+D27 -> 0 | E28: =C28+D28 -> 249441992
B34: 純資産の部
B35: 【資本金】 | C35: =SUM(C36:C38) -> 1000000 | D35: =SUM(D36:D38) -> 0 | E35: =C35+D35 -> 1000000
B36: ='BS (貸方)'!B36 -> 資本金 | C36: ='BS (貸方)'!F36 -> 1000000 | E36: =C36+D36 -> 1000000
E37: =C37+D37 -> 0
E38: =C38+D38 -> 0
B39: 【資本剰余金】 | C39: =SUM(C40:C42) -> 0 | D39: =SUM(D40:D42) -> 0 | E39: =C39+D39 -> 0
E40: =C40+D40 -> 0
E41: =C41+D41 -> 0
E42: =C42+D42 -> 0
B43: 【利益剰余金】 | C43: =SUM(C44:C47) -> -15056815 | D43: =SUM(D44:D47) -> 0 | E43: =C43+D43 -> -15056815
B44: ='BS (貸方)'!B44 -> 繰越利益剰余金 | C44: ='BS (貸方)'!F44 -> -15056815 | E44: =C44+D44 -> -15056815
B45: ='BS (貸方)'!B45 -> 0 | C45: ='BS (貸方)'!F45 -> 0 | E45: =C45+D45 -> 0
B46: ='BS (貸方)'!B46 -> 0 | C46: ='BS (貸方)'!F46 -> 0 | E46: =C46+D46 -> 0
...

Sheet 未払人件費・賞与
D2: (単位：千円) | E2: (単位：千円) | F2: (単位：千円)
B3: 支払給与 | C3: 未払日数 | D3: 未払給与引当額 | E3: 概算社会保険料 | F3: 未払給与引当額
B4: 未評価：賃金台帳では当月締・翌月25日払であり、11月分給与が未払費用20,114千円に含まれているか要確認。未計上であれば社会保険料概算15%を含め約10,000千円超の追加計上が必要。賞与制度の有無も未確認のため引当計上していない。
B8: 支払予定賞与

Sheet 退職金
J2: (単位：千円)
B3: № | C3: 氏名 | D3: 勤続年数(年) | E3: 基本給 | F3: 支給倍率 | G3: 退職理由率 | H3: 要支給額 | I3: 中退共積立額 | J3: 引当不足
C4: 未評価：従業員退職金規程・役員退職慰労金規程がいずれも未受領のため、要支給額を算定できず引当計上していない（要確認）。

Sheet 税効果
E2: (単位：千円)
B3: 修正科目 | C3: 適用判定 | D3: 修正額 | E3: 繰延税金資産/負債 | F3: 備考
B4: 棚卸資産 | C4: × | D4: -44000000 | E4: － | F4: 繰越欠損金を有し課税所得の見込みが立たないため回収可能性を認めず、繰延税金資産を計上しない
B5: 営業権 | C5: × | D5: -1500004 | E5: － | F5: 同上。またB/S計上の営業権は年買法での二重計上を避けるための評価減であり税務上の影響はない
B6: 仮払金 | C6: × | D6: -1650000 | E6: － | F6: 同上
B9: ※実効税率34%。評価差額合計△47,150千円に対する繰延税金資産16,031千円は、回収可能性が認められないため認識していない（保守的な取扱い）。課税所得の見通しが立つ場合は同額だけ時価純資産が上振れする。

Sheet ネットキャッシュ
F2: (単位：千円)
B3: キャッシュライクアイテム | C3: 金額 | E3: デットライクアイテム | F3: 金額
B4: 現金及び預金 | C4: ='BS(借方)'!F6 -> 10140492 | E4: 短期借入金
B5: 役員貸付金 | E5: 長期借入金 | F5: ='BS (貸方)'!F19 -> 191858000
B6: 従業員貸付金 | E6: 社債
B7: 立替金 | E7: 役員借入金 | F7: ='BS (貸方)'!F20 -> 7565770
B8: 保険積立金 | E8: 未払法人税 | F8: ='BS (貸方)'!F10 -> 242500
B9: 投資有価証券 | E9: 資産除去債務
B10: 売却予定不動産 | E10: 役員退職慰労金
B11: 売却予定車両 | E11: 営業循環外前受金
E12: ファイナンスリース債務
B13: 合計 | C13: =SUM(C4:C12) -> 10140492 | E13: 合計 | F13: =SUM(F4:F12) -> 199666270
B15: ※基準日（2025年11月30日）の残高。保険積立金・投資有価証券・役員貸付金の残高はない。※長期未払金2,346千円は分割払いの未払金であり有利子負債ではないためデットライクに含めていない（要確認）。 | C15: =C13-F13 -> -189525778 | E15: ネットデット | F15: =F13-I13 -> 199666270
C17: ↑どっちか消す | F17: ↑どっちか消す

Sheet 修正PL
K2: (単位：千円)
B3: 科目 | C3: ='BS(借方)'!C4 -> － | F3: ='BS(借方)'!D4 -> 23年11月期 | I3: ='BS(借方)'!E4 -> 24年11月期 | L3: ='BS(借方)'!F4 -> 25年11月期 | O3: ='BS(借方)'!G4 -> 26年11月期 （7か月TB） | S3: 調整事由
C4: 帳簿価額 | D4: 修正額 | E4: 修正後 | F4: 帳簿価額 | G4: 修正額 | H4: 修正後 | I4: 帳簿価額 | J4: 修正額 | K4: 修正後 | L4: 帳簿価額 | M4: 修正額 | N4: 修正後 | O4: 帳簿価額 | P4: 修正額 | Q4: 修正後
B5: =PL!B5 -> 生体売上高 | C5: =PL!C5 -> 0 | E5: =C5+D5 -> 0 | F5: =PL!E5 -> 293213620 | H5: =F5+G5 -> 293213620 | I5: =PL!G5 -> 333089628 | K5: =I5+J5 -> 333089628 | L5: =PL!I5 -> 338295378 | N5: =L5+M5 -> 338295378 | O5: =PL!K5 -> 165116994 | Q5: =O5+P5 -> 165116994
B6: =PL!B6 -> サービス売上高 | C6: =PL!C6 -> 0 | E6: =C6+D6 -> 0 | F6: =PL!E6 -> 65655525 | H6: =F6+G6 -> 65655525 | I6: =PL!G6 -> 60897406 | K6: =I6+J6 -> 60897406 | L6: =PL!I6 -> 52699187 | N6: =L6+M6 -> 52699187 | O6: =PL!K6 -> 32791687 | Q6: =O6+P6 -> 32791687
B7: =PL!B7 -> 物販売上高 | C7: =PL!C7 -> 0 | E7: =C7+D7 -> 0 | F7: =PL!E7 -> 115559176 | H7: =F7+G7 -> 115559176 | I7: =PL!G7 -> 145047985 | K7: =I7+J7 -> 145047985 | L7: =PL!I7 -> 167395169 | N7: =L7+M7 -> 167395169 | O7: =PL!K7 -> 81244762 | Q7: =O7+P7 -> 81244762
B8: =PL!B8 -> 0 | C8: =PL!C8 -> 0 | E8: =C8+D8 -> 0 | F8: =PL!E8 -> 0 | H8: =F8+G8 -> 0 | I8: =PL!G8 -> 0 | K8: =I8+J8 -> 0 | L8: =PL!I8 -> 0 | N8: =L8+M8 -> 0 | O8: =PL!K8 -> 0 | Q8: =O8+P8 -> 0
B9: =PL!B9 -> 0 | C9: =PL!C9 -> 0 | E9: =C9+D9 -> 0 | F9: =PL!E9 -> 0 | H9: =F9+G9 -> 0 | I9: =PL!G9 -> 0 | K9: =I9+J9 -> 0 | L9: =PL!I9 -> 0 | N9: =L9+M9 -> 0 | O9: =PL!K9 -> 0 | Q9: =O9+P9 -> 0
E10: =C10+D10 -> 0 | H10: =F10+G10 -> 0 | K10: =I10+J10 -> 0 | N10: =L10+M10 -> 0 | Q10: =O10+P10 -> 0
B11: 売上高 | C11: =SUM(C5:C10) -> 0 | D11: =SUM(D5:D10) -> 0 | E11: =C11+D11 -> 0 | F11: =SUM(F5:F10) -> 474428321 | G11: =SUM(G5:G10) -> 0 | H11: =F11+G11 -> 474428321 | I11: =SUM(I5:I10) -> 539035019 | J11: =SUM(J5:J10) -> 0 | K11: =I11+J11 -> 539035019 | L11: =SUM(L5:L10) -> 558389734 | M11: =SUM(M5:M10) -> 0 | N11: =L11+M11 -> 558389734 | O11: =SUM(O5:O10) -> 279153443 | P11: =SUM(P5:P10) -> 0 | Q11: =O11+P11 -> 279153443
B12: =PL!B12 -> 期首棚卸高 | C12: =PL!C12 -> 0 | E12: =C12+D12 -> 0 | F12: =PL!E12 -> 39485899 | H12: =F12+G12 -> 39485899 | I12: =PL!G12 -> 70917819 | K12: =I12+J12 -> 70917819 | L12: =PL!I12 -> 127080914 | N12: =L12+M12 -> 127080914 | O12: =PL!K12 -> 106017284 | Q12: =O12+P12 -> 106017284
B13: =PL!B13 -> 商品仕入高 | C13: =PL!C13 -> 0 | E13: =C13+D13 -> 0 | F13: =PL!E13 -> 183853875 | H13: =F13+G13 -> 183853875 | I13: =PL!G13 -> 220800993 | K13: =I13+J13 -> 220800993 | L13: =PL!I13 -> 182243467 | N13: =L13+M13 -> 182243467 | O13: =PL!K13 -> 92273907 | Q13: =O13+P13 -> 92273907
B14: =PL!B14 -> 外注費 | C14: =PL!C14 -> 0 | E14: =C14+D14 -> 0 | F14: =PL!E14 -> 29627732 | H14: =F14+G14 -> 29627732 | I14: =PL!G14 -> 31465971 | K14: =I14+J14 -> 31465971 | L14: =PL!I14 -> 25058151 | N14: =L14+M14 -> 25058151 | O14: =PL!K14 -> 8916840 | Q14: =O14+P14 -> 8916840
B15: =PL!B15 -> 他勘定振替高 | C15: =PL!C15 -> 0 | E15: =C15+D15 -> 0 | F15: =PL!E15 -> 0 | H15: =F15+G15 -> 0 | I15: =PL!G15 -> 0 | K15: =I15+J15 -> 0 | L15: =PL!I15 -> 0 | N15: =L15+M15 -> 0 | O15: =PL!K15 -> -44000000 | Q15: =O15+P15 -> -44000000
B16: =PL!B16 -> 期末棚卸高 | C16: =PL!C16 -> 0 | E16: =C16+D16 -> 0 | F16: =PL!E16 -> -70917819 | H16: =F16+G16 -> -70917819 | I16: =PL!G16 -> -127080914 | K16: =I16+J16 -> -127080914 | L16: =PL!I16 -> -106017284 | N16: =L16+M16 -> -106017284 | O16: =PL!K16 -> -58445785 | Q16: =O16+P16 -> -58445785
B17: 売上原価 | C17: =SUM(C12:C16) -> 0 | D17: =SUM(D12:D16) -> 0 | E17: =C17+D17 -> 0 | F17: =SUM(F12:F16) -> 182049687 | G17: =SUM(G12:G16) -> 0 | H17: =F17+G17 -> 182049687 | I17: =SUM(I12:I16) -> 196103869 | J17: =SUM(J12:J16) -> 0 | K17: =I17+J17 -> 196103869 | L17: =SUM(L12:L16) -> 228365248 | M17: =SUM(M12:M16) -> 0 | N17: =L17+M17 -> 228365248 | O17: =SUM(O12:O16) -> 104762246 | P17: =SUM(P12:P16) -> 0 | Q17: =O17+P17 -> 104762246
B18: 売上総利益 | C18: =C11-C17 -> 0 | D18: =D11-D17 -> 0 | E18: =C18+D18 -> 0 | F18: =F11-F17 -> 292378634 | G18: =G11-G17 -> 0 | H18: =F18+G18 -> 292378634 | I18: =I11-I17 -> 342931150 | J18: =J11-J17 -> 0 | K18: =I18+J18 -> 342931150 | L18: =L11-L17 -> 330024486 | M18: =M11-M17 -> 0 | N18: =L18+M18 -> 330024486 | O18: =O11-O17 -> 174391197 | P18: =P11-P17 -> 0 | Q18: =O18+P18 -> 174391197
B19: 販売費及び一般管理費 | C19: =修正SGA!C39 -> 0 | E19: =C19+D19 -> 0 | F19: =修正SGA!F39 -> 290037494 | G19: =修正SGA!G39 -> -7535000 | H19: =F19+G19 -> 282502494 | I19: =修正SGA!I39 -> 339909050 | J19: =修正SGA!J39 -> -19814000 | K19: =I19+J19 -> 320095050 | L19: =修正SGA!L39 -> 349576223 | M19: =修正SGA!M39 -> -19229000 | N19: =L19+M19 -> 330347223 | O19: =修正SGA!O39 -> 167754348 | Q19: =O19+P19 -> 167754348
B20: 営業利益 | C20: =C18- C19 -> 0 | D20: =D18- D19 -> 0 | E20: =C20+D20 -> 0 | F20: =F18- F19 -> 2341140 | G20: =G18- G19 -> 7535000 | H20: =F20+G20 -> 9876140 | I20: =I18- I19 -> 3022100 | J20: =J18- J19 -> 19814000 | K20: =I20+J20 -> 22836100 | L20: =L18- L19 -> -19551737 | M20: =M18- M19 -> 19229000 | N20: =L20+M20 -> -322737 | O20: =O18- O19 -> 6636849 | P20: =P18- P19 -> 0 | Q20: =O20+P20 -> 6636849
B21: 営業外収益 | C21: =SUM(C22:C28) -> 0 | D21: =SUM(D22:D28) -> 0 | E21: =C21+D21 -> 0 | F21: =SUM(F22:F28) -> 1321452 | G21: =SUM(G22:G28) -> 1321000 | H21: =F21+G21 -> 2642452 | I21: =SUM(I22:I28) -> 2383452 | J21: =SUM(J22:J28) -> 635000 | K21: =I21+J21 -> 3018452 | L21: =SUM(L22:L28) -> 3631958 | M21: =SUM(M22:M28) -> 654868 | N21: =L21+M21 -> 4286826 | O21: =SUM(O22:O28) -> 1059276 | P21: =SUM(P22:P28) -> 0 | Q21: =O21+P21 -> 1059276
B22: =PL!B22 -> 受取利息 | C22: =PL!C22 -> 0 | E22: =C22+D22 -> 0 | F22: =PL!E22 -> 193 | H22: =F22+G22 -> 193 | I22: =PL!G22 -> 4702 | K22: =I22+J22 -> 4702 | L22: =PL!I22 -> 24608 | N22: =L22+M22 -> 24608 | O22: =PL!K22 -> 6446 | Q22: =O22+P22 -> 6446
B23: =PL!B23 -> 受取配当金 | C23: =PL!C23 -> 0 | E23: =C23+D23 -> 0 | F23: =PL!E23 -> 188 | H23: =F23+G23 -> 188 | I23: =PL!G23 -> 376 | K23: =I23+J23 -> 376 | L23: =PL!I23 -> 282 | N23: =L23+M23 -> 282 | O23: =PL!K23 -> 300 | Q23: =O23+P23 -> 300
B24: =PL!B24 -> 雑収入 | C24: =PL!C24 -> 0 | E24: =C24+D24 -> 0 | F24: =PL!E24 -> 1321071 | G24: 1321000 | H24: =F24+G24 -> 2642071 | I24: =PL!G24 -> 2378374 | J24: 635000 | K24: =I24+J24 -> 3013374 | L24: =PL!I24 -> 3607068 | M24: 654868 | N24: =L24+M24 -> 4261936 | O24: =PL!K24 -> 1052530 | Q24: =O24+P24 -> 1052530 | S24: 社員割引に伴う経常的な雑収入。事業に付随して継続的に発生するため正常収益力に加算
B25: =PL!B25 -> 0 | C25: =PL!C25 -> 0 | E25: =C25+D25 -> 0 | F25: =PL!E25 -> 0 | H25: =F25+G25 -> 0 | I25: =PL!G25 -> 0 | K25: =I25+J25 -> 0 | L25: =PL!I25 -> 0 | N25: =L25+M25 -> 0 | O25: =PL!K25 -> 0 | Q25: =O25+P25 -> 0
B26: =PL!B26 -> 0 | C26: =PL!C26 -> 0 | E26: =C26+D26 -> 0 | F26: =PL!E26 -> 0 | H26: =F26+G26 -> 0 | I26: =PL!G26 -> 0 | K26: =I26+J26 -> 0 | L26: =PL!I26 -> 0 | N26: =L26+M26 -> 0 | O26: =PL!K26 -> 0 | Q26: =O26+P26 -> 0
B27: =PL!B27 -> 0 | C27: =PL!C27 -> 0 | E27: =C27+D27 -> 0 | F27: =PL!E27 -> 0 | H27: =F27+G27 -> 0 | I27: =PL!G27 -> 0 | K27: =I27+J27 -> 0 | L27: =PL!I27 -> 0 | N27: =L27+M27 -> 0 | O27: =PL!K27 -> 0 | Q27: =O27+P27 -> 0
E28: =C28+D28 -> 0 | H28: =F28+G28 -> 0 | K28: =I28+J28 -> 0 | N28: =L28+M28 -> 0 | Q28: =O28+P28 -> 0
B29: 営業外費用 | C29: =SUM(C30:C36) -> 0 | D29: =SUM(D30:D36) -> 0 | E29: =C29+D29 -> 0 | F29: =SUM(F30:F36) -> 1134221 | G29: =SUM(G30:G36) -> 0 | H29: =F29+G29 -> 1134221 | I29: =SUM(I30:I36) -> 2295915 | J29: =SUM(J30:J36) -> 0 | K29: =I29+J29 -> 2295915 | L29: =SUM(L30:L36) -> 2655577 | M29: =SUM(M30:M36) -> 0 | N29: =L29+M29 -> 2655577 | O29: =SUM(O30:O36) -> 1881979 | P29: =SUM(P30:P36) -> 0 | Q29: =O29+P29 -> 1881979
B30: =PL!B30 -> 支払利息 | C30: =PL!C30 -> 0 | E30: =C30+D30 -> 0 | F30: =PL!E30 -> 1134221 | H30: =F30+G30 -> 1134221 | I30: =PL!G30 -> 1787923 | K30: =I30+J30 -> 1787923 | L30: =PL!I30 -> 2590791 | N30: =L30+M30 -> 2590791 | O30: =PL!K30 -> 1881899 | Q30: =O30+P30 -> 1881899
B31: =PL!B31 -> 雑損失 | C31: =PL!C31 -> 0 | E31: =C31+D31 -> 0 | F31: =PL!E31 -> 0 | H31: =F31+G31 -> 0 | I31: =PL!G31 -> 507992 | K31: =I31+J31 -> 507992 | L31: =PL!I31 -> 64786 | N31: =L31+M31 -> 64786 | O31: =PL!K31 -> 80 | Q31: =O31+P31 -> 80
B32: =PL!B32 -> 0 | C32: =PL!C32 -> 0 | E32: =C32+D32 -> 0 | F32: =PL!E32 -> 0 | H32: =F32+G32 -> 0 | I32: =PL!G32 -> 0 | K32: =I32+J32 -> 0 | L32: =PL!I32 -> 0 | N32: =L32+M32 -> 0 | O32: =PL!K32 -> 0 | Q32: =O32+P32 -> 0
B33: =PL!B33 -> 0 | C33: =PL!C33 -> 0 | E33: =C33+D33 -> 0 | F33: =PL!E33 -> 0 | H33: =F33+G33 -> 0 | I33: =PL!G33 -> 0 | K33: =I33+J33 -> 0 | L33: =PL!I33 -> 0 | N33: =L33+M33 -> 0 | O33: =PL!K33 -> 0 | Q33: =O33+P33 -> 0
B34: =PL!B34 -> 0 | C34: =PL!C34 -> 0 | E34: =C34+D34 -> 0 | F34: =PL!E34 -> 0 | H34: =F34+G34 -> 0 | I34: =PL!G34 -> 0 | K34: =I34+J34 -> 0 | L34: =PL!I34 -> 0 | N34: =L34+M34 -> 0 | O34: =PL!K34 -> 0 | Q34: =O34+P34 -> 0
B35: =PL!B35 -> 0 | C35: =PL!C35 -> 0 | E35: =C35+D35 -> 0 | F35: =PL!E35 -> 0 | H35: =F35+G35 -> 0 | I35: =PL!G35 -> 0 | K35: =I35+J35 -> 0 | L35: =PL!I35 -> 0 | N35: =L35+M35 -> 0 | O35: =PL!K35 -> 0 | Q35: =O35+P35 -> 0
E36: =C36+D36 -> 0 | H36: =F36+G36 -> 0 | K36: =I36+J36 -> 0 | N36: =L36+M36 -> 0 | Q36: =O36+P36 -> 0
B37: 経常利益 | C37: =C20+C21-C29 -> 0 | D37: =D20+D21-D29 -> 0 | E37: =C37+D37 -> 0 | F37: =F20+F21-F29 -> 2528371 | G37: =G20+G21-G29 -> 8856000 | H37: =F37+G37 -> 11384371 | I37: =I20+I21-I29 -> 3109637 | J37: =J20+J21-J29 -> 20449000 | K37: =I37+J37 -> 23558637 | L37: =L20+L21-L29 -> -18575356 | M37: =M20+M21-M29 -> 19883868 | N37: =L37+M37 -> 1308512 | O37: =O20+O21-O29 -> 5814146 | P37: =P20+P21-P29 -> 0 | Q37: =O37+P37 -> 5814146
B38: 特別利益 | C38: =SUM(C39:C44) -> 0 | D38: =SUM(D39:D44) -> 0 | E38: =C38+D38 -> 0 | F38: =SUM(F39:F44) -> 0 | G38: =SUM(G39:G44) -> 0 | H38: =F38+G38 -> 0 | I38: =SUM(I39:I44) -> 0 | J38: =SUM(J39:J44) -> 0 | K38: =I38+J38 -> 0 | L38: =SUM(L39:L44) -> 0 | M38: =SUM(M39:M44) -> 0 | N38: =L38+M38 -> 0 | O38: =SUM(O39:O44) -> 0 | P38: =SUM(P39:P44) -> 0 | Q38: =O38+P38 -> 0
B39: =PL!B39 -> 0 | C39: =PL!C39 -> 0 | E39: =C39+D39 -> 0 | F39: =PL!E39 -> 0 | H39: =F39+G39 -> 0 | I39: =PL!G39 -> 0 | K39: =I39+J39 -> 0 | L39: =PL!I39 -> 0 | N39: =L39+M39 -> 0 | O39: =PL!K39 -> 0 | Q39: =O39+P39 -> 0
B40: =PL!B40 -> 0 | C40: =PL!C40 -> 0 | E40: =C40+D40 -> 0 | F40: =PL!E40 -> 0 | H40: =F40+G40 -> 0 | I40: =PL!G40 -> 0 | K40: =I40+J40 -> 0 | L40: =PL!I40 -> 0 | N40: =L40+M40 -> 0 | O40: =PL!K40 -> 0 | Q40: =O40+P40 -> 0
B41: =PL!B41 -> 0 | C41: =PL!C41 -> 0 | E41: =C41+D41 -> 0 | F41: =PL!E41 -> 0 | H41: =F41+G41 -> 0 | I41: =PL!G41 -> 0 | K41: =I41+J41 -> 0 | L41: =PL!I41 -> 0 | N41: =L41+M41 -> 0 | O41: =PL!K41 -> 0 | Q41: =O41+P41 -> 0
...

Sheet 修正SGA
K2: (単位：千円)
B3: 科目 | C3: ='BS(借方)'!C4 -> － | F3: ='BS(借方)'!D4 -> 23年11月期 | I3: ='BS(借方)'!E4 -> 24年11月期 | L3: ='BS(借方)'!F4 -> 25年11月期 | O3: ='BS(借方)'!G4 -> 26年11月期 （7か月TB） | S3: 調整事由
C4: 帳簿価額 | D4: 修正額 | E4: 修正後 | F4: 帳簿価額 | G4: 修正額 | H4: 修正後 | I4: 帳簿価額 | J4: 修正額 | K4: 修正後 | L4: 帳簿価額 | M4: 修正額 | N4: 修正後 | O4: 帳簿価額 | P4: 修正額 | Q4: 修正後
B5: =SGA!B6 -> 従業員給与 | C5: =SGA!C6 -> 0 | E5: =C5+D5 -> 0 | F5: =SGA!E6 -> 112323477 | G5: 0 | H5: =F5+G5 -> 112323477 | I5: =SGA!G6 -> 115961553 | J5: -8831000 | K5: =I5+J5 -> 107130553 | L5: =SGA!I6 -> 127016990 | M5: -8183000 | N5: =L5+M5 -> 118833990 | O5: =SGA!K6 -> 64179726 | Q5: =O5+P5 -> 64179726 | S5: 現場責任者（淺野崇氏）の人件費を役員報酬へ振替
B6: =SGA!B7 -> 旅費交通費 | C6: =SGA!C7 -> 0 | E6: =C6+D6 -> 0 | F6: =SGA!E7 -> 3152359 | H6: =F6+G6 -> 3152359 | I6: =SGA!G7 -> 4978151 | K6: =I6+J6 -> 4978151 | L6: =SGA!I7 -> 5724652 | N6: =L6+M6 -> 5724652 | O6: =SGA!K7 -> 3504938 | Q6: =O6+P6 -> 3504938
B7: =SGA!B8 -> 広告宣伝費 | C7: =SGA!C8 -> 0 | E7: =C7+D7 -> 0 | F7: =SGA!E8 -> 24335030 | H7: =F7+G7 -> 24335030 | I7: =SGA!G8 -> 34052424 | K7: =I7+J7 -> 34052424 | L7: =SGA!I8 -> 26650854 | N7: =L7+M7 -> 26650854 | O7: =SGA!K8 -> 15163208 | Q7: =O7+P7 -> 15163208
B8: =SGA!B9 -> 発送配達費 | C8: =SGA!C9 -> 0 | E8: =C8+D8 -> 0 | F8: =SGA!E9 -> 352787 | H8: =F8+G8 -> 352787 | I8: =SGA!G9 -> 280605 | K8: =I8+J8 -> 280605 | L8: =SGA!I9 -> 436931 | N8: =L8+M8 -> 436931 | O8: =SGA!K9 -> 129150 | Q8: =O8+P8 -> 129150
B9: =SGA!B10 -> ロイヤリティ | C9: =SGA!C10 -> 0 | E9: =C9+D9 -> 0 | F9: =SGA!E10 -> 45990311 | H9: =F9+G9 -> 45990311 | I9: =SGA!G10 -> 39848148 | K9: =I9+J9 -> 39848148 | L9: =SGA!I10 -> 29981679 | N9: =L9+M9 -> 29981679 | O9: =SGA!K10 -> 14193011 | Q9: =O9+P9 -> 14193011
B10: =SGA!B11 -> 会議費 | C10: =SGA!C11 -> 0 | E10: =C10+D10 -> 0 | F10: =SGA!E11 -> 189625 | H10: =F10+G10 -> 189625 | I10: =SGA!G11 -> 484171 | K10: =I10+J10 -> 484171 | L10: =SGA!I11 -> 1489497 | N10: =L10+M10 -> 1489497 | O10: =SGA!K11 -> 887177 | Q10: =O10+P10 -> 887177
B11: =SGA!B12 -> 役員報酬 | C11: =SGA!C12 -> 0 | E11: =C11+D11 -> 0 | F11: =SGA!E12 -> 9600000 | G11: 0 | H11: =F11+G11 -> 9600000 | I11: =SGA!G12 -> 9600000 | J11: 0 | K11: =I11+J11 -> 9600000 | L11: =SGA!I12 -> 14400000 | M11: 0 | N11: =L11+M11 -> 14400000 | O11: =SGA!K12 -> 6300000 | Q11: =O11+P11 -> 6300000 | S11: 代表者の退任分を戻し入れ、後任役員の同水準報酬を控除（差引ゼロ）
B12: =SGA!B13 -> 法定福利費 | C12: =SGA!C13 -> 0 | E12: =C12+D12 -> 0 | F12: =SGA!E13 -> 10104201 | H12: =F12+G12 -> 10104201 | I12: =SGA!G13 -> 22242217 | K12: =I12+J12 -> 22242217 | L12: =SGA!I13 -> 15295210 | N12: =L12+M12 -> 15295210 | O12: =SGA!K13 -> 2778916 | Q12: =O12+P12 -> 2778916
B13: =SGA!B14 -> 厚生費 | C13: =SGA!C14 -> 0 | E13: =C13+D13 -> 0 | F13: =SGA!E14 -> 2936211 | H13: =F13+G13 -> 2936211 | I13: =SGA!G14 -> 3945609 | K13: =I13+J13 -> 3945609 | L13: =SGA!I14 -> 3862961 | N13: =L13+M13 -> 3862961 | O13: =SGA!K14 -> 1748144 | Q13: =O13+P13 -> 1748144
B14: =SGA!B15 -> 減価償却費 | C14: =SGA!C15 -> 0 | E14: =C14+D14 -> 0 | F14: =SGA!E15 -> 3911003 | H14: =F14+G14 -> 3911003 | I14: =SGA!G15 -> 9294598 | K14: =I14+J14 -> 9294598 | L14: =SGA!I15 -> 6349173 | N14: =L14+M14 -> 6349173 | O14: =SGA!K15 -> 0 | Q14: =O14+P14 -> 0
B15: =SGA!B16 -> リース料 | C15: =SGA!C16 -> 0 | E15: =C15+D15 -> 0 | F15: =SGA!E16 -> 4294932 | G15: -2386000 | H15: =F15+G15 -> 1908932 | I15: =SGA!G16 -> 4554982 | J15: -3154000 | K15: =I15+J15 -> 1400982 | L15: =SGA!I16 -> 7249573 | M15: -5604000 | N15: =L15+M15 -> 1645573 | O15: =SGA!K16 -> 4352502 | Q15: =O15+P15 -> 4352502 | S15: 非事業用車両のリース料（本件実行後に発生しない）
B16: =SGA!B17 -> 地代家賃 | C16: =SGA!C17 -> 0 | E16: =C16+D16 -> 0 | F16: =SGA!E17 -> 8230492 | H16: =F16+G16 -> 8230492 | I16: =SGA!G17 -> 19460488 | K16: =I16+J16 -> 19460488 | L16: =SGA!I17 -> 33248832 | N16: =L16+M16 -> 33248832 | O16: =SGA!K17 -> 19879129 | Q16: =O16+P16 -> 19879129
B17: =SGA!B18 -> 修繕費 | C17: =SGA!C18 -> 0 | E17: =C17+D17 -> 0 | F17: =SGA!E18 -> 468295 | H17: =F17+G17 -> 468295 | I17: =SGA!G18 -> 1088033 | K17: =I17+J17 -> 1088033 | L17: =SGA!I18 -> 275210 | N17: =L17+M17 -> 275210 | O17: =SGA!K18 -> 243111 | Q17: =O17+P17 -> 243111
B18: =SGA!B19 -> 事務用消耗品費 | C18: =SGA!C19 -> 0 | E18: =C18+D18 -> 0 | F18: =SGA!E19 -> 9801863 | H18: =F18+G18 -> 9801863 | I18: =SGA!G19 -> 6407354 | K18: =I18+J18 -> 6407354 | L18: =SGA!I19 -> 4371794 | N18: =L18+M18 -> 4371794 | O18: =SGA!K19 -> 1558723 | Q18: =O18+P18 -> 1558723
B19: =SGA!B20 -> 通信費 | C19: =SGA!C20 -> 0 | E19: =C19+D19 -> 0 | F19: =SGA!E20 -> 2455532 | H19: =F19+G19 -> 2455532 | I19: =SGA!G20 -> 2672628 | K19: =I19+J19 -> 2672628 | L19: =SGA!I20 -> 3045340 | N19: =L19+M19 -> 3045340 | O19: =SGA!K20 -> 2149718 | Q19: =O19+P19 -> 2149718
